Workbook

Sheet Note
A1: skip
B2: Life cycle inventories of global metal and mineral supply chains: a comprehensive data review, analysis and processing Frédéric Laia*, Stéphanie Mullera, Audrey Philippea, Robert Istrateb, Brenda Miranda Xicotencatlb, Afsoon Mansouri Askic, Aina Mas Fonsd,a, Juliana Segura-Salazare, Jair Santillán Saldivara, Alexander Cimprichf, Stephen Northeyg, Lígia da Silva Limah, Lieselot Booneh, Ryosuke Yokoii, Kamrul Islami, Ioanna Paschalidouj, Felipe Cerdask,l, Victor Balboa-Espinozae, Anish Koyamparambathd, Diae Henniouia, Victoire Collignona, Aurélien Reysa, Gyslain Ngadi Sakatadim, Jo Dewulfh, Bernhard Steubingb, Christoph Helbigc, Gaétan Lefebvrea, Gian Andrea Blenginin,m, Valeria Supertio, Masaharu Motoshitai, Guido Sonnemannd, Kwame Awuah-Offeij, Steven B. Youngf, Shinsuke Murakamip, Antoine Beylota aBRGM, F-45060 Orléans, France bInstitute of Environmental Sciences (CML), Leiden University, Einsteinweg 2, 2333 CC Leiden, NL cEcological Resource Technology, University of Bayreuth, Universitätstr. 30, 95447 Bayreuth, Germany dUniv. Bordeaux, CNRS, Bordeaux INP, ISM, UMR 5255, F-33400 Talence, France eSustainable Minerals Institute, The University of Queensland, QLD, 4072, Australia fSchool of Environment, Enterprise and Development, University of Waterloo, 200 University Avenue West, Waterloo, Ontario N2L 3G1, Canada gUniversity of Technology Sydney, Institute for Sustainable Futures, Australia hSustainable Systems Engineering (STEN), Department of Green Chemistry and Technology, Faculty of Bioscience Engineering, Ghent University, Coupure Links 653, 9000 Ghent, Belgium iAIST, 305-8569 Tsukuba, Japan jMining & Explosives Engineering, Missouri University of Science & Technology, Rolla, MO, USA 65409 kInstitute for Sustainable Energy Systems (INSYS), Technical University of Applied Sciences Würzburg-Schweinfurt (THWS), Ignaz-Schön-Straße 11, Schweinfurt, Germany lFraunhofer Institute for Surface Engineering and Thin Films IST, Riedenkamp 2, Braunschweig 38108, Germany mDepartment of Environment, Land and Infrastructure Engineering, Politecnico di Torino, Corso Duca degli Abruzzi, 24, 10129 Torino, Italy nUniversity of Turin, Earth Sciences Department (DST), Via Valperga Caluso, 35 – 10125 Torino, Italy oecoinvent association, Technopark, Technoparkstrasse 1, 8005 Zürich, Switzerland pGraduate School of Engineering, The University of Tokyo, Tokyo 113-8656, Japan *Corresponding author: f.lai@brgm.fr This file provides all LCI datasets developed for Aluminium (Al), with distinguishing its global market and each individual production route.
B33: Sheet | C33: Corresponding route
B34: Al_Market_GLO | C34: Al global market
B35: PR1_Al_SAM | C35: Bauxite mining and Al ingot production in South America
B36: PR2_Al_OCA | C36: Bauxite mining and Al ingot production in Oceania
B37: PR3_Al_NAM | C37: Al ingot production in North America
B38: PR4_Al_EUR | C38: Al ingot production in Europe
B39: PR5_Al_ROE | C39: Al ingot production in Russia and rest-of-Europe
B40: PR6_Al_GCC | C40: Al ingot production in Gulf Cooperation Council (GCC) countries
B41: PR7_Al_AFR | C41: Al ingot production in Africa
B42: PR8_Al_OAS | C42: Al ingot production in rest-of-Asia
B43: PR9_Al_CN | C43: Bauxite mining and Al ingot production in China
B44: PR10_Al_CN_Recycling | C44: Al production in China through Al scraps recycling
... B46: PR12_Al_EUR_Recycling | C46: Al production in Europe through Al scraps recycling

Sheet Al_Market_GLO
A1: database | B1: Aluminium
A3: Activity | B3: Aluminium (Al) global market
A4: reference product | B4: Al ingot
A5: location | B5: GLO
A6: amount | B6: 1
A7: unit | B7: kilogram
A8: comment | B8: n/a
A9: Exchanges
A10: name | B10: reference product | C10: location | D10: amount | E10: unit | F10: database | G10: type | H10: categories | I10: uncertainty type | J10: pedigree | K10: loc | L10: scale | M10: minimum | N10: maximum
A11: =B3 -> Aluminium (Al) global market | B11: =B4 -> Al ingot | C11: =B5 -> GLO | D11: 1 | E11: =B7 -> kilogram | F11: =B1 -> Aluminium | G11: production
A12: =PR1_Al_SAM!A161 -> Bauxite mining and Al ingot production in South America | B12: =PR1_Al_SAM!B161 -> Al ingot | C12: =PR1_Al_SAM!C161 -> South America | D12: 0.015211462 | E12: =PR1_Al_SAM!E161 -> kilogram | F12: =PR1_Al_SAM!F161 -> Aluminium | G12: technosphere
A13: =PR2_Al_OCA!A154 -> Bauxite mining and Al ingot production in Oceania | B13: =PR2_Al_OCA!B154 -> Al ingot | C13: =PR2_Al_OCA!C154 -> Oceania | D13: 0.026699936 | E13: =PR2_Al_OCA!E154 -> kilogram | F13: =PR2_Al_OCA!F154 -> Aluminium | G13: technosphere
A14: =PR3_Al_NAM!A153 -> Al ingot production in North America | B14: =PR3_Al_NAM!B153 -> Al ingot | C14: =PR3_Al_NAM!C153 -> North America | D14: 0.054886289 | E14: =PR3_Al_NAM!E153 -> kilogram | F14: =PR3_Al_NAM!F153 -> Aluminium | G14: technosphere
A15: =PR4_Al_EUR!A165 -> Al ingot production in Europe | B15: =PR4_Al_EUR!B165 -> Al ingot | C15: =PR4_Al_EUR!C165 -> Europe | D15: 0.051455028 | E15: =PR4_Al_EUR!E165 -> kilogram | F15: =PR4_Al_EUR!F165 -> Aluminium | G15: technosphere
A16: =PR5_Al_ROE!A116 -> Al ingot production in Russia and rest-of-Europe | B16: =PR5_Al_ROE!B116 -> Al ingot | C16: =PR5_Al_ROE!C116 -> Russia and Rest-of-Europe | D16: 0.061429302 | E16: =PR5_Al_ROE!E116 -> kilogram | F16: =PR5_Al_ROE!F116 -> Aluminium | G16: technosphere
A17: =PR6_Al_GCC!A107 -> Al ingot production in Gulf Cooperation Council (GCC) countries | B17: =PR6_Al_GCC!B107 -> Al ingot | C17: =PR6_Al_GCC!C107 -> Gulf Cooperation Council (GCC) countries | D17: 0.078543933 | E17: =PR6_Al_GCC!E107 -> kilogram | F17: =PR6_Al_GCC!F107 -> Aluminium | G17: technosphere
A18: =PR7_Al_AFR!A96 -> Al ingot production in Africa | B18: =PR7_Al_AFR!B96 -> Al ingot | C18: =PR7_Al_AFR!C96 -> Africa | D18: 0.023727103 | E18: =PR7_Al_AFR!E96 -> kilogram | F18: =PR7_Al_AFR!F96 -> Aluminium | G18: technosphere
A19: =PR8_Al_OAS!A132 -> Al ingot production in rest-of-Asia | B19: =PR8_Al_OAS!B132 -> Al ingot | C19: =PR8_Al_OAS!C132 -> Rest-of-Asia | D19: 0.075821151 | E19: =PR8_Al_OAS!E132 -> kilogram | F19: =PR8_Al_OAS!F132 -> Aluminium | G19: technosphere
A20: =PR9_Al_CN!A167 -> Bauxite mining and Al ingot production in China | B20: =PR9_Al_CN!B167 -> Al ingot | C20: =PR9_Al_CN!C167 -> CN | D20: 0.49725506 | E20: =PR9_Al_CN!E167 -> kilogram | F20: =PR9_Al_CN!F167 -> Aluminium | G20: technosphere
A21: =PR10_Al_CN_Recycling!A40 -> Al production in China through Al scraps recycling | B21: =PR10_Al_CN_Recycling!B40 -> Al ingot | C21: =PR10_Al_CN_Recycling!C40 -> CN | D21: 0.094715249 | E21: =PR10_Al_CN_Recycling!E40 -> kilogram | F21: =PR10_Al_CN_Recycling!F40 -> Aluminium | G21: technosphere
A22: =PR11_Al_NAM_Recycling!A44 -> Al production in North America through Al scraps recycling | B22: =PR11_Al_NAM_Recycling!B44 -> Al ingot | C22: =PR11_Al_NAM_Recycling!C44 -> North America | D22: 0.010454531 | E22: =PR11_Al_NAM_Recycling!E44 -> kilogram | F22: =PR11_Al_NAM_Recycling!F44 -> Aluminium | G22: technosphere
A23: =PR12_Al_EUR_Recycling!A51 -> Al production in Europe through Al scraps recycling | B23: =PR12_Al_EUR_Recycling!B51 -> Al ingot | C23: =PR12_Al_EUR_Recycling!C51 -> Europe | D23: 0.0098009577 | E23: =PR12_Al_EUR_Recycling!E51 -> kilogram | F23: =PR12_Al_EUR_Recycling!F51 -> Aluminium | G23: technosphere

Sheet Al_Mining_GLO
A1: Activity | B1: [M+C] Bauxite mining - Global
A2: reference product | B2: Bauxite
A3: location | B3: GLO
A4: amount | B4: 1
A5: unit | B5: kilogram
A6: comment | B6: n/a
A7: Exchanges
A8: name | B8: reference product | C8: location | D8: amount | E8: unit | F8: database | G8: type | H8: categories | I8: uncertainty type | J8: pedigree | K8: loc | L8: scale | M8: minimum | N8: maximum
A9: =B1 -> [M+C] Bauxite mining - Global | B9: =B2 -> Bauxite | C9: =B3 -> GLO | D9: 1 | E9: kilogram | F9: =Al_Market_GLO!B1 -> Aluminium | G9: production
A10: market for heavy fuel oil | B10: heavy fuel oil | C10: RoW | D10: 0.00013648749 | E10: kilogram | F10: ecoinvent 3.10 cutoff | G10: technosphere | J10: (1,4,2,1,1)
A11: market for diesel, burned in building machine | B11: diesel, burned in building machine | C11: GLO | D11: 0.079353336 | E11: megajoule | F11: ecoinvent 3.10 cutoff | G11: technosphere | J11: (1,4,2,1,1)
A12: market group for natural gas, high pressure | B12: natural gas, high pressure | C12: GLO | D12: 2.7084316e-05 | E12: cubic meter | F12: ecoinvent 3.10 cutoff | G12: technosphere | J12: (1,4,2,1,1)
A13: market for hard coal briquettes | B13: hard coal briquettes | C13: RoW | D13: 0.021927162 | E13: megajoule | F13: ecoinvent 3.10 cutoff | G13: technosphere | J13: (1,4,2,1,1)
A14: market group for electricity, medium voltage | B14: electricity, medium voltage | C14: GLO | D14: 0.0063808964 | E14: kilowatt hour | F14: ecoinvent 3.10 cutoff | G14: technosphere | J14: (1,4,2,1,1)
A15: market for electricity, medium voltage, renewable energy products | B15: electricity, medium voltage, renewable energy products | C15: CH | D15: 1.7699132e-06 | E15: kilowatt hour | F15: ecoinvent 3.10 cutoff | G15: technosphere | J15: (1,4,2,1,1)
A16: market for inert waste, for final disposal | B16: inert waste, for final disposal | C16: RoW | D16: -6.2589073e-05 | E16: kilogram | F16: ecoinvent 3.10 cutoff | G16: technosphere | J16: (1,4,2,1,1)
A17: market for non-sulfidic overburden, off-site | B17: non-sulfidic overburden, off-site | C17: GLO | D17: -0.37627302 | E17: kilogram | F17: ecoinvent 3.10 cutoff | G17: technosphere | J17: (1,4,2,1,1)
A18: market for hazardous waste, for incineration | B18: hazardous waste, for incineration | C18: RoW | D18: -3.6413434e-05 | E18: kilogram | F18: ecoinvent 3.10 cutoff | G18: technosphere | J18: (1,4,2,1,1)
A19: Water, unspecified natural origin | D19: 0.00046917403 | E19: cubic meter | F19: biosphere3 | G19: biosphere | H19: natural resource::in ground | J19: (1,4,2,1,1)
A20: Water, salt, ocean | D20: 0.00025078697 | E20: cubic meter | F20: biosphere3 | G20: biosphere | H20: natural resource::in water | J20: (1,4,2,1,1)
A21: Water, unspecified natural origin | D21: 0.00066421594 | E21: cubic meter | F21: biosphere3 | G21: biosphere | H21: natural resource::in ground | J21: (1,4,2,1,1)
A22: Water, salt, ocean | D22: 1.2410904e-05 | E22: cubic meter | F22: biosphere3 | G22: biosphere | H22: natural resource::in water | J22: (1,4,2,1,1)
A23: Transformation, from forest, unspecified | D23: 0.00034245319 | E23: square meter | F23: biosphere3 | G23: biosphere | H23: natural resource::land | J23: (1,4,2,1,1)
A24: Transformation, to mineral extraction site | D24: 0.00034245319 | E24: square meter | F24: biosphere3 | G24: biosphere | H24: natural resource::land | J24: (1,4,2,1,1)
A25: Occupation, mineral extraction site | D25: 7.9250893e-11 | E25: square meter-year | F25: biosphere3 | G25: biosphere | H25: natural resource::land | J25: (1,5,2,1,1)
A26: Particulate Matter, > 2.5 um and < 10um | D26: 0.00017555274 | E26: kilogram | F26: biosphere3 | G26: biosphere | H26: air | J26: (1,4,2,1,1)
A27: Sulfur dioxide | D27: 1.3108487e-07 | E27: kilogram | F27: biosphere3 | G27: biosphere | H27: air | J27: (1,5,2,1,1)
A28: Nitrogen oxides | D28: 6.1064826e-05 | E28: kilogram | F28: biosphere3 | G28: biosphere | H28: air | J28: (1,4,2,1,1)
A29: Water | D29: 8.018378e-05 | E29: cubic meter | F29: biosphere3 | G29: biosphere | H29: water | J29: (1,4,2,1,1)
A30: Water | D30: 0.00023837606 | E30: cubic meter | F30: biosphere3 | G30: biosphere | H30: water::ocean | J30: (1,4,2,1,1)
A32: Activity | B32: [P] Alumina production - Global
A33: reference product | B33: Alumina
A34: location | B34: GLO
A35: amount | B35: 1
A36: unit | B36: kilogram
A37: comment | B37: n/a
A38: Exchanges
A39: name | B39: reference product | C39: location | D39: amount | E39: unit | F39: database | G39: type | H39: categories | I39: uncertainty type | J39: pedigree | K39: loc | L39: scale | M39: minimum | N39: maximum
A40: =B32 -> [P] Alumina production - Global | B40: =B33 -> Alumina | C40: =B34 -> GLO | D40: 1 | E40: kilogram | F40: =F9 -> Aluminium | G40: production
A41: market for transport, freight, sea, container ship | B41: transport, freight, sea, container ship | C41: GLO | D41: 4.3053047 | E41: ton kilometer | F41: ecoinvent 3.10 cutoff | G41: technosphere | J41: (1,4,2,1,1)
...

Sheet PR1_Al_SAM
A1: Activity | B1: [M+C] Bauxite mining
A2: reference product | B2: Bauxite
A3: location | B3: South America
A4: amount | B4: 1
A5: unit | B5: kilogram
A6: comment | B6: n/a
A7: Exchanges
A8: name | B8: reference product | C8: location | D8: amount | E8: unit | F8: database | G8: type | H8: categories | I8: uncertainty type | J8: pedigree | K8: loc | L8: scale | M8: minimum | N8: maximum
A9: =B1 -> [M+C] Bauxite mining | B9: =B2 -> Bauxite | C9: =B3 -> South America | D9: 1 | E9: kilogram | F9: =Al_Market_GLO!B1 -> Aluminium | G9: production
A10: market for heavy fuel oil | B10: heavy fuel oil | C10: RoW | D10: 0.00047314293 | E10: kilogram | F10: ecoinvent 3.10 cutoff | G10: technosphere | J10: (1,4,2,1,1)
A11: market for diesel, burned in building machine | B11: diesel, burned in building machine | C11: GLO | D11: 0.16483149 | E11: megajoule | F11: ecoinvent 3.10 cutoff | G11: technosphere | J11: (1,4,2,1,1)
A12: market for electricity, medium voltage, aluminium industry | B12: electricity, medium voltage, aluminium industry | C12: IAI Area, South America | D12: 0.0010637542 | E12: kilowatt hour | F12: ecoinvent 3.10 cutoff | G12: technosphere | J12: (1,4,2,1,1)
A13: market for inert waste, for final disposal | B13: inert waste, for final disposal | C13: RoW | D13: -0.00013643675 | E13: kilogram | F13: ecoinvent 3.10 cutoff | G13: technosphere | J13: (1,5,2,1,1)
A14: market for non-sulfidic overburden, off-site | B14: non-sulfidic overburden, off-site | C14: GLO | D14: -0.0069631169 | E14: kilogram | F14: ecoinvent 3.10 cutoff | G14: technosphere | J14: (1,5,2,1,1)
A15: market for hazardous waste, for incineration | B15: hazardous waste, for incineration | C15: RoW | D15: -3.1379562e-08 | E15: kilogram | F15: ecoinvent 3.10 cutoff | G15: technosphere | J15: (1,5,2,1,1)
A16: Water, unspecified natural origin | D16: 0.0010353374 | E16: cubic meter | F16: biosphere3 | G16: biosphere | H16: natural resource::in ground | J16: (1,4,2,1,1)
A17: Transformation, from forest, unspecified | D17: 0.0005135046 | E17: square meter | F17: biosphere3 | G17: biosphere | H17: natural resource::land | J17: (1,5,2,1,1)
A18: Transformation, to mineral extraction site | D18: 0.0005135046 | E18: square meter | F18: biosphere3 | G18: biosphere | H18: natural resource::land | J18: (1,5,2,1,1)
A19: Occupation, mineral extraction site | D19: 7.1195153e-10 | E19: square meter-year | F19: biosphere3 | G19: biosphere | H19: natural resource::land | J19: (1,5,2,1,1)
A20: Particulate Matter, > 2.5 um and < 10um | D20: 6.95042e-07 | E20: kilogram | F20: biosphere3 | G20: biosphere | H20: air | J20: (1,5,2,1,1)
A21: Sulfur dioxide | D21: 6.1187458e-07 | E21: kilogram | F21: biosphere3 | G21: biosphere | H21: air | J21: (1,5,2,1,1)
A22: Nitrogen oxides | D22: 0.00010297042 | E22: kilogram | F22: biosphere3 | G22: biosphere | H22: air | J22: (1,5,2,1,1)
A23: Water | D23: 0.00031550452 | E23: cubic meter | F23: biosphere3 | G23: biosphere | H23: water | J23: (1,5,2,1,1)
A25: Activity | B25: [P] Alumina production
A26: reference product | B26: Alumina
A27: location | B27: South America
A28: amount | B28: 1
A29: unit | B29: kilogram
A30: comment | B30: n/a
A31: Exchanges
A32: name | B32: reference product | C32: location | D32: amount | E32: unit | F32: database | G32: type | H32: categories | I32: uncertainty type | J32: pedigree | K32: loc | L32: scale | M32: minimum | N32: maximum
A33: =B25 -> [P] Alumina production | B33: =B26 -> Alumina | C33: =B27 -> South America | D33: 1 | E33: kilogram | F33: =F9 -> Aluminium | G33: production
A34: market for transport, freight, sea, container ship | B34: transport, freight, sea, container ship | C34: GLO | D34: 2.9048363 | E34: ton kilometer | F34: ecoinvent 3.10 cutoff | G34: technosphere | J34: (1,4,2,1,1)
A35: market for transport, freight, lorry >32 metric ton, EURO5 | B35: transport, freight, lorry >32 metric ton, EURO5 | C35: RoW | D35: 0.01034096 | E35: ton kilometer | F35: ecoinvent 3.10 cutoff | G35: technosphere | J35: (1,4,2,1,1)
A36: market for transport, freight train | B36: transport, freight train | C36: RoW | D36: 0.559626 | E36: ton kilometer | F36: ecoinvent 3.10 cutoff | G36: technosphere | J36: (1,4,2,1,1)
A37: market for sodium hydroxide, without water, in 50% solution state | B37: sodium hydroxide, without water, in 50% solution state | C37: RoW | D37: 0.099147693 | E37: kilogram | F37: ecoinvent 3.10 cutoff | G37: technosphere | J37: (1,4,2,1,1)
A38: market for lime, packed | B38: lime, packed | C38: RoW | D38: 0.01415097 | E38: kilogram | F38: ecoinvent 3.10 cutoff | G38: technosphere | J38: (1,4,2,1,1)
A39: market for heavy fuel oil | B39: heavy fuel oil | C39: RoW | D39: 0.10673362 | E39: kilogram | F39: ecoinvent 3.10 cutoff | G39: technosphere | J39: (1,2,2,1,1)
A40: market for diesel, burned in building machine | B40: diesel, burned in building machine | C40: GLO | D40: 0.0053720494 | E40: megajoule | F40: ecoinvent 3.10 cutoff | G40: technosphere | J40: (1,2,2,1,1)
A41: market for natural gas, high pressure | B41: natural gas, high pressure | C41: RoW | D41: 0.015190987 | E41: cubic meter | F41: ecoinvent 3.10 cutoff | G41: technosphere | J41: (1,2,2,1,1)
...

Sheet PR2_Al_OCA
A1: Activity | B1: [M+C] Bauxite mining
A2: reference product | B2: Bauxite
A3: location | B3: Oceania
A4: amount | B4: 1
A5: unit | B5: kilogram
A6: comment | B6: n/a
A7: Exchanges
A8: name | B8: reference product | C8: location | D8: amount | E8: unit | F8: database | G8: type | H8: categories | I8: uncertainty type | J8: pedigree | K8: loc | L8: scale | M8: minimum | N8: maximum
A9: =B1 -> [M+C] Bauxite mining | B9: =B2 -> Bauxite | C9: =B3 -> Oceania | D9: 1 | E9: kilogram | F9: =Al_Market_GLO!B1 -> Aluminium | G9: production
A10: market for diesel, burned in building machine | B10: diesel, burned in building machine | C10: GLO | D10: 0.06345037 | E10: megajoule | F10: ecoinvent 3.10 cutoff | G10: technosphere | J10: (1,1,2,1,1)
A11: market for natural gas, high pressure | B11: natural gas, high pressure | C11: AU | D11: 2.5998297e-06 | E11: cubic meter | F11: ecoinvent 3.10 cutoff | G11: technosphere | J11: (1,3,2,1,1)
A12: market for hard coal | B12: hard coal | C12: AU | D12: 0.00093132232 | E12: kilogram | F12: ecoinvent 3.10 cutoff | G12: technosphere | J12: (1,3,2,1,1)
A13: market for electricity, medium voltage | B13: electricity, medium voltage | C13: AU | D13: 0.0024285424 | E13: kilowatt hour | F13: ecoinvent 3.10 cutoff | G13: technosphere | J13: (1,2,2,1,1)
A14: market for electricity, medium voltage, renewable energy products | B14: electricity, medium voltage, renewable energy products | C14: CH | D14: 1.7699132e-06 | E14: kilowatt hour | F14: ecoinvent 3.10 cutoff | G14: technosphere | J14: (1,4,2,1,1)
A15: market for inert waste, for final disposal | B15: inert waste, for final disposal | C15: RoW | D15: -5.3851188e-05 | E15: kilogram | F15: ecoinvent 3.10 cutoff | G15: technosphere | J15: (1,2,2,1,1)
A16: market for non-sulfidic overburden, off-site | B16: non-sulfidic overburden, off-site | C16: GLO | D16: -0.060863169 | E16: kilogram | F16: ecoinvent 3.10 cutoff | G16: technosphere | J16: (1,2,2,1,1)
A17: market for hazardous waste, for incineration | B17: hazardous waste, for incineration | C17: RoW | D17: -1.7600897e-08 | E17: kilogram | F17: ecoinvent 3.10 cutoff | G17: technosphere | J17: (1,2,2,1,1)
A18: Water, unspecified natural origin | D18: 0.00045279913 | E18: cubic meter | F18: biosphere3 | G18: biosphere | H18: natural resource::in ground | J18: (1,1,2,1,1)
A19: Water, salt, ocean | D19: 0.00026184478 | E19: cubic meter | F19: biosphere3 | G19: biosphere | H19: natural resource::in water | J19: (1,1,2,1,1)
A20: Transformation, from forest, unspecified | D20: 0.00035847276 | E20: square meter | F20: biosphere3 | G20: biosphere | H20: natural resource::land | J20: (1,3,2,1,1)
A21: Transformation, to mineral extraction site | D21: 0.00035847276 | E21: square meter | F21: biosphere3 | G21: biosphere | H21: natural resource::land | J21: (1,3,2,1,1)
A22: Occupation, mineral extraction site | D22: 1.5304876e-10 | E22: square meter-year | F22: biosphere3 | G22: biosphere | H22: natural resource::land | J22: (1,3,2,1,1)
A23: Particulate Matter, > 2.5 um and < 10um | D23: 0.0001853825 | E23: kilogram | F23: biosphere3 | G23: biosphere | H23: air | J23: (1,1,2,1,1)
A24: Sulfur dioxide | D24: 1.7018011e-08 | E24: kilogram | F24: biosphere3 | G24: biosphere | H24: air | J24: (1,4,2,1,1)
A25: Nitrogen oxides | D25: 5.7675067e-05 | E25: kilogram | F25: biosphere3 | G25: biosphere | H25: air | J25: (1,2,2,1,1)
A26: Water, unspecified natural origin | D26: 9.1553345e-05 | E26: cubic meter | F26: biosphere3 | G26: biosphere | H26: water::in ground | J26: (1,1,2,1,1)
A27: Water | D27: 0.00026184478 | E27: cubic meter | F27: biosphere3 | G27: biosphere | H27: water::ocean | J27: (1,1,2,1,1)
A29: Activity | B29: [P] Alumina production
A30: reference product | B30: Alumina
A31: location | B31: Oceania
A32: amount | B32: 1
A33: unit | B33: kilogram
A34: comment | B34: n/a
A35: Exchanges
A36: name | B36: reference product | C36: location | D36: amount | E36: unit | F36: database | G36: type | H36: categories | I36: uncertainty type | J36: pedigree | K36: loc | L36: scale | M36: minimum | N36: maximum
A37: =B29 -> [P] Alumina production | B37: =B30 -> Alumina | C37: =B31 -> Oceania | D37: 1 | E37: kilogram | F37: =F9 -> Aluminium | G37: production
A38: market for transport, freight, sea, container ship | B38: transport, freight, sea, container ship | C38: GLO | D38: 1.24875 | E38: ton kilometer | F38: ecoinvent 3.10 cutoff | G38: technosphere | J38: (1,1,2,1,1)
A39: market for transport, freight train | B39: transport, freight train | C39: RoW | D39: 0.081 | E39: ton kilometer | F39: ecoinvent 3.10 cutoff | G39: technosphere | J39: (1,1,2,1,1)
A40: market for sodium hydroxide, without water, in 50% solution state | B40: sodium hydroxide, without water, in 50% solution state | C40: RoW | D40: 0.075376882 | E40: kilogram | F40: ecoinvent 3.10 cutoff | G40: technosphere | J40: (1,1,2,1,1)
A41: market for lime, packed | B41: lime, packed | C41: RoW | D41: 0.042381483 | E41: kilogram | F41: ecoinvent 3.10 cutoff | G41: technosphere | J41: (1,1,2,1,1)
...

Sheet PR3_Al_NAM
A1: Activity | B1: [P] Alumina production
A2: reference product | B2: Alumina
A3: location | B3: North America
A4: amount | B4: 1
A5: unit | B5: kilogram
A6: comment | B6: n/a
A7: Exchanges
A8: name | B8: reference product | C8: location | D8: amount | E8: unit | F8: database | G8: type | H8: categories | I8: uncertainty type | J8: pedigree | K8: loc | L8: scale | M8: minimum | N8: maximum
A9: =B1 -> [P] Alumina production | B9: =B2 -> Alumina | C9: =B3 -> North America | D9: 1 | E9: kilogram | F9: =Al_Market_GLO!B1 -> Aluminium | G9: production
A10: market for transport, freight, sea, container ship | B10: transport, freight, sea, container ship | C10: GLO | D10: 6.75 | E10: ton kilometer | F10: ecoinvent 3.10 cutoff | G10: technosphere | J10: (1,3,2,1,1)
A11: market for transport, freight train | B11: transport, freight train | C11: RoW | D11: 0.6742 | E11: ton kilometer | F11: ecoinvent 3.10 cutoff | G11: technosphere | J11: (1,3,2,1,1)
A12: market for sodium hydroxide, without water, in 50% solution state | B12: sodium hydroxide, without water, in 50% solution state | C12: RoW | D12: 0.063354952 | E12: kilogram | F12: ecoinvent 3.10 cutoff | G12: technosphere | J12: (1,3,2,1,1)
A13: market for lime, packed | B13: lime, packed | C13: RoW | D13: 0.022056793 | E13: kilogram | F13: ecoinvent 3.10 cutoff | G13: technosphere | J13: (1,3,2,1,1)
A14: market for heavy fuel oil | B14: heavy fuel oil | C14: RoW | D14: 2.3809524e-05 | E14: kilogram | F14: ecoinvent 3.10 cutoff | G14: technosphere | J14: (1,3,2,1,1)
A15: market for natural gas, high pressure | B15: natural gas, high pressure | C15: RoW | D15: 0.10103498 | E15: cubic meter | F15: ecoinvent 3.10 cutoff | G15: technosphere | J15: (1,3,2,1,1)
A16: market group for electricity, medium voltage | B16: electricity, medium voltage | C16: RNA | D16: 0.62167703 | E16: kilowatt hour | F16: ecoinvent 3.10 cutoff | G16: technosphere | J16: (1,3,2,1,1)
A17: market for electricity, medium voltage, renewable energy products | B17: electricity, medium voltage, renewable energy products | C17: CH | D17: 0.27898852 | E17: kilowatt hour | F17: ecoinvent 3.10 cutoff | G17: technosphere | J17: (1,3,2,1,1)
A18: market for redmud from bauxite digestion | B18: redmud from bauxite digestion | C18: RoW | D18: -0.78446597 | E18: kilogram | F18: ecoinvent 3.10 cutoff | G18: technosphere | J18: (1,1,2,1,1)
A19: market for inert waste, for final disposal | B19: inert waste, for final disposal | C19: RoW | D19: -0.00012031168 | E19: kilogram | F19: ecoinvent 3.10 cutoff | G19: technosphere | J19: (1,3,2,1,1)
A20: market for hazardous waste, for incineration | B20: hazardous waste, for incineration | C20: RoW | D20: -0.00012031168 | E20: kilogram | F20: ecoinvent 3.10 cutoff | G20: technosphere | J20: (1,3,2,1,1)
A21: Water, unspecified natural origin | D21: 0.010367786 | E21: cubic meter | F21: biosphere3 | G21: biosphere | H21: natural resource::in ground | J21: (1,3,2,1,1)
A22: Transformation, from forest, unspecified | D22: 0.0013342017 | E22: square meter | F22: biosphere3 | G22: biosphere | H22: natural resource::land | J22: (1,1,2,1,1)
A23: Transformation, to mineral extraction site | D23: 0.0013342017 | E23: square meter | F23: biosphere3 | G23: biosphere | H23: natural resource::land | J23: (1,1,2,1,1)
A24: Occupation, mineral extraction site | D24: 5.1185615e-08 | E24: square meter-year | F24: biosphere3 | G24: biosphere | H24: natural resource::land | J24: (1,3,2,1,1)
A25: Particulate Matter, > 2.5 um and < 10um | D25: 4.8095182e-05 | E25: kilogram | F25: biosphere3 | G25: biosphere | H25: air | J25: (1,3,2,1,1)
A26: Sulfur dioxide | D26: 5.0011107e-07 | E26: kilogram | F26: biosphere3 | G26: biosphere | H26: air | J26: (1,3,2,1,1)
A27: Nitrogen oxides | D27: 0.00015518204 | E27: kilogram | F27: biosphere3 | G27: biosphere | H27: air | J27: (1,3,2,1,1)
A28: Water | D28: 0.010630885 | E28: cubic meter | F28: biosphere3 | G28: biosphere | H28: water | J28: (1,3,2,1,1)
A29: Suspended solids, unspecified | D29: 6.5264587e-05 | E29: kilogram | F29: biosphere3 | G29: biosphere | H29: water | J29: (1,3,2,1,1)
A30: Hydrocarbons, unspecified | D30: 0.011412344 | E30: kilogram | F30: biosphere3 | G30: biosphere | H30: water | J30: (1,3,2,1,1)
A31: Mercury II | D31: 1.6841201e-09 | E31: kilogram | F31: biosphere3 | G31: biosphere | H31: water | J31: (1,3,2,1,1)
A33: Activity | B33: [P] Anode/Paste production
A34: reference product | B34: Anode/Paste
A35: location | B35: North America
A36: amount | B36: 1
A37: unit | B37: kilogram
A38: comment | B38: n/a
A39: Exchanges
A40: name | B40: reference product | C40: location | D40: amount | E40: unit | F40: database | G40: type | H40: categories | I40: uncertainty type | J40: pedigree | K40: loc | L40: scale | M40: minimum | N40: maximum
A41: =B33 -> [P] Anode/Paste production | B41: =B34 -> Anode/Paste | C41: =B35 -> North America | D41: 1 | E41: kilogram | F41: =F9 -> Aluminium | G41: production
...

Sheet PR4_Al_EUR
A1: Activity | B1: [P] Alumina production
A2: reference product | B2: Alumina
A3: location | B3: Europe
A4: amount | B4: 1
A5: unit | B5: kilogram
A6: comment | B6: n/a
A7: Exchanges
A8: name | B8: reference product | C8: location | D8: amount | E8: unit | F8: database | G8: type | H8: categories | I8: uncertainty type | J8: pedigree | K8: loc | L8: scale | M8: minimum | N8: maximum
A9: =B1 -> [P] Alumina production | B9: =B2 -> Alumina | C9: =B3 -> Europe | D9: 1 | E9: kilogram | F9: =Al_Market_GLO!B1 -> Aluminium | G9: production
A10: market for transport, freight, sea, container ship | B10: transport, freight, sea, container ship | C10: GLO | D10: 5.7400452 | E10: ton kilometer | F10: ecoinvent 3.10 cutoff | G10: technosphere | J10: (1,2,2,1,1)
A11: market for sodium hydroxide, without water, in 50% solution state | B11: sodium hydroxide, without water, in 50% solution state | C11: RER | D11: 0.074898814 | E11: kilogram | F11: ecoinvent 3.10 cutoff | G11: technosphere | J11: (1,2,2,1,1)
A12: market for lime, packed | B12: lime, packed | C12: Europe without Switzerland | D12: 0.021731379 | E12: kilogram | F12: ecoinvent 3.10 cutoff | G12: technosphere | J12: (1,2,2,1,1)
A13: market for heavy fuel oil | B13: heavy fuel oil | C13: Europe without Switzerland | D13: 0.00079847753 | E13: kilogram | F13: ecoinvent 3.10 cutoff | G13: technosphere | J13: (1,1,2,1,1)
A14: market for diesel, burned in building machine | B14: diesel, burned in building machine | C14: GLO | D14: 0.011760551 | E14: megajoule | F14: ecoinvent 3.10 cutoff | G14: technosphere | J14: (1,1,2,1,1)
A15: market group for natural gas, high pressure | B15: natural gas, high pressure | C15: Europe without Switzerland | D15: 0.23946015 | E15: cubic meter | F15: ecoinvent 3.10 cutoff | G15: technosphere | J15: (1,1,2,1,1)
A16: market group for electricity, medium voltage | B16: electricity, medium voltage | C16: RER | D16: 0.15250676 | E16: kilowatt hour | F16: ecoinvent 3.10 cutoff | G16: technosphere | J16: (1,1,2,1,1)
A17: market for electricity, medium voltage, renewable energy products | B17: electricity, medium voltage, renewable energy products | C17: CH | D17: 0.009425938 | E17: kilowatt hour | F17: ecoinvent 3.10 cutoff | G17: technosphere | J17: (1,1,2,1,1)
A18: market for inert waste, for final disposal | B18: inert waste, for final disposal | C18: RoW | D18: -0.029046159 | E18: kilogram | F18: ecoinvent 3.10 cutoff | G18: technosphere | J18: (1,3,2,1,1)
A19: market for redmud from bauxite digestion | B19: redmud from bauxite digestion | C19: RER | D19: -0.84690458 | E19: kilogram | F19: ecoinvent 3.10 cutoff | G19: technosphere | J19: (1,1,2,1,1)
A20: market for inert waste, for final disposal | B20: inert waste, for final disposal | C20: RoW | D20: -0.063879387 | E20: kilogram | F20: ecoinvent 3.10 cutoff | G20: technosphere | J20: (1,2,2,1,1)
A21: market for hazardous waste, for incineration | B21: hazardous waste, for incineration | C21: Europe without Switzerland | D21: -0.0049821883 | E21: kilogram | F21: ecoinvent 3.10 cutoff | G21: technosphere | J21: (1,2,2,1,1)
A22: Water, unspecified natural origin | D22: 0.0035184161 | E22: cubic meter | F22: biosphere3 | G22: biosphere | H22: natural resource::in ground | J22: (1,2,2,1,1)
A23: Transformation, from pasture, man made | D23: 0.00067471209 | E23: square meter | F23: biosphere3 | G23: biosphere | H23: natural resource::land | J23: (1,1,2,1,1)
A24: Transformation, to mineral extraction site | D24: 0.00067471209 | E24: square meter | F24: biosphere3 | G24: biosphere | H24: natural resource::land | J24: (1,1,2,1,1)
A25: Occupation, mineral extraction site | D25: 1.014241e-08 | E25: square meter-year | F25: biosphere3 | G25: biosphere | H25: natural resource::land | J25: (1,2,2,1,1)
A26: Particulate Matter, > 2.5 um and < 10um | D26: 2.6185527e-05 | E26: kilogram | F26: biosphere3 | G26: biosphere | H26: air | J26: (1,2,2,1,1)
A27: Sulfur dioxide | D27: 1.1867932e-05 | E27: kilogram | F27: biosphere3 | G27: biosphere | H27: air | J27: (1,2,2,1,1)
A28: Nitrogen oxides | D28: 0.00024491456 | E28: kilogram | F28: biosphere3 | G28: biosphere | H28: air | J28: (1,2,2,1,1)
A29: Water | D29: 0.0035747964 | E29: cubic meter | F29: biosphere3 | G29: biosphere | H29: water | J29: (1,2,2,1,1)
A30: Suspended solids, unspecified | D30: 0.0002329033 | E30: kilogram | F30: biosphere3 | G30: biosphere | H30: water | J30: (1,2,2,1,1)
A32: Activity | B32: [P] Anode/Paste production
A33: reference product | B33: Anode/Paste
A34: location | B34: Europe
A35: amount | B35: 1
A36: unit | B36: kilogram
A37: comment | B37: n/a
A38: Exchanges
A39: name | B39: reference product | C39: location | D39: amount | E39: unit | F39: database | G39: type | H39: categories | I39: uncertainty type | J39: pedigree | K39: loc | L39: scale | M39: minimum | N39: maximum
A40: =B32 -> [P] Anode/Paste production | B40: =B33 -> Anode/Paste | C40: =B34 -> Europe | D40: 1 | E40: kilogram | F40: =F9 -> Aluminium | G40: production
A41: market for petroleum coke | B41: petroleum coke | C41: GLO | D41: 0.9501309 | E41: kilogram | F41: ecoinvent 3.10 cutoff | G41: technosphere | J41: (1,4,2,1,1)
...

Sheet PR5_Al_ROE
A1: Activity | B1: [P] Alumina production
A2: reference product | B2: Alumina
A3: location | B3: Russia and Rest-of-Europe
A4: amount | B4: 1
A5: unit | B5: kilogram
A6: comment | B6: n/a
A7: Exchanges
A8: name | B8: reference product | C8: location | D8: amount | E8: unit | F8: database | G8: type | H8: categories | I8: uncertainty type | J8: pedigree | K8: loc | L8: scale | M8: minimum | N8: maximum
A9: =B1 -> [P] Alumina production | B9: =B2 -> Alumina | C9: =B3 -> Russia and Rest-of-Europe | D9: 1 | E9: kilogram | F9: =Al_Market_GLO!B1 -> Aluminium | G9: production
A10: market for transport, freight, sea, container ship | B10: transport, freight, sea, container ship | C10: GLO | D10: 8.53653 | E10: ton kilometer | F10: ecoinvent 3.10 cutoff | G10: technosphere | J10: (1,2,2,1,1)
A11: market for transport, freight train | B11: transport, freight train | C11: Europe without Switzerland | D11: 1.2288749 | E11: ton kilometer | F11: ecoinvent 3.10 cutoff | G11: technosphere | J11: (1,2,2,1,1)
A12: market for sodium hydroxide, without water, in 50% solution state | B12: sodium hydroxide, without water, in 50% solution state | C12: RER | D12: 0.052065849 | E12: kilogram | F12: ecoinvent 3.10 cutoff | G12: technosphere | J12: (1,2,2,1,1)
A13: market for lime, packed | B13: lime, packed | C13: Europe without Switzerland | D13: 0.088496503 | E13: kilogram | F13: ecoinvent 3.10 cutoff | G13: technosphere | J13: (1,2,2,1,1)
A14: market for natural gas, high pressure | B14: natural gas, high pressure | C14: RoE | D14: 0.35226648 | E14: cubic meter | F14: ecoinvent 3.10 cutoff | G14: technosphere | J14: (1,2,2,1,1)
A15: market group for electricity, medium voltage | B15: electricity, medium voltage | C15: RER | D15: 0.13314007 | E15: kilowatt hour | F15: ecoinvent 3.10 cutoff | G15: technosphere | J15: (1,2,2,1,1)
A16: market for electricity, medium voltage, renewable energy products | B16: electricity, medium voltage, renewable energy products | C16: CH | D16: 0.00065116074 | E16: kilowatt hour | F16: ecoinvent 3.10 cutoff | G16: technosphere | J16: (1,2,2,1,1)
A17: market for redmud from bauxite digestion | B17: redmud from bauxite digestion | C17: RER | D17: -0.02840717 | E17: kilogram | F17: ecoinvent 3.10 cutoff | G17: technosphere | J17: (1,3,2,1,1)
A18: market for inert waste, for final disposal | B18: inert waste, for final disposal | C18: RoW | D18: -0.041387957 | E18: kilogram | F18: ecoinvent 3.10 cutoff | G18: technosphere | J18: (1,2,2,1,1)
A19: market for redmud from bauxite digestion | B19: redmud from bauxite digestion | C19: RER | D19: -1.3563756 | E19: kilogram | F19: ecoinvent 3.10 cutoff | G19: technosphere | J19: (1,3,2,1,1)
A20: market for inert waste | B20: inert waste | C20: RoW | D20: -0.039536387 | E20: kilogram | F20: ecoinvent 3.10 cutoff | G20: technosphere | J20: (1,2,2,1,1)
A21: market for hazardous waste, for incineration | B21: hazardous waste, for incineration | C21: Europe without Switzerland | D21: -0.034761689 | E21: kilogram | F21: ecoinvent 3.10 cutoff | G21: technosphere | J21: (1,2,2,1,1)
A22: Water, unspecified natural origin | D22: 0.016650079 | E22: cubic meter | F22: biosphere3 | G22: biosphere | H22: natural resource::in ground | J22: (1,2,2,1,1)
A23: Water, unspecified natural origin | D23: 0.0076731597 | E23: cubic meter | F23: biosphere3 | G23: biosphere | H23: natural resource::in ground | J23: (1,2,2,1,1)
A24: Transformation, from forest, unspecified | D24: 0.0019471442 | E24: square meter | F24: biosphere3 | G24: biosphere | H24: natural resource::land | J24: (1,1,2,1,1)
A25: Transformation, to mineral extraction site | D25: 0.0019471442 | E25: square meter | F25: biosphere3 | G25: biosphere | H25: natural resource::land | J25: (1,1,2,1,1)
A26: Occupation, mineral extraction site | D26: 4.0839522e-08 | E26: square meter-year | F26: biosphere3 | G26: biosphere | H26: natural resource::land | J26: (1,1,2,1,1)
A27: Particulate Matter, > 2.5 um and < 10um | D27: 0.00028297563 | E27: kilogram | F27: biosphere3 | G27: biosphere | H27: air | J27: (1,2,2,1,1)
A28: Sulfur dioxide | D28: 4.3340026e-06 | E28: kilogram | F28: biosphere3 | G28: biosphere | H28: air | J28: (1,2,2,1,1)
A29: Nitrogen oxides | D29: 0.00026164749 | E29: kilogram | F29: biosphere3 | G29: biosphere | H29: air | J29: (1,2,2,1,1)
A30: Water | D30: 0.0090996818 | E30: cubic meter | F30: biosphere3 | G30: biosphere | H30: water | J30: (1,2,2,1,1)
A31: Suspended solids, unspecified | D31: 2.2754341e-05 | E31: kilogram | F31: biosphere3 | G31: biosphere | H31: water | J31: (1,2,2,1,1)
A32: Hydrocarbons, unspecified | D32: 0.00021532163 | E32: kilogram | F32: biosphere3 | G32: biosphere | H32: water | J32: (1,2,2,1,1)
A34: Activity | B34: [P] Anode/Paste production
A35: reference product | B35: Anode/Paste
A36: location | B36: Russia and Rest-of-Europe
A37: amount | B37: 1
A38: unit | B38: kilogram
A39: comment | B39: n/a
A40: Exchanges
A41: name | B41: reference product | C41: location | D41: amount | E41: unit | F41: database | G41: type | H41: categories | I41: uncertainty type | J41: pedigree | K41: loc | L41: scale | M41: minimum | N41: maximum
...

Sheet PR6_Al_GCC
A1: Activity | B1: [P] Anode/Paste production
A2: reference product | B2: Anode/Paste
A3: location | B3: Gulf Cooperation Council (GCC) countries
A4: amount | B4: 1
A5: unit | B5: kilogram
A6: comment | B6: n/a
A7: Exchanges
A8: name | B8: reference product | C8: location | D8: amount | E8: unit | F8: database | G8: type | H8: categories | I8: uncertainty type | J8: pedigree | K8: loc | L8: scale | M8: minimum | N8: maximum
A9: =B1 -> [P] Anode/Paste production | B9: =B2 -> Anode/Paste | C9: =B3 -> Gulf Cooperation Council (GCC) countries | D9: 1 | E9: kilogram | F9: =Al_Market_GLO!B1 -> Aluminium | G9: production
A10: market for petroleum coke | B10: petroleum coke | C10: GLO | D10: 0.87138955 | E10: kilogram | F10: ecoinvent 3.10 cutoff | G10: technosphere | J10: (1,1,2,1,1)
A11: market for pitch | B11: pitch | C11: RoW | D11: 0.13900171 | E11: kilogram | F11: ecoinvent 3.10 cutoff | G11: technosphere | J11: (1,1,2,1,1)
A12: market for refractory, high aluminium oxide, packed | B12: refractory, high aluminium oxide, packed | C12: GLO | D12: 0.00081716007 | E12: kilogram | F12: ecoinvent 3.10 cutoff | G12: technosphere | J12: (1,3,2,1,1)
A13: market for steel, low-alloyed | B13: steel, low-alloyed | C13: GLO | D13: 0.0031437047 | E13: kilogram | F13: ecoinvent 3.10 cutoff | G13: technosphere | J13: (1,5,2,1,1)
A14: market for natural gas, high pressure | B14: natural gas, high pressure | C14: RoW | D14: 0.064112962 | E14: cubic meter | F14: ecoinvent 3.10 cutoff | G14: technosphere | J14: (1,1,2,1,1)
A15: market for electricity, medium voltage, aluminium industry | B15: electricity, medium voltage, aluminium industry | C15: IAI Area, Gulf Cooperation Council | D15: 0.022908335 | E15: kilowatt hour | F15: ecoinvent 3.10 cutoff | G15: technosphere | J15: (1,1,2,1,1)
A16: market for refractory spent pot liner from Al electrolysis | B16: refractory spent pot liner from Al electrolysis | C16: RoW | D16: -6.4577558e-05 | E16: kilogram | F16: ecoinvent 3.10 cutoff | G16: technosphere | J16: (1,2,2,1,1)
A17: treatment of scrap steel, inert material landfill | B17: scrap steel | C17: RoW | D17: -0.00014343283 | E17: kilogram | F17: ecoinvent 3.10 cutoff | G17: technosphere | J17: (1,4,2,1,1)
A18: market for spent pot liner from Al electrolysis, carbon fraction | B18: spent pot liner from Al electrolysis, carbon fraction | C18: RoW | D18: -0.0047778914 | E18: kilogram | F18: ecoinvent 3.10 cutoff | G18: technosphere | J18: (1,3,2,1,1)
A19: market for refractory spent pot liner from Al electrolysis | B19: refractory spent pot liner from Al electrolysis | C19: RoW | D19: -0.0016966146 | E19: kilogram | F19: ecoinvent 3.10 cutoff | G19: technosphere | J19: (1,3,2,1,1)
A20: Particulate Matter, > 2.5 um and < 10um | D20: 0.00034964449 | E20: kilogram | F20: biosphere3 | G20: biosphere | H20: air | J20: (1,2,2,1,1)
A21: Sulfur dioxide | D21: 0.00068948675 | E21: kilogram | F21: biosphere3 | G21: biosphere | H21: air | J21: (1,2,2,1,1)
A22: Nitrogen oxides | D22: 0.00022673956 | E22: kilogram | F22: biosphere3 | G22: biosphere | H22: air | J22: (1,2,2,1,1)
A23: Fluoride | D23: 2.9677977e-07 | E23: kilogram | F23: biosphere3 | G23: biosphere | H23: air | J23: (1,2,2,1,1)
A24: Fluoride | D24: 2.9335963e-05 | E24: kilogram | F24: biosphere3 | G24: biosphere | H24: air | J24: (1,2,2,1,1)
A25: PAH, polycyclic aromatic hydrocarbons | D25: 2.0235908e-05 | E25: kilogram | F25: biosphere3 | G25: biosphere | H25: air | J25: (1,2,2,1,1)
A26: Benzo(a)pyrene | D26: 2.2185095e-08 | E26: kilogram | F26: biosphere3 | G26: biosphere | H26: air | J26: (1,4,2,1,1)
A27: Hydrocarbons, unspecified | D27: 7.3602187e-05 | E27: kilogram | F27: biosphere3 | G27: biosphere | H27: water | J27: (1,4,2,1,1)
A29: Activity | B29: [R] Electrolysis
A30: reference product | B30: Liquid aluminium (Al)
A31: location | B31: Gulf Cooperation Council (GCC) countries
A32: amount | B32: 1
A33: unit | B33: kilogram
A34: comment | B34: n/a
A35: Exchanges
A36: name | B36: reference product | C36: location | D36: amount | E36: unit | F36: database | G36: type | H36: categories | I36: uncertainty type | J36: pedigree | K36: loc | L36: scale | M36: minimum | N36: maximum
A37: =B29 -> [R] Electrolysis | B37: =B30 -> Liquid aluminium (Al) | C37: =B31 -> Gulf Cooperation Council (GCC) countries | D37: 1 | E37: kilogram | F37: =F9 -> Aluminium | G37: production
A38: market for transport, freight, sea, container ship | B38: transport, freight, sea, container ship | C38: GLO | D38: 20.027574 | E38: ton kilometer | F38: ecoinvent 3.10 cutoff | G38: technosphere | J38: (1,2,2,1,1)
A39: market for transport, freight, lorry >32 metric ton, EURO5 | B39: transport, freight, lorry >32 metric ton, EURO5 | C39: RoW | D39: 0.0011591252 | E39: ton kilometer | F39: ecoinvent 3.10 cutoff | G39: technosphere | J39: (1,2,2,1,1)
A40: market for refractory, high aluminium oxide, packed | B40: refractory, high aluminium oxide, packed | C40: GLO | D40: 0.0052230474 | E40: kilogram | F40: ecoinvent 3.10 cutoff | G40: technosphere | J40: (1,2,2,1,1)
A41: market for steel, low-alloyed | B41: steel, low-alloyed | C41: GLO | D41: 0.0046287583 | E41: kilogram | F41: ecoinvent 3.10 cutoff | G41: technosphere | J41: (1,2,2,1,1)
...

Sheet PR7_Al_AFR
A1: Activity | B1: [P] Anode/Paste production
A2: reference product | B2: Anode/Paste
A3: location | B3: Africa
A4: amount | B4: 1
A5: unit | B5: kilogram
A6: comment | B6: n/a
A7: Exchanges
A8: name | B8: reference product | C8: location | D8: amount | E8: unit | F8: database | G8: type | H8: categories | I8: uncertainty type | J8: pedigree | K8: loc | L8: scale | M8: minimum | N8: maximum
A9: =B1 -> [P] Anode/Paste production | B9: =B2 -> Anode/Paste | C9: =B3 -> Africa | D9: 1 | E9: kilogram | F9: =Al_Market_GLO!B1 -> Aluminium | G9: production
A10: market for petroleum coke | B10: petroleum coke | C10: GLO | D10: 1.4079478 | E10: kilogram | F10: ecoinvent 3.10 cutoff | G10: technosphere | J10: (1,2,2,1,1)
A11: market for pitch | B11: pitch | C11: RoW | D11: 0.22526058 | E11: kilogram | F11: ecoinvent 3.10 cutoff | G11: technosphere | J11: (1,2,2,1,1)
A12: market for refractory, high aluminium oxide, packed | B12: refractory, high aluminium oxide, packed | C12: GLO | D12: 0.0027116871 | E12: kilogram | F12: ecoinvent 3.10 cutoff | G12: technosphere | J12: (1,4,2,1,1)
A13: market for steel, low-alloyed | B13: steel, low-alloyed | C13: GLO | D13: 0.0032625227 | E13: kilogram | F13: ecoinvent 3.10 cutoff | G13: technosphere | J13: (1,4,2,1,1)
A14: market for natural gas, high pressure | B14: natural gas, high pressure | C14: RoW | D14: 0.097697569 | E14: cubic meter | F14: ecoinvent 3.10 cutoff | G14: technosphere | J14: (1,2,2,1,1)
A15: market for electricity, medium voltage, aluminium industry | B15: electricity, medium voltage, aluminium industry | C15: IAI Area, Africa | D15: 0.17191349 | E15: kilowatt hour | F15: ecoinvent 3.10 cutoff | G15: technosphere | J15: (1,2,2,1,1)
A16: market for refractory spent pot liner from Al electrolysis | B16: refractory spent pot liner from Al electrolysis | C16: RoW | D16: -0.006437782 | E16: kilogram | F16: ecoinvent 3.10 cutoff | G16: technosphere | J16: (1,2,2,1,1)
A17: treatment of scrap steel, inert material landfill | B17: scrap steel | C17: RoW | D17: -0.00030251291 | E17: kilogram | F17: ecoinvent 3.10 cutoff | G17: technosphere | J17: (1,2,2,1,1)
A18: market for inert waste, for final disposal | B18: inert waste, for final disposal | C18: RoW | D18: -0.00071364807 | E18: kilogram | F18: ecoinvent 3.10 cutoff | G18: technosphere | J18: (1,2,2,1,1)
A19: market for spent pot liner from Al electrolysis, carbon fraction | B19: spent pot liner from Al electrolysis, carbon fraction | C19: RoW | D19: -0.0031449056 | E19: kilogram | F19: ecoinvent 3.10 cutoff | G19: technosphere | J19: (1,2,2,1,1)
A20: market for fly ash and scrubber sludge | B20: fly ash and scrubber sludge | C20: RoW | D20: -0.00033985002 | E20: kilogram | F20: ecoinvent 3.10 cutoff | G20: technosphere | J20: (1,2,2,1,1)
A21: market for inert waste, for final disposal | B21: inert waste, for final disposal | C21: RoW | D21: -0.0034577623 | E21: kilogram | F21: ecoinvent 3.10 cutoff | G21: technosphere | J21: (1,2,2,1,1)
A22: market for hazardous waste, for underground deposit | B22: hazardous waste, for underground deposit | C22: RoW | D22: -0.0028797073 | E22: kilogram | F22: ecoinvent 3.10 cutoff | G22: technosphere | J22: (1,2,2,1,1)
A23: Water, unspecified natural origin | D23: 1.3248304e-05 | E23: cubic meter | F23: biosphere3 | G23: biosphere | H23: natural resource::in ground | J23: (1,4,2,1,1)
A24: Water, unspecified natural origin | D24: 1.3248304e-05 | E24: cubic meter | F24: biosphere3 | G24: biosphere | H24: natural resource::in ground | J24: (1,4,2,1,1)
A25: Particulate Matter, > 2.5 um and < 10um | D25: 0.0010697215 | E25: kilogram | F25: biosphere3 | G25: biosphere | H25: air | J25: (1,4,2,1,1)
A26: Sulfur dioxide | D26: 0.0011686695 | E26: kilogram | F26: biosphere3 | G26: biosphere | H26: air | J26: (1,4,2,1,1)
A27: Nitrogen oxides | D27: 0.0024792469 | E27: kilogram | F27: biosphere3 | G27: biosphere | H27: air | J27: (1,4,2,1,1)
A28: Fluoride | D28: 1.0560826e-05 | E28: kilogram | F28: biosphere3 | G28: biosphere | H28: air | J28: (1,4,2,1,1)
A30: Activity | B30: [R] Electrolysis
A31: reference product | B31: Liquid aluminium (Al)
A32: location | B32: Africa
A33: amount | B33: 1
A34: unit | B34: kilogram
A35: comment | B35: n/a
A36: Exchanges
A37: name | B37: reference product | C37: location | D37: amount | E37: unit | F37: database | G37: type | H37: categories | I37: uncertainty type | J37: pedigree | K37: loc | L37: scale | M37: minimum | N37: maximum
A38: =B30 -> [R] Electrolysis | B38: =B31 -> Liquid aluminium (Al) | C38: =B32 -> Africa | D38: 1 | E38: kilogram | F38: =F9 -> Aluminium | G38: production
A39: market for transport, freight, sea, container ship | B39: transport, freight, sea, container ship | C39: GLO | D39: 8.4544284 | E39: ton kilometer | F39: ecoinvent 3.10 cutoff | G39: technosphere | J39: (1,2,2,1,1)
A40: market for transport, freight, lorry >32 metric ton, EURO5 | B40: transport, freight, lorry >32 metric ton, EURO5 | C40: RoW | D40: 0.059908727 | E40: ton kilometer | F40: ecoinvent 3.10 cutoff | G40: technosphere | J40: (1,2,2,1,1)
A41: market for refractory, high aluminium oxide, packed | B41: refractory, high aluminium oxide, packed | C41: GLO | D41: 0.0068669213 | E41: kilogram | F41: ecoinvent 3.10 cutoff | G41: technosphere | J41: (1,4,2,1,1)
...

Sheet PR8_Al_OAS
A1: Activity | B1: [P] Alumina production
A2: reference product | B2: Alumina
A3: location | B3: Rest-of-Asia
A4: amount | B4: 1
A5: unit | B5: kilogram
A6: comment | B6: n/a
A7: Exchanges
A8: name | B8: reference product | C8: location | D8: amount | E8: unit | F8: database | G8: type | H8: categories | I8: uncertainty type | J8: pedigree | K8: loc | L8: scale | M8: minimum | N8: maximum
A9: =B1 -> [P] Alumina production | B9: =B2 -> Alumina | C9: =B3 -> Rest-of-Asia | D9: 1 | E9: kilogram | F9: =Al_Market_GLO!B1 -> Aluminium | G9: production
A10: market for transport, freight, lorry >32 metric ton, EURO5 | B10: transport, freight, lorry >32 metric ton, EURO5 | C10: RoW | D10: 0.035 | E10: ton kilometer | F10: ecoinvent 3.10 cutoff | G10: technosphere | J10: (1,4,2,1,1)
A11: market for sodium hydroxide, without water, in 50% solution state | B11: sodium hydroxide, without water, in 50% solution state | C11: RoW | D11: 0.085934698 | E11: kilogram | F11: ecoinvent 3.10 cutoff | G11: technosphere | J11: (1,4,2,1,1)
A12: market for lime, packed | B12: lime, packed | C12: RoW | D12: 0.078255821 | E12: kilogram | F12: ecoinvent 3.10 cutoff | G12: technosphere | J12: (1,5,2,1,1)
A13: market for heavy fuel oil | B13: heavy fuel oil | C13: RoW | D13: 0.047525725 | E13: kilogram | F13: ecoinvent 3.10 cutoff | G13: technosphere | J13: (1,4,2,1,1)
A14: market for diesel, burned in building machine | B14: diesel, burned in building machine | C14: GLO | D14: 0.0031981712 | E14: megajoule | F14: ecoinvent 3.10 cutoff | G14: technosphere | J14: (1,4,2,1,1)
A15: market for natural gas, high pressure | B15: natural gas, high pressure | C15: RoW | D15: 0.0061330392 | E15: cubic meter | F15: ecoinvent 3.10 cutoff | G15: technosphere | J15: (1,4,2,1,1)
A16: market for hard coal briquettes | B16: hard coal briquettes | C16: RoW | D16: 7.5334721 | E16: megajoule | F16: ecoinvent 3.10 cutoff | G16: technosphere | J16: (1,4,2,1,1)
A17: market group for electricity, medium voltage | B17: electricity, medium voltage | C17: RAS | D17: 0.023333158 | E17: kilowatt hour | F17: ecoinvent 3.10 cutoff | G17: technosphere | J17: (1,4,2,1,1)
A18: market for electricity, medium voltage, renewable energy products | B18: electricity, medium voltage, renewable energy products | C18: CH | D18: 0.39273101 | E18: kilowatt hour | F18: ecoinvent 3.10 cutoff | G18: technosphere | J18: (1,4,2,1,1)
A19: market for redmud from bauxite digestion | B19: redmud from bauxite digestion | C19: RoW | D19: -0.083337084 | E19: kilogram | F19: ecoinvent 3.10 cutoff | G19: technosphere | J19: (1,5,2,1,1)
A20: market for redmud from bauxite digestion | B20: redmud from bauxite digestion | C20: RoW | D20: -1.3935633 | E20: kilogram | F20: ecoinvent 3.10 cutoff | G20: technosphere | J20: (1,3,2,1,1)
A21: Water, unspecified natural origin | D21: 0.0034994066 | E21: cubic meter | F21: biosphere3 | G21: biosphere | H21: natural resource::in ground | J21: (1,4,2,1,1)
A22: Water, unspecified natural origin | D22: 0.0034550538 | E22: cubic meter | F22: biosphere3 | G22: biosphere | H22: natural resource::in ground | J22: (1,4,2,1,1)
A23: Particulate Matter, > 2.5 um and < 10um | D23: 0.00027214979 | E23: kilogram | F23: biosphere3 | G23: biosphere | H23: air | J23: (1,4,2,1,1)
A24: Sulfur dioxide | D24: 0.00049040467 | E24: kilogram | F24: biosphere3 | G24: biosphere | H24: air | J24: (1,4,2,1,1)
A25: Nitrogen oxides | D25: 0.00012701392 | E25: kilogram | F25: biosphere3 | G25: biosphere | H25: air | J25: (1,5,2,1,1)
A26: Water | D26: 0.00085144191 | E26: cubic meter | F26: biosphere3 | G26: biosphere | H26: water | J26: (1,5,2,1,1)
A28: Activity | B28: [P] Anode/Paste production
A29: reference product | B29: Anode/Paste
A30: location | B30: Rest-of-Asia
A31: amount | B31: 1
A32: unit | B32: kilogram
A33: comment | B33: n/a
A34: Exchanges
A35: name | B35: reference product | C35: location | D35: amount | E35: unit | F35: database | G35: type | H35: categories | I35: uncertainty type | J35: pedigree | K35: loc | L35: scale | M35: minimum | N35: maximum
A36: =B28 -> [P] Anode/Paste production | B36: =B29 -> Anode/Paste | C36: =B30 -> Rest-of-Asia | D36: 1 | E36: kilogram | F36: =F9 -> Aluminium | G36: production
A37: market for petroleum coke | B37: petroleum coke | C37: GLO | D37: 0.99159291 | E37: kilogram | F37: ecoinvent 3.10 cutoff | G37: technosphere | J37: (1,5,2,1,1)
A38: market for pitch | B38: pitch | C38: RoW | D38: 0.16028644 | E38: kilogram | F38: ecoinvent 3.10 cutoff | G38: technosphere | J38: (1,5,2,1,1)
A39: market for refractory, high aluminium oxide, packed | B39: refractory, high aluminium oxide, packed | C39: GLO | D39: 0.0011746553 | E39: kilogram | F39: ecoinvent 3.10 cutoff | G39: technosphere | J39: (1,5,2,1,1)
A40: market for steel, low-alloyed | B40: steel, low-alloyed | C40: GLO | D40: 0.00047152691 | E40: kilogram | F40: ecoinvent 3.10 cutoff | G40: technosphere | J40: (1,5,2,1,1)
A41: market for heavy fuel oil | B41: heavy fuel oil | C41: RoW | D41: 0.047656217 | E41: kilogram | F41: ecoinvent 3.10 cutoff | G41: technosphere | J41: (1,5,2,1,1)
...

Sheet PR9_Al_CN
A1: Activity | B1: [M+C] Bauxite mining
A2: reference product | B2: Bauxite
A3: location | B3: CN
A4: amount | B4: 1
A5: unit | B5: kilogram
A6: comment | B6: n/a
A7: Exchanges
A8: name | B8: reference product | C8: location | D8: amount | E8: unit | F8: database | G8: type | H8: categories | I8: uncertainty type | J8: pedigree | K8: loc | L8: scale | M8: minimum | N8: maximum
A9: =B1 -> [M+C] Bauxite mining | B9: =B2 -> Bauxite | C9: =B3 -> CN | D9: 1 | E9: kilogram | F9: =Al_Market_GLO!B1 -> Aluminium | G9: production
A10: market group for electricity, medium voltage | B10: electricity, medium voltage | C10: CN | D10: 0.0163 | E10: kilowatt hour | F10: ecoinvent 3.10 cutoff | G10: technosphere | J10: (1,5,2,1,1)
A11: market for light fuel oil | B11: light fuel oil | C11: RoW | D11: 0.00139 | E11: kilogram | F11: ecoinvent 3.10 cutoff | G11: technosphere | J11: (1,5,2,1,1)
A12: Carbon dioxide, fossil | D12: 0.00518 | E12: kilogram | F12: biosphere3 | G12: biosphere | H12: air | J12: (1,1,1,1,1)
A13: Sulfur dioxide | D13: 4.2e-07 | E13: kilogram | F13: biosphere3 | G13: biosphere | H13: air | J13: (1,1,1,1,1)
A14: Carbon monoxide, fossil | D14: 6.7e-07 | E14: kilogram | F14: biosphere3 | G14: biosphere | H14: air | J14: (1,1,1,1,1)
A15: Nitrogen oxides | D15: 8.12e-06 | E15: kilogram | F15: biosphere3 | G15: biosphere | H15: air | J15: (1,1,1,1,1)
A16: Methane, fossil | D16: 2e-07 | E16: kilogram | F16: biosphere3 | G16: biosphere | H16: air | J16: (1,1,1,1,1)
A18: Activity | B18: [P] Alumina production
A19: reference product | B19: Alumina
A20: location | B20: CN
A21: amount | B21: 1
A22: unit | B22: kilogram
A23: comment | B23: n/a
A24: Exchanges
A25: name | B25: reference product | C25: location | D25: amount | E25: unit | F25: database | G25: type | H25: categories | I25: uncertainty type | J25: pedigree | K25: loc | L25: scale | M25: minimum | N25: maximum
A26: =B18 -> [P] Alumina production | B26: =B19 -> Alumina | C26: =B20 -> CN | D26: 1 | E26: kilogram | F26: =F9 -> Aluminium | G26: production
A27: market for soda ash, dense | B27: soda ash, dense | C27: GLO | D27: 0.17 | E27: kilogram | F27: ecoinvent 3.10 cutoff | G27: technosphere | J27: (1,5,2,1,1)
A28: market for calcium carbide, technical grade | B28: calcium carbide, technical grade | C28: RoW | D28: 0.025 | E28: kilogram | F28: ecoinvent 3.10 cutoff | G28: technosphere | J28: (1,5,2,1,1)
A29: market for chemical, inorganic | B29: chemical, inorganic | C29: GLO | D29: 8e-05 | E29: kilogram | F29: ecoinvent 3.10 cutoff | G29: technosphere | J29: (1,5,2,1,1)
A30: market for hard coal | B30: hard coal | C30: CN | D30: 0.18 | E30: kilogram | F30: ecoinvent 3.10 cutoff | G30: technosphere | J30: (1,5,2,1,1)
A31: market for steam, in chemical industry | B31: steam, in chemical industry | C31: RoW | D31: 3.12 | E31: kilogram | F31: ecoinvent 3.10 cutoff | G31: technosphere | J31: (1,5,2,1,1)
A32: market group for electricity, medium voltage | B32: electricity, medium voltage | C32: CN | D32: 0.284 | E32: kilowatt hour | F32: ecoinvent 3.10 cutoff | G32: technosphere | J32: (1,5,2,1,1)
A33: market for natural gas, high pressure | B33: natural gas, high pressure | C33: CN | D33: 0.0884 | E33: cubic meter | F33: ecoinvent 3.10 cutoff | G33: technosphere | J33: (1,5,2,1,1)
A34: market for redmud from bauxite digestion | B34: redmud from bauxite digestion | C34: RoW | D34: -1.03 | E34: kilogram | F34: ecoinvent 3.10 cutoff | G34: technosphere | J34: (1,5,5,1,1)
A35: Carbon dioxide, fossil | D35: 0.49 | E35: kilogram | F35: biosphere3 | G35: biosphere | H35: air | J35: (1,1,1,1,1)
A36: Carbon monoxide, fossil | D36: 0.00066 | E36: kilogram | F36: biosphere3 | G36: biosphere | H36: air | J36: (1,1,1,1,1)
A37: Sulfur dioxide | D37: 0.00032 | E37: kilogram | F37: biosphere3 | G37: biosphere | H37: air | J37: (1,1,1,1,1)
A38: Nitrogen oxides | D38: 0.00141 | E38: kilogram | F38: biosphere3 | G38: biosphere | H38: air | J38: (1,1,1,1,1)
A39: Methane, fossil | D39: 1.8e-07 | E39: kilogram | F39: biosphere3 | G39: biosphere | H39: air | J39: (1,1,1,1,1)
A41: Activity | B41: [R] Electrolysis
A42: reference product | B42: Liquid aluminium (Al)
...

Sheet PR10_Al_CN_Recycling
A1: Activity | B1: Aluminium (Al) scraps
A2: reference product | B2: Al scraps
A3: location | B3: CN
A4: amount | B4: 1
A5: unit | B5: kilogram
A6: comment | B6: Empty activity representing the Al scraps input in the recycling process (following the "cut-off" modelling approach)
A7: Exchanges
A8: name | B8: reference product | C8: location | D8: amount | E8: unit | F8: database | G8: type | H8: categories | I8: uncertainty type | J8: pedigree | K8: loc | L8: scale | M8: minimum | N8: maximum
A9: =B1 -> Aluminium (Al) scraps | B9: =B2 -> Al scraps | C9: =B3 -> CN | D9: 1 | E9: kilogram | F9: =Al_Market_GLO!B1 -> Aluminium | G9: production
A11: Activity | B11: [P+R] Al scraps recycling
A12: reference product | B12: Al ingot
A13: location | B13: CN
A14: amount | B14: 1
A15: unit | B15: kilogram
A16: comment | B16: n/a
A17: Exchanges
A18: name | B18: reference product | C18: location | D18: amount | E18: unit | F18: database | G18: type | H18: categories | I18: uncertainty type | J18: pedigree | K18: loc | L18: scale | M18: minimum | N18: maximum
A19: =B11 -> [P+R] Al scraps recycling | B19: =B12 -> Al ingot | C19: =B13 -> CN | D19: 1 | E19: kilogram | F19: =F9 -> Aluminium | G19: production
A20: market group for electricity, medium voltage | B20: electricity, medium voltage | C20: CN | D20: 0.319 | E20: kilowatt hour | F20: ecoinvent 3.10 cutoff | G20: technosphere | J20: (2,1,3,1,2)
A21: market for natural gas, high pressure | B21: natural gas, high pressure | C21: CN | D21: 0.1 | E21: cubic meter | F21: ecoinvent 3.10 cutoff | G21: technosphere | J21: (2,1,3,1,2)
A22: market for chemical, inorganic | B22: chemical, inorganic | C22: GLO | D22: 0.006 | E22: kilogram | F22: ecoinvent 3.10 cutoff | G22: technosphere | J22: (2,5,5,5,4)
A23: market for petroleum | B23: petroleum | C23: RoW | D23: 2.32e-07 | E23: kilogram | F23: ecoinvent 3.10 cutoff | G23: technosphere | J23: (2,1,3,1,2)
A24: market for municipal solid waste | B24: municipal solid waste | C24: RoW | D24: -0.21 | E24: kilogram | F24: ecoinvent 3.10 cutoff | G24: technosphere | J24: (2,1,3,1,2)
