Workbook

Sheet Note
A1: skip
B2: Life cycle inventories of global metal and mineral supply chains: a comprehensive data review, analysis and processing Frédéric Laia*, Stéphanie Mullera, Audrey Philippea, Robert Istrateb, Brenda Miranda Xicotencatlb, Afsoon Mansouri Askic, Aina Mas Fonsd,a, Juliana Segura-Salazare, Jair Santillán Saldivara, Alexander Cimprichf, Stephen Northeyg, Lígia da Silva Limah, Lieselot Booneh, Ryosuke Yokoii, Kamrul Islami, Ioanna Paschalidouj, Felipe Cerdask,l, Victor Balboa-Espinozae, Anish Koyamparambathd, Diae Henniouia, Victoire Collignona, Aurélien Reysa, Gyslain Ngadi Sakatadim, Jo Dewulfh, Bernhard Steubingb, Christoph Helbigc, Gaétan Lefebvrea, Gian Andrea Blenginin,m, Valeria Supertio, Masaharu Motoshitai, Guido Sonnemannd, Kwame Awuah-Offeij, Steven B. Youngf, Shinsuke Murakamip, Antoine Beylota aBRGM, F-45060 Orléans, France bInstitute of Environmental Sciences (CML), Leiden University, Einsteinweg 2, 2333 CC Leiden, NL cEcological Resource Technology, University of Bayreuth, Universitätstr. 30, 95447 Bayreuth, Germany dUniv. Bordeaux, CNRS, Bordeaux INP, ISM, UMR 5255, F-33400 Talence, France eSustainable Minerals Institute, The University of Queensland, QLD, 4072, Australia fSchool of Environment, Enterprise and Development, University of Waterloo, 200 University Avenue West, Waterloo, Ontario N2L 3G1, Canada gUniversity of Technology Sydney, Institute for Sustainable Futures, Australia hSustainable Systems Engineering (STEN), Department of Green Chemistry and Technology, Faculty of Bioscience Engineering, Ghent University, Coupure Links 653, 9000 Ghent, Belgium iAIST, 305-8569 Tsukuba, Japan jMining & Explosives Engineering, Missouri University of Science & Technology, Rolla, MO, USA 65409 kInstitute for Sustainable Energy Systems (INSYS), Technical University of Applied Sciences Würzburg-Schweinfurt (THWS), Ignaz-Schön-Straße 11, Schweinfurt, Germany lFraunhofer Institute for Surface Engineering and Thin Films IST, Riedenkamp 2, Braunschweig 38108, Germany mDepartment of Environment, Land and Infrastructure Engineering, Politecnico di Torino, Corso Duca degli Abruzzi, 24, 10129 Torino, Italy nUniversity of Turin, Earth Sciences Department (DST), Via Valperga Caluso, 35 – 10125 Torino, Italy oecoinvent association, Technopark, Technoparkstrasse 1, 8005 Zürich, Switzerland pGraduate School of Engineering, The University of Tokyo, Tokyo 113-8656, Japan *Corresponding author: f.lai@brgm.fr This file provides all LCI datasets developed for Gold (Au), with distinguishing its global market and each individual production route.
B33: Sheet | C33: Corresponding route
B34: Au_Market_GLO | C34: Au global market
B35: PR1_Au_CN_Qinghai | C35: Au ore mining and Au production in China/Qinghai
B36: PR2_Au_PE_Alluvial_Carretilla | C36: Au alluvial mining and Au production in Peru through "Carretilla" method
B37: PR3_Au_PE_Alluvial_Traca | C37: Au alluvial mining and Au production in Peru through "Chupadera/traca" method
B38: PR4_Au_PE_Alluvial_Caranchera | C38: Au alluvial mining and Au production in Peru through "Caranchera" method
B39: PR5_Au_PE_Alluvial_Dredge | C39: Au alluvial mining and Au production in Peru through "Dredge" method
B40: PR6_Au_PE_Alluvial_PartialChute | C40: Au alluvial mining and Au production in Peru through "Partial chute" method
B41: PR7_Au_PE_Alluvial_Chute | C41: Au alluvial mining and Au production in Peru through "Complete chute" method
B42: PR8_Au_CO_OpenPit | C42: Au ore mining and Au production in Colombia/Antioquia
B43: PR9_Au_CO_Alluvial | C43: Au alluvial mining and Au production in Colombia/Antioquia
B44: PR10_Au_PE_OpenPit | C44: Au open-pit mining and Au production in Peru
... B48: PR14_Au_RER_Recycling_WEEE | C48: Au production in Europe through WEEE recycling

Sheet Au_Market_GLO
A1: database | B1: Gold
A3: Activity | B3: Gold (Au) global market
A4: reference product | B4: Refined Au
A5: location | B5: GLO
A6: amount | B6: 1
A7: unit | B7: kilogram
A8: comment | B8: n/a
A9: Exchanges
A10: name | B10: reference product | C10: location | D10: amount | E10: unit | F10: database | G10: type | H10: categories | I10: uncertainty type | J10: pedigree | K10: loc | L10: scale | M10: minimum | N10: maximum
A11: =B3 -> Gold (Au) global market | B11: =B4 -> Refined Au | C11: =B5 -> GLO | D11: 1 | E11: kilogram | F11: =B1 -> Gold | G11: production
A12: =PR1_Au_CN_Qinghai!A43 -> Au ore mining and Au production in China/Qinghai | B12: =PR1_Au_CN_Qinghai!B43 -> Refined Au | C12: =PR1_Au_CN_Qinghai!C43 -> CN | D12: 0.31546154 | E12: =PR1_Au_CN_Qinghai!E43 -> kilogram | F12: =PR1_Au_CN_Qinghai!F43 -> Gold | G12: technosphere
A13: =PR2_Au_PE_Alluvial_Carretilla!A32 -> Au alluvial mining and Au production in Peru through "Carretilla" method | B13: =PR2_Au_PE_Alluvial_Carretilla!B32 -> Refined Au | C13: =PR2_Au_PE_Alluvial_Carretilla!C32 -> PE | D13: 0.0025316407 | E13: =PR2_Au_PE_Alluvial_Carretilla!E32 -> kilogram | F13: =PR2_Au_PE_Alluvial_Carretilla!F32 -> Gold | G13: technosphere
A14: =PR3_Au_PE_Alluvial_Traca!A34 -> Au alluvial mining and Au production in Peru through "Chupadera/traca" method | B14: =PR3_Au_PE_Alluvial_Traca!B34 -> Refined Au | C14: =PR3_Au_PE_Alluvial_Traca!C34 -> PE | D14: 0.0025316407 | E14: =PR3_Au_PE_Alluvial_Traca!E34 -> kilogram | F14: =PR3_Au_PE_Alluvial_Traca!F34 -> Gold | G14: technosphere
A15: =PR4_Au_PE_Alluvial_Caranchera!A33 -> Au alluvial mining and Au production in Peru through "Caranchera" method | B15: =PR4_Au_PE_Alluvial_Caranchera!B33 -> Refined Au | C15: =PR4_Au_PE_Alluvial_Caranchera!C33 -> PE | D15: 0.0025316407 | E15: =PR4_Au_PE_Alluvial_Caranchera!E33 -> kilogram | F15: =PR4_Au_PE_Alluvial_Caranchera!F33 -> Gold | G15: technosphere
A16: =PR5_Au_PE_Alluvial_Dredge!A33 -> Au alluvial mining and Au production in Peru through "Dredge" method | B16: =PR5_Au_PE_Alluvial_Dredge!B33 -> Refined Au | C16: =PR5_Au_PE_Alluvial_Dredge!C33 -> PE | D16: 0.0025316407 | E16: =PR5_Au_PE_Alluvial_Dredge!E33 -> kilogram | F16: =PR5_Au_PE_Alluvial_Dredge!F33 -> Gold | G16: technosphere
A17: =PR6_Au_PE_Alluvial_PartialChute!A34 -> Au alluvial mining and Au production in Peru through "Partial chute" method | B17: =PR6_Au_PE_Alluvial_PartialChute!B34 -> Refined Au | C17: =PR6_Au_PE_Alluvial_PartialChute!C34 -> PE | D17: 0.0025316407 | E17: =PR6_Au_PE_Alluvial_PartialChute!E34 -> kilogram | F17: =PR6_Au_PE_Alluvial_PartialChute!F34 -> Gold | G17: technosphere
A18: =PR7_Au_PE_Alluvial_Chute!A34 -> Au alluvial mining and Au production in Peru through "Complete chute" method | B18: =PR7_Au_PE_Alluvial_Chute!B34 -> Refined Au | C18: =PR7_Au_PE_Alluvial_Chute!C34 -> PE | D18: 0.0025316407 | E18: =PR7_Au_PE_Alluvial_Chute!E34 -> kilogram | F18: =PR7_Au_PE_Alluvial_Chute!F34 -> Gold | G18: technosphere
A19: =PR8_Au_CO_OpenPit!A39 -> Au ore mining and Au production in Colombia/Antioquia | B19: =PR8_Au_CO_OpenPit!B39 -> Refined Au | C19: =PR8_Au_CO_OpenPit!C39 -> CO | D19: 0.05325479 | E19: =PR8_Au_CO_OpenPit!E39 -> kilogram | F19: =PR8_Au_CO_OpenPit!F39 -> Gold | G19: technosphere
A20: =PR9_Au_CO_Alluvial!A35 -> Au alluvial mining and Au production in Colombia/Antioquia | B20: =PR9_Au_CO_Alluvial!B35 -> Refined Au | C20: =PR9_Au_CO_Alluvial!C35 -> CO | D20: 0.0086661338 | E20: =PR9_Au_CO_Alluvial!E35 -> kilogram | F20: =PR9_Au_CO_Alluvial!F35 -> Gold | G20: technosphere
A21: =PR10_Au_PE_OpenPit!A76 -> Au open-pit mining and Au production in Peru | B21: =PR10_Au_PE_OpenPit!B76 -> Refined Au | C21: =PR10_Au_PE_OpenPit!C76 -> PE | D21: 0.093344042 | E21: =PR10_Au_PE_OpenPit!E76 -> kilogram | F21: =PR10_Au_PE_OpenPit!F76 -> Gold | G21: technosphere
A22: =PR11_Au_CN_CuSlime!A31 -> Au production in China through Cu anode slime processing | B22: =PR11_Au_CN_CuSlime!B31 -> Refined Au | C22: =PR11_Au_CN_CuSlime!C31 -> CN | D22: 0.044017889 | E22: =PR11_Au_CN_CuSlime!E31 -> kilogram | F22: =PR11_Au_CN_CuSlime!F31 -> Gold | G22: technosphere
A23: =PR12_Au_AU!A31 -> Au ore mining and Au production in Australia | B23: =PR12_Au_AU!B31 -> Refined Au | C23: =PR12_Au_AU!C31 -> AU | D23: 0.34249739 | E23: =PR12_Au_AU!E31 -> kilogram | F23: =PR12_Au_AU!F31 -> Gold | G23: technosphere
A24: =PR13_Au_ZA!A32 -> Au ore mining and Au production in South Africa | B24: =PR13_Au_ZA!B32 -> Refined Au | C24: =PR13_Au_ZA!C32 -> ZA | D24: 0.11711611 | E24: =PR13_Au_ZA!E32 -> kilogram | F24: =PR13_Au_ZA!F32 -> Gold | G24: technosphere
A25: =PR14_Au_RER_Recycling_WEEE!A136 -> Au production in Europe through WEEE recycling | B25: =PR14_Au_RER_Recycling_WEEE!B136 -> Refined Au | C25: =PR14_Au_RER_Recycling_WEEE!C136 -> Europe | D25: 0.010452256 | E25: =PR14_Au_RER_Recycling_WEEE!E136 -> kilogram | F25: =PR14_Au_RER_Recycling_WEEE!F136 -> Gold | G25: technosphere

Sheet PR1_Au_CN_Qinghai
A1: Activity | B1: [M+C+P+R] Gold (Au) production (from ore)
A2: reference product | B2: Refined Au
A3: location | B3: CN
A4: amount | B4: 1
A5: unit | B5: kilogram
A6: comment | B6: The co-produced sulfuric acid is dealt through substitution.
A7: Exchanges
A8: name | B8: reference product | C8: location | D8: amount | E8: unit | F8: database | G8: type | H8: categories | I8: uncertainty type | J8: pedigree | K8: loc | L8: scale | M8: minimum | N8: maximum
A9: =B1 -> [M+C+P+R] Gold (Au) production (from ore) | B9: =B2 -> Refined Au | C9: =B3 -> CN | D9: 1 | E9: kilogram | F9: =Au_Market_GLO!B1 -> Gold | G9: production
A10: market for sodium ethyl xanthate | B10: sodium ethyl xanthate | C10: GLO | D10: 109.82659 | E10: kilogram | F10: ecoinvent 3.10 cutoff | G10: technosphere | J10: (2,1,2,1,1)
A11: market for copper sulfate | B11: copper sulfate | C11: GLO | D11: 150.28902 | E11: kilogram | F11: ecoinvent 3.10 cutoff | G11: technosphere | J11: (1,1,2,1,1)
A12: market for sodium cyanide | B12: sodium cyanide | C12: RoW | D12: 260.11561 | E12: kilogram | F12: ecoinvent 3.10 cutoff | G12: technosphere | J12: (2,1,2,1,1)
A13: market for sodium sulfite | B13: sodium sulfite | C13: RoW | D13: 104.04624 | E13: kilogram | F13: ecoinvent 3.10 cutoff | G13: technosphere | J13: (1,1,2,1,1)
A14: market for limestone, crushed, washed | B14: limestone, crushed, washed | C14: RoW | D14: 2699.422 | E14: kilogram | F14: ecoinvent 3.10 cutoff | G14: technosphere | J14: (1,1,2,1,1)
A15: market group for electricity, medium voltage | B15: electricity, medium voltage | C15: CN | D15: 50942.197 | E15: kilowatt hour | F15: ecoinvent 3.10 cutoff | G15: technosphere | J15: (1,1,2,1,1)
A16: market for hard coal | B16: hard coal | C16: CN | D16: 1768.7861 | E16: kilogram | F16: ecoinvent 3.10 cutoff | G16: technosphere | J16: (1,1,2,1,1)
A17: market for light fuel oil | B17: light fuel oil | C17: RoW | D17: 57.803468 | E17: kilogram | F17: ecoinvent 3.10 cutoff | G17: technosphere | J17: (1,1,2,1,1)
A18: market for diesel, burned in building machine | B18: diesel, burned in building machine | C18: GLO | D18: 10309.249 | E18: megajoule | F18: ecoinvent 3.10 cutoff | G18: technosphere | J18: (1,1,2,1,1)
A19: market for hydrochloric acid, without water, in 30% solution state | B19: hydrochloric acid, without water, in 30% solution state | C19: RoW | D19: 260.11561 | E19: kilogram | F19: ecoinvent 3.10 cutoff | G19: technosphere | J19: (1,1,2,1,1)
A20: market for steel, low-alloyed | B20: steel, low-alloyed | C20: GLO | D20: 589.59538 | E20: kilogram | F20: ecoinvent 3.10 cutoff | G20: technosphere | J20: (1,1,2,1,1)
A21: market for hazardous waste, for incineration | B21: hazardous waste, for incineration | C21: RoW | D21: -8.150289 | E21: kilogram | F21: ecoinvent 3.10 cutoff | G21: technosphere | J21: (1,1,2,1,1)
... A24: market for sulfuric acid | B24: sulfuric acid | C24: RoW | D24: -26531.792 | E24: kilogram | F24: ecoinvent 3.10 cutoff | G24: technosphere | J24: (1,1,2,1,1)
A25: Gold | D25: 1.1156069 | E25: kilogram | F25: biosphere3 | G25: biosphere | H25: natural resource::in ground | J25: (1,1,2,1,1)
A26: Transformation, to mineral extraction site | D26: 26.300578 | E26: square meter | F26: biosphere3 | G26: biosphere | H26: natural resource::land | J26: (1,1,2,1,1)
A27: Transformation, from unspecified | D27: 26.300578 | E27: square meter | F27: biosphere3 | G27: biosphere | H27: natural resource::land | J27: (1,1,2,1,1)
A28: Water, unspecified natural origin | D28: 352.60116 | E28: cubic meter | F28: biosphere3 | G28: biosphere | H28: natural resource::in ground | J28: (1,1,2,1,1)
A29: Sulfur dioxide | D29: 18.138728 | E29: kilogram | F29: biosphere3 | G29: biosphere | H29: air | J29: (1,1,2,1,1)
A30: Arsenic ion | D30: 0.00013294798 | E30: kilogram | F30: biosphere3 | G30: biosphere | H30: air | J30: (1,1,2,1,1)
A31: Particulate Matter, > 10 um | D31: 12.982659 | E31: kilogram | F31: biosphere3 | G31: biosphere | H31: air | J31: (1,1,2,1,1)
A32: Nitrogen oxides | D32: 3.8208092 | E32: kilogram | F32: biosphere3 | G32: biosphere | H32: air | J32: (1,1,2,1,1)
A33: Carbon dioxide, fossil | D33: 2601.1561 | E33: kilogram | F33: biosphere3 | G33: biosphere | H33: air | J33: (1,1,2,1,1)
A35: Activity | B35: Au ore mining and Au production in China/Qinghai
A36: reference product | B36: Refined Au
A37: location | B37: CN
A38: amount | B38: 1
A39: unit | B39: kilogram
A40: comment | B40: n/a
A41: Exchanges
A42: name | B42: reference product | C42: location | D42: amount | E42: unit | F42: database | G42: type | H42: categories | I42: uncertainty type | J42: pedigree | K42: loc | L42: scale | M42: minimum | N42: maximum
A43: =B35 -> Au ore mining and Au production in China/Qinghai | B43: =B36 -> Refined Au | C43: =B37 -> CN | D43: 1 | E43: kilogram | F43: =F9 -> Gold | G43: production
...

Sheet PR2_Au_PE_Alluvial_Carretilla
A1: Activity | B1: [M+C+P+R] Gold (Au) production (alluivial - Carretilla method)
A2: reference product | B2: Refined Au
A3: location | B3: PE
A4: amount | B4: 1
A5: unit | B5: kilogram
A6: comment | B6: n/a
A7: Exchanges
A8: name | B8: reference product | C8: location | D8: amount | E8: unit | F8: database | G8: type | H8: categories | I8: uncertainty type | J8: pedigree | K8: loc | L8: scale | M8: minimum | N8: maximum
A9: =B1 -> [M+C+P+R] Gold (Au) production (alluivial - Carretilla method) | B9: =B2 -> Refined Au | C9: =B3 -> PE | D9: 1 | E9: kilogram | F9: =Au_Market_GLO!B1 -> Gold | G9: production
A10: water pump operation, diesel | B10: water pump operation, diesel | C10: PE | D10: 1879.2 | E10: megajoule | F10: ecoinvent 3.10 cutoff | G10: technosphere | J10: (1,1,2,1,1)
A11: market for diesel, burned in building machine | B11: diesel, burned in building machine | C11: GLO | D11: 114187.5 | E11: megajoule | F11: ecoinvent 3.10 cutoff | G11: technosphere | J11: (1,1,2,1,1)
A12: market for lubricating oil | B12: lubricating oil | C12: RoW | D12: 83.2 | E12: kilogram | F12: ecoinvent 3.10 cutoff | G12: technosphere | J12: (1,1,2,1,1)
A13: market for polyvinylchloride, bulk polymerised | B13: polyvinylchloride, bulk polymerised | C13: GLO | D13: 111.1 | E13: kilogram | F13: ecoinvent 3.10 cutoff | G13: technosphere | J13: (1,1,2,1,1)
A14: market for extrusion, plastic film | B14: extrusion, plastic film | C14: GLO | D14: 212.5 | E14: kilogram | F14: ecoinvent 3.10 cutoff | G14: technosphere | J14: (1,1,2,1,1)
A15: market for polypropylene, granulate | B15: polypropylene, granulate | C15: GLO | D15: 19.4 | E15: kilogram | F15: ecoinvent 3.10 cutoff | G15: technosphere | J15: (1,1,2,1,1)
A16: market for mercury | B16: mercury | C16: GLO | D16: 2 | E16: kilogram | F16: ecoinvent 3.10 cutoff | G16: technosphere | J16: (1,1,2,1,1)
A17: Water, river | D17: 100000 | E17: cubic meter | F17: biosphere3 | G17: biosphere | H17: natural resource::in water | J17: (1,1,2,1,1)
A18: Mercury II | D18: 0.1 | E18: kilogram | F18: biosphere3 | G18: biosphere | H18: air::urban air close to ground | J18: (1,1,2,1,1)
A19: Mercury II | D19: 1.3 | E19: kilogram | F19: biosphere3 | G19: biosphere | H19: air::non-urban air or from high stacks | J19: (1,1,2,1,1)
A20: Mercury II | D20: 0.3 | E20: kilogram | F20: biosphere3 | G20: biosphere | H20: soil | J20: (1,1,2,1,1)
A21: Mercury II | D21: 0.3 | E21: kilogram | F21: biosphere3 | G21: biosphere | H21: water::surface water | J21: (1,1,2,1,1)
A22: Mercury II | D22: 0.795 | E22: kilogram | F22: biosphere3 | G22: biosphere | H22: soil | J22: (1,1,2,1,1)
A24: Activity | B24: Au alluvial mining and Au production in Peru through "Carretilla" method
A25: reference product | B25: Refined Au
A26: location | B26: PE
A27: amount | B27: 1
A28: unit | B28: kilogram
A29: comment | B29: n/a
A30: Exchanges
A31: name | B31: reference product | C31: location | D31: amount | E31: unit | F31: database | G31: type | H31: categories | I31: uncertainty type | J31: pedigree | K31: loc | L31: scale | M31: minimum | N31: maximum
A32: =B24 -> Au alluvial mining and Au production in Peru through "Carretilla" method | B32: =B25 -> Refined Au | C32: =B26 -> PE | D32: 1 | E32: kilogram | F32: =F9 -> Gold | G32: production
A33: =A9 -> [M+C+P+R] Gold (Au) production (alluivial - Carretilla method) | B33: =B9 -> Refined Au | C33: =C9 -> PE | D33: =D9 -> 1 | E33: =E9 -> kilogram | F33: =F9 -> Gold | G33: technosphere

Sheet PR3_Au_PE_Alluvial_Traca
A1: Activity | B1: [M+C+P+R] Gold (Au) production (alluvial - Chupadera/Traca method)
A2: reference product | B2: Refined Au
A3: location | B3: PE
A4: amount | B4: 1
A5: unit | B5: kilogram
A6: comment | B6: n/a
A7: Exchanges
A8: name | B8: reference product | C8: location | D8: amount | E8: unit | F8: database | G8: type | H8: categories | I8: uncertainty type | J8: pedigree | K8: loc | L8: scale | M8: minimum | N8: maximum
A9: =B1 -> [M+C+P+R] Gold (Au) production (alluvial - Chupadera/Traca method) | B9: =B2 -> Refined Au | C9: =B3 -> PE | D9: 1 | E9: kilogram | F9: =Au_Market_GLO!B1 -> Gold | G9: production
A10: market for steel, low-alloyed | B10: steel, low-alloyed | C10: GLO | D10: 8.9 | E10: kilogram | F10: ecoinvent 3.10 cutoff | G10: technosphere | J10: (1,1,2,1,1)
A11: water pump operation, diesel | B11: water pump operation, diesel | C11: PE | D11: 465.45 | E11: megajoule | F11: ecoinvent 3.10 cutoff | G11: technosphere | J11: (1,1,2,1,1)
A12: market for diesel, burned in building machine | B12: diesel, burned in building machine | C12: GLO | D12: 164386.5 | E12: megajoule | F12: ecoinvent 3.10 cutoff | G12: technosphere | J12: (1,1,2,1,1)
A13: market for lubricating oil | B13: lubricating oil | C13: RoW | D13: 33.5 | E13: kilogram | F13: ecoinvent 3.10 cutoff | G13: technosphere | J13: (1,1,2,1,1)
A14: market for polyvinylchloride, bulk polymerised | B14: polyvinylchloride, bulk polymerised | C14: GLO | D14: 22.2 | E14: kilogram | F14: ecoinvent 3.10 cutoff | G14: technosphere | J14: (1,1,2,1,1)
A15: market for extrusion, plastic film | B15: extrusion, plastic film | C15: GLO | D15: 25.5 | E15: kilogram | F15: ecoinvent 3.10 cutoff | G15: technosphere | J15: (1,1,2,1,1)
A16: market for polypropylene, granulate | B16: polypropylene, granulate | C16: GLO | D16: 4.7 | E16: kilogram | F16: ecoinvent 3.10 cutoff | G16: technosphere | J16: (1,1,2,1,1)
A17: market for mercury | B17: mercury | C17: GLO | D17: 2 | E17: kilogram | F17: ecoinvent 3.10 cutoff | G17: technosphere | J17: (1,1,2,1,1)
A18: Water, river | D18: 66667 | E18: cubic meter | F18: biosphere3 | G18: biosphere | H18: natural resource::in water | J18: (1,1,2,1,1)
A19: Transformation, from forest, unspecified | D19: 1111 | E19: square meter | F19: biosphere3 | G19: biosphere | H19: natural resource::land | J19: (1,1,2,1,1)
A20: Transformation, to mineral extraction site | D20: 1111 | E20: square meter | F20: biosphere3 | G20: biosphere | H20: natural resource::land | J20: (1,1,2,1,1)
A21: Mercury II | D21: 0.1 | E21: kilogram | F21: biosphere3 | G21: biosphere | H21: air::urban air close to ground | J21: (1,1,2,1,1)
A22: Mercury II | D22: 1.3 | E22: kilogram | F22: biosphere3 | G22: biosphere | H22: air::non-urban air or from high stacks | J22: (1,1,2,1,1)
A23: Mercury II | D23: 0.3 | E23: kilogram | F23: biosphere3 | G23: biosphere | H23: soil | J23: (1,1,2,1,1)
A24: Mercury II | D24: 0.3 | E24: kilogram | F24: biosphere3 | G24: biosphere | H24: water::surface water | J24: (1,1,2,1,1)
A26: Activity | B26: Au alluvial mining and Au production in Peru through "Chupadera/traca" method
A27: reference product | B27: Refined Au
A28: location | B28: PE
A29: amount | B29: 1
A30: unit | B30: kilogram
A31: comment | B31: n/a
A32: Exchanges
A33: name | B33: reference product | C33: location | D33: amount | E33: unit | F33: database | G33: type | H33: categories | I33: uncertainty type | J33: pedigree | K33: loc | L33: scale | M33: minimum | N33: maximum
A34: =B26 -> Au alluvial mining and Au production in Peru through "Chupadera/traca" method | B34: =B27 -> Refined Au | C34: =B28 -> PE | D34: 1 | E34: kilogram | F34: =F9 -> Gold | G34: production
A35: =A9 -> [M+C+P+R] Gold (Au) production (alluvial - Chupadera/Traca method) | B35: =B9 -> Refined Au | C35: =C9 -> PE | D35: =D9 -> 1 | E35: =E9 -> kilogram | F35: =F9 -> Gold | G35: technosphere

Sheet PR4_Au_PE_Alluvial_Caranchera
A1: Activity | B1: [M+C+P+R] Gold (Au) production (alluvial - Caranchera method)
A2: reference product | B2: Refined Au
A3: location | B3: PE
A4: amount | B4: 1
A5: unit | B5: kilogram
A6: comment | B6: n/a
A7: Exchanges
A8: name | B8: reference product | C8: location | D8: amount | E8: unit | F8: database | G8: type | H8: categories | I8: uncertainty type | J8: pedigree | K8: loc | L8: scale | M8: minimum | N8: maximum
A9: =B1 -> [M+C+P+R] Gold (Au) production (alluvial - Caranchera method) | B9: =B2 -> Refined Au | C9: =B3 -> PE | D9: 1 | E9: kilogram | F9: =Au_Market_GLO!B1 -> Gold | G9: production
A10: market for steel, low-alloyed | B10: steel, low-alloyed | C10: GLO | D10: 17.8 | E10: kilogram | F10: ecoinvent 3.10 cutoff | G10: technosphere | J10: (1,1,2,1,1)
A11: water pump operation, diesel | B11: water pump operation, diesel | C11: PE | D11: 1609.5 | E11: megajoule | F11: ecoinvent 3.10 cutoff | G11: technosphere | J11: (1,1,2,1,1)
A12: market for diesel, burned in building machine | B12: diesel, burned in building machine | C12: GLO | D12: 182656.5 | E12: megajoule | F12: ecoinvent 3.10 cutoff | G12: technosphere | J12: (1,1,2,1,1)
A13: market for lubricating oil | B13: lubricating oil | C13: RoW | D13: 7.4 | E13: kilogram | F13: ecoinvent 3.10 cutoff | G13: technosphere | J13: (1,1,2,1,1)
A14: market for polyvinylchloride, bulk polymerised | B14: polyvinylchloride, bulk polymerised | C14: GLO | D14: 44.4 | E14: kilogram | F14: ecoinvent 3.10 cutoff | G14: technosphere | J14: (1,1,2,1,1)
A15: market for extrusion, plastic film | B15: extrusion, plastic film | C15: GLO | D15: 99.2 | E15: kilogram | F15: ecoinvent 3.10 cutoff | G15: technosphere | J15: (1,1,2,1,1)
A16: market for polypropylene, granulate | B16: polypropylene, granulate | C16: GLO | D16: 10.4 | E16: kilogram | F16: ecoinvent 3.10 cutoff | G16: technosphere | J16: (1,1,2,1,1)
A17: market for mercury | B17: mercury | C17: GLO | D17: 2 | E17: kilogram | F17: ecoinvent 3.10 cutoff | G17: technosphere | J17: (1,1,2,1,1)
A18: Water, river | D18: 100000 | E18: cubic meter | F18: biosphere3 | G18: biosphere | H18: natural resource::in water | J18: (1,1,2,1,1)
A19: Mercury II | D19: 0.1 | E19: kilogram | F19: biosphere3 | G19: biosphere | H19: air::urban air close to ground | J19: (1,1,2,1,1)
A20: Mercury II | D20: 1.3 | E20: kilogram | F20: biosphere3 | G20: biosphere | H20: air::non-urban air or from high stacks | J20: (1,1,2,1,1)
A21: Mercury II | D21: 0.3 | E21: kilogram | F21: biosphere3 | G21: biosphere | H21: soil | J21: (1,1,2,1,1)
A22: Mercury II | D22: 0.3 | E22: kilogram | F22: biosphere3 | G22: biosphere | H22: water::surface water | J22: (1,1,2,1,1)
A23: Mercury II | D23: 0.795 | E23: kilogram | F23: biosphere3 | G23: biosphere | H23: soil | J23: (1,1,2,1,1)
A25: Activity | B25: Au alluvial mining and Au production in Peru through "Caranchera" method
A26: reference product | B26: Refined Au
A27: location | B27: PE
A28: amount | B28: 1
A29: unit | B29: kilogram
A30: comment | B30: n/a
A31: Exchanges
A32: name | B32: reference product | C32: location | D32: amount | E32: unit | F32: database | G32: type | H32: categories | I32: uncertainty type | J32: pedigree | K32: loc | L32: scale | M32: minimum | N32: maximum
A33: =B25 -> Au alluvial mining and Au production in Peru through "Caranchera" method | B33: =B26 -> Refined Au | C33: =B27 -> PE | D33: 1 | E33: kilogram | F33: =F9 -> Gold | G33: production
A34: =A9 -> [M+C+P+R] Gold (Au) production (alluvial - Caranchera method) | B34: =B9 -> Refined Au | C34: =C9 -> PE | D34: =D9 -> 1 | E34: =E9 -> kilogram | F34: =F9 -> Gold | G34: technosphere

Sheet PR5_Au_PE_Alluvial_Dredge
A1: Activity | B1: [M+C+P+R] Gold (Au) production (alluvial - Dredge method)
A2: reference product | B2: Refined Au
A3: location | B3: PE
A4: amount | B4: 1
A5: unit | B5: kilogram
A6: comment | B6: n/a
A7: Exchanges
A8: name | B8: reference product | C8: location | D8: amount | E8: unit | F8: database | G8: type | H8: categories | I8: uncertainty type | J8: pedigree | K8: loc | L8: scale | M8: minimum | N8: maximum
A9: =B1 -> [M+C+P+R] Gold (Au) production (alluvial - Dredge method) | B9: =B2 -> Refined Au | C9: =B3 -> PE | D9: 1 | E9: kilogram | F9: =Au_Market_GLO!B1 -> Gold | G9: production
A10: market for steel, low-alloyed | B10: steel, low-alloyed | C10: GLO | D10: 8.3 | E10: kilogram | F10: ecoinvent 3.10 cutoff | G10: technosphere | J10: (1,1,2,1,1)
A11: water pump operation, diesel | B11: water pump operation, diesel | C11: PE | D11: 778.65 | E11: megajoule | F11: ecoinvent 3.10 cutoff | G11: technosphere | J11: (1,1,2,1,1)
A12: market for diesel, burned in building machine | B12: diesel, burned in building machine | C12: GLO | D12: 109054.5 | E12: megajoule | F12: ecoinvent 3.10 cutoff | G12: technosphere | J12: (1,1,2,1,1)
A13: market for lubricating oil | B13: lubricating oil | C13: RoW | D13: 42.7 | E13: kilogram | F13: ecoinvent 3.10 cutoff | G13: technosphere | J13: (1,1,2,1,1)
A14: market for polyvinylchloride, bulk polymerised | B14: polyvinylchloride, bulk polymerised | C14: GLO | D14: 12.4 | E14: kilogram | F14: ecoinvent 3.10 cutoff | G14: technosphere | J14: (1,1,2,1,1)
A15: market for extrusion, plastic film | B15: extrusion, plastic film | C15: GLO | D15: 22.2 | E15: kilogram | F15: ecoinvent 3.10 cutoff | G15: technosphere | J15: (1,1,2,1,1)
A16: market for polypropylene, granulate | B16: polypropylene, granulate | C16: GLO | D16: 3.5 | E16: kilogram | F16: ecoinvent 3.10 cutoff | G16: technosphere | J16: (1,1,2,1,1)
A17: market for mercury | B17: mercury | C17: GLO | D17: 2 | E17: kilogram | F17: ecoinvent 3.10 cutoff | G17: technosphere | J17: (1,1,2,1,1)
A18: Water, river | D18: 150000 | E18: cubic meter | F18: biosphere3 | G18: biosphere | H18: natural resource::in water | J18: (1,1,2,1,1)
A19: Mercury II | D19: 0.1 | E19: kilogram | F19: biosphere3 | G19: biosphere | H19: air::urban air close to ground | J19: (1,1,2,1,1)
A20: Mercury II | D20: 1.3 | E20: kilogram | F20: biosphere3 | G20: biosphere | H20: air::non-urban air or from high stacks | J20: (1,1,2,1,1)
A21: Mercury II | D21: 0.3 | E21: kilogram | F21: biosphere3 | G21: biosphere | H21: soil | J21: (1,1,2,1,1)
A22: Mercury II | D22: 0.3 | E22: kilogram | F22: biosphere3 | G22: biosphere | H22: water | J22: (1,1,2,1,1)
A23: Mercury II | D23: 0.795 | E23: kilogram | F23: biosphere3 | G23: biosphere | H23: soil | J23: (1,1,2,1,1)
A25: Activity | B25: Au alluvial mining and Au production in Peru through "Dredge" method
A26: reference product | B26: Refined Au
A27: location | B27: PE
A28: amount | B28: 1
A29: unit | B29: kilogram
A30: comment | B30: n/a
A31: Exchanges
A32: name | B32: reference product | C32: location | D32: amount | E32: unit | F32: database | G32: type | H32: categories | I32: uncertainty type | J32: pedigree | K32: loc | L32: scale | M32: minimum | N32: maximum
A33: =B25 -> Au alluvial mining and Au production in Peru through "Dredge" method | B33: =B26 -> Refined Au | C33: =B27 -> PE | D33: 1 | E33: kilogram | F33: =F9 -> Gold | G33: production
A34: =A9 -> [M+C+P+R] Gold (Au) production (alluvial - Dredge method) | B34: =B9 -> Refined Au | C34: =C9 -> PE | D34: =D9 -> 1 | E34: =E9 -> kilogram | F34: =F9 -> Gold | G34: technosphere

Sheet PR6_Au_PE_Alluvial_PartialChute
A1: Activity | B1: [M+C+P+R] Gold (Au) production (alluvial - Partial chute method)
A2: reference product | B2: Refined Au
A3: location | B3: PE
A4: amount | B4: 1
A5: unit | B5: kilogram
A6: comment | B6: n/a
A7: Exchanges
A8: name | B8: reference product | C8: location | D8: amount | E8: unit | F8: database | G8: type | H8: categories | I8: uncertainty type | J8: pedigree | K8: loc | L8: scale | M8: minimum | N8: maximum
A9: =B1 -> [M+C+P+R] Gold (Au) production (alluvial - Partial chute method) | B9: =B2 -> Refined Au | C9: =B3 -> PE | D9: 1 | E9: kilogram | F9: =Au_Market_GLO!B1 -> Gold | G9: production
A10: water pump operation, diesel | B10: water pump operation, diesel | C10: PE | D10: 408.9 | E10: megajoule | F10: ecoinvent 3.10 cutoff | G10: technosphere | J10: (1,1,2,1,1)
A11: market for diesel, burned in building machine | B11: diesel, burned in building machine | C11: GLO | D11: 214890 | E11: megajoule | F11: ecoinvent 3.10 cutoff | G11: technosphere | J11: (1,1,2,1,1)
A12: market for lubricating oil | B12: lubricating oil | C12: RoW | D12: 31.9 | E12: kilogram | F12: ecoinvent 3.10 cutoff | G12: technosphere | J12: (1,1,2,1,1)
A13: market for polyvinylchloride, bulk polymerised | B13: polyvinylchloride, bulk polymerised | C13: GLO | D13: 13.1 | E13: kilogram | F13: ecoinvent 3.10 cutoff | G13: technosphere | J13: (1,1,2,1,1)
A14: market for extrusion, plastic film | B14: extrusion, plastic film | C14: GLO | D14: 17.5 | E14: kilogram | F14: ecoinvent 3.10 cutoff | G14: technosphere | J14: (1,1,2,1,1)
A15: market for polypropylene, granulate | B15: polypropylene, granulate | C15: GLO | D15: 3.4 | E15: kilogram | F15: ecoinvent 3.10 cutoff | G15: technosphere | J15: (1,1,2,1,1)
A16: market for mercury | B16: mercury | C16: GLO | D16: 2 | E16: kilogram | F16: ecoinvent 3.10 cutoff | G16: technosphere | J16: (1,1,2,1,1)
A17: Water, river | D17: 50000 | E17: cubic meter | F17: biosphere3 | G17: biosphere | H17: natural resource::in water | J17: (1,1,2,1,1)
A18: Transformation, from forest, unspecified | D18: 667 | E18: square meter | F18: biosphere3 | G18: biosphere | H18: natural resource::land | J18: (1,1,2,1,1)
A19: Transformation, to mineral extraction site | D19: 667 | E19: square meter | F19: biosphere3 | G19: biosphere | H19: natural resource::land | J19: (1,1,2,1,1)
A20: Mercury II | D20: 0.1 | E20: kilogram | F20: biosphere3 | G20: biosphere | H20: air::urban air close to ground | J20: (1,1,2,1,1)
A21: Mercury II | D21: 1.3 | E21: kilogram | F21: biosphere3 | G21: biosphere | H21: air::non-urban air or from high stacks | J21: (1,1,2,1,1)
A22: Mercury II | D22: 0.3 | E22: kilogram | F22: biosphere3 | G22: biosphere | H22: soil | J22: (1,1,2,1,1)
A23: Mercury II | D23: 0.3 | E23: kilogram | F23: biosphere3 | G23: biosphere | H23: water::surface water | J23: (1,1,2,1,1)
A24: Mercury II | D24: 0.795 | E24: kilogram | F24: biosphere3 | G24: biosphere | H24: soil | J24: (1,1,2,1,1)
A26: Activity | B26: Au alluvial mining and Au production in Peru through "Partial chute" method
A27: reference product | B27: Refined Au
A28: location | B28: PE
A29: amount | B29: 1
A30: unit | B30: kilogram
A31: comment | B31: n/a
A32: Exchanges
A33: name | B33: reference product | C33: location | D33: amount | E33: unit | F33: database | G33: type | H33: categories | I33: uncertainty type | J33: pedigree | K33: loc | L33: scale | M33: minimum | N33: maximum
A34: =B26 -> Au alluvial mining and Au production in Peru through "Partial chute" method | B34: =B27 -> Refined Au | C34: =B28 -> PE | D34: 1 | E34: kilogram | F34: =F9 -> Gold | G34: production
A35: =A9 -> [M+C+P+R] Gold (Au) production (alluvial - Partial chute method) | B35: =B9 -> Refined Au | C35: =C9 -> PE | D35: =D9 -> 1 | E35: =E9 -> kilogram | F35: =F9 -> Gold | G35: technosphere

Sheet PR7_Au_PE_Alluvial_Chute
A1: Activity | B1: [M+C+P+R] Gold (Au) production (alluvial - Complete chute method)
A2: reference product | B2: Refined Au
A3: location | B3: PE
A4: amount | B4: 1
A5: unit | B5: kilogram
A6: comment | B6: n/a
A7: Exchanges
A8: name | B8: reference product | C8: location | D8: amount | E8: unit | F8: database | G8: type | H8: categories | I8: uncertainty type | J8: pedigree | K8: loc | L8: scale | M8: minimum | N8: maximum
A9: =B1 -> [M+C+P+R] Gold (Au) production (alluvial - Complete chute method) | B9: =B2 -> Refined Au | C9: =B3 -> PE | D9: 1 | E9: kilogram | F9: =Au_Market_GLO!B1 -> Gold | G9: production
A10: water pump operation, diesel | B10: water pump operation, diesel | C10: PE | D10: 121.8 | E10: megajoule | F10: ecoinvent 3.10 cutoff | G10: technosphere | J10: (1,1,2,1,1)
A11: market for diesel, burned in building machine | B11: diesel, burned in building machine | C11: GLO | D11: 128542.5 | E11: megajoule | F11: ecoinvent 3.10 cutoff | G11: technosphere | J11: (1,1,2,1,1)
A12: market for lubricating oil | B12: lubricating oil | C12: RoW | D12: 33.4 | E12: kilogram | F12: ecoinvent 3.10 cutoff | G12: technosphere | J12: (1,1,2,1,1)
A13: market for polyvinylchloride, bulk polymerised | B13: polyvinylchloride, bulk polymerised | C13: GLO | D13: 4.1 | E13: kilogram | F13: ecoinvent 3.10 cutoff | G13: technosphere | J13: (1,1,2,1,1)
A14: market for extrusion, plastic film | B14: extrusion, plastic film | C14: GLO | D14: 11 | E14: kilogram | F14: ecoinvent 3.10 cutoff | G14: technosphere | J14: (1,1,2,1,1)
A15: market for polypropylene, granulate | B15: polypropylene, granulate | C15: GLO | D15: 2.2 | E15: kilogram | F15: ecoinvent 3.10 cutoff | G15: technosphere | J15: (1,1,2,1,1)
A16: market for mercury | B16: mercury | C16: GLO | D16: 2 | E16: kilogram | F16: ecoinvent 3.10 cutoff | G16: technosphere | J16: (1,1,2,1,1)
A17: Water, river | D17: 50000 | E17: cubic meter | F17: biosphere3 | G17: biosphere | H17: natural resource::in water | J17: (1,1,2,1,1)
A18: Transformation, from forest, unspecified | D18: 417 | E18: square meter | F18: biosphere3 | G18: biosphere | H18: natural resource::land | J18: (1,1,2,1,1)
A19: Transformation, to mineral extraction site | D19: 417 | E19: square meter | F19: biosphere3 | G19: biosphere | H19: natural resource::land | J19: (1,1,2,1,1)
A20: Mercury II | D20: 0.1 | E20: kilogram | F20: biosphere3 | G20: biosphere | H20: air::urban air close to ground | J20: (1,1,2,1,1)
A21: Mercury II | D21: 1.3 | E21: kilogram | F21: biosphere3 | G21: biosphere | H21: air::non-urban air or from high stacks | J21: (1,1,2,1,1)
A22: Mercury II | D22: 0.3 | E22: kilogram | F22: biosphere3 | G22: biosphere | H22: soil | J22: (1,1,2,1,1)
A23: Mercury II | D23: 0.3 | E23: kilogram | F23: biosphere3 | G23: biosphere | H23: water::surface water | J23: (1,1,2,1,1)
A24: Mercury II | D24: 0.795 | E24: kilogram | F24: biosphere3 | G24: biosphere | H24: soil | J24: (1,1,2,1,1)
A26: Activity | B26: Au alluvial mining and Au production in Peru through "Complete chute" method
A27: reference product | B27: Refined Au
A28: location | B28: PE
A29: amount | B29: 1
A30: unit | B30: kilogram
A31: comment | B31: n/a
A32: Exchanges
A33: name | B33: reference product | C33: location | D33: amount | E33: unit | F33: database | G33: type | H33: categories | I33: uncertainty type | J33: pedigree | K33: loc | L33: scale | M33: minimum | N33: maximum
A34: =B26 -> Au alluvial mining and Au production in Peru through "Complete chute" method | B34: =B27 -> Refined Au | C34: =B28 -> PE | D34: 1 | E34: kilogram | F34: =F9 -> Gold | G34: production
A35: =A9 -> [M+C+P+R] Gold (Au) production (alluvial - Complete chute method) | B35: =B9 -> Refined Au | C35: =C9 -> PE | D35: =D9 -> 1 | E35: =E9 -> kilogram | F35: =F9 -> Gold | G35: technosphere

Sheet PR8_Au_CO_OpenPit
A1: Activity | B1: [M+C+P+R] Gold (Au) production (from ore)
A2: reference product | B2: Refined Au
A3: location | B3: CO
A4: amount | B4: 1
A5: unit | B5: kilogram
A6: comment | B6: Allocated unit process, considering as allocation factors (AF): 98.6% for Au (1 kg) and 1.4% for Ag (1.1 kg).
A7: Exchanges
A8: name | B8: reference product | C8: location | D8: amount | E8: unit | F8: database | G8: type | H8: categories | I8: uncertainty type | J8: pedigree | K8: loc | L8: scale | M8: minimum | N8: maximum
A9: =B1 -> [M+C+P+R] Gold (Au) production (from ore) | B9: =B2 -> Refined Au | C9: =B3 -> CO | D9: 1 | E9: kilogram | F9: =Au_Market_GLO!B1 -> Gold | G9: production
A10: electricity production, photovoltaic, 570kWp open ground installation, multi-Si | B10: electricity, low voltage | C10: RoW | D10: 35064.136 | E10: kilowatt hour | F10: ecoinvent 3.10 cutoff | G10: technosphere | J10: (1,1,1,1,1)
A11: heat production, air-water heat pump 10kW | B11: heat, air-water heat pump 10kW | C11: RoW | D11: 0.81739674 | E11: megajoule | F11: ecoinvent 3.10 cutoff | G11: technosphere | J11: (1,1,1,1,1)
A12: market for compressed air, 800 kPa gauge | B12: compressed air, 800 kPa gauge | C12: RoW | D12: 454.71438 | E12: cubic meter | F12: ecoinvent 3.10 cutoff | G12: technosphere | J12: (1,1,1,1,1)
A13: market for non-sulfidic overburden, off-site | B13: non-sulfidic overburden, off-site | C13: GLO | D13: -3.5851642e+09 | E13: kilogram | F13: ecoinvent 3.10 cutoff | G13: technosphere | J13: (1,1,1,1,1)
A14: market for diesel, burned in building machine | B14: diesel, burned in building machine | C14: GLO | D14: 59494.066 | E14: megajoule | F14: ecoinvent 3.10 cutoff | G14: technosphere | J14: (1,1,1,1,1)
A15: market for electricity, medium voltage | B15: electricity, medium voltage | C15: CO | D15: 29172.211 | E15: kilowatt hour | F15: ecoinvent 3.10 cutoff | G15: technosphere | J15: (1,1,1,1,1)
A16: market for liquefied petroleum gas | B16: liquefied petroleum gas | C16: CO | D16: 17.737361 | E16: kilogram | F16: ecoinvent 3.10 cutoff | G16: technosphere | J16: (1,1,1,1,1)
A17: market for explosive, tovex | B17: explosive, tovex | C17: GLO | D17: 729.44899 | E17: kilogram | F17: ecoinvent 3.10 cutoff | G17: technosphere | J17: (1,1,1,1,1)
A18: market for industrial machine, heavy, unspecified | B18: industrial machine, heavy, unspecified | C18: RoW | D18: 786.35636 | E18: kilogram | F18: ecoinvent 3.10 cutoff | G18: technosphere | J18: (1,1,1,1,1)
A19: market for sodium cyanide | B19: sodium cyanide | C19: RoW | D19: 103.46794 | E19: kilogram | F19: ecoinvent 3.10 cutoff | G19: technosphere | J19: (1,1,1,1,1)
A20: market for sodium hydroxide, without water, in 50% solution state | B20: sodium hydroxide, without water, in 50% solution state | C20: RoW | D20: 5.5872688 | E20: kilogram | F20: ecoinvent 3.10 cutoff | G20: technosphere | J20: (1,1,1,1,1)
A21: market for lime, packed | B21: lime, packed | C21: RoW | D21: 118.98813 | E21: kilogram | F21: ecoinvent 3.10 cutoff | G21: technosphere | J21: (1,1,1,1,1)
... A28: market for hydrochloric acid, without water, in 30% solution state | B28: hydrochloric acid, without water, in 30% solution state | C28: RoW | D28: 51.268365 | E28: kilogram | F28: ecoinvent 3.10 cutoff | G28: technosphere | J28: (1,1,1,1,1)
A29: Water, unspecified natural origin | D29: 3000.5703 | E29: cubic meter | F29: biosphere3 | G29: biosphere | H29: natural resource::in ground | J29: (1,1,1,1,1)
A31: Activity | B31: Au ore mining and Au production in Colombia/Antioquia
A32: reference product | B32: Refined Au
A33: location | B33: CO
A34: amount | B34: 1
A35: unit | B35: kilogram
A36: comment | B36: n/a
A37: Exchanges
A38: name | B38: reference product | C38: location | D38: amount | E38: unit | F38: database | G38: type | H38: categories | I38: uncertainty type | J38: pedigree | K38: loc | L38: scale | M38: minimum | N38: maximum
A39: =B31 -> Au ore mining and Au production in Colombia/Antioquia | B39: =B32 -> Refined Au | C39: =B33 -> CO | D39: 1 | E39: kilogram | F39: =F9 -> Gold | G39: production
A40: =A9 -> [M+C+P+R] Gold (Au) production (from ore) | B40: =B9 -> Refined Au | C40: =C9 -> CO | D40: 1 | E40: =E9 -> kilogram | F40: =F9 -> Gold | G40: technosphere

Sheet PR9_Au_CO_Alluvial
A1: Activity | B1: [M+C+P+R] Gold (Au) production (alluvial)
A2: reference product | B2: Refined Au
A3: location | B3: CO
A4: amount | B4: 1
A5: unit | B5: kilogram
A6: comment | B6: Allocated unit process, considering as allocation factors (AF): 99.98% for Au (1 kg) and 0.02% for Fe (0.6 kg).
A7: Exchanges
A8: name | B8: reference product | C8: location | D8: amount | E8: unit | F8: database | G8: type | H8: categories | I8: uncertainty type | J8: pedigree | K8: loc | L8: scale | M8: minimum | N8: maximum
A9: =B1 -> [M+C+P+R] Gold (Au) production (alluvial) | B9: =B2 -> Refined Au | C9: =B3 -> CO | D9: 1 | E9: kilogram | F9: =Au_Market_GLO!B1 -> Gold | G9: production
A10: electricity production, photovoltaic, 570kWp open ground installation, multi-Si | B10: electricity, low voltage | C10: RoW | D10: 634287.64 | E10: kilowatt hour | F10: ecoinvent 3.10 cutoff | G10: technosphere | J10: (1,1,1,1,1)
A11: heat production, air-water heat pump 10kW | B11: heat, air-water heat pump 10kW | C11: RoW | D11: 18.770614 | E11: megajoule | F11: ecoinvent 3.10 cutoff | G11: technosphere | J11: (1,1,1,1,1)
A12: market for compressed air, 800 kPa gauge | B12: compressed air, 800 kPa gauge | C12: RoW | D12: 0.28517482 | E12: cubic meter | F12: ecoinvent 3.10 cutoff | G12: technosphere | J12: (1,1,1,1,1)
A13: market for compressed air, 800 kPa gauge | B13: compressed air, 800 kPa gauge | C13: RoW | D13: 0.28517482 | E13: cubic meter | F13: ecoinvent 3.10 cutoff | G13: technosphere | J13: (1,1,1,1,1)
A14: market for non-sulfidic overburden, off-site | B14: non-sulfidic overburden, off-site | C14: GLO | D14: -3.2058402e+10 | E14: kilogram | F14: ecoinvent 3.10 cutoff | G14: technosphere | J14: (1,1,1,1,1)
A15: market for diesel, burned in building machine | B15: diesel, burned in building machine | C15: GLO | D15: 361.22143 | E15: megajoule | F15: ecoinvent 3.10 cutoff | G15: technosphere | J15: (1,1,1,1,1)
A16: market for electricity, medium voltage | B16: electricity, medium voltage | C16: CO | D16: 22665.928 | E16: kilowatt hour | F16: ecoinvent 3.10 cutoff | G16: technosphere | J16: (1,1,1,1,1)
A17: market for liquefied petroleum gas | B17: liquefied petroleum gas | C17: CO | D17: 0.10531237 | E17: kilogram | F17: ecoinvent 3.10 cutoff | G17: technosphere | J17: (1,1,1,1,1)
A18: market for industrial machine, heavy, unspecified | B18: industrial machine, heavy, unspecified | C18: RoW | D18: 8514.5052 | E18: kilogram | F18: ecoinvent 3.10 cutoff | G18: technosphere | J18: (1,1,1,1,1)
A19: market for chemical, organic | B19: chemical, organic | C19: GLO | D19: 0.15158399 | E19: kilogram | F19: ecoinvent 3.10 cutoff | G19: technosphere | J19: (1,1,1,1,1)
A20: market for non-ionic surfactant | B20: non-ionic surfactant | C20: GLO | D20: 0.074179402 | E20: kilogram | F20: ecoinvent 3.10 cutoff | G20: technosphere | J20: (1,1,1,1,1)
A21: market for borax, anhydrous, powder | B21: borax, anhydrous, powder | C21: GLO | D21: 75.146959 | E21: kilogram | F21: ecoinvent 3.10 cutoff | G21: technosphere | J21: (1,1,1,1,1)
... A24: market for polyacrylamide | B24: polyacrylamide | C24: GLO | D24: 0.14384354 | E24: kilogram | F24: ecoinvent 3.10 cutoff | G24: technosphere | J24: (1,1,1,1,1)
A25: Water, unspecified natural origin | D25: 46765.275 | E25: cubic meter | F25: biosphere3 | G25: biosphere | H25: natural resource::in ground | J25: (1,1,1,1,1)
A27: Activity | B27: Au alluvial mining and Au production in Colombia/Antioquia
A28: reference product | B28: Refined Au
A29: location | B29: CO
A30: amount | B30: 1
A31: unit | B31: kilogram
A32: comment | B32: n/a
A33: Exchanges
A34: name | B34: reference product | C34: location | D34: amount | E34: unit | F34: database | G34: type | H34: categories | I34: uncertainty type | J34: pedigree | K34: loc | L34: scale | M34: minimum | N34: maximum
A35: =B27 -> Au alluvial mining and Au production in Colombia/Antioquia | B35: =B28 -> Refined Au | C35: =B29 -> CO | D35: 1 | E35: kilogram | F35: =F9 -> Gold | G35: production
A36: =A9 -> [M+C+P+R] Gold (Au) production (alluvial) | B36: =B9 -> Refined Au | C36: =C9 -> CO | D36: 1 | E36: =E9 -> kilogram | F36: =F9 -> Gold | G36: technosphere

Sheet PR10_Au_PE_OpenPit
A1: Activity | B1: [M+C+P+R] Gold (Au) production (from ore)
A2: reference product | B2: Refined Au
A3: location | B3: PE
A4: amount | B4: 1
A5: unit | B5: kilogram
A6: comment | B6: Allocated unit process, considering as allocation factors (AF): 98.3% for Au (1 kg) and 1.7% for Ag (1.3 kg).
A7: Exchanges
A8: name | B8: reference product | C8: location | D8: amount | E8: unit | F8: database | G8: type | H8: categories | I8: uncertainty type | J8: pedigree | K8: loc | L8: scale | M8: minimum | N8: maximum
A9: =B1 -> [M+C+P+R] Gold (Au) production (from ore) | B9: =B2 -> Refined Au | C9: =B3 -> PE | D9: 1 | E9: kilogram | F9: =Au_Market_GLO!B1 -> Gold | G9: production
A10: market for electricity, medium voltage | B10: electricity, medium voltage | C10: PE | D10: 3099.441 | E10: kilowatt hour | F10: ecoinvent 3.10 cutoff | G10: technosphere | J10: (3,1,5,1,1)
A11: market for lime, packed | B11: lime, packed | C11: RoW | D11: 830.06421 | E11: kilogram | F11: ecoinvent 3.10 cutoff | G11: technosphere | J11: (3,1,5,1,1)
A12: market for iron(III) chloride, without water, in 14% iron solution state | B12: iron(III) chloride, without water, in 14% iron solution state | C12: GLO | D12: 7.4038391 | E12: kilogram | F12: ecoinvent 3.10 cutoff | G12: technosphere | J12: (3,1,5,1,1)
A13: market for polyacrylamide | B13: polyacrylamide | C13: GLO | D13: 9.6145628 | E13: kilogram | F13: ecoinvent 3.10 cutoff | G13: technosphere | J13: (3,1,5,1,1)
A14: market for sulfuric acid | B14: sulfuric acid | C14: RoW | D14: 0.00023358591 | E14: kilogram | F14: ecoinvent 3.10 cutoff | G14: technosphere | J14: (3,1,5,1,1)
A15: market for electricity, medium voltage | B15: electricity, medium voltage | C15: PE | D15: 28.572562 | E15: kilowatt hour | F15: ecoinvent 3.10 cutoff | G15: technosphere | J15: (3,1,5,1,1)
A16: market for chemical factory | B16: chemical factory | C16: GLO | D16: 0.048552499 | E16: kilogram | F16: ecoinvent 3.10 cutoff | G16: technosphere | J16: (3,1,5,1,1)
A17: market for chlorine, liquid | B17: chlorine, liquid | C17: RoW | D17: 122.00693 | E17: kilogram | F17: ecoinvent 3.10 cutoff | G17: technosphere | J17: (3,1,5,1,1)
A18: market for iron(III) chloride, without water, in 14% iron solution state | B18: iron(III) chloride, without water, in 14% iron solution state | C18: GLO | D18: 3.1492386 | E18: kilogram | F18: ecoinvent 3.10 cutoff | G18: technosphere | J18: (3,1,5,1,1)
A19: market for sodium hydrosulfide | B19: sodium hydrosulfide | C19: GLO | D19: 0.37749151 | E19: kilogram | F19: ecoinvent 3.10 cutoff | G19: technosphere | J19: (3,1,5,1,1)
A20: market for polyacrylamide | B20: polyacrylamide | C20: GLO | D20: 3.1283827 | E20: kilogram | F20: ecoinvent 3.10 cutoff | G20: technosphere | J20: (3,1,5,1,1)
A21: market for sulfuric acid | B21: sulfuric acid | C21: RoW | D21: 0.00051201197 | E21: kilogram | F21: ecoinvent 3.10 cutoff | G21: technosphere | J21: (3,1,5,1,1)
... A64: market for diesel, burned in building machine | B64: diesel, burned in building machine | C64: GLO | D64: 1.0208956e-07 | E64: megajoule | F64: ecoinvent 3.10 cutoff | G64: technosphere | J64: (3,1,5,1,1)
A65: Transformation, from forest, unspecified | D65: 333.17201 | E65: square meter | F65: biosphere3 | G65: biosphere | H65: natural resource::land | J65: (3,1,5,1,1)
A66: Transformation, to mineral extraction site | D66: 333.17201 | E66: square meter | F66: biosphere3 | G66: biosphere | H66: natural resource::land | J66: (3,1,5,1,1)
A68: Activity | B68: Au open-pit mining and Au production in Peru
A69: reference product | B69: Refined Au
A70: location | B70: PE
A71: amount | B71: 1
A72: unit | B72: kilogram
A73: comment | B73: n/a
A74: Exchanges
A75: name | B75: reference product | C75: location | D75: amount | E75: unit | F75: database | G75: type | H75: categories | I75: uncertainty type | J75: pedigree | K75: loc | L75: scale | M75: minimum | N75: maximum
A76: =B68 -> Au open-pit mining and Au production in Peru | B76: =B69 -> Refined Au | C76: =B70 -> PE | D76: 1 | E76: kilogram | F76: =F9 -> Gold | G76: production
A77: =A9 -> [M+C+P+R] Gold (Au) production (from ore) | B77: =B9 -> Refined Au | C77: =C9 -> PE | D77: 1 | E77: =E9 -> kilogram | F77: =F9 -> Gold | G77: technosphere

Sheet PR11_Au_CN_CuSlime
A1: Activity | B1: [P+R] Gold (Au) production (from anode slime)
A2: reference product | B2: Refined Au
A3: location | B3: CN
A4: amount | B4: 1
A5: unit | B5: kilogram
A6: comment | B6: Allocated unit process, considering as allocation factors (AF): 75.4% for Au (1 kg), 22.2% for Ag (23 kg), 1.3% for Te (14 kg CuTe) and 1.1% for Se (27 kg).
A7: Exchanges
A8: name | B8: reference product | C8: location | D8: amount | E8: unit | F8: database | G8: type | H8: categories | I8: uncertainty type | J8: pedigree | K8: loc | L8: scale | M8: minimum | N8: maximum
A9: =B1 -> [P+R] Gold (Au) production (from anode slime) | B9: =B2 -> Refined Au | C9: =B3 -> CN | D9: 1 | E9: kilogram | F9: =Au_Market_GLO!B1 -> Gold | G9: production
A10: market for sulfuric acid | B10: sulfuric acid | C10: RoW | D10: 17.884575 | E10: kilogram | F10: ecoinvent 3.10 cutoff | G10: technosphere | J10: (1,5,1,1,1)
A11: market for silica sand | B11: silica sand | C11: GLO | D11: 22.109704 | E11: kilogram | F11: ecoinvent 3.10 cutoff | G11: technosphere | J11: (1,5,1,1,1)
A12: market for soda ash, dense | B12: soda ash, dense | C12: GLO | D12: 25.274037 | E12: kilogram | F12: ecoinvent 3.10 cutoff | G12: technosphere | J12: (1,5,1,1,1)
A13: market for sodium hydroxide, without water, in 50% solution state | B13: sodium hydroxide, without water, in 50% solution state | C13: RoW | D13: 323.49775 | E13: kilogram | F13: ecoinvent 3.10 cutoff | G13: technosphere | J13: (1,5,1,1,1)
A14: market for hydrochloric acid, without water, in 30% solution state | B14: hydrochloric acid, without water, in 30% solution state | C14: RoW | D14: 14.589335 | E14: kilogram | F14: ecoinvent 3.10 cutoff | G14: technosphere | J14: (1,5,1,1,1)
A15: market for nitric acid, without water, in 50% solution state | B15: nitric acid, without water, in 50% solution state | C15: RoW | D15: 3.841437 | E15: kilogram | F15: ecoinvent 3.10 cutoff | G15: technosphere | J15: (1,5,1,1,1)
A16: market for sodium chlorate, powder | B16: sodium chlorate, powder | C16: RoW | D16: 0.76738459 | E16: kilogram | F16: ecoinvent 3.10 cutoff | G16: technosphere | J16: (1,5,1,1,1)
A17: market for ammonium chloride | B17: ammonium chloride | C17: GLO | D17: 0.027084162 | E17: kilogram | F17: ecoinvent 3.10 cutoff | G17: technosphere | J17: (1,5,1,1,1)
A18: market group for electricity, medium voltage | B18: electricity, medium voltage | C18: CN | D18: 1420.0226 | E18: kilowatt hour | F18: ecoinvent 3.10 cutoff | G18: technosphere | J18: (1,5,1,1,1)
A19: market for copper slag | B19: copper slag | C19: GLO | D19: -216.83129 | E19: kilogram | F19: ecoinvent 3.10 cutoff | G19: technosphere | J19: (1,5,1,1,1)
A20: Water, unspecified natural origin | D20: 0.51722173 | E20: cubic meter | F20: biosphere3 | G20: biosphere | H20: natural resource::in ground | J20: (1,5,1,1,1)
A21: Carbon dioxide, fossil | D21: 505.562 | E21: kilogram | F21: biosphere3 | G21: biosphere | H21: air | J21: (1,5,1,1,1)
A23: Activity | B23: Au production in China through Cu anode slime processing
A24: reference product | B24: Refined Au
A25: location | B25: CN
A26: amount | B26: 1
A27: unit | B27: kilogram
A28: comment | B28: An ecoinvent activity is here included to model the upstream anode slime production. Applied AF: "anode slime from electrorefining of copper, anode" input = 75.4%.
A29: Exchanges
A30: name | B30: reference product | C30: location | D30: amount | E30: unit | F30: database | G30: type | H30: categories | I30: uncertainty type | J30: pedigree | K30: loc | L30: scale | M30: minimum | N30: maximum
A31: =B23 -> Au production in China through Cu anode slime processing | B31: =B24 -> Refined Au | C31: =B25 -> CN | D31: 1 | E31: kilogram | F31: =F9 -> Gold | G31: production
A32: =A9 -> [P+R] Gold (Au) production (from anode slime) | B32: =B9 -> Refined Au | C32: =C9 -> CN | D32: 1 | E32: =E9 -> kilogram | F32: =F9 -> Gold | G32: technosphere
A33: market for anode slime from electrorefining of copper, anode | B33: anode slime from electrorefining of copper, anode | C33: GLO | D33: 451.4027 | E33: kilogram | F33: ecoinvent 3.10 cutoff | G33: technosphere

Sheet PR12_Au_AU
A1: Activity | B1: [M+C+P+R] Gold (Au) production (from ore)
A2: reference product | B2: Refined Au
A3: location | B3: AU
A4: amount | B4: 1
A5: unit | B5: kilogram
A6: comment | B6: Allocated unit process, considering as allocation factors (AF): 99.9% for Au (1 kg) and 0.1% for Ag (0.1 kg). The co-produced sulfuric acid is dealt through substitution.
A7: Exchanges
A8: name | B8: reference product | C8: location | D8: amount | E8: unit | F8: database | G8: type | H8: categories | I8: uncertainty type | J8: pedigree | K8: loc | L8: scale | M8: minimum | N8: maximum
A9: =B1 -> [M+C+P+R] Gold (Au) production (from ore) | B9: =B2 -> Refined Au | C9: =B3 -> AU | D9: 1 | E9: kilogram | F9: =Au_Market_GLO!B1 -> Gold | G9: production
A10: market for sulfuric acid | B10: sulfuric acid | C10: RoW | D10: -30.288786 | E10: kilogram | F10: ecoinvent 3.10 cutoff | G10: technosphere | J10: (2,5,5,1,1)
A11: market for iron pellet | B11: iron pellet | C11: GLO | D11: 86.539389 | E11: kilogram | F11: ecoinvent 3.10 cutoff | G11: technosphere | J11: (2,5,5,1,1)
A12: market for sodium cyanide | B12: sodium cyanide | C12: RoW | D12: 18.972097 | E12: kilogram | F12: ecoinvent 3.10 cutoff | G12: technosphere | J12: (2,5,5,1,1)
A13: market for lime, packed | B13: lime, packed | C13: RoW | D13: 63.240323 | E13: kilogram | F13: ecoinvent 3.10 cutoff | G13: technosphere | J13: (2,5,5,1,1)
A14: market for sodium hydroxide, without water, in 50% solution state | B14: sodium hydroxide, without water, in 50% solution state | C14: RoW | D14: 1164.9533 | E14: kilogram | F14: ecoinvent 3.10 cutoff | G14: technosphere | J14: (2,5,5,1,1)
A15: market for sulfuric acid | B15: sulfuric acid | C15: RoW | D15: 0.66568761 | E15: kilogram | F15: ecoinvent 3.10 cutoff | G15: technosphere | J15: (2,5,5,1,1)
A16: market for carbon black | B16: carbon black | C16: GLO | D16: 16.975034 | E16: kilogram | F16: ecoinvent 3.10 cutoff | G16: technosphere | J16: (2,5,5,1,1)
A17: market for hydrochloric acid, without water, in 30% solution state | B17: hydrochloric acid, without water, in 30% solution state | C17: RoW | D17: 136.46596 | E17: kilogram | F17: ecoinvent 3.10 cutoff | G17: technosphere | J17: (2,5,5,1,1)
A18: market for steam, in chemical industry | B18: steam, in chemical industry | C18: RoW | D18: 259.61817 | E18: kilogram | F18: ecoinvent 3.10 cutoff | G18: technosphere | J18: (2,5,5,1,1)
A19: market for mercury | B19: mercury | C19: GLO | D19: 1.2980908e-08 | E19: kilogram | F19: ecoinvent 3.10 cutoff | G19: technosphere | J19: (2,5,5,1,1)
A20: market for zinc | B20: zinc | C20: GLO | D20: 2.8957411 | E20: kilogram | F20: ecoinvent 3.10 cutoff | G20: technosphere | J20: (2,5,5,1,1)
A21: market for electricity, medium voltage | B21: electricity, medium voltage | C21: AU | D21: 4326.9694 | E21: kilowatt hour | F21: ecoinvent 3.10 cutoff | G21: technosphere | J21: (2,5,5,1,1)
A23: Activity | B23: Au ore mining and Au production in Australia
A24: reference product | B24: Refined Au
A25: location | B25: AU
A26: amount | B26: 1
A27: unit | B27: kilogram
A28: comment | B28: n/a
A29: Exchanges
A30: name | B30: reference product | C30: location | D30: amount | E30: unit | F30: database | G30: type | H30: categories | I30: uncertainty type | J30: pedigree | K30: loc | L30: scale | M30: minimum | N30: maximum
A31: =B23 -> Au ore mining and Au production in Australia | B31: =B24 -> Refined Au | C31: =B25 -> AU | D31: 1 | E31: kilogram | F31: =F9 -> Gold | G31: production
A32: =A9 -> [M+C+P+R] Gold (Au) production (from ore) | B32: =B9 -> Refined Au | C32: =C9 -> AU | D32: 1 | E32: =E9 -> kilogram | F32: =F9 -> Gold | G32: technosphere

Sheet PR13_Au_ZA
A1: Activity | B1: [M+C+P+R] Gold (Au) production (from ore)
A2: reference product | B2: Refined Au
A3: location | B3: ZA
A4: amount | B4: 1
A5: unit | B5: kilogram
A6: comment | B6: Allocated unit process, considering as allocation factors (AF): 99.9% for Au (1 kg) and 0.1% for Ag (0.1 kg). The co-produced sulfuric acid is dealt through substitution.
A7: Exchanges
A8: name | B8: reference product | C8: location | D8: amount | E8: unit | F8: database | G8: type | H8: categories | I8: uncertainty type | J8: pedigree | K8: loc | L8: scale | M8: minimum | N8: maximum
A9: =B1 -> [M+C+P+R] Gold (Au) production (from ore) | B9: =B2 -> Refined Au | C9: =B3 -> ZA | D9: 1 | E9: kilogram | F9: =Au_Market_GLO!B1 -> Gold | G9: production
A10: market for sulfuric acid | B10: sulfuric acid | C10: RoW | D10: -377.22298 | E10: kilogram | F10: ecoinvent 3.10 cutoff | G10: technosphere | J10: (2,5,5,1,1)
A11: market for iron pellet | B11: iron pellet | C11: GLO | D11: 215.23899 | E11: kilogram | F11: ecoinvent 3.10 cutoff | G11: technosphere | J11: (2,5,5,1,1)
A12: market for zinc | B12: zinc | C12: GLO | D12: 0.0066568761 | E12: kilogram | F12: ecoinvent 3.10 cutoff | G12: technosphere | J12: (2,5,5,1,1)
A13: market for sodium cyanide | B13: sodium cyanide | C13: RoW | D13: 46.598132 | E13: kilogram | F13: ecoinvent 3.10 cutoff | G13: technosphere | J13: (2,5,5,1,1)
A14: market for lime, packed | B14: lime, packed | C14: RoW | D14: 157.54607 | E14: kilogram | F14: ecoinvent 3.10 cutoff | G14: technosphere | J14: (2,5,5,1,1)
A15: market for sodium hydroxide, without water, in 50% solution state | B15: sodium hydroxide, without water, in 50% solution state | C15: RoW | D15: 26.627504 | E15: kilogram | F15: ecoinvent 3.10 cutoff | G15: technosphere | J15: (2,5,5,1,1)
A16: market for sulfuric acid | B16: sulfuric acid | C16: RoW | D16: 0.66568761 | E16: kilogram | F16: ecoinvent 3.10 cutoff | G16: technosphere | J16: (2,5,5,1,1)
A17: market for carbon black | B17: carbon black | C17: GLO | D17: 42.160215 | E17: kilogram | F17: ecoinvent 3.10 cutoff | G17: technosphere | J17: (2,5,5,1,1)
A18: market for hydrochloric acid, without water, in 30% solution state | B18: hydrochloric acid, without water, in 30% solution state | C18: RoW | D18: 33.28438 | E18: kilogram | F18: ecoinvent 3.10 cutoff | G18: technosphere | J18: (2,5,5,1,1)
A19: market for steam, in chemical industry | B19: steam, in chemical industry | C19: RoW | D19: 643.49802 | E19: kilogram | F19: ecoinvent 3.10 cutoff | G19: technosphere | J19: (2,5,5,1,1)
A20: market for mercury | B20: mercury | C20: GLO | D20: 1.0651002e-08 | E20: kilogram | F20: ecoinvent 3.10 cutoff | G20: technosphere | J20: (2,5,5,1,1)
A21: market for zinc | B21: zinc | C21: GLO | D21: 7.1006678 | E21: kilogram | F21: ecoinvent 3.10 cutoff | G21: technosphere | J21: (2,5,5,1,1)
A22: market for electricity, medium voltage | B22: electricity, medium voltage | C22: ZA | D22: 9541.5224 | E22: kilowatt hour | F22: ecoinvent 3.10 cutoff | G22: technosphere | J22: (2,5,5,1,1)
A24: Activity | B24: Au ore mining and Au production in South Africa
A25: reference product | B25: Refined Au
A26: location | B26: ZA
A27: amount | B27: 1
A28: unit | B28: kilogram
A29: comment | B29: n/a
A30: Exchanges
