Workbook

Sheet Note
A1: skip
B2: Life cycle inventories of global metal and mineral supply chains: a comprehensive data review, analysis and processing Frédéric Laia*, Stéphanie Mullera, Audrey Philippea, Robert Istrateb, Brenda Miranda Xicotencatlb, Afsoon Mansouri Askic, Aina Mas Fonsd,a, Juliana Segura-Salazare, Jair Santillán Saldivara, Alexander Cimprichf, Stephen Northeyg, Lígia da Silva Limah, Lieselot Booneh, Ryosuke Yokoii, Kamrul Islami, Ioanna Paschalidouj, Felipe Cerdask,l, Victor Balboa-Espinozae, Anish Koyamparambathd, Diae Henniouia, Victoire Collignona, Aurélien Reysa, Gyslain Ngadi Sakatadim, Jo Dewulfh, Bernhard Steubingb, Christoph Helbigc, Gaétan Lefebvrea, Gian Andrea Blenginin,m, Valeria Supertio, Masaharu Motoshitai, Guido Sonnemannd, Kwame Awuah-Offeij, Steven B. Youngf, Shinsuke Murakamip, Antoine Beylota aBRGM, F-45060 Orléans, France bInstitute of Environmental Sciences (CML), Leiden University, Einsteinweg 2, 2333 CC Leiden, NL cEcological Resource Technology, University of Bayreuth, Universitätstr. 30, 95447 Bayreuth, Germany dUniv. Bordeaux, CNRS, Bordeaux INP, ISM, UMR 5255, F-33400 Talence, France eSustainable Minerals Institute, The University of Queensland, QLD, 4072, Australia fSchool of Environment, Enterprise and Development, University of Waterloo, 200 University Avenue West, Waterloo, Ontario N2L 3G1, Canada gUniversity of Technology Sydney, Institute for Sustainable Futures, Australia hSustainable Systems Engineering (STEN), Department of Green Chemistry and Technology, Faculty of Bioscience Engineering, Ghent University, Coupure Links 653, 9000 Ghent, Belgium iAIST, 305-8569 Tsukuba, Japan jMining & Explosives Engineering, Missouri University of Science & Technology, Rolla, MO, USA 65409 kInstitute for Sustainable Energy Systems (INSYS), Technical University of Applied Sciences Würzburg-Schweinfurt (THWS), Ignaz-Schön-Straße 11, Schweinfurt, Germany lFraunhofer Institute for Surface Engineering and Thin Films IST, Riedenkamp 2, Braunschweig 38108, Germany mDepartment of Environment, Land and Infrastructure Engineering, Politecnico di Torino, Corso Duca degli Abruzzi, 24, 10129 Torino, Italy nUniversity of Turin, Earth Sciences Department (DST), Via Valperga Caluso, 35 – 10125 Torino, Italy oecoinvent association, Technopark, Technoparkstrasse 1, 8005 Zürich, Switzerland pGraduate School of Engineering, The University of Tokyo, Tokyo 113-8656, Japan *Corresponding author: f.lai@brgm.fr This file provides all LCI datasets developed for Beryllium (Be), with distinguishing its global market and each individual production route.
B33: Sheet | C33: Corresponding route
B34: Be_Market_GLO | C34: Be global market
B35: PR1_Be_US | C35: Bertrandite ore mining and Be metal production in the US

Sheet Be_Market_GLO
A1: database | B1: Beryllium
A3: Activity | B3: Beryllium (Be) global market
A4: reference product | B4: Be metal
A5: location | B5: GLO
A6: amount | B6: 1
A7: unit | B7: kilogram
A8: comment | B8: n/a
A9: Exchanges
A10: name | B10: reference product | C10: location | D10: amount | E10: unit | F10: database | G10: type | H10: categories | I10: uncertainty type | J10: pedigree | K10: loc | L10: scale | M10: minimum | N10: maximum
A11: =B3 -> Beryllium (Be) global market | B11: =B4 -> Be metal | C11: =B5 -> GLO | D11: =B6 -> 1 | E11: =B7 -> kilogram | F11: =B1 -> Beryllium | G11: production
A12: =PR1_Be_US!A57 -> Bertrandite ore mining and Be metal production in the US | B12: =PR1_Be_US!B57 -> Be metal | C12: =PR1_Be_US!C57 -> US | D12: =PR1_Be_US!D57 -> 1 | E12: =PR1_Be_US!E57 -> kilogram | F12: =PR1_Be_US!F57 -> Beryllium | G12: technosphere

Sheet PR1_Be_US
A1: Activity | B1: [M+C+P] Bertrandite ore mining and Beryllium hydroxide (Be(OH)2) production
A2: reference product | B2: Be(OH)2
A3: location | B3: US
A4: amount | B4: 1
A5: unit | B5: kilogram
A6: comment | B6: n/a
A7: Exchanges
A8: name | B8: reference product | C8: location | D8: amount | E8: unit | F8: database | G8: type | H8: categories | I8: uncertainty type | J8: pedigree | K8: loc | L8: scale | M8: minimum | N8: maximum
A9: =B1 -> [M+C+P] Bertrandite ore mining and Beryllium hydroxide (Be(OH)2) production | B9: =B2 -> Be(OH)2 | C9: =B3 -> US | D9: 1 | E9: kilogram | F9: =Be_Market_GLO!B1 -> Beryllium | G9: production
A10: market for ammonia, anhydrous, liquid | B10: ammonia, anhydrous, liquid | C10: RNA | D10: 3.1236897 | E10: kilogram | F10: ecoinvent 3.10 cutoff | G10: technosphere | J10: (3.0,2.0,4.0,3.0,1.0)
A11: market for sulfuric acid | B11: sulfuric acid | C11: RoW | D11: 1.5513627 | E11: kilogram | F11: ecoinvent 3.10 cutoff | G11: technosphere | J11: (3.0,2.0,4.0,3.0,1.0)
A12: market for diesel, burned in diesel-electric generating set, 18.5kW | B12: diesel, burned in diesel-electric generating set, 18.5kW | C12: GLO | D12: 22.012579 | E12: megajoule | F12: ecoinvent 3.10 cutoff | G12: technosphere | J12: (3.0,2.0,4.0,3.0,1.0)
A13: market for natural gas, high pressure | B13: natural gas, high pressure | C13: US | D13: 0.41928721 | E13: cubic meter | F13: ecoinvent 3.10 cutoff | G13: technosphere | J13: (3.0,2.0,4.0,3.0,1.0)
A14: market group for electricity, medium voltage | B14: electricity, medium voltage | C14: US | D14: 4.425813 | E14: kilowatt hour | F14: ecoinvent 3.10 cutoff | G14: technosphere | J14: (3.0,2.0,4.0,3.0,1.0)
A15: market for transport, freight, lorry >32 metric ton, EURO3 | B15: transport, freight, lorry >32 metric ton, EURO3 | C15: RoW | D15: 0.016771488 | E15: ton kilometer | F15: ecoinvent 3.10 cutoff | G15: technosphere | J15: (3.0,2.0,4.0,3.0,1.0)
A16: market for conveyor belt | B16: conveyor belt | C16: GLO | D16: 6.9392034e-06 | E16: meter | F16: ecoinvent 3.10 cutoff | G16: technosphere | J16: (2.0,4.0,5.0,5.0,4.0)
A17: mine construction, open cast, non-ferrous metal | B17: mine infrastructure, open cast, non-ferrous metal | C17: GLO | D17: 4.5702306e-09 | E17: unit | F17: ecoinvent 3.10 cutoff | G17: technosphere | J17: (2.0,4.0,5.0,5.0,4.0)
A18: market for sulfidic tailings, generic | B18: sulfidic tailings, generic | C18: GLO | D18: -47.798742 | E18: kilogram | F18: ecoinvent 3.10 cutoff | G18: technosphere | J18: (nan,nan,nan,nan,nan)
A19: market for non-sulfidic overburden, off-site | B19: non-sulfidic overburden, off-site | C19: GLO | D19: -43.186583 | E19: kilogram | F19: ecoinvent 3.10 cutoff | G19: technosphere | J19: (nan,nan,nan,nan,nan)
A20: Beryllium | D20: 3.1236897 | E20: kilogram | F20: biosphere3 | G20: biosphere | H20: natural resource::in ground | J20: (3.0,2.0,4.0,3.0,1.0)
A21: Water, unspecified natural origin | D21: 0.77568134 | E21: cubic meter | F21: biosphere3 | G21: biosphere | H21: natural resource::in ground | J21: (3.0,2.0,4.0,3.0,1.0)
A22: Transformation, from unspecified | D22: 0.00078406709 | E22: square meter | F22: biosphere3 | G22: biosphere | H22: natural resource | J22: (2.0,4.0,5.0,5.0,4.0)
A23: Transformation, to mineral extraction site | D23: 0.00078406709 | E23: square meter | F23: biosphere3 | G23: biosphere | H23: natural resource | J23: (2.0,4.0,5.0,5.0,4.0)
A24: Transformation, to unspecified | D24: 0.00078406709 | E24: square meter | F24: biosphere3 | G24: biosphere | H24: natural resource | J24: (2.0,4.0,5.0,5.0,4.0)
A25: Occupation, mineral extraction site | D25: 0.034591195 | E25: square meter-year | F25: biosphere3 | G25: biosphere | H25: natural resource | J25: (2.0,4.0,5.0,5.0,4.0)
A27: Activity | B27: [R] Be metal production
A28: reference product | B28: Be metal
A29: location | B29: US
A30: amount | B30: 1
A31: unit | B31: kilogram
A32: comment | B32: n/a
A33: Exchanges
A34: name | B34: reference product | C34: location | D34: amount | E34: unit | F34: database | G34: type | H34: categories | I34: uncertainty type | J34: pedigree | K34: loc | L34: scale | M34: minimum | N34: maximum
A35: =B27 -> [R] Be metal production | B35: =B28 -> Be metal | C35: =B29 -> US | D35: 1 | E35: kilogram | F35: =F9 -> Beryllium | G35: production
A36: market for natural gas, high pressure | B36: natural gas, high pressure | C36: US | D36: 48.552632 | E36: cubic meter | F36: ecoinvent 3.10 cutoff | G36: technosphere | J36: (3.0,2.0,1.0,3.0,1.0)
A37: market group for electricity, medium voltage | B37: electricity, medium voltage | C37: US | D37: 512.50041 | E37: kilowatt hour | F37: ecoinvent 3.10 cutoff | G37: technosphere | J37: (3.0,2.0,1.0,3.0,1.0)
A38: market for ammonia, anhydrous, liquid | B38: ammonia, anhydrous, liquid | C38: RNA | D38: 4.4 | E38: kilogram | F38: ecoinvent 3.10 cutoff | G38: technosphere | J38: (3.0,2.0,1.0,3.0,1.0)
A39: market for hydrogen fluoride | B39: hydrogen fluoride | C39: RoW | D39: 4.9 | E39: kilogram | F39: ecoinvent 3.10 cutoff | G39: technosphere | J39: (3.0,2.0,1.0,3.0,1.0)
A40: market for sodium hydroxide, without water, in 50% solution state | B40: sodium hydroxide, without water, in 50% solution state | C40: RoW | D40: 14.2 | E40: kilogram | F40: ecoinvent 3.10 cutoff | G40: technosphere | J40: (3.0,2.0,1.0,3.0,1.0)
A41: market for magnesium | B41: magnesium | C41: GLO | D41: 3 | E41: kilogram | F41: ecoinvent 3.10 cutoff | G41: technosphere | J41: (3.0,2.0,1.0,3.0,1.0)
...
