Workbook

Sheet Note
A1: skip
B2: Life cycle inventories of global metal and mineral supply chains: a comprehensive data review, analysis and processing Frédéric Laia*, Stéphanie Mullera, Audrey Philippea, Robert Istrateb, Brenda Miranda Xicotencatlb, Afsoon Mansouri Askic, Aina Mas Fonsd,a, Juliana Segura-Salazare, Jair Santillán Saldivara, Alexander Cimprichf, Stephen Northeyg, Lígia da Silva Limah, Lieselot Booneh, Ryosuke Yokoii, Kamrul Islami, Ioanna Paschalidouj, Felipe Cerdask,l, Victor Balboa-Espinozae, Anish Koyamparambathd, Diae Henniouia, Victoire Collignona, Aurélien Reysa, Gyslain Ngadi Sakatadim, Jo Dewulfh, Bernhard Steubingb, Christoph Helbigc, Gaétan Lefebvrea, Gian Andrea Blenginin,m, Valeria Supertio, Masaharu Motoshitai, Guido Sonnemannd, Kwame Awuah-Offeij, Steven B. Youngf, Shinsuke Murakamip, Antoine Beylota aBRGM, F-45060 Orléans, France bInstitute of Environmental Sciences (CML), Leiden University, Einsteinweg 2, 2333 CC Leiden, NL cEcological Resource Technology, University of Bayreuth, Universitätstr. 30, 95447 Bayreuth, Germany dUniv. Bordeaux, CNRS, Bordeaux INP, ISM, UMR 5255, F-33400 Talence, France eSustainable Minerals Institute, The University of Queensland, QLD, 4072, Australia fSchool of Environment, Enterprise and Development, University of Waterloo, 200 University Avenue West, Waterloo, Ontario N2L 3G1, Canada gUniversity of Technology Sydney, Institute for Sustainable Futures, Australia hSustainable Systems Engineering (STEN), Department of Green Chemistry and Technology, Faculty of Bioscience Engineering, Ghent University, Coupure Links 653, 9000 Ghent, Belgium iAIST, 305-8569 Tsukuba, Japan jMining & Explosives Engineering, Missouri University of Science & Technology, Rolla, MO, USA 65409 kInstitute for Sustainable Energy Systems (INSYS), Technical University of Applied Sciences Würzburg-Schweinfurt (THWS), Ignaz-Schön-Straße 11, Schweinfurt, Germany lFraunhofer Institute for Surface Engineering and Thin Films IST, Riedenkamp 2, Braunschweig 38108, Germany mDepartment of Environment, Land and Infrastructure Engineering, Politecnico di Torino, Corso Duca degli Abruzzi, 24, 10129 Torino, Italy nUniversity of Turin, Earth Sciences Department (DST), Via Valperga Caluso, 35 – 10125 Torino, Italy oecoinvent association, Technopark, Technoparkstrasse 1, 8005 Zürich, Switzerland pGraduate School of Engineering, The University of Tokyo, Tokyo 113-8656, Japan *Corresponding author: f.lai@brgm.fr This file provides all LCI datasets developed for Cadmium (Cd), with distinguishing its global market and each individual production route.
B33: Sheet | C33: Corresponding route
B34: Cd_Market_GLO | C34: Cd global market
B35: PR1_Cd_CA_KiddCreek | C35: Cd recovery from Zn production in Canada/Kidd Creek
B36: PR2_Cd_CN_Yangtze_Hydro | C36: Cd recovery from Zn production in China/Yangtze through Hydrometallurgy

Sheet Cd_Market_GLO
A1: database | B1: Cadmium
A3: Activity | B3: Cadmium (Cd) global market
A4: reference product | B4: Refined Cd
A5: location | B5: GLO
A6: amount | B6: 1
A7: unit | B7: kilogram
A8: comment | B8: n/a
A9: Exchanges
A10: name | B10: reference product | C10: location | D10: amount | E10: unit | F10: database | G10: type | H10: categories | I10: uncertainty type | J10: pedigree | K10: loc | L10: scale | M10: minimum | N10: maximum
A11: =B3 -> Cadmium (Cd) global market | B11: =B4 -> Refined Cd | C11: =B5 -> GLO | D11: 1 | E11: =B7 -> kilogram | F11: =B1 -> Cadmium | G11: production
A12: =PR1_Cd_CA_KiddCreek!A56 -> Cd recovery from Zn production in Canada/Kidd Creek | B12: =PR1_Cd_CA_KiddCreek!B56 -> Refined Cd | C12: =PR1_Cd_CA_KiddCreek!C56 -> CA | D12: 0.15254237 | E12: =PR1_Cd_CA_KiddCreek!E56 -> kilogram | F12: =PR1_Cd_CA_KiddCreek!F56 -> Cadmium | G12: technosphere
A13: =PR2_Cd_CN_Yangtze_Hydro!A178 -> Cd recovery from Zn production in China/Yangtze through Hydrometallurgy | B13: =PR2_Cd_CN_Yangtze_Hydro!B178 -> Refined Cd | C13: =PR2_Cd_CN_Yangtze_Hydro!C178 -> CN | D13: 0.84745763 | E13: =PR2_Cd_CN_Yangtze_Hydro!E178 -> kilogram | F13: =PR2_Cd_CN_Yangtze_Hydro!F178 -> Cadmium | G13: technosphere

Sheet PR1_Cd_CA_KiddCreek
A1: Activity | B1: [M+C] Zinc (Zn) ore mining and concentration (Canada)
A2: reference product | B2: Zn concentrate
A3: location | B3: CA
A4: amount | B4: 1
A5: unit | B5: kilogram
A6: comment | B6: This unit process is allocated, but with unknown allocation factors (not provided in the original data source). In the absence of detailed mass balance for this intermediary product, the reference flow of this unit process is set by default at 1 kg, while the input and ouput flows of the inventory are actually scaled to 1 kg of refined Cd.
A7: Exchanges
A8: name | B8: reference product | C8: location | D8: amount | E8: unit | F8: database | G8: type | H8: categories | I8: uncertainty type | J8: pedigree | K8: loc | L8: scale | M8: minimum | N8: maximum
A9: =B1 -> [M+C] Zinc (Zn) ore mining and concentration (Canada) | B9: =B2 -> Zn concentrate | C9: =B3 -> CA | D9: 1 | E9: kilogram | F9: =Cd_Market_GLO!B1 -> Cadmium | G9: production
A10: market group for electricity, medium voltage | B10: electricity, medium voltage | C10: CA | D10: 0.36111111 | E10: kilowatt hour | F10: ecoinvent 3.10 cutoff | G10: technosphere | J10: (1,5,5,3,3)
A11: market for heavy fuel oil, burned in refinery furnace | B11: heavy fuel oil, burned in refinery furnace | C11: GLO | D11: 1.8 | E11: megajoule | F11: ecoinvent 3.10 cutoff | G11: technosphere | J11: (1,5,5,3,3)
A12: Particulate Matter, > 2.5 um and < 10um | D12: 1.8e-05 | E12: kilogram | F12: biosphere3 | G12: biosphere | H12: air | J12: (5,5,5,5,5)
A14: Activity | B14: [P+R] Refined Cadmium (Cd) production - Pyrometallurgy
A15: reference product | B15: Refined Cd
A16: location | B16: CA
A17: amount | B17: 1
A18: unit | B18: kilogram
A19: comment | B19: This unit process is allocated, but with unknown allocation factors (not provided in the original data source).
A20: Exchanges
A21: name | B21: reference product | C21: location | D21: amount | E21: unit | F21: database | G21: type | H21: categories | I21: uncertainty type | J21: pedigree | K21: loc | L21: scale | M21: minimum | N21: maximum
A22: =B14 -> [P+R] Refined Cadmium (Cd) production - Pyrometallurgy | B22: =B15 -> Refined Cd | C22: =B16 -> CA | D22: 1 | E22: kilogram | F22: =F9 -> Cadmium | G22: production
A23: market group for electricity, medium voltage | B23: electricity, medium voltage | C23: CA | D23: 0.52777778 | E23: kilowatt hour | F23: ecoinvent 3.10 cutoff | G23: technosphere | J23: (2,1,5,2,2)
A24: market for hard coal briquettes | B24: hard coal briquettes | C24: RoW | D24: 0.9 | E24: megajoule | F24: ecoinvent 3.10 cutoff | G24: technosphere | J24: (2,1,5,2,2)
A25: market for heat, district or industrial, natural gas | B25: heat, district or industrial, natural gas | C25: CA-QC | D25: 2.5 | E25: megajoule | F25: ecoinvent 3.10 cutoff | G25: technosphere | J25: (2,1,5,2,2)
A26: market for heavy fuel oil, burned in refinery furnace | B26: heavy fuel oil, burned in refinery furnace | C26: GLO | D26: 0.4 | E26: megajoule | F26: ecoinvent 3.10 cutoff | G26: technosphere | J26: (2,1,5,2,2)
A27: Sulfur oxides | D27: 0.0043 | E27: kilogram | F27: biosphere3 | G27: biosphere | H27: air | J27: (1,1,5,1,1)
A28: Arsenic ion | D28: 1.5e-06 | E28: kilogram | F28: biosphere3 | G28: biosphere | H28: air | J28: (1,1,5,1,1)
A29: Cadmium II | D29: 5.9e-07 | E29: kilogram | F29: biosphere3 | G29: biosphere | H29: air | J29: (1,1,5,1,1)
A30: Chromium III | D30: 2.7e-07 | E30: kilogram | F30: biosphere3 | G30: biosphere | H30: air | J30: (1,1,5,1,1)
A31: Cobalt II | D31: 4.5e-08 | E31: kilogram | F31: biosphere3 | G31: biosphere | H31: air | J31: (1,1,5,1,1)
A32: Copper ion | D32: 7.12e-05 | E32: kilogram | F32: biosphere3 | G32: biosphere | H32: air | J32: (1,1,5,1,1)
A33: Lead II | D33: 3.11e-05 | E33: kilogram | F33: biosphere3 | G33: biosphere | H33: air | J33: (1,1,5,1,1)
A34: Mercury II | D34: 1e-08 | E34: kilogram | F34: biosphere3 | G34: biosphere | H34: air | J34: (1,1,5,1,1)
A35: Nickel II | D35: 2.6e-07 | E35: kilogram | F35: biosphere3 | G35: biosphere | H35: air | J35: (1,1,5,1,1)
A36: Silver I | D36: 2.6e-07 | E36: kilogram | F36: biosphere3 | G36: biosphere | H36: air | J36: (1,1,5,1,1)
A37: Zinc II | D37: 3.87e-05 | E37: kilogram | F37: biosphere3 | G37: biosphere | H37: air | J37: (1,1,5,1,1)
A38: Arsenic ion | D38: 1e-07 | E38: kilogram | F38: biosphere3 | G38: biosphere | H38: water | J38: (1,1,5,1,1)
... A46: Zinc II | D46: 2.22e-05 | E46: kilogram | F46: biosphere3 | G46: biosphere | H46: water | J46: (1,1,5,1,1)
A48: Activity | B48: Cd recovery from Zn production in Canada/Kidd Creek
A49: reference product | B49: Refined Cd
...

Sheet PR2_Cd_CN_Yangtze_Hydro
A1: Activity | B1: [M+C] Zinc (Zn) ore mining and concentration (Guangdong)
A2: reference product | B2: Zn concentrate
A3: location | B3: CN
A4: amount | B4: 1
A5: unit | B5: kilogram
A6: comment | B6: Allocated unit process, considering as allocation factors: 56% for Zn (1 kg concentrate), 21% for Pb (0.4 kg concentrate) and 23% for Pb-Zn (0.6 kg bulk concentrate). The co-produced sulfur concentrate is dealt through substitution.
A7: Exchanges
A8: name | B8: reference product | C8: location | D8: amount | E8: unit | F8: database | G8: type | H8: categories | I8: uncertainty type | J8: pedigree | K8: loc | L8: scale | M8: minimum | N8: maximum
A9: [M+C] Zinc (Zn) ore mining and concentration (Guangdong) | B9: Zn concentrate | C9: CN | D9: 1 | E9: kilogram | F9: =Cd_Market_GLO!B1 -> Cadmium | G9: production
A10: market for diesel, burned in building machine | B10: diesel, burned in building machine | C10: GLO | D10: 0.12919384 | E10: megajoule | F10: ecoinvent 3.10 cutoff | G10: technosphere | J10: (1,1,2,1,1)
A11: market group for electricity, medium voltage | B11: electricity, medium voltage | C11: CN | D11: 0.54694873 | E11: kilowatt hour | F11: ecoinvent 3.10 cutoff | G11: technosphere | J11: (1,1,2,1,1)
A12: market for heat, district or industrial, other than natural gas | B12: heat, district or industrial, other than natural gas | C12: RoW | D12: 0.00047129011 | E12: megajoule | F12: ecoinvent 3.10 cutoff | G12: technosphere | J12: (1,1,2,1,1)
A13: market for polymer foaming | B13: polymer foaming | C13: GLO | D13: 1.9421296e-05 | E13: kilogram | F13: ecoinvent 3.10 cutoff | G13: technosphere | J13: (1,1,2,1,1)
A14: market for explosive, tovex | B14: explosive, tovex | C14: GLO | D14: 0.0029272678 | E14: kilogram | F14: ecoinvent 3.10 cutoff | G14: technosphere | J14: (1,1,2,1,1)
A15: market for steel, low-alloyed | B15: steel, low-alloyed | C15: GLO | D15: 0.0024769189 | E15: kilogram | F15: ecoinvent 3.10 cutoff | G15: technosphere | J15: (1,1,2,1,1)
A16: market for synthetic rubber | B16: synthetic rubber | C16: GLO | D16: 0.00027809044 | E16: kilogram | F16: ecoinvent 3.10 cutoff | G16: technosphere | J16: (1,1,2,1,1)
A17: market for particleboard, uncoated | B17: particleboard, uncoated | C17: RoW | D17: 6.2485908e-06 | E17: cubic meter | F17: ecoinvent 3.10 cutoff | G17: technosphere | J17: (1,1,2,1,1)
A18: market for lime, packed | B18: lime, packed | C18: RoW | D18: 0.057700951 | E18: kilogram | F18: ecoinvent 3.10 cutoff | G18: technosphere | J18: (1,1,2,1,1)
A19: market for copper sulfate | B19: copper sulfate | C19: GLO | D19: 0.0035183507 | E19: kilogram | F19: ecoinvent 3.10 cutoff | G19: technosphere | J19: (1,1,2,1,1)
A20: market for sodium ethyl xanthate | B20: sodium ethyl xanthate | C20: GLO | D20: 0.0036196792 | E20: kilogram | F20: ecoinvent 3.10 cutoff | G20: technosphere | J20: (1,1,2,1,1)
A21: market for [thio]carbamate-compound | B21: [thio]carbamate-compound | C21: GLO | D21: 0.00064737653 | E21: kilogram | F21: ecoinvent 3.10 cutoff | G21: technosphere | J21: (1,1,2,1,1)
... A30: market for sulfur trioxide | B30: sulfur trioxide | C30: RoW | D30: -0.011624839 | E30: kilogram | F30: ecoinvent 3.10 cutoff | G30: technosphere | J30: (1,1,2,1,1)
A31: Lead | D31: 0.23924785 | E31: kilogram | F31: biosphere3 | G31: biosphere | H31: natural resource::in ground | J31: (1,1,2,1,1)
A32: Zinc | D32: 0.43458668 | E32: kilogram | F32: biosphere3 | G32: biosphere | H32: natural resource::in ground | J32: (1,1,2,1,1)
A33: Sulfur | D33: 1.3876375 | E33: kilogram | F33: biosphere3 | G33: biosphere | H33: natural resource::in ground | J33: (1,1,2,1,1)
A34: Iron | D34: 0.25106951 | E34: kilogram | F34: biosphere3 | G34: biosphere | H34: natural resource::in ground | J34: (1,1,2,1,1)
A35: Silver | D35: 0.00047793276 | E35: kilogram | F35: biosphere3 | G35: biosphere | H35: natural resource::in ground | J35: (1,1,2,1,1)
A36: Gold | D36: 4.5034889e-07 | E36: kilogram | F36: biosphere3 | G36: biosphere | H36: natural resource::in ground | J36: (1,1,2,1,1)
A37: Carbon dioxide, non-fossil | D37: 0.009119565 | E37: kilogram | F37: biosphere3 | G37: biosphere | H37: air | J37: (1,1,2,1,1)
A38: Carbon monoxide, non-fossil | D38: 0.00030832011 | E38: kilogram | F38: biosphere3 | G38: biosphere | H38: air | J38: (1,1,2,1,1)
A39: Nitrogen oxides | D39: 0.001093053 | E39: kilogram | F39: biosphere3 | G39: biosphere | H39: air | J39: (1,1,2,1,1)
A40: Sulfur dioxide | D40: 4.4303072e-05 | E40: kilogram | F40: biosphere3 | G40: biosphere | H40: air | J40: (1,1,2,1,1)
A41: Hydrocarbons, aromatic | D41: 2.6007648e-05 | E41: kilogram | F41: biosphere3 | G41: biosphere | H41: air | J41: (1,1,2,1,1)
A42: Particulate Matter, > 2.5 um and < 10um | D42: 0.00029160091 | E42: kilogram | F42: biosphere3 | G42: biosphere | H42: air | J42: (1,1,2,1,1)
... A46: Arsenic ion | D46: 0.0012947531 | E46: kilogram | F46: biosphere3 | G46: biosphere | H46: water | J46: (1,1,2,1,1)
A48: Activity | B48: [P+R] Refined Cadmium (Cd) production - Hydrometallurgy (Yangtze)
A49: reference product | B49: Refined Cd
A50: location | B50: CN
A51: amount | B51: 1
A52: unit | B52: kilogram
...
