Workbook

Sheet Note
A1: skip
B2: Life cycle inventories of global metal and mineral supply chains: a comprehensive data review, analysis and processing Frédéric Laia*, Stéphanie Mullera, Audrey Philippea, Robert Istrateb, Brenda Miranda Xicotencatlb, Afsoon Mansouri Askic, Aina Mas Fonsd,a, Juliana Segura-Salazare, Jair Santillán Saldivara, Alexander Cimprichf, Stephen Northeyg, Lígia da Silva Limah, Lieselot Booneh, Ryosuke Yokoii, Kamrul Islami, Ioanna Paschalidouj, Felipe Cerdask,l, Victor Balboa-Espinozae, Anish Koyamparambathd, Diae Henniouia, Victoire Collignona, Aurélien Reysa, Gyslain Ngadi Sakatadim, Jo Dewulfh, Bernhard Steubingb, Christoph Helbigc, Gaétan Lefebvrea, Gian Andrea Blenginin,m, Valeria Supertio, Masaharu Motoshitai, Guido Sonnemannd, Kwame Awuah-Offeij, Steven B. Youngf, Shinsuke Murakamip, Antoine Beylota aBRGM, F-45060 Orléans, France bInstitute of Environmental Sciences (CML), Leiden University, Einsteinweg 2, 2333 CC Leiden, NL cEcological Resource Technology, University of Bayreuth, Universitätstr. 30, 95447 Bayreuth, Germany dUniv. Bordeaux, CNRS, Bordeaux INP, ISM, UMR 5255, F-33400 Talence, France eSustainable Minerals Institute, The University of Queensland, QLD, 4072, Australia fSchool of Environment, Enterprise and Development, University of Waterloo, 200 University Avenue West, Waterloo, Ontario N2L 3G1, Canada gUniversity of Technology Sydney, Institute for Sustainable Futures, Australia hSustainable Systems Engineering (STEN), Department of Green Chemistry and Technology, Faculty of Bioscience Engineering, Ghent University, Coupure Links 653, 9000 Ghent, Belgium iAIST, 305-8569 Tsukuba, Japan jMining & Explosives Engineering, Missouri University of Science & Technology, Rolla, MO, USA 65409 kInstitute for Sustainable Energy Systems (INSYS), Technical University of Applied Sciences Würzburg-Schweinfurt (THWS), Ignaz-Schön-Straße 11, Schweinfurt, Germany lFraunhofer Institute for Surface Engineering and Thin Films IST, Riedenkamp 2, Braunschweig 38108, Germany mDepartment of Environment, Land and Infrastructure Engineering, Politecnico di Torino, Corso Duca degli Abruzzi, 24, 10129 Torino, Italy nUniversity of Turin, Earth Sciences Department (DST), Via Valperga Caluso, 35 – 10125 Torino, Italy oecoinvent association, Technopark, Technoparkstrasse 1, 8005 Zürich, Switzerland pGraduate School of Engineering, The University of Tokyo, Tokyo 113-8656, Japan *Corresponding author: f.lai@brgm.fr This file provides all LCI datasets developed for Chromium (Cr), with distinguishing its global market and each individual production route.
B33: Sheet | C33: Corresponding route
B34: Cr_Market_GLO | C34: Cr global market
B35: PR1_FeCr_GLO_OpenFurnace | C35: Chromite ore mining and FeCr production in South Africa/Finland/Kazakhstan through Open Furnace Smelting
B36: PR2_FeCr_GLO_ClosedFurnace | C36: Chromite ore mining and FeCr production in South Africa/Finland/Kazakhstan through Closed Furnace Smelting (without preheating)
B37: PR3_FeCr_GLO_ClosedFurnaceHeat | C37: Chromite ore mining and FeCr production in South Africa/Finland/Kazakhstan through Closed Furnace Smelting (with preheating)
B38: PR4_Cr_GLO | C38: Chromite ore mining and Cr metal production in South Africa/Finland/Kazakhstan

Sheet Cr_Market_GLO
A1: database | B1: Chromium
A3: Activity | B3: Chromium (Cr) global market
A4: reference product | B4: Cr commodities
A5: location | B5: GLO
A6: amount | B6: 1
A7: unit | B7: kilogram
A8: comment | B8: n/a
A9: Exchanges
A10: name | B10: reference product | C10: location | D10: amount | E10: unit | F10: database | G10: type | H10: categories | I10: uncertainty type | J10: pedigree | K10: loc | L10: scale | M10: minimum | N10: maximum
A11: =B3 -> Chromium (Cr) global market | B11: =B4 -> Cr commodities | C11: =B5 -> GLO | D11: 1 | E11: =B7 -> kilogram | F11: =B1 -> Chromium | G11: production
A12: =PR1_FeCr_GLO_OpenFurnace!A49 -> Chromite ore mining and FeCr production in South Africa/Finland/Kazakhstan through Open Furnace Smelting | B12: =PR1_FeCr_GLO_OpenFurnace!B49 -> FeCr | C12: =PR1_FeCr_GLO_OpenFurnace!C49 -> GLO | D12: 0.43304843 | E12: =PR1_FeCr_GLO_OpenFurnace!E49 -> kilogram | F12: =PR1_FeCr_GLO_OpenFurnace!F49 -> Chromium | G12: technosphere
A13: =PR2_FeCr_GLO_ClosedFurnace!A47 -> Chromite ore mining and FeCr production in South Africa/Finland/Kazakhstan through Closed Furnace Smelting (without preheating) | B13: =PR2_FeCr_GLO_ClosedFurnace!B47 -> FeCr | C13: =PR2_FeCr_GLO_ClosedFurnace!C47 -> GLO | D13: 0.18306138 | E13: =PR2_FeCr_GLO_ClosedFurnace!E47 -> kilogram | F13: =PR2_FeCr_GLO_ClosedFurnace!F47 -> Chromium | G13: technosphere
A14: =PR3_FeCr_GLO_ClosedFurnaceHeat!A48 -> Chromite ore mining and FeCr production in South Africa/Finland/Kazakhstan through Closed Furnace Smelting (with preheating) | B14: =PR3_FeCr_GLO_ClosedFurnaceHeat!B48 -> FeCr | C14: =PR3_FeCr_GLO_ClosedFurnaceHeat!C48 -> GLO | D14: 0.36317016 | E14: =PR3_FeCr_GLO_ClosedFurnaceHeat!E48 -> kilogram | F14: =PR3_FeCr_GLO_ClosedFurnaceHeat!F48 -> Chromium | G14: technosphere
A15: =PR4_Cr_GLO!A40 -> Chromite ore mining and Cr metal production in South Africa/Finland/Kazakhstan | B15: =PR4_Cr_GLO!B40 -> Cr metal | C15: =PR4_Cr_GLO!C40 -> GLO | D15: 0.020720021 | E15: =PR4_Cr_GLO!E40 -> kilogram | F15: =PR4_Cr_GLO!F40 -> Chromium | G15: technosphere
A17: Activity | B17: Chromium (Cr) global market (Cr content)
A18: reference product | B18: Cr content
A19: location | B19: GLO
A20: amount | B20: 1
A21: unit | B21: kilogram
A22: comment | B22: Activity expressed for 1 kg Cr contained
A23: Exchanges
A24: name | B24: reference product | C24: location | D24: amount | E24: unit | F24: database | G24: type | H24: categories | I24: uncertainty type | J24: pedigree | K24: loc | L24: scale | M24: minimum | N24: maximum
A25: =B17 -> Chromium (Cr) global market (Cr content) | B25: =B18 -> Cr content | C25: =B19 -> GLO | D25: 1 | E25: =B21 -> kilogram | F25: =F11 -> Chromium | G25: production
A26: =PR1_FeCr_GLO_OpenFurnace!A60 -> Chromite ore mining and FeCr production in South Africa/Finland/Kazakhstan through Open Furnace Smelting (Cr content) | B26: =PR1_FeCr_GLO_OpenFurnace!B60 -> FeCr (Cr content) | C26: =PR1_FeCr_GLO_OpenFurnace!C60 -> GLO | D26: 0.43304843 | E26: =PR1_FeCr_GLO_OpenFurnace!E60 -> kilogram | F26: =PR1_FeCr_GLO_OpenFurnace!F60 -> Chromium | G26: technosphere
A27: =PR2_FeCr_GLO_ClosedFurnace!A58 -> Chromite ore mining and FeCr production in South Africa/Finland/Kazakhstan through Closed Furnace Smelting (without preheating) (Cr content) | B27: =PR2_FeCr_GLO_ClosedFurnace!B58 -> FeCr (Cr content) | C27: =PR2_FeCr_GLO_ClosedFurnace!C58 -> GLO | D27: 0.18306138 | E27: =PR2_FeCr_GLO_ClosedFurnace!E58 -> kilogram | F27: =PR2_FeCr_GLO_ClosedFurnace!F58 -> Chromium | G27: technosphere
A28: =PR3_FeCr_GLO_ClosedFurnaceHeat!A59 -> Chromite ore mining and FeCr production in South Africa/Finland/Kazakhstan through Closed Furnace Smelting (with preheating) (Cr content) | B28: =PR3_FeCr_GLO_ClosedFurnaceHeat!B59 -> FeCr (Cr content) | C28: =PR3_FeCr_GLO_ClosedFurnaceHeat!C59 -> GLO | D28: 0.36317016 | E28: =PR3_FeCr_GLO_ClosedFurnaceHeat!E59 -> kilogram | F28: =PR3_FeCr_GLO_ClosedFurnaceHeat!F59 -> Chromium | G28: technosphere
A29: =PR4_Cr_GLO!A40 -> Chromite ore mining and Cr metal production in South Africa/Finland/Kazakhstan | B29: =PR4_Cr_GLO!B40 -> Cr metal | C29: =PR4_Cr_GLO!C40 -> GLO | D29: 0.020720021 | E29: =PR4_Cr_GLO!E40 -> kilogram | F29: =PR4_Cr_GLO!F40 -> Chromium | G29: technosphere

Sheet PR1_FeCr_GLO_OpenFurnace
A1: Activity | B1: [M+C+P+R] Ferrochromium (FeCr) production - Open Furnace Smelting
A2: reference product | B2: FeCr
A3: location | B3: GLO
A4: amount | B4: 1
A5: unit | B5: kilogram
A6: comment | B6: n/a
A7: Exchanges
A8: name | B8: reference product | C8: location | D8: amount | E8: unit | F8: database | G8: type | H8: categories | I8: uncertainty type | J8: pedigree | K8: loc | L8: scale | M8: minimum | N8: maximum
A9: =B1 -> [M+C+P+R] Ferrochromium (FeCr) production - Open Furnace Smelting | B9: =B2 -> FeCr | C9: =B3 -> GLO | D9: 1 | E9: kilogram | F9: =Cr_Market_GLO!B1 -> Chromium | G9: production
A10: market group for electricity, medium voltage | B10: electricity, medium voltage | C10: GLO | D10: 4.45 | E10: kilowatt hour | F10: ecoinvent 3.10 cutoff | G10: technosphere | J10: (4,1,5,1,1)
A11: market group for tap water | B11: tap water | C11: GLO | D11: 5.99 | E11: kilogram | F11: ecoinvent 3.10 cutoff | G11: technosphere | J11: (4,1,5,1,1)
A12: market for explosive, tovex | B12: explosive, tovex | C12: GLO | D12: 0.0011 | E12: kilogram | F12: ecoinvent 3.10 cutoff | G12: technosphere | J12: (4,1,5,1,1)
A13: diesel, burned in building machine | B13: diesel, burned in building machine | C13: GLO | D13: 0.0495 | E13: megajoule | F13: ecoinvent 3.10 cutoff | G13: technosphere | J13: (4,4,5,4,4)
A14: market for heavy fuel oil, burned in refinery furnace | B14: heavy fuel oil, burned in refinery furnace | C14: GLO | D14: 0.0177216 | E14: megajoule | F14: ecoinvent 3.10 cutoff | G14: technosphere | J14: (4,4,5,4,4)
A15: market for natural gas, burned in gas turbine | B15: natural gas, burned in gas turbine | C15: GLO | D15: 0.02622 | E15: megajoule | F15: ecoinvent 3.10 cutoff | G15: technosphere | J15: (4,4,5,4,4)
A16: market for petrol, unleaded, burned in machinery | B16: petrol, unleaded, burned in machinery | C16: GLO | D16: 0.689586 | E16: megajoule | F16: ecoinvent 3.10 cutoff | G16: technosphere | J16: (4,4,5,4,4)
A17: market for heavy fuel oil, burned in refinery furnace | B17: heavy fuel oil, burned in refinery furnace | C17: GLO | D17: 0.10437 | E17: megajoule | F17: ecoinvent 3.10 cutoff | G17: technosphere | J17: (4,4,5,4,4)
A18: market for chemical, inorganic | B18: chemical, inorganic | C18: GLO | D18: 2.85e-05 | E18: kilogram | F18: ecoinvent 3.10 cutoff | G18: technosphere | J18: (4,1,5,1,1)
A19: market for hard coal | B19: hard coal | C19: RoW | D19: 0.158 | E19: kilogram | F19: ecoinvent 3.10 cutoff | G19: technosphere | J19: (4,1,5,1,1)
A20: market for coke | B20: coke | C20: RoW | D20: 3.484 | E20: megajoule | F20: ecoinvent 3.10 cutoff | G20: technosphere | J20: (4,1,5,1,1)
A21: market for coke | B21: coke | C21: RoW | D21: 3.38 | E21: megajoule | F21: ecoinvent 3.10 cutoff | G21: technosphere | J21: (4,1,5,1,1)
... A28: market for inert waste, for final disposal | B28: inert waste, for final disposal | C28: RoW | D28: -1.45 | E28: kilogram | F28: ecoinvent 3.10 cutoff | G28: technosphere | J28: (4,1,5,1,1)
A29: Water, well, in ground | D29: 0.00529 | E29: cubic meter | F29: biosphere3 | G29: biosphere | H29: natural resource::in water | J29: (4,1,5,1,1)
A30: Water, lake | D30: 0.00529 | E30: cubic meter | F30: biosphere3 | G30: biosphere | H30: natural resource::in water | J30: (4,1,5,1,1)
A31: Carbon dioxide, fossil | D31: 1.53 | E31: kilogram | F31: biosphere3 | G31: biosphere | H31: air | J31: (4,1,5,1,1)
A32: Chromium VI | D32: 2.41e-08 | E32: kilogram | F32: biosphere3 | G32: biosphere | H32: water | J32: (4,1,5,1,1)
A33: Chromium III | D33: 0.00035 | E33: kilogram | F33: biosphere3 | G33: biosphere | H33: air | J33: (4,1,5,1,1)
A34: Chromium VI | D34: 3e-07 | E34: kilogram | F34: biosphere3 | G34: biosphere | H34: air | J34: (4,1,5,1,1)
A35: Lead II | D35: 1.1e-06 | E35: kilogram | F35: biosphere3 | G35: biosphere | H35: air | J35: (4,1,5,1,1)
A36: Manganese II | D36: 1.5e-06 | E36: kilogram | F36: biosphere3 | G36: biosphere | H36: air | J36: (4,1,5,1,1)
A37: Cadmium II | D37: 1.4e-08 | E37: kilogram | F37: biosphere3 | G37: biosphere | H37: air | J37: (4,1,5,1,1)
A38: Vanadium V | D38: 7.6e-10 | E38: kilogram | F38: biosphere3 | G38: biosphere | H38: air | J38: (4,1,5,1,1)
A39: Particulate Matter, > 2.5 um and < 10um | D39: 0.0038 | E39: kilogram | F39: biosphere3 | G39: biosphere | H39: air | J39: (4,1,5,1,1)
A41: Activity | B41: Chromite ore mining and FeCr production in South Africa/Finland/Kazakhstan through Open Furnace Smelting
A42: reference product | B42: FeCr
A43: location | B43: GLO
A44: amount | B44: 1
A45: unit | B45: kilogram
A46: comment | B46: n/a
A47: Exchanges
...

Sheet PR2_FeCr_GLO_ClosedFurnace
A1: Activity | B1: [M+C+P+R] Ferrochromium (FeCr) production - Closed Furnace Smelting
A2: reference product | B2: FeCr
A3: location | B3: GLO
A4: amount | B4: 1
A5: unit | B5: kilogram
A6: comment | B6: n/a
A7: Exchanges
A8: name | B8: reference product | C8: location | D8: amount | E8: unit | F8: database | G8: type | H8: categories | I8: uncertainty type | J8: pedigree | K8: loc | L8: scale | M8: minimum | N8: maximum
A9: =B1 -> [M+C+P+R] Ferrochromium (FeCr) production - Closed Furnace Smelting | B9: =B2 -> FeCr | C9: =B3 -> GLO | D9: 1 | E9: kilogram | F9: =Cr_Market_GLO!B1 -> Chromium | G9: production
A10: market group for electricity, medium voltage | B10: electricity, medium voltage | C10: GLO | D10: 4.42 | E10: kilowatt hour | F10: ecoinvent 3.10 cutoff | G10: technosphere | J10: (4,1,5,1,1)
A11: market group for tap water | B11: tap water | C11: GLO | D11: 3.42 | E11: kilogram | F11: ecoinvent 3.10 cutoff | G11: technosphere | J11: (4,1,5,1,1)
A12: market for explosive, tovex | B12: explosive, tovex | C12: GLO | D12: 0.000975 | E12: kilogram | F12: ecoinvent 3.10 cutoff | G12: technosphere | J12: (4,1,5,1,1)
A13: diesel, burned in building machine | B13: diesel, burned in building machine | C13: GLO | D13: 0.041715 | E13: megajoule | F13: ecoinvent 3.10 cutoff | G13: technosphere | J13: (4,4,5,4,4)
A14: market for heavy fuel oil, burned in refinery furnace | B14: heavy fuel oil, burned in refinery furnace | C14: GLO | D14: 0.0158046 | E14: megajoule | F14: ecoinvent 3.10 cutoff | G14: technosphere | J14: (4,4,5,4,4)
A15: market for natural gas, burned in gas turbine | B15: natural gas, burned in gas turbine | C15: GLO | D15: 0.02337 | E15: megajoule | F15: ecoinvent 3.10 cutoff | G15: technosphere | J15: (4,4,5,4,4)
A16: market for petrol, unleaded, burned in machinery | B16: petrol, unleaded, burned in machinery | C16: GLO | D16: 0.010764 | E16: megajoule | F16: ecoinvent 3.10 cutoff | G16: technosphere | J16: (4,4,5,4,4)
A17: market for heavy fuel oil, burned in refinery furnace | B17: heavy fuel oil, burned in refinery furnace | C17: GLO | D17: 0.092868 | E17: megajoule | F17: ecoinvent 3.10 cutoff | G17: technosphere | J17: (4,4,5,4,4)
A18: market for chemical, inorganic | B18: chemical, inorganic | C18: GLO | D18: 2.54e-05 | E18: kilogram | F18: ecoinvent 3.10 cutoff | G18: technosphere | J18: (4,1,5,1,1)
A19: market for hard coal | B19: hard coal | C19: RoW | D19: 0.21 | E19: kilogram | F19: ecoinvent 3.10 cutoff | G19: technosphere | J19: (4,1,5,1,1)
A20: market for coke | B20: coke | C20: RoW | D20: 4.966 | E20: megajoule | F20: ecoinvent 3.10 cutoff | G20: technosphere | J20: (4,1,5,1,1)
A21: market for coke | B21: coke | C21: RoW | D21: 2.054 | E21: megajoule | F21: ecoinvent 3.10 cutoff | G21: technosphere | J21: (4,1,5,1,1)
... A28: market for inert waste, for final disposal | B28: inert waste, for final disposal | C28: RoW | D28: -1.58 | E28: kilogram | F28: ecoinvent 3.10 cutoff | G28: technosphere | J28: (4,1,5,1,1)
A29: Water, well, in ground | D29: 0.00527 | E29: cubic meter | F29: biosphere3 | G29: biosphere | H29: natural resource::in water | J29: (4,1,5,1,1)
A30: Water, lake | D30: 0.00527 | E30: cubic meter | F30: biosphere3 | G30: biosphere | H30: natural resource::in water | J30: (4,1,5,1,1)
A31: Carbon dioxide, fossil | D31: 1.68 | E31: kilogram | F31: biosphere3 | G31: biosphere | H31: air | J31: (4,1,5,1,1)
A32: Chromium VI | D32: 2.15e-08 | E32: kilogram | F32: biosphere3 | G32: biosphere | H32: water | J32: (4,1,5,1,1)
A33: Lead II | D33: 1.1e-06 | E33: kilogram | F33: biosphere3 | G33: biosphere | H33: air | J33: (4,1,5,1,1)
A34: Manganese II | D34: 1.5e-06 | E34: kilogram | F34: biosphere3 | G34: biosphere | H34: air | J34: (4,1,5,1,1)
A35: Cadmium II | D35: 1.4e-08 | E35: kilogram | F35: biosphere3 | G35: biosphere | H35: air | J35: (4,1,5,1,1)
A36: Vanadium V | D36: 7.6e-10 | E36: kilogram | F36: biosphere3 | G36: biosphere | H36: air | J36: (4,1,5,1,1)
A37: Particulate Matter, > 2.5 um and < 10um | D37: 0.0048 | E37: kilogram | F37: biosphere3 | G37: biosphere | H37: air | J37: (4,1,5,1,1)
A39: Activity | B39: Chromite ore mining and FeCr production in South Africa/Finland/Kazakhstan through Closed Furnace Smelting (without preheating)
A40: reference product | B40: FeCr
A41: location | B41: GLO
A42: amount | B42: 1
A43: unit | B43: kilogram
A44: comment | B44: n/a
A45: Exchanges
A46: name | B46: reference product | C46: location | D46: amount | E46: unit | F46: database | G46: type | H46: categories | I46: uncertainty type | J46: pedigree | K46: loc | L46: scale | M46: minimum | N46: maximum
A47: =B39 -> Chromite ore mining and FeCr production in South Africa/Finland/Kazakhstan through Closed Furnace Smelting (without preheating) | B47: =B40 -> FeCr | C47: =B41 -> GLO | D47: 1 | E47: kilogram | F47: =F9 -> Chromium | G47: production
...

Sheet PR3_FeCr_GLO_ClosedFurnaceHeat
A1: Activity | B1: [M+C+P+R] Ferrochromium (FeCr) production - Closed Furnace Smelting (with preheating)
A2: reference product | B2: FeCr
A3: location | B3: GLO
A4: amount | B4: 1
A5: unit | B5: kilogram
A6: comment | B6: n/a
A7: Exchanges
A8: name | B8: reference product | C8: location | D8: amount | E8: unit | F8: database | G8: type | H8: categories | I8: uncertainty type | J8: pedigree | K8: loc | L8: scale | M8: minimum | N8: maximum
A9: =B1 -> [M+C+P+R] Ferrochromium (FeCr) production - Closed Furnace Smelting (with preheating) | B9: =B2 -> FeCr | C9: =B3 -> GLO | D9: 1 | E9: kilogram | F9: =Cr_Market_GLO!B1 -> Chromium | G9: production
A10: market group for electricity, medium voltage | B10: electricity, medium voltage | C10: GLO | D10: 3.53 | E10: kilowatt hour | F10: ecoinvent 3.10 cutoff | G10: technosphere | J10: (4,1,5,1,1)
A11: market group for tap water | B11: tap water | C11: GLO | D11: 3.94 | E11: kilogram | F11: ecoinvent 3.10 cutoff | G11: technosphere | J11: (4,1,5,1,1)
A12: market for explosive, tovex | B12: explosive, tovex | C12: GLO | D12: 0.00102 | E12: kilogram | F12: ecoinvent 3.10 cutoff | G12: technosphere | J12: (4,1,5,1,1)
A13: diesel, burned in building machine | B13: diesel, burned in building machine | C13: GLO | D13: 0.13725 | E13: megajoule | F13: ecoinvent 3.10 cutoff | G13: technosphere | J13: (4,4,5,4,4)
A14: market for heavy fuel oil, burned in refinery furnace | B14: heavy fuel oil, burned in refinery furnace | C14: GLO | D14: 0.0164436 | E14: megajoule | F14: ecoinvent 3.10 cutoff | G14: technosphere | J14: (4,4,5,4,4)
A15: market for natural gas, burned in gas turbine | B15: natural gas, burned in gas turbine | C15: GLO | D15: 0.024282 | E15: megajoule | F15: ecoinvent 3.10 cutoff | G15: technosphere | J15: (4,4,5,4,4)
A16: market for petrol, unleaded, burned in machinery | B16: petrol, unleaded, burned in machinery | C16: GLO | D16: 0.011224 | E16: megajoule | F16: ecoinvent 3.10 cutoff | G16: technosphere | J16: (4,4,5,4,4)
A17: market for heavy fuel oil, burned in refinery furnace | B17: heavy fuel oil, burned in refinery furnace | C17: GLO | D17: 0.096702 | E17: megajoule | F17: ecoinvent 3.10 cutoff | G17: technosphere | J17: (4,4,5,4,4)
A18: market for chemical, inorganic | B18: chemical, inorganic | C18: GLO | D18: 2.64e-05 | E18: kilogram | F18: ecoinvent 3.10 cutoff | G18: technosphere | J18: (4,1,5,1,1)
A19: market for hard coal | B19: hard coal | C19: RoW | D19: 0.026 | E19: kilogram | F19: ecoinvent 3.10 cutoff | G19: technosphere | J19: (4,1,5,1,1)
A20: market for coke | B20: coke | C20: RoW | D20: 3.302 | E20: megajoule | F20: ecoinvent 3.10 cutoff | G20: technosphere | J20: (4,1,5,1,1)
A21: market for coke | B21: coke | C21: RoW | D21: 4.472 | E21: megajoule | F21: ecoinvent 3.10 cutoff | G21: technosphere | J21: (4,1,5,1,1)
... A28: market for inert waste, for final disposal | B28: inert waste, for final disposal | C28: RoW | D28: -1.62 | E28: kilogram | F28: ecoinvent 3.10 cutoff | G28: technosphere | J28: (4,1,5,1,1)
A29: Water, well, in ground | D29: 0.00584 | E29: cubic meter | F29: biosphere3 | G29: biosphere | H29: natural resource::in water | J29: (4,1,5,1,1)
A30: Water, lake | D30: 0.00584 | E30: cubic meter | F30: biosphere3 | G30: biosphere | H30: natural resource::in water | J30: (4,1,5,1,1)
A31: Carbon dioxide, fossil | D31: 1.51 | E31: kilogram | F31: biosphere3 | G31: biosphere | H31: air | J31: (4,1,5,1,1)
A32: Chromium VI | D32: 2.23e-08 | E32: kilogram | F32: biosphere3 | G32: biosphere | H32: water | J32: (4,1,5,1,1)
A33: Lead II | D33: 1.1e-06 | E33: kilogram | F33: biosphere3 | G33: biosphere | H33: air | J33: (4,1,5,1,1)
A34: Manganese II | D34: 1.5e-06 | E34: kilogram | F34: biosphere3 | G34: biosphere | H34: air | J34: (4,1,5,1,1)
A35: Cadmium II | D35: 1.4e-08 | E35: kilogram | F35: biosphere3 | G35: biosphere | H35: air | J35: (4,1,5,1,1)
A36: Vanadium V | D36: 7.6e-10 | E36: kilogram | F36: biosphere3 | G36: biosphere | H36: air | J36: (4,1,5,1,1)
A37: Particulate Matter, > 2.5 um and < 10um | D37: 0.0048 | E37: kilogram | F37: biosphere3 | G37: biosphere | H37: air | J37: (4,1,5,1,1)
A38: Zinc II | D38: 0.0011 | E38: kilogram | F38: biosphere3 | G38: biosphere | H38: air | J38: (4,1,5,1,1)
A40: Activity | B40: Chromite ore mining and FeCr production in South Africa/Finland/Kazakhstan through Closed Furnace Smelting (with preheating)
A41: reference product | B41: FeCr
A42: location | B42: GLO
A43: amount | B43: 1
A44: unit | B44: kilogram
A45: comment | B45: n/a
A46: Exchanges
A47: name | B47: reference product | C47: location | D47: amount | E47: unit | F47: database | G47: type | H47: categories | I47: uncertainty type | J47: pedigree | K47: loc | L47: scale | M47: minimum | N47: maximum
...

Sheet PR4_Cr_GLO
A1: Activity | B1: [M+C+P+R] Chromium (Cr) metal production
A2: reference product | B2: Cr Metal
A3: location | B3: GLO
A4: amount | B4: 1
A5: unit | B5: kilogram
A6: comment | B6: Allocated unit process, considering as allocation factors (AF): 29% for Cr (1 kg), 61% for Fe (0.8 kg iron (III) oxide) and 10% for Al (1 kg oxide). The co-produced sodium sulfate is dealt through substitution.
A7: Exchanges
A8: name | B8: reference product | C8: location | D8: amount | E8: unit | F8: database | G8: type | H8: categories | I8: uncertainty type | J8: pedigree | K8: loc | L8: scale | M8: minimum | N8: maximum
A9: =B1 -> [M+C+P+R] Chromium (Cr) metal production | B9: =B2 -> Cr Metal | C9: =B3 -> GLO | D9: 1 | E9: kilogram | F9: =Cr_Market_GLO!B1 -> Chromium | G9: production
A10: market group for electricity, medium voltage | B10: electricity, medium voltage | C10: GLO | D10: 0.04651863 | E10: kilowatt hour | F10: ecoinvent 3.10 cutoff | G10: technosphere | J10: (4,1,5,1,1)
A11: market group for tap water | B11: tap water | C11: GLO | D11: 1.0921765 | E11: kilogram | F11: ecoinvent 3.10 cutoff | G11: technosphere | J11: (4,1,5,1,1)
A12: market for explosive, tovex | B12: explosive, tovex | C12: GLO | D12: 0.00031205044 | E12: kilogram | F12: ecoinvent 3.10 cutoff | G12: technosphere | J12: (4,1,5,1,1)
A13: diesel, burned in building machine | B13: diesel, burned in building machine | C13: GLO | D13: 0.007554221 | E13: megajoule | F13: ecoinvent 3.10 cutoff | G13: technosphere | J13: (4,4,5,4,4)
A14: market for heavy fuel oil, burned in refinery furnace | B14: heavy fuel oil, burned in refinery furnace | C14: GLO | D14: 0.0050342403 | E14: megajoule | F14: ecoinvent 3.10 cutoff | G14: technosphere | J14: (4,4,5,4,4)
A15: market for natural gas, burned in gas turbine | B15: natural gas, burned in gas turbine | C15: GLO | D15: 0.0074441365 | E15: megajoule | F15: ecoinvent 3.10 cutoff | G15: technosphere | J15: (4,4,5,4,4)
A16: market for petrol, unleaded, burned in machinery | B16: petrol, unleaded, burned in machinery | C16: GLO | D16: 0.0034290876 | E16: megajoule | F16: ecoinvent 3.10 cutoff | G16: technosphere | J16: (4,4,5,4,4)
A17: market for heavy fuel oil, burned in refinery furnace | B17: heavy fuel oil, burned in refinery furnace | C17: GLO | D17: 0.029663861 | E17: megajoule | F17: ecoinvent 3.10 cutoff | G17: technosphere | J17: (4,4,5,4,4)
A18: market for chemical, inorganic | B18: chemical, inorganic | C18: GLO | D18: 8.0901965e-06 | E18: kilogram | F18: ecoinvent 3.10 cutoff | G18: technosphere | J18: (4,1,5,1,1)
A19: market group for heat, district or industrial, natural gas | B19: heat, district or industrial, natural gas | C19: GLO | D19: 1.5631415 | E19: megajoule | F19: ecoinvent 3.10 cutoff | G19: technosphere | J19: (4,1,5,1,1)
A20: market for soda ash, dense | B20: soda ash, dense | C20: GLO | D20: 0.5894286 | E20: kilogram | F20: ecoinvent 3.10 cutoff | G20: technosphere | J20: (4,1,5,1,1)
A21: market for sulfuric acid | B21: sulfuric acid | C21: RoW | D21: 0.27246626 | E21: kilogram | F21: ecoinvent 3.10 cutoff | G21: technosphere | J21: (4,1,5,1,1)
... A26: market for sodium sulfate, anhydrite | B26: sodium sulfate, anhydrite | C26: RoW | D26: -0.78879416 | E26: kilogram | F26: ecoinvent 3.10 cutoff | G26: technosphere | J26: (4,1,5,1,1)
A27: Water, well, in ground | D27: 0.0011297382 | E27: cubic meter | F27: biosphere3 | G27: biosphere | H27: natural resource::in water | J27: (4,1,5,1,1)
A28: Water, lake | D28: 0.0011297382 | E28: cubic meter | F28: biosphere3 | G28: biosphere | H28: natural resource::in water | J28: (4,1,5,1,1)
A29: Carbon dioxide, fossil | D29: 0.24443951 | E29: kilogram | F29: biosphere3 | G29: biosphere | H29: air | J29: (4,1,5,1,1)
A30: Chromium VI | D30: 6.8477734e-09 | E30: kilogram | F30: biosphere3 | G30: biosphere | H30: water | J30: (4,1,5,1,1)
A32: Activity | B32: Chromite ore mining and Cr metal production in South Africa/Finland/Kazakhstan
A33: reference product | B33: Cr metal
A34: location | B34: GLO
A35: amount | B35: 1
A36: unit | B36: kilogram
A37: comment | B37: n/a
A38: Exchanges
A39: name | B39: reference product | C39: location | D39: amount | E39: unit | F39: database | G39: type | H39: categories | I39: uncertainty type | J39: pedigree | K39: loc | L39: scale | M39: minimum | N39: maximum
A40: =B32 -> Chromite ore mining and Cr metal production in South Africa/Finland/Kazakhstan | B40: =B33 -> Cr metal | C40: =B34 -> GLO | D40: 1 | E40: kilogram | F40: =F9 -> Chromium | G40: production
A41: =A9 -> [M+C+P+R] Chromium (Cr) metal production | B41: =B9 -> Cr Metal | C41: =C9 -> GLO | D41: 1 | E41: =E9 -> kilogram | F41: =F9 -> Chromium | G41: technosphere
