Workbook

Sheet Note
A1: skip
B2: Life cycle inventories of global metal and mineral supply chains: a comprehensive data review, analysis and processing Frédéric Laia*, Stéphanie Mullera, Audrey Philippea, Robert Istrateb, Brenda Miranda Xicotencatlb, Afsoon Mansouri Askic, Aina Mas Fonsd,a, Juliana Segura-Salazare, Jair Santillán Saldivara, Alexander Cimprichf, Stephen Northeyg, Lígia da Silva Limah, Lieselot Booneh, Ryosuke Yokoii, Kamrul Islami, Ioanna Paschalidouj, Felipe Cerdask,l, Victor Balboa-Espinozae, Anish Koyamparambathd, Diae Henniouia, Victoire Collignona, Aurélien Reysa, Gyslain Ngadi Sakatadim, Jo Dewulfh, Bernhard Steubingb, Christoph Helbigc, Gaétan Lefebvrea, Gian Andrea Blenginin,m, Valeria Supertio, Masaharu Motoshitai, Guido Sonnemannd, Kwame Awuah-Offeij, Steven B. Youngf, Shinsuke Murakamip, Antoine Beylota aBRGM, F-45060 Orléans, France bInstitute of Environmental Sciences (CML), Leiden University, Einsteinweg 2, 2333 CC Leiden, NL cEcological Resource Technology, University of Bayreuth, Universitätstr. 30, 95447 Bayreuth, Germany dUniv. Bordeaux, CNRS, Bordeaux INP, ISM, UMR 5255, F-33400 Talence, France eSustainable Minerals Institute, The University of Queensland, QLD, 4072, Australia fSchool of Environment, Enterprise and Development, University of Waterloo, 200 University Avenue West, Waterloo, Ontario N2L 3G1, Canada gUniversity of Technology Sydney, Institute for Sustainable Futures, Australia hSustainable Systems Engineering (STEN), Department of Green Chemistry and Technology, Faculty of Bioscience Engineering, Ghent University, Coupure Links 653, 9000 Ghent, Belgium iAIST, 305-8569 Tsukuba, Japan jMining & Explosives Engineering, Missouri University of Science & Technology, Rolla, MO, USA 65409 kInstitute for Sustainable Energy Systems (INSYS), Technical University of Applied Sciences Würzburg-Schweinfurt (THWS), Ignaz-Schön-Straße 11, Schweinfurt, Germany lFraunhofer Institute for Surface Engineering and Thin Films IST, Riedenkamp 2, Braunschweig 38108, Germany mDepartment of Environment, Land and Infrastructure Engineering, Politecnico di Torino, Corso Duca degli Abruzzi, 24, 10129 Torino, Italy nUniversity of Turin, Earth Sciences Department (DST), Via Valperga Caluso, 35 – 10125 Torino, Italy oecoinvent association, Technopark, Technoparkstrasse 1, 8005 Zürich, Switzerland pGraduate School of Engineering, The University of Tokyo, Tokyo 113-8656, Japan *Corresponding author: f.lai@brgm.fr This file provides all LCI datasets developed for Iron (Fe), with distinguishing its global market and each individual production route.
B33: Sheet | C33: Corresponding route
B34: Fe_Market_GLO | C34: Fe global market
B35: PR1_CrudeSteel_BR | C35: Iron ore mining and steel production in Brazil
B36: PR2_SteelAHSS_CN | C36: Iron ore mining and steel (AHSS) production in China
B37: PR3_Steel_CN_Shandong | C37: Steel billet production in China/Shandong
B38: PR4_CrudeSteel_CN | C38: Crude steel production in China through Blast Furnace-Basic Oxygen Furnace (BF-BOF)
B39: PR5_FeLiquid_CN | C39: Liquid iron production in China
B40: PR6_Steel_IT | C40: Steel production in Italy
B41: PR7_CrudeSteel_IN | C41: Steel production in India
B42: PR8_CrudeSteel_DE | C42: Steel production in Germany
B43: PR9_CrudeSteel_KR | C43: Steel production in Korea
B44: PR10_CrudeSteel_RU | C44: Steel production in Russia
... B47: PR13_Fe_CN_Recycling_ELV | C47: Fe production in China through ELV wastes recycling

Sheet Fe_Market_GLO
A1: database | B1: Iron
A3: Activity | B3: Iron (Fe) global market
A4: reference product | B4: Steel
A5: location | B5: GLO
A6: amount | B6: 1
A7: unit | B7: kilogram
A8: comment | B8: n/a
A9: Exchanges
A10: name | B10: reference product | C10: location | D10: amount | E10: unit | F10: database | G10: type | H10: categories | I10: uncertainty type | J10: pedigree | K10: loc | L10: scale | M10: minimum | N10: maximum
A11: =B3 -> Iron (Fe) global market | B11: =B4 -> Steel | C11: =B5 -> GLO | D11: 1 | E11: =B7 -> kilogram | F11: =B1 -> Iron | G11: production
A12: =PR1_CrudeSteel_BR!A93 -> Iron ore mining and steel production in Brazil | B12: =PR1_CrudeSteel_BR!B93 -> Steel | C12: =PR1_CrudeSteel_BR!C93 -> BR | D12: 0.021149674 | E12: =PR1_CrudeSteel_BR!E93 -> kilogram | F12: =PR1_CrudeSteel_BR!F93 -> Iron | G12: technosphere
A13: =PR2_SteelAHSS_CN!A56 -> Iron ore mining and steel (AHSS) production in China | B13: =PR2_SteelAHSS_CN!B56 -> Steel | C13: =PR2_SteelAHSS_CN!C56 -> CN | D13: 0.53226101 | E13: =PR2_SteelAHSS_CN!E56 -> kilogram | F13: =PR2_SteelAHSS_CN!F56 -> Iron | G13: technosphere
A14: =PR3_Steel_CN_Shandong!A124 -> Steel billet production in China/Shandong | B14: =PR3_Steel_CN_Shandong!B124 -> Steel | C14: =PR3_Steel_CN_Shandong!C124 -> CN | D14: 0.006313891 | E14: =PR3_Steel_CN_Shandong!E124 -> kilogram | F14: =PR3_Steel_CN_Shandong!F124 -> Iron | G14: technosphere
A15: =PR4_CrudeSteel_CN!A146 -> Crude steel production in China through Blast Furnace-Basic Oxygen Furnace (BF-BOF) | B15: =PR4_CrudeSteel_CN!B146 -> Steel | C15: =PR4_CrudeSteel_CN!C146 -> CN | D15: 0.046407099 | E15: =PR4_CrudeSteel_CN!E146 -> kilogram | F15: =PR4_CrudeSteel_CN!F146 -> Iron | G15: technosphere
A16: =PR5_FeLiquid_CN!A76 -> Liquid iron production in China | B16: =PR5_FeLiquid_CN!B76 -> Steel | C16: =PR5_FeLiquid_CN!C76 -> CN | D16: 0.046407099 | E16: =PR5_FeLiquid_CN!E76 -> kilogram | F16: =PR5_FeLiquid_CN!F76 -> Iron | G16: technosphere
A17: =PR6_Steel_IT!A137 -> Steel production in Italy | B17: =PR6_Steel_IT!B137 -> Steel | C17: =PR6_Steel_IT!C137 -> IT | D17: 0.013396861 | E17: =PR6_Steel_IT!E137 -> kilogram | F17: =PR6_Steel_IT!F137 -> Iron | G17: technosphere
A18: =PR7_CrudeSteel_IN!A34 -> Steel production in India | B18: =PR7_CrudeSteel_IN!B34 -> Steel | C18: =PR7_CrudeSteel_IN!C34 -> IN | D18: 0.077714199 | E18: =PR7_CrudeSteel_IN!E34 -> kilogram | F18: =PR7_CrudeSteel_IN!F34 -> Iron | G18: technosphere
A19: =PR8_CrudeSteel_DE!A41 -> Steel production in Germany | B19: =PR8_CrudeSteel_DE!B41 -> Steel | C19: =PR8_CrudeSteel_DE!C41 -> DE | D19: 0.022824282 | E19: =PR8_CrudeSteel_DE!E41 -> kilogram | F19: =PR8_CrudeSteel_DE!F41 -> Iron | G19: technosphere
A20: =PR9_CrudeSteel_KR!A27 -> Steel production in Korea | B20: =PR9_CrudeSteel_KR!B27 -> Steel | C20: =PR9_CrudeSteel_KR!C27 -> KR | D20: 0.040810809 | E20: =PR9_CrudeSteel_KR!E27 -> kilogram | F20: =PR9_CrudeSteel_KR!F27 -> Iron | G20: technosphere
A21: =PR10_CrudeSteel_RU!A29 -> Steel production in Russia | B21: =PR10_CrudeSteel_RU!B29 -> Steel | C21: =PR10_CrudeSteel_RU!C29 -> RU | D21: 0.044346091 | E21: =PR10_CrudeSteel_RU!E29 -> kilogram | F21: =PR10_CrudeSteel_RU!F29 -> Iron | G21: technosphere
A22: =PR11_CrudeSteel_TR!A48 -> Steel production in Turkey | B22: =PR11_CrudeSteel_TR!B48 -> Steel | C22: =PR11_CrudeSteel_TR!C48 -> TR | D22: 0.021769899 | E22: =PR11_CrudeSteel_TR!E48 -> kilogram | F22: =PR11_CrudeSteel_TR!F48 -> Iron | G22: technosphere
A23: =PR12_Fe_CN_Recycling_CDW!A36 -> Fe production in China through C&D wastes recycling | B23: =PR12_Fe_CN_Recycling_CDW!B36 -> Steel | C23: =PR12_Fe_CN_Recycling_CDW!C36 -> CN | D23: 0.10680143 | E23: =PR12_Fe_CN_Recycling_CDW!E36 -> kilogram | F23: =PR12_Fe_CN_Recycling_CDW!F36 -> Iron | G23: technosphere
A24: =PR13_Fe_CN_Recycling_ELV!A35 -> Fe production in China through ELV wastes recycling | B24: =PR13_Fe_CN_Recycling_ELV!B35 -> Steel | C24: =PR13_Fe_CN_Recycling_ELV!C35 -> CN | D24: 0.019797653 | E24: =PR13_Fe_CN_Recycling_ELV!E35 -> kilogram | F24: =PR13_Fe_CN_Recycling_ELV!F35 -> Iron | G24: technosphere

Sheet FeMine_Market_GLO
A1: Activity | B1: [M+C] Iron (Fe) ore mining and concentration (Australia)
A2: reference product | B2: Fe concentrate
A3: location | B3: AU
A4: amount | B4: 1
A5: unit | B5: kilogram
A6: comment | B6: n/a
A7: Exchanges
A8: name | B8: reference product | C8: location | D8: amount | E8: unit | F8: database | G8: type | H8: categories | I8: uncertainty type | J8: pedigree | K8: loc | L8: scale | M8: minimum | N8: maximum
A9: =B1 -> [M+C] Iron (Fe) ore mining and concentration (Australia) | B9: =B2 -> Fe concentrate | C9: =B3 -> AU | D9: 1 | E9: kilogram | F9: =Fe_Market_GLO!B1 -> Iron | G9: production
A10: market for diesel, burned in building machine | B10: diesel, burned in building machine | C10: GLO | D10: 0.00135 | E10: megajoule | F10: ecoinvent 3.10 cutoff | G10: technosphere | J10: (3,5,4,1,2)
A11: market for explosive, tovex | B11: explosive, tovex | C11: GLO | D11: 0.0005 | E11: kilogram | F11: ecoinvent 3.10 cutoff | G11: technosphere | J11: (3,5,4,1,2)
A12: market for diesel, burned in building machine | B12: diesel, burned in building machine | C12: GLO | D12: 0.099 | E12: megajoule | F12: ecoinvent 3.10 cutoff | G12: technosphere | J12: (3,5,4,1,2)
A13: market for electricity, medium voltage | B13: electricity, medium voltage | C13: AU | D13: 0.0025 | E13: kilowatt hour | F13: ecoinvent 3.10 cutoff | G13: technosphere | J13: (3,5,4,1,2)
A14: market for electricity, medium voltage | B14: electricity, medium voltage | C14: AU | D14: 0.0005 | E14: kilowatt hour | F14: ecoinvent 3.10 cutoff | G14: technosphere | J14: (3,5,4,1,2)
A15: market for diesel, burned in building machine | B15: diesel, burned in building machine | C15: GLO | D15: 0.0225 | E15: megajoule | F15: ecoinvent 3.10 cutoff | G15: technosphere | J15: (3,5,4,1,2)
A16: market for electricity, medium voltage | B16: electricity, medium voltage | C16: AU | D16: 0.0008 | E16: kilowatt hour | F16: ecoinvent 3.10 cutoff | G16: technosphere | J16: (3,5,4,1,2)
A17: market for non-sulfidic overburden, off-site | B17: non-sulfidic overburden, off-site | C17: GLO | D17: -0.0013 | E17: kilogram | F17: ecoinvent 3.10 cutoff | G17: technosphere | J17: (3,5,4,1,2)
A18: Water, unspecified natural origin | D18: 0.00021 | E18: cubic meter | F18: biosphere3 | G18: biosphere | H18: natural resource::in ground | J18: (3,5,4,1,2)
A20: Activity | B20: [M+C] Iron (Fe) ore mining and concentration (Canada)
A21: reference product | B21: Fe concentrate
A22: location | B22: CA
A23: amount | B23: 1
A24: unit | B24: kilogram
A25: comment | B25: n/a
A26: Exchanges
A27: name | B27: reference product | C27: location | D27: amount | E27: unit | F27: database | G27: type | H27: categories | I27: uncertainty type | J27: pedigree | K27: loc | L27: scale | M27: minimum | N27: maximum
A28: =B20 -> [M+C] Iron (Fe) ore mining and concentration (Canada) | B28: =B21 -> Fe concentrate | C28: =B22 -> CA | D28: 1 | E28: kilogram | F28: =F9 -> Iron | G28: production
A29: market for diesel, burned in building machine | B29: diesel, burned in building machine | C29: GLO | D29: 0.059 | E29: megajoule | F29: ecoinvent 3.10 cutoff | G29: technosphere | J29: (4,5,4,5,4)
A30: market group for electricity, medium voltage | B30: electricity, medium voltage | C30: CA | D30: 0.0024 | E30: kilowatt hour | F30: ecoinvent 3.10 cutoff | G30: technosphere | J30: (4,5,4,5,4)
A31: market for explosive, tovex | B31: explosive, tovex | C31: GLO | D31: 0.0047 | E31: kilogram | F31: ecoinvent 3.10 cutoff | G31: technosphere | J31: (4,5,4,5,4)
A32: market for rock crushing | B32: rock crushing | C32: GLO | D32: 2.4e-10 | E32: kilogram | F32: ecoinvent 3.10 cutoff | G32: technosphere | J32: (4,5,4,5,4)
A33: Water, unspecified natural origin | D33: 0.0002 | E33: cubic meter | F33: biosphere3 | G33: biosphere | H33: natural resource::in ground | J33: (4,5,4,5,4)
A34: Particulate Matter, < 2.5 um | D34: 0.0013 | E34: kilogram | F34: biosphere3 | G34: biosphere | H34: air | J34: (4,5,4,5,4)
A35: Particulate Matter, > 10 um | D35: 0.0014 | E35: kilogram | F35: biosphere3 | G35: biosphere | H35: air | J35: (4,5,4,5,4)
A36: Particulate Matter, > 2.5 um and < 10um | D36: 0.00014 | E36: kilogram | F36: biosphere3 | G36: biosphere | H36: air | J36: (4,5,4,5,4)
A38: Activity | B38: [M+C] Iron (Fe) ore mining and concentration (South Africa)
A39: reference product | B39: Fe concentrate
A40: location | B40: ZA
A41: amount | B41: 1
A42: unit | B42: kilogram
...

Sheet PR1_CrudeSteel_BR
A1: Activity | B1: [M+C] Iron (Fe) ore mining and concentration (Brazil)
A2: reference product | B2: Fe concentrate
A3: location | B3: BR
A4: amount | B4: 1
A5: unit | B5: kilogram
A6: comment | B6: n/a
A7: Exchanges
A8: name | B8: reference product | C8: location | D8: amount | E8: unit | F8: database | G8: type | H8: categories | I8: uncertainty type | J8: pedigree | K8: loc | L8: scale | M8: minimum | N8: maximum
A9: =B1 -> [M+C] Iron (Fe) ore mining and concentration (Brazil) | B9: =B2 -> Fe concentrate | C9: =B3 -> BR | D9: 1 | E9: kilogram | F9: =Fe_Market_GLO!B1 -> Iron | G9: production
A10: market for diesel, burned in building machine | B10: diesel, burned in building machine | C10: GLO | D10: 0.021924 | E10: megajoule | F10: ecoinvent 3.10 cutoff | G10: technosphere | J10: (1,1,3,1,1)
A11: market for conveyor belt | B11: conveyor belt | C11: GLO | D11: 1.09736e-08 | E11: meter | F11: ecoinvent 3.10 cutoff | G11: technosphere | J11: (1,1,3,1,1)
A12: market group for electricity, medium voltage | B12: electricity, medium voltage | C12: BR | D12: 0.0026216 | E12: kilowatt hour | F12: ecoinvent 3.10 cutoff | G12: technosphere | J12: (1,1,3,1,1)
A13: market for explosive, tovex | B13: explosive, tovex | C13: GLO | D13: 0.0203696 | E13: kilogram | F13: ecoinvent 3.10 cutoff | G13: technosphere | J13: (1,1,3,1,1)
A14: market for industrial machine, heavy, unspecified | B14: industrial machine, heavy, unspecified | C14: RoW | D14: 5.5216e-10 | E14: kilogram | F14: ecoinvent 3.10 cutoff | G14: technosphere | J14: (1,1,3,1,1)
A15: market for diesel, burned in building machine | B15: diesel, burned in building machine | C15: GLO | D15: 0.0205784 | E15: megajoule | F15: ecoinvent 3.10 cutoff | G15: technosphere | J15: (1,1,3,1,1)
A16: market group for electricity, medium voltage | B16: electricity, medium voltage | C16: BR | D16: 0.986 | E16: kilowatt hour | F16: ecoinvent 3.10 cutoff | G16: technosphere | J16: (1,1,3,1,1)
A17: market for amine oxides | B17: amine oxides | C17: GLO | D17: 0.000121 | E17: kilogram | F17: ecoinvent 3.10 cutoff | G17: technosphere | J17: (1,1,3,1,1)
A18: market for chemical, inorganic | B18: chemical, inorganic | C18: GLO | D18: 6.84e-06 | E18: kilogram | F18: ecoinvent 3.10 cutoff | G18: technosphere | J18: (1,1,3,1,1)
A19: market for chemical, organic | B19: chemical, organic | C19: GLO | D19: 3.13e-05 | E19: kilogram | F19: ecoinvent 3.10 cutoff | G19: technosphere | J19: (1,1,3,1,1)
A20: market for chemical, organic | B20: chemical, organic | C20: GLO | D20: 1.67e-06 | E20: kilogram | F20: ecoinvent 3.10 cutoff | G20: technosphere | J20: (1,1,3,1,1)
A21: market for potato starch | B21: potato starch | C21: GLO | D21: 0.00117 | E21: kilogram | F21: ecoinvent 3.10 cutoff | G21: technosphere | J21: (1,1,3,1,1)
... A33: market for hazardous waste, for incineration | B33: hazardous waste, for incineration | C33: RoW | D33: -2e-06 | E33: kilogram | F33: ecoinvent 3.10 cutoff | G33: technosphere | J33: (1,1,3,1,1)
A34: Occupation, mineral extraction site | D34: 2.0996e-06 | E34: square meter-year | F34: biosphere3 | G34: biosphere | H34: natural resource::land | J34: (1,1,3,1,1)
A35: Transformation, from unspecified | D35: 2.8072e-08 | E35: square meter | F35: biosphere3 | G35: biosphere | H35: natural resource::land | J35: (1,1,3,1,1)
A36: Transformation, to mineral extraction site | D36: 2.8072e-08 | E36: square meter | F36: biosphere3 | G36: biosphere | H36: natural resource::land | J36: (1,1,3,1,1)
A37: Occupation, industrial area | D37: 2.15992e-06 | E37: square meter-year | F37: biosphere3 | G37: biosphere | H37: natural resource::land | J37: (1,1,3,1,1)
A38: Transformation, from unspecified | D38: 2.8768e-10 | E38: square meter | F38: biosphere3 | G38: biosphere | H38: natural resource::land | J38: (1,1,3,1,1)
A39: Transformation, to industrial area | D39: 2.8768e-10 | E39: square meter | F39: biosphere3 | G39: biosphere | H39: natural resource::land | J39: (1,1,3,1,1)
A40: Transformation, to industrial area | D40: 1.10664e-10 | E40: square meter | F40: biosphere3 | G40: biosphere | H40: natural resource::land | J40: (1,1,3,1,1)
A41: Transformation, to unspecified, natural (non-use) | D41: 2.8072e-08 | E41: square meter | F41: biosphere3 | G41: biosphere | H41: natural resource::land | J41: (1,1,3,1,1)
A42: Iron | D42: 0.9976 | E42: kilogram | F42: biosphere3 | G42: biosphere | H42: natural resource::in ground | J42: (1,1,3,1,1)
A43: Water, unspecified natural origin | D43: 0.000874 | E43: cubic meter | F43: biosphere3 | G43: biosphere | H43: natural resource::in ground | J43: (1,1,3,1,1)
A45: Activity | B45: [P+R] Crude steel production (Brazil)
A46: reference product | B46: Steel
A47: location | B47: BR
A48: amount | B48: 1
A49: unit | B49: kilogram
A50: comment | B50: n/a
A51: Exchanges
A52: name | B52: reference product | C52: location | D52: amount | E52: unit | F52: database | G52: type | H52: categories | I52: uncertainty type | J52: pedigree | K52: loc | L52: scale | M52: minimum | N52: maximum
...

Sheet PR2_SteelAHSS_CN
A1: Activity | B1: [M+C] Iron (Fe) ore mining and concentration (China)
A2: reference product | B2: Fe concentrate
A3: location | B3: CN
A4: amount | B4: 1
A5: unit | B5: kilogram
A6: comment | B6: n/a
A7: Exchanges
A8: name | B8: reference product | C8: location | D8: amount | E8: unit | F8: database | G8: type | H8: categories | I8: uncertainty type | J8: pedigree | K8: loc | L8: scale | M8: minimum | N8: maximum
A9: =B1 -> [M+C] Iron (Fe) ore mining and concentration (China) | B9: =B2 -> Fe concentrate | C9: =B3 -> CN | D9: 1 | E9: kilogram | F9: =Fe_Market_GLO!B1 -> Iron | G9: production
A10: market for iron ore, crude ore, 46% Fe | B10: iron ore, crude ore, 46% Fe | C10: GLO | D10: 2.2998478 | E10: kilogram | F10: ecoinvent 3.10 cutoff | G10: technosphere | J10: (1.0,1,5,1,1)
A11: market for steel, low-alloyed | B11: steel, low-alloyed | C11: GLO | D11: 0.0010147133 | E11: kilogram | F11: ecoinvent 3.10 cutoff | G11: technosphere | J11: (1.0,1,5,1,1)
A12: market group for electricity, medium voltage | B12: electricity, medium voltage | C12: CN | D12: 0.037544394 | E12: kilowatt hour | F12: ecoinvent 3.10 cutoff | G12: technosphere | J12: (1.0,1,5,1,1)
A13: market for non-sulfidic tailing, off-site | B13: non-sulfidic tailing, off-site | C13: GLO | D13: -1.072552 | E13: kilogram | F13: ecoinvent 3.10 cutoff | G13: technosphere | J13: (1.0,1,5,1,1)
A14: Carbon dioxide, fossil | D14: 0.18396753 | E14: kilogram | F14: biosphere3 | G14: biosphere | H14: air | J14: (5.0,1,5,1,1)
A15: Sulfur dioxide | D15: 0.015638762 | E15: kilogram | F15: biosphere3 | G15: biosphere | H15: air | J15: (5.0,1,5,1,1)
A16: Carbon monoxide, fossil | D16: 0.11499239 | E16: kilogram | F16: biosphere3 | G16: biosphere | H16: air | J16: (5.0,1,5,1,1)
A17: Nitrogen oxides | D17: 0.0073597159 | E17: kilogram | F17: biosphere3 | G17: biosphere | H17: air | J17: (5.0,1,5,1,1)
A18: Methane, fossil | D18: 0.0052897007 | E18: kilogram | F18: biosphere3 | G18: biosphere | H18: air | J18: (5.0,1,5,1,1)
A19: Particulate Matter, > 2.5 um and < 10um | D19: 0.075895485 | E19: kilogram | F19: biosphere3 | G19: biosphere | H19: air | J19: (5.0,1,5,1,1)
A21: Activity | B21: [P+R] Steel production (AHSS)
A22: reference product | B22: Steel
A23: location | B23: CN
A24: amount | B24: 1
A25: unit | B25: kilogram
A26: comment | B26: n/a
A27: Exchanges
A28: name | B28: reference product | C28: location | D28: amount | E28: unit | F28: database | G28: type | H28: categories | I28: uncertainty type | J28: pedigree | K28: loc | L28: scale | M28: minimum | N28: maximum
A29: =B21 -> [P+R] Steel production (AHSS) | B29: =B22 -> Steel | C29: =B23 -> CN | D29: 1 | E29: kilogram | F29: =Fe_Market_GLO!B1 -> Iron | G29: production
A30: market for hard coal | B30: hard coal | C30: CN | D30: 0.043083333 | E30: kilogram | F30: ecoinvent 3.10 cutoff | G30: technosphere | J30: (4,1,3,2,2)
A31: market group for electricity, medium voltage | B31: electricity, medium voltage | C31: CN | D31: 0.1366965 | E31: kilowatt hour | F31: ecoinvent 3.10 cutoff | G31: technosphere | J31: (4,1,3,2,2)
A32: market for limestone, crushed, washed | B32: limestone, crushed, washed | C32: RoW | D32: 0.009 | E32: kilogram | F32: ecoinvent 3.10 cutoff | G32: technosphere | J32: (4,1,3,2,2)
A33: market for hard coal | B33: hard coal | C33: CN | D33: 0.98916667 | E33: kilogram | F33: ecoinvent 3.10 cutoff | G33: technosphere | J33: (4,1,3,2,2)
A34: market group for electricity, medium voltage | B34: electricity, medium voltage | C34: CN | D34: 0.23759154 | E34: kilowatt hour | F34: ecoinvent 3.10 cutoff | G34: technosphere | J34: (4,1,3,2,2)
A35: market for hard coal | B35: hard coal | C35: CN | D35: 0.051833333 | E35: kilogram | F35: ecoinvent 3.10 cutoff | G35: technosphere | J35: (4,1,3,2,2)
A36: market group for electricity, medium voltage | B36: electricity, medium voltage | C36: CN | D36: 0.097640358 | E36: kilowatt hour | F36: ecoinvent 3.10 cutoff | G36: technosphere | J36: (4,1,3,2,2)
A37: market for limestone, crushed, washed | B37: limestone, crushed, washed | C37: RoW | D37: 0.043 | E37: kilogram | F37: ecoinvent 3.10 cutoff | G37: technosphere | J37: (4,1,3,2,2)
A38: market group for electricity, medium voltage | B38: electricity, medium voltage | C38: CN | D38: 0.16842962 | E38: kilowatt hour | F38: ecoinvent 3.10 cutoff | G38: technosphere | J38: (4,1,3,2,2)
A39: market for limestone, crushed, washed | B39: limestone, crushed, washed | C39: RoW | D39: 0.063 | E39: kilogram | F39: ecoinvent 3.10 cutoff | G39: technosphere | J39: (4,1,3,2,2)
A40: market for natural gas, high pressure | B40: natural gas, high pressure | C40: CN | D40: 0.032166667 | E40: cubic meter | F40: ecoinvent 3.10 cutoff | G40: technosphere | J40: (4,1,3,2,2)
A41: market group for electricity, medium voltage | B41: electricity, medium voltage | C41: CN | D41: 0.15703824 | E41: kilowatt hour | F41: ecoinvent 3.10 cutoff | G41: technosphere | J41: (4,1,3,2,2)
...

Sheet PR3_Steel_CN_Shandong
A1: Activity | B1: [P] Sintering (Shandong)
A2: reference product | B2: Iron (Fe) sinter
A3: location | B3: CN
A4: amount | B4: 1
A5: unit | B5: kilogram
A6: comment | B6: n/a
A7: Exchanges
A8: name | B8: reference product | C8: location | D8: amount | E8: unit | F8: database | G8: type | H8: categories | I8: uncertainty type | J8: pedigree | K8: loc | L8: scale | M8: minimum | N8: maximum
A9: =B1 -> [P] Sintering (Shandong) | B9: =B2 -> Iron (Fe) sinter | C9: =B3 -> CN | D9: 1 | E9: kilogram | F9: =Fe_Market_GLO!B1 -> Iron | G9: production
A10: market for ferrite | B10: ferrite | C10: GLO | D10: 0.16923077 | E10: kilogram | F10: ecoinvent 3.10 cutoff | G10: technosphere | J10: (1,1,2,1,1)
A11: market for quicklime, milled, packed | B11: quicklime, milled, packed | C11: RoW | D11: 0.10769231 | E11: kilogram | F11: ecoinvent 3.10 cutoff | G11: technosphere | J11: (1,1,2,1,1)
A12: market for dolomite | B12: dolomite | C12: RoW | D12: 0.061538462 | E12: kilogram | F12: ecoinvent 3.10 cutoff | G12: technosphere | J12: (1,1,2,1,1)
A13: market for water, completely softened | B13: water, completely softened | C13: RoW | D13: 0.00044615385 | E13: kilogram | F13: ecoinvent 3.10 cutoff | G13: technosphere | J13: (1,1,2,1,1)
A14: market group for electricity, medium voltage | B14: electricity, medium voltage | C14: CN | D14: 0.033215385 | E14: kilowatt hour | F14: ecoinvent 3.10 cutoff | G14: technosphere | J14: (1,1,2,1,1)
A15: market for charcoal | B15: charcoal | C15: GLO | D15: 0.030769231 | E15: kilogram | F15: ecoinvent 3.10 cutoff | G15: technosphere | J15: (1,1,2,1,1)
A16: =A106 -> Coke production (Shandong) | B16: =B106 -> Coke | C16: =C106 -> CN | D16: 0.030769231 | E16: kilogram | F16: =F106 -> Iron | G16: technosphere | J16: (1,1,2,1,1)
A17: market for gypsum, mineral | B17: gypsum, mineral | C17: RoW | D17: -0.0049076923 | E17: kilogram | F17: ecoinvent 3.10 cutoff | G17: technosphere | J17: (1,1,2,1,1)
A18: Water, unspecified natural origin | D18: 0.00010769231 | E18: cubic meter | F18: biosphere3 | G18: biosphere | H18: natural resource::in ground | J18: (1,1,2,1,1)
A19: Sulfur dioxide | D19: 0.00036923077 | E19: kilogram | F19: biosphere3 | G19: biosphere | H19: air | J19: (1,1,2,1,1)
A20: Particulate Matter, > 2.5 um and < 10um | D20: 2.3076923e-05 | E20: kilogram | F20: biosphere3 | G20: biosphere | H20: air | J20: (1,1,2,1,1)
A22: Activity | B22: [R] Fe production - Blast Furnace (Shandong)
A23: reference product | B23: Fe
A24: location | B24: CN
A25: amount | B25: 1
A26: unit | B26: kilogram
A27: comment | B27: n/a
A28: Exchanges
A29: name | B29: reference product | C29: location | D29: amount | E29: unit | F29: database | G29: type | H29: categories | I29: uncertainty type | J29: pedigree | K29: loc | L29: scale | M29: minimum | N29: maximum
A30: =B22 -> [R] Fe production - Blast Furnace (Shandong) | B30: =B23 -> Fe | C30: =B24 -> CN | D30: 1 | E30: kilogram | F30: =F9 -> Iron | G30: production
A31: market for compressed air, 800 kPa gauge | B31: compressed air, 800 kPa gauge | C31: RoW | D31: 9.2839335 | E31: cubic meter | F31: ecoinvent 3.10 cutoff | G31: technosphere | J31: (1,1,2,1,1)
A32: market for compressed air, 800 kPa gauge | B32: compressed air, 800 kPa gauge | C32: RoW | D32: 1.1722763 | E32: cubic meter | F32: ecoinvent 3.10 cutoff | G32: technosphere | J32: (1,1,2,1,1)
A33: market for compressed air, 800 kPa gauge | B33: compressed air, 800 kPa gauge | C33: RoW | D33: 0.045184211 | E33: cubic meter | F33: ecoinvent 3.10 cutoff | G33: technosphere | J33: (1,1,2,1,1)
A34: market for nitrogen, liquid | B34: nitrogen, liquid | C34: RoW | D34: 0.097648026 | E34: kilogram | F34: ecoinvent 3.10 cutoff | G34: technosphere | J34: (1,1,2,1,1)
A35: market for iron ore, crude ore, 46% Fe | B35: iron ore, crude ore, 46% Fe | C35: GLO | D35: 0.19736842 | E35: kilogram | F35: ecoinvent 3.10 cutoff | G35: technosphere | J35: (1,1,2,1,1)
A36: market for steam, in chemical industry | B36: steam, in chemical industry | C36: RoW | D36: 0.026315789 | E36: kilogram | F36: ecoinvent 3.10 cutoff | G36: technosphere | J36: (1,1,2,1,1)
A37: market for water, ultrapure | B37: water, ultrapure | C37: RoW | D37: 0.026315789 | E37: kilogram | F37: ecoinvent 3.10 cutoff | G37: technosphere | J37: (1,1,2,1,1)
A38: market group for electricity, medium voltage | B38: electricity, medium voltage | C38: CN | D38: 0.027210526 | E38: kilowatt hour | F38: ecoinvent 3.10 cutoff | G38: technosphere | J38: (1,1,2,1,1)
A39: =A106 -> Coke production (Shandong) | B39: =B106 -> Coke | C39: =C106 -> CN | D39: 0.40789474 | E39: kilogram | F39: =F106 -> Iron | G39: technosphere | J39: (1,1,2,1,1)
A40: market for hard coal | B40: hard coal | C40: CN | D40: 0.13157895 | E40: kilogram | F40: ecoinvent 3.10 cutoff | G40: technosphere | J40: (1,1,2,1,1)
A41: market for inert waste, for final disposal | B41: inert waste, for final disposal | C41: RoW | D41: -0.00575 | E41: kilogram | F41: ecoinvent 3.10 cutoff | G41: technosphere | J41: (1,1,2,1,1)
...

Sheet PR4_CrudeSteel_CN
A1: Activity | B1: [P] Pelletizing
A2: reference product | B2: Iron (Fe) pellets
A3: location | B3: CN
A4: amount | B4: 1
A5: unit | B5: kilogram
A6: comment | B6: n/a
A7: Exchanges
A8: name | B8: reference product | C8: location | D8: amount | E8: unit | F8: database | G8: type | H8: categories | I8: uncertainty type | J8: pedigree | K8: loc | L8: scale | M8: minimum | N8: maximum
A9: =B1 -> [P] Pelletizing | B9: =B2 -> Iron (Fe) pellets | C9: =B3 -> CN | D9: 1 | E9: kilogram | F9: =Fe_Market_GLO!B1 -> Iron | G9: production
A10: market for hard coal | B10: hard coal | C10: CN | D10: 0.031088489 | E10: kilogram | F10: ecoinvent 3.10 cutoff | G10: technosphere | J10: (1,1,1,1,1)
A11: market for diesel | B11: diesel | C11: RoW | D11: 0.0014487079 | E11: kilogram | F11: ecoinvent 3.10 cutoff | G11: technosphere | J11: (1,1,1,1,1)
A12: market for light fuel oil | B12: light fuel oil | C12: RoW | D12: 0.00030148786 | E12: kilogram | F12: ecoinvent 3.10 cutoff | G12: technosphere | J12: (1,1,1,1,1)
A13: market for light fuel oil | B13: light fuel oil | C13: RoW | D13: 0.0012920908 | E13: kilogram | F13: ecoinvent 3.10 cutoff | G13: technosphere | J13: (1,1,1,1,1)
A14: market group for electricity, medium voltage | B14: electricity, medium voltage | C14: CN | D14: 0.02486296 | E14: kilowatt hour | F14: ecoinvent 3.10 cutoff | G14: technosphere | J14: (1,1,1,1,1)
A15: market for bentonite | B15: bentonite | C15: GLO | D15: 0.015622553 | E15: kilogram | F15: ecoinvent 3.10 cutoff | G15: technosphere | J15: (1,1,1,1,1)
A16: Water, unspecified natural origin | D16: 0.00010422866 | E16: cubic meter | F16: biosphere3 | G16: biosphere | H16: natural resource::in ground | J16: (1,1,1,1,1)
A17: Carbon dioxide, fossil | D17: 0.053346319 | E17: kilogram | F17: biosphere3 | G17: biosphere | H17: air | J17: (1,1,1,1,1)
A18: Carbon monoxide, fossil | D18: 0.0028905337 | E18: kilogram | F18: biosphere3 | G18: biosphere | H18: air | J18: (1,1,1,1,1)
A19: Sulfur dioxide | D19: 0.00010128555 | E19: kilogram | F19: biosphere3 | G19: biosphere | H19: air | J19: (1,1,1,1,1)
A20: Nitrogen oxides | D20: 0.00010128555 | E20: kilogram | F20: biosphere3 | G20: biosphere | H20: air | J20: (1,1,1,1,1)
A21: Particulate Matter, > 2.5 um and < 10um | D21: 0.00045188937 | E21: kilogram | F21: biosphere3 | G21: biosphere | H21: air | J21: (1,1,1,1,1)
A23: Activity | B23: [P] Sintering
A24: reference product | B24: Fe sinter
A25: location | B25: CN
A26: amount | B26: 1
A27: unit | B27: kilogram
A28: comment | B28: n/a
A29: Exchanges
A30: name | B30: reference product | C30: location | D30: amount | E30: unit | F30: database | G30: type | H30: categories | I30: uncertainty type | J30: pedigree | K30: loc | L30: scale | M30: minimum | N30: maximum
A31: =B23 -> [P] Sintering | B31: =B24 -> Fe sinter | C31: =B25 -> CN | D31: 1 | E31: kilogram | F31: =F9 -> Iron | G31: production
A32: market for charcoal | B32: charcoal | C32: GLO | D32: 0.032107519 | E32: kilogram | F32: ecoinvent 3.10 cutoff | G32: technosphere | J32: (1,1,1,1,1)
A33: market group for electricity, medium voltage | B33: electricity, medium voltage | C33: CN | D33: 0.045040904 | E33: kilowatt hour | F33: ecoinvent 3.10 cutoff | G33: technosphere | J33: (1,1,1,1,1)
A34: market for steam, in chemical industry | B34: steam, in chemical industry | C34: RoW | D34: 0.0024698091 | E34: kilogram | F34: ecoinvent 3.10 cutoff | G34: technosphere | J34: (1,1,1,1,1)
A35: market for quicklime, milled, packed | B35: quicklime, milled, packed | C35: RoW | D35: 0.0066225166 | E35: kilogram | F35: ecoinvent 3.10 cutoff | G35: technosphere | J35: (1,1,1,1,1)
A36: market for ammonia, anhydrous, liquid | B36: ammonia, anhydrous, liquid | C36: CN | D36: 0.00063887807 | E36: kilogram | F36: ecoinvent 3.10 cutoff | G36: technosphere | J36: (1,1,1,1,1)
A37: market for coke | B37: coke | C37: CN | D37: 0.71608882 | E37: megajoule | F37: ecoinvent 3.10 cutoff | G37: technosphere | J37: (1,1,1,1,1)
A38: market for compressed air, 800 kPa gauge | B38: compressed air, 800 kPa gauge | C38: RoW | D38: 0.00029606545 | E38: cubic meter | F38: ecoinvent 3.10 cutoff | G38: technosphere | J38: (1,1,1,1,1)
A39: market for limestone, crushed, washed | B39: limestone, crushed, washed | C39: RoW | D39: 0.14031944 | E39: kilogram | F39: ecoinvent 3.10 cutoff | G39: technosphere | J39: (1,1,1,1,1)
A40: market for wastewater, average | B40: wastewater, average | C40: RoW | D40: -3.0385664e-07 | E40: cubic meter | F40: ecoinvent 3.10 cutoff | G40: technosphere | J40: (1,1,1,1,1)
A41: Water, unspecified natural origin | D41: 6.977016e-05 | E41: cubic meter | F41: biosphere3 | G41: biosphere | H41: natural resource::in ground | J41: (1,1,1,1,1)
...

Sheet PR5_FeLiquid_CN
A1: Activity | B1: [P] Sintering (Liquid iron)
A2: reference product | B2: Iron (Fe) sinter
A3: location | B3: CN
A4: amount | B4: 1
A5: unit | B5: kilogram
A6: comment | B6: n/a
A7: Exchanges
A8: name | B8: reference product | C8: location | D8: amount | E8: unit | F8: database | G8: type | H8: categories | I8: uncertainty type | J8: pedigree | K8: loc | L8: scale | M8: minimum | N8: maximum
A9: =B1 -> [P] Sintering (Liquid iron) | B9: =B2 -> Iron (Fe) sinter | C9: =B3 -> CN | D9: 1 | E9: kilogram | F9: =Fe_Market_GLO!B1 -> Iron | G9: production
A10: market for charcoal | B10: charcoal | C10: GLO | D10: 0.032107519 | E10: kilogram | F10: ecoinvent 3.10 cutoff | G10: technosphere | J10: (1,1,1,1,1)
A11: market group for electricity, medium voltage | B11: electricity, medium voltage | C11: CN | D11: 0.045040904 | E11: kilowatt hour | F11: ecoinvent 3.10 cutoff | G11: technosphere | J11: (1,1,1,1,1)
A12: market for steam, in chemical industry | B12: steam, in chemical industry | C12: RoW | D12: 0.0024698091 | E12: kilogram | F12: ecoinvent 3.10 cutoff | G12: technosphere | J12: (1,1,1,1,1)
A13: market for quicklime, milled, packed | B13: quicklime, milled, packed | C13: RoW | D13: 0.0066225166 | E13: kilogram | F13: ecoinvent 3.10 cutoff | G13: technosphere | J13: (1,1,1,1,1)
A14: market for ammonia, anhydrous, liquid | B14: ammonia, anhydrous, liquid | C14: CN | D14: 0.00063887807 | E14: kilogram | F14: ecoinvent 3.10 cutoff | G14: technosphere | J14: (1,1,1,1,1)
A15: market for coke | B15: coke | C15: CN | D15: 0.71608882 | E15: megajoule | F15: ecoinvent 3.10 cutoff | G15: technosphere | J15: (1,1,1,1,1)
A16: market for compressed air, 800 kPa gauge | B16: compressed air, 800 kPa gauge | C16: RoW | D16: 0.00029606545 | E16: cubic meter | F16: ecoinvent 3.10 cutoff | G16: technosphere | J16: (1,1,1,1,1)
A17: market for limestone, crushed, washed | B17: limestone, crushed, washed | C17: RoW | D17: 0.14031944 | E17: kilogram | F17: ecoinvent 3.10 cutoff | G17: technosphere | J17: (1,1,1,1,1)
A18: market for wastewater, average | B18: wastewater, average | C18: RoW | D18: -3.0385664e-07 | E18: cubic meter | F18: ecoinvent 3.10 cutoff | G18: technosphere | J18: (1,1,1,1,1)
A19: Carbon dioxide, fossil | D19: 0.00301 | E19: kilogram | F19: biosphere3 | G19: biosphere | H19: air | J19: (1,1,2,1,1)
A20: Methane, fossil | D20: 5.84375e-08 | E20: kilogram | F20: biosphere3 | G20: biosphere | H20: air | J20: (1,1,2,1,1)
A21: Nitrogen oxides | D21: 5.84375e-09 | E21: kilogram | F21: biosphere3 | G21: biosphere | H21: air | J21: (1,1,2,1,1)
A22: Water, unspecified natural origin | D22: 6.977016e-05 | E22: cubic meter | F22: biosphere3 | G22: biosphere | H22: natural resource::in ground | J22: (1,1,1,1,1)
A23: Particulate Matter, > 2.5 um and < 10um | D23: 0.00017919751 | E23: kilogram | F23: biosphere3 | G23: biosphere | H23: air | J23: (1,1,1,1,1)
A25: Activity | B25: [R] Fe production (Liquid)
A26: reference product | B26: Fe
A27: location | B27: CN
A28: amount | B28: 1
A29: unit | B29: kilogram
A30: comment | B30: n/a
A31: Exchanges
A32: name | B32: reference product | C32: location | D32: amount | E32: unit | F32: database | G32: type | H32: categories | I32: uncertainty type | J32: pedigree | K32: loc | L32: scale | M32: minimum | N32: maximum
A33: =B25 -> [R] Fe production (Liquid) | B33: =B26 -> Fe | C33: =B27 -> CN | D33: 1 | E33: kilogram | F33: =F9 -> Iron | G33: production
A34: =A55 -> Coke production (Liquid iron) | B34: =B55 -> Coke | C34: =C55 -> CN | D34: 0.4 | E34: kilogram | F34: =F55 -> Iron | G34: technosphere | J34: (1,1,2,1,1)
A35: market for charcoal | B35: charcoal | C35: GLO | D35: 0.073419689 | E35: kilogram | F35: ecoinvent 3.10 cutoff | G35: technosphere | J35: (1,1,1,1,1)
A36: market for hard coal | B36: hard coal | C36: CN | D36: 0.06892228 | E36: kilogram | F36: ecoinvent 3.10 cutoff | G36: technosphere | J36: (1,1,1,1,1)
A37: market group for electricity, medium voltage | B37: electricity, medium voltage | C37: CN | D37: 0.023647668 | E37: kilowatt hour | F37: ecoinvent 3.10 cutoff | G37: technosphere | J37: (1,1,1,1,1)
A38: market for compressed air, 800 kPa gauge | B38: compressed air, 800 kPa gauge | C38: RoW | D38: 0.076476684 | E38: cubic meter | F38: ecoinvent 3.10 cutoff | G38: technosphere | J38: (1,1,1,1,1)
A39: market for compressed air, 800 kPa gauge | B39: compressed air, 800 kPa gauge | C39: RoW | D39: 0.055699482 | E39: cubic meter | F39: ecoinvent 3.10 cutoff | G39: technosphere | J39: (1,1,1,1,1)
A40: market for wastewater, average | B40: wastewater, average | C40: RoW | D40: -2.0725389e-07 | E40: cubic meter | F40: ecoinvent 3.10 cutoff | G40: technosphere | J40: (1,1,1,1,1)
A41: Carbon dioxide, fossil | D41: 0.8092 | E41: kilogram | F41: biosphere3 | G41: biosphere | H41: air | J41: (1,1,2,1,1)
...

Sheet PR6_Steel_IT
A1: Activity | B1: [P] Sintering (Italy)
A2: reference product | B2: Iron (Fe) sinter
A3: location | B3: IT
A4: amount | B4: 1
A5: unit | B5: kilogram
A6: comment | B6: n/a
A7: Exchanges
A8: name | B8: reference product | C8: location | D8: amount | E8: unit | F8: database | G8: type | H8: categories | I8: uncertainty type | J8: pedigree | K8: loc | L8: scale | M8: minimum | N8: maximum
A9: =B1 -> [P] Sintering (Italy) | B9: =B2 -> Iron (Fe) sinter | C9: =B3 -> IT | D9: 1 | E9: kilogram | F9: =Fe_Market_GLO!B1 -> Iron | G9: production
A10: market for limestone, crushed, washed | B10: limestone, crushed, washed | C10: RoW | D10: 0.15613369 | E10: kilogram | F10: ecoinvent 3.10 cutoff | G10: technosphere | J10: (1,1,3,1,1)
A11: market for lime, packed | B11: lime, packed | C11: Europe without Switzerland | D11: 0.042610372 | E11: kilogram | F11: ecoinvent 3.10 cutoff | G11: technosphere | J11: (1,1,3,1,1)
A12: market for lime, hydrated, packed | B12: lime, hydrated, packed | C12: RER | D12: 0.0060862132 | E12: kilogram | F12: ecoinvent 3.10 cutoff | G12: technosphere | J12: (1,1,3,1,1)
A13: market for iron scrap, sorted, pressed | B13: iron scrap, sorted, pressed | C13: RER | D13: 0.015271863 | E13: kilogram | F13: ecoinvent 3.10 cutoff | G13: technosphere | J13: (1,1,3,1,1)
A14: =A102 -> Coke production (Italy) | B14: =B102 -> Coke | C14: =C102 -> IT | D14: 0.047525267 | E14: kilogram | F14: =F102 -> Iron | G14: technosphere | J14: (1,1,3,1,1)
A15: market for steam, in chemical industry | B15: steam, in chemical industry | C15: RER | D15: 0.015657142 | E15: kilogram | F15: ecoinvent 3.10 cutoff | G15: technosphere | J15: (1,1,3,1,1)
A16: market for electricity, medium voltage | B16: electricity, medium voltage | C16: IT | D16: 0.041758113 | E16: kilowatt hour | F16: ecoinvent 3.10 cutoff | G16: technosphere | J16: (1,1,3,1,1)
A17: market for inert waste, for final disposal | B17: inert waste, for final disposal | C17: RoW | D17: -0.00011781987 | E17: kilogram | F17: ecoinvent 3.10 cutoff | G17: technosphere | J17: (2,1,3,1,2)
A18: Carbon dioxide, fossil | D18: 0.2113224 | E18: kilogram | F18: biosphere3 | G18: biosphere | H18: air | J18: (2,1,3,1,2)
A19: Carbon monoxide, fossil | D19: 0.00029583967 | E19: kilogram | F19: biosphere3 | G19: biosphere | H19: air | J19: (2,1,3,1,2)
A20: Particulate Matter, > 2.5 um and < 10um | D20: 0.00031905964 | E20: kilogram | F20: biosphere3 | G20: biosphere | H20: air | J20: (2,1,3,1,2)
A21: Nitrogen oxides | D21: 0.000894399 | E21: kilogram | F21: biosphere3 | G21: biosphere | H21: air | J21: (2,1,3,1,2)
A22: Sulfur dioxide | D22: 0.0013906184 | E22: kilogram | F22: biosphere3 | G22: biosphere | H22: air | J22: (2,1,3,1,2)
A23: Lead II | D23: 6.0199933e-06 | E23: kilogram | F23: biosphere3 | G23: biosphere | H23: air | J23: (2,1,3,1,2)
A24: VOC, volatile organic compounds | D24: 5.331994e-05 | E24: kilogram | F24: biosphere3 | G24: biosphere | H24: air | J24: (2,1,3,1,2)
A25: Zinc II | D25: 1.7199981e-06 | E25: kilogram | F25: biosphere3 | G25: biosphere | H25: air | J25: (2,1,3,1,2)
A26: Hydrochloric acid | D26: 8.5999904e-07 | E26: kilogram | F26: biosphere3 | G26: biosphere | H26: air | J26: (2,1,3,1,2)
A27: Hydrogen fluoride | D27: 4.6439948e-05 | E27: kilogram | F27: biosphere3 | G27: biosphere | H27: air | J27: (2,1,3,1,2)
A28: VOC, volatile organic compounds | D28: 8.5999904e-07 | E28: kilogram | F28: biosphere3 | G28: biosphere | H28: air | J28: (2,1,3,1,2)
A29: PAH, polycyclic aromatic hydrocarbons | D29: 8.5999904e-07 | E29: kilogram | F29: biosphere3 | G29: biosphere | H29: air | J29: (2,1,3,1,2)
... A31: Polychlorinated biphenyls | D31: 6.1059932e-09 | E31: kilogram | F31: biosphere3 | G31: biosphere | H31: air | J31: (2,1,3,1,2)
A33: Activity | B33: [R] Pig iron production - Blast Furnace
A34: reference product | B34: Pig iron
A35: location | B35: IT
A36: amount | B36: 1
A37: unit | B37: kilogram
A38: comment | B38: n/a
A39: Exchanges
A40: name | B40: reference product | C40: location | D40: amount | E40: unit | F40: database | G40: type | H40: categories | I40: uncertainty type | J40: pedigree | K40: loc | L40: scale | M40: minimum | N40: maximum
A41: =B33 -> [R] Pig iron production - Blast Furnace | B41: =B34 -> Pig iron | C41: =B35 -> IT | D41: 1 | E41: =B37 -> kilogram | F41: =F9 -> Iron | G41: production
A42: market for iron ore, crude ore, 46% Fe | B42: iron ore, crude ore, 46% Fe | C42: GLO | D42: 0.17839035 | E42: kilogram | F42: ecoinvent 3.10 cutoff | G42: technosphere | J42: (1,1,3,1,1)
...

Sheet PR7_CrudeSteel_IN
A1: Activity | B1: [R] Crude steel production (India)
A2: reference product | B2: Steel
A3: location | B3: IN
A4: amount | B4: 1
A5: unit | B5: kilogram
A6: comment | B6: n/a
A7: Exchanges
A8: name | B8: reference product | C8: location | D8: amount | E8: unit | F8: database | G8: type | H8: categories | I8: uncertainty type | J8: pedigree | K8: loc | L8: scale | M8: minimum | N8: maximum
A9: =B1 -> [R] Crude steel production (India) | B9: =B2 -> Steel | C9: =B3 -> IN | D9: 1 | E9: kilogram | F9: =Fe_Market_GLO!B1 -> Iron | G9: production
A10: market for limestone, crushed, washed | B10: limestone, crushed, washed | C10: RoW | D10: 9.47e-11 | E10: kilogram | F10: ecoinvent 3.10 cutoff | G10: technosphere | J10: (5,5,5,5,5)
A11: market group for electricity, low voltage | B11: electricity, low voltage | C11: IN | D11: 0.411 | E11: kilowatt hour | F11: ecoinvent 3.10 cutoff | G11: technosphere | J11: (5,5,5,5,5)
A12: market for anode, for metal electrolysis | B12: anode, for metal electrolysis | C12: GLO | D12: 0.00179 | E12: kilogram | F12: ecoinvent 3.10 cutoff | G12: technosphere | J12: (5,5,5,5,5)
A13: market for activated carbon, granular | B13: activated carbon, granular | C13: GLO | D13: 0.0874 | E13: kilogram | F13: ecoinvent 3.10 cutoff | G13: technosphere | J13: (5,5,5,5,5)
A14: market for compressed air, 800 kPa gauge | B14: compressed air, 800 kPa gauge | C14: RoW | D14: 0.0050947368 | E14: cubic meter | F14: ecoinvent 3.10 cutoff | G14: technosphere | J14: (5,5,5,5,5)
A15: Carbon dioxide, fossil | D15: 2 | E15: kilogram | F15: biosphere3 | G15: biosphere | H15: air | J15: (5,5,5,5,5)
A16: Hydrocarbons, unspecified | D16: 0.00726 | E16: kilogram | F16: biosphere3 | G16: biosphere | H16: air::non-urban air or from high stacks | J16: (5,5,5,5,5)
A17: Methane, fossil | D17: 0.00695 | E17: kilogram | F17: biosphere3 | G17: biosphere | H17: air | J17: (5,5,5,5,5)
A18: Chromium III | D18: 9.05e-09 | E18: kilogram | F18: biosphere3 | G18: biosphere | H18: water | J18: (5,5,5,5,5)
A19: Nitrogen | D19: 2e-07 | E19: kilogram | F19: biosphere3 | G19: biosphere | H19: air | J19: (5,5,5,5,5)
A20: COD, Chemical Oxygen Demand | D20: 3.05e-07 | E20: kilogram | F20: biosphere3 | G20: biosphere | H20: water | J20: (5,5,5,5,5)
A21: Nitrogen oxides | D21: 0.000421 | E21: kilogram | F21: biosphere3 | G21: biosphere | H21: air | J21: (5,5,5,5,5)
A22: Sulfur dioxide | D22: 0.00295 | E22: kilogram | F22: biosphere3 | G22: biosphere | H22: air | J22: (5,5,5,5,5)
A23: Nitrogen oxides | D23: 1e-05 | E23: kilogram | F23: biosphere3 | G23: biosphere | H23: air | J23: (5,5,5,5,5)
A24: Phosphoric acid | D24: 5.05e-08 | E24: kilogram | F24: biosphere3 | G24: biosphere | H24: water | J24: (5,5,5,5,5)
A26: Activity | B26: Steel production in India
A27: reference product | B27: Steel
A28: location | B28: IN
A29: amount | B29: 1
A30: unit | B30: kilogram
A31: comment | B31: n/a
A32: Exchanges
A33: name | B33: reference product | C33: location | D33: amount | E33: unit | F33: database | G33: type | H33: categories | I33: uncertainty type | J33: pedigree | K33: loc | L33: scale | M33: minimum | N33: maximum
A34: =B26 -> Steel production in India | B34: =B27 -> Steel | C34: =B28 -> IN | D34: 1 | E34: kilogram | F34: =F9 -> Iron | G34: production
A35: =A9 -> [R] Crude steel production (India) | B35: =B9 -> Steel | C35: =C9 -> IN | D35: 1 | E35: =E9 -> kilogram | F35: =F9 -> Iron | G35: technosphere
A36: market for pig iron | B36: pig iron | C36: RoW | D36: 1 | E36: kilogram | F36: ecoinvent 3.10 cutoff | G36: technosphere | J36: (5,5,5,5,5)

Sheet PR8_CrudeSteel_DE
A1: Activity | B1: [R] Crude steel production (Germany)
A2: reference product | B2: Steel
A3: location | B3: DE
A4: amount | B4: 1
A5: unit | B5: kilogram
A6: comment | B6: n/a
A7: Exchanges
A8: name | B8: reference product | C8: location | D8: amount | E8: unit | F8: database | G8: type | H8: categories | I8: uncertainty type | J8: pedigree | K8: loc | L8: scale | M8: minimum | N8: maximum
A9: =B1 -> [R] Crude steel production (Germany) | B9: =B2 -> Steel | C9: =B3 -> DE | D9: 1 | E9: kilogram | F9: =Fe_Market_GLO!B1 -> Iron | G9: production
A10: market for natural gas, high pressure | B10: natural gas, high pressure | C10: DE | D10: 0.00011133005 | E10: cubic meter | F10: ecoinvent 3.10 cutoff | G10: technosphere | J10: (1,3,4,3,3)
A11: market for electricity, low voltage | B11: electricity, low voltage | C11: DE | D11: 0.429 | E11: kilowatt hour | F11: ecoinvent 3.10 cutoff | G11: technosphere | J11: (1,3,4,3,3)
A12: market for anode, for metal electrolysis | B12: anode, for metal electrolysis | C12: GLO | D12: 0.00221 | E12: kilogram | F12: ecoinvent 3.10 cutoff | G12: technosphere | J12: (1,3,4,3,3)
A13: market for cast iron | B13: cast iron | C13: GLO | D13: 0.00224 | E13: kilogram | F13: ecoinvent 3.10 cutoff | G13: technosphere | J13: (1,3,4,3,3)
A14: market for quicklime, milled, packed | B14: quicklime, milled, packed | C14: RER | D14: 0.0452 | E14: kilogram | F14: ecoinvent 3.10 cutoff | G14: technosphere | J14: (1,3,4,3,3)
A15: market for refractory, basic, packed | B15: refractory, basic, packed | C15: GLO | D15: 0.0595 | E15: kilogram | F15: ecoinvent 3.10 cutoff | G15: technosphere | J15: (1,3,4,3,3)
A16: market for basic oxygen furnace slag | B16: basic oxygen furnace slag | C16: RER | D16: -0.00738 | E16: kilogram | F16: ecoinvent 3.10 cutoff | G16: technosphere | J16: (1,3,4,3,3)
A17: market for basic oxygen furnace slag | B17: basic oxygen furnace slag | C17: RER | D17: -0.193 | E17: kilogram | F17: ecoinvent 3.10 cutoff | G17: technosphere | J17: (1,3,4,3,3)
A18: market for refinery sludge | B18: refinery sludge | C18: Europe without Switzerland | D18: -0.00881 | E18: kilogram | F18: ecoinvent 3.10 cutoff | G18: technosphere | J18: (1,3,4,3,3)
A19: market for iron scrap, sorted, pressed | B19: iron scrap, sorted, pressed | C19: RER | D19: -0.0081 | E19: kilogram | F19: ecoinvent 3.10 cutoff | G19: technosphere | J19: (1,3,4,3,3)
A20: market for wastewater, average | B20: wastewater, average | C20: Europe without Switzerland | D20: -0.000548 | E20: cubic meter | F20: ecoinvent 3.10 cutoff | G20: technosphere | J20: (1,3,4,3,3)
A21: Carbon dioxide, fossil | D21: 0.262 | E21: kilogram | F21: biosphere3 | G21: biosphere | H21: air | J21: (1,3,4,3,3)
A22: Carbon monoxide, fossil | D22: 0.00262 | E22: kilogram | F22: biosphere3 | G22: biosphere | H22: air | J22: (1,3,4,3,3)
A23: Lead II | D23: 5.24e-07 | E23: kilogram | F23: biosphere3 | G23: biosphere | H23: air | J23: (1,3,4,3,3)
A24: Chromium III | D24: 9.05e-08 | E24: kilogram | F24: biosphere3 | G24: biosphere | H24: water | J24: (1,3,4,3,3)
A25: Particulate Matter, > 2.5 um and < 10um | D25: 6.67e-05 | E25: kilogram | F25: biosphere3 | G25: biosphere | H25: air | J25: (1,3,4,3,3)
A26: Nickel II | D26: 4.05e-08 | E26: kilogram | F26: biosphere3 | G26: biosphere | H26: water | J26: (1,3,4,3,3)
A27: Zinc II | D27: 1.1e-05 | E27: kilogram | F27: biosphere3 | G27: biosphere | H27: air | J27: (1,3,4,3,3)
A28: Nitrogen oxides | D28: 1e-06 | E28: kilogram | F28: biosphere3 | G28: biosphere | H28: air | J28: (1,3,4,3,3)
A29: Sulfur dioxide | D29: 4.05e-06 | E29: kilogram | F29: biosphere3 | G29: biosphere | H29: air | J29: (1,3,4,3,3)
A30: Cadmium II | D30: 9.05e-08 | E30: kilogram | F30: biosphere3 | G30: biosphere | H30: air | J30: (1,3,4,3,3)
A31: Copper ion | D31: 1.31e-07 | E31: kilogram | F31: biosphere3 | G31: biosphere | H31: air | J31: (1,3,4,3,3)
A33: Activity | B33: Steel production in Germany
A34: reference product | B34: Steel
A35: location | B35: DE
A36: amount | B36: 1
A37: unit | B37: kilogram
A38: comment | B38: n/a
A39: Exchanges
A40: name | B40: reference product | C40: location | D40: amount | E40: unit | F40: database | G40: type | H40: categories | I40: uncertainty type | J40: pedigree | K40: loc | L40: scale | M40: minimum | N40: maximum
A41: =B33 -> Steel production in Germany | B41: =B34 -> Steel | C41: =B35 -> DE | D41: 1 | E41: kilogram | F41: =F9 -> Iron | G41: production
...

Sheet PR9_CrudeSteel_KR
A1: Activity | B1: [P+R] Crude steel production (South Korea)
A2: reference product | B2: Steel
A3: location | B3: KR
A4: amount | B4: 1
A5: unit | B5: kilogram
A6: comment | B6: n/a
A7: Exchanges
A8: name | B8: reference product | C8: location | D8: amount | E8: unit | F8: database | G8: type | H8: categories | I8: uncertainty type | J8: pedigree | K8: loc | L8: scale | M8: minimum | N8: maximum
A9: =B1 -> [P+R] Crude steel production (South Korea) | B9: =B2 -> Steel | C9: =B3 -> KR | D9: 1 | E9: kilogram | F9: =Fe_Market_GLO!B1 -> Iron | G9: production
A10: market for electricity, low voltage | B10: electricity, low voltage | C10: KR | D10: 0.493 | E10: kilowatt hour | F10: ecoinvent 3.10 cutoff | G10: technosphere | J10: (nan,nan,nan,nan,nan)
A11: market for compressed air, 800 kPa gauge | B11: compressed air, 800 kPa gauge | C11: RoW | D11: 0.045789474 | E11: cubic meter | F11: ecoinvent 3.10 cutoff | G11: technosphere | J11: (nan,nan,nan,nan,nan)
A12: market for basic oxygen furnace slag | B12: basic oxygen furnace slag | C12: RoW | D12: -0.261 | E12: kilogram | F12: ecoinvent 3.10 cutoff | G12: technosphere | J12: (nan,nan,nan,nan,nan)
A13: market for refinery sludge | B13: refinery sludge | C13: RoW | D13: 0.0304 | E13: kilogram | F13: ecoinvent 3.10 cutoff | G13: technosphere | J13: (nan,nan,nan,nan,nan)
A14: Particulate Matter, > 2.5 um and < 10um | D14: 0.0377 | E14: kilogram | F14: biosphere3 | G14: biosphere | H14: air | J14: (nan,nan,nan,nan,nan)
A15: Particulate Matter, > 2.5 um and < 10um | D15: 0.00119 | E15: kilogram | F15: biosphere3 | G15: biosphere | H15: air | J15: (nan,nan,nan,nan,nan)
A16: Nitrogen oxides | D16: 4.93e-07 | E16: kilogram | F16: biosphere3 | G16: biosphere | H16: air | J16: (nan,nan,nan,nan,nan)
A17: Sulfur dioxide | D17: 0.0696 | E17: kilogram | F17: biosphere3 | G17: biosphere | H17: air | J17: (nan,nan,nan,nan,nan)
A19: Activity | B19: Steel production in Korea
A20: reference product | B20: Steel
A21: location | B21: KR
A22: amount | B22: 1
A23: unit | B23: kilogram
A24: comment | B24: n/a
A25: Exchanges
A26: name | B26: reference product | C26: location | D26: amount | E26: unit | F26: database | G26: type | H26: categories | I26: uncertainty type | J26: pedigree | K26: loc | L26: scale | M26: minimum | N26: maximum
A27: =B19 -> Steel production in Korea | B27: =B20 -> Steel | C27: =B21 -> KR | D27: 1 | E27: kilogram | F27: =F9 -> Iron | G27: production
A28: =A9 -> [P+R] Crude steel production (South Korea) | B28: =B9 -> Steel | C28: =C9 -> KR | D28: 1 | E28: =E9 -> kilogram | F28: =F9 -> Iron | G28: technosphere
A29: =FeMine_Market_GLO!A82 -> Iron ore mining and concentration - Global market | B29: =FeMine_Market_GLO!B82 -> Fe concentrate | C29: =FeMine_Market_GLO!C82 -> GLO | D29: 1 | E29: =FeMine_Market_GLO!E82 -> kilogram | F29: =FeMine_Market_GLO!F82 -> Iron | G29: technosphere

Sheet PR10_CrudeSteel_RU
A1: Activity | B1: [P+R] Crude steel production (Russia)
A2: reference product | B2: Steel
A3: location | B3: RU
A4: amount | B4: 1
A5: unit | B5: kilogram
A6: comment | B6: n/a
A7: Exchanges
A8: name | B8: reference product | C8: location | D8: amount | E8: unit | F8: database | G8: type | H8: categories | I8: uncertainty type | J8: pedigree | K8: loc | L8: scale | M8: minimum | N8: maximum
A9: =B1 -> [P+R] Crude steel production (Russia) | B9: =B2 -> Steel | C9: =B3 -> RU | D9: 1 | E9: kilogram | F9: =Fe_Market_GLO!B1 -> Iron | G9: production
A10: market for hard coal | B10: hard coal | C10: RU | D10: 0.586 | E10: kilogram | F10: ecoinvent 3.10 cutoff | G10: technosphere | J10: (1,1,5,2,3)
A11: market for electricity, high voltage | B11: electricity, high voltage | C11: RU | D11: 0.24611111 | E11: kilowatt hour | F11: ecoinvent 3.10 cutoff | G11: technosphere | J11: (1,1,5,2,3)
A12: market for iron pellet | B12: iron pellet | C12: GLO | D12: 0.14 | E12: kilogram | F12: ecoinvent 3.10 cutoff | G12: technosphere | J12: (1,1,5,2,3)
A13: market for iron scrap, sorted, pressed | B13: iron scrap, sorted, pressed | C13: RER | D13: 0.127 | E13: kilogram | F13: ecoinvent 3.10 cutoff | G13: technosphere | J13: (1,1,5,2,3)
A14: market for lime, packed | B14: lime, packed | C14: Europe without Switzerland | D14: 0.04 | E14: kilogram | F14: ecoinvent 3.10 cutoff | G14: technosphere | J14: (1,1,5,2,3)
A15: market for basic oxygen furnace slag | B15: basic oxygen furnace slag | C15: RER | D15: -0.414 | E15: kilogram | F15: ecoinvent 3.10 cutoff | G15: technosphere | J15: (1,1,5,2,3)
A16: market for ammonium sulfate | B16: ammonium sulfate | C16: RER | D16: -0.004 | E16: kilogram | F16: ecoinvent 3.10 cutoff | G16: technosphere | J16: (1,1,5,2,3)
A17: market for coal tar | B17: coal tar | C17: GLO | D17: -0.01 | E17: kilogram | F17: ecoinvent 3.10 cutoff | G17: technosphere | J17: (1,1,5,2,3)
A18: Carbon dioxide, fossil | D18: 1.57 | E18: kilogram | F18: biosphere3 | G18: biosphere | H18: air | J18: (1,1,5,2,3)
A19: Particulate Matter, > 2.5 um and < 10um | D19: 0.001 | E19: kilogram | F19: biosphere3 | G19: biosphere | H19: air | J19: (1,1,5,2,3)
A21: Activity | B21: Steel production in Russia
A22: reference product | B22: Steel
A23: location | B23: RU
A24: amount | B24: 1
A25: unit | B25: kilogram
A26: comment | B26: n/a
A27: Exchanges
A28: name | B28: reference product | C28: location | D28: amount | E28: unit | F28: database | G28: type | H28: categories | I28: uncertainty type | J28: pedigree | K28: loc | L28: scale | M28: minimum | N28: maximum
A29: =B21 -> Steel production in Russia | B29: =B22 -> Steel | C29: =B23 -> RU | D29: 1 | E29: kilogram | F29: =F9 -> Iron | G29: production
A30: =A9 -> [P+R] Crude steel production (Russia) | B30: =B9 -> Steel | C30: =C9 -> RU | D30: 1 | E30: =E9 -> kilogram | F30: =F9 -> Iron | G30: technosphere
A31: =FeMine_Market_GLO!A82 -> Iron ore mining and concentration - Global market | B31: =FeMine_Market_GLO!B82 -> Fe concentrate | C31: =FeMine_Market_GLO!C82 -> GLO | D31: 13.3 | E31: =FeMine_Market_GLO!E82 -> kilogram | F31: =FeMine_Market_GLO!F82 -> Iron | G31: technosphere

Sheet PR11_CrudeSteel_TR
A1: Activity | B1: [R] Crude steel production (Turkey)
A2: reference product | B2: Steel
A3: location | B3: TR
A4: amount | B4: 1
A5: unit | B5: kilogram
A6: comment | B6: n/a
A7: Exchanges
A8: name | B8: reference product | C8: location | D8: amount | E8: unit | F8: database | G8: type | H8: categories | I8: uncertainty type | J8: pedigree | K8: loc | L8: scale | M8: minimum | N8: maximum
A9: =B1 -> [R] Crude steel production (Turkey) | B9: =B2 -> Steel | C9: =B3 -> TR | D9: 1 | E9: kilogram | F9: =Fe_Market_GLO!B1 -> Iron | G9: production
A10: market for limestone, crushed, washed | B10: limestone, crushed, washed | C10: RoW | D10: 0.02 | E10: kilogram | F10: ecoinvent 3.10 cutoff | G10: technosphere | J10: (1,1,3,1,3)
A11: market for natural gas, high pressure | B11: natural gas, high pressure | C11: TR | D11: 3.6453202e-05 | E11: cubic meter | F11: ecoinvent 3.10 cutoff | G11: technosphere | J11: (1,1,3,1,3)
A12: market for electricity, low voltage | B12: electricity, low voltage | C12: TR | D12: 0.818 | E12: kilowatt hour | F12: ecoinvent 3.10 cutoff | G12: technosphere | J12: (1,1,3,1,3)
A13: market for anode, for metal electrolysis | B13: anode, for metal electrolysis | C13: GLO | D13: 3e-05 | E13: kilogram | F13: ecoinvent 3.10 cutoff | G13: technosphere | J13: (1,1,3,1,3)
A14: market for refractory, basic, packed | B14: refractory, basic, packed | C14: GLO | D14: 0.0139 | E14: kilogram | F14: ecoinvent 3.10 cutoff | G14: technosphere | J14: (1,1,3,1,3)
A15: market for activated carbon, granular | B15: activated carbon, granular | C15: GLO | D15: 0.0013 | E15: kilogram | F15: ecoinvent 3.10 cutoff | G15: technosphere | J15: (1,1,3,1,3)
A16: market for compressed air, 800 kPa gauge | B16: compressed air, 800 kPa gauge | C16: RER | D16: 0.00030631579 | E16: cubic meter | F16: ecoinvent 3.10 cutoff | G16: technosphere | J16: (1,1,3,1,3)
A17: market for graphite | B17: graphite | C17: GLO | D17: 0.000818 | E17: kilogram | F17: ecoinvent 3.10 cutoff | G17: technosphere | J17: (1,1,3,1,3)
A18: market for ferromanganese, high-coal, 74.5% Mn | B18: ferromanganese, high-coal, 74.5% Mn | C18: GLO | D18: 0.00818 | E18: kilogram | F18: ecoinvent 3.10 cutoff | G18: technosphere | J18: (1,1,3,1,3)
A19: market for ferrosilicon | B19: ferrosilicon | C19: GLO | D19: 0.003 | E19: kilogram | F19: ecoinvent 3.10 cutoff | G19: technosphere | J19: (1,1,3,1,3)
A20: market for fluorspar, 97% purity | B20: fluorspar, 97% purity | C20: GLO | D20: 0.000515 | E20: kilogram | F20: ecoinvent 3.10 cutoff | G20: technosphere | J20: (1,1,3,1,3)
A21: market for transport, freight, lorry, unspecified | B21: transport, freight, lorry, unspecified | C21: RER | D21: 0.279 | E21: ton kilometer | F21: ecoinvent 3.10 cutoff | G21: technosphere | J21: (1,1,3,1,3)
A22: Water, unspecified natural origin | D22: 1.39e-07 | E22: cubic meter | F22: biosphere3 | G22: biosphere | H22: natural resource::in ground | J22: (1,1,3,1,3)
A23: Carbon dioxide, fossil | D23: 5.45e-06 | E23: kilogram | F23: biosphere3 | G23: biosphere | H23: air | J23: (1,1,3,1,3)
A24: Carbon monoxide, fossil | D24: 0.000515 | E24: kilogram | F24: biosphere3 | G24: biosphere | H24: air | J24: (1,1,3,1,3)
A25: Lead II | D25: 8.48e-07 | E25: kilogram | F25: biosphere3 | G25: biosphere | H25: air | J25: (1,1,3,1,3)
A26: Chromium III | D26: 3e-08 | E26: kilogram | F26: biosphere3 | G26: biosphere | H26: water | J26: (1,1,3,1,3)
A27: Particulate Matter, > 2.5 um and < 10um | D27: 4.55e-05 | E27: kilogram | F27: biosphere3 | G27: biosphere | H27: air | J27: (1,1,3,1,3)
A28: Nickel II | D28: 1e-08 | E28: kilogram | F28: biosphere3 | G28: biosphere | H28: water | J28: (1,1,3,1,3)
A29: VOC, volatile organic compounds | D29: 1.39e-05 | E29: kilogram | F29: biosphere3 | G29: biosphere | H29: air | J29: (1,1,3,1,3)
A30: Zinc II | D30: 6.67e-06 | E30: kilogram | F30: biosphere3 | G30: biosphere | H30: air | J30: (1,1,3,1,3)
A31: Hydrochloric acid | D31: 8.79e-07 | E31: kilogram | F31: biosphere3 | G31: biosphere | H31: air | J31: (1,1,3,1,3)
A32: Nitrogen oxides | D32: 0.000188 | E32: kilogram | F32: biosphere3 | G32: biosphere | H32: air | J32: (1,1,3,1,3)
A33: Cadmium II | D33: 3e-08 | E33: kilogram | F33: biosphere3 | G33: biosphere | H33: air | J33: (1,1,3,1,3)
... A38: Polychlorinated biphenyls | D38: 1.64e-14 | E38: kilogram | F38: biosphere3 | G38: biosphere | H38: air | J38: (1,1,3,1,3)
A40: Activity | B40: Steel production in Turkey
A41: reference product | B41: Steel
A42: location | B42: TR
A43: amount | B43: 1
A44: unit | B44: kilogram
