Workbook

Sheet Note
A1: skip
B2: Life cycle inventories of global metal and mineral supply chains: a comprehensive data review, analysis and processing Frédéric Laia*, Stéphanie Mullera, Audrey Philippea, Robert Istrateb, Brenda Miranda Xicotencatlb, Afsoon Mansouri Askic, Aina Mas Fonsd,a, Juliana Segura-Salazare, Jair Santillán Saldivara, Alexander Cimprichf, Stephen Northeyg, Lígia da Silva Limah, Lieselot Booneh, Ryosuke Yokoii, Kamrul Islami, Ioanna Paschalidouj, Felipe Cerdask,l, Victor Balboa-Espinozae, Anish Koyamparambathd, Diae Henniouia, Victoire Collignona, Aurélien Reysa, Gyslain Ngadi Sakatadim, Jo Dewulfh, Bernhard Steubingb, Christoph Helbigc, Gaétan Lefebvrea, Gian Andrea Blenginin,m, Valeria Supertio, Masaharu Motoshitai, Guido Sonnemannd, Kwame Awuah-Offeij, Steven B. Youngf, Shinsuke Murakamip, Antoine Beylota aBRGM, F-45060 Orléans, France bInstitute of Environmental Sciences (CML), Leiden University, Einsteinweg 2, 2333 CC Leiden, NL cEcological Resource Technology, University of Bayreuth, Universitätstr. 30, 95447 Bayreuth, Germany dUniv. Bordeaux, CNRS, Bordeaux INP, ISM, UMR 5255, F-33400 Talence, France eSustainable Minerals Institute, The University of Queensland, QLD, 4072, Australia fSchool of Environment, Enterprise and Development, University of Waterloo, 200 University Avenue West, Waterloo, Ontario N2L 3G1, Canada gUniversity of Technology Sydney, Institute for Sustainable Futures, Australia hSustainable Systems Engineering (STEN), Department of Green Chemistry and Technology, Faculty of Bioscience Engineering, Ghent University, Coupure Links 653, 9000 Ghent, Belgium iAIST, 305-8569 Tsukuba, Japan jMining & Explosives Engineering, Missouri University of Science & Technology, Rolla, MO, USA 65409 kInstitute for Sustainable Energy Systems (INSYS), Technical University of Applied Sciences Würzburg-Schweinfurt (THWS), Ignaz-Schön-Straße 11, Schweinfurt, Germany lFraunhofer Institute for Surface Engineering and Thin Films IST, Riedenkamp 2, Braunschweig 38108, Germany mDepartment of Environment, Land and Infrastructure Engineering, Politecnico di Torino, Corso Duca degli Abruzzi, 24, 10129 Torino, Italy nUniversity of Turin, Earth Sciences Department (DST), Via Valperga Caluso, 35 – 10125 Torino, Italy oecoinvent association, Technopark, Technoparkstrasse 1, 8005 Zürich, Switzerland pGraduate School of Engineering, The University of Tokyo, Tokyo 113-8656, Japan *Corresponding author: f.lai@brgm.fr This file provides all LCI datasets developed for Germanium (Ge), with distinguishing its global market and each individual production route.
B33: Sheet | C33: Corresponding route
B34: Ge_Market_GLO | C34: Ge global market
B35: PR1_Ge_RoW | C35: Ge recovery along with Pb/Zn production in Canada/Peru/Chile/the US

Sheet Ge_Market_GLO
A1: database | B1: Germanium
A3: Activity | B3: Germanium (Ge) global market
A4: reference product | B4: Refined Ge
A5: location | B5: GLO
A6: amount | B6: 1
A7: unit | B7: kilogram
A8: comment | B8: n/a
A9: Exchanges
A10: name | B10: reference product | C10: location | D10: amount | E10: unit | F10: database | G10: type | H10: categories | I10: uncertainty type | J10: pedigree | K10: loc | L10: scale | M10: minimum | N10: maximum
A11: =B3 -> Germanium (Ge) global market | B11: =B4 -> Refined Ge | C11: =B5 -> GLO | D11: =B6 -> 1 | E11: =B7 -> kilogram | F11: =B1 -> Germanium | G11: production
A12: =PR1_Ge_RoW!A55 -> Ge recovery along with Pb/Zn production in Canada/Peru/Chile/the US | B12: =PR1_Ge_RoW!B55 -> Refined Ge | C12: =PR1_Ge_RoW!C55 -> RoW | D12: =PR1_Ge_RoW!D55 -> 1 | E12: =PR1_Ge_RoW!E55 -> kilogram | F12: =PR1_Ge_RoW!F55 -> Germanium | G12: technosphere

Sheet PR1_Ge_RoW
A1: Activity | B1: [M+C] Zinc (Zn) ore mining and concentration
A2: reference product | B2: Zn concentrate
A3: location | B3: RoW
A4: amount | B4: 1
A5: unit | B5: kilogram
A6: comment | B6: n/a
A7: Exchanges
A8: name | B8: reference product | C8: location | D8: amount | E8: unit | F8: database | G8: type | H8: categories | I8: uncertainty type | J8: pedigree | K8: loc | L8: scale | M8: minimum | N8: maximum
A9: [M+C] Zinc (Zn) ore mining and concentration | B9: Zn concentrate | C9: RoW | D9: 1 | E9: kilogram | F9: =Ge_Market_GLO!B1 -> Germanium | G9: production
A10: heat production, heavy fuel oil, at industrial furnace 1MW | B10: heat, district or industrial, other than natural gas | C10: RoW | D10: 4.0502431 | E10: megajoule | F10: ecoinvent 3.10 cutoff | G10: technosphere | J10: (1,1,5,1,1)
A11: market for sulfidic tailings, from zinc-lead mine operation | B11: sulfidic tailings, from zinc-lead mine operation | C11: RoW | D11: -170.07293 | E11: kilogram | F11: ecoinvent 3.10 cutoff | G11: technosphere | J11: (1,1,5,1,1)
A12: Zinc II | D12: 1.7828201e-05 | E12: kilogram | F12: biosphere3 | G12: biosphere | H12: air | J12: (1,1,5,1,1)
A13: Lead II | D13: 1.0048622e-06 | E13: kilogram | F13: biosphere3 | G13: biosphere | H13: air | J13: (1,1,5,1,1)
A14: Cadmium II | D14: 1.9448947e-07 | E14: kilogram | F14: biosphere3 | G14: biosphere | H14: air | J14: (1,1,5,1,1)
A15: Carbon dioxide, fossil | D15: 0.29011345 | E15: kilogram | F15: biosphere3 | G15: biosphere | H15: air | J15: (1,1,5,1,1)
A16: Particulate Matter, > 10 um | D16: 0.00037212318 | E16: kilogram | F16: biosphere3 | G16: biosphere | H16: air | J16: (1,1,5,1,1)
A17: Sulfur oxides | D17: 0.00023387358 | E17: kilogram | F17: biosphere3 | G17: biosphere | H17: air | J17: (1,1,5,1,1)
A18: Nitrogen oxides | D18: 0.0046139384 | E18: kilogram | F18: biosphere3 | G18: biosphere | H18: air | J18: (1,1,5,1,1)
A19: Lead II | D19: 4.8622366e-09 | E19: kilogram | F19: biosphere3 | G19: biosphere | H19: water | J19: (1,1,5,1,1)
A20: Zinc II | D20: 3.6466775e-07 | E20: kilogram | F20: biosphere3 | G20: biosphere | H20: water | J20: (1,1,5,1,1)
A21: Cadmium II | D21: 3.2414911e-09 | E21: kilogram | F21: biosphere3 | G21: biosphere | H21: water | J21: (1,1,5,1,1)
A23: Activity | B23: [P+R] Refined Germanium (Ge) production
A24: reference product | B24: Refined Ge
A25: location | B25: RoW
A26: amount | B26: 1
A27: unit | B27: kilogram
A28: comment | B28: Allocated unit process, considering as allocation factors (AF): 55.37% for Zn (1 kg refined), 12.61% for Pb (0.28 kg refined), 28.81% for Ag (0.002 kg refined), 0.01% for Bi (0.00006 kg refined), 0.62% for In (0.0001 kg refined) and 2.57% for Ge (0.00009 kg refined).
A29: Exchanges
A30: name | B30: reference product | C30: location | D30: amount | E30: unit | F30: database | G30: type | H30: categories | I30: uncertainty type | J30: pedigree | K30: loc | L30: scale | M30: minimum | N30: maximum
A31: =B23 -> [P+R] Refined Germanium (Ge) production | B31: =B24 -> Refined Ge | C31: RoW | D31: 1 | E31: kilogram | F31: =F9 -> Germanium | G31: production
A32: market group for electricity, medium voltage | B32: electricity, medium voltage | C32: GLO | D32: 2877.8632 | E32: kilowatt hour | F32: ecoinvent 3.10 cutoff | G32: technosphere | J32: (1,1,5,1,1)
A33: heat production, heavy fuel oil, at industrial furnace 1MW | B33: heat, district or industrial, other than natural gas | C33: RoW | D33: 4515.3378 | E33: megajoule | F33: ecoinvent 3.10 cutoff | G33: technosphere | J33: (1,1,5,1,1)
A34: Zinc II | D34: 0.0045370367 | E34: kilogram | F34: biosphere3 | G34: biosphere | H34: air | J34: (1,1,5,1,1)
A35: Lead II | D35: 0.0037479868 | E35: kilogram | F35: biosphere3 | G35: biosphere | H35: air | J35: (1,1,5,1,1)
A36: Cadmium II | D36: 8.8768109e-05 | E36: kilogram | F36: biosphere3 | G36: biosphere | H36: air | J36: (1,1,5,1,1)
A37: Mercury II | D37: 9.1727046e-05 | E37: kilogram | F37: biosphere3 | G37: biosphere | H37: air | J37: (1,1,5,1,1)
A38: Sulfur dioxide | D38: 3.4866141 | E38: kilogram | F38: biosphere3 | G38: biosphere | H38: air | J38: (1,1,5,1,1)
A39: Carbon dioxide, fossil | D39: 349.15456 | E39: kilogram | F39: biosphere3 | G39: biosphere | H39: air | J39: (1,1,5,1,1)
A40: Particulate Matter, > 10 um | D40: 0.11342592 | E40: kilogram | F40: biosphere3 | G40: biosphere | H40: air | J40: (1,1,5,1,1)
A41: Particulate Matter, < 2.5 um | D41: 0.0720008 | E41: kilogram | F41: biosphere3 | G41: biosphere | H41: air | J41: (1,1,5,1,1)
...
