Workbook

Sheet Note
A1: skip
B2: Life cycle inventories of global metal and mineral supply chains: a comprehensive data review, analysis and processing Frédéric Laia*, Stéphanie Mullera, Audrey Philippea, Robert Istrateb, Brenda Miranda Xicotencatlb, Afsoon Mansouri Askic, Aina Mas Fonsd,a, Juliana Segura-Salazare, Jair Santillán Saldivara, Alexander Cimprichf, Stephen Northeyg, Lígia da Silva Limah, Lieselot Booneh, Ryosuke Yokoii, Kamrul Islami, Ioanna Paschalidouj, Felipe Cerdask,l, Victor Balboa-Espinozae, Anish Koyamparambathd, Diae Henniouia, Victoire Collignona, Aurélien Reysa, Gyslain Ngadi Sakatadim, Jo Dewulfh, Bernhard Steubingb, Christoph Helbigc, Gaétan Lefebvrea, Gian Andrea Blenginin,m, Valeria Supertio, Masaharu Motoshitai, Guido Sonnemannd, Kwame Awuah-Offeij, Steven B. Youngf, Shinsuke Murakamip, Antoine Beylota aBRGM, F-45060 Orléans, France bInstitute of Environmental Sciences (CML), Leiden University, Einsteinweg 2, 2333 CC Leiden, NL cEcological Resource Technology, University of Bayreuth, Universitätstr. 30, 95447 Bayreuth, Germany dUniv. Bordeaux, CNRS, Bordeaux INP, ISM, UMR 5255, F-33400 Talence, France eSustainable Minerals Institute, The University of Queensland, QLD, 4072, Australia fSchool of Environment, Enterprise and Development, University of Waterloo, 200 University Avenue West, Waterloo, Ontario N2L 3G1, Canada gUniversity of Technology Sydney, Institute for Sustainable Futures, Australia hSustainable Systems Engineering (STEN), Department of Green Chemistry and Technology, Faculty of Bioscience Engineering, Ghent University, Coupure Links 653, 9000 Ghent, Belgium iAIST, 305-8569 Tsukuba, Japan jMining & Explosives Engineering, Missouri University of Science & Technology, Rolla, MO, USA 65409 kInstitute for Sustainable Energy Systems (INSYS), Technical University of Applied Sciences Würzburg-Schweinfurt (THWS), Ignaz-Schön-Straße 11, Schweinfurt, Germany lFraunhofer Institute for Surface Engineering and Thin Films IST, Riedenkamp 2, Braunschweig 38108, Germany mDepartment of Environment, Land and Infrastructure Engineering, Politecnico di Torino, Corso Duca degli Abruzzi, 24, 10129 Torino, Italy nUniversity of Turin, Earth Sciences Department (DST), Via Valperga Caluso, 35 – 10125 Torino, Italy oecoinvent association, Technopark, Technoparkstrasse 1, 8005 Zürich, Switzerland pGraduate School of Engineering, The University of Tokyo, Tokyo 113-8656, Japan *Corresponding author: f.lai@brgm.fr This file provides all LCI datasets developed for Lithium (Li), with distinguishing its global market and each individual production route.
B33: Sheet | C33: Corresponding route
B34: Li_Market_GLO | C34: Li global market
B35: PR1_Li2CO3_AR_Cauchari_Brines | C35: Li2CO3 production in Argentina/Salar de Cauchari
B36: PR2_Li2CO3_CL_Atacama_Brines | C36: Li2CO3 production in Chile/Salar de Atacama
B37: PR3_LiOH_CL_Atacama_Brines | C37: LiOH.H2O production in Chile/Salar de Atacama
B38: PR4_Li2CO3_AU_CN_She_Spodumene | C38: Spodumene ore mining in Australia/Greenbushes and Li2CO3 production in China/Shehong
B39: PR5_LiOH_AU_CN_She_Spodumene | C39: Spodumene ore mining in Australia/Greenbushes and LiOH.H2O production in China/Shehong
B40: PR6_Li2CO3_CN_Zha | C40: Li2CO3 production in China/Zhangjiagang
B41: PR7_Li2CO3_AR_Olaroz_Brines | C41: Li2CO3 production in Argentina/Salar de Olaroz
B42: PR8_Li2CO3_CN_Chaerhan_Brines | C42: Li2CO3 production in China/Chaerhan Salt Lake
B43: PR9_Li2CO3_AR_HombreM_Brines | C43: Li2CO3 production in Argentina/Salar del Hombre Muerto

Sheet Li_Market_GLO
A1: database | B1: Lithium
A3: Activity | B3: Lithium (Li) global market
A4: reference product | B4: Li commodities
A5: location | B5: GLO
A6: amount | B6: 1
A7: unit | B7: kilogram
A8: comment | B8: n/a
A9: Exchanges
A10: name | B10: reference product | C10: location | D10: amount | E10: unit | F10: database | G10: type | H10: categories | I10: uncertainty type | J10: pedigree | K10: loc | L10: scale | M10: minimum | N10: maximum
A11: =B3 -> Lithium (Li) global market | B11: =B4 -> Li commodities | C11: =B5 -> GLO | D11: 1 | E11: =B7 -> kilogram | F11: =B1 -> Lithium | G11: production
A12: =PR1_Li2CO3_AR_Cauchari_Brines!A48 -> Li2CO3 production in Argentina/Salar de Cauchari | B12: =PR1_Li2CO3_AR_Cauchari_Brines!B48 -> Battery-grade Li2CO3 | C12: =PR1_Li2CO3_AR_Cauchari_Brines!C48 -> AR | D12: 0.014624099 | E12: =PR1_Li2CO3_AR_Cauchari_Brines!E48 -> kilogram | F12: =PR1_Li2CO3_AR_Cauchari_Brines!F48 -> Lithium | G12: technosphere
A13: =PR2_Li2CO3_CL_Atacama_Brines!A47 -> Li2CO3 production in Chile/Salar de Atacama | B13: =PR2_Li2CO3_CL_Atacama_Brines!B47 -> Battery-grade Li2CO3 | C13: =PR2_Li2CO3_CL_Atacama_Brines!C47 -> CL | D13: 0.27973785 | E13: =PR2_Li2CO3_CL_Atacama_Brines!E47 -> kilogram | F13: =PR2_Li2CO3_CL_Atacama_Brines!F47 -> Lithium | G13: technosphere
A14: =PR3_LiOH_CL_Atacama_Brines!A26 -> LiOH.H2O production in Chile/Salar de Atacama | B14: =PR3_LiOH_CL_Atacama_Brines!B26 -> Battery-grade LiOH.H2O | C14: =PR3_LiOH_CL_Atacama_Brines!C26 -> CL | D14: 0.045160931 | E14: =PR3_LiOH_CL_Atacama_Brines!E26 -> kilogram | F14: =PR3_LiOH_CL_Atacama_Brines!F26 -> Lithium | G14: technosphere
A15: =PR4_Li2CO3_AU_CN_She_Spodumene!A54 -> Spodumene ore mining in Australia/Greenbushes and Li2CO3 production in China/Shehong | B15: =PR4_Li2CO3_AU_CN_She_Spodumene!B54 -> Battery-grade Li2CO3 | C15: =PR4_Li2CO3_AU_CN_She_Spodumene!C54 -> AU-CN | D15: 0.20718982 | E15: =PR4_Li2CO3_AU_CN_She_Spodumene!E54 -> kilogram | F15: =PR4_Li2CO3_AU_CN_She_Spodumene!F54 -> Lithium | G15: technosphere
A16: =PR5_LiOH_AU_CN_She_Spodumene!A28 -> Spodumene ore mining in Australia/Greenbushes and LiOH.H2O production in China/Shehong | B16: =PR5_LiOH_AU_CN_She_Spodumene!B28 -> Battery-grade LiOH.H2O | C16: =PR5_LiOH_AU_CN_She_Spodumene!C28 -> AU-CN | D16: 0.059197093 | E16: =PR5_LiOH_AU_CN_She_Spodumene!E28 -> kilogram | F16: =PR5_LiOH_AU_CN_She_Spodumene!F28 -> Lithium | G16: technosphere
A17: =PR6_Li2CO3_CN_Zha!A62 -> Li2CO3 production in China/Zhangjiagang | B17: =PR6_Li2CO3_CN_Zha!B62 -> Battery-grade Li2CO3 | C17: =PR6_Li2CO3_CN_Zha!C62 -> AU-CN | D17: 0.22015448 | E17: =PR6_Li2CO3_CN_Zha!E62 -> kilogram | F17: =PR6_Li2CO3_CN_Zha!F62 -> Lithium | G17: technosphere
A18: =PR7_Li2CO3_AR_Olaroz_Brines!A85 -> Li2CO3 production in Argentina/Salar de Olaroz | B18: =PR7_Li2CO3_AR_Olaroz_Brines!B85 -> Battery-grade Li2CO3 | C18: =PR7_Li2CO3_AR_Olaroz_Brines!C85 -> AR | D18: 0.042921344 | E18: =PR7_Li2CO3_AR_Olaroz_Brines!E85 -> kilogram | F18: =PR7_Li2CO3_AR_Olaroz_Brines!F85 -> Lithium | G18: technosphere
A19: =PR8_Li2CO3_CN_Chaerhan_Brines!A69 -> Li2CO3 production in China/Chaerhan Salt Lake | B19: =PR8_Li2CO3_CN_Chaerhan_Brines!B69 -> Battery-grade Li2CO3 | C19: =PR8_Li2CO3_CN_Chaerhan_Brines!C69 -> CN | D19: 0.082284516 | E19: =PR8_Li2CO3_CN_Chaerhan_Brines!E69 -> kilogram | F19: =PR8_Li2CO3_CN_Chaerhan_Brines!F69 -> Lithium | G19: technosphere
A20: =PR9_Li2CO3_AR_HombreM_Brines!A83 -> Li2CO3 production in Argentina/Salar del Hombre Muerto | B20: =PR9_Li2CO3_AR_HombreM_Brines!B83 -> Battery-grade Li2CO3 | C20: =PR9_Li2CO3_AR_HombreM_Brines!C83 -> AR | D20: 0.048729861 | E20: =PR9_Li2CO3_AR_HombreM_Brines!E83 -> kilogram | F20: =PR9_Li2CO3_AR_HombreM_Brines!F83 -> Lithium | G20: technosphere
A22: Activity | B22: Lithium (Li) global market (Li content)
A23: reference product | B23: Li content
A24: location | B24: GLO
A25: amount | B25: 1
A26: unit | B26: kilogram
A27: comment | B27: Activity expressed for 1 kg Li contained
A28: Exchanges
A29: name | B29: reference product | C29: location | D29: amount | E29: unit | F29: database | G29: type | H29: categories | I29: uncertainty type | J29: pedigree | K29: loc | L29: scale | M29: minimum | N29: maximum
A30: =B22 -> Lithium (Li) global market (Li content) | B30: =B23 -> Li content | C30: =B24 -> GLO | D30: 1 | E30: =B26 -> kilogram | F30: =F11 -> Lithium | G30: production
A31: =PR1_Li2CO3_AR_Cauchari_Brines!A60 -> Li2CO3 production in Argentina/Salar de Cauchari (Li content) | B31: =PR1_Li2CO3_AR_Cauchari_Brines!B60 -> Battery-grade Li2CO3 (Li content) | C31: =PR1_Li2CO3_AR_Cauchari_Brines!C60 -> AR | D31: 0.014624099 | E31: =PR1_Li2CO3_AR_Cauchari_Brines!E60 -> kilogram | F31: =PR1_Li2CO3_AR_Cauchari_Brines!F60 -> Lithium | G31: technosphere
A32: =PR2_Li2CO3_CL_Atacama_Brines!A59 -> Li2CO3 production in Chile/Salar de Atacama (Li content) | B32: =PR2_Li2CO3_CL_Atacama_Brines!B59 -> Battery-grade Li2CO3 (Li content) | C32: =PR2_Li2CO3_CL_Atacama_Brines!C59 -> CL | D32: 0.27973785 | E32: =PR2_Li2CO3_CL_Atacama_Brines!E59 -> kilogram | F32: =PR2_Li2CO3_CL_Atacama_Brines!F59 -> Lithium | G32: technosphere
A33: =+PR3_LiOH_CL_Atacama_Brines!A39 -> LiOH.H2O production in Chile/Salar de Atacama (Li content) | B33: =+PR3_LiOH_CL_Atacama_Brines!B39 -> Battery-grade LiOH.H2O (Li content) | C33: =+PR3_LiOH_CL_Atacama_Brines!C39 -> CL | D33: 0.045160931 | E33: =+PR3_LiOH_CL_Atacama_Brines!E39 -> kilogram | F33: =+PR3_LiOH_CL_Atacama_Brines!F39 -> Lithium | G33: technosphere
A34: =+PR4_Li2CO3_AU_CN_She_Spodumene!A66 -> Spodumene ore mining in Australia/Greenbushes and Li2CO3 production in China/Shehong (Li content) | B34: =+PR4_Li2CO3_AU_CN_She_Spodumene!B66 -> Battery-grade Li2CO3 (Li content) | C34: =+PR4_Li2CO3_AU_CN_She_Spodumene!C66 -> AU-CN | D34: 0.20718982 | E34: =+PR4_Li2CO3_AU_CN_She_Spodumene!E66 -> kilogram | F34: =+PR4_Li2CO3_AU_CN_She_Spodumene!F66 -> Lithium | G34: technosphere
A35: =+PR5_LiOH_AU_CN_She_Spodumene!A40 -> Spodumene ore mining in Australia/Greenbushes and LiOH.H2O production in China/Shehong (Li content) | B35: =+PR5_LiOH_AU_CN_She_Spodumene!B40 -> Battery-grade LiOH.H2O (Li content) | C35: =+PR5_LiOH_AU_CN_She_Spodumene!C40 -> AU-CN | D35: 0.059197093 | E35: =+PR5_LiOH_AU_CN_She_Spodumene!E40 -> kilogram | F35: =+PR5_LiOH_AU_CN_She_Spodumene!F40 -> Lithium | G35: technosphere
A36: =+PR6_Li2CO3_CN_Zha!A74 -> Li2CO3 production in China/Zhangjiagang (Li content) | B36: =+PR6_Li2CO3_CN_Zha!B74 -> Battery-grade Li2CO3 (Li content) | C36: =+PR6_Li2CO3_CN_Zha!C74 -> AU-CN | D36: 0.22015448 | E36: =+PR6_Li2CO3_CN_Zha!E74 -> kilogram | F36: =+PR6_Li2CO3_CN_Zha!F74 -> Lithium | G36: technosphere
A37: =PR7_Li2CO3_AR_Olaroz_Brines!A97 -> Li2CO3 production in Argentina/Salar de Olaroz (Li content) | B37: =PR7_Li2CO3_AR_Olaroz_Brines!B97 -> Battery-grade Li2CO3 (Li content) | C37: =PR7_Li2CO3_AR_Olaroz_Brines!C97 -> AR | D37: 0.042921344 | E37: =PR7_Li2CO3_AR_Olaroz_Brines!E97 -> kilogram | F37: =PR7_Li2CO3_AR_Olaroz_Brines!F97 -> Lithium | G37: technosphere
A38: =PR8_Li2CO3_CN_Chaerhan_Brines!A81 -> Li2CO3 production in China/Chaerhan Salt Lake (Li content) | B38: =PR8_Li2CO3_CN_Chaerhan_Brines!B81 -> Battery-grade Li2CO3 (Li content) | C38: =PR8_Li2CO3_CN_Chaerhan_Brines!C81 -> CN | D38: 0.082284516 | E38: =PR8_Li2CO3_CN_Chaerhan_Brines!E81 -> kilogram | F38: =PR8_Li2CO3_CN_Chaerhan_Brines!F81 -> Lithium | G38: technosphere
A39: =PR9_Li2CO3_AR_HombreM_Brines!A95 -> Li2CO3 production in Argentina/Salar del Hombre Muerto (Li content) | B39: =PR9_Li2CO3_AR_HombreM_Brines!B95 -> Battery-grade Li2CO3 (Li content) | C39: =PR9_Li2CO3_AR_HombreM_Brines!C95 -> AR | D39: 0.048729861 | E39: =PR9_Li2CO3_AR_HombreM_Brines!E95 -> kilogram | F39: =PR9_Li2CO3_AR_HombreM_Brines!F95 -> Lithium | G39: technosphere

Sheet PR1_Li2CO3_AR_Cauchari_Brines
A1: Activity | B1: [M+C] Lithium (Li) brine concentration (Salar de Cauchari)
A2: reference product | B2: Li brine
A3: location | B3: AR
A4: amount | B4: 1
A5: unit | B5: kilogram
A6: comment | B6: n/a
A7: Exchanges
A8: name | B8: reference product | C8: location | D8: amount | E8: unit | F8: database | G8: type | H8: categories | I8: uncertainty type | J8: pedigree | K8: loc | L8: scale | M8: minimum | N8: maximum
A9: =B1 -> [M+C] Lithium (Li) brine concentration (Salar de Cauchari) | B9: =B2 -> Li brine | C9: =B3 -> AR | D9: 1 | E9: kilogram | F9: =Li_Market_GLO!B1 -> Lithium | G9: production
A10: market for electricity, medium voltage | B10: electricity, medium voltage | C10: AR | D10: 0.18 | E10: kilowatt hour | F10: ecoinvent 3.10 cutoff | G10: technosphere | J10: (1,1,1,1,1)
A11: market for quicklime, milled, packed | B11: quicklime, milled, packed | C11: RoW | D11: 0.353 | E11: kilogram | F11: ecoinvent 3.10 cutoff | G11: technosphere | J11: (1,1,1,1,1)
A12: market for calcium chloride | B12: calcium chloride | C12: RoW | D12: 0.00887 | E12: kilogram | F12: ecoinvent 3.10 cutoff | G12: technosphere | J12: (1,1,1,1,1)
A13: market for wastewater, average | B13: wastewater, average | C13: RoW | D13: -0.00684 | E13: cubic meter | F13: ecoinvent 3.10 cutoff | G13: technosphere | J13: (1,1,1,1,1)
A14: market for inert waste, for final disposal | B14: inert waste, for final disposal | C14: RoW | D14: -31.7 | E14: kilogram | F14: ecoinvent 3.10 cutoff | G14: technosphere | J14: (1,1,1,1,1)
A15: Lithium | D15: 0.0659 | E15: kilogram | F15: biosphere3 | G15: biosphere | H15: natural resource::in ground | J15: (1,1,1,1,1)
A16: Water, unspecified natural origin | D16: 0.00381 | E16: cubic meter | F16: biosphere3 | G16: biosphere | H16: natural resource::in ground | J16: (1,1,1,1,1)
A17: Water | D17: 0.00558 | E17: cubic meter | F17: biosphere3 | G17: biosphere | H17: water | J17: (1,1,1,1,1)
A18: Occupation, mineral extraction site | D18: 1.0399789e-10 | E18: square meter-year | F18: biosphere3 | G18: biosphere | H18: natural resource::land | J18: (3,3,1,1,1)
A19: Transformation, from unspecified | D19: 2.5999473e-12 | E19: square meter | F19: biosphere3 | G19: biosphere | H19: natural resource::land | J19: (3,3,1,1,1)
A20: Transformation, to mineral extraction site | D20: 2.5999473e-12 | E20: square meter | F20: biosphere3 | G20: biosphere | H20: natural resource::land | J20: (3,3,1,1,1)
A22: Activity | B22: [P] Battery-grade Li carbonate (Li2CO3) production (Salar de Cauchari)
A23: reference product | B23: Battery-grade Li2CO3
A24: location | B24: AR
A25: amount | B25: 1
A26: unit | B26: kilogram
A27: comment | B27: n/a
A28: Exchanges
A29: name | B29: reference product | C29: location | D29: amount | E29: unit | F29: database | G29: type | H29: categories | I29: uncertainty type | J29: pedigree | K29: loc | L29: scale | M29: minimum | N29: maximum
A30: =B22 -> [P] Battery-grade Li carbonate (Li2CO3) production (Salar de Cauchari) | B30: =B23 -> Battery-grade Li2CO3 | C30: =B24 -> AR | D30: 1 | E30: kilogram | F30: =F9 -> Lithium | G30: production
A31: market for soda ash, dense | B31: soda ash, dense | C31: GLO | D31: 1.86 | E31: kilogram | F31: ecoinvent 3.10 cutoff | G31: technosphere | J31: (1,1,1,1,1)
A32: market for quicklime, milled, packed | B32: quicklime, milled, packed | C32: RoW | D32: 0.0071 | E32: kilogram | F32: ecoinvent 3.10 cutoff | G32: technosphere | J32: (1,1,1,1,1)
A33: market for sulfuric acid | B33: sulfuric acid | C33: RoW | D33: 0.023 | E33: kilogram | F33: ecoinvent 3.10 cutoff | G33: technosphere | J33: (1,1,1,1,1)
A34: market for hydrochloric acid, without water, in 30% solution state | B34: hydrochloric acid, without water, in 30% solution state | C34: RoW | D34: 0.045 | E34: kilogram | F34: ecoinvent 3.10 cutoff | G34: technosphere | J34: (1,1,1,1,1)
A35: market for sodium hydroxide, without water, in 50% solution state | B35: sodium hydroxide, without water, in 50% solution state | C35: RoW | D35: 0.02 | E35: kilogram | F35: ecoinvent 3.10 cutoff | G35: technosphere | J35: (1,1,1,1,1)
A36: market for kerosene | B36: kerosene | C36: RoW | D36: 0.0018 | E36: kilogram | F36: ecoinvent 3.10 cutoff | G36: technosphere | J36: (1,1,1,1,1)
A37: market for electricity, medium voltage | B37: electricity, medium voltage | C37: AR | D37: 2.59 | E37: kilowatt hour | F37: ecoinvent 3.10 cutoff | G37: technosphere | J37: (1,1,1,1,1)
A38: Water, unspecified natural origin | D38: 0.0085 | E38: cubic meter | F38: biosphere3 | G38: biosphere | H38: natural resource::in ground | J38: (1,1,1,1,1)
A40: Activity | B40: Li2CO3 production in Argentina/Salar de Cauchari
A41: reference product | B41: Battery-grade Li2CO3
A42: location | B42: AR
...

Sheet PR2_Li2CO3_CL_Atacama_Brines
A1: Activity | B1: [M+C] Lithium (Li) brine concentration (Salar de Atacama)
A2: reference product | B2: Li brine
A3: location | B3: CL
A4: amount | B4: 1
A5: unit | B5: kilogram
A6: comment | B6: The co-produced potash is dealt through substitution.
A7: Exchanges
A8: name | B8: reference product | C8: location | D8: amount | E8: unit | F8: database | G8: type | H8: categories | I8: uncertainty type | J8: pedigree | K8: loc | L8: scale | M8: minimum | N8: maximum
A9: =B1 -> [M+C] Lithium (Li) brine concentration (Salar de Atacama) | B9: =B2 -> Li brine | C9: =B3 -> CL | D9: 1 | E9: kilogram | F9: =Li_Market_GLO!B1 -> Lithium | G9: production
A10: market for electricity, medium voltage | B10: electricity, medium voltage | C10: CL | D10: 0.81184444 | E10: kilowatt hour | F10: ecoinvent 3.10 cutoff | G10: technosphere | J10: (4.0,1.0,1.0,1.0,1.0)
A11: market for diesel, burned in building machine | B11: diesel, burned in building machine | C11: GLO | D11: 2.5228 | E11: megajoule | F11: ecoinvent 3.10 cutoff | G11: technosphere | J11: (4.0,1.0,1.0,1.0,1.0)
A12: potash salt production | B12: potash salt | C12: RoW | D12: -8.52 | E12: kilogram | F12: ecoinvent 3.10 cutoff | G12: technosphere | J12: (4.0,1.0,1.0,1.0,1.0)
A13: Lithium | D13: 0.04097 | E13: kilogram | F13: biosphere3 | G13: biosphere | H13: natural resource::in ground | J13: (4.0,1.0,1.0,1.0,1.0)
A14: Water, unspecified natural origin | D14: 0.022848 | E14: cubic meter | F14: biosphere3 | G14: biosphere | H14: natural resource::in ground | J14: (4.0,1.0,1.0,1.0,1.0)
A15: Occupation, mineral extraction site | D15: 2.2033312e-10 | E15: square meter-year | F15: biosphere3 | G15: biosphere | H15: natural resource::land | J15: (2.0,2.0,1.0,1.0,1.0)
A16: Transformation, from unspecified | D16: 5.5083279e-12 | E16: square meter | F16: biosphere3 | G16: biosphere | H16: natural resource::land | J16: (2.0,2.0,1.0,1.0,1.0)
A17: Transformation, to mineral extraction site | D17: 5.5083279e-12 | E17: square meter | F17: biosphere3 | G17: biosphere | H17: natural resource::land | J17: (2.0,2.0,1.0,1.0,1.0)
A19: Activity | B19: [P] Battery-grade Li carbonate (Li2CO3) production (Salar de Atacama)
A20: reference product | B20: Battery-grade Li2CO3
A21: location | B21: CL
A22: amount | B22: 1
A23: unit | B23: kilogram
A24: comment | B24: n/a
A25: Exchanges
A26: name | B26: reference product | C26: location | D26: amount | E26: unit | F26: database | G26: type | H26: categories | I26: uncertainty type | J26: pedigree | K26: loc | L26: scale | M26: minimum | N26: maximum
A27: =B19 -> [P] Battery-grade Li carbonate (Li2CO3) production (Salar de Atacama) | B27: =B20 -> Battery-grade Li2CO3 | C27: =B21 -> CL | D27: 1 | E27: kilogram | F27: =F9 -> Lithium | G27: production
A28: market for soda ash, dense | B28: soda ash, dense | C28: GLO | D28: 2 | E28: kilogram | F28: ecoinvent 3.10 cutoff | G28: technosphere | J28: (4.0,1.0,1.0,1.0,1.0)
A29: market for sulfuric acid | B29: sulfuric acid | C29: RoW | D29: 0.016 | E29: kilogram | F29: ecoinvent 3.10 cutoff | G29: technosphere | J29: (4.0,1.0,1.0,1.0,1.0)
A30: market for hydrochloric acid, without water, in 30% solution state | B30: hydrochloric acid, without water, in 30% solution state | C30: RoW | D30: 0.016 | E30: kilogram | F30: ecoinvent 3.10 cutoff | G30: technosphere | J30: (4.0,1.0,1.0,1.0,1.0)
A31: market for lime, packed | B31: lime, packed | C31: RoW | D31: 0.016 | E31: kilogram | F31: ecoinvent 3.10 cutoff | G31: technosphere | J31: (4.0,1.0,1.0,1.0,1.0)
A32: market for chemical, organic | B32: chemical, organic | C32: GLO | D32: 0.032 | E32: kilogram | F32: ecoinvent 3.10 cutoff | G32: technosphere | J32: (4.0,1.0,1.0,1.0,1.0)
A33: market for electricity, medium voltage | B33: electricity, medium voltage | C33: CL | D33: 0.41666667 | E33: kilowatt hour | F33: ecoinvent 3.10 cutoff | G33: technosphere | J33: (4.0,1.0,1.0,1.0,1.0)
A34: market for diesel, burned in building machine | B34: diesel, burned in building machine | C34: GLO | D34: 0.4 | E34: megajoule | F34: ecoinvent 3.10 cutoff | G34: technosphere | J34: (4.0,1.0,1.0,1.0,1.0)
A35: market for heat, district or industrial, natural gas | B35: heat, district or industrial, natural gas | C35: RoW | D35: 2.8 | E35: megajoule | F35: ecoinvent 3.10 cutoff | G35: technosphere | J35: (4.0,1.0,1.0,1.0,1.0)
A36: Particulate Matter, > 2.5 um and < 10um | D36: 0.0007 | E36: kilogram | F36: biosphere3 | G36: biosphere | H36: air | J36: (4.0,1.0,1.0,1.0,1.0)
A37: Particulate Matter, < 2.5 um | D37: 0.0004 | E37: kilogram | F37: biosphere3 | G37: biosphere | H37: air | J37: (4.0,1.0,1.0,1.0,1.0)
A39: Activity | B39: Li2CO3 production in Chile/Salar de Atacama
A40: reference product | B40: Battery-grade Li2CO3
A41: location | B41: CL
A42: amount | B42: 1
...

Sheet PR3_LiOH_CL_Atacama_Brines
A1: Activity | B1: [P] Battery-grade Li hydroxide (LiOH.H2O) production (Salar de Atacama)
A2: reference product | B2: Battery-grade LiOH.H2O
A3: location | B3: CL
A4: amount | B4: 1
A5: unit | B5: kilogram
A6: comment | B6: n/a
A7: Exchanges
A8: name | B8: reference product | C8: location | D8: amount | E8: unit | F8: database | G8: type | H8: categories | I8: uncertainty type | J8: pedigree | K8: loc | L8: scale | M8: minimum | N8: maximum
A9: =B1 -> [P] Battery-grade Li hydroxide (LiOH.H2O) production (Salar de Atacama) | B9: =B2 -> Battery-grade LiOH.H2O | C9: =B3 -> CL | D9: 1 | E9: kilogram | F9: =Li_Market_GLO!B1 -> Lithium | G9: production
A10: market for quicklime, milled, packed | B10: quicklime, milled, packed | C10: RoW | D10: 1.15 | E10: kilogram | F10: ecoinvent 3.10 cutoff | G10: technosphere | J10: (4,1,1,1,1)
A11: market for electricity, medium voltage | B11: electricity, medium voltage | C11: CL | D11: 1.3888889 | E11: kilowatt hour | F11: ecoinvent 3.10 cutoff | G11: technosphere | J11: (4,1,1,1,1)
A12: market for diesel, burned in building machine | B12: diesel, burned in building machine | C12: GLO | D12: 3 | E12: megajoule | F12: ecoinvent 3.10 cutoff | G12: technosphere | J12: (4,1,1,1,1)
A13: market for heat, district or industrial, natural gas | B13: heat, district or industrial, natural gas | C13: RoW | D13: 21 | E13: megajoule | F13: ecoinvent 3.10 cutoff | G13: technosphere | J13: (4,1,1,1,1)
A14: Water, unspecified natural origin | D14: 0.0005 | E14: cubic meter | F14: biosphere3 | G14: biosphere | H14: natural resource::in ground | J14: (4,1,1,1,1)
A15: Particulate Matter, > 2.5 um and < 10um | D15: 0.0001 | E15: kilogram | F15: biosphere3 | G15: biosphere | H15: air | J15: (4,1,1,1,1)
A16: Particulate Matter, < 2.5 um | D16: 5e-05 | E16: kilogram | F16: biosphere3 | G16: biosphere | H16: air | J16: (4,1,1,1,1)
A18: Activity | B18: LiOH.H2O production in Chile/Salar de Atacama
A19: reference product | B19: Battery-grade LiOH.H2O
A20: location | B20: CL
A21: amount | B21: 1
A22: unit | B22: kilogram
A23: comment | B23: n/a
A24: Exchanges
A25: name | B25: reference product | C25: location | D25: amount | E25: unit | F25: database | G25: type | H25: categories | I25: uncertainty type | J25: pedigree | K25: loc | L25: scale | M25: minimum | N25: maximum
A26: =B18 -> LiOH.H2O production in Chile/Salar de Atacama | B26: =B19 -> Battery-grade LiOH.H2O | C26: =B20 -> CL | D26: 1 | E26: kilogram | F26: =F9 -> Lithium | G26: production
A27: =A9 -> [P] Battery-grade Li hydroxide (LiOH.H2O) production (Salar de Atacama) | B27: =B9 -> Battery-grade LiOH.H2O | C27: =C9 -> CL | D27: 1 | E27: =E9 -> kilogram | F27: =F9 -> Lithium | G27: technosphere
A28: =PR2_Li2CO3_CL_Atacama_Brines!A27 -> [P] Battery-grade Li carbonate (Li2CO3) production (Salar de Atacama) | B28: =PR2_Li2CO3_CL_Atacama_Brines!B27 -> Battery-grade Li2CO3 | C28: =PR2_Li2CO3_CL_Atacama_Brines!C27 -> CL | D28: 1.05 | E28: =PR2_Li2CO3_CL_Atacama_Brines!E27 -> kilogram | F28: =PR2_Li2CO3_CL_Atacama_Brines!F27 -> Lithium | G28: technosphere
A29: =PR2_Li2CO3_CL_Atacama_Brines!A9 -> [M+C] Lithium (Li) brine concentration (Salar de Atacama) | B29: =PR2_Li2CO3_CL_Atacama_Brines!B9 -> Li brine | C29: =PR2_Li2CO3_CL_Atacama_Brines!C9 -> CL | D29: 4.2 | E29: =PR2_Li2CO3_CL_Atacama_Brines!E9 -> kilogram | F29: =PR2_Li2CO3_CL_Atacama_Brines!F9 -> Lithium | G29: technosphere
A31: Activity | B31: LiOH.H2O production in Chile/Salar de Atacama (Li content)
A32: reference product | B32: Battery-grade LiOH.H2O (Li content)
A33: location | B33: CL
A34: amount | B34: 1
A35: unit | B35: kilogram
A36: comment | B36: Activity expressed for 1 kg Li contained
A37: Exchanges
A38: name | B38: reference product | C38: location | D38: amount | E38: unit | F38: database | G38: type | H38: categories | I38: uncertainty type | J38: pedigree | K38: loc | L38: scale | M38: minimum | N38: maximum
A39: =B31 -> LiOH.H2O production in Chile/Salar de Atacama (Li content) | B39: =B32 -> Battery-grade LiOH.H2O (Li content) | C39: =B33 -> CL | D39: 1 | E39: kilogram | F39: =F26 -> Lithium | G39: production
A40: =A27 -> [P] Battery-grade Li hydroxide (LiOH.H2O) production (Salar de Atacama) | B40: =B27 -> Battery-grade LiOH.H2O | C40: =C27 -> CL | D40: 6.0606061 | E40: =E27 -> kilogram | F40: =F27 -> Lithium | G40: =G27 -> technosphere
A41: =A28 -> [P] Battery-grade Li carbonate (Li2CO3) production (Salar de Atacama) | B41: =B28 -> Battery-grade Li2CO3 | C41: =C28 -> CL | D41: 6.3636364 | E41: =E28 -> kilogram | F41: =F28 -> Lithium | G41: =G28 -> technosphere
A42: =A29 -> [M+C] Lithium (Li) brine concentration (Salar de Atacama) | B42: =B29 -> Li brine | C42: =C29 -> CL | D42: 25.454545 | E42: =E29 -> kilogram | F42: =F29 -> Lithium | G42: =G29 -> technosphere

Sheet PR4_Li2CO3_AU_CN_She_Spodumene
A1: Activity | B1: [M+C] Spodumene ore mining and concentration
A2: reference product | B2: Spodumene concentrate
A3: location | B3: AU
A4: amount | B4: 1
A5: unit | B5: kilogram
A6: comment | B6: n/a
A7: Exchanges
A8: name | B8: reference product | C8: location | D8: amount | E8: unit | F8: database | G8: type | H8: categories | I8: uncertainty type | J8: pedigree | K8: loc | L8: scale | M8: minimum | N8: maximum
A9: =B1 -> [M+C] Spodumene ore mining and concentration | B9: =B2 -> Spodumene concentrate | C9: =B3 -> AU | D9: 1 | E9: kilogram | F9: =Li_Market_GLO!B1 -> Lithium | G9: production
A10: market for recultivation, iron mine | B10: recultivation, iron mine | C10: GLO | D10: 5.36e-06 | E10: square meter | F10: ecoinvent 3.10 cutoff | G10: technosphere | J10: (2.0,5.0,5.0,5.0,5.0)
A11: market for mine infrastructure, iron | B11: mine infrastructure, iron | C11: GLO | D11: 5e-11 | E11: unit | F11: ecoinvent 3.10 cutoff | G11: technosphere | J11: (2.0,5.0,5.0,5.0,5.0)
A12: market for diesel, burned in building machine | B12: diesel, burned in building machine | C12: GLO | D12: 0.0789 | E12: megajoule | F12: ecoinvent 3.10 cutoff | G12: technosphere | J12: (2.0,5.0,5.0,5.0,5.0)
A13: market for blasting | B13: blasting | C13: GLO | D13: 0.000839 | E13: kilogram | F13: ecoinvent 3.10 cutoff | G13: technosphere | J13: (2.0,5.0,5.0,5.0,5.0)
A14: market for soda ash, dense | B14: soda ash, dense | C14: GLO | D14: 0.015 | E14: kilogram | F14: ecoinvent 3.10 cutoff | G14: technosphere | J14: (4.0,1.0,5.0,5.0,5.0)
A15: market for electricity, medium voltage | B15: electricity, medium voltage | C15: AU | D15: 1.9 | E15: kilowatt hour | F15: ecoinvent 3.10 cutoff | G15: technosphere | J15: (2.0,1.0,1.0,1.0,1.0)
A16: market for non-sulfidic tailing, off-site | B16: non-sulfidic tailing, off-site | C16: GLO | D16: -4.2 | E16: kilogram | F16: ecoinvent 3.10 cutoff | G16: technosphere | J16: (2.0,1.0,1.0,1.0,1.0)
A17: Occupation, mineral extraction site | D17: 0.000201 | E17: square meter-year | F17: biosphere3 | G17: biosphere | H17: natural resource::land | J17: (2.0,5.0,5.0,5.0,5.0)
A18: Transformation, from forest, extensive | D18: 6.7e-06 | E18: square meter | F18: biosphere3 | G18: biosphere | H18: natural resource::land | J18: (2.0,5.0,5.0,5.0,5.0)
A19: Transformation, to mineral extraction site | D19: 6.7e-06 | E19: square meter | F19: biosphere3 | G19: biosphere | H19: natural resource::land | J19: (2.0,5.0,5.0,5.0,5.0)
A20: Particulate Matter, > 10 um | D20: 0.00446 | E20: kilogram | F20: biosphere3 | G20: biosphere | H20: air | J20: (2.0,5.0,5.0,5.0,5.0)
A21: Particulate Matter, > 2.5 um and < 10um | D21: 0.00402 | E21: kilogram | F21: biosphere3 | G21: biosphere | H21: air | J21: (2.0,5.0,5.0,5.0,5.0)
A22: Particulate Matter, < 2.5 um | D22: 0.000446 | E22: kilogram | F22: biosphere3 | G22: biosphere | H22: air | J22: (2.0,5.0,5.0,5.0,5.0)
A23: Water, unspecified natural origin | D23: 0.0168 | E23: cubic meter | F23: biosphere3 | G23: biosphere | H23: natural resource::in ground | J23: (2.0,1.0,1.0,1.0,1.0)
A24: Water | D24: 0.0154 | E24: cubic meter | F24: biosphere3 | G24: biosphere | H24: water | J24: (2.0,1.0,1.0,1.0,1.0)
A25: Lithium | D25: 0.02888 | E25: kilogram | F25: biosphere3 | G25: biosphere | H25: natural resource::in ground | J25: (2.0,1.0,1.0,1.0,1.0)
A27: Activity | B27: [P] Battery-grade Li carbonate (Li2CO3) production (Shehong plant)
A28: reference product | B28: Battery-grade Li2CO3
A29: location | B29: CN
A30: amount | B30: 1
A31: unit | B31: kilogram
A32: comment | B32: The co-produced sodium sulfate is dealt through substitution.
A33: Exchanges
A34: name | B34: reference product | C34: location | D34: amount | E34: unit | F34: database | G34: type | H34: categories | I34: uncertainty type | J34: pedigree | K34: loc | L34: scale | M34: minimum | N34: maximum
A35: =B27 -> [P] Battery-grade Li carbonate (Li2CO3) production (Shehong plant) | B35: =B28 -> Battery-grade Li2CO3 | C35: =B29 -> CN | D35: 1 | E35: kilogram | F35: =F9 -> Lithium | G35: production
A36: market for sulfuric acid | B36: sulfuric acid | C36: RoW | D36: 1.71 | E36: kilogram | F36: ecoinvent 3.10 cutoff | G36: technosphere | J36: (1.0,1.0,2.0,1.0,1.0)
A37: market for soda ash, dense | B37: soda ash, dense | C37: GLO | D37: 2.05 | E37: kilogram | F37: ecoinvent 3.10 cutoff | G37: technosphere | J37: (1.0,1.0,2.0,1.0,1.0)
A38: market for sodium hydroxide, without water, in 50% solution state | B38: sodium hydroxide, without water, in 50% solution state | C38: RoW | D38: 0.05 | E38: kilogram | F38: ecoinvent 3.10 cutoff | G38: technosphere | J38: (1.0,1.0,2.0,1.0,1.0)
A39: market for quicklime, milled, packed | B39: quicklime, milled, packed | C39: RoW | D39: 0.7 | E39: kilogram | F39: ecoinvent 3.10 cutoff | G39: technosphere | J39: (1.0,1.0,2.0,1.0,1.0)
A40: market group for electricity, medium voltage | B40: electricity, medium voltage | C40: CN | D40: 1.8 | E40: kilowatt hour | F40: ecoinvent 3.10 cutoff | G40: technosphere | J40: (1.0,1.0,2.0,1.0,1.0)
A41: heat production, at hard coal industrial furnace 1-10MW | B41: heat, district or industrial, other than natural gas | C41: RoW | D41: 82.8929 | E41: megajoule | F41: ecoinvent 3.10 cutoff | G41: technosphere | J41: (1.0,1.0,2.0,1.0,1.0)
...

Sheet PR5_LiOH_AU_CN_She_Spodumene
A1: Activity | B1: [P] Battery-grade Lithium (Li) hydroxide (LiOH.H2O) production (Shehong plant)
A2: reference product | B2: Battery-grade LiOH.H2O
A3: location | B3: CN
A4: amount | B4: 1
A5: unit | B5: kilogram
A6: comment | B6: The co-produced sodium sulfate is dealt through substitution.
A7: Exchanges
A8: name | B8: reference product | C8: location | D8: amount | E8: unit | F8: database | G8: type | H8: categories | I8: uncertainty type | J8: pedigree | K8: loc | L8: scale | M8: minimum | N8: maximum
A9: =B1 -> [P] Battery-grade Lithium (Li) hydroxide (LiOH.H2O) production (Shehong plant) | B9: =B2 -> Battery-grade LiOH.H2O | C9: =B3 -> CN | D9: 1 | E9: kilogram | F9: =Li_Market_GLO!B1 -> Lithium | G9: production
A10: market for sulfuric acid | B10: sulfuric acid | C10: RoW | D10: 1.52 | E10: kilogram | F10: ecoinvent 3.10 cutoff | G10: technosphere | J10: (1.0,1.0,2.0,1.0,1.0)
A11: market for soda ash, dense | B11: soda ash, dense | C11: GLO | D11: 0.025 | E11: kilogram | F11: ecoinvent 3.10 cutoff | G11: technosphere | J11: (1.0,1.0,2.0,1.0,1.0)
A12: market for sodium hydroxide, without water, in 50% solution state | B12: sodium hydroxide, without water, in 50% solution state | C12: RoW | D12: 1.18 | E12: kilogram | F12: ecoinvent 3.10 cutoff | G12: technosphere | J12: (1.0,1.0,2.0,1.0,1.0)
A13: market for quicklime, milled, packed | B13: quicklime, milled, packed | C13: RoW | D13: 0.6 | E13: kilogram | F13: ecoinvent 3.10 cutoff | G13: technosphere | J13: (1.0,1.0,2.0,1.0,1.0)
A14: market group for electricity, medium voltage | B14: electricity, medium voltage | C14: CN | D14: 3.5 | E14: kilowatt hour | F14: ecoinvent 3.10 cutoff | G14: technosphere | J14: (1.0,1.0,2.0,1.0,1.0)
A15: heat production, at hard coal industrial furnace 1-10MW | B15: heat, district or industrial, other than natural gas | C15: RoW | D15: 32.81778 | E15: megajoule | F15: ecoinvent 3.10 cutoff | G15: technosphere | J15: (1.0,1.0,2.0,1.0,1.0)
A16: market for heat, from steam, in chemical industry | B16: heat, from steam, in chemical industry | C16: RoW | D16: 38.52522 | E16: megajoule | F16: ecoinvent 3.10 cutoff | G16: technosphere | J16: (1.0,1.0,2.0,1.0,1.0)
A17: sodium sulfate production, from natural sources | B17: sodium sulfate, anhydrite | C17: RoW | D17: -1.72 | E17: kilogram | F17: ecoinvent 3.10 cutoff | G17: technosphere | J17: (1.0,1.0,2.0,1.0,1.0)
A18: Water, unspecified natural origin | D18: 0.01124 | E18: cubic meter | F18: biosphere3 | G18: biosphere | H18: natural resource::in ground | J18: (1.0,1.0,2.0,1.0,1.0)
A20: Activity | B20: Spodumene ore mining in Australia/Greenbushes and LiOH.H2O production in China/Shehong
A21: reference product | B21: Battery-grade LiOH.H2O
A22: location | B22: AU-CN
A23: amount | B23: 1
A24: unit | B24: kilogram
A25: comment | B25: n/a
A26: Exchanges
A27: name | B27: reference product | C27: location | D27: amount | E27: unit | F27: database | G27: type | H27: categories | I27: uncertainty type | J27: pedigree | K27: loc | L27: scale | M27: minimum | N27: maximum
A28: =B20 -> Spodumene ore mining in Australia/Greenbushes and LiOH.H2O production in China/Shehong | B28: =B21 -> Battery-grade LiOH.H2O | C28: =B22 -> AU-CN | D28: 1 | E28: kilogram | F28: =F9 -> Lithium | G28: production
A29: =A9 -> [P] Battery-grade Lithium (Li) hydroxide (LiOH.H2O) production (Shehong plant) | B29: =B9 -> Battery-grade LiOH.H2O | C29: =C9 -> CN | D29: 1 | E29: =E9 -> kilogram | F29: =F9 -> Lithium | G29: technosphere
A30: =PR4_Li2CO3_AU_CN_She_Spodumene!A9 -> [M+C] Spodumene ore mining and concentration | B30: =PR4_Li2CO3_AU_CN_She_Spodumene!B9 -> Spodumene concentrate | C30: =PR4_Li2CO3_AU_CN_She_Spodumene!C9 -> AU | D30: 6.42 | E30: =PR4_Li2CO3_AU_CN_She_Spodumene!E9 -> kilogram | F30: =PR4_Li2CO3_AU_CN_She_Spodumene!F9 -> Lithium | G30: technosphere
A32: Activity | B32: Spodumene ore mining in Australia/Greenbushes and LiOH.H2O production in China/Shehong (Li content)
A33: reference product | B33: Battery-grade LiOH.H2O (Li content)
A34: location | B34: AU-CN
A35: amount | B35: 1
A36: unit | B36: kilogram
A37: comment | B37: Activity expressed for 1 kg Li contained
A38: Exchanges
A39: name | B39: reference product | C39: location | D39: amount | E39: unit | F39: database | G39: type | H39: categories | I39: uncertainty type | J39: pedigree | K39: loc | L39: scale | M39: minimum | N39: maximum
A40: =B32 -> Spodumene ore mining in Australia/Greenbushes and LiOH.H2O production in China/Shehong (Li content) | B40: =B33 -> Battery-grade LiOH.H2O (Li content) | C40: =B34 -> AU-CN | D40: 1 | E40: kilogram | F40: =F28 -> Lithium | G40: production
A41: =A29 -> [P] Battery-grade Lithium (Li) hydroxide (LiOH.H2O) production (Shehong plant) | B41: =B29 -> Battery-grade LiOH.H2O | C41: =C29 -> CN | D41: 6.0606061 | E41: =E29 -> kilogram | F41: =F29 -> Lithium | G41: =G29 -> technosphere
A42: =A30 -> [M+C] Spodumene ore mining and concentration | B42: =B30 -> Spodumene concentrate | C42: =C30 -> AU | D42: 38.909091 | E42: =E30 -> kilogram | F42: =F30 -> Lithium | G42: =G30 -> technosphere

Sheet PR6_Li2CO3_CN_Zha
A1: Activity | B1: [P] Battery-grade Li carbonate (Li2CO3) production (Zhangjiagang plant)
A2: reference product | B2: Battery-grade Li2CO3
A3: location | B3: CN
A4: amount | B4: 1
A5: unit | B5: kilogram
A6: comment | B6: The co-produced sodium sulfate is dealt through substitution.
A7: Exchanges
A8: name | B8: reference product | C8: location | D8: amount | E8: unit | F8: database | G8: type | H8: categories | I8: uncertainty type | J8: pedigree | K8: loc | L8: scale | M8: minimum | N8: maximum
A9: =B1 -> [P] Battery-grade Li carbonate (Li2CO3) production (Zhangjiagang plant) | B9: =B2 -> Battery-grade Li2CO3 | C9: =B3 -> CN | D9: 1 | E9: kilogram | F9: =Li_Market_GLO!B1 -> Lithium | G9: production
A10: market group for electricity, medium voltage | B10: electricity, medium voltage | C10: CN | D10: 0.19 | E10: kilowatt hour | F10: ecoinvent 3.10 cutoff | G10: technosphere | J10: (1,4,3,1,1)
A11: market group for electricity, medium voltage | B11: electricity, medium voltage | C11: CN | D11: 0.19 | E11: kilowatt hour | F11: ecoinvent 3.10 cutoff | G11: technosphere | J11: (1,4,3,1,1)
A12: market group for electricity, medium voltage | B12: electricity, medium voltage | C12: CN | D12: 0.46 | E12: kilowatt hour | F12: ecoinvent 3.10 cutoff | G12: technosphere | J12: (1,4,3,1,1)
A13: market group for electricity, medium voltage | B13: electricity, medium voltage | C13: CN | D13: 0.47 | E13: kilowatt hour | F13: ecoinvent 3.10 cutoff | G13: technosphere | J13: (1,4,3,1,1)
A14: market group for electricity, medium voltage | B14: electricity, medium voltage | C14: CN | D14: 2.04 | E14: kilowatt hour | F14: ecoinvent 3.10 cutoff | G14: technosphere | J14: (1,4,3,1,1)
A15: market group for electricity, medium voltage | B15: electricity, medium voltage | C15: CN | D15: 0.48 | E15: kilowatt hour | F15: ecoinvent 3.10 cutoff | G15: technosphere | J15: (1,4,3,1,1)
A16: market for natural gas, high pressure | B16: natural gas, high pressure | C16: CN | D16: 0.94 | E16: cubic meter | F16: ecoinvent 3.10 cutoff | G16: technosphere | J16: (1,4,3,1,1)
A17: market for natural gas, high pressure | B17: natural gas, high pressure | C17: CN | D17: 0.3 | E17: cubic meter | F17: ecoinvent 3.10 cutoff | G17: technosphere | J17: (1,4,3,1,1)
A18: market for natural gas, high pressure | B18: natural gas, high pressure | C18: CN | D18: 0.05 | E18: cubic meter | F18: ecoinvent 3.10 cutoff | G18: technosphere | J18: (1,4,3,1,1)
A19: market for natural gas, high pressure | B19: natural gas, high pressure | C19: CN | D19: 0.07 | E19: cubic meter | F19: ecoinvent 3.10 cutoff | G19: technosphere | J19: (1,4,3,1,1)
A20: market for steam, in chemical industry | B20: steam, in chemical industry | C20: RoW | D20: 0.828 | E20: kilogram | F20: ecoinvent 3.10 cutoff | G20: technosphere | J20: (1,4,3,1,1)
A21: market for steam, in chemical industry | B21: steam, in chemical industry | C21: RoW | D21: 3.834 | E21: kilogram | F21: ecoinvent 3.10 cutoff | G21: technosphere | J21: (1,4,3,1,1)
... A35: market for wastewater, average | B35: wastewater, average | C35: RoW | D35: -0.01352 | E35: cubic meter | F35: ecoinvent 3.10 cutoff | G35: technosphere | J35: (2,4,5,1,1)
A36: Water, unspecified natural origin | D36: 0.0263 | E36: cubic meter | F36: biosphere3 | G36: biosphere | H36: natural resource::in ground | J36: (1,4,3,1,1)
A37: Water, unspecified natural origin | D37: 0.00593 | E37: cubic meter | F37: biosphere3 | G37: biosphere | H37: natural resource::in ground | J37: (1,4,3,1,1)
A38: Water, unspecified natural origin | D38: 0.01723 | E38: cubic meter | F38: biosphere3 | G38: biosphere | H38: natural resource::in ground | J38: (1,4,3,1,1)
A39: Sulfuric acid | D39: 5e-05 | E39: kilogram | F39: biosphere3 | G39: biosphere | H39: air | J39: (2,4,5,1,1)
A40: Sulfur dioxide | D40: 7e-05 | E40: kilogram | F40: biosphere3 | G40: biosphere | H40: air | J40: (2,4,5,1,1)
A41: Sulfur dioxide | D41: 2e-05 | E41: kilogram | F41: biosphere3 | G41: biosphere | H41: air | J41: (2,4,5,1,1)
A42: Nitrogen oxides | D42: 0.00099 | E42: kilogram | F42: biosphere3 | G42: biosphere | H42: air | J42: (2,4,5,1,1)
A43: Nitrogen oxides | D43: 0.00032 | E43: kilogram | F43: biosphere3 | G43: biosphere | H43: air | J43: (2,4,5,1,1)
A44: Particulate Matter, > 2.5 um and < 10um | D44: 0.00053 | E44: kilogram | F44: biosphere3 | G44: biosphere | H44: air | J44: (2,4,5,1,1)
A45: COD, Chemical Oxygen Demand | D45: 0.29 | E45: kilogram | F45: biosphere3 | G45: biosphere | H45: water | J45: (2,4,5,1,1)
A46: COD, Chemical Oxygen Demand | D46: 0.07 | E46: kilogram | F46: biosphere3 | G46: biosphere | H46: water | J46: (2,4,5,1,1)
A47: COD, Chemical Oxygen Demand | D47: 0.19 | E47: kilogram | F47: biosphere3 | G47: biosphere | H47: water | J47: (2,4,5,1,1)
... A52: Phosphorus | D52: 0.003 | E52: kilogram | F52: biosphere3 | G52: biosphere | H52: water | J52: (2,4,5,1,1)
A54: Activity | B54: Li2CO3 production in China/Zhangjiagang
A55: reference product | B55: Battery-grade Li2CO3
A56: location | B56: AU-CN
A57: amount | B57: 1
A58: unit | B58: kilogram
...

Sheet PR7_Li2CO3_AR_Olaroz_Brines
A1: Activity | B1: [M+C] Lithium (Li) brine concentration (Salar de Olaroz)
A2: reference product | B2: Li brine
A3: location | B3: AR
A4: amount | B4: 1
A5: unit | B5: kilogram
A6: comment | B6: n/a
A7: Exchanges
A8: name | B8: reference product | C8: location | D8: amount | E8: unit | F8: database | G8: type | H8: categories | I8: uncertainty type | J8: pedigree | K8: loc | L8: scale | M8: minimum | N8: maximum
A9: =B1 -> [M+C] Lithium (Li) brine concentration (Salar de Olaroz) | B9: =B2 -> Li brine | C9: =B3 -> AR | D9: 1 | E9: kilogram | F9: =Li_Market_GLO!B1 -> Lithium | G9: production
A10: Lithium | D10: 0.024643865 | E10: kilogram | F10: biosphere3 | G10: biosphere | H10: natural resource::in ground | I10: 5 | K10: 0.024643865 | M10: 0.017250705 | N10: 0.032037024
A11: heat and power co-generation, natural gas, 1MW electrical, lean burn | B11: electricity, high voltage | C11: RoW | D11: 0.0055256514 | E11: kilowatt hour | F11: ecoinvent 3.10 cutoff | G11: technosphere | I11: 5 | K11: 0.0055256514 | M11: 0.0046968037 | N11: 0.0063544991
A12: machine operation, diesel, >= 74.57 kW, high load factor | B12: machine operation, diesel, >= 74.57 kW, high load factor | C12: GLO | D12: 8.712446e-05 | E12: hour | F12: ecoinvent 3.10 cutoff | G12: technosphere | I12: 2 | J12: (2,2,3,4,5) | K12: -9.3481729 | L12: 0.74909591
A13: market for quicklime, milled, packed | B13: quicklime, milled, packed | C13: RoW | D13: 0.23612971 | E13: kilogram | F13: ecoinvent 3.10 cutoff | G13: technosphere | I13: 5 | K13: 0.23612971 | M13: 0.21251674 | N13: 0.25974268
A14: Water reverse osmosis (Salar de Olaroz) | B14: Water | C14: AR | D14: 0.17847792 | E14: kilogram | F14: Lithium | G14: technosphere | I14: 2 | J14: (4,5,5,3,3) | K14: -1.7232904 | L14: 0.51431269
A15: Occupation, mineral extraction site | D15: 1.5130592e-10 | E15: square meter-year | F15: biosphere3 | G15: biosphere | H15: natural resource::land | I15: 2 | J15: (2,2,4,1,1) | K15: -22.611717 | L15: 0.18977295
A16: Transformation, from unspecified | D16: 3.7826479e-12 | E16: square meter | F16: biosphere3 | G16: biosphere | H16: natural resource::land | I16: 2 | J16: (2,2,1,1,1) | K16: -26.300597 | L16: 0.052655714
A17: Transformation, to mineral extraction site | D17: 3.7826479e-12 | E17: square meter | F17: biosphere3 | G17: biosphere | H17: natural resource::land | I17: 2 | J17: (2,2,1,1,1) | K17: -26.300597 | L17: 0.052655714
A19: Activity | B19: [P] Battery-grade Li carbonate (Li2CO3) production (Salar de Olaroz)
A20: reference product | B20: Battery-grade Li2CO3
A21: location | B21: AR
A22: amount | B22: 1
A23: unit | B23: kilogram
A24: comment | B24: n/a
A25: Exchanges
A26: name | B26: reference product | C26: location | D26: amount | E26: unit | F26: database | G26: type | H26: categories | I26: uncertainty type | J26: pedigree | K26: loc | L26: scale | M26: minimum | N26: maximum
A27: =B19 -> [P] Battery-grade Li carbonate (Li2CO3) production (Salar de Olaroz) | B27: =B20 -> Battery-grade Li2CO3 | C27: =B21 -> AR | D27: 1 | E27: kilogram | F27: =F9 -> Lithium | G27: production
A28: heat and power co-generation, natural gas, 1MW electrical, lean burn | B28: heat, district or industrial, natural gas | C28: RoW | D28: 2.4705882 | E28: megajoule | F28: ecoinvent 3.10 cutoff | G28: technosphere | I28: 2 | J28: (5,5,5,5,5) | K28: 0.90445627 | L28: 1.0034441
A29: heat and power co-generation, natural gas, 1MW electrical, lean burn | B29: electricity, high voltage | C29: RoW | D29: 0.3 | E29: kilowatt hour | F29: ecoinvent 3.10 cutoff | G29: technosphere | I29: 2 | J29: (5,5,5,5,5) | K29: -1.2039728 | L29: 1.0034441
A30: heat and power co-generation, natural gas, 1MW electrical, lean burn | B30: electricity, high voltage | C30: RoW | D30: 0.010053208 | E30: kilowatt hour | F30: ecoinvent 3.10 cutoff | G30: technosphere | I30: 2 | J30: (3,3,5,5,5) | K30: -5.0053286 | L30: 0.90593677
A31: Water reverse osmosis (Salar de Olaroz) | B31: Water | C31: AR | D31: 2 | E31: kilogram | F31: Lithium | G31: technosphere | I31: 2 | J31: (3,5,5,3,4) | L31: 0.60952542
A32: heat and power co-generation, natural gas, 1MW electrical, lean burn | B32: heat, district or industrial, natural gas | C32: RoW | D32: 0.77450918 | E32: megajoule | F32: ecoinvent 3.10 cutoff | G32: technosphere | I32: 5 | K32: 0.38725459 | M32: 0.27107821 | N32: 0.50343096
A33: heat and power co-generation, natural gas, 1MW electrical, lean burn | B33: electricity, high voltage | C33: RoW | D33: 0.01 | E33: kilowatt hour | F33: ecoinvent 3.10 cutoff | G33: technosphere | I33: 2 | J33: (3,3,5,5,5) | K33: -4.6051702 | L33: 0.90593677
A34: heat and power co-generation, natural gas, 1MW electrical, lean burn | B34: heat, district or industrial, natural gas | C34: RoW | D34: 10.445905 | E34: megajoule | F34: ecoinvent 3.10 cutoff | G34: technosphere | I34: 5 | K34: 0.42365161 | M34: 0.29655612 | N34: 0.55074709
A35: heat and power co-generation, natural gas, 1MW electrical, lean burn | B35: electricity, high voltage | C35: RoW | D35: 0.021004615 | E35: kilowatt hour | F35: ecoinvent 3.10 cutoff | G35: technosphere | I35: 2 | J35: (3,5,5,5,5) | K35: -7.1062062 | L35: 0.92281206
A36: Water reverse osmosis (Salar de Olaroz) | B36: Water | C36: AR | D36: 25.615385 | E36: kilogram | F36: Lithium | G36: technosphere | I36: 2 | J36: (3,5,5,5,5) | L36: 0.92281206
A37: market for hydrochloric acid, without water, in 30% solution state | B37: hydrochloric acid, without water, in 30% solution state | C37: RoW | D37: 0.0061476923 | E37: kilogram | F37: ecoinvent 3.10 cutoff | G37: technosphere | I37: 2 | J37: (3,5,5,5,5) | K37: -8.3348716 | L37: 0.92281206
A38: market for sodium hydroxide, without water, in 50% solution state | B38: sodium hydroxide, without water, in 50% solution state | C38: RoW | D38: 0.0030738462 | E38: kilogram | F38: ecoinvent 3.10 cutoff | G38: technosphere | I38: 2 | J38: (3,5,5,5,5) | K38: -9.0280188 | L38: 0.92281206
A39: Heat, waste | D39: 0.041496923 | E39: megajoule | F39: biosphere3 | G39: biosphere | H39: air | I39: 2 | J39: (3,5,5,5,5) | K39: -6.4253291 | L39: 0.92281206
A40: Chlorine | D40: 0.0058915385 | E40: kilogram | F40: biosphere3 | G40: biosphere | H40: water | I40: 2 | J40: (3,5,5,5,5) | K40: -8.3774312 | L40: 0.92281206
A41: Sodium I | D41: 0.0017930769 | E41: kilogram | F41: biosphere3 | G41: biosphere | H41: water | I41: 2 | J41: (3,5,5,5,5) | K41: -9.5670153 | L41: 0.92281206
...

Sheet PR8_Li2CO3_CN_Chaerhan_Brines
A1: Activity | B1: [M+C] Lithium (Li) brine purification and concentration (Chaerhan)
A2: reference product | B2: Li brine
A3: location | B3: CN
A4: amount | B4: 1
A5: unit | B5: kilogram
A6: comment | B6: n/a
A7: Exchanges
A8: name | B8: reference product | C8: location | D8: amount | E8: unit | F8: database | G8: type | H8: categories | I8: uncertainty type | J8: pedigree | K8: loc | L8: scale | M8: minimum | N8: maximum
A9: =B1 -> [M+C] Lithium (Li) brine purification and concentration (Chaerhan) | B9: =B2 -> Li brine | C9: =B3 -> CN | D9: 1 | E9: kilogram | F9: =Li_Market_GLO!B1 -> Lithium | G9: production
A10: electricity, high voltage, production mix | B10: electricity, high voltage | C10: CN-NWG | D10: 0.54144161 | E10: kilowatt hour | F10: ecoinvent 3.10 cutoff | G10: technosphere | I10: 2 | J10: (3,3,1,1,3) | K10: -0.61352006 | L10: 0.21143713
A11: electricity, high voltage, production mix | B11: electricity, high voltage | C11: CN-NWG | D11: 0.35853651 | E11: kilowatt hour | F11: ecoinvent 3.10 cutoff | G11: technosphere | I11: 2 | J11: (3,3,1,1,3) | K11: -1.0257248 | L11: 0.21143713
A12: heat production, natural gas, at industrial furnace >100kW | B12: heat, district or industrial, natural gas | C12: RoW | D12: 10.906161 | E12: megajoule | F12: ecoinvent 3.10 cutoff | G12: technosphere | I12: 2 | J12: (5,5,5,5,5) | K12: -1.3820085 | L12: 1.0034441
A13: electricity, high voltage, production mix | B13: electricity, high voltage | C13: CN-NWG | D13: 0.35136308 | E13: kilowatt hour | F13: ecoinvent 3.10 cutoff | G13: technosphere | I13: 2 | J13: (5,5,5,5,5) | K13: -4.8172716 | L13: 1.0034441
A14: market for hydrochloric acid, without water, in 30% solution state | B14: hydrochloric acid, without water, in 30% solution state | C14: RoW | D14: 0.030342406 | E14: kilogram | F14: ecoinvent 3.10 cutoff | G14: technosphere | I14: 2 | J14: (5,5,5,5,5) | K14: -7.2665454 | L14: 1.0034441
A15: market for sodium hydroxide, without water, in 50% solution state | B15: sodium hydroxide, without water, in 50% solution state | C15: RoW | D15: 0.015171203 | E15: kilogram | F15: ecoinvent 3.10 cutoff | G15: technosphere | I15: 2 | J15: (5,5,5,5,5) | K15: -7.9596926 | L15: 1.0034441
A16: Heat, waste | D16: 0.20481124 | E16: megajoule | F16: biosphere3 | G16: biosphere | H16: air | I16: 2 | J16: (5,5,5,5,5) | K16: -5.3570029 | L16: 1.0034441
A17: Chlorine | D17: 0.029078139 | E17: kilogram | F17: biosphere3 | G17: biosphere | H17: water | I17: 2 | J17: (5,5,5,5,5) | K17: -7.309105 | L17: 1.0034441
A18: Sodium I | D18: 0.0088498684 | E18: kilogram | F18: biosphere3 | G18: biosphere | H18: water | I18: 2 | J18: (5,5,5,5,5) | K18: -8.4986891 | L18: 1.0034441
A19: Lithium | D19: 0.043573629 | E19: kilogram | F19: biosphere3 | G19: biosphere | H19: natural resource::in ground | I19: 2 | J19: (2,5,3,3,3) | K19: -7.2798186 | L19: 0.27989097
A20: electricity, high voltage, production mix | B20: electricity, high voltage | C20: CN-NWG | D20: 0.33155624 | E20: kilowatt hour | F20: ecoinvent 3.10 cutoff | G20: technosphere | I20: 2 | J20: (5,5,5,5,5) | K20: -5.2504733 | L20: 1.0034441
A21: heat production, natural gas, at industrial furnace >100kW | B21: heat, district or industrial, natural gas | C21: RoW | D21: 6.0891884 | E21: megajoule | F21: ecoinvent 3.10 cutoff | G21: technosphere | I21: 2 | J21: (5,5,5,5,5) | K21: -2.3400006 | L21: 1.0034441
A22: Water reverse osmosis (Chaerhan) | B22: Water | C22: CN | D22: 26.780813 | E22: kilogram | F22: Lithium | G22: technosphere | I22: 2 | J22: (2,5,3,3,3) | K22: -0.85882974 | L22: 0.27989097
A23: market for ammonium chloride | B23: ammonium chloride | C23: GLO | D23: 0.037928007 | E23: kilogram | F23: ecoinvent 3.10 cutoff | G23: technosphere | I23: 2 | J23: (2,5,3,3,3) | K23: -7.4185809 | L23: 0.27989097
A25: Activity | B25: [P] Battery-grade Li carbonate (Li2CO3) production (Chaerhan)
A26: reference product | B26: Battery-grade Li2CO3
A27: location | B27: CN
A28: amount | B28: 1
A29: unit | B29: kilogram
A30: comment | B30: n/a
A31: Exchanges
A32: name | B32: reference product | C32: location | D32: amount | E32: unit | F32: database | G32: type | H32: categories | I32: uncertainty type | J32: pedigree | K32: loc | L32: scale | M32: minimum | N32: maximum
A33: =B25 -> [P] Battery-grade Li carbonate (Li2CO3) production (Chaerhan) | B33: =B26 -> Battery-grade Li2CO3 | C33: =B27 -> CN | D33: 1 | E33: kilogram | F33: =F9 -> Lithium | G33: production
A34: heat production, natural gas, at industrial furnace >100kW | B34: heat, district or industrial, natural gas | C34: RoW | D34: 2.4705882 | E34: megajoule | F34: ecoinvent 3.10 cutoff | G34: technosphere | I34: 2 | J34: (5,5,5,5,5) | K34: 0.90445627 | L34: 0.90664754
A35: electricity, high voltage, production mix | B35: electricity, high voltage | C35: CN-NWG | D35: 0.3 | E35: kilowatt hour | F35: ecoinvent 3.10 cutoff | G35: technosphere | I35: 2 | J35: (5,5,5,5,5) | K35: -1.2039728 | L35: 0.90664754
A36: electricity, high voltage, production mix | B36: electricity, high voltage | C36: CN-NWG | D36: 0.0035 | E36: kilowatt hour | F36: ecoinvent 3.10 cutoff | G36: technosphere | I36: 2 | J36: (3,3,5,5,3) | K36: -6.1856206 | L36: 0.59670428
A37: Water reverse osmosis (Chaerhan) | B37: Water | C37: CN | D37: 2 | E37: kilogram | F37: Lithium | G37: technosphere | I37: 2 | J37: (3,5,5,3,4) | K37: -0.55961579 | L37: 0.60952542
A38: heat production, natural gas, at industrial furnace >100kW | B38: heat, district or industrial, natural gas | C38: RoW | D38: 0.84292941 | E38: megajoule | F38: ecoinvent 3.10 cutoff | G38: technosphere | I38: 5 | K38: 0.24083697 | M38: 0.16858588 | N38: 0.31308807
A39: electricity, high voltage, production mix | B39: electricity, high voltage | C39: CN-NWG | D39: 0.027228713 | E39: kilowatt hour | F39: ecoinvent 3.10 cutoff | G39: technosphere | I39: 2 | J39: (3,3,5,5,3) | K39: -4.0089484 | L39: 0.61115429
A40: heat production, natural gas, at industrial furnace >100kW | B40: heat, district or industrial, natural gas | C40: RoW | D40: 11.983446 | E40: megajoule | F40: ecoinvent 3.10 cutoff | G40: technosphere | I40: 5 | K40: 0.44010329 | M40: 0.30807231 | N40: 0.57213428
A41: Water reverse osmosis (Chaerhan) | B41: Water | C41: CN | D41: 27.472527 | E41: kilogram | F41: Lithium | G41: technosphere | I41: 5 | K41: 0.96487843 | M41: 0.6754149 | N41: 1.254342
...

Sheet PR9_Li2CO3_AR_HombreM_Brines
A1: Activity | B1: [M+C] Lithium (Li) brine concentration (Salar del Hombre Muerto)
A2: reference product | B2: Li brine
A3: location | B3: AR
A4: amount | B4: 1
A5: unit | B5: kilogram
A6: comment | B6: n/a
A7: Exchanges
A8: name | B8: reference product | C8: location | D8: amount | E8: unit | F8: database | G8: type | H8: categories | I8: uncertainty type | J8: pedigree | K8: loc | L8: scale | M8: minimum | N8: maximum
A9: =B1 -> [M+C] Lithium (Li) brine concentration (Salar del Hombre Muerto) | B9: =B2 -> Li brine | C9: =B3 -> AR | D9: 1 | E9: kilogram | F9: =Li_Market_GLO!B1 -> Lithium | G9: production
A10: Lithium | D10: 0.021369181 | E10: kilogram | F10: biosphere3 | G10: biosphere | H10: natural resource::in ground | I10: 5 | K10: 0.021369181 | M10: 0.014958427 | N10: 0.027779936
A11: market for electricity, high voltage | B11: electricity, high voltage | C11: AR | D11: 0.0052753186 | E11: kilowatt hour | F11: ecoinvent 3.10 cutoff | G11: technosphere | I11: 5 | K11: 0.0052753186 | M11: 0.0044840209 | N11: 0.0060666164
A12: machine operation, diesel, >= 74.57 kW, high load factor | B12: machine operation, diesel, >= 74.57 kW, high load factor | C12: GLO | D12: 7.254976e-05 | E12: hour | F12: ecoinvent 3.10 cutoff | G12: technosphere | I12: 2 | J12: (2,2,3,4,5) | K12: -9.5312379 | L12: 0.74909591
A13: market for quicklime, milled, packed | B13: quicklime, milled, packed | C13: RoW | D13: 0.13471411 | E13: kilogram | F13: ecoinvent 3.10 cutoff | G13: technosphere | I13: 5 | K13: 0.13471411 | M13: 0.1212427 | N13: 0.14818552
A14: Water reverse osmosis (Salar del Hombre Muerto) | B14: Water | C14: AR | D14: 0.12873148 | E14: kilogram | F14: Lithium | G14: technosphere | I14: 2 | J14: (4,5,5,3,3) | K14: -2.0500266 | L14: 0.51431269
A15: Occupation, mineral extraction site | D15: 2.5497581e-10 | E15: square meter-year | F15: biosphere3 | G15: biosphere | H15: natural resource::land | I15: 2 | J15: (2,2,4,1,1) | K15: -22.089852 | L15: 0.18977295
A16: Transformation, from unspecified | D16: 8.4991937e-12 | E16: square meter | F16: biosphere3 | G16: biosphere | H16: natural resource::land | I16: 2 | J16: (2,2,1,1,1) | K16: -25.49105 | L16: 0.052655714
A17: Transformation, to mineral extraction site | D17: 8.4991937e-12 | E17: square meter | F17: biosphere3 | G17: biosphere | H17: natural resource::land | I17: 2 | J17: (2,2,1,1,1) | K17: -25.49105 | L17: 0.052655714
A19: Activity | B19: [P] Battery-grade Li carbonate (Li2CO3) production (Salar del Hombre Muerto)
A20: reference product | B20: Battery-grade Li2CO3
A21: location | B21: AR
A22: amount | B22: 1
A23: unit | B23: kilogram
A24: comment | B24: n/a
A25: Exchanges
A26: name | B26: reference product | C26: location | D26: amount | E26: unit | F26: database | G26: type | H26: categories | I26: uncertainty type | J26: pedigree | K26: loc | L26: scale | M26: minimum | N26: maximum
A27: =B19 -> [P] Battery-grade Li carbonate (Li2CO3) production (Salar del Hombre Muerto) | B27: =B20 -> Battery-grade Li2CO3 | C27: =B21 -> AR | D27: 1 | E27: kilogram | F27: =F9 -> Lithium | G27: production
A28: heat production, natural gas, at industrial furnace >100kW | B28: heat, district or industrial, natural gas | C28: RoW | D28: 2.4705882 | E28: megajoule | F28: ecoinvent 3.10 cutoff | G28: technosphere | I28: 2 | J28: (5,5,5,5,5) | K28: 0.90445627 | L28: 0.90664754
A29: market for electricity, high voltage | B29: electricity, high voltage | C29: AR | D29: 0.3 | E29: kilowatt hour | F29: ecoinvent 3.10 cutoff | G29: technosphere | I29: 2 | J29: (5,5,5,5,5) | K29: -1.2039728 | L29: 0.90664754
A30: market for electricity, high voltage | B30: electricity, high voltage | C30: AR | D30: 0.015 | E30: kilowatt hour | F30: ecoinvent 3.10 cutoff | G30: technosphere | I30: 2 | J30: (3,3,5,5,3) | K30: -4.6051702 | L30: 0.59670428
A31: Water reverse osmosis (Salar del Hombre Muerto) | B31: Water | C31: AR | D31: 2 | E31: kilogram | F31: Lithium | G31: technosphere | I31: 2 | J31: (2,5,5,1,2) | K31: -0.55961579 | L31: 0.57755075
A32: heat production, natural gas, at industrial furnace >100kW | B32: heat, district or industrial, natural gas | C32: RoW | D32: 0.80053647 | E32: megajoule | F32: ecoinvent 3.10 cutoff | G32: technosphere | I32: 5 | K32: 0.22872471 | M32: 0.16010729 | N32: 0.29734212
A33: market for electricity, high voltage | B33: electricity, high voltage | C33: AR | D33: 0.015 | E33: kilowatt hour | F33: ecoinvent 3.10 cutoff | G33: technosphere | I33: 2 | J33: (3,3,5,5,3) | K33: -4.6051702 | L33: 0.59670428
A34: heat production, natural gas, at industrial furnace >100kW | B34: heat, district or industrial, natural gas | C34: RoW | D34: 11.474814 | E34: megajoule | F34: ecoinvent 3.10 cutoff | G34: technosphere | I34: 5 | K34: 0.4214233 | M34: 0.29499631 | N34: 0.54785029
A35: Water reverse osmosis (Salar del Hombre Muerto) | B35: Water | C35: AR | D35: 27.472527 | E35: kilogram | F35: Lithium | G35: technosphere | I35: 5 | K35: 0.96487843 | M35: 0.6754149 | N35: 1.254342
A36: Water reverse osmosis (Salar del Hombre Muerto) | B36: Water | C36: AR | D36: 2 | E36: kilogram | F36: Lithium | G36: technosphere | I36: 2 | J36: (2,5,5,1,2) | K36: -0.55961579 | L36: 0.57755075
A37: heat production, natural gas, at industrial furnace >100kW | B37: heat, district or industrial, natural gas | C37: RoW | D37: 0.80053647 | E37: megajoule | F37: ecoinvent 3.10 cutoff | G37: technosphere | I37: 5 | K37: 0.22872471 | M37: 0.16010729 | N37: 0.29734212
A38: market for electricity, high voltage | B38: electricity, high voltage | C38: AR | D38: 0.15275387 | E38: kilowatt hour | F38: ecoinvent 3.10 cutoff | G38: technosphere | I38: 2 | J38: (3,3,5,5,3) | K38: -2.2843925 | L38: 0.59670428
