Workbook

Sheet Note
A1: skip
B2: Life cycle inventories of global metal and mineral supply chains: a comprehensive data review, analysis and processing Frédéric Laia*, Stéphanie Mullera, Audrey Philippea, Robert Istrateb, Brenda Miranda Xicotencatlb, Afsoon Mansouri Askic, Aina Mas Fonsd,a, Juliana Segura-Salazare, Jair Santillán Saldivara, Alexander Cimprichf, Stephen Northeyg, Lígia da Silva Limah, Lieselot Booneh, Ryosuke Yokoii, Kamrul Islami, Ioanna Paschalidouj, Felipe Cerdask,l, Victor Balboa-Espinozae, Anish Koyamparambathd, Diae Henniouia, Victoire Collignona, Aurélien Reysa, Gyslain Ngadi Sakatadim, Jo Dewulfh, Bernhard Steubingb, Christoph Helbigc, Gaétan Lefebvrea, Gian Andrea Blenginin,m, Valeria Supertio, Masaharu Motoshitai, Guido Sonnemannd, Kwame Awuah-Offeij, Steven B. Youngf, Shinsuke Murakamip, Antoine Beylota aBRGM, F-45060 Orléans, France bInstitute of Environmental Sciences (CML), Leiden University, Einsteinweg 2, 2333 CC Leiden, NL cEcological Resource Technology, University of Bayreuth, Universitätstr. 30, 95447 Bayreuth, Germany dUniv. Bordeaux, CNRS, Bordeaux INP, ISM, UMR 5255, F-33400 Talence, France eSustainable Minerals Institute, The University of Queensland, QLD, 4072, Australia fSchool of Environment, Enterprise and Development, University of Waterloo, 200 University Avenue West, Waterloo, Ontario N2L 3G1, Canada gUniversity of Technology Sydney, Institute for Sustainable Futures, Australia hSustainable Systems Engineering (STEN), Department of Green Chemistry and Technology, Faculty of Bioscience Engineering, Ghent University, Coupure Links 653, 9000 Ghent, Belgium iAIST, 305-8569 Tsukuba, Japan jMining & Explosives Engineering, Missouri University of Science & Technology, Rolla, MO, USA 65409 kInstitute for Sustainable Energy Systems (INSYS), Technical University of Applied Sciences Würzburg-Schweinfurt (THWS), Ignaz-Schön-Straße 11, Schweinfurt, Germany lFraunhofer Institute for Surface Engineering and Thin Films IST, Riedenkamp 2, Braunschweig 38108, Germany mDepartment of Environment, Land and Infrastructure Engineering, Politecnico di Torino, Corso Duca degli Abruzzi, 24, 10129 Torino, Italy nUniversity of Turin, Earth Sciences Department (DST), Via Valperga Caluso, 35 – 10125 Torino, Italy oecoinvent association, Technopark, Technoparkstrasse 1, 8005 Zürich, Switzerland pGraduate School of Engineering, The University of Tokyo, Tokyo 113-8656, Japan *Corresponding author: f.lai@brgm.fr This file provides all LCI datasets developed for Metal grade Silicon (MG-Si), with distinguishing its global market and each individual production route.
B33: Sheet | C33: Corresponding route
B34: MG-Si_Market_GLO | C34: MG-Si global market
B35: PR1_MG-Si_CN_ThermalReduction | C35: Quartz mining and metal-grade Si production in China through Carbon Thermal reduction
B36: PR2_MG-Si_NO_ThermalReduction | C36: Metal-grade Si production in Norway
B37: PR3_Si_US_Drying | C37: Quartz mining and high-quality silica sand production in the US
B38: PR4_Si_US_MagneticSeparation | C38: Quartz mining and silica sand production in the US through magnetic separation
B39: PR5_Si_US_Flotation | C39: Quartz mining and silica sand production in the US through flotation separation

Sheet MG-Si_Market_GLO
A1: database | B1: Silicon
A3: Activity | B3: Metal grade silicon (MG-Si) global market
A4: reference product | B4: MG-Si
A5: location | B5: GLO
A6: amount | B6: 1
A7: unit | B7: kilogram
A8: comment | B8: n/a
A9: Exchanges
A10: name | B10: reference product | C10: location | D10: amount | E10: unit | F10: database | G10: type | H10: categories | I10: uncertainty type | J10: pedigree | K10: loc | L10: scale | M10: minimum | N10: maximum
A11: =B3 -> Metal grade silicon (MG-Si) global market | B11: =B4 -> MG-Si | C11: =B5 -> GLO | D11: 1 | E11: =B7 -> kilogram | F11: =B1 -> Silicon | G11: production
A12: ='PR1_MG-Si_CN_ThermalReduction'!A64 -> Quartz mining and metal-grade Si production in China through Carbon Thermal reduction | B12: ='PR1_MG-Si_CN_ThermalReduction'!B64 -> MG-Si | C12: ='PR1_MG-Si_CN_ThermalReduction'!C64 -> CN | D12: 0.90952381 | E12: ='PR1_MG-Si_CN_ThermalReduction'!E64 -> kilogram | F12: ='PR1_MG-Si_CN_ThermalReduction'!F64 -> Silicon | G12: technosphere
A13: ='PR2_MG-Si_NO_ThermalReduction'!A60 -> Metal-grade Si production in Norway | B13: ='PR2_MG-Si_NO_ThermalReduction'!B60 -> MG-Si | C13: ='PR2_MG-Si_NO_ThermalReduction'!C60 -> NO | D13: 0.076190476 | E13: ='PR2_MG-Si_NO_ThermalReduction'!E60 -> kilogram | F13: ='PR2_MG-Si_NO_ThermalReduction'!F60 -> Silicon | G13: technosphere
A14: =PR3_Si_US_Drying!A36 -> Quartz mining and high-quality silica sand production in the US | B14: =PR3_Si_US_Drying!B36 -> Silica sand | C14: =PR3_Si_US_Drying!C36 -> US | D14: 0.011907143 | E14: =PR3_Si_US_Drying!E36 -> kilogram | F14: =PR3_Si_US_Drying!F36 -> Silicon | G14: technosphere
A15: =PR4_Si_US_MagneticSeparation!A61 -> Quartz mining and silica sand production in the US through magnetic separation | B15: =PR4_Si_US_MagneticSeparation!B61 -> Silica sand | C15: =PR4_Si_US_MagneticSeparation!C61 -> US | D15: 0.00091857143 | E15: =PR4_Si_US_MagneticSeparation!E61 -> kilogram | F15: =PR4_Si_US_MagneticSeparation!F61 -> Silicon | G15: technosphere
A16: =PR5_Si_US_Flotation!A66 -> Quartz mining and silica sand production in the US through flotation separation | B16: =PR5_Si_US_Flotation!B66 -> Silica sand | C16: =PR5_Si_US_Flotation!C66 -> US | D16: 0.00146 | E16: =PR5_Si_US_Flotation!E66 -> kilogram | F16: =PR5_Si_US_Flotation!F66 -> Silicon | G16: technosphere

Sheet PR1_MG-Si_CN_ThermalReduction
A1: Activity | B1: [M+C] Quartz mining
A2: reference product | B2: Silica sand
A3: location | B3: CN
A4: amount | B4: 1
A5: unit | B5: kilogram
A6: comment | B6: n/a
A7: Exchanges
A8: name | B8: reference product | C8: location | D8: amount | E8: unit | F8: database | G8: type | H8: categories | I8: uncertainty type | J8: pedigree | K8: loc | L8: scale | M8: minimum | N8: maximum
A9: =B1 -> [M+C] Quartz mining | B9: =B2 -> Silica sand | C9: =B3 -> CN | D9: 1 | E9: kilogram | F9: ='MG-Si_Market_GLO'!B1 -> Silicon | G9: production
A10: market group for electricity, medium voltage | B10: electricity, medium voltage | C10: CN | D10: 0.017142857 | E10: kilowatt hour | F10: ecoinvent 3.10 cutoff | G10: technosphere | J10: (4,5,5,1,2)
A11: market for diesel, burned in building machine | B11: diesel, burned in building machine | C11: GLO | D11: 0.064285714 | E11: megajoule | F11: ecoinvent 3.10 cutoff | G11: technosphere | J11: (4,5,5,1,2)
A12: market for explosive, tovex | B12: explosive, tovex | C12: GLO | D12: 0.15928571 | E12: kilogram | F12: ecoinvent 3.10 cutoff | G12: technosphere | J12: (4,5,5,1,2)
A13: market for non-sulfidic tailing, off-site | B13: non-sulfidic tailing, off-site | C13: GLO | D13: -2.1428571e-05 | E13: kilogram | F13: ecoinvent 3.10 cutoff | G13: technosphere | J13: (4,5,5,1,2)
A14: Water, unspecified natural origin | D14: 0.000325 | E14: cubic meter | F14: biosphere3 | G14: biosphere | H14: natural resource::in ground | J14: (4,5,5,1,2)
A15: Silicon | D15: 2.8714286 | E15: kilogram | F15: biosphere3 | G15: biosphere | H15: natural resource::in ground | J15: (4,5,5,1,2)
A16: Carbon monoxide, fossil | D16: 0.0011928571 | E16: kilogram | F16: biosphere3 | G16: biosphere | H16: air | J16: (4,5,5,1,2)
A17: Sulfur dioxide | D17: 0.0027285714 | E17: kilogram | F17: biosphere3 | G17: biosphere | H17: air | J17: (4,5,5,1,2)
A18: Hydrogen sulfide | D18: 0.0013642857 | E18: kilogram | F18: biosphere3 | G18: biosphere | H18: air | J18: (4,5,5,1,2)
A19: Ammonia | D19: 0.00072857143 | E19: kilogram | F19: biosphere3 | G19: biosphere | H19: air | J19: (4,5,5,1,2)
A20: Particulate Matter, > 2.5 um and < 10um | D20: 5e-05 | E20: kilogram | F20: biosphere3 | G20: biosphere | H20: air | J20: (4,5,5,1,2)
A22: Activity | B22: [P+R] Metal grade silicon (MG-Si) production
A23: reference product | B23: MG-Si
A24: location | B24: CN
A25: amount | B25: 1
A26: unit | B26: kilogram
A27: comment | B27: n/a
A28: Exchanges
A29: name | B29: reference product | C29: location | D29: amount | E29: unit | F29: database | G29: type | H29: categories | I29: uncertainty type | J29: pedigree | K29: loc | L29: scale | M29: minimum | N29: maximum
A30: =B22 -> [P+R] Metal grade silicon (MG-Si) production | B30: =B23 -> MG-Si | C30: =B24 -> CN | D30: 1 | E30: kilogram | F30: =F9 -> Silicon | G30: production
A31: market group for electricity, medium voltage | B31: electricity, medium voltage | C31: CN | D31: 12.992857 | E31: kilowatt hour | F31: ecoinvent 3.10 cutoff | G31: technosphere | J31: (4,5,5,1,2)
A32: market for petroleum coke | B32: petroleum coke | C32: GLO | D32: 0.54285714 | E32: kilogram | F32: ecoinvent 3.10 cutoff | G32: technosphere | J32: (4,5,5,1,2)
A33: market for wood chips, wet, measured as dry mass | B33: wood chips, wet, measured as dry mass | C33: RoW | D33: 0.32857143 | E33: kilogram | F33: ecoinvent 3.10 cutoff | G33: technosphere | J33: (4,5,5,1,2)
A34: market for graphite | B34: graphite | C34: GLO | D34: 0.12857143 | E34: kilogram | F34: ecoinvent 3.10 cutoff | G34: technosphere | J34: (4,5,5,1,2)
A35: market for petroleum coke | B35: petroleum coke | C35: GLO | D35: 0.12142857 | E35: kilogram | F35: ecoinvent 3.10 cutoff | G35: technosphere | J35: (4,5,5,1,2)
A36: market for anode, graphite, for Li-ion battery | B36: anode, graphite, for Li-ion battery | C36: CN | D36: 0.040714286 | E36: kilogram | F36: ecoinvent 3.10 cutoff | G36: technosphere | J36: (4,5,5,1,2)
A37: market for charcoal | B37: charcoal | C37: GLO | D37: 0.19285714 | E37: kilogram | F37: ecoinvent 3.10 cutoff | G37: technosphere | J37: (4,5,5,1,2)
A38: market for hard coal | B38: hard coal | C38: CN | D38: 2.1428571 | E38: kilogram | F38: ecoinvent 3.10 cutoff | G38: technosphere | J38: (4,5,5,1,2)
A39: market for coal tar | B39: coal tar | C39: GLO | D39: 0.034285714 | E39: kilogram | F39: ecoinvent 3.10 cutoff | G39: technosphere | J39: (4,5,5,1,2)
A40: market for coal tar | B40: coal tar | C40: GLO | D40: 0.56428571 | E40: kilogram | F40: ecoinvent 3.10 cutoff | G40: technosphere | J40: (4,5,5,1,2)
A41: market for wastewater, average | B41: wastewater, average | C41: RoW | D41: -0.00217735 | E41: cubic meter | F41: ecoinvent 3.10 cutoff | G41: technosphere | J41: (4,5,5,1,2)
...

Sheet PR2_MG-Si_NO_ThermalReduction
A1: Activity | B1: [P+R] Metal grade silicon (MG-Si) production
A2: reference product | B2: MG-Si
A3: location | B3: NO
A4: amount | B4: 1
A5: unit | B5: kilogram
A6: comment | B6: n/a
A7: Exchanges
A8: name | B8: reference product | C8: location | D8: amount | E8: unit | F8: database | G8: type | H8: categories | I8: uncertainty type | J8: pedigree | K8: loc | L8: scale | M8: minimum | N8: maximum
A9: =B1 -> [P+R] Metal grade silicon (MG-Si) production | B9: =B2 -> MG-Si | C9: =B3 -> NO | D9: 1 | E9: kilogram | F9: ='MG-Si_Market_GLO'!B1 -> Silicon | G9: production
A10: market for electricity, medium voltage | B10: electricity, medium voltage | C10: NO | D10: 11 | E10: kilowatt hour | F10: ecoinvent 3.10 cutoff | G10: technosphere | J10: (4,2.0,4.0,1.0,1.0)
A11: market for wood chips, wet, measured as dry mass | B11: wood chips, wet, measured as dry mass | C11: Europe without Switzerland | D11: 0.00325 | E11: kilogram | F11: ecoinvent 3.10 cutoff | G11: technosphere | J11: (4,2.0,4.0,1.0,1.0)
A12: market for coke | B12: coke | C12: RoW | D12: 23.1 | E12: megajoule | F12: ecoinvent 3.10 cutoff | G12: technosphere | J12: (4,2.0,4.0,1.0,1.0)
A13: market for graphite | B13: graphite | C13: GLO | D13: 0.1 | E13: kilogram | F13: ecoinvent 3.10 cutoff | G13: technosphere | J13: (4,2.0,4.0,1.0,1.0)
A14: market for charcoal | B14: charcoal | C14: GLO | D14: 0.17 | E14: kilogram | F14: ecoinvent 3.10 cutoff | G14: technosphere | J14: (4,2.0,4.0,1.0,1.0)
A15: market for petroleum coke | B15: petroleum coke | C15: GLO | D15: 0.5 | E15: kilogram | F15: ecoinvent 3.10 cutoff | G15: technosphere | J15: (4,2.0,4.0,1.0,1.0)
A16: market for silica sand | B16: silica sand | C16: GLO | D16: 2.7 | E16: kilogram | F16: ecoinvent 3.10 cutoff | G16: technosphere | J16: (4,2.0,4.0,1.0,1.0)
A17: market for oxygen, liquid | B17: oxygen, liquid | C17: RER | D17: 0.02 | E17: kilogram | F17: ecoinvent 3.10 cutoff | G17: technosphere | J17: (4,4.0,5.0,3.0,1.0)
A18: market for slag from metallurgical grade silicon production | B18: slag from metallurgical grade silicon production | C18: RoW | D18: -0.025 | E18: kilogram | F18: ecoinvent 3.10 cutoff | G18: technosphere | J18: (4,2.0,4.0,1.0,1.0)
A19: market for silicone factory | B19: silicone factory | C19: GLO | D19: 1e-11 | E19: unit | F19: ecoinvent 3.10 cutoff | G19: technosphere | J19: (4,2.0,4.0,1.0,3.0)
A20: market for transport, freight, sea, container ship | B20: transport, freight, sea, container ship | C20: GLO | D20: 2.55 | E20: ton kilometer | F20: ecoinvent 3.10 cutoff | G20: technosphere | J20: (4,5,4,1,3)
A21: market for transport, freight, lorry, unspecified | B21: transport, freight, lorry, unspecified | C21: RER | D21: 0.156 | E21: ton kilometer | F21: ecoinvent 3.10 cutoff | G21: technosphere | J21: (4,5,4,1,3)
A22: market for transport, freight train | B22: transport, freight train | C22: Europe without Switzerland | D22: 0.069 | E22: ton kilometer | F22: ecoinvent 3.10 cutoff | G22: technosphere | J22: (4,5,4,1,3)
A23: Heat, waste | D23: 71.3 | E23: megajoule | F23: biosphere3 | G23: biosphere | H23: air::low population density, long-term | J23: (4,2.0,4.0,1.0,1.0)
A24: Arsenic ion | D24: 9.42e-09 | E24: kilogram | F24: biosphere3 | G24: biosphere | H24: air::low population density, long-term | J24: (4,4.0,5.0,3.0,1.0)
A25: Aluminium III | D25: 1.55e-06 | E25: kilogram | F25: biosphere3 | G25: biosphere | H25: air::low population density, long-term | J25: (4,4.0,5.0,3.0,1.0)
A26: Antimony ion | D26: 7.85e-09 | E26: kilogram | F26: biosphere3 | G26: biosphere | H26: air::low population density, long-term | J26: (4,4.0,5.0,3.0,1.0)
A27: Boron | D27: 2.79e-07 | E27: kilogram | F27: biosphere3 | G27: biosphere | H27: air::low population density, long-term | J27: (4,4.0,5.0,3.0,1.0)
A28: Cadmium II | D28: 3.14e-10 | E28: kilogram | F28: biosphere3 | G28: biosphere | H28: air::low population density, long-term | J28: (4,4.0,5.0,3.0,1.0)
A29: Calcium II | D29: 7.75e-07 | E29: kilogram | F29: biosphere3 | G29: biosphere | H29: air::low population density, long-term | J29: (4,4.0,5.0,3.0,1.0)
A30: Carbon monoxide, non-fossil | D30: 0.00062 | E30: kilogram | F30: biosphere3 | G30: biosphere | H30: air::low population density, long-term | J30: (4,2.0,4.0,1.0,1.0)
A31: Carbon monoxide, fossil | D31: 0.00138 | E31: kilogram | F31: biosphere3 | G31: biosphere | H31: air::low population density, long-term | J31: (4,2.0,4.0,1.0,1.0)
A32: Carbon dioxide, non-fossil | D32: 1.61 | E32: kilogram | F32: biosphere3 | G32: biosphere | H32: air::low population density, long-term | J32: (4,4.0,5.0,3.0,1.0)
A33: Carbon dioxide, fossil | D33: 3.58 | E33: kilogram | F33: biosphere3 | G33: biosphere | H33: air::low population density, long-term | J33: (4,4.0,5.0,3.0,1.0)
A34: Chromium III | D34: 7.85e-09 | E34: kilogram | F34: biosphere3 | G34: biosphere | H34: air::low population density, long-term | J34: (4,4.0,5.0,3.0,1.0)
... A50: Tin ion | D50: 7.85e-09 | E50: kilogram | F50: biosphere3 | G50: biosphere | H50: air::low population density, long-term | J50: (4,4.0,5.0,3.0,1.0)
A52: Activity | B52: Metal-grade Si production in Norway
A53: reference product | B53: MG-Si
A54: location | B54: NO
A55: amount | B55: 1
A56: unit | B56: kilogram
...

Sheet PR3_Si_US_Drying
A1: Activity | B1: [M+C] Silica sand production (High-quality)
A2: reference product | B2: Silica sand
A3: location | B3: US
A4: amount | B4: 1
A5: unit | B5: kilogram
A6: comment | B6: n/a
A7: Exchanges
A8: name | B8: reference product | C8: location | D8: amount | E8: unit | F8: database | G8: type | H8: categories | I8: uncertainty type | J8: pedigree | K8: loc | L8: scale | M8: minimum | N8: maximum
A9: =B1 -> [M+C] Silica sand production (High-quality) | B9: =B2 -> Silica sand | C9: =B3 -> US | D9: 1 | E9: kilogram | F9: ='MG-Si_Market_GLO'!B1 -> Silicon | G9: production
A10: market for lubricating oil | B10: lubricating oil | C10: RoW | D10: 1.2750838e-06 | E10: kilogram | F10: ecoinvent 3.10 cutoff | G10: technosphere | J10: (4,4,5,1,2)
A11: market for steel, low-alloyed, hot rolled | B11: steel, low-alloyed, hot rolled | C11: GLO | D11: 1.3519782e-05 | E11: kilogram | F11: ecoinvent 3.10 cutoff | G11: technosphere | J11: (4,4,5,1,2)
A12: market for mine infrastructure, open cast, non-ferrous metal | B12: mine infrastructure, open cast, non-ferrous metal | C12: GLO | D12: 4.9424368e-11 | E12: unit | F12: ecoinvent 3.10 cutoff | G12: technosphere | J12: (4,4,5,1,2)
A13: market for light fuel oil | B13: light fuel oil | C13: RoW | D13: 5.6807742e-05 | E13: kilogram | F13: ecoinvent 3.10 cutoff | G13: technosphere | J13: (4,4,5,1,2)
A14: market for diesel, burned in building machine | B14: diesel, burned in building machine | C14: GLO | D14: 0.015400939 | E14: megajoule | F14: ecoinvent 3.10 cutoff | G14: technosphere | J14: (4,4,5,1,2)
A15: market for synthetic rubber | B15: synthetic rubber | C15: GLO | D15: 2.0800413e-06 | E15: kilogram | F15: ecoinvent 3.10 cutoff | G15: technosphere | J15: (4,4,5,1,2)
A16: market group for electricity, medium voltage | B16: electricity, medium voltage | C16: US | D16: 0.0028288 | E16: kilowatt hour | F16: ecoinvent 3.10 cutoff | G16: technosphere | J16: (4,4,5,1,2)
A17: market group for transport, freight, light commercial vehicle | B17: transport, freight, light commercial vehicle | C17: GLO | D17: 1.6120023e-05 | E17: ton kilometer | F17: ecoinvent 3.10 cutoff | G17: technosphere | J17: (4,4,5,1,2)
A18: market for transport, freight, lorry 7.5-16 metric ton, EURO5 | B18: transport, freight, lorry 7.5-16 metric ton, EURO5 | C18: RoW | D18: 9.1418859e-07 | E18: ton kilometer | F18: ecoinvent 3.10 cutoff | G18: technosphere | J18: (4,4,5,1,2)
A19: market for transport, freight, lorry 16-32 metric ton, EURO5 | B19: transport, freight, lorry 16-32 metric ton, EURO5 | C19: RoW | D19: 1.7887944e-05 | E19: ton kilometer | F19: ecoinvent 3.10 cutoff | G19: technosphere | J19: (4,4,5,1,2)
A20: market for building, hall | B20: building, hall | C20: GLO | D20: 5.2311963e-07 | E20: square meter | F20: ecoinvent 3.10 cutoff | G20: technosphere | J20: (4,4,5,1,2)
A21: market for conveyor belt | B21: conveyor belt | C21: GLO | D21: 9.8956886e-08 | E21: meter | F21: ecoinvent 3.10 cutoff | G21: technosphere | J21: (4,4,5,1,2)
... A23: market for heavy fuel oil, burned in refinery furnace | B23: heavy fuel oil, burned in refinery furnace | C23: GLO | D23: 0.2 | E23: megajoule | F23: ecoinvent 3.10 cutoff | G23: technosphere | J23: (4,4,5,1,2)
A24: Sand, unspecified | D24: 1.081496 | E24: kilogram | F24: biosphere3 | G24: biosphere | H24: natural resource::in ground | J24: (4,4,5,1,2)
A25: Water, unspecified natural origin | D25: 0.010503998 | E25: cubic meter | F25: biosphere3 | G25: biosphere | H25: natural resource::in ground | J25: (4,4,5,1,2)
A26: Water, unspecified natural origin | D26: 0.0014352001 | E26: cubic meter | F26: biosphere3 | G26: biosphere | H26: natural resource::in ground | J26: (4,4,5,1,2)
A28: Activity | B28: Quartz mining and high-quality silica sand production in the US
A29: reference product | B29: Silica sand
A30: location | B30: US
A31: amount | B31: 1
A32: unit | B32: kilogram
A33: comment | B33: An ecoinvent activity is here included to model the downstream silica sand refining to produce metal grade silicon. This ecoinvent activity shall be modified by removing the 'silica sand' input (so as to avoid double counting).
A34: Exchanges
A35: name | B35: reference product | C35: location | D35: amount | E35: unit | F35: database | G35: type | H35: categories | I35: uncertainty type | J35: pedigree | K35: loc | L35: scale | M35: minimum | N35: maximum
A36: =B28 -> Quartz mining and high-quality silica sand production in the US | B36: =B29 -> Silica sand | C36: =B30 -> US | D36: 1 | E36: kilogram | F36: =F9 -> Silicon | G36: production
A37: silicon production, metallurgical grade | B37: silicon, metallurgical grade | C37: RoW | D37: 1 | E37: kilogram | F37: ecoinvent 3.10 cutoff | G37: technosphere
A38: =A9 -> [M+C] Silica sand production (High-quality) | B38: =B9 -> Silica sand | C38: =C9 -> US | D38: 2.8714286 | E38: =E9 -> kilogram | F38: =F9 -> Silicon | G38: technosphere

Sheet PR4_Si_US_MagneticSeparation
A1: Activity | B1: [M+C] Silica sand production - Magnetic separation
A2: reference product | B2: Silica sand
A3: location | B3: US
A4: amount | B4: 1
A5: unit | B5: kilogram
A6: comment | B6: n/a
A7: Exchanges
A8: name | B8: reference product | C8: location | D8: amount | E8: unit | F8: database | G8: type | H8: categories | I8: uncertainty type | J8: pedigree | K8: loc | L8: scale | M8: minimum | N8: maximum
A9: =B1 -> [M+C] Silica sand production - Magnetic separation | B9: =B2 -> Silica sand | C9: =B3 -> US | D9: 1 | E9: kilogram | F9: ='MG-Si_Market_GLO'!B1 -> Silicon | G9: production
A10: market for lubricating oil | B10: lubricating oil | C10: RoW | D10: 4.2890595e-05 | E10: kilogram | F10: ecoinvent 3.10 cutoff | G10: technosphere | J10: (4,4,5,1,2)
A11: market for light fuel oil | B11: light fuel oil | C11: RoW | D11: 2.1445297e-05 | E11: kilogram | F11: ecoinvent 3.10 cutoff | G11: technosphere | J11: (4,4,5,1,2)
A12: market for lubricating oil | B12: lubricating oil | C12: RoW | D12: 4.8227805e-06 | E12: kilogram | F12: ecoinvent 3.10 cutoff | G12: technosphere | J12: (4,4,5,1,2)
A13: market for synthetic rubber | B13: synthetic rubber | C13: GLO | D13: 7.0412595e-06 | E13: kilogram | F13: ecoinvent 3.10 cutoff | G13: technosphere | J13: (4,4,5,1,2)
A14: market for diesel, burned in building machine | B14: diesel, burned in building machine | C14: GLO | D14: 0.013124233 | E14: megajoule | F14: ecoinvent 3.10 cutoff | G14: technosphere | J14: (4,4,5,1,2)
A15: market for building, hall | B15: building, hall | C15: GLO | D15: 7.7791449e-07 | E15: square meter | F15: ecoinvent 3.10 cutoff | G15: technosphere | J15: (4,4,5,1,2)
A16: market group for electricity, low voltage | B16: electricity, low voltage | C16: US | D16: 0.00018496971 | E16: kilowatt hour | F16: ecoinvent 3.10 cutoff | G16: technosphere | J16: (4,4,5,1,2)
A17: market for transport, freight, lorry 3.5-7.5 metric ton, EURO5 | B17: transport, freight, lorry 3.5-7.5 metric ton, EURO5 | C17: RoW | D17: 0.0096503838 | E17: ton kilometer | F17: ecoinvent 3.10 cutoff | G17: technosphere | J17: (4,4,5,1,2)
A18: market group for transport, freight, light commercial vehicle | B18: transport, freight, light commercial vehicle | C18: GLO | D18: 2.3971309e-05 | E18: ton kilometer | F18: ecoinvent 3.10 cutoff | G18: technosphere | J18: (4,4,5,1,2)
A19: market group for electricity, medium voltage | B19: electricity, medium voltage | C19: US | D19: 0.00015172467 | E19: kilowatt hour | F19: ecoinvent 3.10 cutoff | G19: technosphere | J19: (4,4,5,1,2)
A20: market group for electricity, medium voltage | B20: electricity, medium voltage | C20: US | D20: 0.00022758701 | E20: kilowatt hour | F20: ecoinvent 3.10 cutoff | G20: technosphere | J20: (4,4,5,1,2)
A21: market group for electricity, medium voltage | B21: electricity, medium voltage | C21: US | D21: 0.00033683907 | E21: kilowatt hour | F21: ecoinvent 3.10 cutoff | G21: technosphere | J21: (4,4,5,1,2)
... A44: market for diesel, burned in building machine | B44: diesel, burned in building machine | C44: GLO | D44: 2.8936683e-07 | E44: megajoule | F44: ecoinvent 3.10 cutoff | G44: technosphere | J44: (4,4,5,1,2)
A45: Sand, unspecified | D45: 1.6075935 | E45: kilogram | F45: biosphere3 | G45: biosphere | H45: natural resource::in ground | J45: (4,4,5,1,2)
A46: Transformation, from unspecified | D46: 7.3949301e-11 | E46: square meter | F46: biosphere3 | G46: biosphere | H46: natural resource::land | J46: (4,4,5,1,2)
A47: Transformation, to mineral extraction site | D47: 7.3949301e-11 | E47: square meter | F47: biosphere3 | G47: biosphere | H47: natural resource::land | J47: (4,4,5,1,2)
A48: Water, unspecified natural origin | D48: 0.0052630361 | E48: cubic meter | F48: biosphere3 | G48: biosphere | H48: natural resource::in ground | J48: (4,4,5,1,2)
A49: Water, unspecified natural origin | D49: 0.0012223819 | E49: cubic meter | F49: biosphere3 | G49: biosphere | H49: natural resource::in ground | J49: (4,4,5,1,2)
A50: Water, unspecified natural origin | D50: 1.3310874e-07 | E50: cubic meter | F50: biosphere3 | G50: biosphere | H50: natural resource::in ground | J50: (4,4,5,1,2)
A51: Water, unspecified natural origin | D51: 3.3772967e-05 | E51: cubic meter | F51: biosphere3 | G51: biosphere | H51: natural resource::in ground | J51: (4,4,5,1,2)
A53: Activity | B53: Quartz mining and silica sand production in the US through magnetic separation
A54: reference product | B54: Silica sand
A55: location | B55: US
A56: amount | B56: 1
A57: unit | B57: kilogram
A58: comment | B58: An ecoinvent activity is here included to model the downstream silica sand refining to produce metal grade silicon. This ecoinvent activity shall be modified by removing the 'silica sand' input (so as to avoid double counting).
A59: Exchanges
A60: name | B60: reference product | C60: location | D60: amount | E60: unit | F60: database | G60: type | H60: categories | I60: uncertainty type | J60: pedigree | K60: loc | L60: scale | M60: minimum | N60: maximum
A61: =B53 -> Quartz mining and silica sand production in the US through magnetic separation | B61: =B54 -> Silica sand | C61: =B55 -> US | D61: 1 | E61: kilogram | F61: =F9 -> Silicon | G61: production
A62: silicon production, metallurgical grade | B62: silicon, metallurgical grade | C62: RoW | D62: 1 | E62: kilogram | F62: ecoinvent 3.10 cutoff | G62: technosphere
A63: =A9 -> [M+C] Silica sand production - Magnetic separation | B63: =B9 -> Silica sand | C63: =C9 -> US | D63: 2.8714286 | E63: =E9 -> kilogram | F63: =F9 -> Silicon | G63: technosphere

Sheet PR5_Si_US_Flotation
A1: Activity | B1: [M+C] Silica sand production - Flotation
A2: reference product | B2: Silica sand
A3: location | B3: US
A4: amount | B4: 1
A5: unit | B5: kilogram
A6: comment | B6: n/a
A7: Exchanges
A8: name | B8: reference product | C8: location | D8: amount | E8: unit | F8: database | G8: type | H8: categories | I8: uncertainty type | J8: pedigree | K8: loc | L8: scale | M8: minimum | N8: maximum
A9: =B1 -> [M+C] Silica sand production - Flotation | B9: =B2 -> Silica sand | C9: =B3 -> US | D9: 1 | E9: kilogram | F9: ='MG-Si_Market_GLO'!B1 -> Silicon | G9: production
A10: market for lubricating oil | B10: lubricating oil | C10: RoW | D10: 4.4913806e-05 | E10: kilogram | F10: ecoinvent 3.10 cutoff | G10: technosphere | J10: (4,4,5,1,2)
A11: market for light fuel oil | B11: light fuel oil | C11: RoW | D11: 2.2456903e-05 | E11: kilogram | F11: ecoinvent 3.10 cutoff | G11: technosphere | J11: (4,4,5,1,2)
A12: market for lubricating oil | B12: lubricating oil | C12: RoW | D12: 5.050278e-06 | E12: kilogram | F12: ecoinvent 3.10 cutoff | G12: technosphere | J12: (4,4,5,1,2)
A13: market for synthetic rubber | B13: synthetic rubber | C13: GLO | D13: 7.3734059e-06 | E13: kilogram | F13: ecoinvent 3.10 cutoff | G13: technosphere | J13: (4,4,5,1,2)
A14: market for diesel, burned in building machine | B14: diesel, burned in building machine | C14: GLO | D14: 0.013743322 | E14: megajoule | F14: ecoinvent 3.10 cutoff | G14: technosphere | J14: (4,4,5,1,2)
A15: market for building, hall | B15: building, hall | C15: GLO | D15: 8.1460985e-07 | E15: square meter | F15: ecoinvent 3.10 cutoff | G15: technosphere | J15: (4,4,5,1,2)
A16: market group for electricity, low voltage | B16: electricity, low voltage | C16: US | D16: 0.000193695 | E16: kilowatt hour | F16: ecoinvent 3.10 cutoff | G16: technosphere | J16: (4,4,5,1,2)
A17: market for transport, freight, lorry 3.5-7.5 metric ton, EURO5 | B17: transport, freight, lorry 3.5-7.5 metric ton, EURO5 | C17: RoW | D17: 0.010105606 | E17: ton kilometer | F17: ecoinvent 3.10 cutoff | G17: technosphere | J17: (4,4,5,1,2)
A18: market group for transport, freight, light commercial vehicle | B18: transport, freight, light commercial vehicle | C18: GLO | D18: 2.510207e-05 | E18: ton kilometer | F18: ecoinvent 3.10 cutoff | G18: technosphere | J18: (4,4,5,1,2)
A19: market group for electricity, medium voltage | B19: electricity, medium voltage | C19: US | D19: 0.00015888175 | E19: kilowatt hour | F19: ecoinvent 3.10 cutoff | G19: technosphere | J19: (4,4,5,1,2)
A20: market group for electricity, medium voltage | B20: electricity, medium voltage | C20: US | D20: 0.00023832262 | E20: kilowatt hour | F20: ecoinvent 3.10 cutoff | G20: technosphere | J20: (4,4,5,1,2)
A21: market group for electricity, medium voltage | B21: electricity, medium voltage | C21: US | D21: 0.00035272825 | E21: kilowatt hour | F21: ecoinvent 3.10 cutoff | G21: technosphere | J21: (4,4,5,1,2)
... A47: market group for electricity, medium voltage | B47: electricity, medium voltage | C47: US | D47: 0.00013804885 | E47: kilowatt hour | F47: ecoinvent 3.10 cutoff | G47: technosphere | J47: (4,4,5,1,2)
A48: Sand, unspecified | D48: 1.683426 | E48: kilogram | F48: biosphere3 | G48: biosphere | H48: natural resource::in ground | J48: (4,4,5,1,2)
A49: Transformation, from unspecified | D49: 7.7437597e-11 | E49: square meter | F49: biosphere3 | G49: biosphere | H49: natural resource::land | J49: (4,4,5,1,2)
A50: Transformation, to mineral extraction site | D50: 7.7437597e-11 | E50: square meter | F50: biosphere3 | G50: biosphere | H50: natural resource::land | J50: (4,4,5,1,2)
A51: Water, unspecified natural origin | D51: 0.0055113011 | E51: cubic meter | F51: biosphere3 | G51: biosphere | H51: natural resource::in ground | J51: (4,4,5,1,2)
A52: Water, unspecified natural origin | D52: 0.0012800435 | E52: cubic meter | F52: biosphere3 | G52: biosphere | H52: natural resource::in ground | J52: (4,4,5,1,2)
A53: Water, unspecified natural origin | D53: 7.2718954e-07 | E53: cubic meter | F53: biosphere3 | G53: biosphere | H53: natural resource::in ground | J53: (4,4,5,1,2)
A54: Water, unspecified natural origin | D54: 0.002814621 | E54: cubic meter | F54: biosphere3 | G54: biosphere | H54: natural resource::in ground | J54: (4,4,5,1,2)
A55: Water, unspecified natural origin | D55: 0.0026738865 | E55: cubic meter | F55: biosphere3 | G55: biosphere | H55: natural resource::in ground | J55: (4,4,5,1,2)
A56: Water, unspecified natural origin | D56: 0.0024067437 | E56: cubic meter | F56: biosphere3 | G56: biosphere | H56: natural resource::in ground | J56: (4,4,5,1,2)
A58: Activity | B58: Quartz mining and silica sand production in the US through flotation separation
A59: reference product | B59: Silica sand
A60: location | B60: US
A61: amount | B61: 1
A62: unit | B62: kilogram
A63: comment | B63: An ecoinvent activity is here included to model the downstream silica sand refining to produce metal grade silicon. This ecoinvent activity shall be modified by removing the 'silica sand' input (so as to avoid double counting).
A64: Exchanges
A65: name | B65: reference product | C65: location | D65: amount | E65: unit | F65: database | G65: type | H65: categories | I65: uncertainty type | J65: pedigree | K65: loc | L65: scale | M65: minimum | N65: maximum
A66: =B58 -> Quartz mining and silica sand production in the US through flotation separation | B66: =B59 -> Silica sand | C66: =B60 -> US | D66: 1 | E66: kilogram | F66: =F9 -> Silicon | G66: production
...
