Workbook

Sheet Note
A1: skip
B2: Life cycle inventories of global metal and mineral supply chains: a comprehensive data review, analysis and processing Frédéric Laia*, Stéphanie Mullera, Audrey Philippea, Robert Istrateb, Brenda Miranda Xicotencatlb, Afsoon Mansouri Askic, Aina Mas Fonsd,a, Juliana Segura-Salazare, Jair Santillán Saldivara, Alexander Cimprichf, Stephen Northeyg, Lígia da Silva Limah, Lieselot Booneh, Ryosuke Yokoii, Kamrul Islami, Ioanna Paschalidouj, Felipe Cerdask,l, Victor Balboa-Espinozae, Anish Koyamparambathd, Diae Henniouia, Victoire Collignona, Aurélien Reysa, Gyslain Ngadi Sakatadim, Jo Dewulfh, Bernhard Steubingb, Christoph Helbigc, Gaétan Lefebvrea, Gian Andrea Blenginin,m, Valeria Supertio, Masaharu Motoshitai, Guido Sonnemannd, Kwame Awuah-Offeij, Steven B. Youngf, Shinsuke Murakamip, Antoine Beylota aBRGM, F-45060 Orléans, France bInstitute of Environmental Sciences (CML), Leiden University, Einsteinweg 2, 2333 CC Leiden, NL cEcological Resource Technology, University of Bayreuth, Universitätstr. 30, 95447 Bayreuth, Germany dUniv. Bordeaux, CNRS, Bordeaux INP, ISM, UMR 5255, F-33400 Talence, France eSustainable Minerals Institute, The University of Queensland, QLD, 4072, Australia fSchool of Environment, Enterprise and Development, University of Waterloo, 200 University Avenue West, Waterloo, Ontario N2L 3G1, Canada gUniversity of Technology Sydney, Institute for Sustainable Futures, Australia hSustainable Systems Engineering (STEN), Department of Green Chemistry and Technology, Faculty of Bioscience Engineering, Ghent University, Coupure Links 653, 9000 Ghent, Belgium iAIST, 305-8569 Tsukuba, Japan jMining & Explosives Engineering, Missouri University of Science & Technology, Rolla, MO, USA 65409 kInstitute for Sustainable Energy Systems (INSYS), Technical University of Applied Sciences Würzburg-Schweinfurt (THWS), Ignaz-Schön-Straße 11, Schweinfurt, Germany lFraunhofer Institute for Surface Engineering and Thin Films IST, Riedenkamp 2, Braunschweig 38108, Germany mDepartment of Environment, Land and Infrastructure Engineering, Politecnico di Torino, Corso Duca degli Abruzzi, 24, 10129 Torino, Italy nUniversity of Turin, Earth Sciences Department (DST), Via Valperga Caluso, 35 – 10125 Torino, Italy oecoinvent association, Technopark, Technoparkstrasse 1, 8005 Zürich, Switzerland pGraduate School of Engineering, The University of Tokyo, Tokyo 113-8656, Japan *Corresponding author: f.lai@brgm.fr This file provides all LCI datasets developed for Magnesium (Mg), with distinguishing its global market and each individual production route.
B33: Sheet | C33: Corresponding route
B34: Mg_Market_GLO | C34: Mg global market
B35: PR1_Mg_CN_Dolomite_Pidgeon | C35: Dolomite ore mining and Mg production in China through Pidgeon process
B36: PR2_Mg_BR_Dolomite_Bolzano | C36: Dolomite ore mining and Mg production in Brazil through Bolzano process

Sheet Mg_Market_GLO
A1: database | B1: Magnesium
A3: Activity | B3: Magnesium (Mg) global market
A4: reference product | B4: Refined Mg
A5: location | B5: GLO
A6: amount | B6: 1
A7: unit | B7: kilogram
A8: comment | B8: n/a
A9: Exchanges
A10: name | B10: reference product | C10: location | D10: amount | E10: unit | F10: database | G10: type | H10: categories | I10: uncertainty type | J10: pedigree | K10: loc | L10: scale | M10: minimum | N10: maximum
A11: =B3 -> Magnesium (Mg) global market | B11: =B4 -> Refined Mg | C11: =B5 -> GLO | D11: 1 | E11: =B7 -> kilogram | F11: =B1 -> Magnesium | G11: production
A12: =PR1_Mg_CN_Dolomite_Pidgeon!A55 -> Dolomite ore mining and Mg production in China through Pidgeon process | B12: =PR1_Mg_CN_Dolomite_Pidgeon!B55 -> Refined Mg | C12: =PR1_Mg_CN_Dolomite_Pidgeon!C55 -> CN | D12: 0.98051948 | E12: =PR1_Mg_CN_Dolomite_Pidgeon!E55 -> kilogram | F12: =PR1_Mg_CN_Dolomite_Pidgeon!F55 -> Magnesium | G12: technosphere
A13: =PR2_Mg_BR_Dolomite_Bolzano!A46 -> Dolomite ore mining and Mg production in Brazil through Bolzano process | B13: =PR2_Mg_BR_Dolomite_Bolzano!B46 -> Refined Mg | C13: =PR2_Mg_BR_Dolomite_Bolzano!C46 -> BR | D13: 0.019480519 | E13: =PR2_Mg_BR_Dolomite_Bolzano!E46 -> kilogram | F13: =PR2_Mg_BR_Dolomite_Bolzano!F46 -> Magnesium | G13: technosphere

Sheet PR1_Mg_CN_Dolomite_Pidgeon
A1: Activity | B1: [M+C] Magnesium (Mg) ore mining and concentration (China)
A2: reference product | B2: Dolomite ore
A3: location | B3: CN
A4: amount | B4: 1
A5: unit | B5: kilogram
A6: comment | B6: n/a
A7: Exchanges
A8: name | B8: reference product | C8: location | D8: amount | E8: unit | F8: database | G8: type | H8: categories | I8: uncertainty type | J8: pedigree | K8: loc | L8: scale | M8: minimum | N8: maximum
A9: =B1 -> [M+C] Magnesium (Mg) ore mining and concentration (China) | B9: =B2 -> Dolomite ore | C9: =B3 -> CN | D9: 1 | E9: kilogram | F9: =Mg_Market_GLO!B1 -> Magnesium | G9: production
A10: market group for electricity, medium voltage | B10: electricity, medium voltage | C10: CN | D10: 0.033916379 | E10: kilowatt hour | F10: ecoinvent 3.10 cutoff | G10: technosphere | J10: (4,5,5,2,2)
A11: market for industrial machine, heavy, unspecified | B11: industrial machine, heavy, unspecified | C11: RoW | D11: 1.4655172e-05 | E11: kilogram | F11: ecoinvent 3.10 cutoff | G11: technosphere | J11: (4,5,5,2,2)
A12: market for explosive, tovex | B12: explosive, tovex | C12: GLO | D12: 0.0025 | E12: kilogram | F12: ecoinvent 3.10 cutoff | G12: technosphere | J12: (4,5,5,2,2)
A13: diesel, burned in building machine | B13: diesel, burned in building machine | C13: GLO | D13: 0.021956897 | E13: megajoule | F13: ecoinvent 3.10 cutoff | G13: technosphere | J13: (4,5,5,2,2)
A14: market for industrial machine, heavy, unspecified | B14: industrial machine, heavy, unspecified | C14: RoW | D14: 0.00071724138 | E14: kilogram | F14: ecoinvent 3.10 cutoff | G14: technosphere | J14: (4,5,5,2,2)
A15: Dolomite | D15: 1 | E15: kilogram | F15: biosphere3 | G15: biosphere | H15: natural resource::in ground | J15: (4,5,5,2,2)
A17: Activity | B17: [P+R] Refined Mg production - Pidgeon process
A18: reference product | B18: Refined Mg
A19: location | B19: CN
A20: amount | B20: 1
A21: unit | B21: kilogram
A22: comment | B22: n/a
A23: Exchanges
A24: name | B24: reference product | C24: location | D24: amount | E24: unit | F24: database | G24: type | H24: categories | I24: uncertainty type | J24: pedigree | K24: loc | L24: scale | M24: minimum | N24: maximum
A25: =B17 -> [P+R] Refined Mg production - Pidgeon process | B25: =B18 -> Refined Mg | C25: =B19 -> CN | D25: 1 | E25: kilogram | F25: =F9 -> Magnesium | G25: production
A26: market for coal gas | B26: coal gas | C26: GLO | D26: 33150 | E26: megajoule | F26: ecoinvent 3.10 cutoff | G26: technosphere | J26: (2,2,2,2,1)
A27: market for coal gas | B27: coal gas | C27: GLO | D27: 147900 | E27: megajoule | F27: ecoinvent 3.10 cutoff | G27: technosphere | J27: (2,2,2,2,1)
A28: market for coal gas | B28: coal gas | C28: GLO | D28: 122910 | E28: megajoule | F28: ecoinvent 3.10 cutoff | G28: technosphere | J28: (2,2,2,2,1)
A29: market for hard coal briquettes | B29: hard coal briquettes | C29: RoW | D29: 42 | E29: megajoule | F29: ecoinvent 3.10 cutoff | G29: technosphere | J29: (2,2,2,2,1)
A30: market group for electricity, medium voltage | B30: electricity, medium voltage | C30: CN | D30: 0.3 | E30: kilowatt hour | F30: ecoinvent 3.10 cutoff | G30: technosphere | J30: (2,2,2,2,1)
A31: market for ferrosilicon | B31: ferrosilicon | C31: GLO | D31: 1.05 | E31: kilogram | F31: ecoinvent 3.10 cutoff | G31: technosphere | J31: (2,2,4,2,1)
A32: market for calcium chloride | B32: calcium chloride | C32: RoW | D32: 0.13 | E32: kilogram | F32: ecoinvent 3.10 cutoff | G32: technosphere | J32: (2,2,4,2,1)
A33: market group for electricity, medium voltage | B33: electricity, medium voltage | C33: CN | D33: 0.22 | E33: kilowatt hour | F33: ecoinvent 3.10 cutoff | G33: technosphere | J33: (2,2,2,2,1)
A34: market for coal gas | B34: coal gas | C34: GLO | D34: 76500 | E34: megajoule | F34: ecoinvent 3.10 cutoff | G34: technosphere | J34: (2,2,2,2,1)
A35: market for coal gas | B35: coal gas | C35: GLO | D35: 165750 | E35: megajoule | F35: ecoinvent 3.10 cutoff | G35: technosphere | J35: (2,2,2,2,1)
A36: market for coal gas | B36: coal gas | C36: GLO | D36: 197880 | E36: megajoule | F36: ecoinvent 3.10 cutoff | G36: technosphere | J36: (2,2,2,2,1)
A37: market for natural gas, high pressure | B37: natural gas, high pressure | C37: CN | D37: 1.2 | E37: cubic meter | F37: ecoinvent 3.10 cutoff | G37: technosphere | J37: (2,2,2,2,1)
... A45: market for sulfur | B45: sulfur | C45: GLO | D45: 0.003 | E45: kilogram | F45: ecoinvent 3.10 cutoff | G45: technosphere | J45: (2,2,4,2,1)
A47: Activity | B47: Dolomite ore mining and Mg production in China through Pidgeon process
A48: reference product | B48: Refined Mg
A49: location | B49: CN
...

Sheet PR2_Mg_BR_Dolomite_Bolzano
A1: Activity | B1: [M+C] Magnesium (Mg) ore mining and concentration (Brazil)
A2: reference product | B2: Dolomite ore
A3: location | B3: BR
A4: amount | B4: 1
A5: unit | B5: kilogram
A6: comment | B6: n/a
A7: Exchanges
A8: name | B8: reference product | C8: location | D8: amount | E8: unit | F8: database | G8: type | H8: categories | I8: uncertainty type | J8: pedigree | K8: loc | L8: scale | M8: minimum | N8: maximum
A9: =B1 -> [M+C] Magnesium (Mg) ore mining and concentration (Brazil) | B9: =B2 -> Dolomite ore | C9: =B3 -> BR | D9: 1 | E9: kilogram | F9: =Mg_Market_GLO!B1 -> Magnesium | G9: production
A10: market group for electricity, medium voltage | B10: electricity, medium voltage | C10: BR | D10: 0.033925118 | E10: kilowatt hour | F10: ecoinvent 3.10 cutoff | G10: technosphere | J10: (4,5,5,2,2)
A11: market for industrial machine, heavy, unspecified | B11: industrial machine, heavy, unspecified | C11: RoW | D11: 0.00023601896 | E11: kilogram | F11: ecoinvent 3.10 cutoff | G11: technosphere | J11: (4,5,5,2,2)
A12: market for explosive, tovex | B12: explosive, tovex | C12: GLO | D12: 0.0025004739 | E12: kilogram | F12: ecoinvent 3.10 cutoff | G12: technosphere | J12: (4,5,5,2,2)
A13: diesel, burned in building machine | B13: diesel, burned in building machine | C13: GLO | D13: 0.021924171 | E13: megajoule | F13: ecoinvent 3.10 cutoff | G13: technosphere | J13: (4,5,5,2,2)
A14: market for industrial machine, heavy, unspecified | B14: industrial machine, heavy, unspecified | C14: RoW | D14: 0.00071753555 | E14: kilogram | F14: ecoinvent 3.10 cutoff | G14: technosphere | J14: (4,5,5,2,2)
A15: market for inert waste, for final disposal | B15: inert waste, for final disposal | C15: RoW | D15: -0.40189573 | E15: kilogram | F15: ecoinvent 3.10 cutoff | G15: technosphere | J15: (4,5,5,2,2)
A16: Dolomite | D16: 1 | E16: kilogram | F16: biosphere3 | G16: biosphere | H16: natural resource::in ground | J16: (4,5,5,2,2)
A18: Activity | B18: [P+R] Refined Mg production - Bolzano process
A19: reference product | B19: Refined Mg
A20: location | B20: BR
A21: amount | B21: 1
A22: unit | B22: kilogram
A23: comment | B23: n/a
A24: Exchanges
A25: name | B25: reference product | C25: location | D25: amount | E25: unit | F25: database | G25: type | H25: categories | I25: uncertainty type | J25: pedigree | K25: loc | L25: scale | M25: minimum | N25: maximum
A26: =B18 -> [P+R] Refined Mg production - Bolzano process | B26: =B19 -> Refined Mg | C26: =B20 -> BR | D26: 1 | E26: kilogram | F26: =F9 -> Magnesium | G26: production
A27: market group for electricity, medium voltage | B27: electricity, medium voltage | C27: BR | D27: 20.2 | E27: kilowatt hour | F27: ecoinvent 3.10 cutoff | G27: technosphere | J27: (4,5,5,2,2)
A28: market for natural gas, high pressure | B28: natural gas, high pressure | C28: BR | D28: 2.323077 | E28: cubic meter | F28: ecoinvent 3.10 cutoff | G28: technosphere | J28: (4,5,5,2,2)
A29: market for industrial machine, heavy, unspecified | B29: industrial machine, heavy, unspecified | C29: RoW | D29: 2e-05 | E29: kilogram | F29: ecoinvent 3.10 cutoff | G29: technosphere | J29: (4,5,5,2,2)
A30: market for ferrosilicon | B30: ferrosilicon | C30: GLO | D30: 0.7 | E30: kilogram | F30: ecoinvent 3.10 cutoff | G30: technosphere | J30: (4,5,5,2,2)
A31: market for calcium chloride | B31: calcium chloride | C31: RoW | D31: 0.2 | E31: kilogram | F31: ecoinvent 3.10 cutoff | G31: technosphere | J31: (4,5,5,2,2)
A32: market for sulfur | B32: sulfur | C32: GLO | D32: 0.05 | E32: kilogram | F32: ecoinvent 3.10 cutoff | G32: technosphere | J32: (4,5,5,2,2)
A33: market for inert waste, for final disposal | B33: inert waste, for final disposal | C33: RoW | D33: -5.26 | E33: kilogram | F33: ecoinvent 3.10 cutoff | G33: technosphere | J33: (4,5,5,2,2)
A34: market for iron scrap, unsorted | B34: iron scrap, unsorted | C34: GLO | D34: -0.18 | E34: kilogram | F34: ecoinvent 3.10 cutoff | G34: technosphere | J34: (4,5,5,2,2)
A35: Water, unspecified natural origin | D35: 0.00584 | E35: cubic meter | F35: biosphere3 | G35: biosphere | H35: natural resource::in ground | J35: (4,5,5,2,2)
A36: Carbon dioxide, fossil | D36: 1.22 | E36: kilogram | F36: biosphere3 | G36: biosphere | H36: air | J36: (4,5,5,2,2)
A38: Activity | B38: Dolomite ore mining and Mg production in Brazil through Bolzano process
A39: reference product | B39: Refined Mg
A40: location | B40: BR
A41: amount | B41: 1
A42: unit | B42: kilogram
...
