Workbook

Sheet Note
A1: skip
B2: Life cycle inventories of global metal and mineral supply chains: a comprehensive data review, analysis and processing Frédéric Laia*, Stéphanie Mullera, Audrey Philippea, Robert Istrateb, Brenda Miranda Xicotencatlb, Afsoon Mansouri Askic, Aina Mas Fonsd,a, Juliana Segura-Salazare, Jair Santillán Saldivara, Alexander Cimprichf, Stephen Northeyg, Lígia da Silva Limah, Lieselot Booneh, Ryosuke Yokoii, Kamrul Islami, Ioanna Paschalidouj, Felipe Cerdask,l, Victor Balboa-Espinozae, Anish Koyamparambathd, Diae Henniouia, Victoire Collignona, Aurélien Reysa, Gyslain Ngadi Sakatadim, Jo Dewulfh, Bernhard Steubingb, Christoph Helbigc, Gaétan Lefebvrea, Gian Andrea Blenginin,m, Valeria Supertio, Masaharu Motoshitai, Guido Sonnemannd, Kwame Awuah-Offeij, Steven B. Youngf, Shinsuke Murakamip, Antoine Beylota aBRGM, F-45060 Orléans, France bInstitute of Environmental Sciences (CML), Leiden University, Einsteinweg 2, 2333 CC Leiden, NL cEcological Resource Technology, University of Bayreuth, Universitätstr. 30, 95447 Bayreuth, Germany dUniv. Bordeaux, CNRS, Bordeaux INP, ISM, UMR 5255, F-33400 Talence, France eSustainable Minerals Institute, The University of Queensland, QLD, 4072, Australia fSchool of Environment, Enterprise and Development, University of Waterloo, 200 University Avenue West, Waterloo, Ontario N2L 3G1, Canada gUniversity of Technology Sydney, Institute for Sustainable Futures, Australia hSustainable Systems Engineering (STEN), Department of Green Chemistry and Technology, Faculty of Bioscience Engineering, Ghent University, Coupure Links 653, 9000 Ghent, Belgium iAIST, 305-8569 Tsukuba, Japan jMining & Explosives Engineering, Missouri University of Science & Technology, Rolla, MO, USA 65409 kInstitute for Sustainable Energy Systems (INSYS), Technical University of Applied Sciences Würzburg-Schweinfurt (THWS), Ignaz-Schön-Straße 11, Schweinfurt, Germany lFraunhofer Institute for Surface Engineering and Thin Films IST, Riedenkamp 2, Braunschweig 38108, Germany mDepartment of Environment, Land and Infrastructure Engineering, Politecnico di Torino, Corso Duca degli Abruzzi, 24, 10129 Torino, Italy nUniversity of Turin, Earth Sciences Department (DST), Via Valperga Caluso, 35 – 10125 Torino, Italy oecoinvent association, Technopark, Technoparkstrasse 1, 8005 Zürich, Switzerland pGraduate School of Engineering, The University of Tokyo, Tokyo 113-8656, Japan *Corresponding author: f.lai@brgm.fr This file provides all LCI datasets developed for Manganese (Mn), with distinguishing its global market and each individual production route.
B33: Sheet | C33: Corresponding route
B34: Mn_Market_GLO | C34: Mn global market
B35: PR1_Mn_CN | C35: Mn ore mining and Mn metal production in China
B36: PR2_FeMn_AU_Tasmania | C36: Mn ore mining and FeMn production in Australia/Tasmania
B37: PR3_SiMn_AU_Tasmania | C37: Mn ore mining and SiMn production in Australia/Tasmania

Sheet Mn_Market_GLO
A1: database | B1: Manganese
A3: Activity | B3: Manganese (Mn) global market
A4: reference product | B4: Mn commodities
A5: location | B5: GLO
A6: amount | B6: 1
A7: unit | B7: kilogram
A8: comment | B8: n/a
A9: Exchanges
A10: name | B10: reference product | C10: location | D10: amount | E10: unit | F10: database | G10: type | H10: categories | I10: uncertainty type | J10: pedigree | K10: loc | L10: scale | M10: minimum | N10: maximum
A11: =B3 -> Manganese (Mn) global market | B11: =B4 -> Mn commodities | C11: =B5 -> GLO | D11: 1 | E11: =B7 -> kilogram | F11: =B1 -> Manganese | G11: production
A12: =PR1_Mn_CN!A67 -> Mn ore mining and Mn metal production in China | B12: =PR1_Mn_CN!B67 -> Mn metal | C12: =PR1_Mn_CN!C67 -> CN | D12: 0.72932331 | E12: =PR1_Mn_CN!E67 -> kilogram | F12: =PR1_Mn_CN!F67 -> Manganese | G12: technosphere
A13: =PR2_FeMn_AU_Tasmania!A38 -> Mn ore mining and FeMn production in Australia/Tasmania | B13: =PR2_FeMn_AU_Tasmania!B38 -> FeMn | C13: =PR2_FeMn_AU_Tasmania!C38 -> AU | D13: 0.16240602 | E13: =PR2_FeMn_AU_Tasmania!E38 -> kilogram | F13: =PR2_FeMn_AU_Tasmania!F38 -> Manganese | G13: technosphere
A14: =PR3_SiMn_AU_Tasmania!A39 -> Mn ore mining and SiMn production in Australia/Tasmania | B14: =PR3_SiMn_AU_Tasmania!B39 -> SiMn | C14: =PR3_SiMn_AU_Tasmania!C39 -> AU | D14: 0.10827068 | E14: =PR3_SiMn_AU_Tasmania!E39 -> kilogram | F14: =PR3_SiMn_AU_Tasmania!F39 -> Manganese | G14: technosphere
A16: Activity | B16: Manganese (Mn) global market (Mn content)
A17: reference product | B17: Mn content
A18: location | B18: GLO
A19: amount | B19: 1
A20: unit | B20: kilogram
A21: comment | B21: Activity expressed for 1 kg Mn contained
A22: Exchanges
A23: name | B23: reference product | C23: location | D23: amount | E23: unit | F23: database | G23: type | H23: categories | I23: uncertainty type | J23: pedigree | K23: loc | L23: scale | M23: minimum | N23: maximum
A24: =B16 -> Manganese (Mn) global market (Mn content) | B24: =B17 -> Mn content | C24: =B18 -> GLO | D24: 1 | E24: =B20 -> kilogram | F24: =F11 -> Manganese | G24: production
A25: =PR1_Mn_CN!A67 -> Mn ore mining and Mn metal production in China | B25: =PR1_Mn_CN!B67 -> Mn metal | C25: =PR1_Mn_CN!C67 -> CN | D25: 0.72932331 | E25: =PR1_Mn_CN!E67 -> kilogram | F25: =PR1_Mn_CN!F67 -> Manganese | G25: technosphere
A26: =PR2_FeMn_AU_Tasmania!A49 -> Mn ore mining and FeMn production in Australia/Tasmania (Mn content) | B26: =PR2_FeMn_AU_Tasmania!B49 -> FeMn (Mn content) | C26: =PR2_FeMn_AU_Tasmania!C49 -> AU | D26: 0.16240602 | E26: =PR2_FeMn_AU_Tasmania!E49 -> kilogram | F26: =PR2_FeMn_AU_Tasmania!F49 -> Manganese | G26: technosphere
A27: =PR3_SiMn_AU_Tasmania!A50 -> Mn ore mining and SiMn production in Australia/Tasmania (Mn content) | B27: =PR3_SiMn_AU_Tasmania!B50 -> SiMn (Mn content) | C27: =PR3_SiMn_AU_Tasmania!C50 -> AU | D27: 0.10827068 | E27: =PR3_SiMn_AU_Tasmania!E50 -> kilogram | F27: =PR3_SiMn_AU_Tasmania!F50 -> Manganese | G27: technosphere

Sheet PR1_Mn_CN
A1: Activity | B1: [M+C+P+R] Manganese (Mn) metal production
A2: reference product | B2: Mn metal
A3: location | B3: CN
A4: amount | B4: 1
A5: unit | B5: kilogram
A6: comment | B6: n/a
A7: Exchanges
A8: name | B8: reference product | C8: location | D8: amount | E8: unit | F8: database | G8: type | H8: categories | I8: uncertainty type | J8: pedigree | K8: loc | L8: scale | M8: minimum | N8: maximum
A9: =B1 -> [M+C+P+R] Manganese (Mn) metal production | B9: =B2 -> Mn metal | C9: =B3 -> CN | D9: 1 | E9: kilogram | F9: =Mn_Market_GLO!B1 -> Manganese | G9: production
A10: market for explosive, tovex | B10: explosive, tovex | C10: GLO | D10: 0.00065 | E10: kilogram | F10: ecoinvent 3.10 cutoff | G10: technosphere | J10: (1,1,2,1,1)
A11: market for tungsten carbide powder | B11: tungsten carbide powder | C11: GLO | D11: 1.3e-06 | E11: kilogram | F11: ecoinvent 3.10 cutoff | G11: technosphere | J11: (1,1,2,1,1)
A12: market for steel, low-alloyed | B12: steel, low-alloyed | C12: GLO | D12: 3.906e-05 | E12: kilogram | F12: ecoinvent 3.10 cutoff | G12: technosphere | J12: (1,1,2,1,1)
A13: market for light fuel oil | B13: light fuel oil | C13: RoW | D13: 0.00043 | E13: kilogram | F13: ecoinvent 3.10 cutoff | G13: technosphere | J13: (1,1,2,1,1)
A14: market for glued laminated timber, average glue mix | B14: glued laminated timber, average glue mix | C14: RoW | D14: 1.3e-06 | E14: cubic meter | F14: ecoinvent 3.10 cutoff | G14: technosphere | J14: (1,1,2,1,1)
A15: market for sulfuric acid | B15: sulfuric acid | C15: RoW | D15: 0.81 | E15: kilogram | F15: ecoinvent 3.10 cutoff | G15: technosphere | J15: (1,1,2,1,1)
A16: market for ammonia, anhydrous, liquid | B16: ammonia, anhydrous, liquid | C16: SAS | D16: 0.0505 | E16: kilogram | F16: ecoinvent 3.10 cutoff | G16: technosphere | J16: (1,1,2,1,1)
A17: market for dithiocarbamate-compound | B17: dithiocarbamate-compound | C17: GLO | D17: 0.002 | E17: kilogram | F17: ecoinvent 3.10 cutoff | G17: technosphere | J17: (1,1,2,1,1)
A18: market for selenium | B18: selenium | C18: GLO | D18: 0.0011 | E18: kilogram | F18: ecoinvent 3.10 cutoff | G18: technosphere | J18: (1,1,2,1,1)
A19: market for chemical, organic | B19: chemical, organic | C19: GLO | D19: 1.087e-05 | E19: kilogram | F19: ecoinvent 3.10 cutoff | G19: technosphere | J19: (1,1,2,1,1)
A20: market for sodium dichromate | B20: sodium dichromate | C20: GLO | D20: 0.00057 | E20: kilogram | F20: ecoinvent 3.10 cutoff | G20: technosphere | J20: (1,1,2,1,1)
A21: market for calcium carbonate, precipitated | B21: calcium carbonate, precipitated | C21: RoW | D21: 0.00907 | E21: kilogram | F21: ecoinvent 3.10 cutoff | G21: technosphere | J21: (1,1,2,1,1)
... A31: treatment of hazardous waste, hazardous waste incineration | B31: hazardous waste, for incineration | C31: RoW | D31: -0.00022 | E31: kilogram | F31: ecoinvent 3.10 cutoff | G31: technosphere | J31: (1,1,2,1,1)
A32: Manganese | D32: 1.5 | E32: kilogram | F32: biosphere3 | G32: biosphere | H32: natural resource::in ground | J32: (1,1,2,1,1)
A33: Water, unspecified natural origin | D33: 0.00424 | E33: cubic meter | F33: biosphere3 | G33: biosphere | H33: natural resource::in ground | J33: (1,1,2,1,1)
A34: Particulate Matter, > 2.5 um and < 10um | D34: 0.00371 | E34: kilogram | F34: biosphere3 | G34: biosphere | H34: air | J34: (1,1,2,1,1)
A35: Nitrogen oxides | D35: 0.00018674 | E35: kilogram | F35: biosphere3 | G35: biosphere | H35: air | J35: (1,1,2,1,1)
A36: Sulfur dioxide | D36: 3.224e-05 | E36: kilogram | F36: biosphere3 | G36: biosphere | H36: air | J36: (1,1,2,1,1)
A37: Nitrogen oxides | D37: 2.828e-05 | E37: kilogram | F37: biosphere3 | G37: biosphere | H37: air | J37: (1,1,2,1,1)
A38: Sulfuric acid | D38: 0.00013293 | E38: kilogram | F38: biosphere3 | G38: biosphere | H38: air | J38: (1,1,2,1,1)
A39: Ammonia | D39: 2.137e-05 | E39: kilogram | F39: biosphere3 | G39: biosphere | H39: air | J39: (1,1,2,1,1)
A40: Dimethylamine | D40: 2.5e-06 | E40: kilogram | F40: biosphere3 | G40: biosphere | H40: air | J40: (1,1,2,1,1)
A41: Carbon disulfide | D41: 4.2e-06 | E41: kilogram | F41: biosphere3 | G41: biosphere | H41: air | J41: (1,1,2,1,1)
A42: Hydrogen sulfide | D42: 1e-09 | E42: kilogram | F42: biosphere3 | G42: biosphere | H42: air | J42: (1,1,2,1,1)
A43: Hydrocarbons, unspecified | D43: 0.5 | E43: kilogram | F43: biosphere3 | G43: biosphere | H43: air::non-urban air or from high stacks | J43: (1,1,2,1,1)
... A57: Manganese II | D57: 6.33e-08 | E57: kilogram | F57: biosphere3 | G57: biosphere | H57: water | J57: (1,1,2,1,1)
A59: Activity | B59: Mn ore mining and Mn metal production in China
A60: reference product | B60: Mn metal
A61: location | B61: CN
A62: amount | B62: 1
A63: unit | B63: kilogram
...

Sheet PR2_FeMn_AU_Tasmania
A1: Activity | B1: [M+C+P+R] Ferromanganese (FeMn) production
A2: reference product | B2: FeMn
A3: location | B3: AU
A4: amount | B4: 1
A5: unit | B5: kilogram
A6: comment | B6: n/a
A7: Exchanges
A8: name | B8: reference product | C8: location | D8: amount | E8: unit | F8: database | G8: type | H8: categories | I8: uncertainty type | J8: pedigree | K8: loc | L8: scale | M8: minimum | N8: maximum
A9: =B1 -> [M+C+P+R] Ferromanganese (FeMn) production | B9: =B2 -> FeMn | C9: =B3 -> AU | D9: 1 | E9: kilogram | F9: =Mn_Market_GLO!B1 -> Manganese | G9: production
A10: market for diesel, burned in building machine | B10: diesel, burned in building machine | C10: GLO | D10: 0.025637976 | E10: megajoule | F10: ecoinvent 3.10 cutoff | G10: technosphere | J10: (4,5,4,2,1)
A11: market for diesel, burned in diesel-electric generating set, 18.5kW | B11: diesel, burned in diesel-electric generating set, 18.5kW | C11: GLO | D11: 0.023014555 | E11: megajoule | F11: ecoinvent 3.10 cutoff | G11: technosphere | J11: (4,5,4,2,1)
A12: market for transport, freight, sea, ferry | B12: transport, freight, sea, ferry | C12: GLO | D12: 8.281 | E12: ton kilometer | F12: ecoinvent 3.10 cutoff | G12: technosphere | J12: (4,5,4,2,1)
A13: market for coke | B13: coke | C13: RoW | D13: 4.914 | E13: megajoule | F13: ecoinvent 3.10 cutoff | G13: technosphere | J13: (4,5,4,2,1)
A14: market for electricity, medium voltage | B14: electricity, medium voltage | C14: AU | D14: 0.0546 | E14: kilowatt hour | F14: ecoinvent 3.10 cutoff | G14: technosphere | J14: (4,5,4,2,1)
A15: market for iron ore concentrate | B15: iron ore concentrate | C15: GLO | D15: 0.14 | E15: kilogram | F15: ecoinvent 3.10 cutoff | G15: technosphere | J15: (4,5,4,2,1)
A16: market for transport, freight, sea, ferry | B16: transport, freight, sea, ferry | C16: GLO | D16: 3 | E16: ton kilometer | F16: ecoinvent 3.10 cutoff | G16: technosphere | J16: (4,5,4,2,1)
A17: limestone production, crushed, washed | B17: limestone, crushed, washed | C17: RoW | D17: 0.18 | E17: kilogram | F17: ecoinvent 3.10 cutoff | G17: technosphere | J17: (4,5,4,2,1)
A18: market for transport, freight, sea, ferry | B18: transport, freight, sea, ferry | C18: GLO | D18: 2 | E18: ton kilometer | F18: ecoinvent 3.10 cutoff | G18: technosphere | J18: (4,5,4,2,1)
A19: market for coke | B19: coke | C19: RoW | D19: 9.3 | E19: megajoule | F19: ecoinvent 3.10 cutoff | G19: technosphere | J19: (4,5,4,2,1)
A20: market for transport, freight, sea, ferry | B20: transport, freight, sea, ferry | C20: GLO | D20: 0.8 | E20: ton kilometer | F20: ecoinvent 3.10 cutoff | G20: technosphere | J20: (4,5,4,2,1)
A21: market for hard coal | B21: hard coal | C21: AU | D21: 0.13 | E21: kilogram | F21: ecoinvent 3.10 cutoff | G21: technosphere | J21: (4,5,4,2,1)
... A25: market for electric arc furnace slag, for recovery | B25: electric arc furnace slag, for recovery | C25: RoW | D25: -0.63 | E25: kilogram | F25: ecoinvent 3.10 cutoff | G25: technosphere | J25: (4,5,4,2,1)
A26: Water, unspecified natural origin | D26: 0.000430612 | E26: cubic meter | F26: biosphere3 | G26: biosphere | H26: natural resource::in ground | J26: (4,5,4,2,1)
A27: Manganese | D27: 1.7330477 | E27: kilogram | F27: biosphere3 | G27: biosphere | H27: natural resource::in ground | J27: (4,5,4,2,1)
A28: Gangue | D28: 1.2817332 | E28: kilogram | F28: biosphere3 | G28: biosphere | H28: natural resource::in ground | J28: (4,5,4,2,1)
A30: Activity | B30: Mn ore mining and FeMn production in Australia/Tasmania
A31: reference product | B31: FeMn
A32: location | B32: AU
A33: amount | B33: 1
A34: unit | B34: kilogram
A35: comment | B35: n/a
A36: Exchanges
A37: name | B37: reference product | C37: location | D37: amount | E37: unit | F37: database | G37: type | H37: categories | I37: uncertainty type | J37: pedigree | K37: loc | L37: scale | M37: minimum | N37: maximum
A38: =B30 -> Mn ore mining and FeMn production in Australia/Tasmania | B38: =B31 -> FeMn | C38: =B32 -> AU | D38: 1 | E38: kilogram | F38: =F9 -> Manganese | G38: production
A39: =A9 -> [M+C+P+R] Ferromanganese (FeMn) production | B39: =B9 -> FeMn | C39: =C9 -> AU | D39: =D9 -> 1 | E39: =E9 -> kilogram | F39: =F9 -> Manganese | G39: technosphere
A41: Activity | B41: Mn ore mining and FeMn production in Australia/Tasmania (Mn content)
A42: reference product | B42: FeMn (Mn content)
A43: location | B43: AU
A44: amount | B44: 1
A45: unit | B45: kilogram
...

Sheet PR3_SiMn_AU_Tasmania
A1: Activity | B1: [M+C+P+R] Silicomanganese (SiMn) production
A2: reference product | B2: SiMn
A3: location | B3: AU
A4: amount | B4: 1
A5: unit | B5: kilogram
A6: comment | B6: n/a
A7: Exchanges
A8: name | B8: reference product | C8: location | D8: amount | E8: unit | F8: database | G8: type | H8: categories | I8: uncertainty type | J8: pedigree | K8: loc | L8: scale | M8: minimum | N8: maximum
A9: =B1 -> [M+C+P+R] Silicomanganese (SiMn) production | B9: =B2 -> SiMn | C9: =B3 -> AU | D9: 1 | E9: kilogram | F9: =Mn_Market_GLO!B1 -> Manganese | G9: production
A10: market for diesel, burned in building machine | B10: diesel, burned in building machine | C10: GLO | D10: 0.023806692 | E10: megajoule | F10: ecoinvent 3.10 cutoff | G10: technosphere | J10: (4,5,4,2,1)
A11: market for diesel, burned in diesel-electric generating set, 10MW | B11: diesel, burned in diesel-electric generating set, 10MW | C11: GLO | D11: 0.021370658 | E11: megajoule | F11: ecoinvent 3.10 cutoff | G11: technosphere | J11: (4,5,4,2,1)
A12: market for transport, freight, sea, ferry | B12: transport, freight, sea, ferry | C12: GLO | D12: 7.6895 | E12: ton kilometer | F12: ecoinvent 3.10 cutoff | G12: technosphere | J12: (4,5,4,2,1)
A13: market for coke | B13: coke | C13: RoW | D13: 4.563 | E13: megajoule | F13: ecoinvent 3.10 cutoff | G13: technosphere | J13: (4,5,4,2,1)
A14: market for electricity, medium voltage | B14: electricity, medium voltage | C14: AU | D14: 0.0507 | E14: kilowatt hour | F14: ecoinvent 3.10 cutoff | G14: technosphere | J14: (4,5,4,2,1)
A15: market for electric arc furnace slag, for recovery | B15: electric arc furnace slag, for recovery | C15: RoW | D15: 0.65 | E15: kilogram | F15: ecoinvent 3.10 cutoff | G15: technosphere | J15: (4,5,4,2,1)
A16: market for iron ore concentrate | B16: iron ore concentrate | C16: GLO | D16: 0.12 | E16: kilogram | F16: ecoinvent 3.10 cutoff | G16: technosphere | J16: (4,5,4,2,1)
A17: market for transport, freight, sea, ferry | B17: transport, freight, sea, ferry | C17: GLO | D17: 3 | E17: ton kilometer | F17: ecoinvent 3.10 cutoff | G17: technosphere | J17: (4,5,4,2,1)
A18: market for silica sand | B18: silica sand | C18: GLO | D18: 0.559 | E18: kilogram | F18: ecoinvent 3.10 cutoff | G18: technosphere | J18: (4,5,4,2,1)
A19: market for dolomite | B19: dolomite | C19: RoW | D19: 0.355 | E19: kilogram | F19: ecoinvent 3.10 cutoff | G19: technosphere | J19: (4,5,4,2,1)
A20: market for coke | B20: coke | C20: RoW | D20: 13.56 | E20: megajoule | F20: ecoinvent 3.10 cutoff | G20: technosphere | J20: (4,5,4,2,1)
A21: market for transport, freight, sea, ferry | B21: transport, freight, sea, ferry | C21: GLO | D21: 0.8 | E21: ton kilometer | F21: ecoinvent 3.10 cutoff | G21: technosphere | J21: (4,5,4,2,1)
... A26: treatment of electric arc furnace slag, residual material landfill | B26: electric arc furnace slag | C26: RoW | D26: -1.049 | E26: kilogram | F26: ecoinvent 3.10 cutoff | G26: technosphere | J26: (4,5,4,2,1)
A27: Water, unspecified natural origin | D27: 0.000399854 | E27: cubic meter | F27: biosphere3 | G27: biosphere | H27: natural resource::in ground | J27: (4,5,4,2,1)
A28: Manganese | D28: 1.6092586 | E28: kilogram | F28: biosphere3 | G28: biosphere | H28: natural resource::in ground | J28: (4,5,4,2,1)
A29: Gangue | D29: 0.092868 | E29: kilogram | F29: biosphere3 | G29: biosphere | H29: natural resource::in ground | J29: (4,5,4,2,1)
A31: Activity | B31: Mn ore mining and SiMn production in Australia/Tasmania
A32: reference product | B32: SiMn
A33: location | B33: AU
A34: amount | B34: 1
A35: unit | B35: kilogram
A36: comment | B36: n/a
A37: Exchanges
A38: name | B38: reference product | C38: location | D38: amount | E38: unit | F38: database | G38: type | H38: categories | I38: uncertainty type | J38: pedigree | K38: loc | L38: scale | M38: minimum | N38: maximum
A39: =B31 -> Mn ore mining and SiMn production in Australia/Tasmania | B39: =B32 -> SiMn | C39: =B33 -> AU | D39: 1 | E39: kilogram | F39: =F9 -> Manganese | G39: production
A40: =A9 -> [M+C+P+R] Silicomanganese (SiMn) production | B40: =B9 -> SiMn | C40: =C9 -> AU | D40: =D9 -> 1 | E40: =E9 -> kilogram | F40: =F9 -> Manganese | G40: technosphere
A42: Activity | B42: Mn ore mining and SiMn production in Australia/Tasmania (Mn content)
A43: reference product | B43: SiMn (Mn content)
A44: location | B44: AU
A45: amount | B45: 1
A46: unit | B46: kilogram
...
