Workbook

Sheet Note
A1: skip
B2: Life cycle inventories of global metal and mineral supply chains: a comprehensive data review, analysis and processing Frédéric Laia*, Stéphanie Mullera, Audrey Philippea, Robert Istrateb, Brenda Miranda Xicotencatlb, Afsoon Mansouri Askic, Aina Mas Fonsd,a, Juliana Segura-Salazare, Jair Santillán Saldivara, Alexander Cimprichf, Stephen Northeyg, Lígia da Silva Limah, Lieselot Booneh, Ryosuke Yokoii, Kamrul Islami, Ioanna Paschalidouj, Felipe Cerdask,l, Victor Balboa-Espinozae, Anish Koyamparambathd, Diae Henniouia, Victoire Collignona, Aurélien Reysa, Gyslain Ngadi Sakatadim, Jo Dewulfh, Bernhard Steubingb, Christoph Helbigc, Gaétan Lefebvrea, Gian Andrea Blenginin,m, Valeria Supertio, Masaharu Motoshitai, Guido Sonnemannd, Kwame Awuah-Offeij, Steven B. Youngf, Shinsuke Murakamip, Antoine Beylota aBRGM, F-45060 Orléans, France bInstitute of Environmental Sciences (CML), Leiden University, Einsteinweg 2, 2333 CC Leiden, NL cEcological Resource Technology, University of Bayreuth, Universitätstr. 30, 95447 Bayreuth, Germany dUniv. Bordeaux, CNRS, Bordeaux INP, ISM, UMR 5255, F-33400 Talence, France eSustainable Minerals Institute, The University of Queensland, QLD, 4072, Australia fSchool of Environment, Enterprise and Development, University of Waterloo, 200 University Avenue West, Waterloo, Ontario N2L 3G1, Canada gUniversity of Technology Sydney, Institute for Sustainable Futures, Australia hSustainable Systems Engineering (STEN), Department of Green Chemistry and Technology, Faculty of Bioscience Engineering, Ghent University, Coupure Links 653, 9000 Ghent, Belgium iAIST, 305-8569 Tsukuba, Japan jMining & Explosives Engineering, Missouri University of Science & Technology, Rolla, MO, USA 65409 kInstitute for Sustainable Energy Systems (INSYS), Technical University of Applied Sciences Würzburg-Schweinfurt (THWS), Ignaz-Schön-Straße 11, Schweinfurt, Germany lFraunhofer Institute for Surface Engineering and Thin Films IST, Riedenkamp 2, Braunschweig 38108, Germany mDepartment of Environment, Land and Infrastructure Engineering, Politecnico di Torino, Corso Duca degli Abruzzi, 24, 10129 Torino, Italy nUniversity of Turin, Earth Sciences Department (DST), Via Valperga Caluso, 35 – 10125 Torino, Italy oecoinvent association, Technopark, Technoparkstrasse 1, 8005 Zürich, Switzerland pGraduate School of Engineering, The University of Tokyo, Tokyo 113-8656, Japan *Corresponding author: f.lai@brgm.fr This file provides all LCI datasets developed for Molybdenum (Mo), with distinguishing its global market and each individual production route.
B33: Sheet | C33: Corresponding route
B34: Mo_Market_GLO | C34: Mo global market
B35: PR1_FeMo_US_MoMine | C35: Mo ore mining and FeMo production in the US
B36: PR2_FeMo_CN_MoMine | C36: Mo ore mining and FeMo production in China
B37: PR3_FeMo_US_CuMine | C37: FeMo recovery from Cu ore mining in the US

Sheet Mo_Market_GLO
A1: database | B1: Molybdenum
A3: Activity | B3: Molybdenum (Mo) global market
A4: reference product | B4: FeMo
A5: location | B5: GLO
A6: amount | B6: 1
A7: unit | B7: kilogram
A8: comment | B8: n/a
A9: Exchanges
A10: name | B10: reference product | C10: location | D10: amount | E10: unit | F10: database | G10: type | H10: categories | I10: uncertainty type | J10: pedigree | K10: loc | L10: scale | M10: minimum | N10: maximum
A11: =B3 -> Molybdenum (Mo) global market | B11: =B4 -> FeMo | C11: =B5 -> GLO | D11: 1 | E11: =B7 -> kilogram | F11: =B1 -> Molybdenum | G11: production
A12: =PR1_FeMo_US_MoMine!A50 -> Mo ore mining and FeMo production in the US | B12: =PR1_FeMo_US_MoMine!B50 -> FeMo | C12: =PR1_FeMo_US_MoMine!C50 -> US | D12: 0.2224026 | E12: =PR1_FeMo_US_MoMine!E50 -> kilogram | F12: =PR1_FeMo_US_MoMine!F50 -> Molybdenum | G12: technosphere
A13: =PR2_FeMo_CN_MoMine!A38 -> Mo ore mining and FeMo production in China | B13: =PR2_FeMo_CN_MoMine!B38 -> FeMo | C13: =PR2_FeMo_CN_MoMine!C38 -> CN | D13: 0.55519481 | E13: =PR2_FeMo_CN_MoMine!E38 -> kilogram | F13: =PR2_FeMo_CN_MoMine!F38 -> Molybdenum | G13: technosphere
A14: =PR3_FeMo_US_CuMine!A39 -> FeMo recovery from Cu ore mining in the US | B14: =PR3_FeMo_US_CuMine!B39 -> FeMo | C14: =PR3_FeMo_US_CuMine!C39 -> US | D14: 0.2224026 | E14: =PR3_FeMo_US_CuMine!E39 -> kilogram | F14: =PR3_FeMo_US_CuMine!F39 -> Molybdenum | G14: technosphere
A16: Activity | B16: Molybdenum (Mo) global market (Mo content)
A17: reference product | B17: Mo content
A18: location | B18: GLO
A19: amount | B19: 1
A20: unit | B20: kilogram
A21: comment | B21: Activity expressed for 1 kg Mo contained
A22: Exchanges
A23: name | B23: reference product | C23: location | D23: amount | E23: unit | F23: database | G23: type | H23: categories | I23: uncertainty type | J23: pedigree | K23: loc | L23: scale | M23: minimum | N23: maximum
A24: =B16 -> Molybdenum (Mo) global market (Mo content) | B24: =B17 -> Mo content | C24: =B18 -> GLO | D24: 1 | E24: =B20 -> kilogram | F24: =F11 -> Molybdenum | G24: production
A25: =PR1_FeMo_US_MoMine!A62 -> Mo ore mining and FeMo production in the US (Mo content) | B25: =PR1_FeMo_US_MoMine!B62 -> FeMo (Mo content) | C25: =PR1_FeMo_US_MoMine!C62 -> US | D25: 0.2224026 | E25: =PR1_FeMo_US_MoMine!E62 -> kilogram | F25: =PR1_FeMo_US_MoMine!F62 -> Molybdenum | G25: technosphere
A26: =PR2_FeMo_CN_MoMine!A50 -> Mo ore mining and FeMo production in China (Mo content) | B26: =PR2_FeMo_CN_MoMine!B50 -> FeMo (Mo content) | C26: =PR2_FeMo_CN_MoMine!C50 -> CN | D26: 0.55519481 | E26: =PR2_FeMo_CN_MoMine!E50 -> kilogram | F26: =PR2_FeMo_CN_MoMine!F50 -> Molybdenum | G26: technosphere
A27: =PR3_FeMo_US_CuMine!A51 -> FeMo recovery from Cu ore mining in the US (Mo content) | B27: =PR3_FeMo_US_CuMine!B51 -> FeMo (Mo content) | C27: =PR3_FeMo_US_CuMine!C51 -> US | D27: 0.2224026 | E27: =PR3_FeMo_US_CuMine!E51 -> kilogram | F27: =PR3_FeMo_US_CuMine!F51 -> Molybdenum | G27: technosphere

Sheet PR1_FeMo_US_MoMine
A1: Activity | B1: [M+C] Molybdenum (Mo) ore mining and concentration
A2: reference product | B2: Mo concentrate
A3: location | B3: US
A4: amount | B4: 1
A5: unit | B5: kilogram
A6: comment | B6: In the absence of detailed mass balance for this intermediary product, the reference flow of this unit process is set by default at 1 kg, while the input and ouput flows of the inventory are actually scaled to 1 kg of FeMo.
A7: Exchanges
A8: name | B8: reference product | C8: location | D8: amount | E8: unit | F8: database | G8: type | H8: categories | I8: uncertainty type | J8: pedigree | K8: loc | L8: scale | M8: minimum | N8: maximum
A9: =B1 -> [M+C] Molybdenum (Mo) ore mining and concentration | B9: =B2 -> Mo concentrate | C9: =B3 -> US | D9: 1 | E9: kilogram | F9: =Mo_Market_GLO!B1 -> Molybdenum | G9: production
A10: market for diesel, burned in building machine | B10: diesel, burned in building machine | C10: GLO | D10: 51.586839 | E10: megajoule | F10: ecoinvent 3.10 cutoff | G10: technosphere | J10: (1,2,2,1,1)
A11: market group for electricity, medium voltage | B11: electricity, medium voltage | C11: US | D11: 0.98846774 | E11: kilowatt hour | F11: ecoinvent 3.10 cutoff | G11: technosphere | J11: (1,2,2,1,1)
A12: market for transport, freight train | B12: transport, freight train | C12: US | D12: 1.1854839 | E12: ton kilometer | F12: ecoinvent 3.10 cutoff | G12: technosphere | J12: (1,2,2,1,1)
A13: market for diesel, burned in building machine | B13: diesel, burned in building machine | C13: GLO | D13: 14.391 | E13: megajoule | F13: ecoinvent 3.10 cutoff | G13: technosphere | J13: (1,2,2,1,1)
A14: market group for electricity, medium voltage | B14: electricity, medium voltage | C14: US | D14: 0.27572133 | E14: kilowatt hour | F14: ecoinvent 3.10 cutoff | G14: technosphere | J14: (1,2,2,1,1)
A15: market for transport, freight train | B15: transport, freight train | C15: US | D15: 0.95887097 | E15: ton kilometer | F15: ecoinvent 3.10 cutoff | G15: technosphere | J15: (1,2,2,1,1)
A17: Activity | B17: [P+R] Ferromolybdenum (FeMo) production (from Mo ore)
A18: reference product | B18: FeMo
A19: location | B19: US
A20: amount | B20: 1
A21: unit | B21: kilogram
A22: comment | B22: n/a
A23: Exchanges
A24: name | B24: reference product | C24: location | D24: amount | E24: unit | F24: database | G24: type | H24: categories | I24: uncertainty type | J24: pedigree | K24: loc | L24: scale | M24: minimum | N24: maximum
A25: =B17 -> [P+R] Ferromolybdenum (FeMo) production (from Mo ore) | B25: =B18 -> FeMo | C25: =B19 -> US | D25: 1 | E25: kilogram | F25: =F9 -> Molybdenum | G25: production
A26: market for compressed air, 800 kPa gauge | B26: compressed air, 800 kPa gauge | C26: RoW | D26: 0.32205942 | E26: cubic meter | F26: ecoinvent 3.10 cutoff | G26: technosphere | J26: (1,2,2,1,1)
A27: market for iron scrap, sorted, pressed | B27: iron scrap, sorted, pressed | C27: RoW | D27: 0.038612903 | E27: kilogram | F27: ecoinvent 3.10 cutoff | G27: technosphere | J27: (1,2,2,1,1)
A28: market for iron ore, crude ore, 63% Fe | B28: iron ore, crude ore, 63% Fe | C28: GLO | D28: 0.14801613 | E28: kilogram | F28: ecoinvent 3.10 cutoff | G28: technosphere | J28: (1,2,2,1,1)
A29: market for lime, packed | B29: lime, packed | C29: RoW | D29: 0.038274194 | E29: kilogram | F29: ecoinvent 3.10 cutoff | G29: technosphere | J29: (1,2,2,1,1)
A30: market for aluminium, wrought alloy | B30: aluminium, wrought alloy | C30: GLO | D30: 0.027774194 | E30: kilogram | F30: ecoinvent 3.10 cutoff | G30: technosphere | J30: (1,2,2,1,1)
A31: market for ferrosilicon | B31: ferrosilicon | C31: GLO | D31: 0.12735484 | E31: kilogram | F31: ecoinvent 3.10 cutoff | G31: technosphere | J31: (1,2,2,1,1)
A32: market group for electricity, medium voltage | B32: electricity, medium voltage | C32: US | D32: 0.34153226 | E32: kilowatt hour | F32: ecoinvent 3.10 cutoff | G32: technosphere | J32: (1,2,2,1,1)
A33: market for compressed air, 800 kPa gauge | B33: compressed air, 800 kPa gauge | C33: RoW | D33: 5.5469032 | E33: cubic meter | F33: ecoinvent 3.10 cutoff | G33: technosphere | J33: (1,2,2,1,1)
A34: market for transport, freight, sea, container ship | B34: transport, freight, sea, container ship | C34: GLO | D34: 4.6290323 | E34: ton kilometer | F34: ecoinvent 3.10 cutoff | G34: technosphere | J34: (1,2,2,1,1)
A35: market for iron scrap, sorted, pressed | B35: iron scrap, sorted, pressed | C35: RoW | D35: 0.073403226 | E35: kilogram | F35: ecoinvent 3.10 cutoff | G35: technosphere | J35: (1,2,2,1,1)
A36: market for iron ore, crude ore, 63% Fe | B36: iron ore, crude ore, 63% Fe | C36: GLO | D36: 0.29758065 | E36: kilogram | F36: ecoinvent 3.10 cutoff | G36: technosphere | J36: (1,2,2,1,1)
A37: market for lime, packed | B37: lime, packed | C37: RoW | D37: 0.074725806 | E37: kilogram | F37: ecoinvent 3.10 cutoff | G37: technosphere | J37: (1,2,2,1,1)
... A40: market group for electricity, medium voltage | B40: electricity, medium voltage | C40: US | D40: 0.70813172 | E40: kilowatt hour | F40: ecoinvent 3.10 cutoff | G40: technosphere | J40: (1,2,2,1,1)
A42: Activity | B42: Mo ore mining and FeMo production in the US
A43: reference product | B43: FeMo
A44: location | B44: US
...

Sheet PR2_FeMo_CN_MoMine
A1: Activity | B1: [M+C] Molybdenum (Mo) ore mining and concentration
A2: reference product | B2: Mo concentrate
A3: location | B3: CN
A4: amount | B4: 1
A5: unit | B5: kilogram
A6: comment | B6: In the absence of detailed mass balance for this intermediary product, the reference flow of this unit process is set by default at 1 kg, while the input and ouput flows of the inventory are actually scaled to 1 kg of FeMo.
A7: Exchanges
A8: name | B8: reference product | C8: location | D8: amount | E8: unit | F8: database | G8: type | H8: categories | I8: uncertainty type | J8: pedigree | K8: loc | L8: scale | M8: minimum | N8: maximum
A9: =B1 -> [M+C] Molybdenum (Mo) ore mining and concentration | B9: =B2 -> Mo concentrate | C9: =B3 -> CN | D9: 1 | E9: kilogram | F9: =Mo_Market_GLO!B1 -> Molybdenum | G9: production
A10: market for diesel, burned in building machine | B10: diesel, burned in building machine | C10: GLO | D10: 39.76 | E10: megajoule | F10: ecoinvent 3.10 cutoff | G10: technosphere | J10: (1,4,2,1,1)
A11: market group for electricity, medium voltage | B11: electricity, medium voltage | C11: CN | D11: 0.76194445 | E11: kilowatt hour | F11: ecoinvent 3.10 cutoff | G11: technosphere | J11: (1,4,2,1,1)
A13: Activity | B13: [P+R] Ferromolybdenum (FeMo) production (from Mo ore)
A14: reference product | B14: FeMo
A15: location | B15: CN
A16: amount | B16: 1
A17: unit | B17: kilogram
A18: comment | B18: n/a
A19: Exchanges
A20: name | B20: reference product | C20: location | D20: amount | E20: unit | F20: database | G20: type | H20: categories | I20: uncertainty type | J20: pedigree | K20: loc | L20: scale | M20: minimum | N20: maximum
A21: =B13 -> [P+R] Ferromolybdenum (FeMo) production (from Mo ore) | B21: =B14 -> FeMo | C21: =B15 -> CN | D21: 1 | E21: kilogram | F21: =F9 -> Molybdenum | G21: production
A22: market for compressed air, 800 kPa gauge | B22: compressed air, 800 kPa gauge | C22: RoW | D22: 0.90652632 | E22: cubic meter | F22: ecoinvent 3.10 cutoff | G22: technosphere | J22: (1,4,2,1,1)
A23: market for iron scrap, sorted, pressed | B23: iron scrap, sorted, pressed | C23: RoW | D23: 0.092 | E23: kilogram | F23: ecoinvent 3.10 cutoff | G23: technosphere | J23: (1,4,2,1,1)
A24: market for iron ore, crude ore, 63% Fe | B24: iron ore, crude ore, 63% Fe | C24: GLO | D24: 0.488 | E24: kilogram | F24: ecoinvent 3.10 cutoff | G24: technosphere | J24: (1,4,2,1,1)
A25: market for lime, packed | B25: lime, packed | C25: RoW | D25: 0.113 | E25: kilogram | F25: ecoinvent 3.10 cutoff | G25: technosphere | J25: (1,4,2,1,1)
A26: market for aluminium, wrought alloy | B26: aluminium, wrought alloy | C26: GLO | D26: 0.092 | E26: kilogram | F26: ecoinvent 3.10 cutoff | G26: technosphere | J26: (1,4,2,1,1)
A27: market for ferrosilicon | B27: ferrosilicon | C27: GLO | D27: 0.379 | E27: kilogram | F27: ecoinvent 3.10 cutoff | G27: technosphere | J27: (1,4,2,1,1)
A28: market group for electricity, medium voltage | B28: electricity, medium voltage | C28: CN | D28: 1.2191667 | E28: kilowatt hour | F28: ecoinvent 3.10 cutoff | G28: technosphere | J28: (1,4,2,1,1)
A30: Activity | B30: Mo ore mining and FeMo production in China
A31: reference product | B31: FeMo
A32: location | B32: CN
A33: amount | B33: 1
A34: unit | B34: kilogram
A35: comment | B35: n/a
A36: Exchanges
A37: name | B37: reference product | C37: location | D37: amount | E37: unit | F37: database | G37: type | H37: categories | I37: uncertainty type | J37: pedigree | K37: loc | L37: scale | M37: minimum | N37: maximum
A38: =B30 -> Mo ore mining and FeMo production in China | B38: =B31 -> FeMo | C38: =B32 -> CN | D38: 1 | E38: kilogram | F38: =F21 -> Molybdenum | G38: production
A39: =A21 -> [P+R] Ferromolybdenum (FeMo) production (from Mo ore) | B39: =B21 -> FeMo | C39: =C21 -> CN | D39: =D21 -> 1 | E39: =E21 -> kilogram | F39: =F21 -> Molybdenum | G39: technosphere
A40: =A9 -> [M+C] Molybdenum (Mo) ore mining and concentration | B40: =B9 -> Mo concentrate | C40: =C9 -> CN | D40: =D9 -> 1 | E40: =E9 -> kilogram | F40: =F9 -> Molybdenum | G40: technosphere
A42: Activity | B42: Mo ore mining and FeMo production in China (Mo content)
A43: reference product | B43: FeMo (Mo content)
...

Sheet PR3_FeMo_US_CuMine
A1: Activity | B1: [M+C] Copper (Cu) ore mining and concentration
A2: reference product | B2: Molybdenum (Mo) concentrate
A3: location | B3: US
A4: amount | B4: 1
A5: unit | B5: kilogram
A6: comment | B6: Allocated unit process, considering as allocation factors (AF): 11% for Mo (1 kg concentrate) and 89% for Cu (33 kg concentrate). In the absence of detailed mass balance for this intermediary product, the reference flow of this unit process is set by default at 1 kg, while the input and ouput flows of the inventory are actually scaled to 1 kg of FeMo.
A7: Exchanges
A8: name | B8: reference product | C8: location | D8: amount | E8: unit | F8: database | G8: type | H8: categories | I8: uncertainty type | J8: pedigree | K8: loc | L8: scale | M8: minimum | N8: maximum
A9: =B1 -> [M+C] Copper (Cu) ore mining and concentration | B9: =B2 -> Molybdenum (Mo) concentrate | C9: =B3 -> US | D9: 1 | E9: kilogram | F9: =Mo_Market_GLO!B1 -> Molybdenum | G9: production
A10: market for diesel, burned in building machine | B10: diesel, burned in building machine | C10: GLO | D10: 0.21367678 | E10: megajoule | F10: ecoinvent 3.10 cutoff | G10: technosphere | J10: (1,3,2,1,1)
A11: market group for electricity, medium voltage | B11: electricity, medium voltage | C11: US | D11: 3.8159651 | E11: kilowatt hour | F11: ecoinvent 3.10 cutoff | G11: technosphere | J11: (1,3,2,1,1)
A12: market for transport, freight train | B12: transport, freight train | C12: US | D12: 6.2160517 | E12: ton kilometer | F12: ecoinvent 3.10 cutoff | G12: technosphere | J12: (1,3,2,1,1)
A14: Activity | B14: [P+R] Ferromolybdenum (FeMo) production (from Cu ore)
A15: reference product | B15: FeMo
A16: location | B16: US
A17: amount | B17: 1
A18: unit | B18: kilogram
A19: comment | B19: n/a
A20: Exchanges
A21: name | B21: reference product | C21: location | D21: amount | E21: unit | F21: database | G21: type | H21: categories | I21: uncertainty type | J21: pedigree | K21: loc | L21: scale | M21: minimum | N21: maximum
A22: =B14 -> [P+R] Ferromolybdenum (FeMo) production (from Cu ore) | B22: =B15 -> FeMo | C22: =B16 -> US | D22: 1 | E22: kilogram | F22: =F9 -> Molybdenum | G22: production
A23: market for compressed air, 800 kPa gauge | B23: compressed air, 800 kPa gauge | C23: RoW | D23: 0.89894737 | E23: cubic meter | F23: ecoinvent 3.10 cutoff | G23: technosphere | J23: (1,3,2,1,1)
A24: market for iron scrap, sorted, pressed | B24: iron scrap, sorted, pressed | C24: RoW | D24: 0.114 | E24: kilogram | F24: ecoinvent 3.10 cutoff | G24: technosphere | J24: (1,3,2,1,1)
A25: market for iron ore, crude ore, 63% Fe | B25: iron ore, crude ore, 63% Fe | C25: GLO | D25: 0.437 | E25: kilogram | F25: ecoinvent 3.10 cutoff | G25: technosphere | J25: (1,3,2,1,1)
A26: market for lime, packed | B26: lime, packed | C26: RoW | D26: 0.113 | E26: kilogram | F26: ecoinvent 3.10 cutoff | G26: technosphere | J26: (1,3,2,1,1)
A27: market for aluminium, wrought alloy | B27: aluminium, wrought alloy | C27: GLO | D27: 0.082 | E27: kilogram | F27: ecoinvent 3.10 cutoff | G27: technosphere | J27: (1,3,2,1,1)
A28: market for ferrosilicon | B28: ferrosilicon | C28: GLO | D28: 0.376 | E28: kilogram | F28: ecoinvent 3.10 cutoff | G28: technosphere | J28: (1,3,2,1,1)
A29: market group for electricity, medium voltage | B29: electricity, medium voltage | C29: US | D29: 1.0097222 | E29: kilowatt hour | F29: ecoinvent 3.10 cutoff | G29: technosphere | J29: (1,3,2,1,1)
A31: Activity | B31: FeMo recovery from Cu ore mining in the US
A32: reference product | B32: FeMo
A33: location | B33: US
A34: amount | B34: 1
A35: unit | B35: kilogram
A36: comment | B36: n/a
A37: Exchanges
A38: name | B38: reference product | C38: location | D38: amount | E38: unit | F38: database | G38: type | H38: categories | I38: uncertainty type | J38: pedigree | K38: loc | L38: scale | M38: minimum | N38: maximum
A39: =B31 -> FeMo recovery from Cu ore mining in the US | B39: =B32 -> FeMo | C39: =B33 -> US | D39: 1 | E39: kilogram | F39: =F22 -> Molybdenum | G39: production
A40: =A22 -> [P+R] Ferromolybdenum (FeMo) production (from Cu ore) | B40: =B22 -> FeMo | C40: =C22 -> US | D40: 1 | E40: =E22 -> kilogram | F40: =F22 -> Molybdenum | G40: technosphere
A41: =A9 -> [M+C] Copper (Cu) ore mining and concentration | B41: =B9 -> Molybdenum (Mo) concentrate | C41: =C9 -> US | D41: 1 | E41: =E9 -> kilogram | F41: =F9 -> Molybdenum | G41: technosphere
A43: Activity | B43: FeMo recovery from Cu ore mining in the US (Mo content)
...
