Workbook

Sheet Note
A1: skip
B2: Life cycle inventories of global metal and mineral supply chains: a comprehensive data review, analysis and processing Frédéric Laia*, Stéphanie Mullera, Audrey Philippea, Robert Istrateb, Brenda Miranda Xicotencatlb, Afsoon Mansouri Askic, Aina Mas Fonsd,a, Juliana Segura-Salazare, Jair Santillán Saldivara, Alexander Cimprichf, Stephen Northeyg, Lígia da Silva Limah, Lieselot Booneh, Ryosuke Yokoii, Kamrul Islami, Ioanna Paschalidouj, Felipe Cerdask,l, Victor Balboa-Espinozae, Anish Koyamparambathd, Diae Henniouia, Victoire Collignona, Aurélien Reysa, Gyslain Ngadi Sakatadim, Jo Dewulfh, Bernhard Steubingb, Christoph Helbigc, Gaétan Lefebvrea, Gian Andrea Blenginin,m, Valeria Supertio, Masaharu Motoshitai, Guido Sonnemannd, Kwame Awuah-Offeij, Steven B. Youngf, Shinsuke Murakamip, Antoine Beylota aBRGM, F-45060 Orléans, France bInstitute of Environmental Sciences (CML), Leiden University, Einsteinweg 2, 2333 CC Leiden, NL cEcological Resource Technology, University of Bayreuth, Universitätstr. 30, 95447 Bayreuth, Germany dUniv. Bordeaux, CNRS, Bordeaux INP, ISM, UMR 5255, F-33400 Talence, France eSustainable Minerals Institute, The University of Queensland, QLD, 4072, Australia fSchool of Environment, Enterprise and Development, University of Waterloo, 200 University Avenue West, Waterloo, Ontario N2L 3G1, Canada gUniversity of Technology Sydney, Institute for Sustainable Futures, Australia hSustainable Systems Engineering (STEN), Department of Green Chemistry and Technology, Faculty of Bioscience Engineering, Ghent University, Coupure Links 653, 9000 Ghent, Belgium iAIST, 305-8569 Tsukuba, Japan jMining & Explosives Engineering, Missouri University of Science & Technology, Rolla, MO, USA 65409 kInstitute for Sustainable Energy Systems (INSYS), Technical University of Applied Sciences Würzburg-Schweinfurt (THWS), Ignaz-Schön-Straße 11, Schweinfurt, Germany lFraunhofer Institute for Surface Engineering and Thin Films IST, Riedenkamp 2, Braunschweig 38108, Germany mDepartment of Environment, Land and Infrastructure Engineering, Politecnico di Torino, Corso Duca degli Abruzzi, 24, 10129 Torino, Italy nUniversity of Turin, Earth Sciences Department (DST), Via Valperga Caluso, 35 – 10125 Torino, Italy oecoinvent association, Technopark, Technoparkstrasse 1, 8005 Zürich, Switzerland pGraduate School of Engineering, The University of Tokyo, Tokyo 113-8656, Japan *Corresponding author: f.lai@brgm.fr This file provides all LCI datasets developed for Lead (Pb), with distinguishing its global market and each individual production route.
B33: Sheet | C33: Corresponding route
B34: Pb_Market_GLO | C34: Pb global market
B35: PR1_Pb_CN_Jiangxi | C35: Pb ore mining and refining in China/Jiangxi
B36: PR2_Pb_CN_South | C36: Pb refining from South China
B37: PR3_Pb_CN_Anhui_Recycling | C37: Pb production in China/Anhui through Pb scraps recycling
B38: PR4_Pb_CN_Guangdong | C38: Pb ore recovery from Zn ore mining in China/Guangdong
B39: PR5_Pb_CN_Smelting | C39: Pb recovery from Zn ore mining and Zn production in China through Smelting
B40: PR6_Pb_RoW | C40: Pb/Zn ore mining and Pb/Zn production in Canada/Peru/Chile/the US
B41: PR7_Pb_SE_Pyro | C41: Pb recovery from Cu ore mining in Sweden/Aitik and Cu production in Sweden/Rönnskärsverken

Sheet Pb_Market_GLO
A1: database | B1: Lead
A3: Activity | B3: Lead (Pb) global market
A4: reference product | B4: Refined Pb
A5: location | B5: GLO
A6: amount | B6: 1
A7: unit | B7: kilogram
A8: comment | B8: n/a
A9: Exchanges
A10: name | B10: reference product | C10: location | D10: amount | E10: unit | F10: database | G10: type | H10: categories | I10: uncertainty type | J10: pedigree | K10: loc | L10: scale | M10: minimum | N10: maximum
A11: =B3 -> Lead (Pb) global market | B11: =B4 -> Refined Pb | C11: =B5 -> GLO | D11: 1 | E11: =B7 -> kilogram | F11: =B1 -> Lead | G11: production
A12: =PR1_Pb_CN_Jiangxi!A84 -> Pb ore mining and refining in China/Jiangxi | B12: =PR1_Pb_CN_Jiangxi!B84 -> Refined Pb | C12: =PR1_Pb_CN_Jiangxi!C84 -> CN | D12: 0.011034327 | E12: =PR1_Pb_CN_Jiangxi!E84 -> kilogram | F12: =PR1_Pb_CN_Jiangxi!F84 -> Lead | G12: technosphere
A13: =PR2_Pb_CN_South!A69 -> Pb refining from South China | B13: =PR2_Pb_CN_South!B69 -> Refined Pb | C13: =PR2_Pb_CN_South!C69 -> CN | D13: 0.011034327 | E13: =PR2_Pb_CN_South!E69 -> kilogram | F13: =PR2_Pb_CN_South!F69 -> Lead | G13: technosphere
A14: =PR3_Pb_CN_Anhui_Recycling!A47 -> Pb production in China/Anhui through Pb scraps recycling | B14: =PR3_Pb_CN_Anhui_Recycling!B47 -> Refined Pb | C14: =PR3_Pb_CN_Anhui_Recycling!C47 -> CN | D14: 0.44158234 | E14: =PR3_Pb_CN_Anhui_Recycling!E47 -> kilogram | F14: =PR3_Pb_CN_Anhui_Recycling!F47 -> Lead | G14: technosphere
A15: =PR4_Pb_CN_Guangdong!A56 -> Pb ore recovery from Zn ore mining in China/Guangdong | B15: =PR4_Pb_CN_Guangdong!B56 -> Refined Pb | C15: =PR4_Pb_CN_Guangdong!C56 -> CN | D15: 0.0107913 | E15: =PR4_Pb_CN_Guangdong!E56 -> kilogram | F15: =PR4_Pb_CN_Guangdong!F56 -> Lead | G15: technosphere
A16: =PR5_Pb_CN_Smelting!A137 -> Pb recovery from Zn ore mining and Zn production in China through Smelting | B16: =PR5_Pb_CN_Smelting!B137 -> Refined Pb | C16: =PR5_Pb_CN_Smelting!C137 -> CN | D16: 0.40872238 | E16: =PR5_Pb_CN_Smelting!E137 -> kilogram | F16: =PR5_Pb_CN_Smelting!F137 -> Lead | G16: technosphere
A17: =PR6_Pb_RoW!A55 -> Pb/Zn ore mining and Pb/Zn production in Canada/Peru/Chile/the US | B17: =PR6_Pb_RoW!B55 -> Refined Pb | C17: =PR6_Pb_RoW!C55 -> RoW | D17: 0.11652867 | E17: =PR6_Pb_RoW!E55 -> kilogram | F17: =PR6_Pb_RoW!F55 -> Lead | G17: technosphere
A18: =PR7_Pb_SE_Pyro!A142 -> Pb recovery from Cu ore mining in Sweden/Aitik and Cu production in Sweden/Rönnskärsverken | B18: =PR7_Pb_SE_Pyro!B142 -> Refined Pb | C18: =PR7_Pb_SE_Pyro!C142 -> SE | D18: 0.0003066544 | E18: =PR7_Pb_SE_Pyro!E142 -> kilogram | F18: =PR7_Pb_SE_Pyro!F142 -> Lead | G18: technosphere

Sheet PR1_Pb_CN_Jiangxi
A1: Activity | B1: [M+C] Lead (Pb) ore mining and concentration (Jiangxi)
A2: reference product | B2: Pb concentrate
A3: location | B3: CN
A4: amount | B4: 1
A5: unit | B5: kilogram
A6: comment | B6: n/a
A7: Exchanges
A8: name | B8: reference product | C8: location | D8: amount | E8: unit | F8: database | G8: type | H8: categories | I8: uncertainty type | J8: pedigree | K8: loc | L8: scale | M8: minimum | N8: maximum
A9: [M+C] Lead (Pb) ore mining and concentration (Jiangxi) | B9: Pb concentrate | C9: CN | D9: 1 | E9: kilogram | F9: =Pb_Market_GLO!B1 -> Lead | G9: production
A10: market group for electricity, medium voltage | B10: electricity, medium voltage | C10: CN | D10: 0.10710667 | E10: kilowatt hour | F10: ecoinvent 3.10 cutoff | G10: technosphere | J10: (1,5,3,1,1)
A11: market for explosive, tovex | B11: explosive, tovex | C11: GLO | D11: 7.3333333e-05 | E11: kilogram | F11: ecoinvent 3.10 cutoff | G11: technosphere | J11: (1,5,3,1,1)
A12: market for sodium ethyl xanthate | B12: sodium ethyl xanthate | C12: GLO | D12: 6.6666667e-06 | E12: kilogram | F12: ecoinvent 3.10 cutoff | G12: technosphere | J12: (1,5,3,1,1)
A13: market for carbon black | B13: carbon black | C13: GLO | D13: 1.6066667e-05 | E13: kilogram | F13: ecoinvent 3.10 cutoff | G13: technosphere | J13: (1,5,3,1,1)
A14: market for lime, packed | B14: lime, packed | C14: RoW | D14: 0.000186 | E14: kilogram | F14: ecoinvent 3.10 cutoff | G14: technosphere | J14: (2,5,3,1,1)
A15: market for light fuel oil | B15: light fuel oil | C15: RoW | D15: 8e-06 | E15: kilogram | F15: ecoinvent 3.10 cutoff | G15: technosphere | J15: (1,5,3,1,1)
A16: market for aniline | B16: aniline | C16: RoW | D16: 1.0733333e-05 | E16: kilogram | F16: ecoinvent 3.10 cutoff | G16: technosphere | J16: (1,5,3,1,1)
A17: market for zinc monosulfate | B17: zinc monosulfate | C17: RoW | D17: 0.00017 | E17: kilogram | F17: ecoinvent 3.10 cutoff | G17: technosphere | J17: (1,5,3,1,1)
A18: market for sodium sulfite | B18: sodium sulfite | C18: RoW | D18: 1.4866667e-05 | E18: kilogram | F18: ecoinvent 3.10 cutoff | G18: technosphere | J18: (1,5,3,1,1)
A19: market for sodium sulfate, anhydrite | B19: sodium sulfate, anhydrite | C19: RoW | D19: 1.6066667e-05 | E19: kilogram | F19: ecoinvent 3.10 cutoff | G19: technosphere | J19: (1,5,3,1,1)
A20: market for copper sulfate | B20: copper sulfate | C20: GLO | D20: 0.000102 | E20: kilogram | F20: ecoinvent 3.10 cutoff | G20: technosphere | J20: (1,5,3,1,1)
A21: market for activated carbon, granular | B21: activated carbon, granular | C21: GLO | D21: 1.6066667e-05 | E21: kilogram | F21: ecoinvent 3.10 cutoff | G21: technosphere | J21: (1,5,3,1,1)
... A25: market for inert waste, for final disposal | B25: inert waste, for final disposal | C25: RoW | D25: -0.75333333 | E25: kilogram | F25: ecoinvent 3.10 cutoff | G25: technosphere | J25: (1,5,3,1,1)
A26: Transformation, from unspecified | D26: 0.0017266667 | E26: square meter | F26: biosphere3 | G26: biosphere | H26: natural resource::land | J26: (1,5,3,1,1)
A27: Transformation, to mineral extraction site | D27: 0.0017266667 | E27: square meter | F27: biosphere3 | G27: biosphere | H27: natural resource::land | J27: (1,5,3,1,1)
A28: Water, unspecified natural origin | D28: 0.00023333333 | E28: cubic meter | F28: biosphere3 | G28: biosphere | H28: natural resource::in ground | J28: (1,5,3,1,1)
A30: Activity | B30: [P+R] Refined Pb production - Pyrometallurgy (Jiangxi)
A31: reference product | B31: Refined Pb
A32: location | B32: CN
A33: amount | B33: 1
A34: unit | B34: kilogram
A35: comment | B35: n/a
A36: Exchanges
A37: name | B37: reference product | C37: location | D37: amount | E37: unit | F37: database | G37: type | H37: categories | I37: uncertainty type | J37: pedigree | K37: loc | L37: scale | M37: minimum | N37: maximum
A38: [P+R] Refined Pb production - Pyrometallurgy (Jiangxi) | B38: Refined Pb | C38: CN | D38: 1 | E38: kilogram | F38: =F9 -> Lead | G38: production
A39: market for silica sand | B39: silica sand | C39: GLO | D39: 0.13 | E39: kilogram | F39: ecoinvent 3.10 cutoff | G39: technosphere | J39: (1,5,3,1,1)
A40: market for limestone, crushed, washed | B40: limestone, crushed, washed | C40: RoW | D40: 0.28 | E40: kilogram | F40: ecoinvent 3.10 cutoff | G40: technosphere | J40: (1,5,3,1,1)
A41: market for coke | B41: coke | C41: CN | D41: 2.31575 | E41: megajoule | F41: ecoinvent 3.10 cutoff | G41: technosphere | J41: (1,5,3,1,1)
A42: market for hard coal | B42: hard coal | C42: CN | D42: 0.32 | E42: kilogram | F42: ecoinvent 3.10 cutoff | G42: technosphere | J42: (1,5,3,1,1)
A43: market for hard coal briquettes | B43: hard coal briquettes | C43: RoW | D43: 1.884 | E43: megajoule | F43: ecoinvent 3.10 cutoff | G43: technosphere | J43: (1,5,3,1,1)
A44: market for sulfur | B44: sulfur | C44: GLO | D44: 0.00093 | E44: kilogram | F44: ecoinvent 3.10 cutoff | G44: technosphere | J44: (2,5,3,5,5)
...

Sheet PR2_Pb_CN_South
A1: Activity | B1: [P+R] Crude Lead (Pb) production - Smelting
A2: reference product | B2: Crude Pb
A3: location | B3: CN
A4: amount | B4: 1
A5: unit | B5: kilogram
A6: comment | B6: n/a
A7: Exchanges
A8: name | B8: reference product | C8: location | D8: amount | E8: unit | F8: database | G8: type | H8: categories | I8: uncertainty type | J8: pedigree | K8: loc | L8: scale | M8: minimum | N8: maximum
A9: [P+R] Crude Lead (Pb) production - Smelting | B9: Crude Pb | C9: CN | D9: 1 | E9: kilogram | F9: =Pb_Market_GLO!B1 -> Lead | G9: production
A10: market for silver, unrefined | B10: silver, unrefined | C10: GLO | D10: 0.79196023 | E10: kilogram | F10: ecoinvent 3.10 cutoff | G10: technosphere | J10: (1,5,1,1,1)
A11: market for limestone, crushed, washed | B11: limestone, crushed, washed | C11: RoW | D11: 0.28332017 | E11: kilogram | F11: ecoinvent 3.10 cutoff | G11: technosphere | J11: (1,5,1,1,1)
A12: market for charcoal | B12: charcoal | C12: GLO | D12: 1.3826024 | E12: kilogram | F12: ecoinvent 3.10 cutoff | G12: technosphere | J12: (1,5,1,1,1)
A13: market for compressed air, 800 kPa gauge | B13: compressed air, 800 kPa gauge | C13: RoW | D13: 1.1717435 | E13: cubic meter | F13: ecoinvent 3.10 cutoff | G13: technosphere | J13: (1,5,1,1,1)
A14: market group for electricity, medium voltage | B14: electricity, medium voltage | C14: CN | D14: 0.02802294 | E14: kilowatt hour | F14: ecoinvent 3.10 cutoff | G14: technosphere | J14: (1,5,1,1,1)
A15: market for nitric acid, without water, in 50% solution state | B15: nitric acid, without water, in 50% solution state | C15: CN | D15: 0.0072117861 | E15: kilogram | F15: ecoinvent 3.10 cutoff | G15: technosphere | J15: (1,5,1,1,1)
A16: market for sulfuric acid | B16: sulfuric acid | C16: RoW | D16: 0.00015110409 | E16: kilogram | F16: ecoinvent 3.10 cutoff | G16: technosphere | J16: (1,5,1,1,1)
A17: market for hydrochloric acid, without water, in 30% solution state | B17: hydrochloric acid, without water, in 30% solution state | C17: RoW | D17: 0.0037776023 | E17: kilogram | F17: ecoinvent 3.10 cutoff | G17: technosphere | J17: (1,5,1,1,1)
A18: market for sulfuric acid | B18: sulfuric acid | C18: RoW | D18: -2.7253683 | E18: kilogram | F18: ecoinvent 3.10 cutoff | G18: technosphere | J18: (1,5,1,1,1)
A19: market group for electricity, medium voltage | B19: electricity, medium voltage | C19: CN | D19: 0.0053916687 | E19: kilowatt hour | F19: ecoinvent 3.10 cutoff | G19: technosphere | J19: (1,5,1,1,1)
A20: market for hard coal briquettes | B20: hard coal briquettes | C20: RoW | D20: 0.22393626 | E20: megajoule | F20: ecoinvent 3.10 cutoff | G20: technosphere | J20: (1,5,1,1,1)
A21: Particulate Matter, > 2.5 um and < 10um | D21: 0.0007612212 | E21: kilogram | F21: biosphere3 | G21: biosphere | H21: air | J21: (1,5,1,1,1)
A22: Sulfur dioxide | D22: 0.010575226 | E22: kilogram | F22: biosphere3 | G22: biosphere | H22: air | J22: (1,5,1,1,1)
A23: Nitrogen oxides | D23: 0.0039877743 | E23: kilogram | F23: biosphere3 | G23: biosphere | H23: air | J23: (1,5,1,1,1)
A25: Activity | B25: [P+R] Refined Pb production - Refining
A26: reference product | B26: Refined Pb
A27: location | B27: CN
A28: amount | B28: 1
A29: unit | B29: kilogram
A30: comment | B30: n/a
A31: Exchanges
A32: name | B32: reference product | C32: location | D32: amount | E32: unit | F32: database | G32: type | H32: categories | I32: uncertainty type | J32: pedigree | K32: loc | L32: scale | M32: minimum | N32: maximum
A33: [P+R] Refined Pb production - Refining | B33: Refined Pb | C33: CN | D33: 1 | E33: kilogram | F33: =F9 -> Lead | G33: production
A34: market for lead | B34: lead | C34: GLO | D34: 0.28 | E34: kilogram | F34: ecoinvent 3.10 cutoff | G34: technosphere | J34: (1,5,1,1,1)
A35: market for sulfur | B35: sulfur | C35: GLO | D35: 0.00108 | E35: kilogram | F35: ecoinvent 3.10 cutoff | G35: technosphere | J35: (1,5,1,1,1)
A36: market for fluosilicic acid, without water, in 22% solution state | B36: fluosilicic acid, without water, in 22% solution state | C36: GLO | D36: 0.01167 | E36: kilogram | F36: ecoinvent 3.10 cutoff | G36: technosphere | J36: (1,5,1,1,1)
A37: market for adhesive, for metal | B37: adhesive, for metal | C37: RoW | D37: 0.0004 | E37: kilogram | F37: ecoinvent 3.10 cutoff | G37: technosphere | J37: (1,5,1,1,1)
A38: market for sodium cumenesulphonate | B38: sodium cumenesulphonate | C38: GLO | D38: 0.0002 | E38: kilogram | F38: ecoinvent 3.10 cutoff | G38: technosphere | J38: (1,5,1,1,1)
A39: market for natural gas, high pressure | B39: natural gas, high pressure | C39: CN | D39: 0.0305 | E39: cubic meter | F39: ecoinvent 3.10 cutoff | G39: technosphere | J39: (1,5,1,1,1)
A40: market group for electricity, medium voltage | B40: electricity, medium voltage | C40: CN | D40: 0.0579 | E40: kilowatt hour | F40: ecoinvent 3.10 cutoff | G40: technosphere | J40: (1,5,1,1,1)
A41: market for lead smelter slag | B41: lead smelter slag | C41: GLO | D41: -0.013593 | E41: kilogram | F41: ecoinvent 3.10 cutoff | G41: technosphere | J41: (1,5,1,1,1)
...

Sheet PR3_Pb_CN_Anhui_Recycling
A1: Activity | B1: [P+R] Lead (Pb) scraps recycling
A2: reference product | B2: Refined Pb
A3: location | B3: CN
A4: amount | B4: 1
A5: unit | B5: kilogram
A6: comment | B6: n/a
A7: Exchanges
A8: name | B8: reference product | C8: location | D8: amount | E8: unit | F8: database | G8: type | H8: categories | I8: uncertainty type | J8: pedigree | K8: loc | L8: scale | M8: minimum | N8: maximum
A9: [P+R] Lead (Pb) scraps recycling | B9: Refined Pb | C9: CN | D9: 1 | E9: kilogram | F9: =Pb_Market_GLO!B1 -> Lead | G9: production
A10: market for hard coal | B10: hard coal | C10: CN | D10: 0.03013 | E10: kilogram | F10: ecoinvent 3.10 cutoff | G10: technosphere | J10: (1,5,3,1,1)
A11: market group for electricity, medium voltage | B11: electricity, medium voltage | C11: CN | D11: 0.05279 | E11: kilowatt hour | F11: ecoinvent 3.10 cutoff | G11: technosphere | J11: (2,5,3,2,2)
A12: market for soda ash, dense | B12: soda ash, dense | C12: GLO | D12: 0.15 | E12: kilogram | F12: ecoinvent 3.10 cutoff | G12: technosphere | J12: (1,5,3,5,5)
A13: market for sodium hydroxide, without water, in 50% solution state | B13: sodium hydroxide, without water, in 50% solution state | C13: RoW | D13: 0.0013 | E13: kilogram | F13: ecoinvent 3.10 cutoff | G13: technosphere | J13: (2,5,3,2,2)
A14: market for iron scrap, unsorted | B14: iron scrap, unsorted | C14: GLO | D14: 0.02688 | E14: kilogram | F14: ecoinvent 3.10 cutoff | G14: technosphere | J14: (1,5,3,2,1)
A15: market for sodium nitrate | B15: sodium nitrate | C15: GLO | D15: 0.00182 | E15: kilogram | F15: ecoinvent 3.10 cutoff | G15: technosphere | J15: (1,5,3,3,1)
A16: market for natural gas, high pressure | B16: natural gas, high pressure | C16: CN | D16: 0.06577 | E16: cubic meter | F16: ecoinvent 3.10 cutoff | G16: technosphere | J16: (1,5,3,2,1)
A17: market for lime, hydrated, packed | B17: lime, hydrated, packed | C17: RoW | D17: 0.00191 | E17: kilogram | F17: ecoinvent 3.10 cutoff | G17: technosphere | J17: (2,5,3,2,2)
A18: market for sulfuric acid | B18: sulfuric acid | C18: RoW | D18: 0.00248 | E18: kilogram | F18: ecoinvent 3.10 cutoff | G18: technosphere | J18: (1,5,3,5,5)
A19: market for polyacrylamide | B19: polyacrylamide | C19: GLO | D19: 6.63e-06 | E19: kilogram | F19: ecoinvent 3.10 cutoff | G19: technosphere | J19: (1,5,3,2,1)
A20: market for phosphate rock, beneficiated | B20: phosphate rock, beneficiated | C20: RoW | D20: 0.00088 | E20: kilogram | F20: ecoinvent 3.10 cutoff | G20: technosphere | J20: (1,5,3,3,1)
A21: market for inert waste, for final disposal | B21: inert waste, for final disposal | C21: RoW | D21: -0.00019 | E21: kilogram | F21: ecoinvent 3.10 cutoff | G21: technosphere | J21: (1,5,3,2,1)
... A26: market for inert waste, for final disposal | B26: inert waste, for final disposal | C26: RoW | D26: -0.00562 | E26: kilogram | F26: ecoinvent 3.10 cutoff | G26: technosphere | J26: (1,5,3,2,1)
A27: Transformation, from unspecified | D27: 3e-05 | E27: square meter | F27: biosphere3 | G27: biosphere | H27: natural resource::land | J27: (1,5,3,1,1)
A28: Transformation, to mineral extraction site | D28: 3e-05 | E28: square meter | F28: biosphere3 | G28: biosphere | H28: natural resource::land | J28: (1,5,3,1,1)
A29: Water, unspecified natural origin | D29: 0.00079 | E29: cubic meter | F29: biosphere3 | G29: biosphere | H29: natural resource::in ground | J29: (1,5,3,2,1)
A30: Carbon dioxide, non-fossil | D30: 0.0243 | E30: kilogram | F30: biosphere3 | G30: biosphere | H30: air | J30: (1,5,3,3,1)
A31: Lead II | D31: 8e-06 | E31: kilogram | F31: biosphere3 | G31: biosphere | H31: air | J31: (1,5,3,3,1)
A32: Particulate Matter, > 2.5 um and < 10um | D32: 0.00044 | E32: kilogram | F32: biosphere3 | G32: biosphere | H32: air | J32: (1,5,3,3,1)
A33: Sulfur dioxide | D33: 0.00138 | E33: kilogram | F33: biosphere3 | G33: biosphere | H33: air | J33: (1,5,3,3,1)
A34: Nitrogen oxides | D34: 0.00102 | E34: kilogram | F34: biosphere3 | G34: biosphere | H34: air | J34: (1,5,3,3,1)
A35: Suspended solids, unspecified | D35: 3.69e-06 | E35: kilogram | F35: biosphere3 | G35: biosphere | H35: water | J35: (1,5,3,3,1)
A36: COD, Chemical Oxygen Demand | D36: 4.63e-06 | E36: kilogram | F36: biosphere3 | G36: biosphere | H36: water | J36: (1,5,3,3,1)
A37: Ammonium | D37: 6.25e-07 | E37: kilogram | F37: biosphere3 | G37: biosphere | H37: water | J37: (1,5,3,2,1)
A39: Activity | B39: Pb production in China/Anhui through Pb scraps recycling
A40: reference product | B40: Refined Pb
A41: location | B41: CN
A42: amount | B42: 1
A43: unit | B43: kilogram
A44: comment | B44: n/a
A45: Exchanges
...

Sheet PR4_Pb_CN_Guangdong
A1: Activity | B1: [M+C] Zinc (Zn) ore mining and concentration (Guangdong)
A2: reference product | B2: Lead (Pb) concentrate
A3: location | B3: CN
A4: amount | B4: 1
A5: unit | B5: kilogram
A6: comment | B6: Allocated unit process, considering as allocation factors: 56% for Zn (1 kg concentrate), 21% for Pb (0.4 kg concentrate) and 23% for Pb-Zn (0.6 kg bulk concentrate). The co-produced sulfur concentrate is dealt through substitution.
A7: Exchanges
A8: name | B8: reference product | C8: location | D8: amount | E8: unit | F8: database | G8: type | H8: categories | I8: uncertainty type | J8: pedigree | K8: loc | L8: scale | M8: minimum | N8: maximum
A9: =B1 -> [M+C] Zinc (Zn) ore mining and concentration (Guangdong) | B9: =B2 -> Lead (Pb) concentrate | C9: CN | D9: 1 | E9: kilogram | F9: =Pb_Market_GLO!B1 -> Lead | G9: production
A10: market for diesel, burned in building machine | B10: diesel, burned in building machine | C10: GLO | D10: 0.11833873 | E10: megajoule | F10: ecoinvent 3.10 cutoff | G10: technosphere | J10: (1,1,2,1,1)
A11: market group for electricity, medium voltage | B11: electricity, medium voltage | C11: CN | D11: 0.50099308 | E11: kilowatt hour | F11: ecoinvent 3.10 cutoff | G11: technosphere | J11: (1,1,2,1,1)
A12: market for heat, district or industrial, other than natural gas | B12: heat, district or industrial, other than natural gas | C12: RoW | D12: 0.00043169144 | E12: megajoule | F12: ecoinvent 3.10 cutoff | G12: technosphere | J12: (1,1,2,1,1)
A13: market for polymer foaming | B13: polymer foaming | C13: GLO | D13: 1.7789482e-05 | E13: kilogram | F13: ecoinvent 3.10 cutoff | G13: technosphere | J13: (1,1,2,1,1)
A14: market for explosive, tovex | B14: explosive, tovex | C14: GLO | D14: 0.0026813133 | E14: kilogram | F14: ecoinvent 3.10 cutoff | G14: technosphere | J14: (1,1,2,1,1)
A15: market for steel, low-alloyed | B15: steel, low-alloyed | C15: GLO | D15: 0.0022688036 | E15: kilogram | F15: ecoinvent 3.10 cutoff | G15: technosphere | J15: (1,1,2,1,1)
A16: market for synthetic rubber | B16: synthetic rubber | C16: GLO | D16: 0.00025472476 | E16: kilogram | F16: ecoinvent 3.10 cutoff | G16: technosphere | J16: (1,1,2,1,1)
A17: market for particleboard, uncoated | B17: particleboard, uncoated | C17: RoW | D17: 5.7235726e-06 | E17: cubic meter | F17: ecoinvent 3.10 cutoff | G17: technosphere | J17: (1,1,2,1,1)
A18: market for lime, packed | B18: lime, packed | C18: RoW | D18: 0.05285281 | E18: kilogram | F18: ecoinvent 3.10 cutoff | G18: technosphere | J18: (1,1,2,1,1)
A19: market for copper sulfate | B19: copper sulfate | C19: GLO | D19: 0.0032227323 | E19: kilogram | F19: ecoinvent 3.10 cutoff | G19: technosphere | J19: (1,1,2,1,1)
A20: market for sodium ethyl xanthate | B20: sodium ethyl xanthate | C20: GLO | D20: 0.003315547 | E20: kilogram | F20: ecoinvent 3.10 cutoff | G20: technosphere | J20: (1,1,2,1,1)
A21: market for [thio]carbamate-compound | B21: [thio]carbamate-compound | C21: GLO | D21: 0.00059298275 | E21: kilogram | F21: ecoinvent 3.10 cutoff | G21: technosphere | J21: (1,1,2,1,1)
... A30: market for sulfur trioxide | B30: sulfur trioxide | C30: RoW | D30: -1.8562938 | E30: kilogram | F30: ecoinvent 3.10 cutoff | G30: technosphere | J30: (1,1,2,1,1)
A31: Lead | D31: 0.2191458 | E31: kilogram | F31: biosphere3 | G31: biosphere | H31: natural resource::in ground | J31: (1,1,2,1,1)
A32: Zinc | D32: 0.3980719 | E32: kilogram | F32: biosphere3 | G32: biosphere | H32: natural resource::in ground | J32: (1,1,2,1,1)
A33: Sulfur | D33: 1.2710456 | E33: kilogram | F33: biosphere3 | G33: biosphere | H33: natural resource::in ground | J33: (1,1,2,1,1)
A34: Iron | D34: 0.22997418 | E34: kilogram | F34: biosphere3 | G34: biosphere | H34: natural resource::in ground | J34: (1,1,2,1,1)
A35: Silver | D35: 0.00043777596 | E35: kilogram | F35: biosphere3 | G35: biosphere | H35: natural resource::in ground | J35: (1,1,2,1,1)
A36: Gold | D36: 4.1250974e-07 | E36: kilogram | F36: biosphere3 | G36: biosphere | H36: natural resource::in ground | J36: (1,1,2,1,1)
A37: Carbon dioxide, non-fossil | D37: 0.0083533222 | E37: kilogram | F37: biosphere3 | G37: biosphere | H37: air | J37: (1,1,2,1,1)
A38: Carbon monoxide, non-fossil | D38: 0.00028241448 | E38: kilogram | F38: biosphere3 | G38: biosphere | H38: air | J38: (1,1,2,1,1)
A39: Nitrogen oxides | D39: 0.0010012127 | E39: kilogram | F39: biosphere3 | G39: biosphere | H39: air | J39: (1,1,2,1,1)
A40: Sulfur dioxide | D40: 4.0580645e-05 | E40: kilogram | F40: biosphere3 | G40: biosphere | H40: air | J40: (1,1,2,1,1)
A41: Hydrocarbons, aromatic | D41: 2.3822437e-05 | E41: kilogram | F41: biosphere3 | G41: biosphere | H41: air | J41: (1,1,2,1,1)
A42: Particulate Matter, > 2.5 um and < 10um | D42: 0.00026710005 | E42: kilogram | F42: biosphere3 | G42: biosphere | H42: air | J42: (1,1,2,1,1)
... A46: Arsenic ion | D46: 0.0011859655 | E46: kilogram | F46: biosphere3 | G46: biosphere | H46: water | J46: (1,1,2,1,1)
A48: Activity | B48: Pb ore recovery from Zn ore mining in China/Guangdong
A49: reference product | B49: Refined Pb
A50: location | B50: CN
A51: amount | B51: 1
A52: unit | B52: kilogram
...

Sheet PR5_Pb_CN_Smelting
A1: Activity | B1: [M+C] Zinc (Zn) ore mining and concentration (for Smelting)
A2: reference product | B2: Zn concentrate
A3: location | B3: CN
A4: amount | B4: 1
A5: unit | B5: kilogram
A6: comment | B6: In the absence of detailed mass balance for this intermediary product, the reference flow of this unit process is set by default at 1 kg, while the input and ouput flows of the inventory are actually scaled to 1 kg of refined Pb.
A7: Exchanges
A8: name | B8: reference product | C8: location | D8: amount | E8: unit | F8: database | G8: type | H8: categories | I8: uncertainty type | J8: pedigree | K8: loc | L8: scale | M8: minimum | N8: maximum
A9: =B1 -> [M+C] Zinc (Zn) ore mining and concentration (for Smelting) | B9: Zn concentrate | C9: CN | D9: 1 | E9: kilogram | F9: =Pb_Market_GLO!B1 -> Lead | G9: production
A10: market for explosive, tovex | B10: explosive, tovex | C10: GLO | D10: 0.0020259343 | E10: kilogram | F10: ecoinvent 3.10 cutoff | G10: technosphere | J10: (2,1,2,2,2)
A11: market for chemical, inorganic | B11: chemical, inorganic | C11: GLO | D11: 0.01205726 | E11: kilogram | F11: ecoinvent 3.10 cutoff | G11: technosphere | J11: (2,1,2,2,2)
A12: market for chemical, organic | B12: chemical, organic | C12: GLO | D12: 0.00096182707 | E12: kilogram | F12: ecoinvent 3.10 cutoff | G12: technosphere | J12: (2,1,2,2,2)
A13: market for charcoal | B13: charcoal | C13: GLO | D13: 0.00044452539 | E13: kilogram | F13: ecoinvent 3.10 cutoff | G13: technosphere | J13: (2,1,2,2,2)
A14: market for limestone, crushed, washed | B14: limestone, crushed, washed | C14: RoW | D14: 0.0051533475 | E14: kilogram | F14: ecoinvent 3.10 cutoff | G14: technosphere | J14: (2,1,2,2,2)
A15: market for transport, freight, conveyor belt | B15: transport, freight, conveyor belt | C15: GLO | D15: 2.1742656e-09 | E15: ton kilometer | F15: ecoinvent 3.10 cutoff | G15: technosphere | J15: (2,1,2,2,2)
A16: market for transport, freight, lorry, unspecified | B16: transport, freight, lorry, unspecified | C16: RoW | D16: 0.073366359 | E16: ton kilometer | F16: ecoinvent 3.10 cutoff | G16: technosphere | J16: (2,1,2,2,2)
A17: market group for electricity, medium voltage | B17: electricity, medium voltage | C17: CN | D17: 0.2222627 | E17: kilowatt hour | F17: ecoinvent 3.10 cutoff | G17: technosphere | J17: (2,1,2,2,2)
A18: market for diesel, burned in building machine | B18: diesel, burned in building machine | C18: GLO | D18: 0.20456036 | E18: megajoule | F18: ecoinvent 3.10 cutoff | G18: technosphere | J18: (2,1,2,2,2)
A19: market for municipal solid waste | B19: municipal solid waste | C19: RoW | D19: -0.00073956437 | E19: kilogram | F19: ecoinvent 3.10 cutoff | G19: technosphere | J19: (3,1,2,1,1)
A20: market for hazardous waste, for underground deposit | B20: hazardous waste, for underground deposit | C20: RoW | D20: -20.849421 | E20: kilogram | F20: ecoinvent 3.10 cutoff | G20: technosphere | J20: (3,1,2,1,1)
A21: Occupation, mineral extraction site | D21: 0.047796315 | E21: square meter-year | F21: biosphere3 | G21: biosphere | H21: natural resource::land | J21: (2,1,2,2,2)
A22: Water, unspecified natural origin | D22: 0.0020652729 | E22: cubic meter | F22: biosphere3 | G22: biosphere | H22: natural resource::in ground | J22: (2,1,2,2,2)
A23: Particulate Matter, > 2.5 um and < 10um | D23: 4.0440009e-06 | E23: kilogram | F23: biosphere3 | G23: biosphere | H23: air | J23: (3,1,2,1,1)
A24: Sulfur dioxide | D24: 5.192686e-07 | E24: kilogram | F24: biosphere3 | G24: biosphere | H24: air | J24: (3,1,2,1,1)
A25: Lead II | D25: 1.0729584e-05 | E25: kilogram | F25: biosphere3 | G25: biosphere | H25: air | J25: (3,1,2,1,1)
A26: Cadmium II | D26: 1.5342027e-07 | E26: kilogram | F26: biosphere3 | G26: biosphere | H26: air | J26: (3,1,2,1,1)
A27: Arsenic ion | D27: 2.7143586e-07 | E27: kilogram | F27: biosphere3 | G27: biosphere | H27: air | J27: (3,1,2,1,1)
A28: Mercury II | D28: 2.0062651e-07 | E28: kilogram | F28: biosphere3 | G28: biosphere | H28: air | J28: (3,1,2,1,1)
A29: Nitrogen oxides | D29: 4.4649232e-07 | E29: kilogram | F29: biosphere3 | G29: biosphere | H29: air | J29: (3,1,2,1,1)
A30: Particulate Matter, > 2.5 um and < 10um | D30: 3.8571429e-06 | E30: kilogram | F30: biosphere3 | G30: biosphere | H30: air | J30: (3,1,2,1,1)
A31: Ammonia | D31: 4.7717637e-06 | E31: kilogram | F31: biosphere3 | G31: biosphere | H31: air | J31: (3,1,2,1,1)
A32: Hydrogen sulfide | D32: 7.2776281e-08 | E32: kilogram | F32: biosphere3 | G32: biosphere | H32: air | J32: (3,1,2,1,1)
... A62: Mineral oil | D62: 4.3272384e-08 | E62: kilogram | F62: biosphere3 | G62: biosphere | H62: soil::agricultural | J62: (3,1,2,1,1)
A64: Activity | B64: [P+R] Refined Lead (Pb) production - Smelting
A65: reference product | B65: Refined Pb
A66: location | B66: CN
A67: amount | B67: 1
A68: unit | B68: kilogram
A69: comment | B69: Allocated unit process, considering as allocation factors: 54% for Zn (1 kg refined) and 46% for Pb (1.04 kg refined).
A70: Exchanges
...

Sheet PR6_Pb_RoW
A1: Activity | B1: [M+C] Zinc (Zn) ore mining and concentration
A2: reference product | B2: Zn concentrate
A3: location | B3: RoW
A4: amount | B4: 1
A5: unit | B5: kilogram
A6: comment | B6: n/a
A7: Exchanges
A8: name | B8: reference product | C8: location | D8: amount | E8: unit | F8: database | G8: type | H8: categories | I8: uncertainty type | J8: pedigree | K8: loc | L8: scale | M8: minimum | N8: maximum
A9: [M+C] Zinc (Zn) ore mining and concentration | B9: Zn concentrate | C9: RoW | D9: 1 | E9: kilogram | F9: =Pb_Market_GLO!B1 -> Lead | G9: production
A10: heat production, heavy fuel oil, at industrial furnace 1MW | B10: heat, district or industrial, other than natural gas | C10: RoW | D10: 4.0502431 | E10: megajoule | F10: ecoinvent 3.10 cutoff | G10: technosphere | J10: (1,1,5,1,1)
A11: market for sulfidic tailings, from zinc-lead mine operation | B11: sulfidic tailings, from zinc-lead mine operation | C11: RoW | D11: -170.07293 | E11: kilogram | F11: ecoinvent 3.10 cutoff | G11: technosphere | J11: (1,1,5,1,1)
A12: Zinc II | D12: 1.7828201e-05 | E12: kilogram | F12: biosphere3 | G12: biosphere | H12: air | J12: (1,1,5,1,1)
A13: Lead II | D13: 1.0048622e-06 | E13: kilogram | F13: biosphere3 | G13: biosphere | H13: air | J13: (1,1,5,1,1)
A14: Cadmium II | D14: 1.9448947e-07 | E14: kilogram | F14: biosphere3 | G14: biosphere | H14: air | J14: (1,1,5,1,1)
A15: Carbon dioxide, fossil | D15: 0.29011345 | E15: kilogram | F15: biosphere3 | G15: biosphere | H15: air | J15: (1,1,5,1,1)
A16: Particulate Matter, > 10 um | D16: 0.00037212318 | E16: kilogram | F16: biosphere3 | G16: biosphere | H16: air | J16: (1,1,5,1,1)
A17: Sulfur oxides | D17: 0.00023387358 | E17: kilogram | F17: biosphere3 | G17: biosphere | H17: air | J17: (1,1,5,1,1)
A18: Nitrogen oxides | D18: 0.0046139384 | E18: kilogram | F18: biosphere3 | G18: biosphere | H18: air | J18: (1,1,5,1,1)
A19: Lead II | D19: 4.8622366e-09 | E19: kilogram | F19: biosphere3 | G19: biosphere | H19: water | J19: (1,1,5,1,1)
A20: Zinc II | D20: 3.6466775e-07 | E20: kilogram | F20: biosphere3 | G20: biosphere | H20: water | J20: (1,1,5,1,1)
A21: Cadmium II | D21: 3.2414911e-09 | E21: kilogram | F21: biosphere3 | G21: biosphere | H21: water | J21: (1,1,5,1,1)
A23: Activity | B23: [P+R] Refined Lead (Pb) production
A24: reference product | B24: Refined Pb
A25: location | B25: RoW
A26: amount | B26: 1
A27: unit | B27: kilogram
A28: comment | B28: Allocated unit process, considering as allocation factors (AF): 55.37% for Zn (1 kg refined), 12.61% for Pb (0.28 kg refined), 28.81% for Ag (0.002 kg refined), 0.01% for Bi (0.00006 kg refined), 0.62% for In (0.0001 kg refined) and 2.57% for Ge (0.00009 kg refined).
A29: Exchanges
A30: name | B30: reference product | C30: location | D30: amount | E30: unit | F30: database | G30: type | H30: categories | I30: uncertainty type | J30: pedigree | K30: loc | L30: scale | M30: minimum | N30: maximum
A31: =B23 -> [P+R] Refined Lead (Pb) production | B31: =B24 -> Refined Pb | C31: RoW | D31: 1 | E31: kilogram | F31: =F9 -> Lead | G31: production
A32: market group for electricity, medium voltage | B32: electricity, medium voltage | C32: GLO | D32: 4.3648405 | E32: kilowatt hour | F32: ecoinvent 3.10 cutoff | G32: technosphere | J32: (1,1,5,1,1)
A33: heat production, heavy fuel oil, at industrial furnace 1MW | B33: heat, district or industrial, other than natural gas | C33: RoW | D33: 6.8483899 | E33: megajoule | F33: ecoinvent 3.10 cutoff | G33: technosphere | J33: (1,1,5,1,1)
A34: Zinc II | D34: 6.8813004e-06 | E34: kilogram | F34: biosphere3 | G34: biosphere | H34: air | J34: (1,1,5,1,1)
A35: Lead II | D35: 5.6845525e-06 | E35: kilogram | F35: biosphere3 | G35: biosphere | H35: air | J35: (1,1,5,1,1)
A36: Cadmium II | D36: 1.3463414e-07 | E36: kilogram | F36: biosphere3 | G36: biosphere | H36: air | J36: (1,1,5,1,1)
A37: Mercury II | D37: 1.3912194e-07 | E37: kilogram | F37: biosphere3 | G37: biosphere | H37: air | J37: (1,1,5,1,1)
A38: Sulfur dioxide | D38: 0.0052881298 | E38: kilogram | F38: biosphere3 | G38: biosphere | H38: air | J38: (1,1,5,1,1)
A39: Carbon dioxide, fossil | D39: 0.52956095 | E39: kilogram | F39: biosphere3 | G39: biosphere | H39: air | J39: (1,1,5,1,1)
A40: Particulate Matter, > 10 um | D40: 0.00017203251 | E40: kilogram | F40: biosphere3 | G40: biosphere | H40: air | J40: (1,1,5,1,1)
A41: Particulate Matter, < 2.5 um | D41: 0.00010920325 | E41: kilogram | F41: biosphere3 | G41: biosphere | H41: air | J41: (1,1,5,1,1)
...

Sheet PR7_Pb_SE_Pyro
A1: Activity | B1: [M+C] Copper (Cu) ore mining and concentration (Sweden)
A2: reference product | B2: Cu concentrate
A3: location | B3: SE
A4: amount | B4: 1
A5: unit | B5: kilogram
A6: comment | B6: n/a
A7: Exchanges
A8: name | B8: reference product | C8: location | D8: amount | E8: unit | F8: database | G8: type | H8: categories | I8: uncertainty type | J8: pedigree | K8: loc | L8: scale | M8: minimum | N8: maximum
A9: =B1 -> [M+C] Copper (Cu) ore mining and concentration (Sweden) | B9: =B2 -> Cu concentrate | C9: SE | D9: 1 | E9: kilogram | F9: =Pb_Market_GLO!B1 -> Lead | G9: production
A10: market for diesel, burned in building machine | B10: diesel, burned in building machine | C10: GLO | D10: 4.0289823 | E10: megajoule | F10: ecoinvent 3.10 cutoff | G10: technosphere | J10: (1,1,3,1,1)
A11: market for electricity, high voltage | B11: electricity, high voltage | C11: SE | D11: 0.24177706 | E11: kilowatt hour | F11: ecoinvent 3.10 cutoff | G11: technosphere | J11: (1,1,3,1,1)
A12: heat production, wood pellet, at furnace 25kW, state-of-the-art 2014 | B12: heat, central or small-scale, other than natural gas | C12: RoW | D12: 0.025828164 | E12: megajoule | F12: ecoinvent 3.10 cutoff | G12: technosphere | J12: (1,1,3,1,1)
A13: market for explosive, tovex | B13: explosive, tovex | C13: GLO | D13: 0.082326296 | E13: kilogram | F13: ecoinvent 3.10 cutoff | G13: technosphere | J13: (1,1,3,1,1)
A14: market for lime, packed | B14: lime, packed | C14: Europe without Switzerland | D14: 0.025824903 | E14: kilogram | F14: ecoinvent 3.10 cutoff | G14: technosphere | J14: (1,1,3,1,1)
A15: market for sodium chloride, powder | B15: sodium chloride, powder | C15: GLO | D15: 0.0045916737 | E15: kilogram | F15: ecoinvent 3.10 cutoff | G15: technosphere | J15: (1,1,3,1,1)
A16: market for sodium chloride, brine solution | B16: sodium chloride, brine solution | C16: GLO | D16: 0.00019155889 | E16: kilogram | F16: ecoinvent 3.10 cutoff | G16: technosphere | J16: (1,1,3,1,1)
A17: market for electricity, high voltage | B17: electricity, high voltage | C17: SE | D17: 2.2461111 | E17: kilowatt hour | F17: ecoinvent 3.10 cutoff | G17: technosphere | J17: (1,1,3,1,1)
A18: heat production, wood pellet, at furnace 25kW, state-of-the-art 2014 | B18: heat, central or small-scale, other than natural gas | C18: RoW | D18: 0.028657522 | E18: megajoule | F18: ecoinvent 3.10 cutoff | G18: technosphere | J18: (1,1,3,1,1)
A19: market for aluminium hydroxide | B19: aluminium hydroxide | C19: GLO | D19: 2.2827923e-05 | E19: kilogram | F19: ecoinvent 3.10 cutoff | G19: technosphere | J19: (1,1,3,1,1)
A20: market for chemical, inorganic | B20: chemical, inorganic | C20: GLO | D20: 0.0018001448 | E20: kilogram | F20: ecoinvent 3.10 cutoff | G20: technosphere | J20: (1,1,3,1,1)
A21: market for light fuel oil | B21: light fuel oil | C21: Europe without Switzerland | D21: 2.5436829e-06 | E21: kilogram | F21: ecoinvent 3.10 cutoff | G21: technosphere | J21: (1,1,3,1,1)
... A32: treatment of hazardous waste, hazardous waste incineration | B32: hazardous waste, for incineration | C32: Europe without Switzerland | D32: -1.8197116e-05 | E32: kilogram | F32: ecoinvent 3.10 cutoff | G32: technosphere | J32: (1,1,3,1,1)
A33: Occupation, mineral extraction site | D33: 0.081528297 | E33: square meter-year | F33: biosphere3 | G33: biosphere | H33: natural resource::land | J33: (1,1,3,1,1)
A34: Copper | D34: 0.21319389 | E34: kilogram | F34: biosphere3 | G34: biosphere | H34: natural resource::in ground | J34: (1,1,3,1,1)
A35: Water, river | D35: 0.0019566791 | E35: cubic meter | F35: biosphere3 | G35: biosphere | H35: natural resource::in water | J35: (1,1,3,1,1)
A36: Water, well, in ground | D36: 0.00032611319 | E36: cubic meter | F36: biosphere3 | G36: biosphere | H36: natural resource::in water | J36: (1,1,3,1,1)
A37: Nitrogen oxides | D37: 0.00011692462 | E37: kilogram | F37: biosphere3 | G37: biosphere | H37: air | J37: (1,1,3,1,1)
A38: Carbon dioxide, fossil | D38: 0.0012392301 | E38: kilogram | F38: biosphere3 | G38: biosphere | H38: air | J38: (1,1,3,1,1)
A39: Copper ion | D39: 2.8404459e-07 | E39: kilogram | F39: biosphere3 | G39: biosphere | H39: water | J39: (1,1,3,1,1)
A40: Aluminium III | D40: 7.5593037e-06 | E40: kilogram | F40: biosphere3 | G40: biosphere | H40: water | J40: (1,1,3,1,1)
A41: Arsenic ion | D41: 2.5436829e-09 | E41: kilogram | F41: biosphere3 | G41: biosphere | H41: water | J41: (1,1,3,1,1)
A42: Lead II | D42: 9.7833956e-09 | E42: kilogram | F42: biosphere3 | G42: biosphere | H42: water | J42: (1,1,3,1,1)
A43: Cadmium II | D43: 3.2611319e-09 | E43: kilogram | F43: biosphere3 | G43: biosphere | H43: water | J43: (1,1,3,1,1)
A44: Copper ion | D44: 2.4621546e-07 | E44: kilogram | F44: biosphere3 | G44: biosphere | H44: water | J44: (1,1,3,1,1)
... A50: Nitrogen | D50: 0.00016461868 | E50: kilogram | F50: biosphere3 | G50: biosphere | H50: water | J50: (1,1,3,1,1)
A52: Activity | B52: [P+R] Refined Lead (Pb) production - Pyrometallurgy (Sweden)
A53: reference product | B53: Refined Pb
A54: location | B54: SE
A55: amount | B55: 1
A56: unit | B56: kilogram
...
