Workbook
Name NdFeB_grinding_losses_grinding_and_slicing_of_NdFeB: [1]Manufacture!#REF!
Name Shaped_NdFeB_magnet_grinding_and_slicing_of_NdFeB: [1]Manufacture!#REF!

Sheet Note
A1: skip
B2: Life cycle inventories of global metal and mineral supply chains: a comprehensive data review, analysis and processing Frédéric Laia*, Stéphanie Mullera, Audrey Philippea, Robert Istrateb, Brenda Miranda Xicotencatlb, Afsoon Mansouri Askic, Aina Mas Fonsd,a, Juliana Segura-Salazare, Jair Santillán Saldivara, Alexander Cimprichf, Stephen Northeyg, Lígia da Silva Limah, Lieselot Booneh, Ryosuke Yokoii, Kamrul Islami, Ioanna Paschalidouj, Felipe Cerdask,l, Victor Balboa-Espinozae, Anish Koyamparambathd, Diae Henniouia, Victoire Collignona, Aurélien Reysa, Gyslain Ngadi Sakatadim, Jo Dewulfh, Bernhard Steubingb, Christoph Helbigc, Gaétan Lefebvrea, Gian Andrea Blenginin,m, Valeria Supertio, Masaharu Motoshitai, Guido Sonnemannd, Kwame Awuah-Offeij, Steven B. Youngf, Shinsuke Murakamip, Antoine Beylota aBRGM, F-45060 Orléans, France bInstitute of Environmental Sciences (CML), Leiden University, Einsteinweg 2, 2333 CC Leiden, NL cEcological Resource Technology, University of Bayreuth, Universitätstr. 30, 95447 Bayreuth, Germany dUniv. Bordeaux, CNRS, Bordeaux INP, ISM, UMR 5255, F-33400 Talence, France eSustainable Minerals Institute, The University of Queensland, QLD, 4072, Australia fSchool of Environment, Enterprise and Development, University of Waterloo, 200 University Avenue West, Waterloo, Ontario N2L 3G1, Canada gUniversity of Technology Sydney, Institute for Sustainable Futures, Australia hSustainable Systems Engineering (STEN), Department of Green Chemistry and Technology, Faculty of Bioscience Engineering, Ghent University, Coupure Links 653, 9000 Ghent, Belgium iAIST, 305-8569 Tsukuba, Japan jMining & Explosives Engineering, Missouri University of Science & Technology, Rolla, MO, USA 65409 kInstitute for Sustainable Energy Systems (INSYS), Technical University of Applied Sciences Würzburg-Schweinfurt (THWS), Ignaz-Schön-Straße 11, Schweinfurt, Germany lFraunhofer Institute for Surface Engineering and Thin Films IST, Riedenkamp 2, Braunschweig 38108, Germany mDepartment of Environment, Land and Infrastructure Engineering, Politecnico di Torino, Corso Duca degli Abruzzi, 24, 10129 Torino, Italy nUniversity of Turin, Earth Sciences Department (DST), Via Valperga Caluso, 35 – 10125 Torino, Italy oecoinvent association, Technopark, Technoparkstrasse 1, 8005 Zürich, Switzerland pGraduate School of Engineering, The University of Tokyo, Tokyo 113-8656, Japan *Corresponding author: f.lai@brgm.fr This file provides all LCI datasets developed for Rare Earths (RE), with distinguishing its global market and each individual production route. Disaggregation of each RE element is also provided in each dataset.
B33: Sheet | C33: Corresponding route
B34: RE_Market_GLO | C34: RE global market
B35: PR1_REO_CN_Sichuan_Bastnaesite | C35: Bastnaesite ore mining and REO production in China/Sichuan
B36: PR2_REO_US_Mt.Pass_Bastnaesite | C36: Bastnaesite ore mining and REO production in the US/Mt. Pass
B37: PR3_REO_CN_BayanObo_Bast-Mona | C37: Bastnaesite-monazite ore mining and REO production in China/Bayan Obo
B38: PR4_REO_AU-MY_MtWeld_Monazite | C38: Monazite ore mining in Australia/Mt. Weld and REO production in Malaysia
B39: PR5_REO_CN_IAC | C39: REO production from ion-adsorption clays in China

Sheet RE_Market_GLO
A1: database | B1: Rare Earths
A3: Activity | B3: Rare Earths (RE) global market
A4: reference product | B4: Rare Earths oxides (REO)
A5: location | B5: GLO
A6: amount | B6: 1
A7: unit | B7: kilogram
A8: comment | B8: n/a
A9: Exchanges
A10: name | B10: reference product | C10: location | D10: amount | E10: unit | F10: database | G10: type | H10: categories | I10: uncertainty type | J10: pedigree | K10: loc | L10: scale | M10: minimum | N10: maximum
A11: =B3 -> Rare Earths (RE) global market | B11: =B4 -> Rare Earths oxides (REO) | C11: =B5 -> GLO | D11: 1 | E11: =B7 -> kilogram | F11: =B1 -> Rare Earths | G11: production
A12: =PR1_REO_CN_Sichuan_Bastnaesite!A94 -> Bastnaesite ore mining and REO production in China/Sichuan | B12: =PR1_REO_CN_Sichuan_Bastnaesite!B94 -> REO | C12: =PR1_REO_CN_Sichuan_Bastnaesite!C94 -> CN-SWG | D12: 0.27116877 | E12: =PR1_REO_CN_Sichuan_Bastnaesite!E94 -> kilogram | F12: =PR1_REO_CN_Sichuan_Bastnaesite!F94 -> Rare Earths | G12: technosphere
A13: =PR2_REO_US_Mt.Pass_Bastnaesite!A98 -> Bastnaesite ore mining and REO production in the US/Mt. Pass | B13: =PR2_REO_US_Mt.Pass_Bastnaesite!B98 -> REO | C13: =PR2_REO_US_Mt.Pass_Bastnaesite!C98 -> US-WECC | D13: 0.18255531 | E13: =PR2_REO_US_Mt.Pass_Bastnaesite!E98 -> kilogram | F13: =PR2_REO_US_Mt.Pass_Bastnaesite!F98 -> Rare Earths | G13: technosphere
A14: ='PR3_REO_CN_BayanObo_Bast-Mona'!A208 -> Bastnaesite-monazite ore mining and REO production in China/Bayan Obo | B14: ='PR3_REO_CN_BayanObo_Bast-Mona'!B208 -> REO | C14: ='PR3_REO_CN_BayanObo_Bast-Mona'!C208 -> CN | D14: 0.37067068 | E14: ='PR3_REO_CN_BayanObo_Bast-Mona'!E208 -> kilogram | F14: ='PR3_REO_CN_BayanObo_Bast-Mona'!F208 -> Rare Earths | G14: technosphere
A15: ='PR4_REO_AU-MY_MtWeld_Monazite'!A191 -> Monazite ore mining in Australia/Mt. Weld and REO production in Malaysia | B15: ='PR4_REO_AU-MY_MtWeld_Monazite'!B191 -> REO | C15: ='PR4_REO_AU-MY_MtWeld_Monazite'!C191 -> AU-MY | D15: 0.094521024 | E15: ='PR4_REO_AU-MY_MtWeld_Monazite'!E191 -> kilogram | F15: ='PR4_REO_AU-MY_MtWeld_Monazite'!F191 -> Rare Earths | G15: technosphere
A16: =PR5_REO_CN_IAC!A109 -> REO production from ion-adsorption clays in China | B16: =PR5_REO_CN_IAC!B109 -> REO | C16: =PR5_REO_CN_IAC!C109 -> CN | D16: 0.081084212 | E16: =PR5_REO_CN_IAC!E109 -> kilogram | F16: =PR5_REO_CN_IAC!F109 -> Rare Earths | G16: technosphere
A18: Activity | B18: Neodymium (Nd) global market
A19: reference product | B19: Nd oxide (Nd2O3)
A20: location | B20: GLO
A21: amount | B21: 1
A22: unit | B22: kilogram
A23: comment | B23: n/a
A24: Exchanges
A25: name | B25: reference product | C25: location | D25: amount | E25: unit | F25: database | G25: type | H25: categories | I25: uncertainty type | J25: pedigree | K25: loc | L25: scale | M25: minimum | N25: maximum | O25: comment
A26: =B18 -> Neodymium (Nd) global market | B26: =B19 -> Nd oxide (Nd2O3) | C26: =B20 -> GLO | D26: 1 | E26: =B22 -> kilogram | F26: =F11 -> Rare Earths | G26: production
A27: =PR1_REO_CN_Sichuan_Bastnaesite!A216 -> Neodymium oxide (Nd2O3) production in China/Sichuan | B27: =PR1_REO_CN_Sichuan_Bastnaesite!B216 -> Nd2O3 | C27: =PR1_REO_CN_Sichuan_Bastnaesite!C216 -> CN-SWG | D27: 0.27116877 | E27: =PR1_REO_CN_Sichuan_Bastnaesite!E216 -> kilogram | F27: =PR1_REO_CN_Sichuan_Bastnaesite!F216 -> Rare Earths | G27: technosphere
A28: =PR2_REO_US_Mt.Pass_Bastnaesite!A200 -> Neodymium oxide (Nd2O3) production in the US/Mt. Pass | B28: =PR2_REO_US_Mt.Pass_Bastnaesite!B200 -> Nd2O3 | C28: =PR2_REO_US_Mt.Pass_Bastnaesite!C200 -> US-WECC | D28: 0.18255531 | E28: =PR2_REO_US_Mt.Pass_Bastnaesite!E200 -> kilogram | F28: =PR2_REO_US_Mt.Pass_Bastnaesite!F200 -> Rare Earths | G28: technosphere
A29: ='PR3_REO_CN_BayanObo_Bast-Mona'!A223 -> Neodymium oxide (Nd2O3) production in China/Bayan Obo | B29: ='PR3_REO_CN_BayanObo_Bast-Mona'!B223 -> Nd2O3 | C29: ='PR3_REO_CN_BayanObo_Bast-Mona'!C223 -> CN | D29: 0.37067068 | E29: ='PR3_REO_CN_BayanObo_Bast-Mona'!E223 -> kilogram | F29: ='PR3_REO_CN_BayanObo_Bast-Mona'!F223 -> Rare Earths | G29: technosphere
A30: ='PR4_REO_AU-MY_MtWeld_Monazite'!A207 -> Neodymium oxide (Nd2O3) production in Australia/Mt. Weld - Malaysia | B30: ='PR4_REO_AU-MY_MtWeld_Monazite'!B207 -> Nd2O3 | C30: ='PR4_REO_AU-MY_MtWeld_Monazite'!C207 -> AU-MY | D30: 0.094521024 | E30: ='PR4_REO_AU-MY_MtWeld_Monazite'!E207 -> kilogram | F30: ='PR4_REO_AU-MY_MtWeld_Monazite'!F207 -> Rare Earths | G30: technosphere
A31: =PR5_REO_CN_IAC!A121 -> Neodymium oxide (Nd2O3) production from ion-adsorption clays in China | B31: =PR5_REO_CN_IAC!B121 -> Nd2O3 | C31: =PR5_REO_CN_IAC!C121 -> CN | D31: 0.081084212 | E31: =PR5_REO_CN_IAC!E121 -> kilogram | F31: =PR5_REO_CN_IAC!F121 -> Rare Earths | G31: technosphere
A33: Activity | B33: Neodymium (Nd) global market (Nd content)
A34: reference product | B34: Nd content
A35: location | B35: GLO
A36: amount | B36: 1
A37: unit | B37: kilogram
A38: comment | B38: Activity expressed for 1 kg Nd contained
A39: Exchanges
A40: name | B40: reference product | C40: location | D40: amount | E40: unit | F40: database | G40: type | H40: categories | I40: uncertainty type | J40: pedigree | K40: loc | L40: scale | M40: minimum | N40: maximum | O40: comment
A41: =B33 -> Neodymium (Nd) global market (Nd content) | B41: =B34 -> Nd content | C41: =B35 -> GLO | D41: 1 | E41: =B37 -> kilogram | F41: =F26 -> Rare Earths | G41: production
A42: =PR1_REO_CN_Sichuan_Bastnaesite!A227 -> Neodymium oxide (Nd2O3) production in China/Sichuan (Nd content) | B42: =PR1_REO_CN_Sichuan_Bastnaesite!B227 -> Nd2O3 (Nd content) | C42: =PR1_REO_CN_Sichuan_Bastnaesite!C227 -> CN-SWG | D42: 0.27116877 | E42: =PR1_REO_CN_Sichuan_Bastnaesite!E227 -> kilogram | F42: =PR1_REO_CN_Sichuan_Bastnaesite!F227 -> Rare Earths | G42: technosphere
A43: =PR2_REO_US_Mt.Pass_Bastnaesite!A211 -> Neodymium oxide (Nd2O3) production in the US/Mt. Pass (Nd content) | B43: =PR2_REO_US_Mt.Pass_Bastnaesite!B211 -> Nd2O3 (Nd content) | C43: =PR2_REO_US_Mt.Pass_Bastnaesite!C211 -> US-WECC | D43: 0.18255531 | E43: =PR2_REO_US_Mt.Pass_Bastnaesite!E211 -> kilogram | F43: =PR2_REO_US_Mt.Pass_Bastnaesite!F211 -> Rare Earths | G43: technosphere
...

Sheet PR1_REO_CN_Sichuan_Bastnaesite
A1: Activity | B1: [M+C] Bastnaesite ore mining and concentration (Sichuan province)
A2: reference product | B2: Concentrated Rare Earths oxides (REO) mixed (70%)
A3: location | B3: CN-SWG
A4: amount | B4: 1
A5: unit | B5: kilogram
A6: comment | B6: n/a
A7: Exchanges
A8: name | B8: reference product | C8: location | D8: amount | E8: unit | F8: database | G8: type | H8: categories | I8: uncertainty type | J8: pedigree | K8: loc | L8: scale | M8: minimum | N8: maximum | O8: comment
A9: =B1 -> [M+C] Bastnaesite ore mining and concentration (Sichuan province) | B9: =B2 -> Concentrated Rare Earths oxides (REO) mixed (70%) | C9: =B3 -> CN-SWG | D9: 1 | E9: kilogram | F9: =RE_Market_GLO!B1 -> Rare Earths | G9: production
A10: market for iron ore, crude ore, 46% Fe | B10: iron ore, crude ore, 46% Fe | C10: GLO | D10: 16.470588 | E10: kilogram | F10: ecoinvent 3.10 cutoff | G10: technosphere | J10: (1,1,3,1,1) | O10: Proxy to CLCD process "Iron ore-open-pit mining"
A11: market for sulfuric acid | B11: sulfuric acid | C11: RoW | D11: 0.029554412 | E11: kilogram | F11: ecoinvent 3.10 cutoff | G11: technosphere | J11: (4,1,3,5,2)
A12: market for sodium silicate, solid | B12: sodium silicate, solid | C12: RoW | D12: 0.024705882 | E12: kilogram | F12: ecoinvent 3.10 cutoff | G12: technosphere | J12: (4,1,3,5,2)
A13: market for electricity, medium voltage | B13: electricity, medium voltage | C13: CN-SWG | D13: 0.51056471 | E13: kilowatt hour | F13: ecoinvent 3.10 cutoff | G13: technosphere | J13: (4,1,3,5,2)
A14: market for steam, in chemical industry | B14: steam, in chemical industry | C14: RoW | D14: 2.31 | E14: kilogram | F14: ecoinvent 3.10 cutoff | G14: technosphere | J14: (1,1,3,2,1)
A15: market for water, deionised | B15: water, deionised | C15: RoW | D15: 24.242647 | E15: kilogram | F15: ecoinvent 3.10 cutoff | G15: technosphere | J15: (4,1,4,2,1)
A16: Suspended solids, unspecified | D16: 0.0016969853 | E16: kilogram | F16: biosphere3 | G16: biosphere | H16: water | J16: (4,1,4,2,1)
A17: COD, Chemical Oxygen Demand | D17: 0.0019394118 | E17: kilogram | F17: biosphere3 | G17: biosphere | H17: water | J17: (4,1,4,2,1)
A18: Mercury II | D18: 8.4e-07 | E18: kilogram | F18: biosphere3 | G18: biosphere | H18: water | J18: (4,1,4,2,1)
A19: Cadmium II | D19: 1.9394118e-06 | E19: kilogram | F19: biosphere3 | G19: biosphere | H19: water | J19: (4,1,4,2,1)
A20: Lead II | D20: 1.2121324e-05 | E20: kilogram | F20: biosphere3 | G20: biosphere | H20: water | J20: (4,1,4,2,1)
A21: Arsenic ion | D21: 7.2727941e-06 | E21: kilogram | F21: biosphere3 | G21: biosphere | H21: water | J21: (4,1,4,2,1)
A22: Fluoride | D22: 0.00024242647 | E22: kilogram | F22: biosphere3 | G22: biosphere | H22: water | J22: (4,1,4,2,1)
A23: Oils, unspecified | D23: 0.00012121324 | E23: kilogram | F23: biosphere3 | G23: biosphere | H23: water | J23: (4,1,4,2,1)
A24: Phosphorus | D24: 7.2727941e-05 | E24: kilogram | F24: biosphere3 | G24: biosphere | H24: water | J24: (4,1,4,2,1) | O24: originally "Total Phosphorus"
A25: Nitrogen | D25: 0.0012121324 | E25: kilogram | F25: biosphere3 | G25: biosphere | H25: water | J25: (4,1,4,2,1) | O25: originally "Total Nitrogen"
A26: Ammonium | D26: 0.00060606618 | E26: kilogram | F26: biosphere3 | G26: biosphere | H26: water | J26: (4,1,4,2,1) | O26: originally "Ammonia"
A27: Zinc II | D27: 3.6363971e-05 | E27: kilogram | F27: biosphere3 | G27: biosphere | H27: water | J27: (4,1,4,2,1) | O27: originally "Total Zinc"
A28: Thorium-232 | D28: 0.0098371961 | E28: kilo Becquerel | F28: biosphere3 | G28: biosphere | H28: water | J28: (4,1,4,2,1) | O28: Calculated based on 2.42E-06 kg in Lee and Wen (2017), with the mass fraction of Th in thorium oxide being 0.8788, and assuming that 1 kg thorium oxide contains 3566 kBq of Th-232 (Zhang & Sun, 2005; IAEA, 2011).
A29: Uranium-238 | D29: 0.029931664 | E29: kilo Becquerel | F29: biosphere3 | G29: biosphere | H29: water | J29: (4,1,4,2,1) | O29: Calculated based on 2.42E-06 kg in Lee and Wen (2017), with the mass fraction of U in uranium oxide being 0.8480, and assuming that 1 kg uranium oxide contains 10470 kBq of U-238 (IAEA, 2011).
A30: Chromium III | D30: 2.4242647e-05 | E30: kilogram | F30: biosphere3 | G30: biosphere | H30: water | J30: (4,1,4,2,1)
A31: Chromium VI | D31: 7.2727941e-06 | E31: kilogram | F31: biosphere3 | G31: biosphere | H31: water | J31: (4,1,4,2,1)
A32: Particulate Matter, > 2.5 um and < 10um | D32: 0.00039529412 | E32: kilogram | F32: biosphere3 | G32: biosphere | H32: air | J32: (4,1,4,2,1)
A33: Thorium | D33: 4.9411765e-05 | E33: kilogram | F33: biosphere3 | G33: biosphere | H33: air | J33: (4,1,4,2,1)
A34: Uranium | D34: 4.9411765e-07 | E34: kilogram | F34: biosphere3 | G34: biosphere | H34: air | J34: (4,1,4,2,1)
A36: Activity | B36: [P] REO separation (Sichuan province)
A37: reference product | B37: Separated REO mix (100%)
A38: location | B38: CN-SWG
A39: amount | B39: 1
A40: unit | B40: kilogram
A41: comment | B41: The co-produced calcium chloride and ammonium chloride are dealt through substitution.
...

Sheet PR2_REO_US_Mt.Pass_Bastnaesite
A1: Activity | B1: [M] Bastnaesite ore mining (Mountain Pass)
A2: reference product | B2: Bastnaesite ore
A3: location | B3: US-WECC
A4: amount | B4: 1
A5: unit | B5: kilogram
A6: comment | B6: n/a
A7: Exchanges
A8: name | B8: reference product | C8: location | D8: amount | E8: unit | F8: database | G8: type | H8: categories | I8: uncertainty type | J8: pedigree | K8: loc | L8: scale | M8: minimum | N8: maximum
A9: =B1 -> [M] Bastnaesite ore mining (Mountain Pass) | B9: =B2 -> Bastnaesite ore | C9: =B3 -> US-WECC | D9: 1 | E9: kilogram | F9: =RE_Market_GLO!B1 -> Rare Earths | G9: production
A10: market for diesel, burned in building machine | B10: diesel, burned in building machine | C10: GLO | D10: 0.22722401 | E10: megajoule | F10: ecoinvent 3.10 cutoff | G10: technosphere | J10: (4,1,2,5,4)
A11: market for explosive, tovex | B11: explosive, tovex | C11: GLO | D11: 0.00082529475 | E11: kilogram | F11: ecoinvent 3.10 cutoff | G11: technosphere | J11: (5,1,2,5,5)
A12: market for transport, freight, lorry >32 metric ton, EURO3 | B12: transport, freight, lorry >32 metric ton, EURO3 | C12: RoW | D12: 0.0016505895 | E12: ton kilometer | F12: ecoinvent 3.10 cutoff | G12: technosphere | J12: (1,1,2,1,1)
A13: market for mine infrastructure, iron | B13: mine infrastructure, iron | C13: GLO | D13: 1.3933548e-13 | E13: unit | F13: ecoinvent 3.10 cutoff | G13: technosphere | J13: (4,1,2,5,4)
A14: market for lubricating oil | B14: lubricating oil | C14: RoW | D14: 0.00013933548 | E14: kilogram | F14: ecoinvent 3.10 cutoff | G14: technosphere | J14: (4,1,2,5,4)
A15: market for wastewater, average | B15: wastewater, average | C15: RoW | D15: -3.1082529e-05 | E15: cubic meter | F15: ecoinvent 3.10 cutoff | G15: technosphere | J15: (1,1,2,1,1)
A16: market for non-sulfidic overburden, off-site | B16: non-sulfidic overburden, off-site | C16: GLO | D16: -7.6527331 | E16: kilogram | F16: ecoinvent 3.10 cutoff | G16: technosphere | J16: (1,1,2,1,1)
A17: treatment of hazardous waste, hazardous waste incineration | B17: hazardous waste, for incineration | C17: RoW | D17: -0.00013933548 | E17: kilogram | F17: ecoinvent 3.10 cutoff | G17: technosphere | J17: (5,1,2,5,5)
A18: Occupation, mineral extraction site | D18: 5.6377278e-05 | E18: square meter-year | F18: biosphere3 | G18: biosphere | H18: natural resource::land | J18: (1,1,2,1,1)
A19: Transformation, from unspecified | D19: 5.6377278e-05 | E19: square meter | F19: biosphere3 | G19: biosphere | H19: natural resource::land | J19: (1,1,2,1,1)
A20: Transformation, to mineral extraction site | D20: 5.6377278e-05 | E20: square meter | F20: biosphere3 | G20: biosphere | H20: natural resource::land | J20: (1,1,2,1,1)
A21: Particulate Matter, > 2.5 um and < 10um | D21: 0.0024866024 | E21: kilogram | F21: biosphere3 | G21: biosphere | H21: air | J21: (4,1,2,5,4)
A22: Thorium-232 | D22: 0.00018595927 | E22: kilo Becquerel | F22: biosphere3 | G22: biosphere | H22: air | J22: (4,1,2,1,1)
A23: Uranium-238 | D23: 0.00018595927 | E23: kilo Becquerel | F23: biosphere3 | G23: biosphere | H23: air | J23: (4,1,2,1,1)
A25: Activity | B25: [C] Bastnaesite ore crushing (Mountain Pass)
A26: reference product | B26: Crushed bastnaesite ore
A27: location | B27: US-WECC
A28: amount | B28: 1
A29: unit | B29: kilogram
A30: comment | B30: n/a
A31: Exchanges
A32: name | B32: reference product | C32: location | D32: amount | E32: unit | F32: database | G32: type | H32: categories | I32: uncertainty type | J32: pedigree | K32: loc | L32: scale | M32: minimum | N32: maximum
A33: =B25 -> [C] Bastnaesite ore crushing (Mountain Pass) | B33: =B26 -> Crushed bastnaesite ore | C33: =B27 -> US-WECC | D33: 1 | E33: kilogram | F33: =F9 -> Rare Earths | G33: production
A34: market for electricity, medium voltage | B34: electricity, medium voltage | C34: US-WECC | D34: 0.0015005359 | E34: kilowatt hour | F34: ecoinvent 3.10 cutoff | G34: technosphere | J34: (4,1,2,1,1)
A35: market for steel, low-alloyed | B35: steel, low-alloyed | C35: GLO | D35: 3.0332262e-05 | E35: kilogram | F35: ecoinvent 3.10 cutoff | G35: technosphere | J35: (4,1,2,1,1)
A36: market for transport, freight, lorry >32 metric ton, EURO3 | B36: transport, freight, lorry >32 metric ton, EURO3 | C36: RoW | D36: 1.039657e-05 | E36: ton kilometer | F36: ecoinvent 3.10 cutoff | G36: technosphere | J36: (1,1,2,1,1)
A37: Particulate Matter, > 2.5 um and < 10um | D37: 0.0015305466 | E37: kilogram | F37: biosphere3 | G37: biosphere | H37: air | J37: (1,1,2,1,1)
A38: Thorium-232 | D38: 0.00070578778 | E38: kilo Becquerel | F38: biosphere3 | G38: biosphere | H38: air | J38: (4,1,2,1,1)
A39: Uranium-238 | D39: 0.00070578778 | E39: kilo Becquerel | F39: biosphere3 | G39: biosphere | H39: air | J39: (4,1,2,1,1)
A41: Activity | B41: [C] Bastnaesite ore milling and flotation (Mountain Pass)
A42: reference product | B42: Concentrated Rare Earths oxides (REO) mixed
...

Sheet PR3_REO_CN_BayanObo_Bast-Mona
A1: Activity | B1: [M] Bastnaesite-Monazite ore mining (Bayan Obo)
A2: reference product | B2: Bastnaesite-Monazite ore
A3: location | B3: CN
A4: amount | B4: 1
A5: unit | B5: kilogram
A6: comment | B6: n/a
A7: Exchanges
A8: name | B8: reference product | C8: location | D8: amount | E8: unit | F8: database | G8: type | H8: categories | I8: uncertainty type | J8: pedigree | K8: loc | L8: scale | M8: minimum | N8: maximum | O8: comment
A9: =B1 -> [M] Bastnaesite-Monazite ore mining (Bayan Obo) | B9: =B2 -> Bastnaesite-Monazite ore | C9: =B3 -> CN | D9: 1 | E9: kilogram | F9: =RE_Market_GLO!B1 -> Rare Earths | G9: production
A10: market for blasting | B10: blasting | C10: GLO | D10: 0.000168 | E10: kilogram | F10: ecoinvent 3.10 cutoff | G10: technosphere
A11: market for diesel, burned in building machine | B11: diesel, burned in building machine | C11: GLO | D11: 0.0158 | E11: megajoule | F11: ecoinvent 3.10 cutoff | G11: technosphere
A12: diesel, burned in diesel-electric generating set, 10MW | B12: diesel, burned in diesel-electric generating set, 10MW | C12: GLO | D12: 0.00088380837 | E12: megajoule | F12: ecoinvent 3.10 cutoff | G12: technosphere
A13: market for mine infrastructure, iron | B13: mine infrastructure, iron | C13: GLO | D13: 3.65e-16 | E13: unit | F13: ecoinvent 3.10 cutoff | G13: technosphere
A14: market for recultivation, iron mine | B14: recultivation, iron mine | C14: GLO | D14: 4.13e-06 | E14: square meter | F14: ecoinvent 3.10 cutoff | G14: technosphere
A15: Cerium | D15: 0.016516147 | E15: kilogram | F15: biosphere3 | G15: biosphere | H15: natural resource::in ground
A16: Dysprosium | D16: 3.4852715e-06 | E16: kilogram | F16: biosphere3 | G16: biosphere | H16: natural resource::in ground
A17: Erbium | D17: 3.4980793e-06 | E17: kilogram | F17: biosphere3 | G17: biosphere | H17: natural resource::in ground
A18: Europium | D18: 6.2180128e-05 | E18: kilogram | F18: biosphere3 | G18: biosphere | H18: natural resource::in ground
A19: Gadolinium | D19: 0.00024292534 | E19: kilogram | F19: biosphere3 | G19: biosphere | H19: natural resource::in ground
A20: Heat, waste | D20: 0.00513 | E20: megajoule | F20: biosphere3 | G20: biosphere | H20: air::non-urban air or from high stacks
A21: Holmium | D21: 3.4918928e-06 | E21: kilogram | F21: biosphere3 | G21: biosphere | H21: natural resource::in ground
A22: Iron | D22: 0.3 | E22: kilogram | F22: biosphere3 | G22: biosphere | H22: natural resource::in ground
A23: Lanthanum | D23: 0.0085268001 | E23: kilogram | F23: biosphere3 | G23: biosphere | H23: natural resource::in ground
A24: Lutetium | D24: 3.5175238e-06 | E24: kilogram | F24: biosphere3 | G24: biosphere | H24: natural resource::in ground
A25: Neodymium | D25: 0.0056928235 | E25: kilogram | F25: biosphere3 | G25: biosphere | H25: natural resource::in ground
A26: Niobium | D26: 0.0013 | E26: kilogram | F26: biosphere3 | G26: biosphere | H26: natural resource::in ground
... A47: Yttrium | D47: 0.00013543964 | E47: kilogram | F47: biosphere3 | G47: biosphere | H47: natural resource::in ground
A49: Activity | B49: [C] Bastnaesite-Monazite ore concentration (Bayan Obo)
A50: reference product | B50: Rare Earths (RE) concentrate
A51: location | B51: CN
A52: amount | B52: 1
A53: unit | B53: kilogram
A54: comment | B54: Allocated unit process, considering as allocation factors (AF): 91% for RE (1 kg) and 9% for Fe (10.3 kg ore).
A55: Exchanges
A56: name | B56: reference product | C56: location | D56: amount | E56: unit | F56: database | G56: type | H56: categories | I56: uncertainty type | J56: pedigree | K56: loc | L56: scale | M56: minimum | N56: maximum | O56: comment
A57: =B49 -> [C] Bastnaesite-Monazite ore concentration (Bayan Obo) | B57: =B50 -> Rare Earths (RE) concentrate | C57: =B51 -> CN | D57: 1 | E57: kilogram | F57: =F9 -> Rare Earths | G57: production
A58: =A175 -> Production of ammonium hydroxide (10% mass) | B58: =B175 -> ammonium hydroxide (10%) | C58: =C175 -> CN | D58: 0.070399191 | E58: =E175 -> kilogram | F58: =F175 -> Rare Earths | G58: technosphere
A59: market for heat, from steam, in chemical industry | B59: heat, from steam, in chemical industry | C59: RoW | D59: 2.9657531 | E59: megajoule | F59: ecoinvent 3.10 cutoff | G59: technosphere
A60: market group for electricity, medium voltage | B60: electricity, medium voltage | C60: CN | D60: 0.49878576 | E60: kilowatt hour | F60: ecoinvent 3.10 cutoff | G60: technosphere
A61: market for water, deionised | B61: water, deionised | C61: RoW | D61: 26.098628 | E61: kilogram | F61: ecoinvent 3.10 cutoff | G61: technosphere
...

Sheet PR4_REO_AU-MY_MtWeld_Monazite
A1: Activity | B1: [M] Monazite ore mining (Mt. Weld)
A2: reference product | B2: Monazite ore
A3: location | B3: AU
A4: amount | B4: 1
A5: unit | B5: kilogram
A6: comment | B6: n/a
A7: Exchanges
A8: name | B8: reference product | C8: location | D8: amount | E8: unit | F8: database | G8: type | H8: categories | I8: uncertainty type | J8: pedigree | K8: loc | L8: scale | M8: minimum | N8: maximum | O8: comment
A9: =B1 -> [M] Monazite ore mining (Mt. Weld) | B9: =B2 -> Monazite ore | C9: =B3 -> AU | D9: 1 | E9: kilogram | F9: =RE_Market_GLO!B1 -> Rare Earths | G9: production
A10: diesel, burned in diesel-electric generating set, 10MW | B10: diesel, burned in diesel-electric generating set, 10MW | C10: GLO | D10: 0.010070761 | E10: megajoule | F10: ecoinvent 3.10 cutoff | G10: technosphere
A11: lubricating oil production | B11: lubricating oil | C11: RoW | D11: 9.0634441e-05 | E11: kilogram | F11: ecoinvent 3.10 cutoff | G11: technosphere
A12: market for blasting | B12: blasting | C12: GLO | D12: 0.00053247152 | E12: kilogram | F12: ecoinvent 3.10 cutoff | G12: technosphere
A13: market for diesel, burned in building machine | B13: diesel, burned in building machine | C13: GLO | D13: 0.05015024 | E13: megajoule | F13: ecoinvent 3.10 cutoff | G13: technosphere
A14: market for recultivation, iron mine | B14: recultivation, iron mine | C14: GLO | D14: 2.3504532e-09 | E14: square meter | F14: ecoinvent 3.10 cutoff | G14: technosphere
A15: market for transport, freight train | B15: transport, freight train | C15: RoW | D15: 0.0023867069 | E15: ton kilometer | F15: ecoinvent 3.10 cutoff | G15: technosphere
A16: market for transport, freight, lorry 16-32 metric ton, EURO5 | B16: transport, freight, lorry 16-32 metric ton, EURO5 | C16: RoW | D16: 0.0014501511 | E16: ton kilometer | F16: ecoinvent 3.10 cutoff | G16: technosphere
A17: mine construction, iron | B17: mine infrastructure, iron | C17: GLO | D17: 2.9305136e-14 | E17: unit | F17: ecoinvent 3.10 cutoff | G17: technosphere
A18: treatment of wastewater from pig iron production, wastewater treatment | B18: wastewater from pig iron production | C18: RoW | D18: -0.0023746224 | E18: cubic meter | F18: ecoinvent 3.10 cutoff | G18: technosphere
A19: treatment of waste mineral oil, hazardous waste incineration | B19: waste mineral oil | C19: RoW | D19: -9.0634441e-05 | E19: kilogram | F19: ecoinvent 3.10 cutoff | G19: technosphere
A20: Cerium | D20: 0.059516616 | E20: kilogram | F20: biosphere3 | G20: biosphere | H20: natural resource::in ground
A21: Dysprosium | D21: 0.00033534743 | E21: kilogram | F21: biosphere3 | G21: biosphere | H21: natural resource::in ground
A22: Erbium | D22: 8.0664653e-05 | E22: kilogram | F22: biosphere3 | G22: biosphere | H22: natural resource::in ground
A23: Europium | D23: 0.00070392749 | E23: kilogram | F23: biosphere3 | G23: biosphere | H23: natural resource::in ground
A24: Gadolinium | D24: 0.0014561934 | E24: kilogram | F24: biosphere3 | G24: biosphere | H24: natural resource::in ground
A25: Holmium | D25: 4.0181269e-05 | E25: kilogram | F25: biosphere3 | G25: biosphere | H25: natural resource::in ground
A26: Iron | D26: 0.24374979 | E26: kilogram | F26: biosphere3 | G26: biosphere | H26: natural resource::in ground
A27: Lanthanum | D27: 0.03141994 | E27: kilogram | F27: biosphere3 | G27: biosphere | H27: natural resource::in ground
A28: Neodymium | D28: 0.023927492 | E28: kilogram | F28: biosphere3 | G28: biosphere | H28: natural resource::in ground
A29: Niobium | D29: 0.0133 | E29: kilogram | F29: biosphere3 | G29: biosphere | H29: natural resource::in ground
A30: Occupation, mineral extraction site | D30: 1.8688754e-07 | E30: square meter-year | F30: biosphere3 | G30: biosphere | H30: natural resource::land
A31: Particulate Matter, < 2.5 um | D31: 6.7371601e-06 | E31: kilogram | F31: biosphere3 | G31: biosphere | H31: air::low population density, long-term
... A45: Yttrium | D45: 0.00092145015 | E45: kilogram | F45: biosphere3 | G45: biosphere | H45: natural resource::in ground
A47: Activity | B47: [C] Monazite ore crushing and milling (Mt. Weld)
A48: reference product | B48: Monazite ore pulp
A49: location | B49: AU
A50: amount | B50: 1
A51: unit | B51: kilogram
A52: comment | B52: n/a
A53: Exchanges
A54: name | B54: reference product | C54: location | D54: amount | E54: unit | F54: database | G54: type | H54: categories | I54: uncertainty type | J54: pedigree | K54: loc | L54: scale | M54: minimum | N54: maximum | O54: comment
...

Sheet PR5_REO_CN_IAC
A1: Activity | B1: [M+C] Mining and in situ leaching from ion adsorption clay (IAC) deposits
A2: reference product | B2: Rare Earths (RE) concentrate
A3: location | B3: CN
A4: amount | B4: 1
A5: unit | B5: kilogram
A6: comment | B6: n/a
A7: Exchanges
A8: name | B8: reference product | C8: location | D8: amount | E8: unit | F8: database | G8: type | H8: categories | I8: uncertainty type | J8: pedigree | K8: loc | L8: scale | M8: minimum | N8: maximum | O8: comment
A9: =B1 -> [M+C] Mining and in situ leaching from ion adsorption clay (IAC) deposits | B9: =B2 -> Rare Earths (RE) concentrate | C9: =B3 -> CN | D9: 1 | E9: kilogram | F9: =RE_Market_GLO!B1 -> Rare Earths | G9: production
A10: ammonium bicarbonate production | B10: ammonium bicarbonate | C10: RoW | D10: 3.35 | E10: kilogram | F10: ecoinvent 3.10 cutoff | G10: technosphere
A11: ammonium sulfate production | B11: ammonium sulfate | C11: RoW | D11: 38.915248 | E11: kilogram | F11: ecoinvent 3.10 cutoff | G11: technosphere
A12: excavation, hydraulic digger | B12: excavation, hydraulic digger | C12: RoW | D12: 1.15 | E12: cubic meter | F12: ecoinvent 3.10 cutoff | G12: technosphere
A13: extrusion, plastic pipes | B13: extrusion, plastic pipes | C13: RoW | D13: 0.101 | E13: kilogram | F13: ecoinvent 3.10 cutoff | G13: technosphere
A14: heat production, heavy fuel oil, at industrial furnace 1MW | B14: heat, district or industrial, other than natural gas | C14: RoW | D14: 24.3 | E14: megajoule | F14: ecoinvent 3.10 cutoff | G14: technosphere
A15: market for limestone, crushed, for mill | B15: limestone, crushed, for mill | C15: RoW | D15: 0.005 | E15: kilogram | F15: ecoinvent 3.10 cutoff | G15: technosphere
A16: market for water, deionised | B16: water, deionised | C16: RoW | D16: 1000 | E16: kilogram | F16: ecoinvent 3.10 cutoff | G16: technosphere
A17: market group for electricity, medium voltage | B17: electricity, medium voltage | C17: CN | D17: 2.915 | E17: kilowatt hour | F17: ecoinvent 3.10 cutoff | G17: technosphere
A18: polyvinylchloride production, suspension polymerisation | B18: polyvinylchloride, suspension polymerised | C18: RoW | D18: 0.096 | E18: kilogram | F18: ecoinvent 3.10 cutoff | G18: technosphere
A19: sulfuric acid production | B19: sulfuric acid | C19: RoW | D19: 0.525 | E19: kilogram | F19: ecoinvent 3.10 cutoff | G19: technosphere
A20: Aluminium III | D20: 0.004 | E20: kilogram | F20: biosphere3 | G20: biosphere | H20: water
A21: Ammonium | D21: 0.34 | E21: kilogram | F21: biosphere3 | G21: biosphere | H21: water
A22: Carbon dioxide, fossil | D22: 0.95 | E22: kilogram | F22: biosphere3 | G22: biosphere | H22: air
A23: Cerium | D23: 0.060632744 | E23: kilogram | F23: biosphere3 | G23: biosphere | H23: natural resource::in ground
A24: Dysprosium | D24: 0.074537369 | E24: kilogram | F24: biosphere3 | G24: biosphere | H24: natural resource::in ground
A25: Erbium | D25: 0.050003166 | E25: kilogram | F25: biosphere3 | G25: biosphere | H25: natural resource::in ground
A26: Europium | D26: 0.018518857 | E26: kilogram | F26: biosphere3 | G26: biosphere | H26: natural resource::in ground
A27: Gadolinium | D27: 0.11922908 | E27: kilogram | F27: biosphere3 | G27: biosphere | H27: natural resource::in ground
A28: Holmium | D28: 0.014895533 | E28: kilogram | F28: biosphere3 | G28: biosphere | H28: natural resource::in ground
A29: Kaolinite | D29: 766.07269 | E29: kilogram | F29: biosphere3 | G29: biosphere | H29: natural resource::in ground
A30: Lanthanum | D30: 0.5418781 | E30: kilogram | F30: biosphere3 | G30: biosphere | H30: natural resource::in ground
A31: Lutetium | D31: 0.004258212 | E31: kilogram | F31: biosphere3 | G31: biosphere | H31: natural resource::in ground
... A46: Yttrium | D46: 0.44048587 | E46: kilogram | F46: biosphere3 | G46: biosphere | H46: natural resource::in ground
A48: Activity | B48: [P] Solvent extraction and calcination (IAC)
A49: reference product | B49: Separated RE oxides (REO) mix
A50: location | B50: CN
A51: amount | B51: 1
A52: unit | B52: kilogram
A53: comment | B53: n/a
A54: Exchanges
A55: name | B55: reference product | C55: location | D55: amount | E55: unit | F55: database | G55: type | H55: categories | I55: uncertainty type | J55: pedigree | K55: loc | L55: scale | M55: minimum | N55: maximum | O55: comment
...

Sheet AllocationDetails
A1: skip
A2: Rare earth market prices in US$/kg | I2: Allocation table - Mountain Pass
A3: Target metal | B3: Contract official name | C3: Market price average (US$/kg) | D3: Start period | E3: End period | F3: Comment | I3: Target metal | J3: Functional flow | K3: Price (USD/kg) | L3: Quantity | M3: Proceeds | N3: Allocation factor
A4: Cerium (Ce) | B4: Cerium (oxide), min. 99 %, fob China | C4: 2.6756667 | D4: 41275 | E4: 44926 | F4: Calculation 10 year average (Jan 2013- Dec 2022) | I4: Cerium (Ce) | J4: CeO2 | K4: =VLOOKUP(I4,$A$4:$C$19,3,FALSE) -> 2.6756667 | L4: 0.4959 | M4: =IFERROR(K4*L4,0) -> 1.3268631 | N4: =M4/SUM($M$4:$M$18) -> 0.098571334
A5: Dysprosium (Dy) | B5: Dysprosium (oxide), min. 99 % fob China | C5: 279.072 | D5: 41275 | E5: 44926 | F5: Calculation 10 year average (Jan 2013- Dec 2022) | I5: Dysprosium (Dy) | J5: Dy2O3 | K5: =VLOOKUP(I5,$A$4:$C$19,3,FALSE) -> 279.072 | L5: n.a. | M5: =IFERROR(K5*L5,0) -> 0 | N5: =M5/SUM($M$4:$M$18) -> 0
A6: Erbium (Er) | B6: Erbium (oxide), min. 99 % , fob China | C6: 38.016667 | D6: 41275 | E6: 44926 | F6: Calculation 10 year average (Jan 2013- Dec 2022) | I6: Erbium (Er) | J6: Er2O3 | K6: =VLOOKUP(I6,$A$4:$C$19,3,FALSE) -> 38.016667 | L6: n.a. | M6: =IFERROR(K6*L6,0) -> 0 | N6: =M6/SUM($M$4:$M$18) -> 0
A7: Europium (Eu) | B7: Europium (oxide), min. 99 % fob China | C7: 226.9465 | D7: 41275 | E7: 44926 | F7: Calculation 10 year average (Jan 2013- Dec 2022) | I7: Europium (Eu) | J7: Eu2O3 | K7: =VLOOKUP(I7,$A$4:$C$19,3,FALSE) -> 226.9465 | L7: 0.0011 | M7: =IFERROR(K7*L7,0) -> 0.24964115 | N7: =M7/SUM($M$4:$M$18) -> 0.018545592
A8: Lanthanum (La) | B8: Lanthanum (oxide), min. 99 %, fob China | C8: 2.7781667 | D8: 41275 | E8: 44926 | F8: Calculation 10 year average (Jan 2013- Dec 2022) | I8: Lanthanum (La) | J8: La2O3 | K8: =VLOOKUP(I8,$A$4:$C$19,3,FALSE) -> 2.7781667 | L8: 0.3379 | M8: =IFERROR(K8*L8,0) -> 0.93874252 | N8: =M8/SUM($M$4:$M$18) -> 0.069738243
A9: Neodymium (Nd) | B9: Neodymium (oxide), min. 99 % fob China | C9: 67.253 | D9: 41275 | E9: 44926 | F9: Calculation 10 year average (Jan 2013- Dec 2022) | I9: Neodymium (Nd) | J9: Nd2O3 | K9: =VLOOKUP(I9,$A$4:$C$19,3,FALSE) -> 67.253 | L9: 0.1116 | M9: =IFERROR(K9*L9,0) -> 7.5054348 | N9: =M9/SUM($M$4:$M$18) -> 0.55757125
A10: Praseodymium (Pr) | B10: Praseodymium (oxide), min. 99 %, fob China | C10: 81.121 | D10: 41275 | E10: 44926 | F10: Calculation 10 year average (Jan 2013- Dec 2022) | I10: Praseodymium (Pr) | J10: Pr6O11 | K10: =VLOOKUP(I10,$A$4:$C$19,3,FALSE) -> 81.121 | L10: 0.0412 | M10: =IFERROR(K10*L10,0) -> 3.3421852 | N10: =M10/SUM($M$4:$M$18) -> 0.2482876
A11: Samarium (Sm) | B11: Samarium (oxide), min. 99 % fob China | C11: 3.694 | D11: 41275 | E11: 44926 | F11: Calculation 10 year average (Jan 2013- Dec 2022) | I11: Samarium (Sm) | J11: Sm2O3 | K11: =VLOOKUP(I11,$A$4:$C$19,3,FALSE) -> 3.694 | L11: 0.0085 | M11: =IFERROR(K11*L11,0) -> 0.031399 | N11: =M11/SUM($M$4:$M$18) -> 0.0023326003
A12: Terbium (Tb) | B12: Terbium (oxide), min. 99,9 %, fob China | C12: 797.28283 | D12: 41275 | E12: 44926 | F12: Calculation 10 year average (Jan 2013- Dec 2022) | I12: Terbium (Tb) | J12: Tb4O7 | K12: =VLOOKUP(I12,$A$4:$C$19,3,FALSE) -> 797.28283 | L12: n.a. | M12: =IFERROR(K12*L12,0) -> 0 | N12: =M12/SUM($M$4:$M$18) -> 0
A13: Yttrium (Y) | B13: Yttrium (oxide), min. 99.999 %, fob China | C13: 7.804 | D13: 41275 | E13: 44926 | F13: Calculation 10 year average (Jan 2013- Dec 2022) | I13: Yttrium (Y) | J13: Y2O3 | K13: =VLOOKUP(I13,$A$4:$C$19,3,FALSE) -> 7.804 | L13: 0.0013 | M13: =IFERROR(K13*L13,0) -> 0.0101452 | N13: =M13/SUM($M$4:$M$18) -> 0.00075367677
A14: Iron (Fe) | B14: Iron ore (65% Fe); dry price; extrapolated from iron ore (62% Fe), cfr spot. | C14: 0.10007423 | D14: 41275 | E14: 44926 | F14: Calculation 10 year average (Jan 2013- Dec 2022) based on available data (see 'Contract official name') | I14: Gadolinium (Gd) | J14: Gd2O3 | K14: =VLOOKUP(I14,$A$4:$C$19,3,FALSE) -> 26.92 | L14: 0.0021 | M14: =IFERROR(K14*L14,0) -> 0.056532 | N14: =M14/SUM($M$4:$M$18) -> 0.0041997058
A15: Gadolinium (Gd) | B15: Gadolinium oxide 99.5-99.9% ex-works China spot, USD/kg | C15: 26.92 | D15: 2013 | E15: 2023 | F15: Assumed 10 year average (Jan 2013- Dec 2022) based on available data from Argus Media (2024) via BRGM (see 'Contract official name') | I15: Ytterbium (Yb) | J15: Yb2O3 | K15: =VLOOKUP(I15,$A$4:$C$19,3,FALSE) -> 12.18 | L15: n.a. | M15: =IFERROR(K15*L15,0) -> 0 | N15: =M15/SUM($M$4:$M$18) -> 0
A16: Ytterbium (Yb) | B16: Ytterbium oxide Price, CNY/Mt,<99.99%, VAT excluded,Traded price, DDP | C16: 12.18 | D16: 2020 | E16: 2023 | F16: Assumed 10 year average (Jan 2013- Dec 2022) based on available data from SMM (2024) via BRGM (see 'Contract official name') | I16: Lutetium (Lu) | J16: Lu2O3 | K16: =VLOOKUP(I16,$A$4:$C$19,3,FALSE) -> 673 | L16: n.a. | M16: =IFERROR(K16*L16,0) -> 0 | N16: =M16/SUM($M$4:$M$18) -> 0
A17: Lutetium (Lu) | B17: Lutetium oxide Price, CNY/kg, <99.99%, VAT excluded, Traded price, DDP | C17: 673 | D17: 2020 | E17: 2023 | F17: Assumed 10 year average (Jan 2013- Dec 2022) based on available data from SMM (2024) via BRGM (see 'Contract official name') | I17: Holmium (Ho) | J17: Ho2O3 | K17: =VLOOKUP(I17,$A$4:$C$19,3,FALSE) -> 13.67 | L17: n.a. | M17: =IFERROR(K17*L17,0) -> 0 | N17: =M17/SUM($M$4:$M$18) -> 0
A18: Holmium (Ho) | B18: Holmium Oxide Price, CNY/mt, DDP | C18: 13.67 | D18: 2020 | E18: 2023 | F18: Assumed 10 year average (Jan 2013- Dec 2022) based on available data from SMM (2024) via BRGM (see 'Contract official name') | I18: Thulium (Tm) | J18: Tm2O3 | K18: =VLOOKUP(I18,$A$4:$C$19,3,FALSE) -> 110 | L18: n.a. | M18: =IFERROR(K18*L18,0) -> 0 | N18: =M18/SUM($M$4:$M$18) -> 0
A19: Thulium (Tm) | B19: Thulium oxide Ex Works China, incl. 13% VAT. | C19: 110 | D19: 2017 | E19: 2023 | F19: Assumed 10 year average (Jan 2013- Dec 2022) based on available data from Ginger Consulting (2024) via BRGM (see 'Contract official name') | I19: Quantity source: Composition of the REO obtained from Table S2 in the Supplementary material in Marx et al. (2018). The compositon matches the breakdown of the output from the solvent extraction processes in Table S4 (Marx et al. 2018), with the HREE fraction being the sum of europium, samarium, yttrium and gadolinium oxides.
A20: Source: Calculations and assumptions based on data from The World Bank (2025), DERA (2018-2024), SMM (2024), Argus Media (2024) and Ginger Consulting (2024), as in Miranda Xicotencatl (2025) in Zenodo.
I21: Allocation table - Sichuan
I22: Target metal | J22: Functional flow | K22: Price (USD/kg) | L22: Quantity | M22: Proceeds | N22: Allocation factor
I23: Cerium (Ce) | J23: CeO2 | K23: =VLOOKUP(I23,$A$4:$C$19,3,FALSE) -> 2.6756667 | L23: 0.5 | M23: =IFERROR(K23*L23,0) -> 1.3378333 | N23: =M23/SUM($M$23:$M$37) -> 0.077610787
I24: Dysprosium (Dy) | J24: Dy2O3 | K24: =VLOOKUP(I24,$A$4:$C$19,3,FALSE) -> 279.072 | L24: n.a. | M24: =IFERROR(K24*L24,0) -> 0 | N24: =M24/SUM($M$23:$M$37) -> 0
I25: Erbium (Er) | J25: Er2O3 | K25: =VLOOKUP(I25,$A$4:$C$19,3,FALSE) -> 38.016667 | L25: 0.01 | M25: =IFERROR(K25*L25,0) -> 0.38016667 | N25: =M25/SUM($M$23:$M$37) -> 0.022054342
C26: REO breakdown in ore - Mount Weld | I26: Europium (Eu) | J26: Eu2O3 | K26: =VLOOKUP(I26,$A$4:$C$19,3,FALSE) -> 226.9465 | L26: 0.002 | M26: =IFERROR(K26*L26,0) -> 0.453893 | N26: =M26/SUM($M$23:$M$37) -> 0.026331376
C27: Target metal | D27: Functional flow | E27: Quantity | I27: Lanthanum (La) | J27: La2O3 | K27: =VLOOKUP(I27,$A$4:$C$19,3,FALSE) -> 2.7781667 | L27: 0.27 | M27: =IFERROR(K27*L27,0) -> 0.750105 | N27: =M27/SUM($M$23:$M$37) -> 0.043515316
C28: Cerium (Ce) | D28: CeO2 | E28: 0.4755 | I28: Neodymium (Nd) | J28: Nd2O3 | K28: =VLOOKUP(I28,$A$4:$C$19,3,FALSE) -> 67.253 | L28: 0.15 | M28: =IFERROR(K28*L28,0) -> 10.08795 | N28: =M28/SUM($M$23:$M$37) -> 0.58522517
C29: Dysprosium (Dy) | D29: Dy2O3 | E29: 0.0025 | I29: Praseodymium (Pr) | J29: Pr6O11 | K29: =VLOOKUP(I29,$A$4:$C$19,3,FALSE) -> 81.121 | L29: 0.05 | M29: =IFERROR(K29*L29,0) -> 4.05605 | N29: =M29/SUM($M$23:$M$37) -> 0.23530079
C30: Erbium (Er) | D30: Er2O3 | E30: 0.0006 | I30: Samarium (Sm) | J30: Sm2O3 | K30: =VLOOKUP(I30,$A$4:$C$19,3,FALSE) -> 3.694 | L30: 0.011 | M30: =IFERROR(K30*L30,0) -> 0.040634 | N30: =M30/SUM($M$23:$M$37) -> 0.0023572718
C31: Europium (Eu) | D31: Eu2O3 | E31: 0.0053 | I31: Terbium (Tb) | J31: Tb4O7 | K31: =VLOOKUP(I31,$A$4:$C$19,3,FALSE) -> 797.28283 | L31: n.a. | M31: =IFERROR(K31*L31,0) -> 0 | N31: =M31/SUM($M$23:$M$37) -> 0
C32: Lanthanum (La) | D32: La2O3 | E32: 0.2388 | I32: Yttrium (Y) | J32: Y2O3 | K32: =VLOOKUP(I32,$A$4:$C$19,3,FALSE) -> 7.804 | L32: 0.003 | M32: =IFERROR(K32*L32,0) -> 0.023412 | N32: =M32/SUM($M$23:$M$37) -> 0.0013581839
C33: Neodymium (Nd) | D33: Nd2O3 | E33: 0.1812 | I33: Gadolinium (Gd) | J33: Gd2O3 | K33: =VLOOKUP(I33,$A$4:$C$19,3,FALSE) -> 26.92 | L33: 0.004 | M33: =IFERROR(K33*L33,0) -> 0.10768 | N33: =M33/SUM($M$23:$M$37) -> 0.0062467644
C34: Praseodymium (Pr) | D34: Pr6O11 | E34: 0.0516 | I34: Ytterbium (Yb) | J34: Yb2O3 | K34: =VLOOKUP(I34,$A$4:$C$19,3,FALSE) -> 12.18 | L34: n.a. | M34: =IFERROR(K34*L34,0) -> 0 | N34: =M34/SUM($M$23:$M$37) -> 0
C35: Samarium (Sm) | D35: Sm2O3 | E35: 0.0244 | I35: Lutetium (Lu) | J35: Lu2O3 | K35: =VLOOKUP(I35,$A$4:$C$19,3,FALSE) -> 673 | L35: n.a. | M35: =IFERROR(K35*L35,0) -> 0 | N35: =M35/SUM($M$23:$M$37) -> 0
C36: Terbium (Tb) | D36: Tb4O7 | E36: 0.0009 | I36: Holmium (Ho) | J36: Ho2O3 | K36: =VLOOKUP(I36,$A$4:$C$19,3,FALSE) -> 13.67 | L36: n.a. | M36: =IFERROR(K36*L36,0) -> 0 | N36: =M36/SUM($M$23:$M$37) -> 0
C37: Yttrium (Y) | D37: Y2O3 | E37: 0.0076 | I37: Thulium (Tm) | J37: Tm2O3 | K37: =VLOOKUP(I37,$A$4:$C$19,3,FALSE) -> 110 | L37: n.a. | M37: =IFERROR(K37*L37,0) -> 0 | N37: =M37/SUM($M$23:$M$37) -> 0
C38: Gadolinium (Gd) | D38: Gd2O3 | E38: 0.0109 | I38: Quantity source: Composition of the REO produced in Sichuan province as obtained from Table S1-2 in the supplementary material of Lee and Wen (2017).
C39: Ytterbium (Yb) | D39: Yb2O3 | E39: 0.0003
C40: Lutetium (Lu) | D40: Lu2O3 | E40: 0 | I40: Allocation table - Bayan Obo
...
