Workbook

Sheet Note
A1: skip
B2: Life cycle inventories of global metal and mineral supply chains: a comprehensive data review, analysis and processing Frédéric Laia*, Stéphanie Mullera, Audrey Philippea, Robert Istrateb, Brenda Miranda Xicotencatlb, Afsoon Mansouri Askic, Aina Mas Fonsd,a, Juliana Segura-Salazare, Jair Santillán Saldivara, Alexander Cimprichf, Stephen Northeyg, Lígia da Silva Limah, Lieselot Booneh, Ryosuke Yokoii, Kamrul Islami, Ioanna Paschalidouj, Felipe Cerdask,l, Victor Balboa-Espinozae, Anish Koyamparambathd, Diae Henniouia, Victoire Collignona, Aurélien Reysa, Gyslain Ngadi Sakatadim, Jo Dewulfh, Bernhard Steubingb, Christoph Helbigc, Gaétan Lefebvrea, Gian Andrea Blenginin,m, Valeria Supertio, Masaharu Motoshitai, Guido Sonnemannd, Kwame Awuah-Offeij, Steven B. Youngf, Shinsuke Murakamip, Antoine Beylota aBRGM, F-45060 Orléans, France bInstitute of Environmental Sciences (CML), Leiden University, Einsteinweg 2, 2333 CC Leiden, NL cEcological Resource Technology, University of Bayreuth, Universitätstr. 30, 95447 Bayreuth, Germany dUniv. Bordeaux, CNRS, Bordeaux INP, ISM, UMR 5255, F-33400 Talence, France eSustainable Minerals Institute, The University of Queensland, QLD, 4072, Australia fSchool of Environment, Enterprise and Development, University of Waterloo, 200 University Avenue West, Waterloo, Ontario N2L 3G1, Canada gUniversity of Technology Sydney, Institute for Sustainable Futures, Australia hSustainable Systems Engineering (STEN), Department of Green Chemistry and Technology, Faculty of Bioscience Engineering, Ghent University, Coupure Links 653, 9000 Ghent, Belgium iAIST, 305-8569 Tsukuba, Japan jMining & Explosives Engineering, Missouri University of Science & Technology, Rolla, MO, USA 65409 kInstitute for Sustainable Energy Systems (INSYS), Technical University of Applied Sciences Würzburg-Schweinfurt (THWS), Ignaz-Schön-Straße 11, Schweinfurt, Germany lFraunhofer Institute for Surface Engineering and Thin Films IST, Riedenkamp 2, Braunschweig 38108, Germany mDepartment of Environment, Land and Infrastructure Engineering, Politecnico di Torino, Corso Duca degli Abruzzi, 24, 10129 Torino, Italy nUniversity of Turin, Earth Sciences Department (DST), Via Valperga Caluso, 35 – 10125 Torino, Italy oecoinvent association, Technopark, Technoparkstrasse 1, 8005 Zürich, Switzerland pGraduate School of Engineering, The University of Tokyo, Tokyo 113-8656, Japan *Corresponding author: f.lai@brgm.fr This file provides all LCI datasets developed for Antimony (Sb), with distinguishing its global market and each individual production route.
B33: Sheet | C33: Corresponding route
B34: Sb_Market_GLO | C34: Sb global market
B35: PR1_Sb_CN | C35: Stibnite ore mining and Sb production in China

Sheet Sb_Market_GLO
A1: database | B1: Antimony
A3: Activity | B3: Antimony (Sb) global market
A4: reference product | B4: Refined Sb
A5: location | B5: GLO
A6: amount | B6: 1
A7: unit | B7: kilogram
A8: comment | B8: n/a
A9: Exchanges
A10: name | B10: reference product | C10: location | D10: amount | E10: unit | F10: database | G10: type | H10: categories | I10: uncertainty type | J10: pedigree | K10: loc | L10: scale | M10: minimum | N10: maximum
A11: =B3 -> Antimony (Sb) global market | B11: =B4 -> Refined Sb | C11: =B5 -> GLO | D11: =B6 -> 1 | E11: =B7 -> kilogram | F11: =B1 -> Antimony | G11: production
A12: =PR1_Sb_CN!A121 -> Stibnite ore mining and Sb production in China | B12: =PR1_Sb_CN!B121 -> Refined Sb | C12: =PR1_Sb_CN!C121 -> CN | D12: =PR1_Sb_CN!D121 -> 1 | E12: =PR1_Sb_CN!E121 -> kilogram | F12: =PR1_Sb_CN!F121 -> Antimony | G12: technosphere

Sheet PR1_Sb_CN
A1: Activity | B1: [M+C] Stibnite ore mining and concentration
A2: reference product | B2: Stibnite concentrate
A3: location | B3: CN
A4: amount | B4: 1
A5: unit | B5: kilogram
A6: comment | B6: n/a
A7: Exchanges
A8: name | B8: reference product | C8: location | D8: amount | E8: unit | F8: database | G8: type | H8: categories | I8: uncertainty type | J8: pedigree | K8: loc | L8: scale | M8: minimum | N8: maximum
A9: =B1 -> [M+C] Stibnite ore mining and concentration | B9: =B2 -> Stibnite concentrate | C9: =B3 -> CN | D9: 1 | E9: kilogram | F9: =Sb_Market_GLO!B1 -> Antimony | G9: production
A10: market group for electricity, medium voltage | B10: electricity, medium voltage | C10: CN | D10: 3.98 | E10: kilowatt hour | F10: ecoinvent 3.10 cutoff | G10: technosphere | J10: (2.0,5.0,5.0,5.0,5.0)
A11: market for limestone, crushed, washed | B11: limestone, crushed, washed | C11: RoW | D11: 0.198 | E11: kilogram | F11: ecoinvent 3.10 cutoff | G11: technosphere | J11: (2.0,5.0,5.0,5.0,5.0)
A12: market for explosive, tovex | B12: explosive, tovex | C12: GLO | D12: 0.157 | E12: kilogram | F12: ecoinvent 3.10 cutoff | G12: technosphere | J12: (2.0,5.0,5.0,5.0,5.0)
A13: market for diesel, burned in building machine | B13: diesel, burned in building machine | C13: GLO | D13: 0.00794 | E13: megajoule | F13: ecoinvent 3.10 cutoff | G13: technosphere | J13: (2.0,5.0,5.0,5.0,5.0)
A14: market for steel, chromium steel 18/8 | B14: steel, chromium steel 18/8 | C14: GLO | D14: 0.117 | E14: kilogram | F14: ecoinvent 3.10 cutoff | G14: technosphere | J14: (2.0,5.0,5.0,5.0,5.0)
A15: market for chemical, inorganic | B15: chemical, inorganic | C15: GLO | D15: 0.121 | E15: kilogram | F15: ecoinvent 3.10 cutoff | G15: technosphere | J15: (2.0,5.0,5.0,5.0,5.0)
A16: market for sodium cyanide | B16: sodium cyanide | C16: RoW | D16: 0.00549 | E16: kilogram | F16: ecoinvent 3.10 cutoff | G16: technosphere | J16: (2.0,5.0,5.0,5.0,5.0)
A17: market for chemical, organic | B17: chemical, organic | C17: GLO | D17: 0.0354 | E17: kilogram | F17: ecoinvent 3.10 cutoff | G17: technosphere | J17: (2.0,5.0,5.0,5.0,5.0)
A18: market for conveyor belt | B18: conveyor belt | C18: GLO | D18: 1.19e-05 | E18: meter | F18: ecoinvent 3.10 cutoff | G18: technosphere | J18: (2.0,5.0,5.0,5.0,5.0)
A19: market for aluminium hydroxide factory | B19: aluminium hydroxide factory | C19: GLO | D19: 1.32e-09 | E19: unit | F19: ecoinvent 3.10 cutoff | G19: technosphere | J19: (2.0,5.0,5.0,5.0,5.0)
A20: market for mine infrastructure, open cast, non-ferrous metal | B20: mine infrastructure, open cast, non-ferrous metal | C20: GLO | D20: 1.73e-09 | E20: unit | F20: ecoinvent 3.10 cutoff | G20: technosphere | J20: (2.0,5.0,5.0,5.0,5.0)
A21: market for mine infrastructure, underground, non-ferrous metal | B21: mine infrastructure, underground, non-ferrous metal | C21: GLO | D21: 7.53e-10 | E21: unit | F21: ecoinvent 3.10 cutoff | G21: technosphere | J21: (2.0,5.0,5.0,5.0,5.0)
A22: market for sulfidic tailings, generic | B22: sulfidic tailings, generic | C22: GLO | D22: -270 | E22: kilogram | F22: ecoinvent 3.10 cutoff | G22: technosphere | J22: (2.0,5.0,5.0,5.0,5.0)
A23: Water, river | D23: 0.232 | E23: cubic meter | F23: biosphere3 | G23: biosphere | H23: natural resource::in water | J23: (2.0,5.0,5.0,5.0,5.0)
A24: Occupation, mineral extraction site | D24: 0.00818 | E24: square meter-year | F24: biosphere3 | G24: biosphere | H24: natural resource::land | J24: (2.0,5.0,5.0,5.0,5.0)
A25: Transformation, to mineral extraction site | D25: 0.000273 | E25: square meter | F25: biosphere3 | G25: biosphere | H25: natural resource::land | J25: (2.0,5.0,5.0,5.0,5.0)
A26: Transformation, from unspecified | D26: 0.000273 | E26: square meter | F26: biosphere3 | G26: biosphere | H26: natural resource::land | J26: (2.0,5.0,5.0,5.0,5.0)
A27: Stibnite | D27: 0.7 | E27: kilogram | F27: biosphere3 | G27: biosphere | H27: natural resource::in ground | J27: (2.0,5.0,5.0,5.0,5.0)
A28: Antimony ion | D28: 1.44e-08 | E28: kilogram | F28: biosphere3 | G28: biosphere | H28: air | J28: (2.0,5.0,5.0,5.0,5.0)
A29: Arsenic ion | D29: 1.09e-07 | E29: kilogram | F29: biosphere3 | G29: biosphere | H29: air | J29: (2.0,5.0,5.0,5.0,5.0)
A30: Cadmium II | D30: 7.94e-09 | E30: kilogram | F30: biosphere3 | G30: biosphere | H30: air | J30: (2.0,5.0,5.0,5.0,5.0)
A31: Carbon dioxide, fossil | D31: 0.087 | E31: kilogram | F31: biosphere3 | G31: biosphere | H31: air | J31: (2.0,5.0,5.0,5.0,5.0)
A32: Chromium III | D32: 7.24e-06 | E32: kilogram | F32: biosphere3 | G32: biosphere | H32: air | J32: (2.0,5.0,5.0,5.0,5.0)
A33: Copper ion | D33: 3.61e-06 | E33: kilogram | F33: biosphere3 | G33: biosphere | H33: air | J33: (2.0,5.0,5.0,5.0,5.0)
A34: Heat, waste | D34: 14.3 | E34: megajoule | F34: biosphere3 | G34: biosphere | H34: air | J34: (2.0,5.0,5.0,5.0,5.0)
... A69: TOC, Total Organic Carbon | D69: 0.000946 | E69: kilogram | F69: biosphere3 | G69: biosphere | H69: water | J69: (2.0,5.0,5.0,5.0,5.0)
A71: Activity | B71: [P+R] Refined Antimony (Sb) production
A72: reference product | B72: Refined Sb
A73: location | B73: CN
A74: amount | B74: 1
A75: unit | B75: kilogram
...
