Workbook

Sheet Note
A1: skip
B2: Life cycle inventories of global metal and mineral supply chains: a comprehensive data review, analysis and processing Frédéric Laia*, Stéphanie Mullera, Audrey Philippea, Robert Istrateb, Brenda Miranda Xicotencatlb, Afsoon Mansouri Askic, Aina Mas Fonsd,a, Juliana Segura-Salazare, Jair Santillán Saldivara, Alexander Cimprichf, Stephen Northeyg, Lígia da Silva Limah, Lieselot Booneh, Ryosuke Yokoii, Kamrul Islami, Ioanna Paschalidouj, Felipe Cerdask,l, Victor Balboa-Espinozae, Anish Koyamparambathd, Diae Henniouia, Victoire Collignona, Aurélien Reysa, Gyslain Ngadi Sakatadim, Jo Dewulfh, Bernhard Steubingb, Christoph Helbigc, Gaétan Lefebvrea, Gian Andrea Blenginin,m, Valeria Supertio, Masaharu Motoshitai, Guido Sonnemannd, Kwame Awuah-Offeij, Steven B. Youngf, Shinsuke Murakamip, Antoine Beylota aBRGM, F-45060 Orléans, France bInstitute of Environmental Sciences (CML), Leiden University, Einsteinweg 2, 2333 CC Leiden, NL cEcological Resource Technology, University of Bayreuth, Universitätstr. 30, 95447 Bayreuth, Germany dUniv. Bordeaux, CNRS, Bordeaux INP, ISM, UMR 5255, F-33400 Talence, France eSustainable Minerals Institute, The University of Queensland, QLD, 4072, Australia fSchool of Environment, Enterprise and Development, University of Waterloo, 200 University Avenue West, Waterloo, Ontario N2L 3G1, Canada gUniversity of Technology Sydney, Institute for Sustainable Futures, Australia hSustainable Systems Engineering (STEN), Department of Green Chemistry and Technology, Faculty of Bioscience Engineering, Ghent University, Coupure Links 653, 9000 Ghent, Belgium iAIST, 305-8569 Tsukuba, Japan jMining & Explosives Engineering, Missouri University of Science & Technology, Rolla, MO, USA 65409 kInstitute for Sustainable Energy Systems (INSYS), Technical University of Applied Sciences Würzburg-Schweinfurt (THWS), Ignaz-Schön-Straße 11, Schweinfurt, Germany lFraunhofer Institute for Surface Engineering and Thin Films IST, Riedenkamp 2, Braunschweig 38108, Germany mDepartment of Environment, Land and Infrastructure Engineering, Politecnico di Torino, Corso Duca degli Abruzzi, 24, 10129 Torino, Italy nUniversity of Turin, Earth Sciences Department (DST), Via Valperga Caluso, 35 – 10125 Torino, Italy oecoinvent association, Technopark, Technoparkstrasse 1, 8005 Zürich, Switzerland pGraduate School of Engineering, The University of Tokyo, Tokyo 113-8656, Japan *Corresponding author: f.lai@brgm.fr This file provides all LCI datasets developed for Selenium (Se), with distinguishing its global market and each individual production route.
B33: Sheet | C33: Corresponding route
B34: Se_Market_GLO | C34: Se global market
B35: PR1_Se_US | C35: Se recovery from Cu production in the US through Pyrometallurgy
B36: PR2_Se_SE_Pyro | C36: Se recovery from Cu production in Sweden/Rönnskärsverken
B37: PR3_Se_CN_CuSlime | C37: Se production in China through Cu anode slime processing

Sheet Se_Market_GLO
A1: database | B1: Selenium
A3: Activity | B3: Selenium (Se) global market
A4: reference product | B4: Refined Se
A5: location | B5: GLO
A6: amount | B6: 1
A7: unit | B7: kilogram
A8: comment | B8: n/a
A9: Exchanges
A10: name | B10: reference product | C10: location | D10: amount | E10: unit | F10: database | G10: type | H10: categories | I10: uncertainty type | J10: pedigree | K10: loc | L10: scale | M10: minimum | N10: maximum
A11: =B3 -> Selenium (Se) global market | B11: =B4 -> Refined Se | C11: =B5 -> GLO | D11: 1 | E11: kilogram | F11: =B1 -> Selenium | G11: production
A12: =PR1_Se_US!A63 -> Se recovery from Cu production in the US through Pyrometallurgy | B12: =PR1_Se_US!B63 -> Refined Se | C12: =PR1_Se_US!C63 -> US | D12: 0.04545 | E12: =PR1_Se_US!E63 -> kilogram | F12: =PR1_Se_US!F63 -> Selenium | G12: technosphere
A13: =PR2_Se_SE_Pyro!A142 -> Se recovery from Cu production in Sweden/Rönnskärsverken | B13: =PR2_Se_SE_Pyro!B142 -> Refined Se | C13: =PR2_Se_SE_Pyro!C142 -> SE | D13: 0.04545 | E13: =PR2_Se_SE_Pyro!E142 -> kilogram | F13: =PR2_Se_SE_Pyro!F142 -> Selenium | G13: technosphere
A14: =PR3_Se_CN_CuSlime!A31 -> Se production in China through Cu anode slime processing | B14: =PR3_Se_CN_CuSlime!B31 -> Refined Se | C14: =PR3_Se_CN_CuSlime!C31 -> CN | D14: 0.9091 | E14: =PR3_Se_CN_CuSlime!E31 -> kilogram | F14: =PR3_Se_CN_CuSlime!F31 -> Selenium | G14: technosphere

Sheet PR1_Se_US
A1: Activity | B1: [M+C] Copper (Cu) ore mining and concentration (United States)
A2: reference product | B2: Cu concentrate
A3: location | B3: US
A4: amount | B4: 1
A5: unit | B5: kilogram
A6: comment | B6: This unit process is allocated, but with unknown allocation factors (not provided in the original data source). In the absence of detailed mass balance for this intermediary product, the reference flow of this unit process is set by default at 1 kg, while the input and ouput flows of the inventory are actually scaled to 1 kg of refined Se.
A7: Exchanges
A8: name | B8: reference product | C8: location | D8: amount | E8: unit | F8: database | G8: type | H8: categories | I8: uncertainty type | J8: pedigree | K8: loc | L8: scale | M8: minimum | N8: maximum
A9: =B1 -> [M+C] Copper (Cu) ore mining and concentration (United States) | B9: =B2 -> Cu concentrate | C9: =B3 -> US | D9: 1 | E9: kilogram | F9: =Se_Market_GLO!B1 -> Selenium | G9: production
A10: market group for electricity, medium voltage | B10: electricity, medium voltage | C10: US | D10: 1.3888889 | E10: kilowatt hour | F10: ecoinvent 3.10 cutoff | G10: technosphere | J10: (4,5,5,1,2)
A11: market for heavy fuel oil, burned in refinery furnace | B11: heavy fuel oil, burned in refinery furnace | C11: GLO | D11: 4.6 | E11: megajoule | F11: ecoinvent 3.10 cutoff | G11: technosphere | J11: (4,5,5,1,2)
A12: Particulate Matter, > 2.5 um and < 10um | D12: 0.000232 | E12: kilogram | F12: biosphere3 | G12: biosphere | H12: air | J12: (3,5,5,1,2)
A14: Activity | B14: [P+R] Refined Selenium (Se) production - Pyrometallurgy
A15: reference product | B15: Refined Se
A16: location | B16: US
A17: amount | B17: 1
A18: unit | B18: kilogram
A19: comment | B19: This unit process is allocated, but with unknown allocation factors (not provided in the original data source).
A20: Exchanges
A21: name | B21: reference product | C21: location | D21: amount | E21: unit | F21: database | G21: type | H21: categories | I21: uncertainty type | J21: pedigree | K21: loc | L21: scale | M21: minimum | N21: maximum
A22: =B14 -> [P+R] Refined Selenium (Se) production - Pyrometallurgy | B22: =B15 -> Refined Se | C22: =B16 -> US | D22: 1 | E22: kilogram | F22: =F9 -> Selenium | G22: production
A23: market group for electricity, medium voltage | B23: electricity, medium voltage | C23: US | D23: 8.1388889 | E23: kilowatt hour | F23: ecoinvent 3.10 cutoff | G23: technosphere | J23: (3,5,5,2,2)
A24: market for hard coal briquettes | B24: hard coal briquettes | C24: RoW | D24: 14.7 | E24: megajoule | F24: ecoinvent 3.10 cutoff | G24: technosphere | J24: (3,5,5,2,2)
A25: market for heat, district or industrial, natural gas | B25: heat, district or industrial, natural gas | C25: RoW | D25: 38.8 | E25: megajoule | F25: ecoinvent 3.10 cutoff | G25: technosphere | J25: (3,5,5,2,2)
A26: market for heavy fuel oil, burned in refinery furnace | B26: heavy fuel oil, burned in refinery furnace | C26: GLO | D26: 6 | E26: megajoule | F26: ecoinvent 3.10 cutoff | G26: technosphere | J26: (3,5,5,2,2)
A27: Sulfur oxides | D27: 0.0086 | E27: kilogram | F27: biosphere3 | G27: biosphere | H27: air | J27: (1,5,5,1,2)
A28: Silver I | D28: 3.1e-06 | E28: kilogram | F28: biosphere3 | G28: biosphere | H28: air | J28: (1,5,5,1,2)
A29: Arsenic ion | D29: 1.14e-05 | E29: kilogram | F29: biosphere3 | G29: biosphere | H29: air | J29: (1,5,5,1,2)
A30: Cadmium II | D30: 1.6e-06 | E30: kilogram | F30: biosphere3 | G30: biosphere | H30: air | J30: (1,5,5,1,2)
A31: Chromium III | D31: 3.1e-06 | E31: kilogram | F31: biosphere3 | G31: biosphere | H31: air | J31: (1,5,5,1,2)
A32: Copper ion | D32: 0.000334 | E32: kilogram | F32: biosphere3 | G32: biosphere | H32: air | J32: (1,5,5,1,2)
A33: Mercury II | D33: 6.2e-08 | E33: kilogram | F33: biosphere3 | G33: biosphere | H33: air | J33: (1,5,5,1,2)
A34: Manganese II | D34: 1.6e-06 | E34: kilogram | F34: biosphere3 | G34: biosphere | H34: air | J34: (1,5,5,1,2)
A35: Nickel II | D35: 3.1e-06 | E35: kilogram | F35: biosphere3 | G35: biosphere | H35: air | J35: (1,5,5,1,2)
A36: Lead II | D36: 5.37e-05 | E36: kilogram | F36: biosphere3 | G36: biosphere | H36: air | J36: (1,5,5,1,2)
A37: Antimony ion | D37: 3.1e-06 | E37: kilogram | F37: biosphere3 | G37: biosphere | H37: air | J37: (1,5,5,1,2)
A38: Selenium IV | D38: 3.1e-06 | E38: kilogram | F38: biosphere3 | G38: biosphere | H38: air | J38: (1,5,5,1,2)
... A53: Zinc II | D53: 4.6e-06 | E53: kilogram | F53: biosphere3 | G53: biosphere | H53: water | J53: (1,5,5,1,2)
A55: Activity | B55: Se recovery from Cu production in the US through Pyrometallurgy
A56: reference product | B56: Refined Se
...

Sheet PR2_Se_SE_Pyro
A1: Activity | B1: [M+C] Copper (Cu) ore mining and concentration (Sweden)
A2: reference product | B2: Cu concentrate
A3: location | B3: SE
A4: amount | B4: 1
A5: unit | B5: kilogram
A6: comment | B6: n/a
A7: Exchanges
A8: name | B8: reference product | C8: location | D8: amount | E8: unit | F8: database | G8: type | H8: categories | I8: uncertainty type | J8: pedigree | K8: loc | L8: scale | M8: minimum | N8: maximum
A9: =B1 -> [M+C] Copper (Cu) ore mining and concentration (Sweden) | B9: =B2 -> Cu concentrate | C9: SE | D9: 1 | E9: kilogram | F9: =Se_Market_GLO!B1 -> Selenium | G9: production
A10: market for diesel, burned in building machine | B10: diesel, burned in building machine | C10: GLO | D10: 4.0289823 | E10: megajoule | F10: ecoinvent 3.10 cutoff | G10: technosphere | J10: (1,1,3,1,1)
A11: market for electricity, high voltage | B11: electricity, high voltage | C11: SE | D11: 0.24177706 | E11: kilowatt hour | F11: ecoinvent 3.10 cutoff | G11: technosphere | J11: (1,1,3,1,1)
A12: heat production, wood pellet, at furnace 25kW, state-of-the-art 2014 | B12: heat, central or small-scale, other than natural gas | C12: RoW | D12: 0.025828164 | E12: megajoule | F12: ecoinvent 3.10 cutoff | G12: technosphere | J12: (1,1,3,1,1)
A13: market for explosive, tovex | B13: explosive, tovex | C13: GLO | D13: 0.082326296 | E13: kilogram | F13: ecoinvent 3.10 cutoff | G13: technosphere | J13: (1,1,3,1,1)
A14: market for lime, packed | B14: lime, packed | C14: Europe without Switzerland | D14: 0.025824903 | E14: kilogram | F14: ecoinvent 3.10 cutoff | G14: technosphere | J14: (1,1,3,1,1)
A15: market for sodium chloride, powder | B15: sodium chloride, powder | C15: GLO | D15: 0.0045916737 | E15: kilogram | F15: ecoinvent 3.10 cutoff | G15: technosphere | J15: (1,1,3,1,1)
A16: market for sodium chloride, brine solution | B16: sodium chloride, brine solution | C16: GLO | D16: 0.00019155889 | E16: kilogram | F16: ecoinvent 3.10 cutoff | G16: technosphere | J16: (1,1,3,1,1)
A17: market for electricity, high voltage | B17: electricity, high voltage | C17: SE | D17: 2.2461111 | E17: kilowatt hour | F17: ecoinvent 3.10 cutoff | G17: technosphere | J17: (1,1,3,1,1)
A18: heat production, wood pellet, at furnace 25kW, state-of-the-art 2014 | B18: heat, central or small-scale, other than natural gas | C18: RoW | D18: 0.028657522 | E18: megajoule | F18: ecoinvent 3.10 cutoff | G18: technosphere | J18: (1,1,3,1,1)
A19: market for aluminium hydroxide | B19: aluminium hydroxide | C19: GLO | D19: 2.2827923e-05 | E19: kilogram | F19: ecoinvent 3.10 cutoff | G19: technosphere | J19: (1,1,3,1,1)
A20: market for chemical, inorganic | B20: chemical, inorganic | C20: GLO | D20: 0.0018001448 | E20: kilogram | F20: ecoinvent 3.10 cutoff | G20: technosphere | J20: (1,1,3,1,1)
A21: market for light fuel oil | B21: light fuel oil | C21: Europe without Switzerland | D21: 2.5436829e-06 | E21: kilogram | F21: ecoinvent 3.10 cutoff | G21: technosphere | J21: (1,1,3,1,1)
... A32: treatment of hazardous waste, hazardous waste incineration | B32: hazardous waste, for incineration | C32: Europe without Switzerland | D32: -1.8197116e-05 | E32: kilogram | F32: ecoinvent 3.10 cutoff | G32: technosphere | J32: (1,1,3,1,1)
A33: Occupation, mineral extraction site | D33: 0.081528297 | E33: square meter-year | F33: biosphere3 | G33: biosphere | H33: natural resource::land | J33: (1,1,3,1,1)
A34: Copper | D34: 0.21319389 | E34: kilogram | F34: biosphere3 | G34: biosphere | H34: natural resource::in ground | J34: (1,1,3,1,1)
A35: Water, river | D35: 0.0019566791 | E35: cubic meter | F35: biosphere3 | G35: biosphere | H35: natural resource::in water | J35: (1,1,3,1,1)
A36: Water, well, in ground | D36: 0.00032611319 | E36: cubic meter | F36: biosphere3 | G36: biosphere | H36: natural resource::in water | J36: (1,1,3,1,1)
A37: Nitrogen oxides | D37: 0.00011692462 | E37: kilogram | F37: biosphere3 | G37: biosphere | H37: air | J37: (1,1,3,1,1)
A38: Carbon dioxide, fossil | D38: 0.0012392301 | E38: kilogram | F38: biosphere3 | G38: biosphere | H38: air | J38: (1,1,3,1,1)
A39: Copper ion | D39: 2.8404459e-07 | E39: kilogram | F39: biosphere3 | G39: biosphere | H39: water | J39: (1,1,3,1,1)
A40: Aluminium III | D40: 7.5593037e-06 | E40: kilogram | F40: biosphere3 | G40: biosphere | H40: water | J40: (1,1,3,1,1)
A41: Arsenic ion | D41: 2.5436829e-09 | E41: kilogram | F41: biosphere3 | G41: biosphere | H41: water | J41: (1,1,3,1,1)
A42: Lead II | D42: 9.7833956e-09 | E42: kilogram | F42: biosphere3 | G42: biosphere | H42: water | J42: (1,1,3,1,1)
A43: Cadmium II | D43: 3.2611319e-09 | E43: kilogram | F43: biosphere3 | G43: biosphere | H43: water | J43: (1,1,3,1,1)
A44: Copper ion | D44: 2.4621546e-07 | E44: kilogram | F44: biosphere3 | G44: biosphere | H44: water | J44: (1,1,3,1,1)
... A50: Nitrogen | D50: 0.00016461868 | E50: kilogram | F50: biosphere3 | G50: biosphere | H50: water | J50: (1,1,3,1,1)
A52: Activity | B52: [P+R] Selenium (Se) production - Pyrometallurgy (Sweden)
A53: reference product | B53: Refined Se
A54: location | B54: SE
A55: amount | B55: 1
A56: unit | B56: kilogram
...

Sheet PR3_Se_CN_CuSlime
A1: Activity | B1: [P+R] Selenium (Se) production (from anode slime)
A2: reference product | B2: Refined Se
A3: location | B3: CN
A4: amount | B4: 1
A5: unit | B5: kilogram
A6: comment | B6: Allocated unit process, considering as allocation factors (AF): 75.4% for Au (1 kg), 22.2% for Ag (23 kg), 1.3% for Te (14 kg CuTe) and 1.1% for Se (27 kg).
A7: Exchanges
A8: name | B8: reference product | C8: location | D8: amount | E8: unit | F8: database | G8: type | H8: categories | I8: uncertainty type | J8: pedigree | K8: loc | L8: scale | M8: minimum | N8: maximum
A9: =B1 -> [P+R] Selenium (Se) production (from anode slime) | B9: =B2 -> Refined Se | C9: =B3 -> CN | D9: 1 | E9: kilogram | F9: =Se_Market_GLO!B1 -> Selenium | G9: production
A10: market for sulfuric acid | B10: sulfuric acid | C10: RoW | D10: 0.0092818745 | E10: kilogram | F10: ecoinvent 3.10 cutoff | G10: technosphere | J10: (1,5,1,1,1)
A11: market for silica sand | B11: silica sand | C11: GLO | D11: 0.011474665 | E11: kilogram | F11: ecoinvent 3.10 cutoff | G11: technosphere | J11: (1,5,1,1,1)
A12: market for soda ash, dense | B12: soda ash, dense | C12: GLO | D12: 0.013116914 | E12: kilogram | F12: ecoinvent 3.10 cutoff | G12: technosphere | J12: (1,5,1,1,1)
A13: market for sodium hydroxide, without water, in 50% solution state | B13: sodium hydroxide, without water, in 50% solution state | C13: RoW | D13: 0.16789135 | E13: kilogram | F13: ecoinvent 3.10 cutoff | G13: technosphere | J13: (1,5,1,1,1)
A14: market for hydrochloric acid, without water, in 30% solution state | B14: hydrochloric acid, without water, in 30% solution state | C14: RoW | D14: 0.0075716856 | E14: kilogram | F14: ecoinvent 3.10 cutoff | G14: technosphere | J14: (1,5,1,1,1)
A15: market for nitric acid, without water, in 50% solution state | B15: nitric acid, without water, in 50% solution state | C15: RoW | D15: 0.0019936586 | E15: kilogram | F15: ecoinvent 3.10 cutoff | G15: technosphere | J15: (1,5,1,1,1)
A16: market for sodium chlorate, powder | B16: sodium chlorate, powder | C16: RoW | D16: 0.00039826317 | E16: kilogram | F16: ecoinvent 3.10 cutoff | G16: technosphere | J16: (1,5,1,1,1)
A17: market for ammonium chloride | B17: ammonium chloride | C17: GLO | D17: 1.4056347e-05 | E17: kilogram | F17: ecoinvent 3.10 cutoff | G17: technosphere | J17: (1,5,1,1,1)
A18: market group for electricity, medium voltage | B18: electricity, medium voltage | C18: CN | D18: 0.73697427 | E18: kilowatt hour | F18: ecoinvent 3.10 cutoff | G18: technosphere | J18: (1,5,1,1,1)
A19: market for copper slag | B19: copper slag | C19: GLO | D19: -0.11253277 | E19: kilogram | F19: ecoinvent 3.10 cutoff | G19: technosphere | J19: (1,5,1,1,1)
A20: Water, unspecified natural origin | D20: 0.00026843172 | E20: cubic meter | F20: biosphere3 | G20: biosphere | H20: natural resource::in ground | J20: (1,5,1,1,1)
A21: Carbon dioxide, fossil | D21: 0.26238046 | E21: kilogram | F21: biosphere3 | G21: biosphere | H21: air | J21: (1,5,1,1,1)
A23: Activity | B23: Se production in China through Cu anode slime processing
A24: reference product | B24: Refined Se
A25: location | B25: CN
A26: amount | B26: 1
A27: unit | B27: kilogram
A28: comment | B28: An ecoinvent activity is here included to model the upstream anode slime production. Applied AF: "Anode slime" input = 1.1%.
A29: Exchanges
A30: name | B30: reference product | C30: location | D30: amount | E30: unit | F30: database | G30: type | H30: categories | I30: uncertainty type | J30: pedigree | K30: loc | L30: scale | M30: minimum | N30: maximum
A31: =B23 -> Se production in China through Cu anode slime processing | B31: =B24 -> Refined Se | C31: =B25 -> CN | D31: 1 | E31: kilogram | F31: =F9 -> Selenium | G31: production
A32: =A9 -> [P+R] Selenium (Se) production (from anode slime) | B32: =B9 -> Refined Se | C32: =C9 -> CN | D32: 1 | E32: =E9 -> kilogram | F32: =F9 -> Selenium | G32: technosphere
A33: market for anode slime from electrorefining of copper, anode | B33: anode slime from electrorefining of copper, anode | C33: GLO | D33: 0.23427245 | E33: kilogram | F33: ecoinvent 3.10 cutoff | G33: technosphere
