Workbook
Name IQ_CH: 110000
Name IQ_CQ: 5000
Name IQ_CY: 10000
Name IQ_DAILY: 500000
Name IQ_FH: 100000
Name IQ_FQ: 500
Name IQ_FY: 1000
Name IQ_LTM: 2000
Name IQ_MONTH: 15000
Name IQ_NTM: 6000
Name IQ_WEEK: 50000
Name IQ_YTD: 3000

Sheet Note
A1: skip
B2: Life cycle inventories of global metal and mineral supply chains: a comprehensive data review, analysis and processing Frédéric Laia*, Stéphanie Mullera, Audrey Philippea, Robert Istrateb, Brenda Miranda Xicotencatlb, Afsoon Mansouri Askic, Aina Mas Fonsd,a, Juliana Segura-Salazare, Jair Santillán Saldivara, Alexander Cimprichf, Stephen Northeyg, Lígia da Silva Limah, Lieselot Booneh, Ryosuke Yokoii, Kamrul Islami, Ioanna Paschalidouj, Felipe Cerdask,l, Victor Balboa-Espinozae, Anish Koyamparambathd, Diae Henniouia, Victoire Collignona, Aurélien Reysa, Gyslain Ngadi Sakatadim, Jo Dewulfh, Bernhard Steubingb, Christoph Helbigc, Gaétan Lefebvrea, Gian Andrea Blenginin,m, Valeria Supertio, Masaharu Motoshitai, Guido Sonnemannd, Kwame Awuah-Offeij, Steven B. Youngf, Shinsuke Murakamip, Antoine Beylota aBRGM, F-45060 Orléans, France bInstitute of Environmental Sciences (CML), Leiden University, Einsteinweg 2, 2333 CC Leiden, NL cEcological Resource Technology, University of Bayreuth, Universitätstr. 30, 95447 Bayreuth, Germany dUniv. Bordeaux, CNRS, Bordeaux INP, ISM, UMR 5255, F-33400 Talence, France eSustainable Minerals Institute, The University of Queensland, QLD, 4072, Australia fSchool of Environment, Enterprise and Development, University of Waterloo, 200 University Avenue West, Waterloo, Ontario N2L 3G1, Canada gUniversity of Technology Sydney, Institute for Sustainable Futures, Australia hSustainable Systems Engineering (STEN), Department of Green Chemistry and Technology, Faculty of Bioscience Engineering, Ghent University, Coupure Links 653, 9000 Ghent, Belgium iAIST, 305-8569 Tsukuba, Japan jMining & Explosives Engineering, Missouri University of Science & Technology, Rolla, MO, USA 65409 kInstitute for Sustainable Energy Systems (INSYS), Technical University of Applied Sciences Würzburg-Schweinfurt (THWS), Ignaz-Schön-Straße 11, Schweinfurt, Germany lFraunhofer Institute for Surface Engineering and Thin Films IST, Riedenkamp 2, Braunschweig 38108, Germany mDepartment of Environment, Land and Infrastructure Engineering, Politecnico di Torino, Corso Duca degli Abruzzi, 24, 10129 Torino, Italy nUniversity of Turin, Earth Sciences Department (DST), Via Valperga Caluso, 35 – 10125 Torino, Italy oecoinvent association, Technopark, Technoparkstrasse 1, 8005 Zürich, Switzerland pGraduate School of Engineering, The University of Tokyo, Tokyo 113-8656, Japan *Corresponding author: f.lai@brgm.fr This file provides all LCI datasets developed for Strontium (Sr), with distinguishing its global market and each individual production route.
B33: Sheet | C33: Corresponding route
B34: Sr_Market_GLO | C34: Sr global market
B35: PR1_SrCO3_GLO | C35: Celestite ore mining and SrCO3 production worldwide

Sheet Sr_Market_GLO
A1: database | B1: Strontium
A3: Activity | B3: Strontium (Sr) global market
A4: reference product | B4: SrCO3
A5: location | B5: GLO
A6: amount | B6: 1
A7: unit | B7: kilogram
A8: comment | B8: n/a
A9: Exchanges
A10: name | B10: reference product | C10: location | D10: amount | E10: unit | F10: database | G10: type | H10: categories | I10: uncertainty type | J10: pedigree | K10: loc | L10: scale | M10: minimum | N10: maximum
A11: =B3 -> Strontium (Sr) global market | B11: =B4 -> SrCO3 | C11: =B5 -> GLO | D11: 1 | E11: =B7 -> kilogram | F11: =B1 -> Strontium | G11: production
A12: =PR1_SrCO3_GLO!A44 -> Celestite ore mining and SrCO3 production worldwide | B12: =PR1_SrCO3_GLO!B44 -> SrCO3 | C12: =PR1_SrCO3_GLO!C44 -> GLO | D12: =PR1_SrCO3_GLO!D44 -> 1 | E12: =PR1_SrCO3_GLO!E44 -> kilogram | F12: =PR1_SrCO3_GLO!F44 -> Strontium | G12: technosphere
A14: Activity | B14: Strontium (Sr) global market (Sr content)
A15: reference product | B15: Sr content
A16: location | B16: GLO
A17: amount | B17: 1
A18: unit | B18: kilogram
A19: comment | B19: Activity expressed for 1 kg Sr contained
A20: Exchanges
A21: name | B21: reference product | C21: location | D21: amount | E21: unit | F21: database | G21: type | H21: categories | I21: uncertainty type | J21: pedigree | K21: loc | L21: scale | M21: minimum | N21: maximum
A22: =B14 -> Strontium (Sr) global market (Sr content) | B22: =B15 -> Sr content | C22: =B16 -> GLO | D22: 1 | E22: =B18 -> kilogram | F22: =F11 -> Strontium | G22: production
A23: =PR1_SrCO3_GLO!A56 -> Celestite ore mining and SrCO3 production worldwide (Sr content) | B23: =PR1_SrCO3_GLO!B56 -> SrCO3 (Sr content) | C23: =PR1_SrCO3_GLO!C56 -> GLO | D23: =PR1_SrCO3_GLO!D56 -> 1 | E23: =PR1_SrCO3_GLO!E56 -> kilogram | F23: =PR1_SrCO3_GLO!F56 -> Strontium | G23: technosphere

Sheet PR1_SrCO3_GLO
A1: Activity | B1: [M+C] Strontium (Sr) ore mining and concentration
A2: reference product | B2: Sr sulfate (SrSO4)
A3: location | B3: GLO
A4: amount | B4: 1
A5: unit | B5: kilogram
A6: comment | B6: n/a
A7: Exchanges
A8: name | B8: reference product | C8: location | D8: amount | E8: unit | F8: database | G8: type | H8: categories | I8: uncertainty type | J8: pedigree | K8: loc | L8: scale | M8: minimum | N8: maximum
A9: =B1 -> [M+C] Strontium (Sr) ore mining and concentration | B9: =B2 -> Sr sulfate (SrSO4) | C9: =B3 -> GLO | D9: 1 | E9: kilogram | F9: =Sr_Market_GLO!B1 -> Strontium | G9: production
A10: market group for electricity, medium voltage | B10: electricity, medium voltage | C10: GLO | D10: 0.84 | E10: kilowatt hour | F10: ecoinvent 3.10 cutoff | G10: technosphere | J10: (4,5,5,5,1)
A11: market for explosive, tovex | B11: explosive, tovex | C11: GLO | D11: 0.011 | E11: kilogram | F11: ecoinvent 3.10 cutoff | G11: technosphere | J11: (4,5,5,5,1)
A12: market for conveyor belt | B12: conveyor belt | C12: GLO | D12: 0.000328 | E12: meter | F12: ecoinvent 3.10 cutoff | G12: technosphere | J12: (4,5,5,5,1)
A13: market for mine infrastructure, open cast, non-ferrous metal | B13: mine infrastructure, open cast, non-ferrous metal | C13: GLO | D13: 2.15e-09 | E13: unit | F13: ecoinvent 3.10 cutoff | G13: technosphere | J13: (4,5,5,5,1)
A14: treatment of non-sulfidic overburden, off-site | B14: non-sulfidic overburden, off-site | C14: GLO | D14: -42.1 | E14: kilogram | F14: ecoinvent 3.10 cutoff | G14: technosphere | J14: (4,5,5,5,1)
A15: Strontium | D15: 20.56 | E15: kilogram | F15: biosphere3 | G15: biosphere | H15: natural resource::in ground | J15: (4,5,5,5,1)
A16: Water, unspecified natural origin | D16: 0.14 | E16: cubic meter | F16: biosphere3 | G16: biosphere | H16: natural resource::in ground | J16: (4,5,5,5,1)
A17: Transformation, from unspecified | D17: 0.00257 | E17: square meter | F17: biosphere3 | G17: biosphere | H17: natural resource::land | J17: (4,5,5,5,1)
A18: Transformation, to mineral extraction site | D18: 0.00257 | E18: square meter | F18: biosphere3 | G18: biosphere | H18: natural resource::land | J18: (4,5,5,5,1)
A19: Transformation, to unspecified | D19: 0.00257 | E19: square meter | F19: biosphere3 | G19: biosphere | H19: natural resource::land | J19: (4,5,5,5,1)
A20: Occupation, mineral extraction site | D20: 0.302 | E20: square meter-year | F20: biosphere3 | G20: biosphere | H20: natural resource::land | J20: (4,5,5,5,1)
A22: Activity | B22: [P] Sr carbonate (SrCO3) production
A23: reference product | B23: SrCO3
A24: location | B24: GLO
A25: amount | B25: 1
A26: unit | B26: kilogram
A27: comment | B27: The co-produced sodium sulfide is dealt through substitution.
A28: Exchanges
A29: name | B29: reference product | C29: location | D29: amount | E29: unit | F29: database | G29: type | H29: categories | I29: uncertainty type | J29: pedigree | K29: loc | L29: scale | M29: minimum | N29: maximum
A30: =B22 -> [P] Sr carbonate (SrCO3) production | B30: =B23 -> SrCO3 | C30: =B24 -> GLO | D30: 1 | E30: kilogram | F30: =F9 -> Strontium | G30: production
A31: heat production, at hard coal industrial furnace 1-10MW | B31: heat, district or industrial, other than natural gas | C31: RoW | D31: 6.14 | E31: megajoule | F31: ecoinvent 3.10 cutoff | G31: technosphere | J31: (4,5,5,5,1)
A32: market for soda ash, dense | B32: soda ash, dense | C32: GLO | D32: 0.85 | E32: kilogram | F32: ecoinvent 3.10 cutoff | G32: technosphere | J32: (4,5,5,5,1)
A33: market for sodium sulfide | B33: sodium sulfide | C33: GLO | D33: -0.5 | E33: kilogram | F33: ecoinvent 3.10 cutoff | G33: technosphere | J33: (4,5,5,5,1)
A34: Carbon dioxide, fossil | D34: 0.71 | E34: kilogram | F34: biosphere3 | G34: biosphere | H34: air | J34: (4,5,5,5,1)
A36: Activity | B36: Celestite ore mining and SrCO3 production worldwide
A37: reference product | B37: SrCO3
A38: location | B38: GLO
A39: amount | B39: 1
A40: unit | B40: kilogram
A41: comment | B41: n/a
A42: Exchanges
...
