Workbook

Sheet Note
A1: skip
B2: Life cycle inventories of global metal and mineral supply chains: a comprehensive data review, analysis and processing Frédéric Laia*, Stéphanie Mullera, Audrey Philippea, Robert Istrateb, Brenda Miranda Xicotencatlb, Afsoon Mansouri Askic, Aina Mas Fonsd,a, Juliana Segura-Salazare, Jair Santillán Saldivara, Alexander Cimprichf, Stephen Northeyg, Lígia da Silva Limah, Lieselot Booneh, Ryosuke Yokoii, Kamrul Islami, Ioanna Paschalidouj, Felipe Cerdask,l, Victor Balboa-Espinozae, Anish Koyamparambathd, Diae Henniouia, Victoire Collignona, Aurélien Reysa, Gyslain Ngadi Sakatadim, Jo Dewulfh, Bernhard Steubingb, Christoph Helbigc, Gaétan Lefebvrea, Gian Andrea Blenginin,m, Valeria Supertio, Masaharu Motoshitai, Guido Sonnemannd, Kwame Awuah-Offeij, Steven B. Youngf, Shinsuke Murakamip, Antoine Beylota aBRGM, F-45060 Orléans, France bInstitute of Environmental Sciences (CML), Leiden University, Einsteinweg 2, 2333 CC Leiden, NL cEcological Resource Technology, University of Bayreuth, Universitätstr. 30, 95447 Bayreuth, Germany dUniv. Bordeaux, CNRS, Bordeaux INP, ISM, UMR 5255, F-33400 Talence, France eSustainable Minerals Institute, The University of Queensland, QLD, 4072, Australia fSchool of Environment, Enterprise and Development, University of Waterloo, 200 University Avenue West, Waterloo, Ontario N2L 3G1, Canada gUniversity of Technology Sydney, Institute for Sustainable Futures, Australia hSustainable Systems Engineering (STEN), Department of Green Chemistry and Technology, Faculty of Bioscience Engineering, Ghent University, Coupure Links 653, 9000 Ghent, Belgium iAIST, 305-8569 Tsukuba, Japan jMining & Explosives Engineering, Missouri University of Science & Technology, Rolla, MO, USA 65409 kInstitute for Sustainable Energy Systems (INSYS), Technical University of Applied Sciences Würzburg-Schweinfurt (THWS), Ignaz-Schön-Straße 11, Schweinfurt, Germany lFraunhofer Institute for Surface Engineering and Thin Films IST, Riedenkamp 2, Braunschweig 38108, Germany mDepartment of Environment, Land and Infrastructure Engineering, Politecnico di Torino, Corso Duca degli Abruzzi, 24, 10129 Torino, Italy nUniversity of Turin, Earth Sciences Department (DST), Via Valperga Caluso, 35 – 10125 Torino, Italy oecoinvent association, Technopark, Technoparkstrasse 1, 8005 Zürich, Switzerland pGraduate School of Engineering, The University of Tokyo, Tokyo 113-8656, Japan *Corresponding author: f.lai@brgm.fr This file provides all LCI datasets developed for Tellurium (Te), with distinguishing its global market and each individual production route.
B33: Sheet | C33: Corresponding route
B34: Te_Market_GLO | C34: Te global market
B35: PR1_Te_CN_CuSlime | C35: Te production in China through Cu anode slime processing
B36: PR2_Te_SE_Pyro | C36: Te recovery from Cu production in Sweden/Rönnskärsverken

Sheet Te_Market_GLO
A1: database | B1: Tellurium
A3: Activity | B3: Tellurium (Te) global market
A4: reference product | B4: CuTe
A5: location | B5: GLO
A6: amount | B6: 1
A7: unit | B7: kilogram
A8: comment | B8: n/a
A9: Exchanges
A10: name | B10: reference product | C10: location | D10: amount | E10: unit | F10: database | G10: type | H10: categories | I10: uncertainty type | J10: pedigree | K10: loc | L10: scale | M10: minimum | N10: maximum
A11: =B3 -> Tellurium (Te) global market | B11: =B4 -> CuTe | C11: =B5 -> GLO | D11: 1 | E11: kilogram | F11: =B1 -> Tellurium | G11: production
A12: =PR1_Te_CN_CuSlime!A31 -> Te production in China through Cu anode slime processing | B12: =PR1_Te_CN_CuSlime!B31 -> CuTe | C12: =PR1_Te_CN_CuSlime!C31 -> CN | D12: 0.92819615 | E12: =PR1_Te_CN_CuSlime!E31 -> kilogram | F12: =PR1_Te_CN_CuSlime!F31 -> Tellurium | G12: technosphere
A13: =PR2_Te_SE_Pyro!A142 -> Te recovery from Cu production in Sweden/Rönnskärsverken | B13: =PR2_Te_SE_Pyro!B142 -> CuTe | C13: =PR2_Te_SE_Pyro!C142 -> SE | D13: 0.071803853 | E13: =PR2_Te_SE_Pyro!E142 -> kilogram | F13: =PR2_Te_SE_Pyro!F142 -> Tellurium | G13: technosphere
A15: Activity | B15: Tellurium (Te) global market (Te content)
A16: reference product | B16: Te content
A17: location | B17: GLO
A18: amount | B18: 1
A19: unit | B19: kilogram
A20: comment | B20: Activity expressed for 1 kg Te contained.
A21: Exchanges
A22: name | B22: reference product | C22: location | D22: amount | E22: unit | F22: database | G22: type | H22: categories | I22: uncertainty type | J22: pedigree | K22: loc | L22: scale | M22: minimum | N22: maximum
A23: =B15 -> Tellurium (Te) global market (Te content) | B23: =B16 -> Te content | C23: =B17 -> GLO | D23: 1 | E23: kilogram | F23: =F11 -> Tellurium | G23: production
A24: =PR1_Te_CN_CuSlime!A43 -> Te production in China through Cu anode slime processing (Te content) | B24: =PR1_Te_CN_CuSlime!B43 -> CuTe (Te content) | C24: =PR1_Te_CN_CuSlime!C43 -> CN | D24: 0.92819615 | E24: =PR1_Te_CN_CuSlime!E43 -> kilogram | F24: =PR1_Te_CN_CuSlime!F43 -> Tellurium | G24: technosphere
A25: =PR2_Te_SE_Pyro!A154 -> Te recovery from Cu production in Sweden/Rönnskärsverken (Te content) | B25: =PR2_Te_SE_Pyro!B154 -> CuTe (Te content) | C25: =PR2_Te_SE_Pyro!C154 -> SE | D25: 0.071803853 | E25: =PR2_Te_SE_Pyro!E154 -> kilogram | F25: =PR2_Te_SE_Pyro!F154 -> Tellurium | G25: technosphere

Sheet PR1_Te_CN_CuSlime
A1: Activity | B1: [P+R] Copper telluride (CuTe) production (from anode slime)
A2: reference product | B2: CuTe
A3: location | B3: CN
A4: amount | B4: 1
A5: unit | B5: kilogram
A6: comment | B6: Allocated unit process, considering as allocation factors (AF): 75.4% for Au (1 kg), 22.2% for Ag (23 kg), 1.3% for Te (14 kg CuTe) and 1.1% for Se (27 kg).
A7: Exchanges
A8: name | B8: reference product | C8: location | D8: amount | E8: unit | F8: database | G8: type | H8: categories | I8: uncertainty type | J8: pedigree | K8: loc | L8: scale | M8: minimum | N8: maximum
A9: =B1 -> [P+R] Copper telluride (CuTe) production (from anode slime) | B9: =B2 -> CuTe | C9: =B3 -> CN | D9: 1 | E9: kilogram | F9: =Te_Market_GLO!B1 -> Tellurium | G9: production
A10: market for sulfuric acid | B10: sulfuric acid | C10: RoW | D10: 0.023232311 | E10: kilogram | F10: ecoinvent 3.10 cutoff | G10: technosphere | J10: (1,5,1,1,1)
A11: market for silica sand | B11: silica sand | C11: GLO | D11: 0.028720812 | E11: kilogram | F11: ecoinvent 3.10 cutoff | G11: technosphere | J11: (1,5,1,1,1)
A12: market for soda ash, dense | B12: soda ash, dense | C12: GLO | D12: 0.032831325 | E12: kilogram | F12: ecoinvent 3.10 cutoff | G12: technosphere | J12: (1,5,1,1,1)
A13: market for sodium hydroxide, without water, in 50% solution state | B13: sodium hydroxide, without water, in 50% solution state | C13: RoW | D13: 0.42022806 | E13: kilogram | F13: ecoinvent 3.10 cutoff | G13: technosphere | J13: (1,5,1,1,1)
A14: market for hydrochloric acid, without water, in 30% solution state | B14: hydrochloric acid, without water, in 30% solution state | C14: RoW | D14: 0.018951749 | E14: kilogram | F14: ecoinvent 3.10 cutoff | G14: technosphere | J14: (1,5,1,1,1)
A15: market for nitric acid, without water, in 50% solution state | B15: nitric acid, without water, in 50% solution state | C15: RoW | D15: 0.0049900799 | E15: kilogram | F15: ecoinvent 3.10 cutoff | G15: technosphere | J15: (1,5,1,1,1)
A16: market for sodium chlorate, powder | B16: sodium chlorate, powder | C16: RoW | D16: 0.00099684322 | E16: kilogram | F16: ecoinvent 3.10 cutoff | G16: technosphere | J16: (1,5,1,1,1)
A17: market for ammonium chloride | B17: ammonium chloride | C17: GLO | D17: 3.5182702e-05 | E17: kilogram | F17: ecoinvent 3.10 cutoff | G17: technosphere | J17: (1,5,1,1,1)
A18: market group for electricity, medium voltage | B18: electricity, medium voltage | C18: CN | D18: 1.8446291 | E18: kilowatt hour | F18: ecoinvent 3.10 cutoff | G18: technosphere | J18: (1,5,1,1,1)
A19: market for copper slag | B19: copper slag | C19: GLO | D19: -0.28166685 | E19: kilogram | F19: ecoinvent 3.10 cutoff | G19: technosphere | J19: (1,5,1,1,1)
A20: Water, unspecified natural origin | D20: 0.00067187819 | E20: cubic meter | F20: biosphere3 | G20: biosphere | H20: natural resource::in ground | J20: (1,5,1,1,1)
A21: Carbon dioxide, fossil | D21: 0.65673204 | E21: kilogram | F21: biosphere3 | G21: biosphere | H21: air | J21: (1,5,1,1,1)
A23: Activity | B23: Te production in China through Cu anode slime processing
A24: reference product | B24: CuTe
A25: location | B25: CN
A26: amount | B26: 1
A27: unit | B27: kilogram
A28: comment | B28: An ecoinvent activity is here included to model the upstream anode slime production. Applied AF: "Anode slime" input = 1.3%.
A29: Exchanges
A30: name | B30: reference product | C30: location | D30: amount | E30: unit | F30: database | G30: type | H30: categories | I30: uncertainty type | J30: pedigree | K30: loc | L30: scale | M30: minimum | N30: maximum
A31: =B23 -> Te production in China through Cu anode slime processing | B31: =B24 -> CuTe | C31: =B25 -> CN | D31: 1 | E31: kilogram | F31: =F9 -> Tellurium | G31: production
A32: =A9 -> [P+R] Copper telluride (CuTe) production (from anode slime) | B32: =B9 -> CuTe | C32: =C9 -> CN | D32: 1 | E32: =E9 -> kilogram | F32: =F9 -> Tellurium | G32: technosphere
A33: market for anode slime from electrorefining of copper, anode | B33: anode slime from electrorefining of copper, anode | C33: GLO | D33: 0.58637836 | E33: kilogram | F33: ecoinvent 3.10 cutoff | G33: technosphere
A35: Activity | B35: Te production in China through Cu anode slime processing (Te content)
A36: reference product | B36: CuTe (Te content)
A37: location | B37: CN
A38: amount | B38: 1
A39: unit | B39: kilogram
A40: comment | B40: An ecoinvent activity is here included to model the upstream anode slime production. Applied AF: "Anode slime" input = 1.3%. Activity expressed for 1 kg Te contained.
A41: Exchanges
A42: name | B42: reference product | C42: location | D42: amount | E42: unit | F42: database | G42: type | H42: categories | I42: uncertainty type | J42: pedigree | K42: loc | L42: scale | M42: minimum | N42: maximum
...

Sheet PR2_Te_SE_Pyro
A1: Activity | B1: [M+C] Copper (Cu) ore mining and concentration (Sweden)
A2: reference product | B2: Cu concentrate
A3: location | B3: SE
A4: amount | B4: 1
A5: unit | B5: kilogram
A6: comment | B6: n/a
A7: Exchanges
A8: name | B8: reference product | C8: location | D8: amount | E8: unit | F8: database | G8: type | H8: categories | I8: uncertainty type | J8: pedigree | K8: loc | L8: scale | M8: minimum | N8: maximum
A9: =B1 -> [M+C] Copper (Cu) ore mining and concentration (Sweden) | B9: =B2 -> Cu concentrate | C9: SE | D9: 1 | E9: kilogram | F9: =Te_Market_GLO!B1 -> Tellurium | G9: production
A10: market for diesel, burned in building machine | B10: diesel, burned in building machine | C10: GLO | D10: 4.0289823 | E10: megajoule | F10: ecoinvent 3.10 cutoff | G10: technosphere | J10: (1,1,3,1,1)
A11: market for electricity, high voltage | B11: electricity, high voltage | C11: SE | D11: 0.24177706 | E11: kilowatt hour | F11: ecoinvent 3.10 cutoff | G11: technosphere | J11: (1,1,3,1,1)
A12: heat production, wood pellet, at furnace 25kW, state-of-the-art 2014 | B12: heat, central or small-scale, other than natural gas | C12: RoW | D12: 0.025828164 | E12: megajoule | F12: ecoinvent 3.10 cutoff | G12: technosphere | J12: (1,1,3,1,1)
A13: market for explosive, tovex | B13: explosive, tovex | C13: GLO | D13: 0.082326296 | E13: kilogram | F13: ecoinvent 3.10 cutoff | G13: technosphere | J13: (1,1,3,1,1)
A14: market for lime, packed | B14: lime, packed | C14: Europe without Switzerland | D14: 0.025824903 | E14: kilogram | F14: ecoinvent 3.10 cutoff | G14: technosphere | J14: (1,1,3,1,1)
A15: market for sodium chloride, powder | B15: sodium chloride, powder | C15: GLO | D15: 0.0045916737 | E15: kilogram | F15: ecoinvent 3.10 cutoff | G15: technosphere | J15: (1,1,3,1,1)
A16: market for sodium chloride, brine solution | B16: sodium chloride, brine solution | C16: GLO | D16: 0.00019155889 | E16: kilogram | F16: ecoinvent 3.10 cutoff | G16: technosphere | J16: (1,1,3,1,1)
A17: market for electricity, high voltage | B17: electricity, high voltage | C17: SE | D17: 2.2461111 | E17: kilowatt hour | F17: ecoinvent 3.10 cutoff | G17: technosphere | J17: (1,1,3,1,1)
A18: heat production, wood pellet, at furnace 25kW, state-of-the-art 2014 | B18: heat, central or small-scale, other than natural gas | C18: RoW | D18: 0.028657522 | E18: megajoule | F18: ecoinvent 3.10 cutoff | G18: technosphere | J18: (1,1,3,1,1)
A19: market for aluminium hydroxide | B19: aluminium hydroxide | C19: GLO | D19: 2.2827923e-05 | E19: kilogram | F19: ecoinvent 3.10 cutoff | G19: technosphere | J19: (1,1,3,1,1)
A20: market for chemical, inorganic | B20: chemical, inorganic | C20: GLO | D20: 0.0018001448 | E20: kilogram | F20: ecoinvent 3.10 cutoff | G20: technosphere | J20: (1,1,3,1,1)
A21: market for light fuel oil | B21: light fuel oil | C21: Europe without Switzerland | D21: 2.5436829e-06 | E21: kilogram | F21: ecoinvent 3.10 cutoff | G21: technosphere | J21: (1,1,3,1,1)
... A32: treatment of hazardous waste, hazardous waste incineration | B32: hazardous waste, for incineration | C32: Europe without Switzerland | D32: -1.8197116e-05 | E32: kilogram | F32: ecoinvent 3.10 cutoff | G32: technosphere | J32: (1,1,3,1,1)
A33: Occupation, mineral extraction site | D33: 0.081528297 | E33: square meter-year | F33: biosphere3 | G33: biosphere | H33: natural resource::land | J33: (1,1,3,1,1)
A34: Copper | D34: 0.21319389 | E34: kilogram | F34: biosphere3 | G34: biosphere | H34: natural resource::in ground | J34: (1,1,3,1,1)
A35: Water, river | D35: 0.0019566791 | E35: cubic meter | F35: biosphere3 | G35: biosphere | H35: natural resource::in water | J35: (1,1,3,1,1)
A36: Water, well, in ground | D36: 0.00032611319 | E36: cubic meter | F36: biosphere3 | G36: biosphere | H36: natural resource::in water | J36: (1,1,3,1,1)
A37: Nitrogen oxides | D37: 0.00011692462 | E37: kilogram | F37: biosphere3 | G37: biosphere | H37: air | J37: (1,1,3,1,1)
A38: Carbon dioxide, fossil | D38: 0.0012392301 | E38: kilogram | F38: biosphere3 | G38: biosphere | H38: air | J38: (1,1,3,1,1)
A39: Copper ion | D39: 2.8404459e-07 | E39: kilogram | F39: biosphere3 | G39: biosphere | H39: water | J39: (1,1,3,1,1)
A40: Aluminium III | D40: 7.5593037e-06 | E40: kilogram | F40: biosphere3 | G40: biosphere | H40: water | J40: (1,1,3,1,1)
A41: Arsenic ion | D41: 2.5436829e-09 | E41: kilogram | F41: biosphere3 | G41: biosphere | H41: water | J41: (1,1,3,1,1)
A42: Lead II | D42: 9.7833956e-09 | E42: kilogram | F42: biosphere3 | G42: biosphere | H42: water | J42: (1,1,3,1,1)
A43: Cadmium II | D43: 3.2611319e-09 | E43: kilogram | F43: biosphere3 | G43: biosphere | H43: water | J43: (1,1,3,1,1)
A44: Copper ion | D44: 2.4621546e-07 | E44: kilogram | F44: biosphere3 | G44: biosphere | H44: water | J44: (1,1,3,1,1)
... A50: Nitrogen | D50: 0.00016461868 | E50: kilogram | F50: biosphere3 | G50: biosphere | H50: water | J50: (1,1,3,1,1)
A52: Activity | B52: [P+R] Copper telluride (CuTe) production - Pyrometallurgy (Sweden)
A53: reference product | B53: CuTe
A54: location | B54: SE
A55: amount | B55: 1
A56: unit | B56: kilogram
...
