Workbook

Sheet Note
A1: skip
B2: Life cycle inventories of global metal and mineral supply chains: a comprehensive data review, analysis and processing Frédéric Laia*, Stéphanie Mullera, Audrey Philippea, Robert Istrateb, Brenda Miranda Xicotencatlb, Afsoon Mansouri Askic, Aina Mas Fonsd,a, Juliana Segura-Salazare, Jair Santillán Saldivara, Alexander Cimprichf, Stephen Northeyg, Lígia da Silva Limah, Lieselot Booneh, Ryosuke Yokoii, Kamrul Islami, Ioanna Paschalidouj, Felipe Cerdask,l, Victor Balboa-Espinozae, Anish Koyamparambathd, Diae Henniouia, Victoire Collignona, Aurélien Reysa, Gyslain Ngadi Sakatadim, Jo Dewulfh, Bernhard Steubingb, Christoph Helbigc, Gaétan Lefebvrea, Gian Andrea Blenginin,m, Valeria Supertio, Masaharu Motoshitai, Guido Sonnemannd, Kwame Awuah-Offeij, Steven B. Youngf, Shinsuke Murakamip, Antoine Beylota aBRGM, F-45060 Orléans, France bInstitute of Environmental Sciences (CML), Leiden University, Einsteinweg 2, 2333 CC Leiden, NL cEcological Resource Technology, University of Bayreuth, Universitätstr. 30, 95447 Bayreuth, Germany dUniv. Bordeaux, CNRS, Bordeaux INP, ISM, UMR 5255, F-33400 Talence, France eSustainable Minerals Institute, The University of Queensland, QLD, 4072, Australia fSchool of Environment, Enterprise and Development, University of Waterloo, 200 University Avenue West, Waterloo, Ontario N2L 3G1, Canada gUniversity of Technology Sydney, Institute for Sustainable Futures, Australia hSustainable Systems Engineering (STEN), Department of Green Chemistry and Technology, Faculty of Bioscience Engineering, Ghent University, Coupure Links 653, 9000 Ghent, Belgium iAIST, 305-8569 Tsukuba, Japan jMining & Explosives Engineering, Missouri University of Science & Technology, Rolla, MO, USA 65409 kInstitute for Sustainable Energy Systems (INSYS), Technical University of Applied Sciences Würzburg-Schweinfurt (THWS), Ignaz-Schön-Straße 11, Schweinfurt, Germany lFraunhofer Institute for Surface Engineering and Thin Films IST, Riedenkamp 2, Braunschweig 38108, Germany mDepartment of Environment, Land and Infrastructure Engineering, Politecnico di Torino, Corso Duca degli Abruzzi, 24, 10129 Torino, Italy nUniversity of Turin, Earth Sciences Department (DST), Via Valperga Caluso, 35 – 10125 Torino, Italy oecoinvent association, Technopark, Technoparkstrasse 1, 8005 Zürich, Switzerland pGraduate School of Engineering, The University of Tokyo, Tokyo 113-8656, Japan *Corresponding author: f.lai@brgm.fr This file provides all LCI datasets developed for Vanadium (V), with distinguishing its global market and each individual production route.
B33: Sheet | C33: Corresponding route
B34: V_Market_GLO | C34: V global market
B35: PR1_V2O5_CN_CaRoasting | C35: V2O5 production in China through Ca-roasting
B36: PR2_V2O5_CN_SubMolten | C36: V2O5 production in China through Sub-Molten Salt Process
B37: PR3_V2O5_CN_PanSteel | C37: VTM ore mining and V2O5 production in China
B38: PR4_V2O5_ZA_Mapochs | C38: VTM ore mining and V2O5 production in South Africa/Mapochs Mine

Sheet V_Market_GLO
A1: database | B1: Vanadium
A3: Activity | B3: Vanadium (V) global market
A4: reference product | B4: V2O5
A5: location | B5: GLO
A6: amount | B6: 1
A7: unit | B7: kilogram
A8: comment | B8: n/a
A9: Exchanges
A10: name | B10: reference product | C10: location | D10: amount | E10: unit | F10: database | G10: type | H10: categories | I10: uncertainty type | J10: pedigree | K10: loc | L10: scale | M10: minimum | N10: maximum
A11: =B3 -> Vanadium (V) global market | B11: =B4 -> V2O5 | C11: =B5 -> GLO | D11: 1 | E11: =B7 -> kilogram | F11: =B1 -> Vanadium | G11: production
A12: =PR1_V2O5_CN_CaRoasting!A33 -> V2O5 production in China through Ca-roasting | B12: =PR1_V2O5_CN_CaRoasting!B33 -> V2O5 | C12: =PR1_V2O5_CN_CaRoasting!C33 -> CN | D12: 0.014647021 | E12: =PR1_V2O5_CN_CaRoasting!E33 -> kilogram | F12: =PR1_V2O5_CN_CaRoasting!F33 -> Vanadium | G12: technosphere
A13: =PR2_V2O5_CN_SubMolten!A34 -> V2O5 production in China through Sub-Molten Salt Process | B13: =PR2_V2O5_CN_SubMolten!B34 -> V2O5 | C13: =PR2_V2O5_CN_SubMolten!C34 -> CN | D13: 0.073235105 | E13: =PR2_V2O5_CN_SubMolten!E34 -> kilogram | F13: =PR2_V2O5_CN_SubMolten!F34 -> Vanadium | G13: technosphere
A14: =PR3_V2O5_CN_PanSteel!A126 -> VTM ore mining and V2O5 production in China | B14: =PR3_V2O5_CN_PanSteel!B126 -> V2O5 | C14: =PR3_V2O5_CN_PanSteel!C126 -> CN | D14: 0.79093914 | E14: =PR3_V2O5_CN_PanSteel!E126 -> kilogram | F14: =PR3_V2O5_CN_PanSteel!F126 -> Vanadium | G14: technosphere
A15: =PR4_V2O5_ZA_Mapochs!A189 -> VTM ore mining and V2O5 production in South Africa/Mapochs Mine | B15: =PR4_V2O5_ZA_Mapochs!B189 -> V2O5 | C15: =PR4_V2O5_ZA_Mapochs!C189 -> ZA | D15: 0.12117874 | E15: =PR4_V2O5_ZA_Mapochs!E189 -> kilogram | F15: =PR4_V2O5_ZA_Mapochs!F189 -> Vanadium | G15: technosphere
A17: Activity | B17: Vanadium (V) global market (V content)
A18: reference product | B18: V content
A19: location | B19: GLO
A20: amount | B20: 1
A21: unit | B21: kilogram
A22: comment | B22: Activity expressed for 1 kg V contained
A23: Exchanges
A24: name | B24: reference product | C24: location | D24: amount | E24: unit | F24: database | G24: type | H24: categories | I24: uncertainty type | J24: pedigree | K24: loc | L24: scale | M24: minimum | N24: maximum
A25: =B17 -> Vanadium (V) global market (V content) | B25: =B18 -> V content | C25: =B19 -> GLO | D25: 1 | E25: =B21 -> kilogram | F25: =F11 -> Vanadium | G25: production
A26: =PR1_V2O5_CN_CaRoasting!A46 -> V2O5 production in China through Ca-roasting (V content) | B26: =PR1_V2O5_CN_CaRoasting!B46 -> V2O5 (V content) | C26: =PR1_V2O5_CN_CaRoasting!C46 -> CN | D26: 0.014647021 | E26: =PR1_V2O5_CN_CaRoasting!E46 -> kilogram | F26: =PR1_V2O5_CN_CaRoasting!F46 -> Vanadium | G26: technosphere
A27: =PR2_V2O5_CN_SubMolten!A47 -> V2O5 production in China through Sub-Molten Salt Process (V content) | B27: =PR2_V2O5_CN_SubMolten!B47 -> V2O5 (V content) | C27: =PR2_V2O5_CN_SubMolten!C47 -> CN | D27: 0.073235105 | E27: =PR2_V2O5_CN_SubMolten!E47 -> kilogram | F27: =PR2_V2O5_CN_SubMolten!F47 -> Vanadium | G27: technosphere
A28: =PR3_V2O5_CN_PanSteel!A139 -> VTM ore mining and V2O5 production in China (V content) | B28: =PR3_V2O5_CN_PanSteel!B139 -> V2O5 (V content) | C28: =PR3_V2O5_CN_PanSteel!C139 -> CN | D28: 0.79093914 | E28: =PR3_V2O5_CN_PanSteel!E139 -> kilogram | F28: =PR3_V2O5_CN_PanSteel!F139 -> Vanadium | G28: technosphere
A29: =PR4_V2O5_ZA_Mapochs!A202 -> VTM ore mining and V2O5 production in South Africa/Mapochs Mine (V content) | B29: =PR4_V2O5_ZA_Mapochs!B202 -> V2O5 (V content) | C29: =PR4_V2O5_ZA_Mapochs!C202 -> ZA | D29: 0.12117874 | E29: =PR4_V2O5_ZA_Mapochs!E202 -> kilogram | F29: =PR4_V2O5_ZA_Mapochs!F202 -> Vanadium | G29: technosphere

Sheet PR1_V2O5_CN_CaRoasting
A1: Activity | B1: [P] Vanadium pentoxide (V2O5) production (Calcium Roasting process)
A2: reference product | B2: V2O5
A3: location | B3: CN
A4: amount | B4: 1
A5: unit | B5: kilogram
A6: comment | B6: n/a
A7: Exchanges
A8: name | B8: reference product | C8: location | D8: amount | E8: unit | F8: database | G8: type | H8: categories | I8: uncertainty type | J8: pedigree | K8: loc | L8: scale | M8: minimum | N8: maximum
A9: =B1 -> [P] Vanadium pentoxide (V2O5) production (Calcium Roasting process) | B9: =B2 -> V2O5 | C9: =B3 -> CN | D9: 1 | E9: kilogram | F9: =V_Market_GLO!B1 -> Vanadium | G9: production
A10: market group for electricity, medium voltage | B10: electricity, medium voltage | C10: CN | D10: 0.91511 | E10: kilowatt hour | F10: ecoinvent 3.10 cutoff | G10: technosphere | J10: (1,1,1,1,1)
A11: market for limestone, crushed, washed | B11: limestone, crushed, washed | C11: RoW | D11: 1.4 | E11: kilogram | F11: ecoinvent 3.10 cutoff | G11: technosphere | J11: (1,1,1,1,1)
A12: market for sulfuric acid | B12: sulfuric acid | C12: RoW | D12: 0.78 | E12: kilogram | F12: ecoinvent 3.10 cutoff | G12: technosphere | J12: (1,1,1,1,1)
A13: market for tap water | B13: tap water | C13: RoW | D13: 15.49 | E13: kilogram | F13: ecoinvent 3.10 cutoff | G13: technosphere | J13: (1,1,1,1,1)
A14: market group for electricity, medium voltage | B14: electricity, medium voltage | C14: CN | D14: 0.72941 | E14: kilowatt hour | F14: ecoinvent 3.10 cutoff | G14: technosphere | J14: (1,1,1,1,1)
A15: market for natural gas, high pressure | B15: natural gas, high pressure | C15: CN | D15: 23.0125 | E15: cubic meter | F15: ecoinvent 3.10 cutoff | G15: technosphere | J15: (1,1,1,1,1)
A16: market for sulfidic tailings, from copper mine operation | B16: sulfidic tailings, from copper mine operation | C16: CN | D16: -7.6 | E16: kilogram | F16: ecoinvent 3.10 cutoff | G16: technosphere | J16: (1,1,1,1,1)
A17: market for sulfuric acid | B17: sulfuric acid | C17: RoW | D17: 0.2 | E17: kilogram | F17: ecoinvent 3.10 cutoff | G17: technosphere | J17: (1,1,1,1,1)
A18: market for ammonium sulfate | B18: ammonium sulfate | C18: RoW | D18: 0.62 | E18: kilogram | F18: ecoinvent 3.10 cutoff | G18: technosphere | J18: (1,1,1,1,1)
A19: market for steam, in chemical industry | B19: steam, in chemical industry | C19: RoW | D19: 2.7 | E19: kilogram | F19: ecoinvent 3.10 cutoff | G19: technosphere | J19: (1,1,1,1,1)
A20: market group for electricity, medium voltage | B20: electricity, medium voltage | C20: CN | D20: 0.35882 | E20: kilowatt hour | F20: ecoinvent 3.10 cutoff | G20: technosphere | J20: (1,1,1,1,1)
A21: market for natural gas, high pressure | B21: natural gas, high pressure | C21: CN | D21: 21.3875 | E21: cubic meter | F21: ecoinvent 3.10 cutoff | G21: technosphere | J21: (1,1,1,1,1)
... A23: market for waste refinery gas | B23: waste refinery gas | C23: GLO | D23: -1019.3145 | E23: megajoule | F23: ecoinvent 3.10 cutoff | G23: technosphere | J23: (1,1,1,1,1)
A25: Activity | B25: V2O5 production in China through Ca-roasting
A26: reference product | B26: V2O5
A27: location | B27: CN
A28: amount | B28: 1
A29: unit | B29: kilogram
A30: comment | B30: Applied AF: "Fe concentrate" input = 0.6%.
A31: Exchanges
A32: name | B32: reference product | C32: location | D32: amount | E32: unit | F32: database | G32: type | H32: categories | I32: uncertainty type | J32: pedigree | K32: loc | L32: scale | M32: minimum | N32: maximum
A33: =B25 -> V2O5 production in China through Ca-roasting | B33: =B26 -> V2O5 | C33: =B27 -> CN | D33: 1 | E33: kilogram | F33: =F9 -> Vanadium | G33: production
A34: =A9 -> [P] Vanadium pentoxide (V2O5) production (Calcium Roasting process) | B34: =B9 -> V2O5 | C34: =C9 -> CN | D34: 1 | E34: =E9 -> kilogram | F34: =F9 -> Vanadium | G34: technosphere
A35: =PR3_V2O5_CN_PanSteel_Unallo!A30 -> [P+R] Crude steel production | B35: =PR3_V2O5_CN_PanSteel_Unallo!B30 -> Vanadium (V) slag | C35: =PR3_V2O5_CN_PanSteel_Unallo!C30 -> CN | D35: 7.01 | E35: =PR3_V2O5_CN_PanSteel_Unallo!E30 -> kilogram | F35: =PR3_V2O5_CN_PanSteel_Unallo!F30 -> Vanadium | G35: technosphere
A36: =PR3_V2O5_CN_PanSteel_Unallo!A9 -> [M+C] Iron (Fe) ore mining and concentration | B36: =PR3_V2O5_CN_PanSteel_Unallo!B9 -> Fe concentrate | C36: =PR3_V2O5_CN_PanSteel_Unallo!C9 -> CN | D36: 2.6161021 | E36: =PR3_V2O5_CN_PanSteel_Unallo!E9 -> kilogram | F36: =PR3_V2O5_CN_PanSteel_Unallo!F9 -> Vanadium | G36: technosphere
A38: Activity | B38: V2O5 production in China through Ca-roasting (V content)
A39: reference product | B39: V2O5 (V content)
A40: location | B40: CN
A41: amount | B41: 1
A42: unit | B42: kilogram
A43: comment | B43: Activity expressed for 1 kg V contained Applied AF: "Fe concentrate" input = 0.6%.
...

Sheet PR2_V2O5_CN_SubMolten
A1: Activity | B1: [P] Vanadium pentoxide (V2O5) production (Sub-Molten Salt process)
A2: reference product | B2: V2O5
A3: location | B3: CN
A4: amount | B4: 1
A5: unit | B5: kilogram
A6: comment | B6: n/a
A7: Exchanges
A8: name | B8: reference product | C8: location | D8: amount | E8: unit | F8: database | G8: type | H8: categories | I8: uncertainty type | J8: pedigree | K8: loc | L8: scale | M8: minimum | N8: maximum
A9: =B1 -> [P] Vanadium pentoxide (V2O5) production (Sub-Molten Salt process) | B9: =B2 -> V2O5 | C9: =B3 -> CN | D9: 1 | E9: kilogram | F9: =V_Market_GLO!B1 -> Vanadium | G9: production
A10: market group for electricity, medium voltage | B10: electricity, medium voltage | C10: CN | D10: 1.2 | E10: kilowatt hour | F10: ecoinvent 3.10 cutoff | G10: technosphere | J10: (1,1,1,1,1)
A11: market for iron scrap, unsorted | B11: iron scrap, unsorted | C11: GLO | D11: -0.95 | E11: kilogram | F11: ecoinvent 3.10 cutoff | G11: technosphere | J11: (1,1,1,1,1)
A12: market for sodium hydroxide, without water, in 50% solution state | B12: sodium hydroxide, without water, in 50% solution state | C12: RoW | D12: 1.11 | E12: kilogram | F12: ecoinvent 3.10 cutoff | G12: technosphere | J12: (1,1,1,1,1)
A13: market for lime, packed | B13: lime, packed | C13: RoW | D13: 1.61 | E13: kilogram | F13: ecoinvent 3.10 cutoff | G13: technosphere | J13: (1,1,1,1,1)
A14: market for steam, in chemical industry | B14: steam, in chemical industry | C14: RoW | D14: 9.76 | E14: kilogram | F14: ecoinvent 3.10 cutoff | G14: technosphere | J14: (1,1,1,1,1)
A15: market group for electricity, medium voltage | B15: electricity, medium voltage | C15: CN | D15: 0.68293 | E15: kilowatt hour | F15: ecoinvent 3.10 cutoff | G15: technosphere | J15: (1,1,1,1,1)
A16: market for compressed air, 800 kPa gauge | B16: compressed air, 800 kPa gauge | C16: RoW | D16: 3.2 | E16: cubic meter | F16: ecoinvent 3.10 cutoff | G16: technosphere | J16: (1,1,1,1,1)
A17: market for compressed air, 800 kPa gauge | B17: compressed air, 800 kPa gauge | C17: RoW | D17: 0.29111 | E17: cubic meter | F17: ecoinvent 3.10 cutoff | G17: technosphere | J17: (1,1,1,1,1)
A18: market for lime, packed | B18: lime, packed | C18: RoW | D18: 1.2 | E18: kilogram | F18: ecoinvent 3.10 cutoff | G18: technosphere | J18: (1,1,1,1,1)
A19: market for ammonium sulfate | B19: ammonium sulfate | C19: RoW | D19: 2.2 | E19: kilogram | F19: ecoinvent 3.10 cutoff | G19: technosphere | J19: (1,1,1,1,1)
A20: market for chemical, inorganic | B20: chemical, inorganic | C20: GLO | D20: 20.53 | E20: kilogram | F20: ecoinvent 3.10 cutoff | G20: technosphere | J20: (1,1,1,1,1)
A21: market for tap water | B21: tap water | C21: RoW | D21: 5.08 | E21: kilogram | F21: ecoinvent 3.10 cutoff | G21: technosphere | J21: (1,1,1,1,1)
... A24: market for sodium dichromate | B24: sodium dichromate | C24: GLO | D24: -0.84 | E24: kilogram | F24: ecoinvent 3.10 cutoff | G24: technosphere | J24: (1,1,1,1,1)
A26: Activity | B26: V2O5 production in China through Sub-Molten Salt Process
A27: reference product | B27: V2O5
A28: location | B28: CN
A29: amount | B29: 1
A30: unit | B30: kilogram
A31: comment | B31: Applied AF: "Fe concentrate" input = 0.6%.
A32: Exchanges
A33: name | B33: reference product | C33: location | D33: amount | E33: unit | F33: database | G33: type | H33: categories | I33: uncertainty type | J33: pedigree | K33: loc | L33: scale | M33: minimum | N33: maximum
A34: =B26 -> V2O5 production in China through Sub-Molten Salt Process | B34: =B27 -> V2O5 | C34: =B28 -> CN | D34: 1 | E34: kilogram | F34: =F9 -> Vanadium | G34: production
A35: =A9 -> [P] Vanadium pentoxide (V2O5) production (Sub-Molten Salt process) | B35: =B9 -> V2O5 | C35: =C9 -> CN | D35: 1 | E35: =E9 -> kilogram | F35: =F9 -> Vanadium | G35: technosphere
A36: =PR3_V2O5_CN_PanSteel_Unallo!A30 -> [P+R] Crude steel production | B36: =PR3_V2O5_CN_PanSteel_Unallo!B30 -> Vanadium (V) slag | C36: =PR3_V2O5_CN_PanSteel_Unallo!C30 -> CN | D36: 10.95 | E36: =PR3_V2O5_CN_PanSteel_Unallo!E30 -> kilogram | F36: =PR3_V2O5_CN_PanSteel_Unallo!F30 -> Vanadium | G36: technosphere
A37: =PR3_V2O5_CN_PanSteel_Unallo!A9 -> [M+C] Iron (Fe) ore mining and concentration | B37: =PR3_V2O5_CN_PanSteel_Unallo!B9 -> Fe concentrate | C37: =PR3_V2O5_CN_PanSteel_Unallo!C9 -> CN | D37: 4.0864932 | E37: =PR3_V2O5_CN_PanSteel_Unallo!E9 -> kilogram | F37: =PR3_V2O5_CN_PanSteel_Unallo!F9 -> Vanadium | G37: technosphere
A39: Activity | B39: V2O5 production in China through Sub-Molten Salt Process (V content)
A40: reference product | B40: V2O5 (V content)
A41: location | B41: CN
A42: amount | B42: 1
A43: unit | B43: kilogram
A44: comment | B44: Activity expressed for 1 kg V contained Applied AF: "Fe concentrate" input = 0.6%.
...

Sheet PR3_V2O5_CN_PanSteel
A1: Activity | B1: [M+C] Iron (Fe) ore mining and concentration
A2: reference product | B2: Fe concentrate
A3: location | B3: CN
A4: amount | B4: 1
A5: unit | B5: kilogram
A6: comment | B6: n/a
A7: Exchanges
A8: name | B8: reference product | C8: location | D8: amount | E8: unit | F8: database | G8: type | H8: categories | I8: uncertainty type | J8: pedigree | K8: loc | L8: scale | M8: minimum | N8: maximum
A9: =B1 -> [M+C] Iron (Fe) ore mining and concentration | B9: =B2 -> Fe concentrate | C9: =B3 -> CN | D9: 1 | E9: kilogram | F9: =V_Market_GLO!B1 -> Vanadium | G9: production
A10: market for iron ore, crude ore, 46% Fe | B10: iron ore, crude ore, 46% Fe | C10: GLO | D10: 2.2998478 | E10: kilogram | F10: ecoinvent 3.10 cutoff | G10: technosphere | J10: (1.0,1,5,1,1)
A11: market for steel, low-alloyed | B11: steel, low-alloyed | C11: GLO | D11: 0.0010147133 | E11: kilogram | F11: ecoinvent 3.10 cutoff | G11: technosphere | J11: (1.0,1,5,1,1)
A12: market group for electricity, medium voltage | B12: electricity, medium voltage | C12: CN | D12: 0.037544394 | E12: kilowatt hour | F12: ecoinvent 3.10 cutoff | G12: technosphere | J12: (1.0,1,5,1,1)
A13: market for non-sulfidic tailing, off-site | B13: non-sulfidic tailing, off-site | C13: GLO | D13: -1.072552 | E13: kilogram | F13: ecoinvent 3.10 cutoff | G13: technosphere | J13: (1.0,1,5,1,1)
A14: Carbon dioxide, fossil | D14: 0.18396753 | E14: kilogram | F14: biosphere3 | G14: biosphere | H14: air | J14: (5.0,1,5,1,1)
A15: Sulfur dioxide | D15: 0.015638762 | E15: kilogram | F15: biosphere3 | G15: biosphere | H15: air | J15: (5.0,1,5,1,1)
A16: Carbon monoxide, fossil | D16: 0.11499239 | E16: kilogram | F16: biosphere3 | G16: biosphere | H16: air | J16: (5.0,1,5,1,1)
A17: Nitrogen oxides | D17: 0.0073597159 | E17: kilogram | F17: biosphere3 | G17: biosphere | H17: air | J17: (5.0,1,5,1,1)
A18: Methane, fossil | D18: 0.0052897007 | E18: kilogram | F18: biosphere3 | G18: biosphere | H18: air | J18: (5.0,1,5,1,1)
A19: Particulate Matter, > 2.5 um and < 10um | D19: 0.075895485 | E19: kilogram | F19: biosphere3 | G19: biosphere | H19: air | J19: (5.0,1,5,1,1)
A21: Activity | B21: [P+R] Crude steel production
A22: reference product | B22: Vanadium (V) slag
A23: location | B23: CN
A24: amount | B24: 1
A25: unit | B25: kilogram
A26: comment | B26: Allocated unit process, considering as allocation factors (AF): 0.6% for V (1 kg slag) and 99.4% for Steel (36 kg).
A27: Exchanges
A28: name | B28: reference product | C28: location | D28: amount | E28: unit | F28: database | G28: type | H28: categories | I28: uncertainty type | J28: pedigree | K28: loc | L28: scale | M28: minimum | N28: maximum
A29: =B21 -> [P+R] Crude steel production | B29: =B22 -> Vanadium (V) slag | C29: =B23 -> CN | D29: 1 | E29: kilogram | F29: =F9 -> Vanadium | G29: production
A30: market for hard coal | B30: hard coal | C30: CN | D30: 0.013101552 | E30: kilogram | F30: ecoinvent 3.10 cutoff | G30: technosphere | J30: (1.0,1,5,1,1)
A31: market for limestone, crushed, washed | B31: limestone, crushed, washed | C31: RoW | D31: 0.040870667 | E31: kilogram | F31: ecoinvent 3.10 cutoff | G31: technosphere | J31: (1.0,1,5,1,1)
A32: =A109 -> Quicklime production | B32: =B109 -> Quicklime | C32: =C109 -> CN | D32: 0.021174226 | E32: =E109 -> kilogram | F32: =F109 -> Vanadium | G32: technosphere
A33: =A92 -> Coke production | B33: =B92 -> Coke | C33: =C92 -> CN | D33: 0.018968577 | E33: =E92 -> kilogram | F33: =F92 -> Vanadium | G33: technosphere
A34: =A92 -> Coke production | B34: =B92 -> Coke | C34: =C92 -> CN | D34: 0.0013895586 | E34: =E92 -> kilogram | F34: =F92 -> Vanadium | G34: technosphere
A35: market group for electricity, medium voltage | B35: electricity, medium voltage | C35: CN | D35: 0.020314023 | E35: kilowatt hour | F35: ecoinvent 3.10 cutoff | G35: technosphere | J35: (1.0,1,5,1,1)
A36: market for bentonite | B36: bentonite | C36: GLO | D36: 0.001543954 | E36: kilogram | F36: ecoinvent 3.10 cutoff | G36: technosphere | J36: (1.0,1,5,1,1)
A37: market group for electricity, medium voltage | B37: electricity, medium voltage | C37: CN | D37: 0.0030217385 | E37: kilowatt hour | F37: ecoinvent 3.10 cutoff | G37: technosphere | J37: (1.0,1,5,1,1)
A38: market for iron ore, crude ore, 46% Fe | B38: iron ore, crude ore, 46% Fe | C38: GLO | D38: 0.025144393 | E38: kilogram | F38: ecoinvent 3.10 cutoff | G38: technosphere | J38: (1.0,1,5,1,1)
A39: market for hard coal | B39: hard coal | C39: CN | D39: 0.030437949 | E39: kilogram | F39: ecoinvent 3.10 cutoff | G39: technosphere | J39: (1.0,1,5,1,1)
A40: =A92 -> Coke production | B40: =B92 -> Coke | C40: =C92 -> CN | D40: 0.10763565 | E40: =E92 -> kilogram | F40: =F92 -> Vanadium | G40: technosphere | J40: (1.0,1,5,1,1)
A41: =A92 -> Coke production | B41: =B92 -> Coke | C41: =C92 -> CN | D41: 0.00072786401 | E41: =E92 -> kilogram | F41: =F92 -> Vanadium | G41: technosphere | J41: (1.0,1,5,1,1)
...

Sheet PR3_V2O5_CN_PanSteel_Unallo
A1: Activity | B1: [M+C] Iron (Fe) ore mining and concentration
A2: reference product | B2: Fe concentrate
A3: location | B3: CN
A4: amount | B4: 1
A5: unit | B5: kilogram
A6: comment | B6: n/a
A7: Exchanges
A8: name | B8: reference product | C8: location | D8: amount | E8: unit | F8: database | G8: type | H8: categories | I8: uncertainty type | J8: pedigree | K8: loc | L8: scale | M8: minimum | N8: maximum
A9: =B1 -> [M+C] Iron (Fe) ore mining and concentration | B9: =B2 -> Fe concentrate | C9: =B3 -> CN | D9: 1 | E9: kilogram | F9: =V_Market_GLO!B1 -> Vanadium | G9: production
A10: market for iron ore, crude ore, 46% Fe | B10: iron ore, crude ore, 46% Fe | C10: GLO | D10: 2.2998478 | E10: kilogram | F10: ecoinvent 3.10 cutoff | G10: technosphere | J10: (1.0,1,5,1,1)
A11: market for steel, low-alloyed | B11: steel, low-alloyed | C11: GLO | D11: 0.0010147133 | E11: kilogram | F11: ecoinvent 3.10 cutoff | G11: technosphere | J11: (1.0,1,5,1,1)
A12: market group for electricity, medium voltage | B12: electricity, medium voltage | C12: CN | D12: 0.037544394 | E12: kilowatt hour | F12: ecoinvent 3.10 cutoff | G12: technosphere | J12: (1.0,1,5,1,1)
A13: n/a (Concentrate) | D13: 1 | E13: kilogram | F13: ecoinvent 3.10 cutoff | G13: technosphere | J13: (1.0,1,5,1,1)
A14: market for non-sulfidic tailing, off-site | B14: non-sulfidic tailing, off-site | C14: GLO | D14: -1.072552 | E14: kilogram | F14: ecoinvent 3.10 cutoff | G14: technosphere | J14: (1.0,1,5,1,1)
A15: Carbon dioxide, fossil | D15: 0.18396753 | E15: kilogram | F15: biosphere3 | G15: biosphere | H15: air | J15: (5.0,1,5,1,1)
A16: Sulfur dioxide | D16: 0.015638762 | E16: kilogram | F16: biosphere3 | G16: biosphere | H16: air | J16: (5.0,1,5,1,1)
A17: Carbon monoxide, fossil | D17: 0.11499239 | E17: kilogram | F17: biosphere3 | G17: biosphere | H17: air | J17: (5.0,1,5,1,1)
A18: Nitrogen oxides | D18: 0.0073597159 | E18: kilogram | F18: biosphere3 | G18: biosphere | H18: air | J18: (5.0,1,5,1,1)
A19: Methane, fossil | D19: 0.0052897007 | E19: kilogram | F19: biosphere3 | G19: biosphere | H19: air | J19: (5.0,1,5,1,1)
A20: Particulate Matter, > 2.5 um and < 10um | D20: 0.075895485 | E20: kilogram | F20: biosphere3 | G20: biosphere | H20: air | J20: (5.0,1,5,1,1)
A22: Activity | B22: [P+R] Crude steel production
A23: reference product | B23: Vanadium (V) slag
A24: location | B24: CN
A25: amount | B25: 1
A26: unit | B26: kilogram
A27: comment | B27: Unallocated LCI
A28: Exchanges
A29: name | B29: reference product | C29: location | D29: amount | E29: unit | F29: database | G29: type | H29: categories | I29: uncertainty type | J29: pedigree | K29: loc | L29: scale | M29: minimum | N29: maximum
A30: =B22 -> [P+R] Crude steel production | B30: =B23 -> Vanadium (V) slag | C30: =B24 -> CN | D30: 1 | E30: kilogram | F30: =F9 -> Vanadium | G30: production
A31: market for hard coal | B31: hard coal | C31: CN | D31: 0.0594 | E31: kilogram | F31: ecoinvent 3.10 cutoff | G31: technosphere | J31: (1.0,1,5,1,1)
A32: n/a (Common concentrate) | D32: 0.279 | E32: kilogram | F32: ecoinvent 3.10 cutoff | G32: technosphere | J32: (1.0,1,5,1,1)
A33: n/a (VTMC) | D33: 1.241 | E33: kilogram | F33: ecoinvent 3.10 cutoff | G33: technosphere | J33: (1.0,1,5,1,1)
A34: market for limestone, crushed, washed | B34: limestone, crushed, washed | C34: RoW | D34: 0.1853 | E34: kilogram | F34: ecoinvent 3.10 cutoff | G34: technosphere | J34: (1.0,1,5,1,1)
A35: =A132 -> Quicklime production | B35: =B132 -> Quicklime | C35: =C132 -> CN | D35: 0.096 | E35: =E132 -> kilogram | F35: =F132 -> Vanadium | G35: technosphere
A36: =A111 -> Coke production | B36: =B111 -> Coke | C36: =C111 -> CN | D36: 0.086 | E36: =E111 -> kilogram | F36: =F111 -> Vanadium | G36: technosphere
A37: =A111 -> Coke production | B37: =B111 -> Coke | C37: =C111 -> CN | D37: 0.0063 | E37: =E111 -> kilogram | F37: =F111 -> Vanadium | G37: technosphere
A38: market group for electricity, medium voltage | B38: electricity, medium voltage | C38: CN | D38: 0.0921 | E38: kilowatt hour | F38: ecoinvent 3.10 cutoff | G38: technosphere | J38: (1.0,1,5,1,1)
A39: n/a (Sinter ores) | D39: 1.718 | E39: kilogram | F39: ecoinvent 3.10 cutoff | G39: technosphere | J39: (1.0,1,5,1,1)
A40: n/a (VTMC) | D40: 0.451 | E40: kilogram | F40: ecoinvent 3.10 cutoff | G40: technosphere | J40: (1.0,1,5,1,1)
A41: market for bentonite | B41: bentonite | C41: GLO | D41: 0.007 | E41: kilogram | F41: ecoinvent 3.10 cutoff | G41: technosphere | J41: (1.0,1,5,1,1)
...

Sheet PR4_V2O5_ZA_Mapochs
A1: Activity | B1: [M+C+P] Iron (Fe) production
A2: reference product | B2: Fe
A3: location | B3: ZA
A4: amount | B4: 1
A5: unit | B5: kilogram
A6: comment | B6: n/a
A7: Exchanges
A8: name | B8: reference product | C8: location | D8: amount | E8: unit | F8: database | G8: type | H8: categories | I8: uncertainty type | J8: pedigree | K8: loc | L8: scale | M8: minimum | N8: maximum
A9: =B1 -> [M+C+P] Iron (Fe) production | B9: =B2 -> Fe | C9: =B3 -> ZA | D9: 1 | E9: kilogram | F9: =V_Market_GLO!B1 -> Vanadium | G9: production
A10: market for rock crushing | B10: rock crushing | C10: GLO | D10: 1.8248175 | E10: kilogram | F10: ecoinvent 3.10 cutoff | G10: technosphere | J10: (2,5,3,5,5)
A11: market for electricity, medium voltage | B11: electricity, medium voltage | C11: ZA | D11: 1.6476575 | E11: kilowatt hour | F11: ecoinvent 3.10 cutoff | G11: technosphere | J11: (2,5,3,5,5)
A12: market for hard coal | B12: hard coal | C12: ZA | D12: 0.80291971 | E12: kilogram | F12: ecoinvent 3.10 cutoff | G12: technosphere | J12: (2,5,3,5,5)
A13: market for dolomite | B13: dolomite | C13: RoW | D13: 0.40145985 | E13: kilogram | F13: ecoinvent 3.10 cutoff | G13: technosphere | J13: (2,5,3,5,5)
A14: market for transport, freight train | B14: transport, freight train | C14: ZA | D14: 0.20072993 | E14: ton kilometer | F14: ecoinvent 3.10 cutoff | G14: technosphere | J14: (2,5,3,5,5)
A15: market for silica sand | B15: silica sand | C15: GLO | D15: 0.027372263 | E15: kilogram | F15: ecoinvent 3.10 cutoff | G15: technosphere | J15: (2,5,3,5,5)
A16: market for anode, for metal electrolysis | B16: anode, for metal electrolysis | C16: GLO | D16: 0.0054744526 | E16: kilogram | F16: ecoinvent 3.10 cutoff | G16: technosphere | J16: (2,5,3,5,5)
A17: market for electric arc furnace converter | B17: electric arc furnace converter | C17: GLO | D17: 7.2992701e-11 | E17: unit | F17: ecoinvent 3.10 cutoff | G17: technosphere | J17: (2,5,3,5,5)
A18: market for iron ore, crude ore, 46% Fe | B18: iron ore, crude ore, 46% Fe | C18: GLO | D18: 1.8248175 | E18: kilogram | F18: ecoinvent 3.10 cutoff | G18: technosphere | J18: (2,5,3,5,5)
A19: market for titania slag, 85% titanium dioxide | B19: titania slag, 85% titanium dioxide | C19: GLO | D19: -0.81751825 | E19: kilogram | F19: ecoinvent 3.10 cutoff | G19: technosphere | J19: (2,5,3,5,5)
A20: market for hard coal ash | B20: hard coal ash | C20: RoW | D20: -0.80291971 | E20: kilogram | F20: ecoinvent 3.10 cutoff | G20: technosphere | J20: (2,5,3,5,5)
A21: treatment of electric arc furnace slag, residual material landfill | B21: electric arc furnace slag | C21: RoW | D21: -0.43613139 | E21: kilogram | F21: ecoinvent 3.10 cutoff | G21: technosphere | J21: (2,5,3,5,5)
A22: Carbon dioxide, fossil | D22: 1.4071326 | E22: kilogram | F22: biosphere3 | G22: biosphere | H22: air::non-urban air or from high stacks | J22: (2,5,3,5,5)
A23: Sulfur dioxide | D23: 0.01171278 | E23: kilogram | F23: biosphere3 | G23: biosphere | H23: air::non-urban air or from high stacks | J23: (2,5,3,5,5)
A24: Radon-220 | D24: 0.0076722423 | E24: kilo Becquerel | F24: biosphere3 | G24: biosphere | H24: air::non-urban air or from high stacks | J24: (2,5,3,5,5)
A25: Radon-222 | D25: 0.0075360486 | E25: kilo Becquerel | F25: biosphere3 | G25: biosphere | H25: air::non-urban air or from high stacks | J25: (2,5,3,5,5)
A26: Nitrogen oxides | D26: 0.0058763777 | E26: kilogram | F26: biosphere3 | G26: biosphere | H26: air::non-urban air or from high stacks | J26: (2,5,3,5,5)
A27: Water | D27: 0.0019091304 | E27: cubic meter | F27: biosphere3 | G27: biosphere | H27: air | J27: (2,5,3,5,5)
A28: Polonium-210 | D28: 0.0018613132 | E28: kilo Becquerel | F28: biosphere3 | G28: biosphere | H28: air::non-urban air or from high stacks | J28: (2,5,3,5,5)
A29: Lead-210 | D29: 0.0010486911 | E29: kilo Becquerel | F29: biosphere3 | G29: biosphere | H29: air::non-urban air or from high stacks | J29: (2,5,3,5,5)
A30: Hydrochloric acid | D30: 0.00040101464 | E30: kilogram | F30: biosphere3 | G30: biosphere | H30: air::non-urban air or from high stacks | J30: (2,5,3,5,5)
A31: Potassium-40 | D31: 0.00034805044 | E31: kilo Becquerel | F31: biosphere3 | G31: biosphere | H31: air::non-urban air or from high stacks | J31: (2,5,3,5,5)
A32: Particulate Matter, > 10 um | D32: 0.00031180779 | E32: kilogram | F32: biosphere3 | G32: biosphere | H32: air::non-urban air or from high stacks | J32: (2,5,3,5,5)
A33: Radium-226 | D33: 0.00027692709 | E33: kilo Becquerel | F33: biosphere3 | G33: biosphere | H33: air::non-urban air or from high stacks | J33: (2,5,3,5,5)
... A105: Dioxins, measured as 2,3,7,8-tetrachlorodibenzo-p-dioxin | D105: 1.6040585e-13 | E105: kilogram | F105: biosphere3 | G105: biosphere | H105: air::non-urban air or from high stacks | J105: (2,5,3,5,5)
A107: Activity | B107: [R] Steel production
A108: reference product | B108: Vanadium (V) slag
A109: location | B109: ZA
A110: amount | B110: 1
A111: unit | B111: kilogram
A112: comment | B112: Allocated unit process, considering as allocation factors (AF): 1.7% for V (1 kg slag) and 98.3% for Steel (13 kg).
...

Sheet PR4_V2O5_ZA_Mapochs_Unallo
A1: Activity | B1: [M+C+P] Iron (Fe) production
A2: reference product | B2: Fe
A3: location | B3: ZA
A4: amount | B4: 1
A5: unit | B5: kilogram
A6: comment | B6: n/a
A7: Exchanges
A8: name | B8: reference product | C8: location | D8: amount | E8: unit | F8: database | G8: type | H8: categories | I8: uncertainty type | J8: pedigree | K8: loc | L8: scale | M8: minimum | N8: maximum
A9: =B1 -> [M+C+P] Iron (Fe) production | B9: =B2 -> Fe | C9: =B3 -> ZA | D9: 1 | E9: kilogram | F9: =V_Market_GLO!B1 -> Vanadium | G9: production
A10: market for rock crushing | B10: rock crushing | C10: GLO | D10: 1.8248175 | E10: kilogram | F10: ecoinvent 3.10 cutoff | G10: technosphere | J10: (2,5,3,5,5)
A11: market for electricity, medium voltage | B11: electricity, medium voltage | C11: ZA | D11: 1.6476575 | E11: kilowatt hour | F11: ecoinvent 3.10 cutoff | G11: technosphere | J11: (2,5,3,5,5)
A12: market for hard coal | B12: hard coal | C12: ZA | D12: 0.80291971 | E12: kilogram | F12: ecoinvent 3.10 cutoff | G12: technosphere | J12: (2,5,3,5,5)
A13: market for dolomite | B13: dolomite | C13: RoW | D13: 0.40145985 | E13: kilogram | F13: ecoinvent 3.10 cutoff | G13: technosphere | J13: (2,5,3,5,5)
A14: market for transport, freight train | B14: transport, freight train | C14: ZA | D14: 0.20072993 | E14: ton kilometer | F14: ecoinvent 3.10 cutoff | G14: technosphere | J14: (2,5,3,5,5)
A15: market for silica sand | B15: silica sand | C15: GLO | D15: 0.027372263 | E15: kilogram | F15: ecoinvent 3.10 cutoff | G15: technosphere | J15: (2,5,3,5,5)
A16: market for anode, for metal electrolysis | B16: anode, for metal electrolysis | C16: GLO | D16: 0.0054744526 | E16: kilogram | F16: ecoinvent 3.10 cutoff | G16: technosphere | J16: (2,5,3,5,5)
A17: market for electric arc furnace converter | B17: electric arc furnace converter | C17: GLO | D17: 7.2992701e-11 | E17: unit | F17: ecoinvent 3.10 cutoff | G17: technosphere | J17: (2,5,3,5,5)
A18: market for iron ore, crude ore, 46% Fe | B18: iron ore, crude ore, 46% Fe | C18: GLO | D18: 1.8248175 | E18: kilogram | F18: ecoinvent 3.10 cutoff | G18: technosphere | J18: (2,5,3,5,5)
A19: n/a (Iron and Vanadium) | D19: 1 | E19: kilogram | F19: ecoinvent 3.10 cutoff | G19: technosphere | J19: (2,5,3,5,5)
A20: market for titania slag, 85% titanium dioxide | B20: titania slag, 85% titanium dioxide | C20: GLO | D20: -0.81751825 | E20: kilogram | F20: ecoinvent 3.10 cutoff | G20: technosphere | J20: (2,5,3,5,5)
A21: market for hard coal ash | B21: hard coal ash | C21: RoW | D21: -0.80291971 | E21: kilogram | F21: ecoinvent 3.10 cutoff | G21: technosphere | J21: (2,5,3,5,5)
A22: n/a (Waste) | D22: -0.43613139 | F22: ecoinvent 3.10 cutoff | G22: technosphere | J22: (2,5,3,5,5)
A23: treatment of electric arc furnace slag, residual material landfill | B23: electric arc furnace slag | C23: RoW | D23: -0.43613139 | E23: kilogram | F23: ecoinvent 3.10 cutoff | G23: technosphere | J23: (2,5,3,5,5)
A24: Carbon dioxide, fossil | D24: 1.4071326 | E24: kilogram | F24: biosphere3 | G24: biosphere | H24: air::non-urban air or from high stacks | J24: (2,5,3,5,5)
A25: Sulfur dioxide | D25: 0.01171278 | E25: kilogram | F25: biosphere3 | G25: biosphere | H25: air::non-urban air or from high stacks | J25: (2,5,3,5,5)
A26: Radon-220 | D26: 0.0076722423 | E26: kilo Becquerel | F26: biosphere3 | G26: biosphere | H26: air::non-urban air or from high stacks | J26: (2,5,3,5,5)
A27: Radon-222 | D27: 0.0075360486 | E27: kilo Becquerel | F27: biosphere3 | G27: biosphere | H27: air::non-urban air or from high stacks | J27: (2,5,3,5,5)
A28: Nitrogen oxides | D28: 0.0058763777 | E28: kilogram | F28: biosphere3 | G28: biosphere | H28: air::non-urban air or from high stacks | J28: (2,5,3,5,5)
A29: Water | D29: 0.0019091304 | E29: cubic meter | F29: biosphere3 | G29: biosphere | H29: air | J29: (2,5,3,5,5)
A30: Polonium-210 | D30: 0.0018613132 | E30: kilo Becquerel | F30: biosphere3 | G30: biosphere | H30: air::non-urban air or from high stacks | J30: (2,5,3,5,5)
A31: Lead-210 | D31: 0.0010486911 | E31: kilo Becquerel | F31: biosphere3 | G31: biosphere | H31: air::non-urban air or from high stacks | J31: (2,5,3,5,5)
A32: Hydrochloric acid | D32: 0.00040101464 | E32: kilogram | F32: biosphere3 | G32: biosphere | H32: air::non-urban air or from high stacks | J32: (2,5,3,5,5)
A33: Potassium-40 | D33: 0.00034805044 | E33: kilo Becquerel | F33: biosphere3 | G33: biosphere | H33: air::non-urban air or from high stacks | J33: (2,5,3,5,5)
A34: Particulate Matter, > 10 um | D34: 0.00031180779 | E34: kilogram | F34: biosphere3 | G34: biosphere | H34: air::non-urban air or from high stacks | J34: (2,5,3,5,5)
A35: Radium-226 | D35: 0.00027692709 | E35: kilo Becquerel | F35: biosphere3 | G35: biosphere | H35: air::non-urban air or from high stacks | J35: (2,5,3,5,5)
... A107: Dioxins, measured as 2,3,7,8-tetrachlorodibenzo-p-dioxin | D107: 1.6040585e-13 | E107: kilogram | F107: biosphere3 | G107: biosphere | H107: air::non-urban air or from high stacks | J107: (2,5,3,5,5)
A109: Activity | B109: [R] Steel production
A110: reference product | B110: Vanadium (V) slag
A111: location | B111: ZA
A112: amount | B112: 1
...
