Workbook

Sheet README
A1: Title of the article | B1: Supplementary Information for ''Towards site-specific life cycle inventories for metals: methodological framework and application to 35 sites in Canada"
A2: Authors | B2: Marin Pellan¹, Titouan Greffe2, Guillaume Majeau-Bettez¹, Anne de Bortoli1,3,4
A3: Affiliations | B3: ¹CIRAIG, Ecole Polytechnique de Montréal, P.O. Box 6079, Montréal, H3C 3A7, Québec, Canada 2CIRAIG, Institute of Environmental Sciences, UQAM, Montreal, Quebec H2X 3Y7, Canada 3CIRAIG, Université du Québec à Montréal, C.P. 8888, succ. Centre-ville. Montréal (Québec) H3C 3P8, Québec, Canada 4LVMT, Ecole des Ponts ParisTech, Cité Descartes, 6-8 Avenue Blaise Pascal, Champs-sur-Marne, 77420, France
A4: Corresponding author | B4: marin.pellan@polymlt.ca; pellan.marin@gmail.com
A5: Journal | B5: Environmental Science & Technology
A6: Date | B6: 46023
A7: Purpose and scope | B7: This spreadsheet ….

Sheet site_selection
A1: main_id | B1: facility_group_id | C1: facility_name | D1: facility_group_name | E1: province | F1: facility_type | G1: mining_processing_type | H1: archetypes | I1: commodities | J1: Create_LCI? | K1: Main_product | L1: Stream | M1: ore_processed_t | N1: dore_t_mass | O1: conc_t_mass | P1: tailings_t_mass | Q1: Au_t | R1: Ag_t | S1: Cu_t | T1: Ni_t | U1: Co_t | V1: Mo_t | W1: Zn_t | X1: Pb_t | Y1: Fe_t | Z1: Pt_t | AA1: Pd_t | AB1: U_t | AC1: Nb_t | AD1: Cu_conc | AE1: Ni_conc | AF1: Mo_conc | AG1: Zn_conc | AH1: Pb_conc | AI1: Pt_conc | AJ1: Pd_conc | AK1: U_conc | AL1: Au_conc
A2: QC-MAIN-089f3c60 | C2: Bloom Lake | E2: Quebec | F2: mining | G2: Open-pit | H2: Magnetite concentrator | I2: Iron | J2: No (iron) | K2: Fe | L2: Fe conc. | M2: =[1]prod_table_raw!N11 -> 11187000 | P2: =M2-N2-O2 -> 11187000 | AD2: =S2/([1]concentrate_grade!$F$4/100) -> 0 | AE2: =T2/([1]concentrate_grade!$F$6/100) -> 0 | AF2: =V2/([1]concentrate_grade!$F$5/100) -> 0 | AG2: =W2/([1]concentrate_grade!$F$9/100) -> 0 | AH2: =X2/([1]concentrate_grade!$F$8/100) -> 0 | AL2: =N2 -> 0
A3: BC-MAIN-857b7b89 | C3: Brucejack | E3: British Columbia | F3: mining | G3: Underground, concentrator | H3: Au–Ag free-milling | I3: Gold, silver | J3: Yes | K3: Au | L3: Au-Ag doré | M3: =[1]prod_table_raw!N13 -> 166000 | N3: =(Q3+R3)/0.98 -> 0.92040969 | P3: =M3-N3-O3 -> 165999.08 | Q3: =[1]prod_table_raw!N14 -> 0.9020015 | AD3: =S3/([1]concentrate_grade!$F$4/100) -> 0 | AE3: =T3/([1]concentrate_grade!$F$6/100) -> 0 | AF3: =V3/([1]concentrate_grade!$F$5/100) -> 0 | AG3: =W3/([1]concentrate_grade!$F$9/100) -> 0 | AH3: =X3/([1]concentrate_grade!$F$8/100) -> 0 | AL3: =N3 -> 0.92040969
A4: QC-MAIN-de3d8b7b | C4: Canadian Electrolytic Zinc Limited (CEZinc) | E4: Quebec | F4: manufacturing | G4: Refinery | H4: Zn refinery | I4: Lead, zinc | J4: No | K4: Zn (Pb) | P4: =M4-N4-O4 -> 0 | W4: =[1]prod_table_raw!N16 -> 752600 | X4: =[1]prod_table_raw!N15 -> 244600 | AD4: =S4/([1]concentrate_grade!$F$4/100) -> 0 | AE4: =T4/([1]concentrate_grade!$F$6/100) -> 0 | AF4: =V4/([1]concentrate_grade!$F$5/100) -> 0 | AH4: =X4/([1]concentrate_grade!$F$8/100) -> 407666.67 | AL4: =N4 -> 0
A5: QC-MAIN-e7e6a960 | C5: Canadian Malartic | E5: Quebec | F5: mining | G5: Open-pit, concentrator | H5: Au–Ag free-milling | I5: Gold, silver | J5: Yes | K5: Au (Ag) | L5: Au-Ag doré | M5: =[1]prod_table_raw!N17 -> 17332900 | N5: =(Q5+R5)/0.98 -> 29.039085 | P5: =M5-N5-O5 -> 17332871 | Q5: =[1]prod_table_raw!N18 -> 18.785114 | R5: =[1]prod_table_raw!N19 -> 9.6731885 | AD5: =S5/([1]concentrate_grade!$F$4/100) -> 0 | AE5: =T5/([1]concentrate_grade!$F$6/100) -> 0 | AF5: =V5/([1]concentrate_grade!$F$5/100) -> 0 | AG5: =W5/([1]concentrate_grade!$F$9/100) -> 0 | AH5: =X5/([1]concentrate_grade!$F$8/100) -> 0 | AL5: =N5 -> 29.039085
A6: NL-MAIN-dd723db4 | C6: Carol Lake | E6: Newfoundland and Labrador | F6: mining | G6: Open-pit, concentrator | H6: Fe concentrator + pellet plant | I6: Iron | J6: No (iron) | K6: Fe | L6: Fe conc., Fe pellets | M6: =[1]prod_table_raw!N21 -> 16478000 | P6: =M6-N6-O6 -> 16478000 | AD6: =S6/([1]concentrate_grade!$F$4/100) -> 0 | AE6: =T6/([1]concentrate_grade!$F$6/100) -> 0 | AF6: =V6/([1]concentrate_grade!$F$5/100) -> 0 | AG6: =W6/([1]concentrate_grade!$F$9/100) -> 0 | AH6: =X6/([1]concentrate_grade!$F$8/100) -> 0 | AL6: =N6 -> 0
A7: QC-MAIN-b86f7d07 | C7: Casa Berardi | E7: Quebec | F7: mining | G7: Open-pit, underground, concentrator | H7: Au–Ag free-milling | I7: Gold, silver | J7: Yes | K7: Au | L7: Au-Ag doré | M7: =[1]prod_table_raw!N24 -> 1361450 | N7: =(Q7+R7)/0.98 -> 3.5165998 | P7: =M7-N7-O7 -> 1361446.5 | Q7: =[1]prod_table_raw!N22 -> 2.6935631 | R7: =[1]prod_table_raw!N23 -> 0.7527047 | AD7: =S7/([1]concentrate_grade!$F$4/100) -> 0 | AE7: =T7/([1]concentrate_grade!$F$6/100) -> 0 | AF7: =V7/([1]concentrate_grade!$F$5/100) -> 0 | AG7: =W7/([1]concentrate_grade!$F$9/100) -> 0 | AH7: =X7/([1]concentrate_grade!$F$8/100) -> 0 | AL7: =N7 -> 3.5165998
A8: ON-MAIN-f080c409 | B8: GRP-dc07540b | C8: Copper Cliff Complex (mine) | D8: Sudbury Operation | E8: Ontario | F8: mining | G8: Underground | H8: Ni–Cu sulfide | I8: Nickel, copper, platinum group metals, gold, silver, cobalt, selenium, tellurium | J8: Not sure (Vale Sudbury) | K8: Ni+Cu | L8: Ni-Cu bulk conc. | M8: =[1]prod_table_raw!N30 -> 748000 | O8: =T8/([1]concentrate_grade!$F$6/100) -> 54693.75 | P8: =M8-N8-O8 -> 693306.25 | S8: =[1]prod_table_raw!N29 -> 10098 | T8: =[1]prod_table_raw!N28 -> 8751 | AE8: =T8/([1]concentrate_grade!$F$6/100) -> 54693.75 | AF8: =V8/([1]concentrate_grade!$F$5/100) -> 0 | AG8: =W8/([1]concentrate_grade!$F$9/100) -> 0 | AH8: =X8/([1]concentrate_grade!$F$8/100) -> 0 | AL8: =N8 -> 0
A9: ON-MAIN-63b394c3 | B9: GRP-dc07540b | C9: Copper Cliff Complex (refinery) | D9: Sudbury Operation | E9: Ontario | F9: manufacturing | G9: Smelter, refinery, plant | H9: Cu-Ni smelter and refinery | I9: Nickel (oxide sinter, pellets, powder, sulfide), copper cathodes, gold, silver, selenium cake, tellurium dioxide cake, platinum group metals (in residues), liquid sulfur dioxide, sulfuric acid | J9: Not sure (Vale Sudbury) | K9: Ni+Cu | L9: Refined Ni+Cu | P9: =M9-N9-O9 -> 0 | S9: =[1]prod_table_raw!N31 -> 57900 | T9: =[1]prod_table_raw!N32 -> 38200 | AF9: =V9/([1]concentrate_grade!$F$5/100) -> 0 | AH9: =X9/([1]concentrate_grade!$F$8/100) -> 0 | AL9: =N9 -> 0
A10: BC-MAIN-599152a0 | C10: Copper Mountain | E10: British Columbia | F10: mining | G10: Open-pit, concentrator | H10: Cu Porphyry | I10: Copper, gold, silver | J10: Yes | K10: Cu (Au, Ag) | L10: Cu conc. | M10: =[1]prod_table_raw!N36 -> 6862152 | O10: =S10/([1]concentrate_grade!$F$4/100) -> 63500 | P10: =M10-N10-O10 -> 6798652 | Q10: =[1]prod_table_raw!N35 -> 0.27520377 | R10: =[1]prod_table_raw!N38 -> 6.7893342 | S10: =[1]prod_table_raw!N39 -> 19050 | AD10: =S10/([1]concentrate_grade!$F$4/100) -> 63500 | AE10: =T10/([1]concentrate_grade!$F$6/100) -> 0 | AF10: =V10/([1]concentrate_grade!$F$5/100) -> 0 | AG10: =W10/([1]concentrate_grade!$F$9/100) -> 0 | AH10: =X10/([1]concentrate_grade!$F$8/100) -> 0 | AL10: =N10 -> 0
A11: ON-MAIN-52224e1e | B11: GRP-dc07540b | C11: Creighton | D11: Sudbury Operation | E11: Ontario | F11: mining | G11: Underground | H11: Ni–Cu sulfide | I11: Nickel, copper, platinum group metals, gold, silver, cobalt, selenium, tellurium | J11: Not sure (Vale Sudbury) | K11: Ni+Cu | L11: Ni-Cu bulk conc. | M11: =[1]prod_table_raw!N44 -> 433000 | O11: =T11/([1]concentrate_grade!$F$6/100) -> 70900 | P11: =M11-N11-O11 -> 362100 | S11: =[1]prod_table_raw!N43 -> 9396 | T11: =[1]prod_table_raw!N42 -> 11344 | AE11: =T11/([1]concentrate_grade!$F$6/100) -> 70900 | AF11: =V11/([1]concentrate_grade!$F$5/100) -> 0 | AG11: =W11/([1]concentrate_grade!$F$9/100) -> 0 | AH11: =X11/([1]concentrate_grade!$F$8/100) -> 0 | AL11: =N11 -> 0
A12: ON-MAIN-aeafbb59 | C12: Detour Lake | E12: Ontario | F12: mining | G12: Open-pit, concentrator | H12: Au–Ag free-milling | I12: Gold | J12: Yes | K12: Au (Ag) | L12: Au-Ag doré | M12: =[1]prod_table_raw!N48 -> 25434854 | N12: =(Q12+R12)/0.98 -> 24.008284 | P12: =M12-N12-O12 -> 25434829 | Q12: =[1]prod_table_raw!N49 -> 21.070942 | R12: =[1]prod_table_raw!N50 -> 2.4571765 | AD12: =S12/([1]concentrate_grade!$F$4/100) -> 0 | AE12: =T12/([1]concentrate_grade!$F$6/100) -> 0 | AF12: =V12/([1]concentrate_grade!$F$5/100) -> 0 | AG12: =W12/([1]concentrate_grade!$F$9/100) -> 0 | AH12: =X12/([1]concentrate_grade!$F$8/100) -> 0 | AL12: =N12 -> 24.008284
A13: ON-MAIN-cb85213a | C13: Eagle River | E13: Ontario | F13: mining | G13: Underground, concentrator | H13: Au–Ag free-milling | I13: Gold | J13: Yes | K13: Au | L13: Au-Ag doré | M13: =[1]prod_table_raw!N55 -> 222627 | N13: =(Q13+R13)/0.98 -> 2.7760509 | P13: =M13-N13-O13 -> 222624.22 | Q13: =[1]prod_table_raw!N54 -> 2.7205298 | AD13: =S13/([1]concentrate_grade!$F$4/100) -> 0 | AE13: =T13/([1]concentrate_grade!$F$6/100) -> 0 | AF13: =V13/([1]concentrate_grade!$F$5/100) -> 0 | AG13: =W13/([1]concentrate_grade!$F$9/100) -> 0 | AH13: =X13/([1]concentrate_grade!$F$8/100) -> 0 | AL13: =N13 -> 2.7760509
A14: QC-MAIN-6dc537e6 | C14: Éléonore | E14: Quebec | F14: mining | G14: Underground, concentrator | H14: Au–Ag free-milling | I14: Gold, silver | J14: Yes | K14: Au (Ag) | L14: Au-Ag doré | M14: =[1]prod_table_raw!N62 -> 1661000 | N14: =(Q14+R14)/0.98 -> 7.7388999 | P14: =M14-N14-O14 -> 1660992.3 | Q14: =[1]prod_table_raw!N59 -> 7.216012 | R14: =[1]prod_table_raw!N60 -> 0.36810992 | AD14: =S14/([1]concentrate_grade!$F$4/100) -> 0 | AE14: =T14/([1]concentrate_grade!$F$6/100) -> 0 | AF14: =V14/([1]concentrate_grade!$F$5/100) -> 0 | AG14: =W14/([1]concentrate_grade!$F$9/100) -> 0 | AH14: =X14/([1]concentrate_grade!$F$8/100) -> 0 | AL14: =N14 -> 7.7388999
A15: BC-MAIN-4724f4ba | C15: Elk | E15: British Columbia | F15: mining | G15: Open-pit | H15: Au–Ag free-milling | I15: Gold | J15: Not sure (no NPRI) | K15: Au | L15: Au-Ag doré | M15: =[1]prod_table_raw!N64 -> 33245 | N15: =(Q15+R15)/0.98 -> 0.12428705 | P15: =M15-N15-O15 -> 33244.876 | Q15: =[1]prod_table_raw!N65 -> 0.12180131 | AD15: =S15/([1]concentrate_grade!$F$4/100) -> 0 | AE15: =T15/([1]concentrate_grade!$F$6/100) -> 0 | AF15: =V15/([1]concentrate_grade!$F$5/100) -> 0 | AG15: =W15/([1]concentrate_grade!$F$9/100) -> 0 | AH15: =X15/([1]concentrate_grade!$F$8/100) -> 0 | AL15: =N15 -> 0.12428705
A16: ON-MAIN-4e0734b5 | C16: Fox Complex | E16: Ontario | F16: mining | G16: Open-pit, underground, concentrator | H16: Au–Ag free-milling | I16: Gold | J16: Not sure (no technosphere) | K16: Au | L16: Au-Ag doré | M16: =[1]prod_table_raw!N70 -> 457000 | N16: =(Q16+R16)/0.98 -> 1.4536126 | P16: =M16-N16-O16 -> 456998.55 | Q16: =[1]prod_table_raw!N71 -> 1.3809954 | R16: =[1]prod_table_raw!N72 -> 0.0435449 | AD16: =S16/([1]concentrate_grade!$F$4/100) -> 0 | AE16: =T16/([1]concentrate_grade!$F$6/100) -> 0 | AF16: =V16/([1]concentrate_grade!$F$5/100) -> 0 | AG16: =W16/([1]concentrate_grade!$F$9/100) -> 0 | AH16: =X16/([1]concentrate_grade!$F$8/100) -> 0 | AL16: =N16 -> 1.4536126
A17: ON-MAIN-206041d1 | B17: GRP-de097f20 | C17: Fraser | D17: Integrated Nickel Operations | E17: Ontario | F17: mining | G17: Underground | H17: Ni–Cu sulfide | I17: Nickel, copper, platinum group metals, gold, cobalt, silver | J17: No | K17: Ni+Cu | L17: Ni-Cu bulk conc. | M17: =[1]prod_table_raw!N73 -> 553033 | O17: =T17/([1]concentrate_grade!$F$6/100) -> 0 | P17: =M17-N17-O17 -> 553033 | AE17: =T17/([1]concentrate_grade!$F$6/100) -> 0 | AF17: =V17/([1]concentrate_grade!$F$5/100) -> 0 | AG17: =W17/([1]concentrate_grade!$F$9/100) -> 0 | AH17: =X17/([1]concentrate_grade!$F$8/100) -> 0 | AL17: =N17 -> 0
A18: ON-MAIN-48fe2205 | B18: GRP-dc07540b | C18: Garson | D18: Sudbury Operation | E18: Ontario | F18: mining | G18: Underground | H18: Ni–Cu sulfide | I18: Nickel, copper, platinum group metals, gold, silver, cobalt, selenium, tellurium | J18: Not sure (Vale Sudbury) | K18: Ni+Cu | L18: Ni-Cu bulk conc. | M18: =[1]prod_table_raw!N76 -> 616000 | O18: =T18/([1]concentrate_grade!$F$6/100) -> 49662.5 | P18: =M18-N18-O18 -> 566337.5 | S18: =[1]prod_table_raw!N75 -> 7453 | T18: =[1]prod_table_raw!N74 -> 7946 | AE18: =T18/([1]concentrate_grade!$F$6/100) -> 49662.5 | AF18: =V18/([1]concentrate_grade!$F$5/100) -> 0 | AG18: =W18/([1]concentrate_grade!$F$9/100) -> 0 | AH18: =X18/([1]concentrate_grade!$F$8/100) -> 0 | AL18: =N18 -> 0
A19: BC-MAIN-6b4800fe | C19: Gibraltar | E19: British Columbia | F19: mining | G19: Open-pit, concentrator | H19: Cu polymetallic | I19: Copper, molybdenum, silver | J19: Yes | K19: Cu+Mo | L19: Cu and Mo conc. | M19: =[1]prod_table_raw!N80 -> 30000000 | O19: =S19/([1]concentrate_grade!$F$4/100)+V19/([1]concentrate_grade!$F$5/100) -> 186436.98 | P19: =M19-N19-O19 -> 29813563 | S19: =[1]prod_table_raw!N82 -> 55610.379 | V19: =[1]prod_table_raw!N81 -> 545.21758 | AD19: =S19/([1]concentrate_grade!$F$4/100) -> 185367.93 | AE19: =T19/([1]concentrate_grade!$F$6/100) -> 0 | AF19: =V19/([1]concentrate_grade!$F$5/100) -> 1069.0541 | AG19: =W19/([1]concentrate_grade!$F$9/100) -> 0 | AH19: =X19/([1]concentrate_grade!$F$8/100) -> 0 | AL19: =N19 -> 0
A20: QC-MAIN-c0660aec | C20: Goldex | E20: Quebec | F20: mining | G20: Underground, concentrator | H20: Au–Ag polymetallic | I20: Gold, silver | J20: Yes | K20: Au-Ag+Cu | L20: Au-Ag doré, Cu conc. | M20: =[1]prod_table_raw!N86 -> 2886927.3 | N20: =(Q20+R20)/0.98 -> 4.4745421 | O20: =S20/([1]concentrate_grade!$F$4/100) -> 130.12253 | P20: =M20-N20-O20 -> 2886792.7 | Q20: =[1]prod_table_raw!N87 -> 4.3850513 | S20: =[1]prod_table_raw!N85 -> 39.036758 | AD20: =S20/([1]concentrate_grade!$F$4/100) -> 130.12253 | AE20: =T20/([1]concentrate_grade!$F$6/100) -> 0 | AF20: =V20/([1]concentrate_grade!$F$5/100) -> 0 | AG20: =W20/([1]concentrate_grade!$F$9/100) -> 0 | AH20: =X20/([1]concentrate_grade!$F$8/100) -> 0 | AL20: =N20 -> 4.4745421
A21: ON-MAIN-6e9be24e | C21: Hemlo (Williams) | E21: Ontario | F21: mining | G21: Open-pit, underground, concentrator | H21: Au–Ag free-milling | I21: Gold | J21: Yes | K21: Au | L21: Au-Ag doré | M21: =[1]prod_table_raw!N91 -> 1266009 | N21: =(Q21+R21)/0.98 -> 4.4765236 | P21: =M21-N21-O21 -> 1266004.5 | Q21: =[1]prod_table_raw!N92 -> 4.3869932 | AD21: =S21/([1]concentrate_grade!$F$4/100) -> 0 | AE21: =T21/([1]concentrate_grade!$F$6/100) -> 0 | AF21: =V21/([1]concentrate_grade!$F$5/100) -> 0 | AG21: =W21/([1]concentrate_grade!$F$9/100) -> 0 | AH21: =X21/([1]concentrate_grade!$F$8/100) -> 0 | AL21: =N21 -> 4.4765236
A22: BC-MAIN-bf503b6b | C22: Highland Valley | E22: British Columbia | F22: mining | G22: Open-pit, concentrator | H22: Cu polymetallic | I22: Copper, silver, molybdenum | J22: Yes | K22: Cu+Mo | L22: Cu and Mo conc. | M22: =[1]prod_table_raw!N93 -> 17408000 | O22: =S22/([1]concentrate_grade!$F$4/100)+V22/([1]concentrate_grade!$F$5/100) -> 343098.04 | P22: =M22-N22-O22 -> 17064902 | S22: =[1]prod_table_raw!N95 -> 102400 | V22: =[1]prod_table_raw!N94 -> 900 | AD22: =S22/([1]concentrate_grade!$F$4/100) -> 341333.33 | AE22: =T22/([1]concentrate_grade!$F$6/100) -> 0 | AF22: =V22/([1]concentrate_grade!$F$5/100) -> 1764.7059 | AG22: =W22/([1]concentrate_grade!$F$9/100) -> 0 | AH22: =X22/([1]concentrate_grade!$F$8/100) -> 0 | AL22: =N22 -> 0
A23: QC-MAIN-30c1828c | B23: GRP-b48ec279 | C23: Horne | D23: CCR | E23: Quebec | F23: manufacturing | G23: Smelter | H23: Cu smelter | I23: Copper anodes, precious metals, sulfuric acid | J23: Manufacturing | K23: Cu | P23: =M23-N23-O23 -> 0 | AD23: =S23/([1]concentrate_grade!$F$4/100) -> 0 | AE23: =T23/([1]concentrate_grade!$F$6/100) -> 0 | AF23: =V23/([1]concentrate_grade!$F$5/100) -> 0 | AH23: =X23/([1]concentrate_grade!$F$8/100) -> 0 | AL23: =N23 -> 0
A24: ON-MAIN-687b8c8d | C24: Island | E24: Ontario | F24: mining | G24: Underground, concentrator | H24: Au–Ag free-milling | I24: Gold | J24: Yes | K24: Au | L24: Au-Ag doré | M24: =[1]prod_table_raw!N105 -> 439008 | N24: =(Q24+R24)/0.98 -> 4.1704081 | P24: =M24-N24-O24 -> 439003.83 | Q24: =[1]prod_table_raw!N103 -> 4.0869999 | AD24: =S24/([1]concentrate_grade!$F$4/100) -> 0 | AE24: =T24/([1]concentrate_grade!$F$6/100) -> 0 | AF24: =V24/([1]concentrate_grade!$F$5/100) -> 0 | AG24: =W24/([1]concentrate_grade!$F$9/100) -> 0 | AH24: =X24/([1]concentrate_grade!$F$8/100) -> 0 | AL24: =N24 -> 4.1704081
A25: YT-MAIN-44857446 | C25: Keno Hill Silver District | D25: Key Lake + McArthur River | E25: Yukon | F25: mining | G25: Underground, concentrator | H25: Ag polymetallic | I25: Silver, zinc, lead | J25: Not sure (no NPRI) but technosphere | K25: Ag (Zn, Pb) | L25: Pb and Zn conc. | M25: =[1]prod_table_raw!N110 -> 127307 | O25: =W25/([1]concentrate_grade!F9/100)+X25/([1]concentrate_grade!F8/100) -> 4719.6667 | P25: =M25-N25-O25 -> 122587.33 | R25: =[1]prod_table_raw!N109 -> 46.735404 | W25: =[1]prod_table_raw!N112 -> 1339 | X25: =[1]prod_table_raw!N111 -> 1225 | AD25: =S25/([1]concentrate_grade!$F$4/100) -> 0 | AE25: =T25/([1]concentrate_grade!$F$6/100) -> 0 | AF25: =V25/([1]concentrate_grade!$F$5/100) -> 0 | AG25: =W25/([1]concentrate_grade!$F$9/100) -> 2678 | AH25: =X25/([1]concentrate_grade!$F$8/100) -> 2041.6667 | AL25: =N25 -> 0
A26: ON-MAIN-f8313ebd | C26: Kidd Creek | E26: Ontario | F26: mining | G26: Underground, concentrator | H26: Cu polymetallic | I26: Copper, zinc, silver, selenium, indium | J26: Not sure (no technosphere) | K26: Cu+Zn (Ag) | L26: Cu and Zn conc. | M26: =[1]prod_table_raw!N116 -> 1340000 | O26: =S26/([1]concentrate_grade!$F$4/100)+W26/([1]concentrate_grade!$F$9/100) -> 152533.33 | P26: =M26-N26-O26 -> 1187466.7 | R26: =[1]prod_table_raw!N115 -> 42.860623 | S26: =[1]prod_table_raw!N113 -> 22600 | W26: =[1]prod_table_raw!N114 -> 38600 | AD26: =S26/([1]concentrate_grade!$F$4/100) -> 75333.333 | AE26: =T26/([1]concentrate_grade!$F$6/100) -> 0 | AF26: =V26/([1]concentrate_grade!$F$5/100) -> 0 | AG26: =W26/([1]concentrate_grade!$F$9/100) -> 77200 | AH26: =X26/([1]concentrate_grade!$F$8/100) -> 0 | AL26: =N26 -> 0
A27: QC-MAIN-9de9bb0d | C27: Kiena | E27: Quebec | F27: mining | G27: Open-pit, concentrator | H27: Au–Ag free-milling | I27: Gold, silver | J27: Not sure (no NPRI) but technosphere | K27: Au (Ag) | L27: Au-Ag doré | M27: =[1]prod_table_raw!N120 -> 191148 | N27: =(Q27+R27)/0.98 -> 1.2201776 | P27: =M27-N27-O27 -> 191146.78 | Q27: =[1]prod_table_raw!N119 -> 1.1053251 | R27: =[1]prod_table_raw!N121 -> 0.090448978 | AD27: =S27/([1]concentrate_grade!$F$4/100) -> 0 | AE27: =T27/([1]concentrate_grade!$F$6/100) -> 0 | AF27: =V27/([1]concentrate_grade!$F$5/100) -> 0 | AG27: =W27/([1]concentrate_grade!$F$9/100) -> 0 | AH27: =X27/([1]concentrate_grade!$F$8/100) -> 0 | AL27: =N27 -> 1.2201776
A28: ON-MAIN-a3c56a83 | C28: Lac des Iles | E28: Ontario | F28: mining | G28: Open-pit, underground, concentrator | H28: Ni–Cu sulfide | I28: Platinum group metals, gold, nickel, copper, cobalt | J28: Not sure (no NPRI) but technosphere | K28: Pt | L28: PGM bulk conc. | M28: =[1]prod_table_raw!N124 -> 3798000 | P28: =M28-N28-O28 -> 3798000 | Q28: =[1]prod_table_raw!N125 -> 0.59407685 | Z28: =[1]prod_table_raw!N127 -> 0.6780563 | AA28: =[1]prod_table_raw!N126 -> 0.7775875 | AD28: =S28/([1]concentrate_grade!$F$4/100) -> 0 | AE28: =T28/([1]concentrate_grade!$F$6/100) -> 0 | AF28: =V28/([1]concentrate_grade!$F$5/100) -> 0 | AG28: =W28/([1]concentrate_grade!$F$9/100) -> 0 | AH28: =X28/([1]concentrate_grade!$F$8/100) -> 0 | AL28: =N28 -> 0
A29: QC-MAIN-f9e41c2a | C29: Lamaque | E29: Quebec | F29: mining | G29: Underground, concentrator | H29: Au–Ag free-milling | I29: Gold, silver | J29: Not sure (no NPRI) but technosphere | K29: Au (Ag) | L29: Au-Ag doré | M29: =[1]prod_table_raw!N134 -> 838419 | N29: =(Q29+R29)/0.98 -> 7.9328207 | P29: =M29-N29-O29 -> 838411.07 | Q29: =[1]prod_table_raw!N133 -> 5.5074656 | R29: =[1]prod_table_raw!N135 -> 2.2666987 | AD29: =S29/([1]concentrate_grade!$F$4/100) -> 0 | AE29: =T29/([1]concentrate_grade!$F$6/100) -> 0 | AF29: =V29/([1]concentrate_grade!$F$5/100) -> 0 | AG29: =W29/([1]concentrate_grade!$F$9/100) -> 0 | AH29: =X29/([1]concentrate_grade!$F$8/100) -> 0 | AL29: =N29 -> 7.9328207
A30: QC-MAIN-e51eda66 | C30: LaRonde | E30: Quebec | F30: mining | G30: Underground, concentrator | H30: Au–Ag polymetallic | I30: Gold, zinc, copper, silver, cadmium | J30: Yes | K30: Au-Ag+Cu+Zn | L30: Au-Ag doré, Cu and Zn conc. | M30: =[1]prod_table_raw!N139 -> 1501500 | N30: =(Q30+R30)/0.98 -> 9.8029028 | O30: =S30/([1]concentrate_grade!$F$4/100)+W30/([1]concentrate_grade!$F$9/100) -> 23998.078 | P30: =M30-N30-O30 -> 1477492.1 | Q30: =[1]prod_table_raw!N138 -> 7.3401461 | R30: =[1]prod_table_raw!N135 -> 2.2666987 | S30: =[1]prod_table_raw!N137 -> 2577.9604 | W30: =[1]prod_table_raw!N136 -> 7702.4385 | AD30: =S30/([1]concentrate_grade!$F$4/100) -> 8593.2013 | AE30: =T30/([1]concentrate_grade!$F$6/100) -> 0 | AF30: =V30/([1]concentrate_grade!$F$5/100) -> 0 | AG30: =W30/([1]concentrate_grade!$F$9/100) -> 15404.877 | AH30: =X30/([1]concentrate_grade!$F$8/100) -> 0 | AL30: =N30 -> 9.8029028
A31: NL-MAIN-d9036091 | C31: Long Harbour | E31: Newfoundland and Labrador | F31: manufacturing | G31: Refinery | H31: Ni hydrometallurgical refinery | I31: Nickel | J31: Yes (manufacturing) | K31: Ni | L31: Refined Ni | P31: =M31-N31-O31 -> 0 | T31: =[1]prod_table_raw!N145 -> 27700 | AD31: =S31/([1]concentrate_grade!$F$4/100) -> 0 | AF31: =V31/([1]concentrate_grade!$F$5/100) -> 0 | AH31: =X31/([1]concentrate_grade!$F$8/100) -> 0 | AL31: =N31 -> 0
A32: ON-MAIN-1f126a43 | C32: Macassa | E32: Ontario | F32: mining | G32: Underground, concentrator | H32: Au–Ag free-milling | I32: Gold, silver | J32: Yes | K32: Au | L32: Au-Ag doré | M32: =[1]prod_table_raw!N146 -> 441588 | N32: =(Q32+R32)/0.98 -> 7.2533045 | P32: =M32-N32-O32 -> 441580.75 | Q32: =[1]prod_table_raw!N147 -> 7.1082384 | AD32: =S32/([1]concentrate_grade!$F$4/100) -> 0 | AE32: =T32/([1]concentrate_grade!$F$6/100) -> 0 | AF32: =V32/([1]concentrate_grade!$F$5/100) -> 0 | AG32: =W32/([1]concentrate_grade!$F$9/100) -> 0 | AH32: =X32/([1]concentrate_grade!$F$8/100) -> 0 | AL32: =N32 -> 7.2533045
A33: ON-MAIN-8825d90d | C33: Magino | E33: Ontario | F33: mining | G33: Open-pit, concentrator | H33: Au–Ag free-milling | I33: Gold, silver | J33: Not sure (no technosphere) | K33: Au | L33: Au-Ag doré | M33: =[1]prod_table_raw!N150 -> 1165551 | N33: =(Q33+R33)/0.98 -> 1.0473628 | P33: =M33-N33-O33 -> 1165550 | Q33: =[1]prod_table_raw!N148 -> 1.0264155 | AD33: =S33/([1]concentrate_grade!$F$4/100) -> 0 | AE33: =T33/([1]concentrate_grade!$F$6/100) -> 0 | AF33: =V33/([1]concentrate_grade!$F$5/100) -> 0 | AG33: =W33/([1]concentrate_grade!$F$9/100) -> 0 | AH33: =X33/([1]concentrate_grade!$F$8/100) -> 0 | AL33: =N33 -> 1.0473628
A34: NU-MAIN-5154702a | C34: Mary River | E34: Nunavut | F34: mining | G34: Open-pit | H34: Direct Shipping Ore | I34: Iron ore | J34: No (iron) | K34: Fe | L34: DSO | M34: =[1]prod_table_raw!N151 -> 5600000 | P34: =M34-N34-O34 -> 5600000 | AD34: =S34/([1]concentrate_grade!$F$4/100) -> 0 | AE34: =T34/([1]concentrate_grade!$F$6/100) -> 0 | AF34: =V34/([1]concentrate_grade!$F$5/100) -> 0 | AG34: =W34/([1]concentrate_grade!$F$9/100) -> 0 | AH34: =X34/([1]concentrate_grade!$F$8/100) -> 0 | AL34: =N34 -> 0
A35: ON-MAIN-7001a391 | C35: McCreedy West | E35: Ontario | F35: mining | G35: Underground | H35: Ni–Cu sulfide | I35: Copper, nickel, platinum group metals, gold, silver, cobalt | J35: Not sure (no technosphere and no GHG) | K35: PGMs+Cu+Ni | L35: Cu-PGM conc. and Ni-Cu conc. | M35: =[1]prod_table_raw!N157 -> 317660 | P35: =M35-N35-O35 -> 317660 | AD35: =S35/([1]concentrate_grade!$F$4/100) -> 0 | AE35: =T35/([1]concentrate_grade!$F$6/100) -> 0 | AF35: =V35/([1]concentrate_grade!$F$5/100) -> 0 | AG35: =W35/([1]concentrate_grade!$F$9/100) -> 0 | AH35: =X35/([1]concentrate_grade!$F$8/100) -> 0 | AL35: =N35 -> 0
A36: NU-MAIN-8b0264c9 | C36: Meliadine | E36: Nunavut | F36: mining | G36: Open-pit, underground, concentrator | H36: Au–Ag free-milling | I36: Gold | J36: Yes | K36: Au (Ag) | L36: Au-Ag doré | M36: =[1]prod_table_raw!N163 -> 1918143 | N36: =(Q36+R36)/0.98 -> 12.414137 | P36: =M36-N36-O36 -> 1918130.6 | Q36: =[1]prod_table_raw!N164 -> 11.32606 | R36: =[1]prod_table_raw!N165 -> 0.8397945 | AD36: =S36/([1]concentrate_grade!$F$4/100) -> 0 | AE36: =T36/([1]concentrate_grade!$F$6/100) -> 0 | AF36: =V36/([1]concentrate_grade!$F$5/100) -> 0 | AG36: =W36/([1]concentrate_grade!$F$9/100) -> 0 | AH36: =X36/([1]concentrate_grade!$F$8/100) -> 0 | AL36: =N36 -> 12.414137
A37: BC-MAIN-ed23117f | C37: Mount Milligan | E37: British Columbia | F37: mining | G37: Open-pit, concentrator | H37: Cu Porphyry | I37: Copper, gold, silver | J37: Yes | K37: Cu (Au) | L37: Cu conc. | M37: =[1]prod_table_raw!N175 -> 21680000 | O37: =S37/([1]concentrate_grade!$F$4/100) -> 93533.694 | P37: =M37-N37-O37 -> 21586466 | Q37: =[1]prod_table_raw!N173 -> 4.8021005 | S37: =[1]prod_table_raw!N171 -> 28060.108 | AD37: =S37/([1]concentrate_grade!$F$4/100) -> 93533.694 | AE37: =T37/([1]concentrate_grade!$F$6/100) -> 0 | AF37: =V37/([1]concentrate_grade!$F$5/100) -> 0 | AG37: =W37/([1]concentrate_grade!$F$9/100) -> 0 | AH37: =X37/([1]concentrate_grade!$F$8/100) -> 0 | AL37: =N37 -> 0
A38: BC-MAIN-3f490561 | C38: Mount Polley | E38: British Columbia | F38: mining | G38: Open-pit, concentrator | H38: Cu Porphyry | I38: Gold, copper, silver | J38: Yes | K38: Cu (Au) | L38: Cu conc. | M38: =[1]prod_table_raw!N179 -> 5948239 | O38: =S38/([1]concentrate_grade!$F$4/100) -> 45578.436 | P38: =M38-N38-O38 -> 5902660.6 | Q38: =[1]prod_table_raw!N178 -> 1.3011838 | S38: =[1]prod_table_raw!N180 -> 13673.531 | AD38: =S38/([1]concentrate_grade!$F$4/100) -> 45578.436 | AE38: =T38/([1]concentrate_grade!$F$6/100) -> 0 | AF38: =V38/([1]concentrate_grade!$F$5/100) -> 0 | AG38: =W38/([1]concentrate_grade!$F$9/100) -> 0 | AH38: =X38/([1]concentrate_grade!$F$8/100) -> 0 | AL38: =N38 -> 0
A39: ON-MAIN-fefeaee4 | C39: Musselwhite | E39: Ontario | F39: mining | G39: Underground, concentrator | H39: Au–Ag free-milling | I39: Gold, silver | J39: Yes | K39: Au | L39: Au-Ag doré | M39: =[1]prod_table_raw!N183 -> 1028000 | N39: =(Q39+R39)/0.98 -> 5.7128878 | P39: =M39-N39-O39 -> 1027994.3 | Q39: =[1]prod_table_raw!N184 -> 5.59863 | AD39: =S39/([1]concentrate_grade!$F$4/100) -> 0 | AE39: =T39/([1]concentrate_grade!$F$6/100) -> 0 | AF39: =V39/([1]concentrate_grade!$F$5/100) -> 0 | AG39: =W39/([1]concentrate_grade!$F$9/100) -> 0 | AH39: =X39/([1]concentrate_grade!$F$8/100) -> 0 | AL39: =N39 -> 5.7128878
A40: BC-MAIN-aa76f6f2 | C40: New Afton | E40: British Columbia | F40: mining | G40: Underground, concentrator | H40: Cu Porphyry | I40: Gold, copper, silver | J40: Yes | K40: Cu (Au) | L40: Cu conc. | M40: =[1]prod_table_raw!N189 -> 3065000 | O40: =S40/([1]concentrate_grade!$F$4/100) -> 71667.536 | P40: =M40-N40-O40 -> 2993332.5 | Q40: =[1]prod_table_raw!N187 -> 2.0974023 | S40: =[1]prod_table_raw!N190 -> 21500.261 | AD40: =S40/([1]concentrate_grade!$F$4/100) -> 71667.536 | AE40: =T40/([1]concentrate_grade!$F$6/100) -> 0 | AF40: =V40/([1]concentrate_grade!$F$5/100) -> 0 | AG40: =W40/([1]concentrate_grade!$F$9/100) -> 0 | AH40: =X40/([1]concentrate_grade!$F$8/100) -> 0 | AL40: =N40 -> 0
...

Sheet market_shares
A1: lci_name | B1: reference_product | C1: site | D1: site_id | E1: activity_name | F1: market_share | G1: info | H1: details
A2: Brucejack | B2: Doré | C2: Brucejack | D2: =site_selection!A3 -> BC-MAIN-857b7b89 | E2: Underground mining and beneficiation at Brucejack | F2: =market_shares_calc!E2 -> 0.004272279
A3: Canadian Malartic | B3: Doré | C3: Canadian Malartic | D3: =site_selection!A5 -> QC-MAIN-e7e6a960 | E3: Open-pit mining and beneficiation at Canadian Malartic | F3: =market_shares_calc!E3 -> 0.13479114
A4: Casa Berardi | B4: Doré | C4: Casa Berardi | D4: =site_selection!A7 -> QC-MAIN-b86f7d07 | E4: Open-pit and underground mining and beneficiation at Casa Berardi | F4: =market_shares_calc!E4 -> 0.016323052
A5: Cigar Lake + McClean Lake | B5: U concentrate | C5: Cigar Lake + McClean Lake | D5: =site_selection!B60 -> GRP-91aaa60b | E5: Underground mining and beneficiation at Cigar Lake + McClean Lake | F5: =market_shares_calc!H48 -> 0.57142857
A6: Copper Mountain | B6: Cu concentrate | C6: Copper Mountain | D6: =site_selection!A10 -> BC-MAIN-599152a0 | E6: Open-pit mining and beneficiation at Copper Mountain | F6: =market_shares_calc!F6 -> 0.06763347
A7: Detour Lake | B7: Doré | C7: Detour Lake | D7: =site_selection!A12 -> ON-MAIN-aeafbb59 | E7: Open-pit mining and beneficiation at Detour Lake | F7: =market_shares_calc!E8 -> 0.1114396
A8: Eagle River | B8: Doré | C8: Eagle River | D8: =site_selection!A13 -> ON-MAIN-cb85213a | E8: Underground mining and beneficiation at Eagle River | F8: =market_shares_calc!E9 -> 0.012885635
A9: Éléonore | B9: Doré | C9: Éléonore | D9: =site_selection!A14 -> QC-MAIN-6dc537e6 | E9: Underground mining and beneficiation at Éléonore | F9: =market_shares_calc!E10 -> 0.035921764
A10: Elk | B10: Doré | C10: Elk | D10: =site_selection!A15 -> BC-MAIN-4724f4ba | E10: Open-pit mining at Elk | F10: =market_shares_calc!E11 -> 0.00057690499 | G10: Lots of missing flows
A11: Fox Complex | B11: Doré | C11: Fox Complex | D11: =site_selection!A16 -> ON-MAIN-4e0734b5 | E11: Open-pit and underground mining and beneficiation at Fox Complex | F11: =market_shares_calc!E12 -> 0.0067472544 | G11: CO2 fossil | H11: No GHG
A12: Gibraltar (Cu) | B12: Cu concentrate | C12: Gibraltar | D12: =site_selection!A19 -> BC-MAIN-6b4800fe | E12: Open-pit mining and beneficiation at Gibraltar | F12: =market_shares_calc!F15 -> 0.19743427
A13: Gibraltar (Mo) | B13: Mo concentrate | C13: Gibraltar | D13: =site_selection!A19 -> BC-MAIN-6b4800fe | E13: Open-pit mining and beneficiation at Gibraltar | F13: =market_shares_calc!J15 -> 0.3772564
A14: Goldex (Cu) | B14: Cu concentrate | C14: Goldex | D14: =site_selection!A20 -> QC-MAIN-c0660aec | E14: Underground mining and beneficiation at Goldex | F14: =market_shares_calc!F16 -> 0.00013859272
A15: Goldex (Doré) | B15: Doré | C15: Goldex | D15: =site_selection!A20 -> QC-MAIN-c0660aec | E15: Underground mining and beneficiation at Goldex | F15: =market_shares_calc!E16 -> 0.020769547
A16: Hemlo | B16: Doré | C16: Hemlo | D16: =site_selection!A21 -> ON-MAIN-6e9be24e | E16: Open-pit and underground mining and beneficiation at Hemlo (Williams) | F16: =market_shares_calc!E17 -> 0.020778745
A17: Highland Valley (Cu) | B17: Cu concentrate | C17: Highland Valley | D17: =site_selection!A22 -> BC-MAIN-bf503b6b | E17: Open-pit mining and beneficiation at Highland Valley | F17: =market_shares_calc!F18 -> 0.36355209
A18: Highland Valley (Mo) | B18: Mo concentrate | C18: Highland Valley | D18: =site_selection!A22 -> BC-MAIN-bf503b6b | E18: Open-pit mining and beneficiation at Highland Valley | F18: =market_shares_calc!J18 -> 0.6227436
A19: Island | B19: Doré | C19: Island | D19: =site_selection!A24 -> ON-MAIN-687b8c8d | E19: Underground mining and beneficiation at Island | F19: =market_shares_calc!E20 -> 0.019357843
A20: Key Lake + McArthur River | B20: U concentrate | C20: Key Lake + McArthur River | D20: =site_selection!B61 -> GRP-21eee27d | E20: Underground mining and beneficiation at Key Lake + McArthur River | F20: =market_shares_calc!H49 -> 0.42857143
A21: Kidd Creek (Cu) | B21: Cu concentrate | C21: Kidd Creek | D21: =site_selection!A26 -> ON-MAIN-f8313ebd | E21: Underground mining and beneficiation at Kidd Creek | F21: =market_shares_calc!F21 -> 0.080237082
A22: Kidd Creek (Zn) | B22: Zn concentrate | C22: Kidd Creek (Zn) | D22: =site_selection!A26 -> ON-MAIN-f8313ebd | E22: Underground mining and beneficiation at Kidd Creek | F22: =market_shares_calc!I21 -> 0.4691102
A23: Kiena | B23: Doré | C23: Kiena | D23: =site_selection!A27 -> QC-MAIN-9de9bb0d | E23: Open-pit mining and beneficiation at Kiena | F23: =market_shares_calc!E22 -> 0.0056637161 | G23: CO2 fossil | H23: Should have GHG (extracted so only scope 1)+Land
A24: Lamaque | B24: Doré | C24: Lamaque | D24: =site_selection!A29 -> QC-MAIN-f9e41c2a | E24: Underground mining and beneficiation at Lamaque | F24: =market_shares_calc!E23 -> 0.036821889 | G24: Lots of missing flows
A25: LaRonde (Cu) | B25: Cu concentrate | C25: LaRonde | D25: =site_selection!A30 -> QC-MAIN-e51eda66 | E25: Underground mining and beneficiation at LaRonde | F25: =market_shares_calc!F24 -> 0.0091525672
A26: LaRonde (Doré) | B26: Doré | C26: LaRonde | D26: =site_selection!A30 -> QC-MAIN-e51eda66 | E26: Underground mining and beneficiation at LaRonde | F26: =market_shares_calc!E24 -> 0.045502276
A27: LaRonde (Zn) | B27: Zn concentrate | C27: LaRonde | D27: =site_selection!A30 -> QC-MAIN-e51eda66 | E27: Underground mining and beneficiation at LaRonde | F27: =market_shares_calc!I24 -> 0.093608613
A28: Macassa | B28: Doré | C28: Macassa | D28: =site_selection!A32 -> ON-MAIN-1f126a43 | E28: Underground mining and beneficiation at Macassa | F28: =market_shares_calc!E25 -> 0.033667768
A29: Magino | B29: Doré | C29: Magino | D29: =site_selection!A33 -> ON-MAIN-8825d90d | E29: Open-pit mining and beneficiation at Magino | F29: =market_shares_calc!E26 -> 0.0048615589 | G29: CO2 fossil | H29: No GHG
A30: Meadowbank complex | B30: Doré | C30: Meadowbank complex | D30: =site_selection!B62 -> GRP-0a2c0d69 | E30: Open-pit and underground mining at Meadowbank complex | F30: =market_shares_calc!E50 -> 0.082007961 | G30: CO2 biomass
A31: Meliadine | B31: Doré | C31: Meliadine | D31: =site_selection!A36 -> NU-MAIN-8b0264c9 | E31: Open-pit and underground mining and beneficiation at Meliadine | F31: =market_shares_calc!E28 -> 0.057622879
A32: Mount Milligan | B32: Cu concentrate | C32: Mount Milligan | D32: =site_selection!A37 -> BC-MAIN-ed23117f | E32: Open-pit mining and beneficiation at Mount Milligan | F32: =market_shares_calc!F29 -> 0.099622178 | G32: CO2 fossil | H32: Should have GHG (extracted so only scope 1)
A33: Mount Polley | B33: Cu concentrate | C33: Mount Polley | D33: =site_selection!A38 -> BC-MAIN-3f490561 | E33: Open-pit mining and beneficiation at Mount Polley | F33: =market_shares_calc!F30 -> 0.04854532
A34: Musselwhite | B34: Doré | C34: Musselwhite | D34: =site_selection!A39 -> ON-MAIN-fefeaee4 | E34: Underground mining and beneficiation at Musselwhite | F34: =market_shares_calc!E31 -> 0.026517594
A35: New Afton | B35: Cu concentrate | C35: New Afton | D35: =site_selection!A40 -> BC-MAIN-aa76f6f2 | E35: Underground mining and beneficiation at New Afton | F35: =market_shares_calc!F32 -> 0.076332664 | G35: CO2 fossil | H35: Should have GHG (extracted so only scope 1)
A36: Nunavik Nickel | B36: Ni concentrate | C36: Nunavik Nickel | D36: =site_selection!A44 -> QC-MAIN-5ce331b8 | E36: Open-pit and underground mining and beneficiation at Nunavik Nickel | F36: =market_shares_calc!G35 -> 0.39893708
A37: Porcupine complex | B37: Doré | C37: Porcupine complex | D37: =site_selection!B63 -> GRP-0d911886 | E37: Open-pit and underground mining at Porcupine complex | F37: =market_shares_calc!E51 -> 0.038303191 | G37: CO2 fossil and biomass | H37: Should have GHG (extracted so only scope 1)+Land
A38: Raglan | B38: Ni concentrate | C38: Raglan | D38: =site_selection!A45 -> QC-MAIN-a97821c0 | E38: Underground mining and beneficiation at Raglan | F38: =market_shares_calc!G36 -> 0.16638629
A39: Rainy River | B39: Doré | C39: Rainy River | D39: =site_selection!A46 -> ON-MAIN-0aadf28f | E39: Open-pit and underground mining and beneficiation at Rainy River | F39: =market_shares_calc!E37 -> 0.037381705
A40: Red Chris | B40: Cu concentrate | C40: Red Chris | D40: =site_selection!A47 -> BC-MAIN-8eb8be0d | E40: Open-pit mining and beneficiation at Red Chris | F40: =market_shares_calc!F38 -> 0.014201254 | H40: Outliers
...

Sheet market_shares_calc
A1: facility_name | B1: facility_group_name | C1: commodities | D1: stream | E1: Au-Ag | F1: Cu | G1: Ni | H1: U | I1: Zn | J1: Mo
A2: =site_selection!C3 -> Brucejack | B2: =site_selection!D3 -> 0 | C2: =site_selection!I3 -> Gold, silver | D2: =site_selection!L3 -> Au-Ag doré | E2: =site_selection!N3/site_selection!$N$68 -> 0.004272279 | F2: =site_selection!AD3/site_selection!$AD$68 -> 0 | G2: =site_selection!AE3/site_selection!$AE$68 -> 0 | H2: =site_selection!AK3/site_selection!$AK$68 -> 0 | I2: =site_selection!AG3/site_selection!$AG$68 -> 0 | J2: =site_selection!AF3/site_selection!$AF$68 -> 0
A3: =site_selection!C5 -> Canadian Malartic | B3: =site_selection!D5 -> 0 | C3: =site_selection!I5 -> Gold, silver | D3: =site_selection!L5 -> Au-Ag doré | E3: =site_selection!N5/site_selection!$N$68 -> 0.13479114 | F3: =site_selection!AD5/site_selection!$AD$68 -> 0 | G3: =site_selection!AE5/site_selection!$AE$68 -> 0 | H3: =site_selection!AK5/site_selection!$AK$68 -> 0 | I3: =site_selection!AG5/site_selection!$AG$68 -> 0 | J3: =site_selection!AF5/site_selection!$AF$68 -> 0
A4: =site_selection!C7 -> Casa Berardi | B4: =site_selection!D7 -> 0 | C4: =site_selection!I7 -> Gold, silver | D4: =site_selection!L7 -> Au-Ag doré | E4: =site_selection!N7/site_selection!$N$68 -> 0.016323052 | F4: =site_selection!AD7/site_selection!$AD$68 -> 0 | G4: =site_selection!AE7/site_selection!$AE$68 -> 0 | H4: =site_selection!AK7/site_selection!$AK$68 -> 0 | I4: =site_selection!AG7/site_selection!$AG$68 -> 0 | J4: =site_selection!AF7/site_selection!$AF$68 -> 0
A5: =site_selection!C8 -> Copper Cliff Complex (mine) | B5: =site_selection!D8 -> Sudbury Operation | C5: =site_selection!I8 -> Nickel, copper, platinum group metals, gold, silver, cobalt, selenium, tellurium | D5: =site_selection!L8 -> Ni-Cu bulk conc. | E5: =site_selection!N8/site_selection!$N$68 -> 0 | F5: =site_selection!AD8/site_selection!$AD$68 -> 0 | G5: =site_selection!AE8/site_selection!$AE$68 -> 0.060087752 | H5: =site_selection!AK8/site_selection!$AK$68 -> 0 | I5: =site_selection!AG8/site_selection!$AG$68 -> 0 | J5: =site_selection!AF8/site_selection!$AF$68 -> 0
A6: =site_selection!C10 -> Copper Mountain | B6: =site_selection!D10 -> 0 | C6: =site_selection!I10 -> Copper, gold, silver | D6: =site_selection!L10 -> Cu conc. | E6: =site_selection!N10/site_selection!$N$68 -> 0 | F6: =site_selection!AD10/site_selection!$AD$68 -> 0.06763347 | G6: =site_selection!AE10/site_selection!$AE$68 -> 0 | H6: =site_selection!AK10/site_selection!$AK$68 -> 0 | I6: =site_selection!AG10/site_selection!$AG$68 -> 0 | J6: =site_selection!AF10/site_selection!$AF$68 -> 0
A7: =site_selection!C11 -> Creighton | B7: =site_selection!D11 -> Sudbury Operation | C7: =site_selection!I11 -> Nickel, copper, platinum group metals, gold, silver, cobalt, selenium, tellurium | D7: =site_selection!L11 -> Ni-Cu bulk conc. | E7: =site_selection!N11/site_selection!$N$68 -> 0 | F7: =site_selection!AD11/site_selection!$AD$68 -> 0 | G7: =site_selection!AE11/site_selection!$AE$68 -> 0.077892294 | H7: =site_selection!AK11/site_selection!$AK$68 -> 0 | I7: =site_selection!AG11/site_selection!$AG$68 -> 0 | J7: =site_selection!AF11/site_selection!$AF$68 -> 0
A8: =site_selection!C12 -> Detour Lake | B8: =site_selection!D12 -> 0 | C8: =site_selection!I12 -> Gold | D8: =site_selection!L12 -> Au-Ag doré | E8: =site_selection!N12/site_selection!$N$68 -> 0.1114396 | F8: =site_selection!AD12/site_selection!$AD$68 -> 0 | G8: =site_selection!AE12/site_selection!$AE$68 -> 0 | H8: =site_selection!AK12/site_selection!$AK$68 -> 0 | I8: =site_selection!AG12/site_selection!$AG$68 -> 0 | J8: =site_selection!AF12/site_selection!$AF$68 -> 0
A9: =site_selection!C13 -> Eagle River | B9: =site_selection!D13 -> 0 | C9: =site_selection!I13 -> Gold | D9: =site_selection!L13 -> Au-Ag doré | E9: =site_selection!N13/site_selection!$N$68 -> 0.012885635 | F9: =site_selection!AD13/site_selection!$AD$68 -> 0 | G9: =site_selection!AE13/site_selection!$AE$68 -> 0 | H9: =site_selection!AK13/site_selection!$AK$68 -> 0 | I9: =site_selection!AG13/site_selection!$AG$68 -> 0 | J9: =site_selection!AF13/site_selection!$AF$68 -> 0
A10: =site_selection!C14 -> Éléonore | B10: =site_selection!D14 -> 0 | C10: =site_selection!I14 -> Gold, silver | D10: =site_selection!L14 -> Au-Ag doré | E10: =site_selection!N14/site_selection!$N$68 -> 0.035921764 | F10: =site_selection!AD14/site_selection!$AD$68 -> 0 | G10: =site_selection!AE14/site_selection!$AE$68 -> 0 | H10: =site_selection!AK14/site_selection!$AK$68 -> 0 | I10: =site_selection!AG14/site_selection!$AG$68 -> 0 | J10: =site_selection!AF14/site_selection!$AF$68 -> 0
A11: =site_selection!C15 -> Elk | B11: =site_selection!D15 -> 0 | C11: =site_selection!I15 -> Gold | D11: =site_selection!L15 -> Au-Ag doré | E11: =site_selection!N15/site_selection!$N$68 -> 0.00057690499 | F11: =site_selection!AD15/site_selection!$AD$68 -> 0 | G11: =site_selection!AE15/site_selection!$AE$68 -> 0 | H11: =site_selection!AK15/site_selection!$AK$68 -> 0 | I11: =site_selection!AG15/site_selection!$AG$68 -> 0 | J11: =site_selection!AF15/site_selection!$AF$68 -> 0
A12: =site_selection!C16 -> Fox Complex | B12: =site_selection!D16 -> 0 | C12: =site_selection!I16 -> Gold | D12: =site_selection!L16 -> Au-Ag doré | E12: =site_selection!N16/site_selection!$N$68 -> 0.0067472544 | F12: =site_selection!AD16/site_selection!$AD$68 -> 0 | G12: =site_selection!AE16/site_selection!$AE$68 -> 0 | H12: =site_selection!AK16/site_selection!$AK$68 -> 0 | I12: =site_selection!AG16/site_selection!$AG$68 -> 0 | J12: =site_selection!AF16/site_selection!$AF$68 -> 0
A13: =site_selection!C17 -> Fraser | B13: =site_selection!D17 -> Integrated Nickel Operations | C13: =site_selection!I17 -> Nickel, copper, platinum group metals, gold, cobalt, silver | D13: =site_selection!L17 -> Ni-Cu bulk conc. | E13: =site_selection!N17/site_selection!$N$68 -> 0 | F13: =site_selection!AD17/site_selection!$AD$68 -> 0 | G13: =site_selection!AE17/site_selection!$AE$68 -> 0 | H13: =site_selection!AK17/site_selection!$AK$68 -> 0 | I13: =site_selection!AG17/site_selection!$AG$68 -> 0 | J13: =site_selection!AF17/site_selection!$AF$68 -> 0
A14: =site_selection!C18 -> Garson | B14: =site_selection!D18 -> Sudbury Operation | C14: =site_selection!I18 -> Nickel, copper, platinum group metals, gold, silver, cobalt, selenium, tellurium | D14: =site_selection!L18 -> Ni-Cu bulk conc. | E14: =site_selection!N18/site_selection!$N$68 -> 0 | F14: =site_selection!AD18/site_selection!$AD$68 -> 0 | G14: =site_selection!AE18/site_selection!$AE$68 -> 0.054560311 | H14: =site_selection!AK18/site_selection!$AK$68 -> 0 | I14: =site_selection!AG18/site_selection!$AG$68 -> 0 | J14: =site_selection!AF18/site_selection!$AF$68 -> 0
A15: =site_selection!C19 -> Gibraltar | B15: =site_selection!D19 -> 0 | C15: =site_selection!I19 -> Copper, molybdenum, silver | D15: =site_selection!L19 -> Cu and Mo conc. | E15: =site_selection!N19/site_selection!$N$68 -> 0 | F15: =site_selection!AD19/site_selection!$AD$68 -> 0.19743427 | G15: =site_selection!AE19/site_selection!$AE$68 -> 0 | H15: =site_selection!AK19/site_selection!$AK$68 -> 0 | I15: =site_selection!AG19/site_selection!$AG$68 -> 0 | J15: =site_selection!AF19/site_selection!$AF$68 -> 0.3772564
A16: =site_selection!C20 -> Goldex | B16: =site_selection!D20 -> 0 | C16: =site_selection!I20 -> Gold, silver | D16: =site_selection!L20 -> Au-Ag doré, Cu conc. | E16: =site_selection!N20/site_selection!$N$68 -> 0.020769547 | F16: =site_selection!AD20/site_selection!$AD$68 -> 0.00013859272 | G16: =site_selection!AE20/site_selection!$AE$68 -> 0 | H16: =site_selection!AK20/site_selection!$AK$68 -> 0 | I16: =site_selection!AG20/site_selection!$AG$68 -> 0 | J16: =site_selection!AF20/site_selection!$AF$68 -> 0
A17: =site_selection!C21 -> Hemlo (Williams) | B17: =site_selection!D21 -> 0 | C17: =site_selection!I21 -> Gold | D17: =site_selection!L21 -> Au-Ag doré | E17: =site_selection!N21/site_selection!$N$68 -> 0.020778745 | F17: =site_selection!AD21/site_selection!$AD$68 -> 0 | G17: =site_selection!AE21/site_selection!$AE$68 -> 0 | H17: =site_selection!AK21/site_selection!$AK$68 -> 0 | I17: =site_selection!AG21/site_selection!$AG$68 -> 0 | J17: =site_selection!AF21/site_selection!$AF$68 -> 0
... A20: =site_selection!C24 -> Island | B20: =site_selection!D24 -> 0 | C20: =site_selection!I24 -> Gold | D20: =site_selection!L24 -> Au-Ag doré | E20: =site_selection!N24/site_selection!$N$68 -> 0.019357843 | F20: =site_selection!AD24/site_selection!$AD$68 -> 0 | G20: =site_selection!AE24/site_selection!$AE$68 -> 0 | H20: =site_selection!AK24/site_selection!$AK$68 -> 0 | I20: =site_selection!AG24/site_selection!$AG$68 -> 0 | J20: =site_selection!AF24/site_selection!$AF$68 -> 0
A21: =site_selection!C26 -> Kidd Creek | B21: =site_selection!D26 -> 0 | C21: =site_selection!I26 -> Copper, zinc, silver, selenium, indium | D21: =site_selection!L26 -> Cu and Zn conc. | E21: =site_selection!N26/site_selection!$N$68 -> 0 | F21: =site_selection!AD26/site_selection!$AD$68 -> 0.080237082 | G21: =site_selection!AE26/site_selection!$AE$68 -> 0 | H21: =site_selection!AK26/site_selection!$AK$68 -> 0 | I21: =site_selection!AG26/site_selection!$AG$68 -> 0.4691102 | J21: =site_selection!AF26/site_selection!$AF$68 -> 0
A22: =site_selection!C27 -> Kiena | B22: =site_selection!D27 -> 0 | C22: =site_selection!I27 -> Gold, silver | D22: =site_selection!L27 -> Au-Ag doré | E22: =site_selection!N27/site_selection!$N$68 -> 0.0056637161 | F22: =site_selection!AD27/site_selection!$AD$68 -> 0 | G22: =site_selection!AE27/site_selection!$AE$68 -> 0 | H22: =site_selection!AK27/site_selection!$AK$68 -> 0 | I22: =site_selection!AG27/site_selection!$AG$68 -> 0 | J22: =site_selection!AF27/site_selection!$AF$68 -> 0
A23: =site_selection!C29 -> Lamaque | B23: =site_selection!D29 -> 0 | C23: =site_selection!I29 -> Gold, silver | D23: =site_selection!L29 -> Au-Ag doré | E23: =site_selection!N29/site_selection!$N$68 -> 0.036821889 | F23: =site_selection!AD29/site_selection!$AD$68 -> 0 | G23: =site_selection!AE29/site_selection!$AE$68 -> 0 | H23: =site_selection!AK29/site_selection!$AK$68 -> 0 | I23: =site_selection!AG29/site_selection!$AG$68 -> 0 | J23: =site_selection!AF29/site_selection!$AF$68 -> 0
A24: =site_selection!C30 -> LaRonde | B24: =site_selection!D30 -> 0 | C24: =site_selection!I30 -> Gold, zinc, copper, silver, cadmium | D24: =site_selection!L30 -> Au-Ag doré, Cu and Zn conc. | E24: =site_selection!N30/site_selection!$N$68 -> 0.045502276 | F24: =site_selection!AD30/site_selection!$AD$68 -> 0.0091525672 | G24: =site_selection!AE30/site_selection!$AE$68 -> 0 | H24: =site_selection!AK30/site_selection!$AK$68 -> 0 | I24: =site_selection!AG30/site_selection!$AG$68 -> 0.093608613 | J24: =site_selection!AF30/site_selection!$AF$68 -> 0
A25: =site_selection!C32 -> Macassa | B25: =site_selection!D32 -> 0 | C25: =site_selection!I32 -> Gold, silver | D25: =site_selection!L32 -> Au-Ag doré | E25: =site_selection!N32/site_selection!$N$68 -> 0.033667768 | F25: =site_selection!AD32/site_selection!$AD$68 -> 0 | G25: =site_selection!AE32/site_selection!$AE$68 -> 0 | H25: =site_selection!AK32/site_selection!$AK$68 -> 0 | I25: =site_selection!AG32/site_selection!$AG$68 -> 0 | J25: =site_selection!AF32/site_selection!$AF$68 -> 0
A26: =site_selection!C33 -> Magino | B26: =site_selection!D33 -> 0 | C26: =site_selection!I33 -> Gold, silver | D26: =site_selection!L33 -> Au-Ag doré | E26: =site_selection!N33/site_selection!$N$68 -> 0.0048615589 | F26: =site_selection!AD33/site_selection!$AD$68 -> 0 | G26: =site_selection!AE33/site_selection!$AE$68 -> 0 | H26: =site_selection!AK33/site_selection!$AK$68 -> 0 | I26: =site_selection!AG33/site_selection!$AG$68 -> 0 | J26: =site_selection!AF33/site_selection!$AF$68 -> 0
A27: =site_selection!C35 -> McCreedy West | B27: =site_selection!D35 -> 0 | C27: =site_selection!I35 -> Copper, nickel, platinum group metals, gold, silver, cobalt | D27: =site_selection!L35 -> Cu-PGM conc. and Ni-Cu conc. | E27: =site_selection!N35/site_selection!$N$68 -> 0 | F27: =site_selection!AD35/site_selection!$AD$68 -> 0 | G27: =site_selection!AE35/site_selection!$AE$68 -> 0 | H27: =site_selection!AK35/site_selection!$AK$68 -> 0 | I27: =site_selection!AG35/site_selection!$AG$68 -> 0 | J27: =site_selection!AF35/site_selection!$AF$68 -> 0
A28: =site_selection!C36 -> Meliadine | B28: =site_selection!D36 -> 0 | C28: =site_selection!I36 -> Gold | D28: =site_selection!L36 -> Au-Ag doré | E28: =site_selection!N36/site_selection!$N$68 -> 0.057622879 | F28: =site_selection!AD36/site_selection!$AD$68 -> 0 | G28: =site_selection!AE36/site_selection!$AE$68 -> 0 | H28: =site_selection!AK36/site_selection!$AK$68 -> 0 | I28: =site_selection!AG36/site_selection!$AG$68 -> 0 | J28: =site_selection!AF36/site_selection!$AF$68 -> 0
A29: =site_selection!C37 -> Mount Milligan | B29: =site_selection!D37 -> 0 | C29: =site_selection!I37 -> Copper, gold, silver | D29: =site_selection!L37 -> Cu conc. | E29: =site_selection!N37/site_selection!$N$68 -> 0 | F29: =site_selection!AD37/site_selection!$AD$68 -> 0.099622178 | G29: =site_selection!AE37/site_selection!$AE$68 -> 0 | H29: =site_selection!AK37/site_selection!$AK$68 -> 0 | I29: =site_selection!AG37/site_selection!$AG$68 -> 0 | J29: =site_selection!AF37/site_selection!$AF$68 -> 0
A30: =site_selection!C38 -> Mount Polley | B30: =site_selection!D38 -> 0 | C30: =site_selection!I38 -> Gold, copper, silver | D30: =site_selection!L38 -> Cu conc. | E30: =site_selection!N38/site_selection!$N$68 -> 0 | F30: =site_selection!AD38/site_selection!$AD$68 -> 0.04854532 | G30: =site_selection!AE38/site_selection!$AE$68 -> 0 | H30: =site_selection!AK38/site_selection!$AK$68 -> 0 | I30: =site_selection!AG38/site_selection!$AG$68 -> 0 | J30: =site_selection!AF38/site_selection!$AF$68 -> 0
A31: =site_selection!C39 -> Musselwhite | B31: =site_selection!D39 -> 0 | C31: =site_selection!I39 -> Gold, silver | D31: =site_selection!L39 -> Au-Ag doré | E31: =site_selection!N39/site_selection!$N$68 -> 0.026517594 | F31: =site_selection!AD39/site_selection!$AD$68 -> 0 | G31: =site_selection!AE39/site_selection!$AE$68 -> 0 | H31: =site_selection!AK39/site_selection!$AK$68 -> 0 | I31: =site_selection!AG39/site_selection!$AG$68 -> 0 | J31: =site_selection!AF39/site_selection!$AF$68 -> 0
A32: =site_selection!C40 -> New Afton | B32: =site_selection!D40 -> 0 | C32: =site_selection!I40 -> Gold, copper, silver | D32: =site_selection!L40 -> Cu conc. | E32: =site_selection!N40/site_selection!$N$68 -> 0 | F32: =site_selection!AD40/site_selection!$AD$68 -> 0.076332664 | G32: =site_selection!AE40/site_selection!$AE$68 -> 0 | H32: =site_selection!AK40/site_selection!$AK$68 -> 0 | I32: =site_selection!AG40/site_selection!$AG$68 -> 0 | J32: =site_selection!AF40/site_selection!$AF$68 -> 0
A33: =site_selection!C41 -> Nickel Rim South | B33: =site_selection!D41 -> Integrated Nickel Operations | C33: =site_selection!I41 -> Nickel, copper, cobalt, platinum group metals, gold | D33: =site_selection!L41 -> Ni-Cu bulk conc. | E33: =site_selection!N41/site_selection!$N$68 -> 0 | F33: =site_selection!AD41/site_selection!$AD$68 -> 0 | G33: =site_selection!AE41/site_selection!$AE$68 -> 0 | H33: =site_selection!AK41/site_selection!$AK$68 -> 0 | I33: =site_selection!AG41/site_selection!$AG$68 -> 0 | J33: =site_selection!AF41/site_selection!$AF$68 -> 0
A34: =site_selection!C43 -> Niobec Converter | B34: =site_selection!D43 -> 0 | C34: =site_selection!I43 -> Ferroniobium | D34: =site_selection!L43 -> 0 | E34: =site_selection!N43/site_selection!$N$68 -> 0 | F34: =site_selection!AD43/site_selection!$AD$68 -> 0 | G34: =site_selection!AE43/site_selection!$AE$68 -> 0 | H34: =site_selection!AK43/site_selection!$AK$68 -> 0 | I34: =site_selection!AG43/site_selection!$AG$68 -> 0 | J34: =site_selection!AF43/site_selection!$AF$68 -> 0
A35: =site_selection!C44 -> Nunavik Nickel | B35: =site_selection!D44 -> 0 | C35: =site_selection!I44 -> Nickel, copper, platinum group metals, cobalt | D35: =site_selection!L44 -> Ni-Cu bulk conc. | E35: =site_selection!N44/site_selection!$N$68 -> 0 | F35: =site_selection!AD44/site_selection!$AD$68 -> 0 | G35: =site_selection!AE44/site_selection!$AE$68 -> 0.39893708 | H35: =site_selection!AK44/site_selection!$AK$68 -> 0 | I35: =site_selection!AG44/site_selection!$AG$68 -> 0 | J35: =site_selection!AF44/site_selection!$AF$68 -> 0
A36: =site_selection!C45 -> Raglan | B36: =site_selection!D45 -> 0 | C36: =site_selection!I45 -> Nickel, platinum group metals, copper, cobalt, gold, silver | D36: =site_selection!L45 -> Ni-Cu bulk conc. | E36: =site_selection!N45/site_selection!$N$68 -> 0 | F36: =site_selection!AD45/site_selection!$AD$68 -> 0 | G36: =site_selection!AE45/site_selection!$AE$68 -> 0.16638629 | H36: =site_selection!AK45/site_selection!$AK$68 -> 0 | I36: =site_selection!AG45/site_selection!$AG$68 -> 0 | J36: =site_selection!AF45/site_selection!$AF$68 -> 0
A37: =site_selection!C46 -> Rainy River | B37: =site_selection!D46 -> 0 | C37: =site_selection!I46 -> Gold, silver | D37: =site_selection!L46 -> Au-Ag doré | E37: =site_selection!N46/site_selection!$N$68 -> 0.037381705 | F37: =site_selection!AD46/site_selection!$AD$68 -> 0 | G37: =site_selection!AE46/site_selection!$AE$68 -> 0 | H37: =site_selection!AK46/site_selection!$AK$68 -> 0 | I37: =site_selection!AG46/site_selection!$AG$68 -> 0 | J37: =site_selection!AF46/site_selection!$AF$68 -> 0
A38: =site_selection!C47 -> Red Chris | B38: =site_selection!D47 -> 0 | C38: =site_selection!I47 -> Gold, copper, silver | D38: =site_selection!L47 -> Cu conc. | E38: =site_selection!N47/site_selection!$N$68 -> 0.00073659983 | F38: =site_selection!AD47/site_selection!$AD$68 -> 0.014201254 | G38: =site_selection!AE47/site_selection!$AE$68 -> 0 | H38: =site_selection!AK47/site_selection!$AK$68 -> 0 | I38: =site_selection!AG47/site_selection!$AG$68 -> 0 | J38: =site_selection!AF47/site_selection!$AF$68 -> 0
A39: =site_selection!C48 -> Red Lake | B39: =site_selection!D48 -> 0 | C39: =site_selection!I48 -> Gold, silver | D39: =site_selection!L48 -> Au-Ag doré | E39: =site_selection!N48/site_selection!$N$68 -> 0.01660296 | F39: =site_selection!AD48/site_selection!$AD$68 -> 0 | G39: =site_selection!AE48/site_selection!$AE$68 -> 0 | H39: =site_selection!AK48/site_selection!$AK$68 -> 0 | I39: =site_selection!AG48/site_selection!$AG$68 -> 0 | J39: =site_selection!AF48/site_selection!$AF$68 -> 0
A40: =site_selection!C50 -> Strathcona | B40: =site_selection!D50 -> Integrated Nickel Operations | C40: =site_selection!I50 -> Nickel, copper, platinum group metals, gold, silver, cobalt, selenium, tellurium | D40: =site_selection!L50 -> Ni-Cu bulk conc. | E40: =site_selection!N50/site_selection!$N$68 -> 0 | F40: =site_selection!AD50/site_selection!$AD$68 -> 0 | G40: =site_selection!AE50/site_selection!$AE$68 -> 0.051703894 | H40: =site_selection!AK50/site_selection!$AK$68 -> 0 | I40: =site_selection!AG50/site_selection!$AG$68 -> 0 | J40: =site_selection!AF50/site_selection!$AF$68 -> 0
A41: =site_selection!C52 -> Sugar Zone | B41: =site_selection!D52 -> 0 | C41: =site_selection!I52 -> Gold | D41: =site_selection!L52 -> Au-Ag doré | E41: =site_selection!N52/site_selection!$N$68 -> 0.0056952426 | F41: =site_selection!AD52/site_selection!$AD$68 -> 0 | G41: =site_selection!AE52/site_selection!$AE$68 -> 0 | H41: =site_selection!AK52/site_selection!$AK$68 -> 0 | I41: =site_selection!AG52/site_selection!$AG$68 -> 0 | J41: =site_selection!AF52/site_selection!$AF$68 -> 0
A42: =site_selection!C54 -> Thompson (T-1 and T-3) | B42: =site_selection!D54 -> 0 | C42: =site_selection!I54 -> Nickel, cobalt, copper, platinum group metals, gold, silver | D42: =site_selection!L54 -> Ni-Cu bulk conc. | E42: =site_selection!N54/site_selection!$N$68 -> 0 | F42: =site_selection!AD54/site_selection!$AD$68 -> 0 | G42: =site_selection!AE54/site_selection!$AE$68 -> 0.054244457 | H42: =site_selection!AK54/site_selection!$AK$68 -> 0 | I42: =site_selection!AG54/site_selection!$AG$68 -> 0 | J42: =site_selection!AF54/site_selection!$AF$68 -> 0
...

Sheet prices
A1: HS code | B1: Commodity | C1: Price (USD/kg) | D1: Source
A2: (CoSO4) Cobalt; mattes and other intermediate products of cobalt metallurgy, unwrought cobalt, powders | B2: Co | C2: 9.3391084 | D2: Lai et al. 2025
A3: Copper; refined, unwrought | B3: Cu | C3: 6.9 | D3: Lai et al. 2025
A4: Metals; gold, non-monetary, unwrought (but not powder) | B4: Au | C4: 51793.135 | D4: Lai et al. 2025
A5: Iron or steel, pig iron, spiegeleisen; granules thereof | B5: Fe | C5: 15.31 | D5: Lai et al. 2025
A6: Lead; unwrought, refined | B6: Pb | C6: 2.0625836 | D6: Lai et al. 2025
A7: Molybdenum oxides and hydroxides | B7: Mo | C7: 29.24 | D7: Lai et al. 2025
A8: Nickel; unwrought, not alloyed | B8: Ni | C8: 15.59 | D8: Lai et al. 2025
B9: Pt | C9: =72449*0.71 -> 51438.79 | D9: MAC 2025 + taux de change 0.71
B10: Pd | C10: =72449*0.71 -> 51438.79 | D10: MAC 2025 + taux de change 0.71
A11: Metals; silver powder / unwrought, (but not powder) | B11: Ag | C11: 672.13 | D11: Lai et al. 2025
B12: U | C12: 0.1717 | D12: MAC 2025 + taux de change 0.71
A13: Zinc; unwrought, (not alloyed) | B13: Zn | C13: 2.5793145 | D13: Lai et al. 2025
A14: Gallium, germanium, hafnium, indium, niobium (columbium), rhenium and vanadium; articles thereof, other than unwrought including waste and scrap and powders | B14: N | C14: 78.78 | D14: Lai et al. 2025
