Workbook

Sheet README
A1: Title of the article | B1: Supplementary Information for ''Towards site-specific life cycle inventories for metals: methodological framework and application to 35 sites in Canada"
A2: Authors | B2: Marin Pellan¹, Titouan Greffe2, Guillaume Majeau-Bettez¹, Anne de Bortoli1,3,4
A3: Affiliations | B3: ¹CIRAIG, Ecole Polytechnique de Montréal, P.O. Box 6079, Montréal, H3C 3A7, Québec, Canada 2CIRAIG, Institute of Environmental Sciences, UQAM, Montreal, Quebec H2X 3Y7, Canada 3CIRAIG, Université du Québec à Montréal, C.P. 8888, succ. Centre-ville. Montréal (Québec) H3C 3P8, Québec, Canada 4LVMT, Ecole des Ponts ParisTech, Cité Descartes, 6-8 Avenue Blaise Pascal, Champs-sur-Marne, 77420, France
A4: Corresponding author | B4: marin.pellan@polymlt.ca; pellan.marin@gmail.com
A5: Journal | B5: Environmental Science & Technology
A6: Date | B6: 46023
A7: Purpose and scope | B7: This spreadsheet ….

Sheet recap
A1: Commodity | B1: Endpoint | C1: Min_MetalliCan | D1: Mean_Metallican | E1: Max_MetalliCan | F1: EI value | G1: RI value | H1: Mean diff with EI | I1: Order of magnitude
A2: Au-Ag | B2: EQ | C2: =MIN(EQ_damages_regioinvent!U18:U38) -> 12341.029 | D2: =AVERAGE(EQ_damages_regioinvent!U18:U38) -> 30231.619 | E2: =MAX(EQ_damages_regioinvent!U18:U38) -> 67619.84 | F2: =EQ_damages_regioinvent!U16 -> 4606.5551 | G2: =EQ_damages_regioinvent!U17 -> 5382.1825 | H2: =D2/F2 -> 6.5627391 | I2: =E2/C2 -> 5.4792707
A3: Cu | B3: EQ | C3: =MIN(EQ_damages_regioinvent!U6:U15) -> 0.96457407 | D3: =AVERAGE(EQ_damages_regioinvent!U6:U15) -> 2.9683288 | E3: =MAX(EQ_damages_regioinvent!U6:U15) -> 6.0975732 | F3: =EQ_damages_regioinvent!U3 -> 11.414936 | G3: =EQ_damages_regioinvent!U5 -> 11.728091 | H3: =D3/F3 -> 0.26003902 | I3: =E3/C3 -> 6.3215188
A4: Ni | B4: EQ | C4: =MIN(EQ_damages_regioinvent!U43:U46) -> 1.6611446 | D4: =AVERAGE(EQ_damages_regioinvent!U43:U46) -> 3.8746194 | E4: =MAX(EQ_damages_regioinvent!U43:U46) -> 7.863519 | F4: =EQ_damages_regioinvent!U41 -> 0.60515901 | G4: =EQ_damages_regioinvent!U42 -> 0.62292963 | H4: =D4/F4 -> 6.4026468 | I4: =E4/C4 -> 4.7337957
A5: Au-Ag | B5: HH | C5: =MIN(HH_damages_regioinvent!L18:L38) -> 0.060735531 | D5: =AVERAGE(HH_damages_regioinvent!L18:L38) -> 0.24625962 | E5: =MAX(HH_damages_regioinvent!L18:L38) -> 0.70724558 | F5: =HH_damages_regioinvent!L16 -> 0.039388707 | G5: =HH_damages_regioinvent!L17 -> 0.056366619 | H5: =D5/F5 -> 6.2520362 | I5: =E5/C5 -> 11.644676
A6: Cu | B6: HH | C6: =MIN(HH_damages_regioinvent!L6:L15) -> 3.7143787e-06 | D6: =AVERAGE(HH_damages_regioinvent!L6:L15) -> 1.6330761e-05 | E6: =MAX(HH_damages_regioinvent!L6:L15) -> 4.7176475e-05 | F6: =HH_damages_regioinvent!L3 -> 1.7411678e-05 | G6: =HH_damages_regioinvent!L5 -> 5.4095811e-05 | H6: =D6/F6 -> 0.93791999 | I6: =E6/C6 -> 12.701041
A7: Ni | B7: HH | C7: =MIN(HH_damages_regioinvent!L43:L46) -> 1.0191632e-05 | D7: =AVERAGE(HH_damages_regioinvent!L43:L46) -> 2.5103416e-05 | E7: =MAX(HH_damages_regioinvent!L43:L46) -> 6.4269956e-05 | F7: =HH_damages_regioinvent!L41 -> 4.2334358e-06 | G7: =HH_damages_regioinvent!L42 -> 8.5359831e-06 | H7: =D7/F7 -> 5.9297972 | I7: =E7/C7 -> 6.3061498

Sheet EQ_damages_regioinvent
A1: Commodity | B1: Source | C1: Reference product | D1: Climate change | E1: Fisheries impact | F1: Freshwater acidification | G1: Freshwater ecotoxicity | H1: Freshwater eutrophication | I1: Ionizing radiations | J1: Land occupation | K1: Land transformation | L1: Marine acidification | M1: Marine ecotoxicity | N1: Marine eutrophication | O1: Photochemical ozone | P1: Terrestrial acidification | Q1: Terrestrial ecotoxicity | R1: Thermally polluted water | S1: Water availability freshwater | T1: Water availability terrestrial | U1: Total EQ
A2: Cu concentrate from Au mine | B2: Ecoinvent | C2: Cu concentrate | D2: 0.53659425 | E2: 7.1970633e-19 | F2: 0.013043044 | G2: 0.18625397 | H2: 0.0001912805 | I2: 2.1423133e-10 | J2: 0.14576339 | K2: 0.43790294 | L2: 0.16396618 | M2: 5.9521369e-07 | N2: 0.0067065585 | O2: 0.053084989 | P2: 0.089063787 | Q2: 0.021725582 | R2: 0.0012256962 | S2: 2.1093337e-05 | T2: 3.8015765e-05 | U2: =SUM(D2:T2) -> 1.6555814
A3: Cu concentrate from Cu mine | B3: Ecoinvent | C3: Cu concentrate | D3: 0.61587607 | E3: 6.8609545e-19 | F3: 0.030580511 | G3: 8.2619915 | H3: 0.00013191805 | I3: 1.2992237e-09 | J3: 0.53101572 | K3: 1.0598634 | L3: 0.18369371 | M3: 7.8176709e-06 | N3: 0.01092335 | O3: 0.17743807 | P3: 0.25728139 | Q3: 0.28534647 | R3: 0.0006733847 | S3: 3.8194052e-05 | T3: 7.4865209e-05 | U3: =SUM(D3:T3) -> 11.414936
A4: Cu concentrate from Au mine | B4: Regioinvent | C4: Cu concentrate | D4: 0.76059257 | E4: 6.8686788e-19 | F4: 0.063708557 | G4: 0.23294288 | H4: 0.00019317451 | I4: 2.4914077e-09 | J4: 0.094816778 | K4: 0.32680787 | L4: 0.23439664 | M4: 7.1015494e-07 | N4: 0.0064698596 | O4: 0.056539772 | P4: 0.13090838 | Q4: 0.02592106 | R4: 0.00091951331 | S4: 2.1674411e-05 | T4: 9.996262e-05 | U4: =SUM(D4:T4) -> 1.9343394
A5: Cu concentrate from Cu mine | B5: Regioinvent | C5: Cu concentrate | D5: 0.62644234 | E5: 6.7497352e-19 | F5: 0.19623575 | G5: 8.2450172 | H5: 0.00017383967 | I5: 1.2966538e-09 | J5: 0.53679632 | K5: 1.0646857 | L5: 0.19039469 | M5: 7.8929063e-06 | N5: 0.0091765466 | O5: 0.17967064 | P5: 0.39055705 | Q5: 0.28809256 | R5: 0.00065688557 | S5: 3.8413038e-05 | T5: 0.00014500186 | U5: =SUM(D5:T5) -> 11.728091
A6: Copper Mountain | B6: MetalliCan | C6: Cu concentrate | D6: 1.0527923 | E6: 2.808792e-19 | F6: 0.012875685 | G6: 1.1105212 | H6: 0.011392309 | I6: 5.3799837e-11 | J6: 0.14382491 | K6: 1.8790794 | L6: 0.32913429 | M6: 2.3659338e-07 | N6: 0.0035590003 | O6: 0.081520013 | P6: 0.080464178 | Q6: 0.0086425219 | R6: 0.00036897799 | S6: 4.6111068e-05 | T6: 4.7073443e-05 | U6: =SUM(D6:T6) -> 4.7142682
A7: Gibraltar (Cu) | B7: MetalliCan | C7: Cu concentrate | D7: 0.88775044 | E7: 4.9524103e-19 | F7: 0.026917668 | G7: 0.18833748 | H7: 0.00014611676 | I7: 7.5963093e-11 | J7: 0.13261628 | K7: 1.1679185 | L7: 0.27646718 | M7: 3.5043498e-07 | N7: 0.0041216985 | O7: 0.081707979 | P7: 0.10941563 | Q7: 0.012791426 | R7: 0.00050371088 | S7: 4.0761419e-05 | T7: 7.0489086e-05 | U7: =SUM(D7:T7) -> 2.8888057
A8: Highland Valley (Cu) | B8: MetalliCan | C8: Cu concentrate | D8: 0.53938846 | E8: 1.5863286e-19 | F8: 0.0060532636 | G8: 0.068068897 | H8: 4.8685175e-05 | I8: 2.6841418e-11 | J8: 0.10241068 | K8: 1.6003319 | L8: 0.16729904 | M8: 1.1378542e-07 | N8: 0.0015606106 | O8: 0.036795019 | P8: 0.03620435 | Q8: 0.0041532465 | R8: 0.00017015129 | S8: 3.0686542e-05 | T8: 2.3364923e-05 | U8: =SUM(D8:T8) -> 2.5625385
A9: Mount Milligan | B9: MetalliCan | C9: Cu concentrate | D9: 0.93239428 | E9: 3.664083e-19 | F9: 0.011962595 | G9: 2.7384625 | H9: 0.016501894 | I9: 6.3070897e-11 | J9: 0.1660321 | K9: 1.3729641 | L9: 0.29057712 | M9: 3.9542766e-07 | N9: 0.0039890582 | O9: 0.056122092 | P9: 0.069219276 | Q9: 0.014444359 | R9: 0.00034062905 | S9: 0.00010598782 | T9: 6.293801e-05 | U9: =SUM(D9:T9) -> 5.6731794
A10: Mount Polley | B10: MetalliCan | C10: Cu concentrate | D10: 1.0376261 | E10: 3.3470951e-19 | F10: 0.25479684 | G10: 0.18096987 | H10: 0.00031600936 | I10: 5.6876564e-11 | J10: 0.14016456 | K10: 1.6173749 | L10: 0.32781424 | M10: 2.8882863e-07 | N10: 0.039084582 | O10: 1.2995786 | P10: 1.1888092 | Q10: 0.010557965 | R10: 0.00037416708 | S10: 5.2046338e-05 | T10: 5.3789355e-05 | U10: =SUM(D10:T10) -> 6.0975732
A11: Goldex (Cu) | B11: MetalliCan | C11: Cu concentrate | D11: 0.91364206 | E11: 1.6300261e-18 | F11: 0.042829447 | G11: 0.23697923 | H11: 0.00024794644 | I11: 3.7560633e-10 | J11: 0.16663394 | K11: 0.44894202 | L11: 0.26742864 | M11: 6.0115471e-07 | N11: 0.0031198268 | O11: 0.028887242 | P11: 0.15699289 | Q11: 0.021943 | R11: 0.0017945685 | S11: 5.9581183e-05 | T11: 0.000156808 | U11: =SUM(D11:T11) -> 2.2896578
A12: Kidd Creek | B12: MetalliCan | C12: Cu concentrate | D12: 0.19887744 | E12: 3.8827681e-20 | F12: 0.0077863705 | G12: 0.17615286 | H12: 1.0949091e-05 | I12: 3.2065597e-12 | J12: 0.022175516 | K12: 0.35092268 | L12: 0.063046619 | M12: 2.4138553e-08 | N12: 0.0023911989 | O12: 0.080121497 | P12: 0.062191255 | Q12: 0.00088107146 | R12: 1.1001712e-05 | S12: 9.7646862e-07 | T12: 4.6207289e-06 | U12: =SUM(D12:T12) -> 0.96457407
A13: LaRonde (Cu) | B13: MetalliCan | C13: Cu concentrate | D13: 0.52170663 | E13: 4.2633972e-19 | F13: 0.042702194 | G13: 0.098411693 | H13: 5.909035e-05 | I13: 2.984959e-10 | J13: 0.12970989 | K13: 0.56955702 | L13: 0.15551486 | M13: 1.7362306e-07 | N13: 0.0038171716 | O13: 0.10343935 | P13: 0.16505878 | Q13: 0.0063507341 | R13: 0.0016303152 | S13: 3.9886216e-05 | T13: 3.9570627e-05 | U13: =SUM(D13:T13) -> 1.7980374
... A57: Snow Lake (Zn) | B57: MetalliCan | C57: Zn concentrate | D57: 0.31909081 | E57: 8.1365007e-20 | F57: 0.021110378 | G57: 0.042871527 | H57: 1.2431983e-05 | I57: 6.64325e-11 | J57: 0.027790831 | K57: 0.040467656 | L57: 0.094083309 | M57: 9.2875771e-08 | N57: 0.0019702737 | O57: 0.006297419 | P57: 0.055758405 | Q57: 0.0033902491 | R57: 0.001656236 | S57: 4.393724e-05 | T57: 4.3587802e-05 | U57: =SUM(D57:T57) -> 0.61458715

Sheet HH_damages_regioinvent
A1: Commodity | B1: Source | C1: Reference product | D1: Climate change | E1: Human toxicity non-cancer | F1: Human toxicity, cancer | G1: Ionizing radiations | H1: Ozone layer depletion | I1: Particulate matter | J1: Photochemical ozone | K1: Water availability | L1: Total HH
A2: Cu concentrate from Au mine | B2: Ecoinvent | C2: Cu concentrate | D2: 7.2316659e-06 | E2: 2.926462e-06 | F2: 4.2767183e-07 | G2: 2.3559124e-09 | H2: 1.5755991e-11 | I2: 9.8617646e-07 | J2: 5.4385286e-09 | K2: 2.5763907e-06 | L2: =SUM(D2:K2) -> 1.4156177e-05
A3: Cu concentrate from Cu mine | B3: Ecoinvent | C3: Cu concentrate | D3: 8.3001448e-06 | E3: 7.9869159e-07 | F3: 5.6200184e-07 | G3: 1.2865848e-08 | H3: 1.7188007e-11 | I3: 3.0547211e-06 | J3: 1.8123086e-08 | K3: 4.6651129e-06 | L3: =SUM(D3:K3) -> 1.7411678e-05
A4: Cu concentrate from Au mine | B4: Regioinvent | C4: Cu concentrate | D4: 1.0250485e-05 | E4: 2.9856741e-06 | F4: 4.8036528e-07 | G4: 2.4296377e-08 | H4: 2.8071499e-11 | I4: 6.4608096e-06 | J4: 5.7607875e-09 | K4: 5.0565936e-08 | L4: =SUM(D4:K4) -> 2.0257985e-05
A5: Cu concentrate from Cu mine | B5: Regioinvent | C5: Cu concentrate | D5: 8.4425462e-06 | E5: 8.2598769e-07 | F5: 5.9207312e-07 | G5: 1.2777435e-08 | H5: 2.0730571e-11 | I5: 4.4050973e-05 | J5: 1.8349373e-08 | K5: 1.5308322e-07 | L5: =SUM(D5:K5) -> 5.4095811e-05
A6: Copper Mountain | B6: MetalliCan | C6: Cu concentrate | D6: 1.4188453e-05 | E6: 4.3403982e-07 | F6: 5.9531999e-07 | G6: 7.5887479e-10 | H6: 4.7112457e-11 | I6: 3.9410641e-06 | J6: 8.3082957e-09 | K6: 4.9264424e-08 | L6: =SUM(D6:K6) -> 1.9217256e-05
A7: Gibraltar (Cu) | B7: MetalliCan | C7: Cu concentrate | D7: 1.1964188e-05 | E7: 2.729475e-07 | F7: 8.4985918e-07 | G7: 1.0849093e-09 | H7: 4.2770524e-11 | I7: 3.8889122e-06 | J7: 8.3462445e-09 | K7: 7.4141028e-08 | L7: =SUM(D7:K7) -> 1.7059522e-05
A8: Highland Valley (Cu) | B8: MetalliCan | C8: Cu concentrate | D8: 7.2693234e-06 | E8: 9.8785402e-08 | F8: 2.752159e-07 | G8: 3.7850113e-10 | H8: 2.3060773e-11 | I8: 2.2332448e-06 | J8: 3.6645346e-09 | K8: 2.5437215e-08 | L8: =SUM(D8:K8) -> 9.9060727e-06
A9: Mount Milligan | B9: MetalliCan | C9: Cu concentrate | D9: 1.2565852e-05 | E9: 7.7515176e-07 | F9: 1.215825e-06 | G9: 8.7673642e-10 | H9: 3.9404386e-11 | I9: 1.1769766e-06 | J9: 5.6778049e-09 | K9: 6.9348397e-08 | L9: =SUM(D9:K9) -> 1.5809748e-05
A10: Mount Polley | B10: MetalliCan | C10: Cu concentrate | D10: 1.3984059e-05 | E10: 2.8568308e-07 | F10: 7.0214904e-07 | G10: 8.0185465e-10 | H10: 4.5961767e-11 | I10: 3.2014075e-05 | J10: 1.3392604e-07 | K10: 5.5735174e-08 | L10: =SUM(D10:K10) -> 4.7176475e-05
A11: Goldex (Cu) | B11: MetalliCan | C11: Cu concentrate | D11: 1.2313129e-05 | E11: 5.0496432e-07 | F11: 9.1546363e-07 | G11: 4.0864779e-09 | H11: 4.0826588e-11 | I11: 6.3883012e-06 | J11: 2.8411832e-09 | K11: 1.3301756e-07 | L11: =SUM(D11:K11) -> 2.0261844e-05
A12: Kidd Creek | B12: MetalliCan | C12: Cu concentrate | D12: 2.6802657e-06 | E12: 2.529468e-07 | F12: 6.9687686e-08 | G12: 4.4985484e-11 | H12: 9.6251711e-13 | I12: 3.7933136e-06 | J12: 8.3599877e-09 | K12: 4.8385587e-09 | L12: =SUM(D12:K12) -> 6.8094583e-06
A13: LaRonde (Cu) | B13: MetalliCan | C13: Cu concentrate | D13: 7.0310259e-06 | E13: 1.7973388e-07 | F13: 2.1632089e-07 | G13: 2.9825111e-09 | H13: 2.5895731e-11 | I13: 1.9489325e-06 | J13: 1.0691372e-08 | K13: 3.5252118e-08 | L13: =SUM(D13:K13) -> 9.424965e-06
... A57: Snow Lake (Zn) | B57: MetalliCan | C57: Zn concentrate | D57: 4.3003781e-06 | E57: 1.4254914e-07 | F57: 7.2194166e-08 | G57: 9.8262733e-10 | H57: 8.9393501e-12 | I57: 6.3540483e-07 | J57: 6.2813804e-10 | K57: 5.4290934e-08 | L57: =SUM(D57:K57) -> 5.2064369e-06

Sheet EQ_damages_ecoinvent
A1: Climate change | B1: Commodity | C1: Fisheries impact | D1: Freshwater acidification | E1: Freshwater ecotoxicity | F1: Freshwater eutrophication | G1: Ionizing radiations | H1: Land occupation | I1: Land transformation | J1: Marine acidification | K1: Marine ecotoxicity | L1: Marine eutrophication | M1: Photochemical ozone | N1: Terrestrial acidification | O1: Terrestrial ecotoxicity | P1: Thermally polluted water | Q1: Water availability freshwater | R1: Water availability terrestrial | S1: Source | T1: Reference product
A2: 0.53659425 | B2: Cu concentrate from Au mine | C2: 7.1970633e-19 | D2: 0.013043044 | E2: 0.18625397 | F2: 0.0001912805 | G2: 2.1423133e-10 | H2: 0.14576339 | I2: 0.43790294 | J2: 0.16396618 | K2: 5.9521369e-07 | L2: 0.0067065585 | M2: 0.053084989 | N2: 0.089063787 | O2: 0.021725582 | P2: 0.0012256962 | Q2: 2.1093337e-05 | R2: 3.8015765e-05 | S2: Ecoinvent | T2: Cu concentrate
A3: 0.61587607 | B3: Cu concentrate from Cu mine | C3: 6.8609545e-19 | D3: 0.030580511 | E3: 8.2619915 | F3: 0.00013191805 | G3: 1.2992237e-09 | H3: 0.53101572 | I3: 1.0598634 | J3: 0.18369371 | K3: 7.8176709e-06 | L3: 0.01092335 | M3: 0.17743807 | N3: 0.25728139 | O3: 0.28534647 | P3: 0.0006733847 | Q3: 3.8194052e-05 | R3: 7.4865209e-05 | S3: Ecoinvent | T3: Cu concentrate
A4: 1493.041 | B4: Au-Ag ingot | C4: 2.0025394e-15 | D4: 36.291482 | E4: 518.24041 | F4: 0.53222644 | G4: 5.9608574e-07 | H4: 405.57782 | I4: 1218.4385 | J4: 456.22598 | K4: 0.001656146 | L4: 18.660594 | M4: 147.70577 | N4: 247.8146 | O4: 60.450115 | P4: 3.4104257 | Q4: 0.058690938 | R4: 0.10577657 | S4: Ecoinvent | T4: Doré
A5: 0.24013254 | B5: Pb concentrate | C5: 3.2207746e-19 | D5: 0.0058369229 | E5: 0.083350946 | F5: 8.5600381e-05 | G5: 9.5871158e-11 | H5: 0.065230912 | I5: 0.19596696 | J5: 0.073376886 | K5: 2.6636545e-07 | L5: 0.0030012676 | M5: 0.023756186 | N5: 0.039857141 | O5: 0.0097224649 | P5: 0.00054851413 | Q5: 9.4395281e-06 | R5: 1.7012523e-05 | S5: Ecoinvent | T5: Pb concentrate
A6: 0.24268714 | B6: Zn concentrate | C6: 3.2550382e-19 | D6: 0.0058990179 | E6: 0.084237661 | F6: 8.6511023e-05 | G6: 9.6891064e-11 | H6: 0.065924858 | I6: 0.19805172 | J6: 0.074157492 | K6: 2.6919914e-07 | L6: 0.0030331959 | M6: 0.024008912 | N6: 0.040281154 | O6: 0.0098258959 | P6: 0.0005543494 | Q6: 9.5399486e-06 | R6: 1.7193508e-05 | S6: Ecoinvent | T6: Zn concentrate
A7: 0.25341127 | B7: Ni concentrate | C7: 1.694847e-19 | D7: 0.0041023903 | E7: 0.038015816 | F7: 2.5271493e-05 | G7: 1.2017385e-11 | H7: 0.029213926 | I7: 0.14115248 | J7: 0.076447689 | K7: 4.3589371e-08 | L7: 0.0017229712 | M7: 0.028718892 | N7: 0.03042539 | O7: 0.0015910694 | P7: 2.3232273e-05 | Q7: 1.3831243e-06 | R7: 0.00030718601 | S7: Ecoinvent | T7: Ni concentrate
A8: 53.93245 | B8: U yellowcake | C8: 4.5844204e-17 | D8: 3.6203505 | E8: 1988.8578 | F8: 0.0059952298 | G8: 3.5145902e-09 | H8: 3.7190761 | I8: 6.0408755 | J8: 16.619942 | K8: 0.0074220858 | L8: 1.2136876 | M8: 9.0600456 | N8: 23.604486 | O8: 270.91909 | P8: 0.0080113117 | Q8: 0.00041973989 | R8: 0.0042669997 | S8: Ecoinvent | T8: U concentrate
A9: 0.76059257 | B9: Cu concentrate from Au mine | C9: 6.8686788e-19 | D9: 0.063708557 | E9: 0.23294288 | F9: 0.00019317451 | G9: 2.4914077e-09 | H9: 0.094816778 | I9: 0.32680787 | J9: 0.23439664 | K9: 7.1015494e-07 | L9: 0.0064698596 | M9: 0.056539772 | N9: 0.13090838 | O9: 0.02592106 | P9: 0.00091951331 | Q9: 2.1674411e-05 | R9: 9.996262e-05 | S9: Regioinvent | T9: Cu concentrate
A10: 0.62644234 | B10: Cu concentrate from Cu mine | C10: 6.7497352e-19 | D10: 0.19623575 | E10: 8.2450172 | F10: 0.00017383967 | G10: 1.2966538e-09 | H10: 0.53679632 | I10: 1.0646857 | J10: 0.19039469 | K10: 7.8929063e-06 | L10: 0.0091765466 | M10: 0.17967064 | N10: 0.39055705 | O10: 0.28809256 | P10: 0.00065688557 | Q10: 3.8413038e-05 | R10: 0.00014500186 | S10: Regioinvent | T10: Cu concentrate
A11: 2116.3029 | B11: Au-Ag ingot | C11: 1.9111684e-15 | D11: 177.26521 | E11: 648.14947 | F11: 0.53749639 | G11: 6.9321916e-06 | H11: 263.82195 | I11: 909.32316 | J11: 652.19448 | K11: 0.0019759631 | L11: 18.001993 | M11: 157.3185 | N11: 364.24466 | O11: 72.123779 | P11: 2.5584902 | Q11: 0.060307742 | R11: 0.27813995 | S11: Regioinvent | T11: Doré
A12: 0.34037454 | B12: Pb concentrate | C12: 3.0738184e-19 | D12: 0.028510364 | E12: 0.10424481 | F12: 8.6447972e-05 | G12: 1.1149356e-09 | H12: 0.042431677 | I12: 0.14625054 | J12: 0.10489538 | K12: 3.1780307e-07 | L12: 0.0028953419 | M12: 0.025302244 | N12: 0.058583112 | O12: 0.011599993 | P12: 0.00041149352 | Q12: 9.699566e-06 | R12: 4.4734503e-05 | S12: Regioinvent | T12: Pb concentrate
A13: 0.34399555 | B13: Zn concentrate | C13: 3.1065187e-19 | D13: 0.028813666 | E13: 0.1053538 | F13: 8.7367631e-05 | G13: 1.1267966e-09 | H13: 0.042883078 | I13: 0.14780641 | J13: 0.10601129 | K13: 3.2118397e-07 | L13: 0.0029261433 | M13: 0.025571417 | N13: 0.059206338 | O13: 0.011723398 | P13: 0.00041587112 | Q13: 9.8027529e-06 | R13: 4.5210402e-05 | S13: Regioinvent | T13: Zn concentrate
... A57: 7.9522056 | B57: Cigar Lake + McClean Lake | C57: 1.6268475e-19 | D57: 0.18697799 | E57: 0.53012425 | F57: 0.00011201879 | G57: 1.0899439e-10 | H57: 0.28961978 | I57: 5.411796 | J57: 2.4377283 | K57: 2.5813116e-07 | L57: 0.052426412 | M57: 0.70487657 | N57: 1.4050906 | O57: 0.0094223818 | P57: 0.00079558335 | Q57: 0.0005967284 | R57: 0.00088268825 | S57: MetalliCan | T57: U concentrate

Sheet HH_damages_ecoinvent
A1: Climate change | B1: Commodity | C1: Human toxicity non-cancer | D1: Human toxicity, cancer | E1: Ionizing radiations | F1: Ozone layer depletion | G1: Particulate matter | H1: Photochemical ozone | I1: Water availability | J1: Source | K1: Reference product
A2: 7.2316659e-06 | B2: Cu concentrate from Au mine | C2: 2.926462e-06 | D2: 4.2767183e-07 | E2: 2.3559124e-09 | F2: 1.5755991e-11 | G2: 9.8617646e-07 | H2: 5.4385286e-09 | I2: 2.5763907e-06 | J2: Ecoinvent | K2: Cu concentrate
A3: 8.3001448e-06 | B3: Cu concentrate from Cu mine | C3: 7.9869159e-07 | D3: 5.6200184e-07 | E3: 1.2865848e-08 | F3: 1.7188007e-11 | G3: 3.0547211e-06 | H3: 1.8123086e-08 | I3: 4.6651129e-06 | J3: Ecoinvent | K3: Cu concentrate
A4: 0.020121673 | B4: Au-Ag ingot | C4: 0.0081427035 | D4: 0.001189971 | E4: 6.555184e-06 | F4: 4.3840092e-08 | G4: 0.0027439763 | H4: 1.5132377e-05 | I4: 0.0071686516 | J4: Ecoinvent | K4: Doré
A5: 3.2362596e-06 | B5: Pb concentrate | C5: 1.3096278e-06 | D5: 1.9138841e-07 | E5: 1.0542998e-09 | F5: 7.0510001e-12 | G5: 4.4132611e-07 | H5: 2.4338085e-09 | I5: 1.1529665e-06 | J5: Ecoinvent | K5: Pb concentrate
A6: 3.2706879e-06 | B6: Zn concentrate | C6: 1.32356e-06 | D6: 1.9342446e-07 | E6: 1.0655158e-09 | F6: 7.1260108e-12 | G6: 4.4602107e-07 | H6: 2.4597001e-09 | I6: 1.1652322e-06 | J6: Ecoinvent | K6: Zn concentrate
A7: 3.4152167e-06 | B7: Ni concentrate | C7: 9.1856359e-08 | D7: 4.2600889e-08 | E7: 1.8211704e-10 | F7: 7.9134939e-12 | G7: 5.1171272e-07 | H7: 2.9209351e-09 | I7: 1.6893811e-07 | J7: Ecoinvent | K7: Ni concentrate
A8: 0.00072684614 | B8: U yellowcake | C8: 0.00093172672 | D8: 8.382751e-05 | E8: 0.00086287406 | F8: 1.6395851e-09 | G8: 0.00036069786 | H8: 9.1834137e-07 | I8: 5.1268034e-05 | J8: Ecoinvent | K8: U concentrate
A9: 1.0250485e-05 | B9: Cu concentrate from Au mine | C9: 2.9856741e-06 | D9: 4.8036528e-07 | E9: 2.4296377e-08 | F9: 2.8071499e-11 | G9: 6.4608096e-06 | H9: 5.7607875e-09 | I9: 5.0565936e-08 | J9: Regioinvent | K9: Cu concentrate
A10: 8.4425462e-06 | B10: Cu concentrate from Cu mine | C10: 8.2598769e-07 | D10: 5.9207312e-07 | E10: 1.2777435e-08 | F10: 2.0730571e-11 | G10: 4.4050973e-05 | H10: 1.8349373e-08 | I10: 1.5308322e-07 | J10: Regioinvent | K10: Cu concentrate
A11: 0.028521355 | B11: Au-Ag ingot | C11: 0.0083074575 | D11: 0.0013365874 | E11: 6.7603203e-05 | F11: 7.8107249e-08 | G11: 0.017976812 | H11: 1.6029043e-05 | I11: 0.00014069666 | J11: Regioinvent | K11: Doré
A12: 4.5872183e-06 | B12: Pb concentrate | C12: 1.3361259e-06 | D12: 2.1496938e-07 | E12: 1.0872928e-08 | F12: 1.2562341e-11 | G12: 2.8912918e-06 | H12: 2.5780233e-09 | I12: 2.2628879e-08 | J12: Regioinvent | K12: Pb concentrate
A13: 4.6360185e-06 | B13: Zn concentrate | C13: 1.35034e-06 | D13: 2.1725629e-07 | E13: 1.0988597e-08 | F13: 1.2695983e-11 | G13: 2.9220502e-06 | H13: 2.6054491e-09 | I13: 2.2869612e-08 | J13: Regioinvent | K13: Zn concentrate
... A57: 0.00010717166 | B57: Cigar Lake + McClean Lake | C57: 8.1598049e-06 | D57: 7.2831528e-07 | E57: 1.3408364e-09 | F57: 1.4894909e-10 | G57: 1.7008379e-05 | H57: 5.6451718e-08 | I57: 7.2885834e-05 | J57: MetalliCan | K57: U concentrate

Sheet MP_results
A1: Commodity | B1: Climate change (kg CO2 eq) | C1: Land occupation biodiversity (m2 arable land eq .yr) | D1: Land transformation biodiversity (m2 arable land eq) | E1: Particulate matter formation (kg PM2.5 eq) | F1: Source | G1: Reference product | H1: Water scarcity (m3 world-eq)
A2: Cu concentrate from Au mine | B2: 1.0800737 | C2: 0.41956417 | D2: 0.0053379257 | E2: 0.00072110084 | F2: Ecoinvent | G2: Copper concentrate
A3: Cu concentrate from Cu mine | B3: 1.2656713 | C3: 2.031346 | D3: 0.012977911 | E3: 0.0022336387 | F3: Ecoinvent | G3: Copper concentrate
A4: Au-Ag ingot | B4: 3005.2397 | C4: 1167.4119 | D4: 14.852456 | E4: 2.0064195 | F4: Ecoinvent | G4: Gold-silver doré
A5: Pb concentrate | B5: 0.48334628 | C5: 0.18776014 | D5: 0.0023887874 | E5: 0.0003227015 | F5: Ecoinvent | G5: Pb concentrate
A6: Zn concentrate | B6: 0.48848827 | C6: 0.18975758 | D6: 0.0024142002 | E6: 0.0003261345 | F6: Ecoinvent | G6: Zinc concentrate
A7: Ni concentrate | B7: 0.51463122 | C7: 0.098754091 | D7: 0.0015393338 | E7: 0.00037416881 | F7: Ecoinvent | G7: Nickel concentrate
A8: U yellowcake | B8: 109.32237 | C8: 11.806889 | D8: 0.02170408 | E8: 0.26374542 | F8: Ecoinvent | G8: Uranium concentrate (yellowcake)
A9: Cu concentrate from Au mine | B9: 1.5056416 | C9: 3.0218147e-05 | D9: 1.6516548e-07 | E9: 6.7811771e-07 | F9: Regioinvent | G9: Copper concentrate
A10: Cu concentrate from Cu mine | B10: 1.2553054 | C10: 1.9640265e-06 | D10: 7.8784718e-09 | E10: 1.0111872e-07 | F10: Regioinvent | G10: Copper concentrate
A11: Au-Ag ingot | B11: 4189.3568 | C11: 0.084080168 | D11: 0.00045956297 | E11: 0.0018868215 | F11: Regioinvent | G11: Gold-silver doré
A12: Pb concentrate | B12: 0.67379317 | C12: 1.3522993e-05 | D12: 7.3913588e-08 | E12: 3.0346603e-07 | F12: Regioinvent | G12: Pb concentrate
A13: Zn concentrate | B13: 0.68096118 | C13: 1.3666855e-05 | D13: 7.4699904e-08 | E13: 3.066944e-07 | F13: Regioinvent | G13: Zinc concentrate
... A15: U yellowcake | B15: 84.137681 | C15: 0.00018921852 | D15: 1.0389959e-06 | E15: 3.1511176e-06 | F15: Regioinvent | G15: Uranium concentrate (yellowcake)
A16: Copper Mountain | B16: 2.1089135 | C16: 0.21827023 | D16: 0.011710211 | E16: 0.0028817405 | F16: MetalliCan | G16: Copper concentrate | H16: 0.37246667
A17: Gibraltar** | B17: 1.8239387 | C17: 0.20125989 | D17: 0.0072783363 | E17: 0.0028436065 | F17: MetalliCan | G17: Copper concentrate | H17: 0.39771659
A18: Highland Valley** | B18: 1.0848636 | C18: 0.15541954 | D18: 0.0099730882 | E18: 0.0016329681 | F18: MetalliCan | G18: Copper concentrate | H18: 0.2288001
A19: Mount Milligan | B19: 1.8618573 | C19: 0.25197209 | D19: 0.0085561576 | E19: 0.00086061557 | F19: MetalliCan | G19: Copper concentrate | H19: 0.75270655
A20: Mount Polley | B20: 2.141271 | C20: 0.21271523 | D20: 0.010079298 | E20: 0.023408971 | F20: MetalliCan | G20: Copper concentrate | H20: 0.41896462
A21: Goldex** | B21: 1.8825847 | C21: 0.25288545 | D21: 0.002797756 | E21: 0.0046711815 | F21: MetalliCan | G21: Copper concentrate | H21: 0.47839848
A22: Kidd Creek | B22: 0.38304484 | C22: 0.033653801 | D22: 0.0021869106 | E22: 0.0027737039 | F22: MetalliCan | G22: Copper concentrate | H22: 0.014160073
A23: LaRonde** | B23: 1.0678312 | C23: 0.19684911 | D23: 0.0035494151 | E23: 0.0014250764 | F23: MetalliCan | G23: Copper concentrate | H23: 0.20745228
A24: New Afton | B24: 0.47706988 | C24: 0.076326184 | D24: 0.0039039558 | E24: 0.00020978314 | F24: MetalliCan | G24: Copper concentrate | H24: 0.141722
A25: Snow Lake** | B25: 1.7020487 | C25: 0.11282536 | D25: 0.00067464052 | E25: 0.0012429014 | F25: MetalliCan | G25: Copper concentrate | H25: 1.85364
A26: Casa Berardi | B26: 16340.756 | C26: 2495.8323 | D26: 96.378852 | E26: 10.791962 | F26: MetalliCan | G26: Gold-silver doré | H26: 1662.5983
A27: Hemlo | B27: 11557.111 | C27: 840.27183 | D27: 43.521081 | E27: 73.405465 | F27: MetalliCan | G27: Gold-silver doré | H27: 1698.295
... A64: Market for Zn concentrate | B64: 0.37856286 | C64: 0.031051302 | D64: 0.00062402684 | E64: 0.00074397556 | F64: MetalliCan market | G64: Zinc concentrate | H64: 0.30645253

Sheet CA_GWP_results
A1: reference_product_market | B1: flow_type | C1: name | D1: supplier_reference_product | E1: categories | F1: unit | G1: location | H1: impact_score_market | I1: n_sites | J1: total_score_market | K1: share_%
A2: Cu concentrate | B2: Biosphere (direct) | C2: Carbon dioxide, fossil | E2: ('air', 'non-urban air or from high stacks') | F2: kilogram | H2: 0.54920894 | I2: 9 | J2: 1.3879451 | K2: 39.569932
A3: Cu concentrate | B3: Biosphere (direct) | C3: Carbon dioxide, from soil or biomass stock | E3: ('air', 'low population density, long-term') | F3: kilogram | H3: 0.11064977 | I3: 8 | J3: 1.3879451 | K3: 7.9722005
A4: Cu concentrate | B4: Biosphere (direct) | C4: Carbon monoxide, fossil | E4: ('air', 'low population density, long-term') | F4: kilogram | H4: 0.021797122 | I4: 6 | J4: 1.3879451 | K4: 1.5704599
A5: Cu concentrate | B5: Biosphere (direct) | C5: Dinitrogen monoxide | E5: ('air', 'non-urban air or from high stacks') | F5: kilogram | H5: 0.014858667 | I5: 7 | J5: 1.3879451 | K5: 1.0705515
A6: Cu concentrate | B6: Biosphere (direct) | C6: Methane, fossil | E6: ('air',) | F6: kilogram | H6: 0.00081946759 | I6: 7 | J6: 1.3879451 | K6: 0.059041786
A7: Cu concentrate | B7: Technosphere (first-tier) | C7: market for steel, low-alloyed | D7: steel, low-alloyed | F7: kilogram | G7: GLO | H7: 0.21930812 | I7: 9 | J7: 1.3879451 | K7: 15.800922
A8: Cu concentrate | B8: Technosphere (first-tier) | C8: market for diesel | D8: diesel | F8: kilogram | G8: RoW | H8: 0.14495708 | I8: 9 | J8: 1.3879451 | K8: 10.444006
A9: Cu concentrate | B9: Technosphere (first-tier) | C9: market for explosive, tovex | D9: explosive, tovex | F9: kilogram | G9: GLO | H9: 0.074513511 | I9: 9 | J9: 1.3879451 | K9: 5.3686208
A10: Cu concentrate | B10: Technosphere (first-tier) | C10: market for polyacrylamide | D10: polyacrylamide | F10: kilogram | G10: GLO | H10: 0.04468516 | I10: 9 | J10: 1.3879451 | K10: 3.2195192
A11: Cu concentrate | B11: Technosphere (first-tier) | C11: market for chemical, organic | D11: chemical, organic | F11: kilogram | G11: GLO | H11: 0.027022172 | I11: 8 | J11: 1.3879451 | K11: 1.9469194
A12: Cu concentrate | B12: Technosphere (first-tier) | C12: market for cement, unspecified | D12: cement, unspecified | F12: kilogram | G12: RoW | H12: 0.0081849918 | I12: 4 | J12: 1.3879451 | K12: 0.58972013
A13: Cu concentrate | B13: Technosphere (first-tier) | C13: market for lime | D13: lime | F13: kilogram | G13: RoW | H13: 0.0068239181 | I13: 9 | J13: 1.3879451 | K13: 0.49165619
A14: Cu concentrate | B14: Technosphere (first-tier) | C14: market for natural gas, high pressure | D14: natural gas, high pressure | F14: cubic meter | G14: CA | H14: 0.0048468968 | I14: 8 | J14: 1.3879451 | K14: 0.34921386
A15: Cu concentrate | B15: Technosphere (first-tier) | C15: market for sodium cyanide | D15: sodium cyanide | F15: kilogram | G15: RoW | H15: 0.0014663101 | I15: 3 | J15: 1.3879451 | K15: 0.10564611
A16: Cu concentrate | B16: Technosphere (first-tier) | C16: market for sodium bicarbonate | D16: sodium bicarbonate | F16: kilogram | G16: RoW | H16: 0.0014352156 | I16: 9 | J16: 1.3879451 | K16: 0.10340579
A17: Cu concentrate | B17: Technosphere (first-tier) | C17: market for propane | D17: propane | F17: kilogram | G17: GLO | H17: 0.00079890456 | I17: 4 | J17: 1.3879451 | K17: 0.057560241
A18: Cu concentrate | B18: Technosphere (first-tier) | C18: market for liquefied petroleum gas | D18: liquefied petroleum gas | F18: kilogram | G18: RoW | H18: 0.00042377814 | I18: 4 | J18: 1.3879451 | K18: 0.030532774
... A26: Cu concentrate | B26: Technosphere (first-tier) | C26: market for sulfidic tailings, from gold mine operation | D26: sulfidic tailings, from gold mine operation | F26: kilogram | G26: CA | H26: 0 | I26: 3 | J26: 1.3879451 | K26: 0
A27: Doré | B27: Biosphere (direct) | C27: Carbon dioxide, fossil | E27: ('air', 'non-urban air or from high stacks') | F27: kilogram | H27: 7839.7172 | I27: 21 | J27: 21404.452 | K27: 36.626572
A28: Doré | B28: Biosphere (direct) | C28: Carbon monoxide, fossil | E28: ('air', 'low population density, long-term') | F28: kilogram | H28: 274.52535 | I28: 19 | J28: 21404.452 | K28: 1.2825619
A29: Doré | B29: Biosphere (direct) | C29: Carbon dioxide, from soil or biomass stock | E29: ('air', 'low population density, long-term') | F29: kilogram | H29: 268.64015 | I29: 16 | J29: 21404.452 | K29: 1.2550667
A30: Doré | B30: Biosphere (direct) | C30: Dinitrogen monoxide | E30: ('air', 'non-urban air or from high stacks') | F30: kilogram | H30: 97.052477 | I30: 18 | J30: 21404.452 | K30: 0.45342191
A31: Doré | B31: Biosphere (direct) | C31: Methane, fossil | E31: ('air',) | F31: kilogram | H31: 31.417761 | I31: 18 | J31: 21404.452 | K31: 0.14678143
A32: Doré | B32: Technosphere (first-tier) | C32: market for explosive, tovex | D32: explosive, tovex | F32: kilogram | G32: GLO | H32: 4161.1704 | I32: 21 | J32: 21404.452 | K32: 19.440677
A33: Doré | B33: Technosphere (first-tier) | C33: market for diesel | D33: diesel | F33: kilogram | G33: RoW | H33: 1750.8329 | I33: 20 | J33: 21404.452 | K33: 8.1797601
A34: Doré | B34: Technosphere (first-tier) | C34: market for steel, low-alloyed | D34: steel, low-alloyed | F34: kilogram | G34: GLO | H34: 1495.8085 | I34: 16 | J34: 21404.452 | K34: 6.9883054
A35: Doré | B35: Technosphere (first-tier) | C35: market for sodium cyanide | D35: sodium cyanide | F35: kilogram | G35: RoW | H35: 1068.1387 | I35: 18 | J35: 21404.452 | K35: 4.990264
A36: Doré | B36: Technosphere (first-tier) | C36: market for cement, unspecified | D36: cement, unspecified | F36: kilogram | G36: RoW | H36: 485.45849 | I36: 18 | J36: 21404.452 | K36: 2.2680258
A37: Doré | B37: Technosphere (first-tier) | C37: market for propane | D37: propane | F37: kilogram | G37: GLO | H37: 109.5709 | I37: 13 | J37: 21404.452 | K37: 0.51190707
A38: Doré | B38: Technosphere (first-tier) | C38: market for natural gas, high pressure | D38: natural gas, high pressure | F38: cubic meter | G38: CA | H38: 74.177022 | I38: 11 | J38: 21404.452 | K38: 0.3465495
A39: Doré | B39: Technosphere (first-tier) | C39: market for sulfur dioxide, liquid | D39: sulfur dioxide, liquid | F39: kilogram | G39: RoW | H39: 70.083251 | I39: 13 | J39: 21404.452 | K39: 0.32742371
A40: Doré | B40: Technosphere (first-tier) | C40: market for activated carbon, granular | D40: activated carbon, granular | F40: kilogram | G40: GLO | H40: 56.370124 | I40: 13 | J40: 21404.452 | K40: 0.263357
A41: Doré | B41: Technosphere (first-tier) | C41: market for lime | D41: lime | F41: kilogram | G41: RoW | H41: 52.430029 | I41: 17 | J41: 21404.452 | K41: 0.24494917
A42: Doré | B42: Technosphere (first-tier) | C42: market for polyacrylamide | D42: polyacrylamide | F42: kilogram | G42: GLO | H42: 38.87423 | I42: 14 | J42: 21404.452 | K42: 0.1816175
A43: Doré | B43: Technosphere (first-tier) | C43: market for hydrochloric acid, without water, in 30% solution state | D43: hydrochloric acid, without water, in 30% solution state | F43: kilogram | G43: RoW | H43: 18.890589 | I43: 14 | J43: 21404.452 | K43: 0.088255418
... A57: Doré | B57: Technosphere (first-tier) | C57: market for sulfidic tailings, from gold mine operation | D57: sulfidic tailings, from gold mine operation | F57: kilogram | G57: CA | H57: 0 | I57: 21 | J57: 21404.452 | K57: 0
A58: Mo concentrate | B58: Biosphere (direct) | C58: Carbon dioxide, fossil | E58: ('air', 'non-urban air or from high stacks') | F58: kilogram | H58: 2.3915939 | I58: 2 | J58: 6.0064789 | K58: 39.816903
A59: Mo concentrate | B59: Biosphere (direct) | C59: Carbon dioxide, from soil or biomass stock | E59: ('air', 'low population density, long-term') | F59: kilogram | H59: 0.58014724 | I59: 2 | J59: 6.0064789 | K59: 9.6586911
A60: Mo concentrate | B60: Biosphere (direct) | C60: Carbon monoxide, fossil | E60: ('air', 'low population density, long-term') | F60: kilogram | H60: 0.11352409 | I60: 2 | J60: 6.0064789 | K60: 1.8900274
...

Sheet bgf_tech
A1: Commodity | B1: Climate change (kg CO2 eq) | C1: Land occupation biodiversity (m2 arable land eq .yr) | D1: Land transformation biodiversity (m2 arable land eq) | E1: Particulate matter formation (kg PM2.5 eq) | F1: Water scarcity (m3 world-eq) | G1: Source | H1: Reference product | I1: site_id | J1: ore_processed_t | K1: dore_t_mass | L1: conc_t_mass
A2: Copper Mountain | B2: 0 | C2: 0 | D2: 0 | E2: 0 | F2: 0 | G2: MetalliCan | H2: Cu concentrate | I2: BC-MAIN-599152a0 | J2: 6862152 | L2: 63500
A3: Gibraltar** | B3: 0.34863642 | C3: 0.013185499 | D3: 8.5787469e-05 | E3: 0.00026613756 | F3: 0.15102916 | G3: MetalliCan | H3: Cu concentrate | I3: BC-MAIN-6b4800fe | J3: 30000000 | L3: 186436.98
A4: Highland Valley** | B4: 0 | C4: 0 | D4: 0 | E4: 0 | F4: 0 | G4: MetalliCan | H4: Cu concentrate | I4: BC-MAIN-bf503b6b | J4: 17408000 | L4: 343098.04
A5: Mount Milligan | B5: 0.31093164 | C5: 0.0089978928 | D5: 9.2840881e-05 | E5: 0.00023642464 | F5: 0.083332861 | G5: MetalliCan | H5: Cu concentrate | I5: BC-MAIN-ed23117f | J5: 21680000 | L5: 93533.694
A6: Mount Polley | B6: 0 | C6: 0 | D6: 0 | E6: 0 | F6: 0 | G6: MetalliCan | H6: Cu concentrate | I6: BC-MAIN-3f490561 | J6: 5948239 | L6: 45578.436
A7: Goldex** | B7: 0.76318551 | C7: 0.15959981 | D7: 0.00015196638 | E7: 0.00090569208 | F7: 0.25260539 | G7: MetalliCan | H7: Cu concentrate | I7: QC-MAIN-c0660aec | J7: 2886927.3 | K7: 4.4745421 | L7: 130.12253
A8: Kidd Creek | B8: 0 | C8: 0 | D8: 0 | E8: 0 | F8: 0 | G8: MetalliCan | H8: Cu concentrate | I8: ON-MAIN-f8313ebd | J8: 1340000 | L8: 152533.33
A9: LaRonde** | B9: 0.3582258 | C9: 0.14370896 | D9: 0.00011397681 | E9: 0.00049825193 | F9: 0.15441425 | G9: MetalliCan | H9: Cu concentrate | I9: QC-MAIN-e51eda66 | J9: 1501500 | K9: 9.8029028 | L9: 23998.078
A10: New Afton | B10: 0.22976867 | C10: 0.0073571968 | D10: 4.2922075e-05 | E10: 0.00018411637 | F10: 0.067919489 | G10: MetalliCan | H10: Cu concentrate | I10: BC-MAIN-aa76f6f2 | J10: 3065000 | L10: 71667.536
A11: Snow Lake** | B11: 0.095040226 | C11: 0.0050816853 | D11: 1.4251557e-05 | E11: 4.9220875e-05 | F11: 0.08803032 | G11: MetalliCan | H11: Cu concentrate | I11: GRP-a13779f8 | J11: 2123641 | K11: 32.978787 | L11: 109797.33
A12: Casa Berardi | B12: 5844.3194 | C12: 1153.3848 | D12: 1.6428513 | E12: 6.6400381 | F12: 1662.5983 | G12: MetalliCan | H12: Doré | I12: QC-MAIN-b86f7d07 | J12: 1361450 | K12: 3.5165998
A13: Hemlo | B13: 0 | C13: 0 | D13: 0 | E13: 0 | F13: 0 | G13: MetalliCan | H13: Doré | I13: ON-MAIN-6e9be24e | J13: 1266009 | K13: 4.4765236
A14: Meliadine | B14: 2442.8983 | C14: 96.218722 | D14: 0.25384592 | E14: 2.39111 | F14: 573.60306 | G14: MetalliCan | H14: Doré | I14: NU-MAIN-8b0264c9 | J14: 1918143 | K14: 12.414137
A15: Rainy River | B15: 27783.23 | C15: 1117.0015 | D15: 4.5298929 | E15: 22.892975 | F15: 8641.1726 | G15: MetalliCan | H15: Doré | I15: ON-MAIN-0aadf28f | J15: 8764000 | K15: 8.0534261
A16: Meadowbank complex | B16: 8418.7493 | C16: 214.75384 | D16: 2.2884277 | E16: 6.7416993 | F16: 1240.1556 | G16: MetalliCan | H16: Doré | I16: GRP-0a2c0d69 | J16: 3842649 | K16: 17.667601
A17: Porcupine complex | B17: 5622.5241 | C17: 183.44885 | D17: 1.2609945 | E17: 3.9437886 | F17: 1643.5231 | G17: MetalliCan | H17: Doré | I17: GRP-0d911886 | J17: 2911000 | K17: 8.251949
A18: Canadian Malartic | B18: 2132.8665 | C18: 618.15917 | D18: 0.96731811 | E18: 2.3853199 | F18: 610.11219 | G18: MetalliCan | H18: Doré | I18: QC-MAIN-e7e6a960 | J18: 17332900 | K18: 29.039085
A19: Detour Lake | B19: 10219.741 | C19: 386.12064 | D19: 2.2293825 | E19: 8.2659426 | F19: 2843.4716 | G19: MetalliCan | H19: Doré | I19: ON-MAIN-aeafbb59 | J19: 25434854 | K19: 24.008284
A20: Kiena | B20: 4517.2968 | C20: 801.16401 | D20: 1.1143374 | E20: 5.0302644 | F20: 1300.197 | G20: MetalliCan | H20: Doré | I20: QC-MAIN-9de9bb0d | J20: 191148 | K20: 1.2201776
A21: Brucejack | B21: 21935.421 | C21: 916.44608 | D21: 4.9799328 | E21: 18.056195 | F21: 10341.984 | G21: MetalliCan | H21: Doré | I21: BC-MAIN-857b7b89 | J21: 166000 | K21: 0.92040969
A22: Eagle River | B22: 2907.8698 | C22: 114.53261 | D22: 0.30216194 | E22: 2.8462244 | F22: 682.78039 | G22: MetalliCan | H22: Doré | I22: ON-MAIN-cb85213a | J22: 222627 | K22: 2.7760509
A23: Éléonore | B23: 4419.8212 | C23: 906.08478 | D23: 1.1063493 | E23: 4.9338163 | F23: 1278.9427 | G23: MetalliCan | H23: Doré | I23: QC-MAIN-6dc537e6 | J23: 1661000 | K23: 7.7388999
A24: Goldex** | B24: 5728.6624 | C24: 1197.9963 | D24: 1.1406979 | E24: 6.7983525 | F24: 1896.1196 | G24: MetalliCan | H24: Doré | I24: QC-MAIN-c0660aec | J24: 2886927.3 | K24: 4.4745421 | L24: 130.12253
A25: Island | B25: 3739.4634 | C25: 154.29182 | D25: 0.81363206 | E25: 2.7961147 | F25: 1281.235 | G25: MetalliCan | H25: Doré | I25: ON-MAIN-687b8c8d | J25: 439008 | K25: 4.1704081
A26: LaRonde** | B26: 2688.9329 | C26: 1078.7155 | D26: 0.8555386 | E26: 3.7400041 | F26: 1159.0722 | G26: MetalliCan | H26: Doré | I26: QC-MAIN-e51eda66 | J26: 1501500 | K26: 9.8029028 | L26: 23998.078
A27: Macassa | B27: 18972.134 | C27: 747.25769 | D27: 1.9714283 | E27: 18.569934 | F27: 4454.7391 | G27: MetalliCan | H27: Doré | I27: ON-MAIN-1f126a43 | J27: 441588 | K27: 7.2533045
A28: Musselwhite | B28: 4788.3276 | C28: 186.93131 | D28: 1.0031582 | E28: 3.8343134 | F28: 1501.2688 | G28: MetalliCan | H28: Doré | I28: ON-MAIN-fefeaee4 | J28: 1028000 | K28: 5.7128878
A29: Red Lake | B29: 0 | C29: 0 | D29: 0 | E29: 0 | F29: 0 | G29: MetalliCan | H29: Doré | I29: ON-MAIN-7f050560 | J29: 841000 | K29: 3.5769025
A30: Seabee Gold Operation | B30: 36627.573 | C30: 134.56073 | D30: 2.0941228 | E30: 9.882687 | F30: 2820.2468 | G30: MetalliCan | H30: Doré | I30: GRP-14bfbb82 | J30: 122000 | K30: 1.2300799
A31: Snow Lake** | B31: 713.39582 | C31: 38.144408 | D31: 0.10697576 | E31: 0.36946426 | F31: 660.77771 | G31: MetalliCan | H31: Doré | I31: GRP-a13779f8 | J31: 2123641 | K31: 32.978787 | L31: 109797.33
A32: Timmins Operation | B32: 7641.2718 | C32: 331.09852 | D32: 1.5842321 | E32: 5.4832229 | F32: 2810.8952 | G32: MetalliCan | H32: Doré | I32: GRP-147b3123 | J32: 1574000 | K32: 4.2180155
A33: Westwood-Doyon | B33: 6943.7974 | C33: 1112.2116 | D33: 1.3485321 | E33: 16.638876 | F33: 2038.7129 | G33: MetalliCan | H33: Doré | I33: QC-MAIN-02884fb5 | J33: 1034000 | K33: 4.1181669
A34: Nunavik Nickel | B34: 0 | C34: 0 | D34: 0 | E34: 0 | F34: 0 | G34: MetalliCan | H34: Ni concentrate | I34: QC-MAIN-5ce331b8 | J34: 6835294.1 | L34: 363125
A35: Thompson | B35: 0 | C35: 0 | D35: 0 | E35: 0 | F35: 0 | G35: MetalliCan | H35: Ni concentrate | I35: MB-MAIN-e0a6250e | J35: 464705.88 | L35: 49375
A36: Voisey's Bay | B36: 0 | C36: 0 | D36: 0 | E36: 0 | F36: 0 | G36: MetalliCan | H36: Ni concentrate | I36: NL-MAIN-2d8801d6 | J36: 794117.65 | L36: 84375
A37: Raglan | B37: 0 | C37: 0 | D37: 0 | E37: 0 | F37: 0 | G37: MetalliCan | H37: Ni concentrate | I37: QC-MAIN-a97821c0 | J37: 1500000 | L37: 151450
A38: Gibraltar** | B38: 1.47741 | C38: 0.055875941 | D38: 0.00036353995 | E38: 0.0011278061 | F38: 0.64001341 | G38: MetalliCan | H38: Mo concentrate | I38: BC-MAIN-6b4800fe | J38: 30000000 | L38: 186436.98
A39: Highland Valley** | B39: 0 | C39: 0 | D39: 0 | E39: 0 | F39: 0 | G39: MetalliCan | H39: Mo concentrate | I39: BC-MAIN-bf503b6b | J39: 17408000 | L39: 343098.04
A40: Kidd Creek** | B40: 0 | C40: 0 | D40: 0 | E40: 0 | F40: 0 | G40: MetalliCan | H40: Zn concentrate | I40: ON-MAIN-f8313ebd | J40: 1340000 | L40: 152533.33
...

Sheet bgf_bio
A1: Commodity | B1: Climate change (kg CO2 eq) | C1: Land occupation biodiversity (m2 arable land eq .yr) | D1: Land transformation biodiversity (m2 arable land eq) | E1: Particulate matter formation (kg PM2.5 eq) | F1: Water scarcity (m3 world-eq) | G1: Source | H1: Reference product | I1: site_id | J1: ore_processed_t | K1: dore_t_mass | L1: conc_t_mass
A2: Copper Mountain | B2: 1.332982 | C2: 0.13119695 | D2: 0.010961052 | E2: 0.031884872 | F2: 0 | G2: MetalliCan | H2: Cu concentrate | I2: BC-MAIN-599152a0 | J2: 6862152 | L2: 63500
A3: Gibraltar** | B3: 0.82976936 | C3: 0.074685089 | D3: 0.0062396818 | E3: 0.0026621719 | F3: 1.2351247 | G3: MetalliCan | H3: Cu concentrate | I3: BC-MAIN-6b4800fe | J3: 30000000 | L3: 186436.98
A4: Highland Valley** | B4: 0.70247092 | C4: 0.11537376 | D4: 0.0096390789 | E4: 0.019027851 | F4: 2.5452594 | G4: MetalliCan | H4: Cu concentrate | I4: BC-MAIN-bf503b6b | J4: 17408000 | L4: 343098.04
A5: Mount Milligan | B5: 0.87661813 | C5: 0.084853263 | D5: 0.0070891974 | E5: 0.00020433363 | F5: 3.7206059 | G5: MetalliCan | H5: Cu concentrate | I5: BC-MAIN-ed23117f | J5: 21680000 | L5: 93533.694
A6: Mount Polley | B6: 1.3048362 | C6: 0.11005584 | D6: 0.0091947863 | E6: 0.01236277 | F6: 0 | G6: MetalliCan | H6: Cu concentrate | I6: BC-MAIN-3f490561 | J6: 5948239 | L6: 45578.436
A7: Goldex** | B7: 0.43343599 | C7: 0.025054193 | D7: 0.0020931913 | E7: 7.7371151e-05 | F7: 0.86422611 | G7: MetalliCan | H7: Cu concentrate | I7: QC-MAIN-c0660aec | J7: 2886927.3 | K7: 4.4745421 | L7: 130.12253
A8: Kidd Creek | B8: 0.3304928 | C8: 0.025391079 | D8: 0.002121337 | E8: 0.0011088603 | F8: 0 | G8: MetalliCan | H8: Cu concentrate | I8: ON-MAIN-f8313ebd | J8: 1340000 | L8: 152533.33
A9: LaRonde** | B9: 0.5728072 | C9: 0.039909053 | D9: 0.0033342636 | E9: 0.00043197593 | F9: 0.4407278 | G9: MetalliCan | H9: Cu concentrate | I9: QC-MAIN-e51eda66 | J9: 1501500 | K9: 9.8029028 | L9: 23998.078
A10: New Afton | B10: 0.24730121 | C10: 0.043486584 | D10: 0.0036331543 | E10: 0.00037646055 | F10: 1.6583858 | G10: MetalliCan | H10: Cu concentrate | I10: BC-MAIN-aa76f6f2 | J10: 3065000 | L10: 71667.536
A11: Snow Lake** | B11: 0.074457954 | C11: 0.0062244122 | D11: 0.00052002816 | E11: 0.00037608328 | F11: 0 | G11: MetalliCan | H11: Cu concentrate | I11: GRP-a13779f8 | J11: 2123641 | K11: 32.978787 | L11: 109797.33
A12: Casa Berardi | B12: 10496.437 | C12: 1110.4624 | D12: 92.775305 | E12: 0.76920897 | F12: 0 | G12: MetalliCan | H12: Doré | I12: QC-MAIN-b86f7d07 | J12: 1361450 | K12: 3.5165998
A13: Hemlo | B13: 6303.7826 | C13: 492.65204 | D13: 41.15938 | E13: 4.3536159 | F13: 338.46908 | G13: MetalliCan | H13: Doré | I13: ON-MAIN-6e9be24e | J13: 1266009 | K13: 4.4765236
A14: Meliadine | B14: 11492.476 | C14: 0 | D14: 0 | E14: 33.05498 | F14: 1400.0758 | G14: MetalliCan | H14: Doré | I14: NU-MAIN-8b0264c9 | J14: 1918143 | K14: 12.414137
A15: Rainy River | B15: 18111.744 | C15: 1781.5196 | D15: 148.83982 | E15: 30.392671 | F15: 30057.033 | G15: MetalliCan | H15: Doré | I15: ON-MAIN-0aadf28f | J15: 8764000 | K15: 8.0534261
A16: Meadowbank complex | B16: 14748.35 | C16: 272.39035 | D16: 22.757274 | E16: 44.989872 | F16: 6055.1396 | G16: MetalliCan | H16: Doré | I16: GRP-0a2c0d69 | J16: 3842649 | K16: 17.667601
A17: Porcupine complex | B17: 14118.662 | C17: 1264.0852 | D17: 105.60997 | E17: 21.443131 | F17: 45438.64 | G17: MetalliCan | H17: Doré | I17: GRP-0d911886 | J17: 2911000 | K17: 8.251949
A18: Canadian Malartic | B18: 7244.0451 | C18: 412.53314 | D18: 34.465721 | E18: 24.93819 | F18: 17008.885 | G18: MetalliCan | H18: Doré | I18: QC-MAIN-e7e6a960 | J18: 17332900 | K18: 29.039085
A19: Detour Lake | B19: 12873.562 | C19: 269.48591 | D19: 22.514619 | E19: 28.464453 | F19: 10022.146 | G19: MetalliCan | H19: Doré | I19: ON-MAIN-aeafbb59 | J19: 25434854 | K19: 24.008284
A20: Kiena | B20: 3508.1142 | C20: 1772.997 | D20: 148.12777 | E20: 0.080122641 | F20: 2571.6756 | G20: MetalliCan | H20: Doré | I20: QC-MAIN-9de9bb0d | J20: 191148 | K20: 1.2201776
A21: Brucejack | B21: 30316.597 | C21: 0 | D21: 0 | E21: 16.87279 | F21: 0 | G21: MetalliCan | H21: Doré | I21: BC-MAIN-857b7b89 | J21: 166000 | K21: 0.92040969
A22: Eagle River | B22: 4686.7295 | C22: 80.027177 | D22: 6.6859944 | E22: 26.957186 | F22: 403.87229 | G22: MetalliCan | H22: Doré | I22: ON-MAIN-cb85213a | J22: 222627 | K22: 2.7760509
A23: Éléonore | B23: 4936.2421 | C23: 117.58953 | D23: 9.8242 | E23: 200.38252 | F23: 4967.9155 | G23: MetalliCan | H23: Doré | I23: QC-MAIN-6dc537e6 | J23: 1661000 | K23: 7.7388999
A24: Goldex** | B24: 3253.4795 | C24: 188.06306 | D24: 15.712021 | E24: 0.58076733 | F24: 6487.0988 | G24: MetalliCan | H24: Doré | I24: QC-MAIN-c0660aec | J24: 2886927.3 | K24: 4.4745421 | L24: 130.12253
A25: Island | B25: 5423.198 | C25: 0 | D25: 0 | E25: 81.320448 | F25: 0 | G25: MetalliCan | H25: Doré | I25: ON-MAIN-687b8c8d | J25: 439008 | K25: 4.1704081
A26: LaRonde** | B26: 4299.6348 | C26: 299.56737 | D26: 25.02782 | E26: 3.24252 | F26: 3308.2139 | G26: MetalliCan | H26: Doré | I26: QC-MAIN-e51eda66 | J26: 1501500 | K26: 9.8029028 | L26: 23998.078
A27: Macassa | B27: 3852.3189 | C27: 503.83514 | D27: 42.093687 | E27: 18.09707 | F27: 16164.58 | G27: MetalliCan | H27: Doré | I27: ON-MAIN-1f126a43 | J27: 441588 | K27: 7.2533045
A28: Musselwhite | B28: 6764.6195 | C28: 170.84707 | D28: 14.273684 | E28: 35.862084 | F28: 3758.9539 | G28: MetalliCan | H28: Doré | I28: ON-MAIN-fefeaee4 | J28: 1028000 | K28: 5.7128878
A29: Red Lake | B29: 10839.481 | C29: 1080.5616 | D29: 90.277198 | E29: 158.60195 | F29: 27393.255 | G29: MetalliCan | H29: Doré | I29: ON-MAIN-7f050560 | J29: 841000 | K29: 3.5769025
A30: Seabee Gold Operation | B30: 22766 | C30: 264.60179 | D30: 22.106568 | E30: 8.2779469 | F30: 9168.8949 | G30: MetalliCan | H30: Doré | I30: GRP-14bfbb82 | J30: 122000 | K30: 1.2300799
A31: Snow Lake** | B31: 558.90013 | C31: 46.722002 | D31: 3.9034622 | E31: 2.8229756 | F31: 0 | G31: MetalliCan | H31: Doré | I31: GRP-a13779f8 | J31: 2123641 | K31: 32.978787 | L31: 109797.33
A32: Timmins Operation | B32: 26527.922 | C32: 218.57935 | D32: 18.261552 | E32: 10.761357 | F32: 13576.57 | G32: MetalliCan | H32: Doré | I32: GRP-147b3123 | J32: 1574000 | K32: 4.2180155
A33: Westwood-Doyon | B33: 4710.9389 | C33: 1108.1925 | D33: 92.585659 | E33: 6.8694877 | F33: 0 | G33: MetalliCan | H33: Doré | I33: QC-MAIN-02884fb5 | J33: 1034000 | K33: 4.1181669
A34: Nunavik Nickel | B34: 0.37987386 | C34: 0 | D34: 0 | E34: 0.0010766099 | F34: 0 | G34: MetalliCan | H34: Ni concentrate | I34: QC-MAIN-5ce331b8 | J34: 6835294.1 | L34: 363125
A35: Thompson | B35: 0.47876387 | C35: 0.095398757 | D35: 0.0079702376 | E35: 0.0012981366 | F35: 0 | G35: MetalliCan | H35: Ni concentrate | I35: MB-MAIN-e0a6250e | J35: 464705.88 | L35: 49375
A36: Voisey's Bay | B36: 2.0986571 | C36: 0.035732594 | D36: 0.0029853352 | E36: 0.0050079554 | F36: 0 | G36: MetalliCan | H36: Ni concentrate | I36: NL-MAIN-2d8801d6 | J36: 794117.65 | L36: 84375
A37: Raglan | B37: 1.0816849 | C37: 0.010291287 | D37: 0.00085980157 | E37: 0.003092403 | F37: 0 | G37: MetalliCan | H37: Ni concentrate | I37: QC-MAIN-a97821c0 | J37: 1500000 | L37: 151450
A38: Gibraltar** | B38: 3.5162979 | C38: 0.31649161 | D38: 0.026441782 | E38: 0.011281435 | F38: 5.2340647 | G38: MetalliCan | H38: Mo concentrate | I38: BC-MAIN-6b4800fe | J38: 30000000 | L38: 186436.98
A39: Highland Valley** | B39: 2.9768477 | C39: 0.4889172 | D39: 0.040847344 | E39: 0.080633964 | F39: 10.785998 | G39: MetalliCan | H39: Mo concentrate | I39: BC-MAIN-bf503b6b | J39: 17408000 | L39: 343098.04
A40: Kidd Creek** | B40: 0.12354273 | C40: 0.0094915331 | D40: 0.00079298484 | E40: 0.00041450713 | F40: 0 | G40: MetalliCan | H40: Zn concentrate | I40: ON-MAIN-f8313ebd | J40: 1340000 | L40: 152533.33
...

Sheet agf_tech
A1: Commodity | B1: Climate change (kg CO2 eq) | C1: Land occupation biodiversity (m2 arable land eq .yr) | D1: Land transformation biodiversity (m2 arable land eq) | E1: Particulate matter formation (kg PM2.5 eq) | F1: Water scarcity (m3 world-eq) | G1: Source | H1: Reference product | I1: site_id | J1: ore_processed_t | K1: dore_t_mass | L1: conc_t_mass
A2: Copper Mountain | B2: 0.85992031 | C2: 0.087145433 | D2: 0.0007201615 | E2: 0.00049430166 | F2: 1.9164561 | G2: MetalliCan | H2: Cu concentrate | I2: BC-MAIN-599152a0 | J2: 6862152 | L2: 63500
A3: Gibraltar** | B3: 1.0781545 | C3: 0.12497844 | D3: 0.00097344711 | E3: 0.00066684936 | F3: 2.5799597 | G3: MetalliCan | H3: Cu concentrate | I3: BC-MAIN-6b4800fe | J3: 30000000 | L3: 186436.98
A4: Highland Valley** | B4: 0.41776713 | C4: 0.040115926 | D4: 0.00033246674 | E4: 0.00023963781 | F4: 0.88034523 | G4: MetalliCan | H4: Cu concentrate | I4: BC-MAIN-bf503b6b | J4: 17408000 | L4: 343098.04
A5: Mount Milligan | B5: 1.0719952 | C5: 0.16456886 | D5: 0.0013621089 | E5: 0.0007236169 | F5: 1.2833586 | G5: MetalliCan | H5: Cu concentrate | I5: BC-MAIN-ed23117f | J5: 21680000 | L5: 93533.694
A6: Mount Polley | B6: 0.92808668 | C6: 0.1020588 | D6: 0.00083910859 | E6: 0.00055314152 | F6: 1.8615331 | G6: MetalliCan | H6: Cu concentrate | I6: BC-MAIN-3f490561 | J6: 5948239 | L6: 45578.436
A7: Goldex** | B7: 1.9395272 | C7: 0.2887451 | D7: 0.00073639238 | E7: 0.0012783446 | F7: 4.5010951 | G7: MetalliCan | H7: Cu concentrate | I7: QC-MAIN-c0660aec | J7: 2886927.3 | K7: 4.4745421 | L7: 130.12253
A8: Kidd Creek | B8: 0.085043738 | C8: 0.00825818 | D8: 6.6243837e-05 | E8: 4.9523456e-05 | F8: 0.020143102 | G8: MetalliCan | H8: Cu concentrate | I8: ON-MAIN-f8313ebd | J8: 1340000 | L8: 152533.33
A9: LaRonde** | B9: 0.61809756 | C9: 0.22429968 | D9: 0.00027167638 | E9: 0.00033092838 | F9: 4.1259525 | G9: MetalliCan | H9: Cu concentrate | I9: QC-MAIN-e51eda66 | J9: 1501500 | K9: 9.8029028 | L9: 23998.078
A10: New Afton | B10: 0.35529687 | C10: 0.033552439 | D10: 0.00026440781 | E10: 0.00017089721 | F10: 0.68686792 | G10: MetalliCan | H10: Cu concentrate | I10: BC-MAIN-aa76f6f2 | J10: 3065000 | L10: 71667.536
A11: Snow Lake** | B11: 1.691844 | C11: 0.14953973 | D11: 0.00016233374 | E11: 0.00092367046 | F11: 14.499711 | G11: MetalliCan | H11: Cu concentrate | I11: GRP-a13779f8 | J11: 2123641 | K11: 32.978787 | L11: 109797.33
A12: Casa Berardi | B12: 8167.7135 | C12: 1872.5478 | D12: 4.0587089 | E12: 3.764782 | F12: 31009.565 | G12: MetalliCan | H12: Doré | I12: QC-MAIN-b86f7d07 | J12: 1361450 | K12: 3.5165998
A13: Hemlo | B13: 6650.5693 | C13: 364.13229 | D13: 2.4546056 | E13: 3.8677368 | F13: 20121.242 | G13: MetalliCan | H13: Doré | I13: ON-MAIN-6e9be24e | J13: 1266009 | K13: 4.4765236
A14: Meliadine | B14: 4996.0386 | C14: 191.5246 | D14: 1.2238942 | E14: 3.3011356 | F14: 1600.6653 | G14: MetalliCan | H14: Doré | I14: NU-MAIN-8b0264c9 | J14: 1918143 | K14: 12.414137
A15: Rainy River | B15: 36081.211 | C15: 1836.7741 | D15: 10.718665 | E15: 17.577837 | F15: 119973.41 | G15: MetalliCan | H15: Doré | I15: ON-MAIN-0aadf28f | J15: 8764000 | K15: 8.0534261
A16: Meadowbank complex | B16: 12897.838 | C16: 339.81656 | D16: 3.6179634 | E16: 7.0291055 | F16: 2983.0056 | G16: MetalliCan | H16: Doré | I16: GRP-0a2c0d69 | J16: 3842649 | K16: 17.667601
A17: Porcupine complex | B17: 8920.3029 | C17: 474.98086 | D17: 3.3687127 | E17: 4.0133442 | F17: 28581.884 | G17: MetalliCan | H17: Doré | I17: GRP-0d911886 | J17: 2911000 | K17: 8.251949
A18: Canadian Malartic | B18: 10085.736 | C18: 1421.3779 | D18: 4.9656427 | E18: 7.1841029 | F18: 20006.031 | G18: MetalliCan | H18: Doré | I18: QC-MAIN-e7e6a960 | J18: 17332900 | K18: 29.039085
A19: Detour Lake | B19: 21464.962 | C19: 1193.2665 | D19: 8.7216258 | E19: 14.200751 | F19: 43665.509 | G19: MetalliCan | H19: Doré | I19: ON-MAIN-aeafbb59 | J19: 25434854 | K19: 24.008284
A20: Kiena | B20: 5761.104 | C20: 1210.3407 | D20: 2.1741007 | E20: 2.9132548 | F20: 21170.596 | G20: MetalliCan | H20: Doré | I20: QC-MAIN-9de9bb0d | J20: 191148 | K20: 1.2201776
A21: Brucejack | B21: 26446.963 | C21: 1206.5379 | D21: 6.2809208 | E21: 12.263685 | F21: 163387.78 | G21: MetalliCan | H21: Doré | I21: BC-MAIN-857b7b89 | J21: 166000 | K21: 0.92040969
A22: Eagle River | B22: 6564.7934 | C22: 252.92223 | D22: 1.4320949 | E22: 3.1191358 | F22: 19003.165 | G22: MetalliCan | H22: Doré | I22: ON-MAIN-cb85213a | J22: 222627 | K22: 2.7760509
A23: Éléonore | B23: 8943.6927 | C23: 1474.1239 | D23: 2.7525317 | E23: 4.3015119 | F23: 25452.321 | G23: MetalliCan | H23: Doré | I23: QC-MAIN-6dc537e6 | J23: 1661000 | K23: 7.7388999
A24: Goldex** | B24: 14558.579 | C24: 2167.3934 | D24: 5.5275466 | E24: 9.595576 | F24: 33786.352 | G24: MetalliCan | H24: Doré | I24: QC-MAIN-c0660aec | J24: 2886927.3 | K24: 4.4745421 | L24: 130.12253
A25: Island | B25: 4486.139 | C25: 247.54541 | D25: 1.4689456 | E25: 1.7024557 | F25: 25240.142 | G25: MetalliCan | H25: Doré | I25: ON-MAIN-687b8c8d | J25: 439008 | K25: 4.1704081
A26: LaRonde** | B26: 4639.5956 | C26: 1683.6497 | D26: 2.0392712 | E26: 2.4840316 | F26: 30970.436 | G26: MetalliCan | H26: Doré | I26: QC-MAIN-e51eda66 | J26: 1501500 | K26: 9.8029028 | L26: 23998.078
A27: Macassa | B27: 28400.159 | C27: 695.92888 | D27: 3.0465567 | E27: 16.281082 | F27: 21464.295 | G27: MetalliCan | H27: Doré | I27: ON-MAIN-1f126a43 | J27: 441588 | K27: 7.2533045
A28: Musselwhite | B28: 7604.6131 | C28: 348.44748 | D28: 2.2102193 | E28: 3.1865819 | F28: 28610.796 | G28: MetalliCan | H28: Doré | I28: ON-MAIN-fefeaee4 | J28: 1028000 | K28: 5.7128878
A29: Red Lake | B29: 7360.3866 | C29: 375.33133 | D29: 2.5769847 | E29: 3.8299991 | F29: 27256.835 | G29: MetalliCan | H29: Doré | I29: ON-MAIN-7f050560 | J29: 841000 | K29: 3.5769025
A30: Seabee Gold Operation | B30: 38928.88 | C30: 234.92679 | D30: 3.0271241 | E30: 7.969409 | F30: 9955.1606 | G30: MetalliCan | H30: Doré | I30: GRP-14bfbb82 | J30: 122000 | K30: 1.2300799
A31: Snow Lake** | B31: 12699.407 | C31: 1122.4828 | D31: 1.2185179 | E31: 6.9333026 | F31: 108838.48 | G31: MetalliCan | H31: Doré | I31: GRP-a13779f8 | J31: 2123641 | K31: 32.978787 | L31: 109797.33
A32: Timmins Operation | B32: 14981.868 | C32: 702.54906 | D32: 4.9013626 | E32: 7.2619532 | F32: 56392.788 | G32: MetalliCan | H32: Doré | I32: GRP-147b3123 | J32: 1574000 | K32: 4.2180155
A33: Westwood-Doyon | B33: 9341.859 | C33: 1682.7815 | D33: 3.0648986 | E33: 5.2740958 | F33: 29170.903 | G33: MetalliCan | H33: Doré | I33: QC-MAIN-02884fb5 | J33: 1034000 | K33: 4.1181669
A34: Nunavik Nickel | B34: 0.81931191 | C34: 0.063424323 | D34: 0.00021629282 | E34: 0.00062107489 | F34: 0.9784261 | G34: MetalliCan | H34: Ni concentrate | I34: QC-MAIN-5ce331b8 | J34: 6835294.1 | L34: 363125
A35: Thompson | B35: 0.59954987 | C35: 0.026840716 | D35: 0.00012295662 | E35: 0.00040502115 | F35: 1.5852044 | G35: MetalliCan | H35: Ni concentrate | I35: MB-MAIN-e0a6250e | J35: 464705.88 | L35: 49375
A36: Voisey's Bay | B36: 1.2495929 | C36: 0.072063773 | D36: 0.00025697159 | E36: 0.00055983151 | F36: 6.1928987 | G36: MetalliCan | H36: Ni concentrate | I36: NL-MAIN-2d8801d6 | J36: 794117.65 | L36: 84375
A37: Raglan | B37: 0.69991331 | C37: 0.13070139 | D37: 0.00023817715 | E37: 0.00041865435 | F37: 2.3870205 | G37: MetalliCan | H37: Ni concentrate | I37: QC-MAIN-a97821c0 | J37: 1500000 | L37: 151450
A38: Gibraltar** | B38: 4.568875 | C38: 0.52961878 | D38: 0.0041251585 | E38: 0.0028258949 | F38: 10.933047 | G38: MetalliCan | H38: Mo concentrate | I38: BC-MAIN-6b4800fe | J38: 30000000 | L38: 186436.98
A39: Highland Valley** | B39: 1.7703639 | C39: 0.1699985 | D39: 0.001408888 | E39: 0.0010155086 | F39: 3.7306223 | G39: MetalliCan | H39: Mo concentrate | I39: BC-MAIN-bf503b6b | J39: 17408000 | L39: 343098.04
A40: Kidd Creek** | B40: 0.031790515 | C40: 0.0030870209 | D40: 2.4762854e-05 | E40: 1.8512547e-05 | F40: 0.0075297675 | G40: MetalliCan | H40: Zn concentrate | I40: ON-MAIN-f8313ebd | J40: 1340000 | L40: 152533.33
...

Sheet agf_bio
A1: Commodity | B1: Climate change (kg CO2 eq) | C1: Land occupation biodiversity (m2 arable land eq .yr) | D1: Land transformation biodiversity (m2 arable land eq) | E1: Particulate matter formation (kg PM2.5 eq) | F1: Water scarcity (m3 world-eq) | G1: Source | H1: Reference product | I1: site_id | J1: ore_processed_t | K1: dore_t_mass | L1: conc_t_mass
A2: Copper Mountain | B2: 1.332982 | C2: 0.13119695 | D2: 0.010961052 | E2: 0.031884872 | F2: 0 | G2: MetalliCan | H2: Cu concentrate | I2: BC-MAIN-599152a0 | J2: 6862152 | L2: 63500
A3: Gibraltar** | B3: 0.82976936 | C3: 0.074685089 | D3: 0.0062396818 | E3: 0.0026621719 | F3: 1.2351247 | G3: MetalliCan | H3: Cu concentrate | I3: BC-MAIN-6b4800fe | J3: 30000000 | L3: 186436.98
A4: Highland Valley** | B4: 0.70247092 | C4: 0.11537376 | D4: 0.0096390789 | E4: 0.019027851 | F4: 2.5452594 | G4: MetalliCan | H4: Cu concentrate | I4: BC-MAIN-bf503b6b | J4: 17408000 | L4: 343098.04
A5: Mount Milligan | B5: 0.87661813 | C5: 0.084853263 | D5: 0.0070891974 | E5: 0.00020433363 | F5: 3.7206059 | G5: MetalliCan | H5: Cu concentrate | I5: BC-MAIN-ed23117f | J5: 21680000 | L5: 93533.694
A6: Mount Polley | B6: 1.3048362 | C6: 0.11005584 | D6: 0.0091947863 | E6: 0.01236277 | F6: 0 | G6: MetalliCan | H6: Cu concentrate | I6: BC-MAIN-3f490561 | J6: 5948239 | L6: 45578.436
A7: Goldex** | B7: 0.43343599 | C7: 0.025054193 | D7: 0.0020931913 | E7: 7.7371151e-05 | F7: 0.86422611 | G7: MetalliCan | H7: Cu concentrate | I7: QC-MAIN-c0660aec | J7: 2886927.3 | K7: 4.4745421 | L7: 130.12253
A8: Kidd Creek | B8: 0.3304928 | C8: 0.025391079 | D8: 0.002121337 | E8: 0.0011088603 | F8: 0 | G8: MetalliCan | H8: Cu concentrate | I8: ON-MAIN-f8313ebd | J8: 1340000 | L8: 152533.33
A9: LaRonde** | B9: 0.5728072 | C9: 0.039909053 | D9: 0.0033342636 | E9: 0.00043197593 | F9: 0.4407278 | G9: MetalliCan | H9: Cu concentrate | I9: QC-MAIN-e51eda66 | J9: 1501500 | K9: 9.8029028 | L9: 23998.078
A10: New Afton | B10: 0.24730121 | C10: 0.043486584 | D10: 0.0036331543 | E10: 0.00037646055 | F10: 1.6583858 | G10: MetalliCan | H10: Cu concentrate | I10: BC-MAIN-aa76f6f2 | J10: 3065000 | L10: 71667.536
A11: Snow Lake** | B11: 0.074457954 | C11: 0.0062244122 | D11: 0.00052002816 | E11: 0.00037608328 | F11: 0 | G11: MetalliCan | H11: Cu concentrate | I11: GRP-a13779f8 | J11: 2123641 | K11: 32.978787 | L11: 109797.33
A12: Casa Berardi | B12: 10496.437 | C12: 1110.4624 | D12: 92.775305 | E12: 0.76920897 | F12: 0 | G12: MetalliCan | H12: Doré | I12: QC-MAIN-b86f7d07 | J12: 1361450 | K12: 3.5165998
A13: Hemlo | B13: 6303.7826 | C13: 492.65204 | D13: 41.15938 | E13: 4.3536159 | F13: 338.46908 | G13: MetalliCan | H13: Doré | I13: ON-MAIN-6e9be24e | J13: 1266009 | K13: 4.4765236
A14: Meliadine | B14: 11492.476 | C14: 0 | D14: 0 | E14: 33.05498 | F14: 1400.0758 | G14: MetalliCan | H14: Doré | I14: NU-MAIN-8b0264c9 | J14: 1918143 | K14: 12.414137
A15: Rainy River | B15: 18111.744 | C15: 1781.5196 | D15: 148.83982 | E15: 30.392671 | F15: 30057.033 | G15: MetalliCan | H15: Doré | I15: ON-MAIN-0aadf28f | J15: 8764000 | K15: 8.0534261
