Workbook

Sheet README
A1: Title of the article | B1: Supplementary Information for ''
A2: Authors | B2: Marin Pellan, Guillaume Majeau-Bettez, Titouan Greffe, Anne de Bortoli
A3: Affiliations
A4: Contact | B4: marin.pellan@polymlt.ca; pellan.marin@gmail.com

Sheet Sources
A1: IMPORTED_FROM | B1: MINERAL | C1: SOURCE | D1: NAME | E1: REFERENCE_PRODUCT | F1: LOCATION | G1: SYSTEM_BOUNDARY | H1: ALLOCATION | I1: UNIT | J1: TIME PERIOD | K1: COMMENT | L1: DESCRIPTION | M1: Technology
A2: Istrate et al (2024) | B2: Cobalt | C2: Arvidsson et al (2022), originally from Dai et al (2018) | D2: cobalt hydroxide, hydrometallurigcal procesing of copper-cobalt ore, economic allocation | E2: cobalt hydroxide | F2: CD | G2: Mining and processing | H2: Economic | I2: kilogram | L2: Cobalt hydroxide from hydrometallurgical ore processing, in the Democratic Republic of the Congo. Adapted in Arvidsson, R., Chordia, M. & NordelÃ¶f, A. Quantifying the life-cycle health impacts of a cobalt-containing lithium-ion battery. Int J Life Cycle Assess (2022). https://doi.org/10.1007/s11367-022-02084-3, originally from Cobalt Life Cycle Analysis Update for the GREET Model, Dai et al. 2018. Economic allocation between copper (7,300 USD/ton) and the cobalt content in the crude cobalt hydroxide (43,000 USD/ton). Pedigree scores assessed in this study; see "Pedigree scores" sheet
A3: Istrate et al (2024) | B3: Cobalt | C3: Arvidsson et al (2022), originally from Dai et al (2018) | D3: cobalt sulfate production, from copper-cobalt ore, economic allocation | E3: cobalt sulfate | F3: CN | G3: Mining and processing (one additional step compared to cobalt hydroxide) | H3: Economic | I3: kilogram | L3: Cobalt sulfate production, in China, from cobalt hydroxide. Adapted in Arvidsson, R., Chordia, M. & NordelÃ¶f, A. Quantifying the life-cycle health impacts of a cobalt-containing lithium-ion battery. Int J Life Cycle Assess (2022). https://doi.org/10.1007/s11367-022-02084-3, originally from Cobalt Life Cycle Analysis Update for the GREET Model, Dai et al. 2018.
A4: Istrate et al (2024) | B4: Cobalt | D4: copper-cobalt mining, industrial | E4: copper-cobalt ore | F4: CD | G4: Mining | I4: kilogram | L4: Copper-cobalt industrial mining, in the Democratic Republic of the Congo. The only technosphere input is diesel for the caterpillar. Adapted in Arvidsson, R., Chordia, M. & NordelÃ¶f, A. Quantifying the life-cycle health impacts of a cobalt-containing lithium-ion battery. Int J Life Cycle Assess (2022). https://doi.org/10.1007/s11367-022-02084-3 from Cobalt Life Cycle Analysis Update for the GREET Model, Dai et al. 2018. Pedigree scores assessed in this study; see "Pedigree scores" sheet
A5: premise | B5: Cobalt | D5: disodium disulphite | E5: disodium disulphite | F5: GLO | I5: kilogram
A6: premise | B6: Cobalt | D6: cobalt sulfate production, from copper mining, economic allocation | E6: cobalt sulfate | F6: CN | I6: kilogram
A7: premise | B7: Cobalt | D7: cobalt sulfate production, from copper mining, mass allocation | E7: cobalt sulfate | F7: CN | I7: kilogram
A8: premise | B8: Cobalt | C8: Arvidsson et al (2022), originally from Dai et al (2018) | D8: copper-cobalt mining, industrial, mass allocation | E8: copper-cobalt ore | F8: CD | I8: kilogram | L8: Copper-cobalt industrial mining, in the Democratic Republic of the Congo. The only technosphere input is diesel for the caterpillar. Adapted in Arvidsson, R., Chordia, M. & NordelÃ¶f, A. Quantifying the life-cycle health impacts of a cobalt-containing lithium-ion battery. Int J Life Cycle Assess (2022). https://doi.org/10.1007/s11367-022-02084-3 from Cobalt Life Cycle Analysis Update for the GREET Model, Dai et al. 2018.
A9: premise | B9: Cobalt | C9: Arvidsson et al (2022), originally from Dai et al (2018) | D9: cobalt hydroxide, via hydrometallurigcal ore procesing, mass allocation | E9: cobalt hydroxide | F9: CD | I9: kilogram | L9: Cobalt hydroxide from hydrometallurgical ore processing, in the Democratic Republic of the Congo. The cobalt-copper ore comes 20% from artisanal mines, 80% from industrial mines. Adapted in Arvidsson, R., Chordia, M. & NordelÃ¶f, A. Quantifying the life-cycle health impacts of a cobalt-containing lithium-ion battery. Int J Life Cycle Assess (2022). https://doi.org/10.1007/s11367-022-02084-3, originally from Cobalt Life Cycle Analysis Update for the GREET Model, Dai et al. 2018. Economic\nallocation between copper (7,300 USD/ton) and the cobalt content in the crude cobalt hydroxide\n(43,000 USD/ton).
A10: premise | B10: Cobalt | C10: Arvidsson et al (2022), originally from Dai et al (2018) | D10: copper-cobalt mining, industrial, economic allocation | E10: copper-cobalt ore | F10: CD | I10: kilogram | L10: Copper-cobalt industrial mining, in the Democratic Republic of the Congo. The only technosphere input is diesel for the caterpillar. Adapted in Arvidsson, R., Chordia, M. & NordelÃ¶f, A. Quantifying the life-cycle health impacts of a cobalt-containing lithium-ion battery. Int J Life Cycle Assess (2022). https://doi.org/10.1007/s11367-022-02084-3 from Cobalt Life Cycle Analysis Update for the GREET Model, Dai et al. 2018.
A11: premise | B11: Cobalt | C11: Arvidsson et al (2022), originally from Dai et al (2018) | D11: copper-cobalt mining, artisanal | E11: copper-cobalt ore | F11: CD | I11: kilogram | L11: Copper-cobalt artisanal mining, in the Democratic Republic of the Congo. It does not have any inputs from the technosphere. Arvidsson, R., Chordia, M. & NordelÃ¶f, A. Quantifying the life-cycle health impacts of a cobalt-containing lithium-ion battery. Int J Life Cycle Assess (2022). https://doi.org/10.1007/s11367-022-02084-3. Originally from Cobalt Life Cycle Analysis Update for the GREET Model, Dai et al. 2018.
A12: premise | B12: Cobalt | C12: Arvidsson et al (2022), originally from Dai et al (2018) | D12: cobalt hydroxide, via hydrometallurigcal ore procesing, economic allocation | E12: cobalt hydroxide | F12: CD | I12: kilogram | L12: Cobalt hydroxide from hydrometallurgical ore processing, in the Democratic Republic of the Congo. The cobalt-copper ore comes 20% from artisanal mines, 80% from industrial mines. Adapted in Arvidsson, R., Chordia, M. & NordelÃ¶f, A. Quantifying the life-cycle health impacts of a cobalt-containing lithium-ion battery. Int J Life Cycle Assess (2022). https://doi.org/10.1007/s11367-022-02084-3, originally from Cobalt Life Cycle Analysis Update for the GREET Model, Dai et al. 2018. Economic\nallocation between copper (7,300 USD/ton) and the cobalt content in the crude cobalt hydroxide (43,000 USD/ton).
A13: premise | B13: Cobalt | C13: Dai et al (2018) | D13: cobalt metal production, from copper mining, via electrolysis, economic allocation | E13: cobalt | F13: CN | I13: kilogram | L13: Cobalt metal refining in China, via electrolysis, from cobalt sulfate, from Dai et al., 2018. Refined metallic cobalt is produced from electrolysis of CoSO4 or CoCl2 solutions in\nelectrowinning cells (Donaldson 2005). The estimated electricity requirements for metallic\ncobalt production via electrowinning range from 5,000 kWh to 6,500 kWh per t of cobalt metal\nproduced for plants based in Zambia and the DRC, and range from 3,100 kWh to 3,700 kWh per\nt of cobalt metal produced for plants based in the rest of the world (Bleiwas 2011).
A14: premise | B14: Cobalt | C14: Dai et al (2018) | D14: cobalt metal production, from copper mining, via electrolysis, mass allocation | E14: cobalt | F14: CN | I14: kilogram | L14: Cobalt metal refining in China, via electrolysis, from cobalt sulfate, from Dai et al., 2018. Refined metallic cobalt is produced from electrolysis of CoSO4 or CoCl2 solutions in\nelectrowinning cells (Donaldson 2005). The estimated electricity requirements for metallic\ncobalt production via electrowinning range from 5,000 kWh to 6,500 kWh per t of cobalt metal\nproduced for plants based in Zambia and the DRC, and range from 3,100 kWh to 3,700 kWh per\nt of cobalt metal produced for plants based in the rest of the world (Bleiwas 2011).
A15: PDF | B15: Copper | C15: GREET model (2022), mainly from Sanjuan-Delmás et al (2022) | D15: copper production from sulfide ore | E15: copper | G15: Mining, beneficiation, primary extraction, refining | H15: Not mentionned | I15: kilogram | K15: Ore grade energy relationship | L15: https://publications.anl.gov/anlpubs/2022/12/178670.pdf
A16: EI | B16: Copper (molybdenite) | C16: Ecoinvent. Orinally Classen et al (2009) and updated in Turner & Hischier (2020). Average ore grade per regions from Northey et al (2014) | D16: Copper mine operation and beneficiation, sulfide ore | E16: copper concentrate, sulfide ore | F16: CA | G16: Mining and beneficiation | H16: Unallocated | I16: kilogram | J16: 2009, 2020 OG update | K16: Concentrate | L16: All exchanges to the environment and from the technosphere calculated using the life cycle inventory model presented in Classen et al. (2009) for "copper, molybdenum & telluride and silver containing byproducts" (ecoinvent v.2.1). All exchange values are calculated as a function of the mass of ore processed, which is itself a function of ore grade. To increase the temporal and geographical representativeness of the inventory, ore grades have been updated here (since v2.1) based on data from Northey et al. (2014). The estimated average copper ore grade in Canada is 0.31%. The amounts and composition (exchange properties) of "copper concentrate, sulfide ore", "molybdenute concentrate" and "treatment of sulfidic tailings, from copper mine operation, tailings impoundment" were estimated based on a global material flow analysis of copper production. Key input data to the model include: production volumes of each metal, taken from the USGS Minerals Yearbook 2015; concentration yields (i.e. transfer coefficients for each element from Earth"s crust to each product via mining and beneficiation), taken as the arithmetic mean of values reported in the literature; anode slime composition, from which the amounts of silver, gold, tellerium and selenium that are extracted from the Earth"s crust during this activity are estimated, taken as the arithmetic mean of values reported in the literature; "copper concentrate,sulfide ore" grade (26.7% Cu), taken from Delbeke & Rodriguez (2014); "molybdenite concentrate" composition, taken as the arithmetic mean of values reported in the literature (48% Mo; 3.5% Cu). | M16: Based on typical current technology. Mining is done 70% open pit and 30% underground, followed by joint beneficiation of copper and molybdenite trough flotation, where considerable amounts of agents are added. Overburden is disposed separate to sulfidic tailings near the mining site. No dewatering (or other pre-treatment) of the tailings of is assumed as this is considered a treatment activity that occurs only at selective sites and is therefore modelled separately.
A17: EI | B17: Gold-silver ingot (copper concentrate sulfide ore, zinc concentrate, lead concentrate) | C17: Ecoinvent | D17: Gold-silver mine operation and beneficiation | E17: gold-silver, ingot | F17: CA-QC | G17: Mining and beneficiation, first refining of gold | H17: Unallocated | I17: kilogram | J17: 2012 | K17: Ingots, concentrate | L17: Inputs and outputs relate to Quebec production. The dataset represents the activity in 2012 | M17: The ore is mined in an underground mine and transported by trucks to the mill for further processing. The ore is then fed into a series of grinding mills where steel balls grind the ore. Then follows the steps of flotation of copper and zinc, concentrate handling, cyanide destruction and backfilling of the tailings, refining of gold by electro-winning and melting in furnace to produce the gold and silver ingots. 20% of the tailings produce are sent underground to be used as backfill; sulfidic tailing is managed on site in tailings ponds.
A18: Istrate et al (2024) | B18: Graphite | C18: Engels et al (2022) | D18: graphite ore mining | E18: graphite ore, mined | F18: CN | G18: Mining | I18: kilogram | K18: Concentrate containing 66.15% Fe (dry basis), produced at 4% humidity | L18: Graphite ore mining. Diesel additive to ammonium nitrate is not used, as "market for explosive" is available instead. Source: Engels P, Cerdas F, Dettmer T, Frey C, Hentschel J, Herrmann C, et al. Life cycle assessment of natural graphite production for lithium-ion battery anodes based on industrial primary data. J Clean Prod 2022;336:130474. https://doi.org/10.1016/J.JCLEPRO.2022.130474.
A19: Istrate et al (2024) | B19: Graphite | D19: natural graphite spheronization | E19: natural graphite, spherical | F19: CN | I19: kilogram | L19: None
A20: Istrate et al (2024) | B20: Graphite | C20: Carrere et al (2024) | D20: calcined coke milling | E20: calcined coke powder | F20: CN | G20: ? | H20: No allocation | I20: kilogram | L20: "Milling of the calcined coke particles into smaller size particles at a mm scale. This process is performed using milling technologies (typically classifier mills) powered by electricity." The process has an overall efficiency of 80%, with 20% being a by-product of coke fines which however have a negligible economic value. Therefore, no allocation was conisdered. Source: CarrÃ¨re, T., Khalid, U., Baumann, M., Bouzidi, M., and Allard, B. (2024). Carbon footprint assessment of manufacturing of synthetic graphite battery anode material for electric mobility applications. Journal of Energy Storage 94, 112356. https://doi.org/10.1016/j.est.2024.112356. Pedigree scores assessed in this study; see "Pedigree scores" sheet
A21: Istrate et al (2024) | B21: Graphite | C21: Carrere et al (2024) | D21: graphite powder coating | E21: synthetic graphite, battery grade | F21: CN | G21: Mining and processing, transport? | I21: kilogram | L21: Including unit processes coating (kneading and thermal treatment) and packaging. Source: CarrÃ¨re, T., Khalid, U., Baumann, M., Bouzidi, M., and Allard, B. (2024). Carbon footprint assessment of manufacturing of synthetic graphite battery anode material for electric mobility applications. Journal of Energy Storage 94, 112356. https://doi.org/10.1016/j.est.2024.112356. Pedigree scores assessed in this study; see "Pedigree scores" sheet
A22: Istrate et al (2024) | B22: Graphite | C22: Carrere et al (2024) | D22: graphitization of calcined coke powder | E22: graphite powder | F22: CN | G22: ? | I22: kilogram | L22: Graphitization of calcined coke powder using an Acheson electrical furnace. No allocation has been considered, which however have a negligible impact on the final results. Source: CarrÃ¨re, T., Khalid, U., Baumann, M., Bouzidi, M., and Allard, B. (2024). Carbon footprint assessment of manufacturing of synthetic graphite battery anode material for electric mobility applications. Journal of Energy Storage 94, 112356. https://doi.org/10.1016/j.est.2024.112356. Pedigree scores assessed in this study; see "Pedigree scores" sheet
A23: Istrate et al (2024) | B23: Graphite | C23: Carrere et al (2024) | D23: micronization of graphite powder | E23: micronized graphite powder | F23: CN | I23: kilogram | L23: "Graphite powder is reduced to its final size suitable for battery anode application (around 10â€“20 Î¼m) in the subsequent process called micronizing using multiple classifier mills". The process has an overall efficiency of 60%, with 40% being a by-product of graphite fines which however have a negligible economic value. Therefore, no allocation was conisdered.Source: CarrÃ¨re, T., Khalid, U., Baumann, M., Bouzidi, M., and Allard, B. (2024). Carbon footprint assessment of manufacturing of synthetic graphite battery anode material for electric mobility applications. Journal of Energy Storage 94, 112356. https://doi.org/10.1016/j.est.2024.112356. Pedigree scores assessed in this study; see "Pedigree scores" sheet
A24: Istrate et al (2024) | B24: Graphite | C24: Engels et al (2022) | D24: natural graphite concentration | E24: graphite ore, concentrated | F24: CN | I24: kilogram | L24: Floation process for natural graphite. Missing input for pine oil, used as floation reagent. Missing ceramic grinding media. Source: Engels P, Cerdas F, Dettmer T, Frey C, Hentschel J, Herrmann C, et al. Life cycle assessment of natural graphite production for lithium-ion battery anodes based on industrial primary data. J Clean Prod 2022;336:130474. https://doi.org/10.1016/J.JCLEPRO.2022.130474.
A25: Istrate et al (2024) | B25: Graphite | C25: Engels et al (2022) | D25: natural graphite production, battery grade, from Heilongjiang | E25: natural graphite, battery grade | F25: CN | I25: kilogram | L25: Purified natural graphite. Source: Engels P, Cerdas F, Dettmer T, Frey C, Hentschel J, Herrmann C, et al. Life cycle assessment of natural graphite production for lithium-ion battery anodes based on industrial primary data. J Clean Prod 2022;336:130474. https://doi.org/10.1016/J.JCLEPRO.2022.130474.
A26: Istrate et al (2024) | B26: Graphite | C26: Engels et al (2022) | D26: natural graphite purification | E26: natural graphite, purified | F26: CN | I26: kilogram | L26: Engels P, Cerdas F, Dettmer T, Frey C, Hentschel J, Herrmann C, et al. Life cycle assessment of natural graphite production for lithium-ion battery anodes based on industrial primary data. J Clean Prod 2022;336:130474. https://doi.org/10.1016/J.JCLEPRO.2022.130474.
A27: Istrate et al (2024) | B27: Graphite | D27: calcined petroleum coke production | E27: calcined petroleum coke | F27: CN | I27: kilogram | L27: LCI dataset for a 500,000 tonnes/year coke calciner operated by Rain Carbon in India. The plant consists of two rotary kilns, waste heat recovery system and a flue gas treatment system. Electricity for plant operation is provided internally through the waste heat recovery boiler; surplus electricity might be exported to the grid, but here it is assumed that this surplus is not used (no allocation). Source: Edwards, L., Hunt, M., Verma, P., Weyell, P. & Koop, J. Sustainable CPC Production at the Vizag Calciner. in Proceedings of the 38th International ICSOBA Conference (2020). https://raincarbon.com/Upload/PDF/2020-icsoba-sustainable-cpc-production-at-the-vizag-calciner.pdf. Pedigree scores assessed in this study; see "Pedigree scores" sheet
A28: premise | B28: Graphite | C28: Engels et al (2022) | D28: graphite purification | E28: graphite, purified | F28: CN | I28: kilogram | L28: Purification process for natural graphite. Source: Engels P, Cerdas F, Dettmer T, Frey C, Hentschel J, Herrmann C, et al. Life cycle assessment of natural graphite production for lithium-ion battery anodes based on industrial primary data. J Clean Prod 2022;336:130474. https://doi.org/10.1016/J.JCLEPRO.2022.130474.
A29: premise | B29: Graphite | C29: Engels et al (2022) | D29: graphite ore mining | E29: graphite ore, mined | F29: CN | I29: kilogram | L29: Graphite ore mining. Diesel additive to ammonium nitrate is not used, as "market for explosive" is available instead. Source: Engels P, Cerdas F, Dettmer T, Frey C, Hentschel J, Herrmann C, et al. Life cycle assessment of natural graphite production for lithium-ion battery anodes based on industrial primary data. J Clean Prod 2022;336:130474. https://doi.org/10.1016/J.JCLEPRO.2022.130474.
A30: premise | B30: Graphite | C30: Engels et al (2022) | D30: natural graphite spheronization | E30: graphite, spherical | F30: CN | I30: kilogram | L30: Purification process for natural graphite. Source: Engels P, Cerdas F, Dettmer T, Frey C, Hentschel J, Herrmann C, et al. Life cycle assessment of natural graphite production for lithium-ion battery anodes based on industrial primary data. J Clean Prod 2022;336:130474. https://doi.org/10.1016/J.JCLEPRO.2022.130474.
A31: premise | B31: Graphite | C31: Engels et al (2022) | D31: natural graphite production, coated | E31: natural graphite, coated | F31: CN | I31: kilogram | L31: Purified natural graphite. Source: Engels P, Cerdas F, Dettmer T, Frey C, Hentschel J, Herrmann C, et al. Life cycle assessment of natural graphite production for lithium-ion battery anodes based on industrial primary data. J Clean Prod 2022;336:130474. https://doi.org/10.1016/J.JCLEPRO.2022.130474.
A32: premise | B32: Graphite | C32: Engels et al (2022) | D32: natural graphite concentration | E32: graphite ore, concentrated | F32: CN | I32: kilogram | L32: Floation process for natural graphite. Missing input for pine oil, used as floation reagent. Missing ceramic grinding media. Source: Engels P, Cerdas F, Dettmer T, Frey C, Hentschel J, Herrmann C, et al. Life cycle assessment of natural graphite production for lithium-ion battery anodes based on industrial primary data. J Clean Prod 2022;336:130474. https://doi.org/10.1016/J.JCLEPRO.2022.130474.
A33: premise | B33: Graphite | C33: Surovtseva et al (2022) | D33: needle coke production | E33: needle coke | F33: CN | I33: kilogram | L33: Surovtseva, D, Crossin, E, Pell, R, Stamford, L. Toward a life cycle inventory for graphite production. J Ind Ecol. 2022; 26: 964â€“ 979. https://doi.org/10.1111/jiec.13234. Green coke is further calcined to produce needle coke, and in this work composition of calcined coke was calculated based on compositions of green coke and volatiles. Relevant dataset covers operation of calcination unit / plant.
A34: premise | B34: Graphite | C34: Surovtseva et al (2022) | D34: market for graphite, battery grade | E34: graphite, battery grade | F34: CN | I34: kilogram | L34: 20-80% natural graphite. Share based on Surovtseva, D, Crossin, E, Pell, R, Stamford, L. Toward a life cycle inventory for graphite production. J Ind Ecol. 2022; 26: 964â€“ 979. https://doi.org/10.1111/jiec.13234
A35: premise | B35: Graphite | C35: Surovtseva et al (2022) | D35: crude oil extraction | E35: crude oil | F35: CN | I35: kilogram | L35: Surovtseva, D, Crossin, E, Pell, R, Stamford, L. Toward a life cycle inventory for graphite production. J Ind Ecol. 2022; 26: 964â€“ 979. https://doi.org/10.1111/jiec.13234
A36: premise | B36: Graphite | C36: Surovtseva et al (2022) | D36: coal coking, for coal tar pitch production | E36: tar pitch | F36: CN | I36: kilogram | L36: Surovtseva, D, Crossin, E, Pell, R, Stamford, L. Toward a life cycle inventory for graphite production. J Ind Ecol. 2022; 26: 964â€“ 979. https://doi.org/10.1111/jiec.13234. Coal is a common precursor for the tar pitch which is used for the preparation of graphitization precursor and also for coating of the final spherical graphite. Relevant data include coal mining, coking to produce tar and distillation of tar to produce pitch. It is understood that the distillation of tar to pitch is generally integrated with the coal coking, and the authors were not able to identify a reputable source containing dedicated dataset for distillation. Allocation is based on physical yield of tar pitch.
A37: premise | B37: Graphite | C37: Surovtseva et al (2022) | D37: graphite precursor production | E37: grahite precursor | F37: CN | I37: kilogram | L37: Surovtseva, D, Crossin, E, Pell, R, Stamford, L. Toward a life cycle inventory for graphite production. J Ind Ecol. 2022; 26: 964â€“ 979. https://doi.org/10.1111/jiec.13234. Calcined coke is then mixed with tar pitch, baked to reduce volatiles and graphitized. Emissions from baking and graphitization are calculated as 0.4% and 2% mass loss in the respective processes. Transportation from calcining plant to graphitization plant is omitted. Crushing of needle coke and mixing of pitch with needle coke is not included.
A38: EI | B38: Iron ore concentrate | C38: Ecoinvent | D38: Iron ore mine operation and beneficiation | E38: iron ore concentrate | F38: CA-QC | G38: Mining and beneficiation | H38: Unallocated | I38: kilogram | J38: 2011 | L38: This dataset represents the production of 1 kg of iron concentrate containing 66.15% of Fe (dry basis) in Quebec in 2011. The concentrate is produced at 4% humidity. Specific data were collected for one compagny which represents nearly 65% of the Québec's production for the year 2011. The iron ore is extracted in two open pit mine; the main pit, where 92% of the ore is extracted, is located on the same site as the concentrator and the extra pit, used only when needed, is located 60 km from the concentrator. The ore is then transported by train. 65% of the 2011 production have been used in the production of iron pellet in Québec, the rest has been sold to other part of Canada, United States, Europe and China. | M38: Milling and mechanical sorting. Average iron yield is 75%.
A39: Istrate et al (2024) | B39: Lithium | C39: Schenker et al (2022) | D39: lithium brine production, from evaporation pond, Salar de Atacama | E39: lithium brine, from evaporation pond | F39: CL | G39: Cradle to gate ("from pumping the brines to the surface until the final product (Li2CO3, battery grade) leaves the processing plant") | I39: kilogram | L39: Source: Regionalized life cycle assessment of present and future lithium production for Li-ion batteries. Vanessa Schenker, Christopher Oberschelp, Stephan Pfister. Includes transport to purification.
A40: Istrate et al (2024) | B40: Lithium | C40: Schenker et al (2022) | D40: lithium brine purification, Salar de Atacama | E40: purified lithium brine | F40: CL | G40: Cradle to gate ("from pumping the brines to the surface until the final product (Li2CO3, battery grade) leaves the processing plant") | I40: kilogram | L40: Removal of lime, boron and manganese. Source: Regionalized life cycle assessment of present and future lithium production for Li-ion batteries. Vanessa Schenker, Christopher Oberschelp, Stephan Pfister.
...

Sheet REF
A1: AUTHORS | B1: LINK
B2: Argonne National Laboratory. 2022. “Life-Cycle Inventory of Critical Materials: Nickel, Copper, Titanium and Rare-Earth Elements.” https://publications.anl.gov/anlpubs/2022/12/178670.pdf.
B3: Norgate, Terry, and Nawshad Haque. 2012. “Using Life Cycle Assessment to Evaluate Some Environmental Impacts of Gold Production.” Journal of Cleaner Production 29–30 (July):53–63. https://doi.org/10.1016/j.jclepro.2012.01.042.
B4: Northey, S., N. Haque, and G. Mudd. 2013. “Using Sustainability Reporting to Assess the Environmental Footprint of Copper Mining.” Journal of Cleaner Production 40 (February):118–28. https://doi.org/10.1016/j.jclepro.2012.09.027.
B5: Sanjuan-Delmás, D., R. A. F. Alvarenga, M. Lindblom, T. C. Kampmann, Lauran Van Oers, Jeroen B. Guinée, and J. Dewulf. 2022. “Environmental Assessment of Copper Production in Europe: An LCA Case Study from Sweden Conducted Using Two Conventional Software-Database Setups.” The International Journal of Life Cycle Assessment 27 (2): 255–66. https://doi.org/10.1007/s11367-021-02018-5.

Sheet PARAMETRIZATION
A1: metal | B1: parameter_name | C1: description | D1: default | E1: min | F1: max | G1: std | H1: distribution | I1: unit | J1: formula_type | K1: formula | L1: source | M1: comment
A2: Au | B2: ore_grade_energy | C2: Total energy as a function of ore grade | J2: Power law (E = a * G**-b) | K2: E = 4.26E+05*G^-0.43 | L2: MetalliCan | M2: R2 = 0.35
A3: Au | B3: ore_grade_water | C3: Water consumption as a function of ore grade | J3: Power law (E = a * G**-b) | K3: E = 4.98E+05*G^-0.61 | L3: MetalliCan | M3: R2 = 0.25
A4: Ni | B4: ore_grade_energy | C4: Total energy as a function of ore grade | D4: 0.0205 | E4: 0.005 | F4: 0.03 | I4: MJ / t metal | J4: Power law (E = a * G**-b) | K4: E = 106.71 * (G ** -1.032) | L4: Argonne GREET 2022 from Wei et al. 2020
A5: Ni | B5: mining_beneficiation_share | C5: Fraction of total energy from mining vs beneficiation | D5: Mining 0.517 / Benef 0.483 | I5: fraction | K5: E_mining=E*0.517; E_benef=E*0.483 | L5: Argonne GREET 2022 from Wei et al. 2020
A6: Ni | B6: energy_mix_mining | C6: Energy mix mining | D6: Elec 0.696 / Diesel 0.304 | I6: fraction | J6: Power law (E = a * G**-b) | K6: E_elec=E_m*0.696; E_diesel=E_m*0.304 | L6: Argonne GREET 2022 from Wei et al. 2020
A7: Ni | B7: energy_mix_beneficiation | C7: Energy mix beneficiation | D7: Elec: 1 | I7: fraction | L7: Argonne GREET 2022 from Wei et al. 2020
A8: Cu | B8: ore_grade_energy | C8: Total energy as a function of ore grade | D8: 0.0018 | E8: 0.0018 | F8: 0.03 | I8: MJ / t metal | J8: Power law (E = a * G**-b) | K8: E = 15.697 * (G ** -0.573) | L8: Originally from Northey et al (2013), used in Argonne GREET 2022, Kuipers et al. 2018, in Van der Voet. 2019, Harpeccht et al 2021
A9: Cu | B9: mining_beneficiation_share | C9: Fraction of total energy from mining vs beneficiation | D9: Mining: 0.367; Beneficiation: 0.633 | I9: fraction | L9: Argonne GREET 2022 from Sanjuan-Delmás et al., 2022
A10: Cu | B10: energy_mix_mining | C10: Energy mix mining | D10: Diesel: 0.8099; Elec: 0.1846 Natural gas: 0.055 | I10: fraction | L10: Argonne GREET 2022 from Sanjuan-Delmás et al., 2022
A11: Cu | B11: energy_mix_beneficiation | C11: Energy mix beneficiation | D11: Electricity: 0.9965; Natural gas: 0.035 | I11: fraction | L11: Argonne GREET 2022 from Sanjuan-Delmás et al., 2022
A12: Cu | B12: ore_grade_energy | C12: Total energy as a function of ore grade | I12: GJ/t | J12: Power law (E = a * G**-b) | K12: E = 25.65*G^-0.366 | L12: Calvo et al. 2016, extracted from Figure 3
A13: Au | B13: ore_grade_energy | C13: Total energy as a function of ore grade | I13: GJ/t | J13: Power law (E = a * G**-b) | K13: E = 169.63*G^-0.275 | L13: Calvo et al. 2016, extracted from Figure 3
A14: Zn | B14: ore_grade_energy | C14: Total energy as a function of ore grade | I14: GJ/t | J14: Power law (E = a * G**-b) | K14: E = 47.15*G^-0.786 | L14: Calvo et al. 2016, extracted from Figure 3
A15: Cu | B15: ore_grade_energy | C15: Total energy as a function of ore grade | J15: Power law (E = a * G**-b) | K15: E = 15.63*G^-0.53 | L15: VanDerVoet2019
A16: Pb | B16: ore_grade_energy | C16: Total energy as a function of ore grade | J16: Power law (E = a * G**-b) | K16: E=75.42*G^-1 | L16: VanDerVoet2019
A17: Ni | B17: ore_grade_energy | C17: Total energy as a function of ore grade | J17: Power law (E = a * G**-b) | K17: E = 198.22*G^-0.406 (sulfides); E = 194.9*G^-0.494 (laterites) | L17: VanDerVoet2019
A18: Zn | B18: ore_grade_energy | C18: Total energy as a function of ore grade | J18: Power law (E = a * G**-b) | K18: E=77.65*G^-1 | L18: VanDerVoet2019
A19: Au | B19: ore_grade_energy | C19: Total energy as a function of ore grade | D19: 3.5g/t | E19: 0.5g/t | F19: 5g/t | J19: Power law (E = a * G**-b) | K19: Need to extract from figures | L19: Norgate & Haque. 2012
A20: Au | B20: ore_grade_water | C20: Total water consumption as a function of ore grade | D20: 3.5g/t | E20: 0.5g/t | F20: 5g/t | J20: Power law (E = a * G**-b) | K20: Need to extract from figures | L20: Norgate & Haque. 2012
A21: Au | B21: ore_grade_energy | C21: Total energy as a function of ore grade | J21: Power law (E = a * G**-b) | K21: Need to extract from figures | L21: Calvo et al 2022
A22: Au | B22: grind_size_energy | C22: Bond's formula | J22: Power law (E = a * G**-b) | K22: Need to extract from figures | L22: Calvo et al 2022

Sheet Material_MetalliCan
A1: site_id | B1: activity_name | C1: mining_method | D1: archetype | E1: flow_type | F1: subflow_type | G1: associated_material_category | H1: mass_t | I1: ore_processed_t | J1: value_normalized | K1: functional_unit | L1: allocation_factor | M1: normalization_key
A2: BC-MAIN-aa76f6f2 | B2: Au and Cu, Underground mining and beneficiation at New Afton | C2: Underground, concentrator | D2: Cu-Au Porphyry sulfide, flotation-based | E2: Material use | F2: 2'' balls | G2: grinding media | H2: 980 | I2: 3065000 | J2: 0.00031973899 | K2: Ore processed | L2: 1 | M2: ore
A3: BC-MAIN-aa76f6f2 | B3: Au and Cu, Underground mining and beneficiation at New Afton | C3: Underground, concentrator | D3: Cu-Au Porphyry sulfide, flotation-based | E3: Material use | F3: 3/4'' balls | G3: grinding media | H3: 179 | I3: 3065000 | J3: 5.8401305e-05 | K3: Ore processed | L3: 1 | M3: ore
A4: BC-MAIN-aa76f6f2 | B4: Au and Cu, Underground mining and beneficiation at New Afton | C4: Underground, concentrator | D4: Cu-Au Porphyry sulfide, flotation-based | E4: Material use | F4: Anti-scalant | G4: anti scalant | H4: 38 | I4: 3065000 | J4: 1.2398042e-05 | K4: Ore processed | L4: 1 | M4: ore
A5: BC-MAIN-aa76f6f2 | B5: Au and Cu, Underground mining and beneficiation at New Afton | C5: Underground, concentrator | D5: Cu-Au Porphyry sulfide, flotation-based | E5: Material use | F5: Flocculant | G5: floculant | H5: 192 | I5: 3065000 | J5: 6.2642741e-05 | K5: Ore processed | L5: 1 | M5: ore
A6: BC-MAIN-aa76f6f2 | B6: Au and Cu, Underground mining and beneficiation at New Afton | C6: Underground, concentrator | D6: Cu-Au Porphyry sulfide, flotation-based | E6: Material use | F6: Lime | G6: ph modifier | H6: 2724 | I6: 3065000 | J6: 0.00088874388 | K6: Ore processed | L6: 1 | M6: ore
A7: BC-MAIN-aa76f6f2 | B7: Au and Cu, Underground mining and beneficiation at New Afton | C7: Underground, concentrator | D7: Cu-Au Porphyry sulfide, flotation-based | E7: Material use | F7: Polyfroth h57 | G7: frother | H7: 55 | I7: 3065000 | J7: 1.7944535e-05 | K7: Ore processed | L7: 1 | M7: ore
A8: BC-MAIN-aa76f6f2 | B8: Au and Cu, Underground mining and beneficiation at New Afton | C8: Underground, concentrator | D8: Cu-Au Porphyry sulfide, flotation-based | E8: Material use | F8: S60 SAG Balls | G8: grinding media | H8: 583 | I8: 3065000 | J8: 0.00019021207 | K8: Ore processed | L8: 1 | M8: ore
A9: GRP-0d911886 | B9: Au, Open-pit and underground mining at Porcupine complex | C9: Open-pit, underground | D9: Free-milling | E9: Material use | F9: Cement | G9: cement | H9: 12578 | I9: 2911000 | J9: 0.0043208519 | K9: Ore processed | L9: 1 | M9: ore
A10: GRP-0d911886 | B10: Au, Open-pit and underground mining at Porcupine complex | C10: Open-pit, underground | D10: Free-milling | E10: Material use | F10: Grinding media | G10: grinding media | H10: 1932.222 | I10: 2911000 | J10: 0.00066376572 | K10: Ore processed | L10: 1 | M10: ore
A11: GRP-0d911886 | B11: Au, Open-pit and underground mining at Porcupine complex | C11: Open-pit, underground | D11: Free-milling | E11: Material use | F11: Hydrochloric acid (HCL) | G11: acid | H11: 2.68345 | I11: 2911000 | J11: 9.2183099e-07 | K11: Ore processed | L11: 1 | M11: ore
A12: GRP-0d911886 | B12: Au, Open-pit and underground mining at Porcupine complex | C12: Open-pit, underground | D12: Free-milling | E12: Material use | F12: Lime | G12: ph modifier | H12: 4346.921 | I12: 2911000 | J12: 0.0014932741 | K12: Ore processed | L12: 1 | M12: ore
A13: GRP-0d911886 | B13: Au, Open-pit and underground mining at Porcupine complex | C13: Open-pit, underground | D13: Free-milling | E13: Material use | F13: Lubricants | G13: lubricant | H13: 545.04208 | I13: 2911000 | J13: 0.00018723534 | K13: Ore processed | L13: 1 | M13: ore
... A60: ON-MAIN-7607a50e | B60: Au, Underground mining and beneficiation at Young-Davidson | C60: Underground, concentrator | D60: Free-milling | E60: Material use | F60: Total sodium cyanide used | G60: cyanide | H60: 1955.7 | I60: 2878047 | J60: 0.0006795233 | K60: Ore processed | L60: 1 | M60: ore

Sheet Material
A1: Source | B1: nb_of_sites | C1: mining_method | D1: archetype | E1: associated_material_category | F1: min | G1: max | H1: mean | I1: std | J1: min_kg_tore | K1: max_kg_tore | L1: mean_kg_tore | M1: std
A2: MetalliCan | B2: 1 | C2: Underground, concentrator | D2: Cu-Au Porphyry sulfide, flotation-based | E2: anti_scalant | F2: 1.2398042e-05 | G2: 1.2398042e-05 | H2: 1.2398042e-05 | J2: =F2*1000 -> 0.012398042 | K2: =G2*1000 -> 0.012398042 | L2: =H2*1000 -> 0.012398042 | M2: =I2*1000 -> 0
A3: MetalliCan | B3: 1 | C3: Underground, concentrator | D3: Cu-Au Porphyry sulfide, flotation-based | E3: floculant | F3: 6.2642741e-05 | G3: 6.2642741e-05 | H3: 6.2642741e-05 | J3: =F3*1000 -> 0.062642741 | K3: =G3*1000 -> 0.062642741 | L3: =H3*1000 -> 0.062642741 | M3: =I3*1000 -> 0
A4: MetalliCan | B4: 1 | C4: Underground, concentrator | D4: Cu-Au Porphyry sulfide, flotation-based | E4: frother | F4: 1.7944535e-05 | G4: 1.7944535e-05 | H4: 1.7944535e-05 | J4: =F4*1000 -> 0.017944535 | K4: =G4*1000 -> 0.017944535 | L4: =H4*1000 -> 0.017944535 | M4: =I4*1000 -> 0
A5: MetalliCan | B5: 1 | C5: Underground, concentrator | D5: Cu-Au Porphyry sulfide, flotation-based | E5: grinding_media | F5: 5.8401305e-05 | G5: 0.00031973899 | H5: 0.00018945079 | I5: 0.0001306705 | J5: =F5*1000 -> 0.058401305 | K5: =G5*1000 -> 0.31973899 | L5: =H5*1000 -> 0.18945079 | M5: =I5*1000 -> 0.1306705
A6: MetalliCan | B6: 1 | C6: Underground, concentrator | D6: Cu-Au Porphyry sulfide, flotation-based | E6: ph_modifier | F6: 0.00088874388 | G6: 0.00088874388 | H6: 0.00088874388 | J6: =F6*1000 -> 0.88874388 | K6: =G6*1000 -> 0.88874388 | L6: =H6*1000 -> 0.88874388 | M6: =I6*1000 -> 0
A7: MetalliCan | B7: 1 | C7: Open-pit, concentrator | D7: Free-milling | E7: explosives | F7: 0.0026471635 | G7: 0.0026471635 | H7: 0.0026471635 | J7: =F7*1000 -> 2.6471635 | K7: =G7*1000 -> 2.6471635 | L7: =H7*1000 -> 2.6471635 | M7: =I7*1000 -> 0
A8: MetalliCan | B8: 1 | C8: Open-pit, underground | D8: Free-milling | E8: acid | F8: 3.160426e-09 | G8: 9.2183099e-07 | H8: 3.3858926e-07 | I8: 5.0699835e-07 | J8: =F8*1000 -> 3.160426e-06 | K8: =G8*1000 -> 0.00092183099 | L8: =H8*1000 -> 0.00033858926 | M8: =I8*1000 -> 0.00050699835
A9: MetalliCan | B9: 1 | C9: Open-pit, underground | D9: Free-milling | E9: cement | F9: 0.0043208519 | G9: 0.0043208519 | H9: 0.0043208519 | J9: =F9*1000 -> 4.3208519 | K9: =G9*1000 -> 4.3208519 | L9: =H9*1000 -> 4.3208519 | M9: =I9*1000 -> 0
A10: MetalliCan | B10: 1 | C10: Open-pit, underground | D10: Free-milling | E10: consuming_equipment | F10: 0.00021538426 | G10: 0.00021538426 | H10: 0.00021538426 | J10: =F10*1000 -> 0.21538426 | K10: =G10*1000 -> 0.21538426 | L10: =H10*1000 -> 0.21538426 | M10: =I10*1000 -> 0
A11: MetalliCan | B11: 1 | C11: Open-pit, underground | D11: Free-milling | E11: cyanide | F11: 0.000252326 | G11: 0.000252326 | H11: 0.000252326 | J11: =F11*1000 -> 0.252326 | K11: =G11*1000 -> 0.252326 | L11: =H11*1000 -> 0.252326 | M11: =I11*1000 -> 0
A12: MetalliCan | B12: 1 | C12: Open-pit, underground | D12: Free-milling | E12: grinding_media | F12: 0.00066376572 | G12: 0.00066376572 | H12: 0.00066376572 | J12: =F12*1000 -> 0.66376572 | K12: =G12*1000 -> 0.66376572 | L12: =H12*1000 -> 0.66376572 | M12: =I12*1000 -> 0
A13: MetalliCan | B13: 1 | C13: Open-pit, underground | D13: Free-milling | E13: lubricant | F13: 0.00018723534 | G13: 0.00018723534 | H13: 0.00018723534 | J13: =F13*1000 -> 0.18723534 | K13: =G13*1000 -> 0.18723534 | L13: =H13*1000 -> 0.18723534 | M13: =I13*1000 -> 0
A14: MetalliCan | B14: 1 | C14: Open-pit, underground | D14: Free-milling | E14: ph_modifier | F14: 0.0014932741 | G14: 0.0014932741 | H14: 0.0014932741 | J14: =F14*1000 -> 1.4932741 | K14: =G14*1000 -> 1.4932741 | L14: =H14*1000 -> 1.4932741 | M14: =I14*1000 -> 0
A15: MetalliCan | B15: 1 | C15: Open-pit, underground, concentrator | D15: Free-milling | E15: anti_scalant | F15: 2.6385192e-05 | G15: 2.6385192e-05 | H15: 2.6385192e-05 | J15: =F15*1000 -> 0.026385192 | K15: =G15*1000 -> 0.026385192 | L15: =H15*1000 -> 0.026385192 | M15: =I15*1000 -> 0
A16: MetalliCan | B16: 1 | C16: Open-pit, underground, concentrator | D16: Free-milling | E16: cyanide | F16: 0.00025896508 | G16: 0.00025896508 | H16: 0.00025896508 | J16: =F16*1000 -> 0.25896508 | K16: =G16*1000 -> 0.25896508 | L16: =H16*1000 -> 0.25896508 | M16: =I16*1000 -> 0
A17: MetalliCan | B17: 2 | C17: Open-pit, underground, concentrator | D17: Free-milling | E17: explosives | F17: 0.0021801195 | G17: 0.0021801195 | H17: 0.0021801195 | J17: =F17*1000 -> 2.1801195 | K17: =G17*1000 -> 2.1801195 | L17: =H17*1000 -> 2.1801195 | M17: =I17*1000 -> 0
A18: MetalliCan | B18: 1 | C18: Open-pit, underground, concentrator | D18: Free-milling | E18: floculant | F18: 1.701278e-05 | G18: 1.701278e-05 | H18: 1.701278e-05 | J18: =F18*1000 -> 0.01701278 | K18: =G18*1000 -> 0.01701278 | L18: =H18*1000 -> 0.01701278 | M18: =I18*1000 -> 0
A19: MetalliCan | B19: 1 | C19: Open-pit, underground, concentrator | D19: Free-milling | E19: grinding_media | F19: 0.00032170128 | G19: 0.00068199681 | H19: 0.00050184904 | I19: 0.00025476741 | J19: =F19*1000 -> 0.32170128 | K19: =G19*1000 -> 0.68199681 | L19: =H19*1000 -> 0.50184904 | M19: =I19*1000 -> 0.25476741
A20: MetalliCan | B20: 1 | C20: Open-pit, underground, concentrator | D20: Free-milling | E20: ph_modifier | F20: 6.0042218e-05 | G20: 0.00072916476 | H20: 0.00039460349 | I20: 0.00047314109 | J20: =F20*1000 -> 0.060042218 | K20: =G20*1000 -> 0.72916476 | L20: =H20*1000 -> 0.39460349 | M20: =I20*1000 -> 0.47314109
A21: MetalliCan | B21: 7 | C21: Underground, concentrator | D21: Free-milling | E21: acid | F21: 8.1930403e-08 | G21: 6.6214008e-05 | H21: 3.0151676e-05 | I21: 3.3470826e-05 | J21: =F21*1000 -> 8.1930403e-05 | K21: =G21*1000 -> 0.066214008 | L21: =H21*1000 -> 0.030151676 | M21: =I21*1000 -> 0.033470826
A22: MetalliCan | B22: 7 | C22: Underground, concentrator | D22: Free-milling | E22: activated_carbon | F22: 5.8413926e-05 | G22: 5.8413926e-05 | H22: 5.8413926e-05 | J22: =F22*1000 -> 0.058413926 | K22: =G22*1000 -> 0.058413926 | L22: =H22*1000 -> 0.058413926 | M22: =I22*1000 -> 0
A23: MetalliCan | B23: 7 | C23: Underground, concentrator | D23: Free-milling | E23: anti_scalant | F23: 3.4235977e-05 | G23: 3.4235977e-05 | H23: 3.4235977e-05 | J23: =F23*1000 -> 0.034235977 | K23: =G23*1000 -> 0.034235977 | L23: =H23*1000 -> 0.034235977 | M23: =I23*1000 -> 0
A24: MetalliCan | B24: 7 | C24: Underground, concentrator | D24: Free-milling | E24: cement | F24: 0.0091610895 | G24: 0.016480433 | H24: 0.012820761 | I24: 0.0051755578 | J24: =F24*1000 -> 9.1610895 | K24: =G24*1000 -> 16.480433 | L24: =H24*1000 -> 12.820761 | M24: =I24*1000 -> 5.1755578
A25: MetalliCan | B25: 7 | C25: Underground, concentrator | D25: Free-milling | E25: consuming_equipment | F25: 9.7962396e-05 | G25: 0.00014524417 | H25: 0.00012160328 | I25: 3.3433263e-05 | J25: =F25*1000 -> 0.097962396 | K25: =G25*1000 -> 0.14524417 | L25: =H25*1000 -> 0.12160328 | M25: =I25*1000 -> 0.033433263
A26: MetalliCan | B26: 7 | C26: Underground, concentrator | D26: Free-milling | E26: cyanide | F26: 0.00037938035 | G26: 0.0006795233 | H26: 0.00050490397 | I26: 0.00011264206 | J26: =F26*1000 -> 0.37938035 | K26: =G26*1000 -> 0.6795233 | L26: =H26*1000 -> 0.50490397 | M26: =I26*1000 -> 0.11264206
A27: MetalliCan | B27: 7 | C27: Underground, concentrator | D27: Free-milling | E27: explosives | F27: 0.00090321666 | G27: 0.0054395918 | H27: 0.0021413172 | I27: 0.0018762707 | J27: =F27*1000 -> 0.90321666 | K27: =G27*1000 -> 5.4395918 | L27: =H27*1000 -> 2.1413172 | M27: =I27*1000 -> 1.8762707
A28: MetalliCan | B28: 7 | C28: Underground, concentrator | D28: Free-milling | E28: floculant | F28: 4.4680851e-05 | G28: 4.4680851e-05 | H28: 4.4680851e-05 | J28: =F28*1000 -> 0.044680851 | K28: =G28*1000 -> 0.044680851 | L28: =H28*1000 -> 0.044680851 | M28: =I28*1000 -> 0
A29: MetalliCan | B29: 7 | C29: Underground, concentrator | D29: Free-milling | E29: grinding_media | F29: 0.00070629475 | G29: 0.0018301626 | H29: 0.0012682286 | I29: 0.00079469455 | J29: =F29*1000 -> 0.70629475 | K29: =G29*1000 -> 1.8301626 | L29: =H29*1000 -> 1.2682286 | M29: =I29*1000 -> 0.79469455
A30: MetalliCan | B30: 7 | C30: Underground, concentrator | D30: Free-milling | E30: lubricant | F30: 1.450677e-06 | G30: 0.00028807245 | H30: 0.00010218469 | I30: 0.00012143315 | J30: =F30*1000 -> 0.001450677 | K30: =G30*1000 -> 0.28807245 | L30: =H30*1000 -> 0.10218469 | M30: =I30*1000 -> 0.12143315
A31: MetalliCan | B31: 7 | C31: Underground, concentrator | D31: Free-milling | E31: ph_modifier | F31: 8.3752418e-05 | G31: 0.0049026112 | H31: 0.0018068094 | I31: 0.0021286361 | J31: =F31*1000 -> 0.083752418 | K31: =G31*1000 -> 4.9026112 | L31: =H31*1000 -> 1.8068094 | M31: =I31*1000 -> 2.1286361
A32: Norgate and Haque | C32: Underground | D32: Hybrid | E32: explosives | L32: =DATA!L3 -> 1.7
A33: Norgate and Haque | C33: Underground | D33: Hybrid | E33: grinding_media | L33: =DATA!L6 -> 0.71
A34: Norgate and Haque | C34: Underground | D34: Hybrid | E34: ph_modifier | L34: =DATA!L16+DATA!L22 -> 2.32
A35: Norgate and Haque | C35: Underground | D35: Hybrid | E35: cyanide | L35: =DATA!L17 -> 0.64
A36: Norgate and Haque | C36: Underground | D36: Hybrid | E36: activated_carbon | L36: =DATA!L21*1000 -> 24000
A37: Norgate and Haque | C37: Underground | D37: Hybrid | E37: acid | L37: =(DATA!L23*1000) -> 83000
A38: Norgate and Haque | C38: Underground | D38: Hybrid

Sheet EI
A1: raw_material | B1: activity_name | C1: reference_product | D1: location | E1: exchange_type | F1: input_name | G1: input_database | H1: input_code | I1: amount | J1: unit | K1: comment
A2: Au-Ag ingot | B2: gold-silver mine operation and beneficiation | C2: gold-silver, ingot | D2: CA-QC | E2: technosphere | F2: electronics scrap, Recycled Content cut-off | G2: ecoinvent-3.10-cutoff | H2: 2aff8641ed51f091644ddd8a5a5140aa | I2: -0.011128011 | J2: kilogram | K2: Measured Value. Reported as computer equipement sent to recovery.
A3: Au-Ag ingot | B3: gold-silver mine operation and beneficiation | C3: gold-silver, ingot | D3: CA-QC | E3: technosphere | F3: iron scrap, sorted, pressed, Recycled Content cut-off | G3: ecoinvent-3.10-cutoff | H3: 2caf7c89279154622d31aba9048ae432 | I3: -20.404834 | J3: kilogram | K3: Measured Value. Reported as ferrous metal sent to recovery.
A4: Au-Ag ingot | B4: gold-silver mine operation and beneficiation | C4: gold-silver, ingot | D4: CA-QC | E4: technosphere | F4: market for aluminium sulfate, powder | G4: ecoinvent-3.10-cutoff | H4: c0d478928e7cc93227d2f8ac093def1b | I4: 3.6919387 | J4: kilogram | K4: Measured Value. Used for wastewater treatment.
A5: Au-Ag ingot | B5: gold-silver mine operation and beneficiation | C5: gold-silver, ingot | D5: CA-QC | E5: technosphere | F5: market for ammonium nitrate | G5: ecoinvent-3.10-cutoff | H5: 4936a0f0500ea80bf274e1cf09d139ff | I5: 22.267829 | J5: kilogram | K5: The exchange has been updated from "ammonium nitrate, as N" into "ammonium nitrate" and therefore its amount has been scaled (multiplied) from 22.3965 kg by 2.8573 kg of "ammonium nitrate" per kg of "ammonium nitrate, as N". Original comment of the exchange is: Calculated value. See parameters exchanges properties for details.
A6: Au-Ag ingot | B6: gold-silver mine operation and beneficiation | C6: gold-silver, ingot | D6: CA-QC | E6: technosphere | F6: market for borax, anhydrous, powder | G6: ecoinvent-3.10-cutoff | H6: 9c828f2ab7283a02f144463d5b6779c3 | I6: 3.765012 | J6: kilogram | K6: Measured Value. Used as Fluxing agent.
A7: Au-Ag ingot | B7: gold-silver mine operation and beneficiation | C7: gold-silver, ingot | D7: CA-QC | E7: technosphere | F7: market for carbon dioxide, liquid | G7: ecoinvent-3.10-cutoff | H7: 4e6b47103213c5f043e6e0b63420c088 | I7: 5.0942491 | J7: kilogram | K7: Measured Value. Used for wastewater treatment. The given amount represent the active agent only, used in a 60-100% solution.
A8: Au-Ag ingot | B8: gold-silver mine operation and beneficiation | C8: gold-silver, ingot | D8: CA-QC | E8: technosphere | F8: market for carboxymethyl cellulose, powder | G8: ecoinvent-3.10-cutoff | H8: a3281f997290a9f8953b895fd70877c6 | I8: 11.57689 | J8: kilogram | K8: Measured Value. Used for the Merill-Crowe process (gold recovery).
A9: Au-Ag ingot | B9: gold-silver mine operation and beneficiation | C9: gold-silver, ingot | D9: CA-QC | E9: technosphere | F9: market for cement, Portland | G9: ecoinvent-3.10-cutoff | H9: a21330ea54a20d86434dedad38c15620 | I9: 753.0024 | J9: kilogram | K9: Measured Value. Extrapolation for ciment type10 (60%) and ciment type 50 (40%).
A10: Au-Ag ingot | B10: gold-silver mine operation and beneficiation | C10: gold-silver, ingot | D10: CA-QC | E10: technosphere | F10: market for chemical, inorganic | G10: ecoinvent-3.10-cutoff | H10: 8b11c93221742fd1a07a536070dbf623 | I10: 2.6410759 | J10: kilogram | K10: Measured Value. Stands for Collector (3418-A) - aÃ©rophine (91%); Collector (KAX-51) - xantate (3%); lead nitrate (6%, for Merill-Crowe process).
A11: Au-Ag ingot | B11: gold-silver mine operation and beneficiation | C11: gold-silver, ingot | D11: CA-QC | E11: technosphere | F11: market for chromium | G11: ecoinvent-3.10-cutoff | H11: 04eb60a45923068c1bfecca832734111 | I11: 12.784338 | J11: kilogram | K11: Calculated Value. Different types of steel balls are used. The only available composition contains 15% chromium. We hence assume a composition of 15% chromium and 85% steel for all balls.
A12: Au-Ag ingot | B12: gold-silver mine operation and beneficiation | C12: gold-silver, ingot | D12: CA-QC | E12: technosphere | F12: market for copper sulfate | G12: ecoinvent-3.10-cutoff | H12: f2c84d9349e7675fe098a1decc1ac167 | I12: 6.6113889 | J12: kilogram | K12: Measured Value.
A13: Au-Ag ingot | B13: gold-silver mine operation and beneficiation | C13: gold-silver, ingot | D13: CA-QC | E13: technosphere | F13: market for diesel, burned in building machine | G13: ecoinvent-3.10-cutoff | H13: 7b503114dd17d341a5d418812fc977be | I13: 4185.8927 | J13: megajoule | K13: Calculated value. See parameters exchanges properties for details.
... A62: Ni concentrate | B62: nickel mine operation and benefication to nickel concentrate, 16% Ni | C62: nickel concentrate, 16% Ni | D62: CA-QC | E62: technosphere | F62: market for sulfidic tailings, from nickel mine operation | G62: ecoinvent-3.10-cutoff | H62: d1f92ee4695761dcf06ecdd1357ce92a | I62: -6.988 | J62: kilogram | K62: Calculated Value based on the Environmental Impact Assessment and a conversion factor (ore mined in 2010/expected amount of ore according to ElA). The sulfidic tailings, off-site dataset is used as a proxy, composition of leachage to water may not fully correspond. For the modelled mine, sulfidic tailings remain on site. The landuse in the tailing dataset is much smaller than the one of the modelled mine. Landuse is hence directly added in this mine operation dataset.
A63: Ni concentrate from AU (Wei) | B63: [M+C] Nickel (Ni) ore mining and concentration (for Ni Class 1) | C63: Ni concentrate | D63: AU | E63: technosphere | F63: market for diesel, burned in building machine | G63: ecoinvent-3.10-cutoff | H63: 7b503114dd17d341a5d418812fc977be | I63: 3.78 | J63: megajoule
A64: Ni concentrate from AU (Wei) | B64: [M+C] Nickel (Ni) ore mining and concentration (for Ni Class 1) | C64: Ni concentrate | D64: AU | E64: technosphere | F64: market for electricity, medium voltage | G64: ecoinvent-3.10-cutoff | H64: 5c11846265475a1ef9369ce4cb55f9be | I64: 2.283 | J64: kilowatt hour
A65: Ni concentrate from AU (Wei) | B65: [M+C] Nickel (Ni) ore mining and concentration (for Ni Class 1) | C65: Ni concentrate | D65: AU | E65: technosphere | F65: market for electricity, medium voltage | G65: ecoinvent-3.10-cutoff | H65: 5c11846265475a1ef9369ce4cb55f9be | I65: 3.064 | J65: kilowatt hour
A66: Ni concentrate from AU (Wei) | B66: [M+C] Nickel (Ni) ore mining and concentration (for Ni Class 1) | C66: Ni concentrate | D66: AU | E66: technosphere | F66: market for natural gas, high pressure | G66: ecoinvent-3.10-cutoff | H66: 168124822c7af05dd85d4e82cedfb116 | I66: 0.22312925 | J66: cubic meter
A67: Fe concentrate | B67: iron ore mine operation and beneficiation | C67: iron ore concentrate | D67: CA-QC | E67: technosphere | F67: market for ammonium nitrate | G67: ecoinvent-3.10-cutoff | H67: 4936a0f0500ea80bf274e1cf09d139ff | I67: 0.0024911529 | J67: kilogram | K67: The exchange has been updated from 'ammonium nitrate, as N' into 'ammonium nitrate' and therefore its amount has been scaled (multiplied) from 0.0009 kg by 2.8573 kg of 'ammonium nitrate' per kg of 'ammonium nitrate, as N'. Original comment of the exchange is: Calculated Value. Use as an explosive (Anfor).
A68: Fe concentrate | B68: iron ore mine operation and beneficiation | C68: iron ore concentrate | D68: CA-QC | E68: technosphere | F68: market for diesel, burned in building machine | G68: ecoinvent-3.10-cutoff | H68: 7b503114dd17d341a5d418812fc977be | I68: 0.098978424 | J68: megajoule | K68: Calculated Value using the total consumption of the plant and substract the amount used for the explosive. Reported in mÂ³.
A69: Fe concentrate | B69: iron ore mine operation and beneficiation | C69: iron ore concentrate | D69: CA-QC | E69: technosphere | F69: market for diesel, low-sulfur | G69: ecoinvent-3.10-cutoff | H69: a3f8685f5022cd35a0ebaee5ae5a989d | I69: 0.00014946 | J69: kilogram | K69: Calculated Value based on this estimation : the explosive Anfo is made of about 94 percent of ammonium nitrate and 6 percent of diesel. Assumption : diesel low sulfur.
A70: Fe concentrate | B70: iron ore mine operation and beneficiation | C70: iron ore concentrate | D70: CA-QC | E70: technosphere | F70: market for electricity, high voltage | G70: ecoinvent-3.10-cutoff | H70: d0d7d353b8ca27cc0effb56c12a47119 | I70: 0.03992 | J70: kilowatt hour | K70: Measured Value given by data provider (source : questionnaire). Reported as 161 kV mainly and 44 kV. The high voltage is between 44 kV and 315 kV in Quebec Souce: http://www.hydroquebec.com/transenergie/fr/commerce/pdf/characteristics-and-target-values-of-voltage.pdf
A71: Fe concentrate | B71: iron ore mine operation and beneficiation | C71: iron ore concentrate | D71: CA-QC | E71: technosphere | F71: market for hazardous waste, for incineration | G71: ecoinvent-3.10-cutoff | H71: 78aba9726eeea373a2cd9e5367092904 | I71: -8.953e-05 | J71: kilogram | K71: Measured Value given by data provider (source : questionnaire). Reported as diesel sent to incineration.
A72: Fe concentrate | B72: iron ore mine operation and beneficiation | C72: iron ore concentrate | D72: CA-QC | E72: technosphere | F72: heat production, heavy fuel oil, at industrial furnace 1MW | G72: ecoinvent-3.10-cutoff | H72: 2ff001b4c88fbd227eda77bd2ad48e53 | I72: 0.024712727 | J72: megajoule | K72: Calculated Value. Calculation is based on reported fuel input (in m3), the Net Heating Value of the fuel and efficiency (1/Fuel_use).
A73: Fe concentrate | B73: iron ore mine operation and beneficiation | C73: iron ore concentrate | D73: CA-QC | E73: technosphere | F73: market for lubricating oil | G73: ecoinvent-3.10-cutoff | H73: edc11964b6464c188c757f82f869c77b | I73: 5.0456e-05 | J73: kilogram | K73: Estimation based on the amount of lubricant burned on site and with the amount of used oil sent to incineration plant.
A74: Fe concentrate | B74: iron ore mine operation and beneficiation | C74: iron ore concentrate | D74: CA-QC | E74: technosphere | F74: market for mine infrastructure, iron | G74: ecoinvent-3.10-cutoff | H74: d0a29ce6082ddf9d9cbb3b8ff52b9e7f | I74: 3.2333146e-13 | J74: unit | K74: Estimation based on the ecoinvent iron mine operation, crude ore, 46%, GLO dataset (ecoinvent v3).
A75: Fe concentrate | B75: iron ore mine operation and beneficiation | C75: iron ore concentrate | D75: CA-QC | E75: technosphere | F75: market for solvent, organic | G75: ecoinvent-3.10-cutoff | H75: 4ca2e594b18dbf86d1034ecbabfdbd06 | I75: 2.189e-06 | J75: kilogram | K75: Estimation based on the amount of waste solvent.
A76: Fe concentrate | B76: iron ore mine operation and beneficiation | C76: iron ore concentrate | D76: CA-QC | E76: technosphere | F76: market for spent solvent mixture | G76: ecoinvent-3.10-cutoff | H76: 087f21c3f228206c6c9c559860d34868 | I76: -2.189e-06 | J76: kilogram | K76: Measured Value given by data provider (source : questionnaire). Reported as non-halogenated organic solvents sent to incineration.
A77: Fe concentrate | B77: iron ore mine operation and beneficiation | C77: iron ore concentrate | D77: CA-QC | E77: technosphere | F77: transport, freight train, diesel | G77: ecoinvent-3.10-cutoff | H77: 34fb4c90cc376739874eac1f4a731605 | I77: 0.0159 | J77: ton kilometer | K77: Calculated Value.Transport of the ore from the extra pit to the concentrator.
A78: Fe concentrate | B78: iron ore mine operation and beneficiation | C78: iron ore concentrate | D78: CA-QC | E78: technosphere | F78: market for waste mineral oil | G78: ecoinvent-3.10-cutoff | H78: 7e3380e62e98e926c429fcf085e2ba3a | I78: -4.025e-06 | J78: kilogram | K78: Measured Value given by data provider (source : questionnaire). Reported as waste oil with BPC concentration less or equal to 3 mg/kg and waste grease sent to incineration.
... A101: Cu concentrate | B101: copper mine operation and beneficiation, sulfide ore | C101: copper concentrate, sulfide ore | D101: CA | E101: technosphere | F101: market for synthetic rubber | G101: ecoinvent-3.10-cutoff | H101: 67e715e9a99ff1fe421b32b1b9c037bd | I101: 5.1812308e-07 | J101: kilogram | K101: Original amount reported in Classen et al. (2009) regionalised based on geography-specific ore grade (see Sampling Procedure and Turner & Hischier, 2020 for details). References: Classen, M., Althaus, H.-J., Blaser, S., Scharnhost, W., Tuchschmid, M., Jungbluth, N., & Emmenegger, M. F. (2009). Life cycle inventories of metals. Final report, ecoinvent data v2.1, No. 10. DÃ¼bendorf, Switzerland. Turner, D. A. & Hischier, R. (2020). Life cycle inventories of pyrometallurgical copper production and anode slime processing. Empa, St. Gallen, Switzerland.
A102: Cu concentrate from AU (Norgate) | B102: [M+C] Copper (Cu) ore mining and concentration (Australia) | C102: Cu concentrate | D102: AU | E102: technosphere | F102: market for diesel, burned in building machine | G102: ecoinvent-3.10-cutoff | H102: 7b503114dd17d341a5d418812fc977be | I102: 0.0315 | J102: megajoule
A103: Cu concentrate from AU (Norgate) | B103: [M+C] Copper (Cu) ore mining and concentration (Australia) | C103: Cu concentrate | D103: AU | E103: technosphere | F103: market for diesel, burned in building machine | G103: ecoinvent-3.10-cutoff | H103: 7b503114dd17d341a5d418812fc977be | I103: 0.0045 | J103: megajoule
A104: Cu concentrate from AU (Norgate) | B104: [M+C] Copper (Cu) ore mining and concentration (Australia) | C104: Cu concentrate | D104: AU | E104: technosphere | F104: market for explosive, tovex | G104: ecoinvent-3.10-cutoff | H104: 4039be70f92cb41f235cdc157a5ea398 | I104: 0.0004 | J104: kilogram
A105: Cu concentrate from AU (Norgate) | B105: [M+C] Copper (Cu) ore mining and concentration (Australia) | C105: Cu concentrate | D105: AU | E105: technosphere | F105: market for diesel, burned in building machine | G105: ecoinvent-3.10-cutoff | H105: 7b503114dd17d341a5d418812fc977be | I105: 0.09 | J105: megajoule
A106: Cu concentrate from AU (Norgate) | B106: [M+C] Copper (Cu) ore mining and concentration (Australia) | C106: Cu concentrate | D106: AU | E106: technosphere | F106: market for electricity, medium voltage | G106: ecoinvent-3.10-cutoff | H106: 5c11846265475a1ef9369ce4cb55f9be | I106: 0.008 | J106: kilowatt hour
A107: Cu concentrate from AU (Norgate) | B107: [M+C] Copper (Cu) ore mining and concentration (Australia) | C107: Cu concentrate | D107: AU | E107: technosphere | F107: market for electricity, medium voltage | G107: ecoinvent-3.10-cutoff | H107: 5c11846265475a1ef9369ce4cb55f9be | I107: 0.0038 | J107: kilowatt hour
A108: Cu concentrate from AU (Norgate) | B108: [M+C] Copper (Cu) ore mining and concentration (Australia) | C108: Cu concentrate | D108: AU | E108: technosphere | F108: market for electricity, medium voltage | G108: ecoinvent-3.10-cutoff | H108: 5c11846265475a1ef9369ce4cb55f9be | I108: 0.0185 | J108: kilowatt hour
A109: Cu concentrate from AU (Norgate) | B109: [M+C] Copper (Cu) ore mining and concentration (Australia) | C109: Cu concentrate | D109: AU | E109: technosphere | F109: market for electricity, medium voltage | G109: ecoinvent-3.10-cutoff | H109: 5c11846265475a1ef9369ce4cb55f9be | I109: 0.0075 | J109: kilowatt hour
