Workbook

Sheet prod_$_data
A1: main_id | B1: facility_group_id | C1: facility_name | D1: facility_group_name | E1: province | F1: facility_type | G1: mining_processing_type | H1: archetypes | I1: biosphere_data? | J1: technosphere_data? | K1: land_data? | L1: commodities | M1: Main_product | N1: ore_processed_t | O1: concentrate_dore_mass_t | P1: tailings_mass_t | Q1: Au_t | R1: Ag_t | S1: Cu_t | T1: Ni_t | U1: Co_t | V1: Mo_t | W1: Zn_t | X1: Pb_t | Y1: Fe_t | Z1: Pt_t | AA1: Pd_t | AB1: U_t | AC1: Nb_t | AD1: Au_conc_t | AE1: Ag_conc_t | AF1: Cu_conc_t | AG1: Ni_conc_t | AH1: Co_conc_t | AI1: Mo_conc_t | AJ1: Zn_conc_t | AK1: Pb_conc_t | AL1: Fe_conc_t | AM1: Pt_conc_t | AN1: Pd_conc_t | AO1: U_conc_t | AP1: Nb_conc_t | AQ1: Au_$ | AR1: Ag_$ | AS1: Cu_$ | AT1: Ni_$ | AU1: Co_$ | AV1: Mo_$ | AW1: Zn_$ | AX1: Pb_$ | AY1: Fe_$ | AZ1: Pt_$ | BA1: U_$ | BB1: N_$ | BC1: Sum | BD1: %Au | BE1: %Cu | BF1: Main_product
A2: QC-MAIN-089f3c60 | C2: Bloom Lake | E2: Quebec | F2: mining | G2: Open-pit | H2: Magnetite concentrator | I2: NPRI+GHG+Land | L2: Iron | M2: Fe | N2: =prod_table_raw!N11 -> 11187000 | O2: =SUM(AD2:AP2) -> 0 | P2: =N2-O2 -> 11187000 | AF2: =S2/(concentrate_grade!$F$4/100) -> 0 | AG2: =T2/(concentrate_grade!$F$6/100) -> 0 | AQ2: =Q2*prices!$C$4 -> 0 | AR2: =R2*prices!$C$11 -> 0 | AS2: =S2*prices!$C$3 -> 0 | AT2: =T2*prices!$C$8 -> 0 | AU2: =U2*prices!$C$2 -> 0 | AV2: =V2*prices!$C$7 -> 0 | AW2: =W2*prices!$C$13 -> 0 | AX2: =X2*prices!$C$6 -> 0 | AY2: =Y2*prices!$C$5 -> 0 | AZ2: =Z2*prices!$C$9 -> 0 | BA2: =AB2*prices!$C$12 -> 0 | BB2: =AC2*prices!$C$14 -> 0 | BC2: =SUM(AQ2:AZ2) -> 0 | BD2: =AQ2/BC2 -> #DIV/0! | BE2: =AS2/BC2 -> #DIV/0! | BF2: Fe
A3: BC-MAIN-857b7b89 | C3: Brucejack | E3: British Columbia | F3: mining | G3: Underground, concentrator | I3: NPRI+GHG+Water | J3: Energy | L3: Gold, silver | M3: Au | N3: =prod_table_raw!N13 -> 166000 | O3: =SUM(AD3:AP3) -> 0 | P3: =N3-O3 -> 166000 | Q3: =prod_table_raw!N14 -> 0.9020015 | AF3: =S3/(concentrate_grade!$F$4/100) -> 0 | AG3: =T3/(concentrate_grade!$F$6/100) -> 0 | AQ3: =Q3*prices!$C$4 -> 46717.485 | AR3: =R3*prices!$C$11 -> 0 | AS3: =S3*prices!$C$3 -> 0 | AT3: =T3*prices!$C$8 -> 0 | AU3: =U3*prices!$C$2 -> 0 | AV3: =V3*prices!$C$7 -> 0 | AW3: =W3*prices!$C$13 -> 0 | AX3: =X3*prices!$C$6 -> 0 | AY3: =Y3*prices!$C$5 -> 0 | AZ3: =Z3*prices!$C$9 -> 0 | BA3: =AB3*prices!$C$12 -> 0 | BB3: =AC3*prices!$C$14 -> 0 | BC3: =SUM(AQ3:AZ3) -> 46717.485 | BD3: =AQ3/BC3 -> 1 | BE3: =AS3/BC3 -> 0 | BF3: Au
A4: QC-MAIN-de3d8b7b | C4: Canadian Electrolytic Zinc Limited (CEZinc) | E4: Quebec | F4: manufacturing | G4: Refinery | L4: Lead, zinc | M4: Zn (Pb) | O4: =SUM(AD4:AP4) -> 0 | P4: =N4-O4 -> 0 | W4: =prod_table_raw!N16 -> 752600 | X4: =prod_table_raw!N15 -> 244600 | AF4: =S4/(concentrate_grade!$F$4/100) -> 0 | AG4: =T4/(concentrate_grade!$F$6/100) -> 0 | AQ4: =Q4*prices!$C$4 -> 0 | AR4: =R4*prices!$C$11 -> 0 | AS4: =S4*prices!$C$3 -> 0 | AT4: =T4*prices!$C$8 -> 0 | AU4: =U4*prices!$C$2 -> 0 | AV4: =V4*prices!$C$7 -> 0 | AW4: =W4*prices!$C$13 -> 1941192.1 | AX4: =X4*prices!$C$6 -> 504507.94 | AY4: =Y4*prices!$C$5 -> 0 | AZ4: =Z4*prices!$C$9 -> 0 | BA4: =AB4*prices!$C$12 -> 0 | BB4: =AC4*prices!$C$14 -> 0 | BC4: =SUM(AQ4:AZ4) -> 2445700.1 | BD4: =AQ4/BC4 -> 0 | BE4: =AS4/BC4 -> 0 | BF4: Zn (Pb)
A5: QC-MAIN-e7e6a960 | C5: Canadian Malartic | E5: Quebec | F5: mining | G5: Open-pit, concentrator | H5: Mixed free-miling-refactory | I5: NPRI+GHG+Land | J5: Energy | L5: Gold, silver | M5: Au (Ag) | N5: =prod_table_raw!N17 -> 17332900 | O5: =SUM(AD5:AP5) -> 0 | P5: =N5-O5 -> 17332900 | Q5: =prod_table_raw!N18 -> 18.785114 | R5: =prod_table_raw!N19 -> 9.6731885 | AF5: =S5/(concentrate_grade!$F$4/100) -> 0 | AG5: =T5/(concentrate_grade!$F$6/100) -> 0 | AQ5: =Q5*prices!$C$4 -> 972939.96 | AR5: =R5*prices!$C$11 -> 6501.6402 | AS5: =S5*prices!$C$3 -> 0 | AT5: =T5*prices!$C$8 -> 0 | AU5: =U5*prices!$C$2 -> 0 | AV5: =V5*prices!$C$7 -> 0 | AW5: =W5*prices!$C$13 -> 0 | AX5: =X5*prices!$C$6 -> 0 | AY5: =Y5*prices!$C$5 -> 0 | AZ5: =Z5*prices!$C$9 -> 0 | BA5: =AB5*prices!$C$12 -> 0 | BB5: =AC5*prices!$C$14 -> 0 | BC5: =SUM(AQ5:AZ5) -> 979441.6 | BD5: =AQ5/BC5 -> 0.99336189 | BE5: =AS5/BC5 -> 0 | BF5: Au (Ag)
A6: NL-MAIN-dd723db4 | C6: Carol Lake | E6: Newfoundland and Labrador | F6: mining | G6: Open-pit, concentrator | H6: Fe concentrator + pellet plant | I6: NPRI+GHG+Land | J6: Energy | L6: Iron | M6: Fe | N6: =prod_table_raw!N21 -> 16478000 | O6: =SUM(AD6:AP6) -> 0 | P6: =N6-O6 -> 16478000 | AF6: =S6/(concentrate_grade!$F$4/100) -> 0 | AG6: =T6/(concentrate_grade!$F$6/100) -> 0 | AQ6: =Q6*prices!$C$4 -> 0 | AR6: =R6*prices!$C$11 -> 0 | AS6: =S6*prices!$C$3 -> 0 | AT6: =T6*prices!$C$8 -> 0 | AU6: =U6*prices!$C$2 -> 0 | AV6: =V6*prices!$C$7 -> 0 | AW6: =W6*prices!$C$13 -> 0 | AX6: =X6*prices!$C$6 -> 0 | AY6: =Y6*prices!$C$5 -> 0 | AZ6: =Z6*prices!$C$9 -> 0 | BA6: =AB6*prices!$C$12 -> 0 | BB6: =AC6*prices!$C$14 -> 0 | BC6: =SUM(AQ6:AZ6) -> 0 | BD6: =AQ6/BC6 -> #DIV/0! | BE6: =AS6/BC6 -> #DIV/0! | BF6: Fe
A7: QC-MAIN-b86f7d07 | C7: Casa Berardi | E7: Quebec | F7: mining | G7: Open-pit, underground, concentrator | H7: Free-miling | I7: NPRI+GHG+Land | J7: Energy | L7: Gold, silver | M7: Au | N7: =prod_table_raw!N24 -> 1361450 | O7: =SUM(AD7:AP7) -> 0 | P7: =N7-O7 -> 1361450 | Q7: =prod_table_raw!N22 -> 2.6935631 | R7: =prod_table_raw!N23 -> 0.7527047 | AF7: =S7/(concentrate_grade!$F$4/100) -> 0 | AG7: =T7/(concentrate_grade!$F$6/100) -> 0 | AQ7: =Q7*prices!$C$4 -> 139508.08 | AR7: =R7*prices!$C$11 -> 505.91541 | AS7: =S7*prices!$C$3 -> 0 | AT7: =T7*prices!$C$8 -> 0 | AU7: =U7*prices!$C$2 -> 0 | AV7: =V7*prices!$C$7 -> 0 | AW7: =W7*prices!$C$13 -> 0 | AX7: =X7*prices!$C$6 -> 0 | AY7: =Y7*prices!$C$5 -> 0 | AZ7: =Z7*prices!$C$9 -> 0 | BA7: =AB7*prices!$C$12 -> 0 | BB7: =AC7*prices!$C$14 -> 0 | BC7: =SUM(AQ7:AZ7) -> 140013.99 | BD7: =AQ7/BC7 -> 0.99638668 | BE7: =AS7/BC7 -> 0 | BF7: Au
A8: SK-MAIN-91cf5448 | C8: Cigar Lake | E8: Saskatchewan | F8: mining | G8: Underground | H8: High-grade U acid-leach mills | I8: NPRI+GHG+Land | L8: Uranium | M8: U | N8: =prod_table_raw!#REF! -> #REF! | O8: =SUM(AD8:AP8) -> 0 | P8: =N8-O8 -> #REF! | AB8: =prod_table_raw!#REF! -> #REF! | AF8: =S8/(concentrate_grade!$F$4/100) -> 0 | AG8: =T8/(concentrate_grade!$F$6/100) -> 0 | AQ8: =Q8*prices!$C$4 -> 0 | AR8: =R8*prices!$C$11 -> 0 | AS8: =S8*prices!$C$3 -> 0 | AT8: =T8*prices!$C$8 -> 0 | AU8: =U8*prices!$C$2 -> 0 | AV8: =V8*prices!$C$7 -> 0 | AW8: =W8*prices!$C$13 -> 0 | AX8: =X8*prices!$C$6 -> 0 | AY8: =Y8*prices!$C$5 -> 0 | AZ8: =Z8*prices!$C$9 -> 0 | BA8: =AB8*prices!$C$12 -> #REF! | BB8: =AC8*prices!$C$14 -> 0 | BC8: =SUM(AQ8:AZ8) -> 0 | BD8: =AQ8/BC8 -> #DIV/0! | BE8: =AS8/BC8 -> #DIV/0! | BF8: U
A9: ON-MAIN-f080c409 | B9: GRP-dc07540b | C9: Copper Cliff Complex (mine) | D9: Sudbury Operation | E9: Ontario | F9: mining | G9: Underground | H9: Ni-Cu Porphyry sulfide, flotation-based | I9: NPRI+Land | L9: Nickel, copper, platinum group metals, gold, silver, cobalt, selenium, tellurium | M9: Ni+Cu | N9: =prod_table_raw!N30 -> 748000 | O9: =SUM(AD9:AP9) -> 88353.75 | P9: =N9-O9 -> 659646.25 | S9: =prod_table_raw!N29 -> 10098 | T9: =prod_table_raw!N28 -> 8751 | AF9: =S9/(concentrate_grade!$F$4/100) -> 33660 | AG9: =T9/(concentrate_grade!$F$6/100) -> 54693.75 | AQ9: =Q9*prices!$C$4 -> 0 | AR9: =R9*prices!$C$11 -> 0 | AS9: =S9*prices!$C$3 -> 69676.2 | AT9: =T9*prices!$C$8 -> 136428.09 | AU9: =U9*prices!$C$2 -> 0 | AV9: =V9*prices!$C$7 -> 0 | AW9: =W9*prices!$C$13 -> 0 | AX9: =X9*prices!$C$6 -> 0 | AY9: =Y9*prices!$C$5 -> 0 | AZ9: =Z9*prices!$C$9 -> 0 | BA9: =AB9*prices!$C$12 -> 0 | BB9: =AC9*prices!$C$14 -> 0 | BC9: =SUM(AQ9:AZ9) -> 206104.29 | BD9: =AQ9/BC9 -> 0 | BE9: =AS9/BC9 -> 0.33806283 | BF9: Ni+Cu
A10: ON-MAIN-63b394c3 | B10: GRP-dc07540b | C10: Copper Cliff Complex (refinery) | D10: Sudbury Operation | E10: Ontario | F10: manufacturing | G10: Smelter, refinery, plant | H10: Cu-Ni smelter and refinery | I10: NPRI+GHG | L10: Nickel (oxide sinter, pellets, powder, sulfide), copper cathodes, gold, silver, selenium cake, tellurium dioxide cake, platinum group metals (in residues), liquid sulfur dioxide, sulfuric acid | M10: Ni+Cu | O10: =SUM(AD10:AP10) -> 431750 | P10: =N10-O10 -> -431750 | S10: =prod_table_raw!N31 -> 57900 | T10: =prod_table_raw!N32 -> 38200 | AF10: =S10/(concentrate_grade!$F$4/100) -> 193000 | AG10: =T10/(concentrate_grade!$F$6/100) -> 238750 | AQ10: =Q10*prices!$C$4 -> 0 | AR10: =R10*prices!$C$11 -> 0 | AS10: =S10*prices!$C$3 -> 399510 | AT10: =T10*prices!$C$8 -> 595538 | AU10: =U10*prices!$C$2 -> 0 | AV10: =V10*prices!$C$7 -> 0 | AW10: =W10*prices!$C$13 -> 0 | AX10: =X10*prices!$C$6 -> 0 | AY10: =Y10*prices!$C$5 -> 0 | AZ10: =Z10*prices!$C$9 -> 0 | BA10: =AB10*prices!$C$12 -> 0 | BB10: =AC10*prices!$C$14 -> 0 | BC10: =SUM(AQ10:AZ10) -> 995048 | BD10: =AQ10/BC10 -> 0 | BE10: =AS10/BC10 -> 0.40149822 | BF10: Ni+Cu
A11: BC-MAIN-599152a0 | C11: Copper Mountain | E11: British Columbia | F11: mining | G11: Open-pit, concentrator | H11: Cu-Au Porphyry sulfide, flotation-based | I11: NPRI+GHG+Land | J11: Energy | L11: Copper, gold, silver | M11: Cu (Au, Ag) | N11: =prod_table_raw!N36 -> 6862152 | O11: =SUM(AD11:AP11) -> 63500 | P11: =N11-O11 -> 6798652 | Q11: =prod_table_raw!N35 -> 0.27520377 | R11: =prod_table_raw!N38 -> 6.7893342 | S11: =prod_table_raw!N39 -> 19050 | AF11: =S11/(concentrate_grade!$F$4/100) -> 63500 | AG11: =T11/(concentrate_grade!$F$6/100) -> 0 | AQ11: =Q11*prices!$C$4 -> 14253.666 | AR11: =R11*prices!$C$11 -> 4563.3152 | AS11: =S11*prices!$C$3 -> 131445 | AT11: =T11*prices!$C$8 -> 0 | AU11: =U11*prices!$C$2 -> 0 | AV11: =V11*prices!$C$7 -> 0 | AW11: =W11*prices!$C$13 -> 0 | AX11: =X11*prices!$C$6 -> 0 | AY11: =Y11*prices!$C$5 -> 0 | AZ11: =Z11*prices!$C$9 -> 0 | BA11: =AB11*prices!$C$12 -> 0 | BB11: =AC11*prices!$C$14 -> 0 | BC11: =SUM(AQ11:AZ11) -> 150261.98 | BD11: =AQ11/BC11 -> 0.094858765 | BE11: =AS11/BC11 -> 0.87477217 | BF11: Cu (Au, Ag)
A12: ON-MAIN-52224e1e | B12: GRP-dc07540b | C12: Creighton | D12: Sudbury Operation | E12: Ontario | F12: mining | G12: Underground | H12: Ni-Cu Porphyry sulfide, flotation-based | I12: NPRI+land | L12: Nickel, copper, platinum group metals, gold, silver, cobalt, selenium, tellurium | M12: Ni+Cu | N12: =prod_table_raw!N44 -> 433000 | O12: =SUM(AD12:AP12) -> 102220 | P12: =N12-O12 -> 330780 | S12: =prod_table_raw!N43 -> 9396 | T12: =prod_table_raw!N42 -> 11344 | AF12: =S12/(concentrate_grade!$F$4/100) -> 31320 | AG12: =T12/(concentrate_grade!$F$6/100) -> 70900 | AQ12: =Q12*prices!$C$4 -> 0 | AR12: =R12*prices!$C$11 -> 0 | AS12: =S12*prices!$C$3 -> 64832.4 | AT12: =T12*prices!$C$8 -> 176852.96 | AU12: =U12*prices!$C$2 -> 0 | AV12: =V12*prices!$C$7 -> 0 | AW12: =W12*prices!$C$13 -> 0 | AX12: =X12*prices!$C$6 -> 0 | AY12: =Y12*prices!$C$5 -> 0 | AZ12: =Z12*prices!$C$9 -> 0 | BA12: =AB12*prices!$C$12 -> 0 | BB12: =AC12*prices!$C$14 -> 0 | BC12: =SUM(AQ12:AZ12) -> 241685.36 | BD12: =AQ12/BC12 -> 0 | BE12: =AS12/BC12 -> 0.26825125 | BF12: Ni+Cu
A13: ON-MAIN-aeafbb59 | C13: Detour Lake | E13: Ontario | F13: mining | G13: Open-pit, concentrator | H13: Free-miling | I13: NPRI+GHG+Land | J13: Energy | L13: Gold | M13: Au (Ag) | N13: =prod_table_raw!N48 -> 25434854 | O13: =SUM(AD13:AP13) -> 0 | P13: =N13-O13 -> 25434854 | Q13: =prod_table_raw!N49 -> 21.070942 | R13: =prod_table_raw!N50 -> 2.4571765 | AF13: =S13/(concentrate_grade!$F$4/100) -> 0 | AG13: =T13/(concentrate_grade!$F$6/100) -> 0 | AQ13: =Q13*prices!$C$4 -> 1091330.1 | AR13: =R13*prices!$C$11 -> 1651.542 | AS13: =S13*prices!$C$3 -> 0 | AT13: =T13*prices!$C$8 -> 0 | AU13: =U13*prices!$C$2 -> 0 | AV13: =V13*prices!$C$7 -> 0 | AW13: =W13*prices!$C$13 -> 0 | AX13: =X13*prices!$C$6 -> 0 | AY13: =Y13*prices!$C$5 -> 0 | AZ13: =Z13*prices!$C$9 -> 0 | BA13: =AB13*prices!$C$12 -> 0 | BB13: =AC13*prices!$C$14 -> 0 | BC13: =SUM(AQ13:AZ13) -> 1092981.7 | BD13: =AQ13/BC13 -> 0.99848896 | BE13: =AS13/BC13 -> 0 | BF13: Au (Ag)
A14: ON-MAIN-cb85213a | C14: Eagle River | E14: Ontario | F14: mining | G14: Underground, concentrator | H14: Free-miling | I14: NPRI+GHG | J14: Energy | L14: Gold | M14: Au | N14: =prod_table_raw!N55 -> 222627 | O14: =SUM(AD14:AP14) -> 0 | P14: =N14-O14 -> 222627 | Q14: =prod_table_raw!N55 -> 222627 | AF14: =S14/(concentrate_grade!$F$4/100) -> 0 | AG14: =T14/(concentrate_grade!$F$6/100) -> 0 | AQ14: =Q14*prices!$C$4 -> 1.153055e+10 | AR14: =R14*prices!$C$11 -> 0 | AS14: =S14*prices!$C$3 -> 0 | AT14: =T14*prices!$C$8 -> 0 | AU14: =U14*prices!$C$2 -> 0 | AV14: =V14*prices!$C$7 -> 0 | AW14: =W14*prices!$C$13 -> 0 | AX14: =X14*prices!$C$6 -> 0 | AY14: =Y14*prices!$C$5 -> 0 | AZ14: =Z14*prices!$C$9 -> 0 | BA14: =AB14*prices!$C$12 -> 0 | BB14: =AC14*prices!$C$14 -> 0 | BC14: =SUM(AQ14:AZ14) -> 1.153055e+10 | BD14: =AQ14/BC14 -> 1 | BE14: =AS14/BC14 -> 0 | BF14: Au
A15: QC-MAIN-6dc537e6 | C15: Éléonore | E15: Quebec | F15: mining | G15: Underground, concentrator | H15: Free-miling | I15: NPRI+GHG | J15: Energy and materials | L15: Gold, silver | M15: Au (Ag) | N15: =prod_table_raw!N62 -> 1661000 | O15: =SUM(AD15:AP15) -> 0 | P15: =N15-O15 -> 1661000 | Q15: =prod_table_raw!N59 -> 7.216012 | R15: =prod_table_raw!N60 -> 0.36810992 | AF15: =S15/(concentrate_grade!$F$4/100) -> 0 | AG15: =T15/(concentrate_grade!$F$6/100) -> 0 | AQ15: =Q15*prices!$C$4 -> 373739.88 | AR15: =R15*prices!$C$11 -> 247.41772 | AS15: =S15*prices!$C$3 -> 0 | AT15: =T15*prices!$C$8 -> 0 | AU15: =U15*prices!$C$2 -> 0 | AV15: =V15*prices!$C$7 -> 0 | AW15: =W15*prices!$C$13 -> 0 | AX15: =X15*prices!$C$6 -> 0 | AY15: =Y15*prices!$C$5 -> 0 | AZ15: =Z15*prices!$C$9 -> 0 | BA15: =AB15*prices!$C$12 -> 0 | BB15: =AC15*prices!$C$14 -> 0 | BC15: =SUM(AQ15:AZ15) -> 373987.3 | BD15: =AQ15/BC15 -> 0.99933843 | BE15: =AS15/BC15 -> 0 | BF15: Au (Ag)
A16: BC-MAIN-4724f4ba | C16: Elk | E16: British Columbia | F16: mining | G16: Open-pit | H16: Free-miling | I16: Land | L16: Gold | M16: Au | N16: =prod_table_raw!N64 -> 33245 | O16: =SUM(AD16:AP16) -> 0 | P16: =N16-O16 -> 33245 | Q16: =prod_table_raw!N65 -> 0.12180131 | AF16: =S16/(concentrate_grade!$F$4/100) -> 0 | AG16: =T16/(concentrate_grade!$F$6/100) -> 0 | AQ16: =Q16*prices!$C$4 -> 6308.4715 | AR16: =R16*prices!$C$11 -> 0 | AS16: =S16*prices!$C$3 -> 0 | AT16: =T16*prices!$C$8 -> 0 | AU16: =U16*prices!$C$2 -> 0 | AV16: =V16*prices!$C$7 -> 0 | AW16: =W16*prices!$C$13 -> 0 | AX16: =X16*prices!$C$6 -> 0 | AY16: =Y16*prices!$C$5 -> 0 | AZ16: =Z16*prices!$C$9 -> 0 | BA16: =AB16*prices!$C$12 -> 0 | BB16: =AC16*prices!$C$14 -> 0 | BC16: =SUM(AQ16:AZ16) -> 6308.4715 | BD16: =AQ16/BC16 -> 1 | BE16: =AS16/BC16 -> 0 | BF16: Au
A17: ON-MAIN-4e0734b5 | C17: Fox Complex | E17: Ontario | F17: mining | G17: Open-pit, underground, concentrator | H17: Free-miling | I17: NPRI+land | L17: Gold | M17: Au | N17: =prod_table_raw!N70 -> 457000 | O17: =SUM(AD17:AP17) -> 0 | P17: =N17-O17 -> 457000 | Q17: =prod_table_raw!N71 -> 1.3809954 | R17: =prod_table_raw!N72 -> 0.0435449 | AF17: =S17/(concentrate_grade!$F$4/100) -> 0 | AG17: =T17/(concentrate_grade!$F$6/100) -> 0 | AQ17: =Q17*prices!$C$4 -> 71526.081 | AR17: =R17*prices!$C$11 -> 29.267834 | AS17: =S17*prices!$C$3 -> 0 | AT17: =T17*prices!$C$8 -> 0 | AU17: =U17*prices!$C$2 -> 0 | AV17: =V17*prices!$C$7 -> 0 | AW17: =W17*prices!$C$13 -> 0 | AX17: =X17*prices!$C$6 -> 0 | AY17: =Y17*prices!$C$5 -> 0 | AZ17: =Z17*prices!$C$9 -> 0 | BA17: =AB17*prices!$C$12 -> 0 | BB17: =AC17*prices!$C$14 -> 0 | BC17: =SUM(AQ17:AZ17) -> 71555.349 | BD17: =AQ17/BC17 -> 0.99959098 | BE17: =AS17/BC17 -> 0 | BF17: Au
A18: ON-MAIN-206041d1 | B18: GRP-de097f20 | C18: Fraser | D18: Integrated Nickel Operations | E18: Ontario | F18: mining | G18: Underground | H18: Ni-Cu Porphyry sulfide, flotation-based | I18: Land | L18: Nickel, copper, platinum group metals, gold, cobalt, silver | M18: Ni+Cu | N18: =prod_table_raw!N73 -> 553033 | O18: =SUM(AD18:AP18) -> 0 | P18: =N18-O18 -> 553033 | AF18: =S18/(concentrate_grade!$F$4/100) -> 0 | AG18: =T18/(concentrate_grade!$F$6/100) -> 0 | AQ18: =Q18*prices!$C$4 -> 0 | AR18: =R18*prices!$C$11 -> 0 | AS18: =S18*prices!$C$3 -> 0 | AT18: =T18*prices!$C$8 -> 0 | AU18: =U18*prices!$C$2 -> 0 | AV18: =V18*prices!$C$7 -> 0 | AW18: =W18*prices!$C$13 -> 0 | AX18: =X18*prices!$C$6 -> 0 | AY18: =Y18*prices!$C$5 -> 0 | AZ18: =Z18*prices!$C$9 -> 0 | BA18: =AB18*prices!$C$12 -> 0 | BB18: =AC18*prices!$C$14 -> 0 | BC18: =SUM(AQ18:AZ18) -> 0 | BD18: =AQ18/BC18 -> #DIV/0! | BE18: =AS18/BC18 -> #DIV/0! | BF18: Ni+Cu
A19: ON-MAIN-48fe2205 | B19: GRP-dc07540b | C19: Garson | D19: Sudbury Operation | E19: Ontario | F19: mining | G19: Underground | H19: Ni-Cu Porphyry sulfide, flotation-based | I19: NPRI+Land | L19: Nickel, copper, platinum group metals, gold, silver, cobalt, selenium, tellurium | M19: Ni+Cu | N19: =prod_table_raw!N76 -> 616000 | O19: =SUM(AD19:AP19) -> 74505.833 | P19: =N19-O19 -> 541494.17 | S19: =prod_table_raw!N75 -> 7453 | T19: =prod_table_raw!N74 -> 7946 | AF19: =S19/(concentrate_grade!$F$4/100) -> 24843.333 | AG19: =T19/(concentrate_grade!$F$6/100) -> 49662.5 | AQ19: =Q19*prices!$C$4 -> 0 | AR19: =R19*prices!$C$11 -> 0 | AS19: =S19*prices!$C$3 -> 51425.7 | AT19: =T19*prices!$C$8 -> 123878.14 | AU19: =U19*prices!$C$2 -> 0 | AV19: =V19*prices!$C$7 -> 0 | AW19: =W19*prices!$C$13 -> 0 | AX19: =X19*prices!$C$6 -> 0 | AY19: =Y19*prices!$C$5 -> 0 | AZ19: =Z19*prices!$C$9 -> 0 | BA19: =AB19*prices!$C$12 -> 0 | BB19: =AC19*prices!$C$14 -> 0 | BC19: =SUM(AQ19:AZ19) -> 175303.84 | BD19: =AQ19/BC19 -> 0 | BE19: =AS19/BC19 -> 0.29335182 | BF19: Ni+Cu
A20: BC-MAIN-6b4800fe | C20: Gibraltar | E20: British Columbia | F20: mining | G20: Open-pit, concentrator | H20: Cu-Mo Porphyry sulfide, flotation-based | I20: NPRI+GHG+Water+Land | J20: Energy | L20: Copper, molybdenum, silver | M20: Cu (Mo) | N20: =prod_table_raw!N80 -> 30000000 | O20: =SUM(AD20:AP20) -> 185367.93 | P20: =N20-O20 -> 29814632 | S20: =prod_table_raw!N82 -> 55610.379 | V20: =prod_table_raw!N81 -> 545.21758 | AF20: =S20/(concentrate_grade!$F$4/100) -> 185367.93 | AG20: =T20/(concentrate_grade!$F$6/100) -> 0 | AQ20: =Q20*prices!$C$4 -> 0 | AR20: =R20*prices!$C$11 -> 0 | AS20: =S20*prices!$C$3 -> 383711.62 | AT20: =T20*prices!$C$8 -> 0 | AU20: =U20*prices!$C$2 -> 0 | AV20: =V20*prices!$C$7 -> 15942.162 | AW20: =W20*prices!$C$13 -> 0 | AX20: =X20*prices!$C$6 -> 0 | AY20: =Y20*prices!$C$5 -> 0 | AZ20: =Z20*prices!$C$9 -> 0 | BA20: =AB20*prices!$C$12 -> 0 | BB20: =AC20*prices!$C$14 -> 0 | BC20: =SUM(AQ20:AZ20) -> 399653.78 | BD20: =AQ20/BC20 -> 0 | BE20: =AS20/BC20 -> 0.96011007 | BF20: Cu (Mo)
A21: QC-MAIN-c0660aec | C21: Goldex | E21: Quebec | F21: mining | G21: Underground, concentrator | H21: Free-miling | I21: NPRI+GHG+Land | J21: Energy | L21: Gold, silver | M21: Au (Cu, Ag) | N21: =prod_table_raw!N86 -> 2886927.3 | O21: =SUM(AD21:AP21) -> 130.12253 | P21: =N21-O21 -> 2886797.2 | Q21: =prod_table_raw!N87 -> 4.3850513 | S21: =prod_table_raw!N85 -> 39.036758 | AF21: =S21/(concentrate_grade!$F$4/100) -> 130.12253 | AG21: =T21/(concentrate_grade!$F$6/100) -> 0 | AQ21: =Q21*prices!$C$4 -> 227115.55 | AR21: =R21*prices!$C$11 -> 0 | AS21: =S21*prices!$C$3 -> 269.35363 | AT21: =T21*prices!$C$8 -> 0 | AU21: =U21*prices!$C$2 -> 0 | AV21: =V21*prices!$C$7 -> 0 | AW21: =W21*prices!$C$13 -> 0 | AX21: =X21*prices!$C$6 -> 0 | AY21: =Y21*prices!$C$5 -> 0 | AZ21: =Z21*prices!$C$9 -> 0 | BA21: =AB21*prices!$C$12 -> 0 | BB21: =AC21*prices!$C$14 -> 0 | BC21: =SUM(AQ21:AZ21) -> 227384.91 | BD21: =AQ21/BC21 -> 0.99881543 | BE21: =AS21/BC21 -> 0.0011845713 | BF21: Au (Cu, Ag)
A22: ON-MAIN-6e9be24e | C22: Hemlo (Williams) | E22: Ontario | F22: mining | G22: Open-pit, underground, concentrator | I22: NPRI+GHG+Land | J22: Energy | L22: Gold | M22: Au | N22: =prod_table_raw!N91 -> 1266009 | O22: =SUM(AD22:AP22) -> 0 | P22: =N22-O22 -> 1266009 | Q22: =prod_table_raw!N91 -> 1266009 | AF22: =S22/(concentrate_grade!$F$4/100) -> 0 | AG22: =T22/(concentrate_grade!$F$6/100) -> 0 | AQ22: =Q22*prices!$C$4 -> 6.5570575e+10 | AR22: =R22*prices!$C$11 -> 0 | AS22: =S22*prices!$C$3 -> 0 | AT22: =T22*prices!$C$8 -> 0 | AU22: =U22*prices!$C$2 -> 0 | AV22: =V22*prices!$C$7 -> 0 | AW22: =W22*prices!$C$13 -> 0 | AX22: =X22*prices!$C$6 -> 0 | AY22: =Y22*prices!$C$5 -> 0 | AZ22: =Z22*prices!$C$9 -> 0 | BA22: =AB22*prices!$C$12 -> 0 | BB22: =AC22*prices!$C$14 -> 0 | BC22: =SUM(AQ22:AZ22) -> 6.5570575e+10 | BD22: =AQ22/BC22 -> 1 | BE22: =AS22/BC22 -> 0 | BF22: Au
A23: BC-MAIN-bf503b6b | C23: Highland Valley | E23: British Columbia | F23: mining | G23: Open-pit, concentrator | H23: Cu-Mo Porphyry sulfide, flotation-based | I23: NPRI+GHG+Water+Land | L23: Copper, silver, molybdenum | M23: Cu (Mo) | N23: =prod_table_raw!N93 -> 17408000 | O23: =SUM(AD23:AP23) -> 341333.33 | P23: =N23-O23 -> 17066667 | S23: =prod_table_raw!N95 -> 102400 | V23: =prod_table_raw!N94 -> 900 | AF23: =S23/(concentrate_grade!$F$4/100) -> 341333.33 | AG23: =T23/(concentrate_grade!$F$6/100) -> 0 | AQ23: =Q23*prices!$C$4 -> 0 | AR23: =R23*prices!$C$11 -> 0 | AS23: =S23*prices!$C$3 -> 706560 | AT23: =T23*prices!$C$8 -> 0 | AU23: =U23*prices!$C$2 -> 0 | AV23: =V23*prices!$C$7 -> 26316 | AW23: =W23*prices!$C$13 -> 0 | AX23: =X23*prices!$C$6 -> 0 | AY23: =Y23*prices!$C$5 -> 0 | AZ23: =Z23*prices!$C$9 -> 0 | BA23: =AB23*prices!$C$12 -> 0 | BB23: =AC23*prices!$C$14 -> 0 | BC23: =SUM(AQ23:AZ23) -> 732876 | BD23: =AQ23/BC23 -> 0 | BE23: =AS23/BC23 -> 0.96409215 | BF23: Cu (Mo)
A24: QC-MAIN-30c1828c | B24: GRP-b48ec279 | C24: Horne | D24: CCR | E24: Quebec | F24: manufacturing | G24: Smelter | I24: NPRI+GHG | L24: Copper anodes, precious metals, sulfuric acid | M24: Cu | O24: =SUM(AD24:AP24) -> 0 | P24: =N24-O24 -> 0 | AF24: =S24/(concentrate_grade!$F$4/100) -> 0 | AG24: =T24/(concentrate_grade!$F$6/100) -> 0 | AQ24: =Q24*prices!$C$4 -> 0 | AR24: =R24*prices!$C$11 -> 0 | AS24: =S24*prices!$C$3 -> 0 | AT24: =T24*prices!$C$8 -> 0 | AU24: =U24*prices!$C$2 -> 0 | AV24: =V24*prices!$C$7 -> 0 | AW24: =W24*prices!$C$13 -> 0 | AX24: =X24*prices!$C$6 -> 0 | AY24: =Y24*prices!$C$5 -> 0 | AZ24: =Z24*prices!$C$9 -> 0 | BA24: =AB24*prices!$C$12 -> 0 | BB24: =AC24*prices!$C$14 -> 0 | BC24: =SUM(AQ24:AZ24) -> 0 | BD24: =AQ24/BC24 -> #DIV/0! | BE24: =AS24/BC24 -> #DIV/0! | BF24: Cu
A25: ON-MAIN-687b8c8d | C25: Island | E25: Ontario | F25: mining | G25: Underground, concentrator | H25: Free-miling | I25: NPRI+GHG | J25: Energy | L25: Gold | M25: Au | N25: =prod_table_raw!N105 -> 439008 | O25: =SUM(AD25:AP25) -> 0 | P25: =N25-O25 -> 439008 | Q25: =prod_table_raw!N103 -> 4.0869999 | AF25: =S25/(concentrate_grade!$F$4/100) -> 0 | AG25: =T25/(concentrate_grade!$F$6/100) -> 0 | AQ25: =Q25*prices!$C$4 -> 211678.54 | AR25: =R25*prices!$C$11 -> 0 | AS25: =S25*prices!$C$3 -> 0 | AT25: =T25*prices!$C$8 -> 0 | AU25: =U25*prices!$C$2 -> 0 | AV25: =V25*prices!$C$7 -> 0 | AW25: =W25*prices!$C$13 -> 0 | AX25: =X25*prices!$C$6 -> 0 | AY25: =Y25*prices!$C$5 -> 0 | AZ25: =Z25*prices!$C$9 -> 0 | BA25: =AB25*prices!$C$12 -> 0 | BB25: =AC25*prices!$C$14 -> 0 | BC25: =SUM(AQ25:AZ25) -> 211678.54 | BD25: =AQ25/BC25 -> 1 | BE25: =AS25/BC25 -> 0 | BF25: Au
A26: YT-MAIN-44857446 | C26: Keno Hill Silver District | E26: Yukon | F26: mining | G26: Underground, concentrator | H26: High-grade polymetallic Pb-Zn-Ag | J26: Energy | L26: Silver, zinc, lead | M26: Ag (Zn) | N26: =prod_table_raw!N110 -> 127307 | O26: =SUM(AD26:AP26) -> 0 | P26: =N26-O26 -> 127307 | R26: =prod_table_raw!N109 -> 46.735404 | W26: =prod_table_raw!N112 -> 1339 | X26: =prod_table_raw!N111 -> 1225 | AF26: =S26/(concentrate_grade!$F$4/100) -> 0 | AG26: =T26/(concentrate_grade!$F$6/100) -> 0 | AQ26: =Q26*prices!$C$4 -> 0 | AR26: =R26*prices!$C$11 -> 31412.267 | AS26: =S26*prices!$C$3 -> 0 | AT26: =T26*prices!$C$8 -> 0 | AU26: =U26*prices!$C$2 -> 0 | AV26: =V26*prices!$C$7 -> 0 | AW26: =W26*prices!$C$13 -> 3453.7022 | AX26: =X26*prices!$C$6 -> 2526.6649 | AY26: =Y26*prices!$C$5 -> 0 | AZ26: =Z26*prices!$C$9 -> 0 | BA26: =AB26*prices!$C$12 -> 0 | BB26: =AC26*prices!$C$14 -> 0 | BC26: =SUM(AQ26:AZ26) -> 37392.634 | BD26: =AQ26/BC26 -> 0 | BE26: =AS26/BC26 -> 0 | BF26: Ag (Zn)
B27: GRP-21eee27d | C27: Key Lake + McArthur River | E27: Saskatchewan | F27: mining | G27: Underground, Concentrator | H27: High-grade U acid-leach mills | L27: Uranium | M27: U | N27: =prod_table_raw!N153 -> 98408.871 | O27: =SUM(AD27:AP27) -> 0 | P27: =N27-O27 -> 98408.871 | AB27: =prod_table_raw!N152 -> 6123.492 | AF27: =S27/(concentrate_grade!$F$4/100) -> 0 | AG27: =T27/(concentrate_grade!$F$6/100) -> 0 | AQ27: =Q27*prices!$C$4 -> 0 | AR27: =R27*prices!$C$11 -> 0 | AS27: =S27*prices!$C$3 -> 0 | AT27: =T27*prices!$C$8 -> 0 | AU27: =U27*prices!$C$2 -> 0 | AV27: =V27*prices!$C$7 -> 0 | AW27: =W27*prices!$C$13 -> 0 | AX27: =X27*prices!$C$6 -> 0 | AY27: =Y27*prices!$C$5 -> 0 | AZ27: =Z27*prices!$C$9 -> 0 | BA27: =AB27*prices!$C$12 -> 1051.4036 | BB27: =AC27*prices!$C$14 -> 0 | BC27: =SUM(AQ27:AZ27) -> 0 | BD27: =AQ27/BC27 -> #DIV/0! | BE27: =AS27/BC27 -> #DIV/0! | BF27: U
A28: ON-MAIN-f8313ebd | C28: Kidd Creek | E28: Ontario | F28: mining | G28: Underground, concentrator | H28: Cu-Zn Porphyry sulfide, flotation-based | I28: NPRI+Land | L28: Copper, zinc, silver, selenium, indium | M28: Cu (Zn, Ag) | N28: =prod_table_raw!N116 -> 1340000 | O28: =SUM(AD28:AP28) -> 75333.333 | P28: =N28-O28 -> 1264666.7 | R28: =prod_table_raw!N115 -> 42.860623 | S28: =prod_table_raw!N113 -> 22600 | W28: =prod_table_raw!N114 -> 38600 | AF28: =S28/(concentrate_grade!$F$4/100) -> 75333.333 | AG28: =T28/(concentrate_grade!$F$6/100) -> 0 | AQ28: =Q28*prices!$C$4 -> 0 | AR28: =R28*prices!$C$11 -> 28807.911 | AS28: =S28*prices!$C$3 -> 155940 | AT28: =T28*prices!$C$8 -> 0 | AU28: =U28*prices!$C$2 -> 0 | AV28: =V28*prices!$C$7 -> 0 | AW28: =W28*prices!$C$13 -> 99561.541 | AX28: =X28*prices!$C$6 -> 0 | AY28: =Y28*prices!$C$5 -> 0 | AZ28: =Z28*prices!$C$9 -> 0 | BA28: =AB28*prices!$C$12 -> 0 | BB28: =AC28*prices!$C$14 -> 0 | BC28: =SUM(AQ28:AZ28) -> 284309.45 | BD28: =AQ28/BC28 -> 0 | BE28: =AS28/BC28 -> 0.54848687 | BF28: Cu (Zn, Ag)
A29: QC-MAIN-9de9bb0d | C29: Kiena | E29: Quebec | F29: mining | G29: Open-pit, concentrator | H29: Free-miling | I29: Land | J29: Energy | L29: Gold, silver | M29: Au (Ag) | N29: =prod_table_raw!N120 -> 191148 | O29: =SUM(AD29:AP29) -> 0 | P29: =N29-O29 -> 191148 | Q29: =prod_table_raw!N119 -> 1.1053251 | R29: =prod_table_raw!N121 -> 0.090448978 | AF29: =S29/(concentrate_grade!$F$4/100) -> 0 | AG29: =T29/(concentrate_grade!$F$6/100) -> 0 | AQ29: =Q29*prices!$C$4 -> 57248.251 | AR29: =R29*prices!$C$11 -> 60.793472 | AS29: =S29*prices!$C$3 -> 0 | AT29: =T29*prices!$C$8 -> 0 | AU29: =U29*prices!$C$2 -> 0 | AV29: =V29*prices!$C$7 -> 0 | AW29: =W29*prices!$C$13 -> 0 | AX29: =X29*prices!$C$6 -> 0 | AY29: =Y29*prices!$C$5 -> 0 | AZ29: =Z29*prices!$C$9 -> 0 | BA29: =AB29*prices!$C$12 -> 0 | BB29: =AC29*prices!$C$14 -> 0 | BC29: =SUM(AQ29:AZ29) -> 57309.045 | BD29: =AQ29/BC29 -> 0.9989392 | BE29: =AS29/BC29 -> 0 | BF29: Au (Ag)
A30: ON-MAIN-a3c56a83 | C30: Lac des Iles | E30: Ontario | F30: mining | G30: Open-pit, underground, concentrator | H30: Porphyry sulfide, flotation-based | I30: GHG | J30: Energy | L30: Platinum group metals, gold, nickel, copper, cobalt | M30: Pt | N30: =prod_table_raw!N124 -> 3798000 | O30: =SUM(AD30:AP30) -> 0 | P30: =N30-O30 -> 3798000 | Q30: =prod_table_raw!N125 -> 0.59407685 | Z30: =prod_table_raw!N127 -> 0.6780563 | AA30: =prod_table_raw!N126 -> 0.7775875 | AF30: =S30/(concentrate_grade!$F$4/100) -> 0 | AG30: =T30/(concentrate_grade!$F$6/100) -> 0 | AQ30: =Q30*prices!$C$4 -> 30769.102 | AR30: =R30*prices!$C$11 -> 0 | AS30: =S30*prices!$C$3 -> 0 | AT30: =T30*prices!$C$8 -> 0 | AU30: =U30*prices!$C$2 -> 0 | AV30: =V30*prices!$C$7 -> 0 | AW30: =W30*prices!$C$13 -> 0 | AX30: =X30*prices!$C$6 -> 0 | AY30: =Y30*prices!$C$5 -> 0 | AZ30: =Z30*prices!$C$9 -> 34878.396 | BA30: =AB30*prices!$C$12 -> 0 | BB30: =AC30*prices!$C$14 -> 0 | BC30: =SUM(AQ30:AZ30) -> 65647.498 | BD30: =AQ30/BC30 -> 0.46870183 | BE30: =AS30/BC30 -> 0 | BF30: Pt
A31: QC-MAIN-f9e41c2a | C31: Lamaque | E31: Quebec | F31: mining | G31: Underground, concentrator | H31: Free-miling | I31: Land | J31: Energy | L31: Gold, silver | M31: Au (Ag) | N31: =prod_table_raw!N134 -> 838419 | O31: =SUM(AD31:AP31) -> 0 | P31: =N31-O31 -> 838419 | Q31: =prod_table_raw!N133 -> 5.5074656 | R31: =prod_table_raw!N135 -> 2.2666987 | AF31: =S31/(concentrate_grade!$F$4/100) -> 0 | AG31: =T31/(concentrate_grade!$F$6/100) -> 0 | AQ31: =Q31*prices!$C$4 -> 285248.91 | AR31: =R31*prices!$C$11 -> 1523.5162 | AS31: =S31*prices!$C$3 -> 0 | AT31: =T31*prices!$C$8 -> 0 | AU31: =U31*prices!$C$2 -> 0 | AV31: =V31*prices!$C$7 -> 0 | AW31: =W31*prices!$C$13 -> 0 | AX31: =X31*prices!$C$6 -> 0 | AY31: =Y31*prices!$C$5 -> 0 | AZ31: =Z31*prices!$C$9 -> 0 | BA31: =AB31*prices!$C$12 -> 0 | BB31: =AC31*prices!$C$14 -> 0 | BC31: =SUM(AQ31:AZ31) -> 286772.43 | BD31: =AQ31/BC31 -> 0.99468737 | BE31: =AS31/BC31 -> 0 | BF31: Au (Ag)
A32: QC-MAIN-e51eda66 | C32: LaRonde | E32: Quebec | F32: mining | G32: Underground, concentrator | H32: Cu-Mo Porphyry sulfide, flotation-based | I32: NPRI+GHG+Land | J32: Energy | L32: Gold, zinc, copper, silver, cadmium | M32: Au (Zn, Cu, Ag) | N32: =prod_table_raw!N139 -> 1501500 | O32: =SUM(AD32:AP32) -> 8593.2013 | P32: =N32-O32 -> 1492906.8 | Q32: =prod_table_raw!N138 -> 7.3401461 | R32: =prod_table_raw!N135 -> 2.2666987 | S32: =prod_table_raw!N137 -> 2577.9604 | W32: =prod_table_raw!N136 -> 7702.4385 | AF32: =S32/(concentrate_grade!$F$4/100) -> 8593.2013 | AG32: =T32/(concentrate_grade!$F$6/100) -> 0 | AQ32: =Q32*prices!$C$4 -> 380169.18 | AR32: =R32*prices!$C$11 -> 1523.5162 | AS32: =S32*prices!$C$3 -> 17787.927 | AT32: =T32*prices!$C$8 -> 0 | AU32: =U32*prices!$C$2 -> 0 | AV32: =V32*prices!$C$7 -> 0 | AW32: =W32*prices!$C$13 -> 19867.012 | AX32: =X32*prices!$C$6 -> 0 | AY32: =Y32*prices!$C$5 -> 0 | AZ32: =Z32*prices!$C$9 -> 0 | BA32: =AB32*prices!$C$12 -> 0 | BB32: =AC32*prices!$C$14 -> 0 | BC32: =SUM(AQ32:AZ32) -> 419347.63 | BD32: =AQ32/BC32 -> 0.90657285 | BE32: =AS32/BC32 -> 0.042418093 | BF32: Au (Zn, Cu, Ag)
A33: NL-MAIN-d9036091 | C33: Long Harbour | E33: Newfoundland and Labrador | F33: manufacturing | G33: Refinery | H33: Ni hydrometallurgical refinery | I33: NPRI+GHG | L33: Nickel | M33: Ni | O33: =SUM(AD33:AP33) -> 173125 | P33: =N33-O33 -> -173125 | T33: =prod_table_raw!N145 -> 27700 | AF33: =S33/(concentrate_grade!$F$4/100) -> 0 | AG33: =T33/(concentrate_grade!$F$6/100) -> 173125 | AQ33: =Q33*prices!$C$4 -> 0 | AR33: =R33*prices!$C$11 -> 0 | AS33: =S33*prices!$C$3 -> 0 | AT33: =T33*prices!$C$8 -> 431843 | AU33: =U33*prices!$C$2 -> 0 | AV33: =V33*prices!$C$7 -> 0 | AW33: =W33*prices!$C$13 -> 0 | AX33: =X33*prices!$C$6 -> 0 | AY33: =Y33*prices!$C$5 -> 0 | AZ33: =Z33*prices!$C$9 -> 0 | BA33: =AB33*prices!$C$12 -> 0 | BB33: =AC33*prices!$C$14 -> 0 | BC33: =SUM(AQ33:AZ33) -> 431843 | BD33: =AQ33/BC33 -> 0 | BE33: =AS33/BC33 -> 0 | BF33: Ni
A34: ON-MAIN-1f126a43 | C34: Macassa | E34: Ontario | F34: mining | G34: Underground, concentrator | I34: NPRI+GHG+Land | J34: Energy | L34: Gold, silver | M34: Au | N34: =prod_table_raw!N146 -> 441588 | O34: =SUM(AD34:AP34) -> 0 | P34: =N34-O34 -> 441588 | Q34: =prod_table_raw!N147 -> 7.1082384 | AF34: =S34/(concentrate_grade!$F$4/100) -> 0 | AG34: =T34/(concentrate_grade!$F$6/100) -> 0 | AQ34: =Q34*prices!$C$4 -> 368157.95 | AR34: =R34*prices!$C$11 -> 0 | AS34: =S34*prices!$C$3 -> 0 | AT34: =T34*prices!$C$8 -> 0 | AU34: =U34*prices!$C$2 -> 0 | AV34: =V34*prices!$C$7 -> 0 | AW34: =W34*prices!$C$13 -> 0 | AX34: =X34*prices!$C$6 -> 0 | AY34: =Y34*prices!$C$5 -> 0 | AZ34: =Z34*prices!$C$9 -> 0 | BA34: =AB34*prices!$C$12 -> 0 | BB34: =AC34*prices!$C$14 -> 0 | BC34: =SUM(AQ34:AZ34) -> 368157.95 | BD34: =AQ34/BC34 -> 1 | BE34: =AS34/BC34 -> 0 | BF34: Au
A35: ON-MAIN-8825d90d | C35: Magino | E35: Ontario | F35: mining | G35: Open-pit, concentrator | H35: Free-miling | I35: NPRI+Land | L35: Gold, silver | M35: Au | N35: =prod_table_raw!N150 -> 1165551 | O35: =SUM(AD35:AP35) -> 0 | P35: =N35-O35 -> 1165551 | Q35: =prod_table_raw!N148 -> 1.0264155 | AF35: =S35/(concentrate_grade!$F$4/100) -> 0 | AG35: =T35/(concentrate_grade!$F$6/100) -> 0 | AQ35: =Q35*prices!$C$4 -> 53161.277 | AR35: =R35*prices!$C$11 -> 0 | AS35: =S35*prices!$C$3 -> 0 | AT35: =T35*prices!$C$8 -> 0 | AU35: =U35*prices!$C$2 -> 0 | AV35: =V35*prices!$C$7 -> 0 | AW35: =W35*prices!$C$13 -> 0 | AX35: =X35*prices!$C$6 -> 0 | AY35: =Y35*prices!$C$5 -> 0 | AZ35: =Z35*prices!$C$9 -> 0 | BA35: =AB35*prices!$C$12 -> 0 | BB35: =AC35*prices!$C$14 -> 0 | BC35: =SUM(AQ35:AZ35) -> 53161.277 | BD35: =AQ35/BC35 -> 1 | BE35: =AS35/BC35 -> 0 | BF35: Au
A36: NU-MAIN-5154702a | C36: Mary River | E36: Nunavut | F36: mining | G36: Open-pit | H36: Direct Shipping Ore | I36: GHG | L36: Iron ore | M36: U | N36: =prod_table_raw!N151 -> 5600000 | O36: =SUM(AD36:AP36) -> 0 | P36: =N36-O36 -> 5600000 | AF36: =S36/(concentrate_grade!$F$4/100) -> 0 | AG36: =T36/(concentrate_grade!$F$6/100) -> 0 | AQ36: =Q36*prices!$C$4 -> 0 | AR36: =R36*prices!$C$11 -> 0 | AS36: =S36*prices!$C$3 -> 0 | AT36: =T36*prices!$C$8 -> 0 | AU36: =U36*prices!$C$2 -> 0 | AV36: =V36*prices!$C$7 -> 0 | AW36: =W36*prices!$C$13 -> 0 | AX36: =X36*prices!$C$6 -> 0 | AY36: =Y36*prices!$C$5 -> 0 | AZ36: =Z36*prices!$C$9 -> 0 | BA36: =AB36*prices!$C$12 -> 0 | BB36: =AC36*prices!$C$14 -> 0 | BC36: =SUM(AQ36:AZ36) -> 0 | BD36: =AQ36/BC36 -> #DIV/0! | BE36: =AS36/BC36 -> #DIV/0! | BF36: U
A37: SK-MAIN-60ba74c4 | C37: McClean Lake | E37: Saskatchewan | F37: mining | G37: Concentrator | H37: High-grade U acid-leach mills | I37: NPRI+GHG+Land | L37: Uranium | M37: U | O37: =SUM(AD37:AP37) -> 0 | P37: =N37-O37 -> 0 | AB37: =prod_table_raw!N155 -> 8164.656 | AF37: =S37/(concentrate_grade!$F$4/100) -> 0 | AG37: =T37/(concentrate_grade!$F$6/100) -> 0 | AQ37: =Q37*prices!$C$4 -> 0 | AR37: =R37*prices!$C$11 -> 0 | AS37: =S37*prices!$C$3 -> 0 | AT37: =T37*prices!$C$8 -> 0 | AU37: =U37*prices!$C$2 -> 0 | AV37: =V37*prices!$C$7 -> 0 | AW37: =W37*prices!$C$13 -> 0 | AX37: =X37*prices!$C$6 -> 0 | AY37: =Y37*prices!$C$5 -> 0 | AZ37: =Z37*prices!$C$9 -> 0 | BA37: =AB37*prices!$C$12 -> 1401.8714 | BB37: =AC37*prices!$C$14 -> 0 | BC37: =SUM(AQ37:AZ37) -> 0 | BD37: =AQ37/BC37 -> #DIV/0! | BE37: =AS37/BC37 -> #DIV/0! | BF37: U
A38: ON-MAIN-7001a391 | C38: McCreedy West | E38: Ontario | F38: mining | G38: Underground | H38: Porphyry sulfide, flotation-based | I38: NPRI+Land | L38: Copper, nickel, platinum group metals, gold, silver, cobalt | M38: PGMs+Cu+Ni | N38: =prod_table_raw!N157 -> 317660 | O38: =SUM(AD38:AP38) -> 0 | P38: =N38-O38 -> 317660 | AF38: =S38/(concentrate_grade!$F$4/100) -> 0 | AG38: =T38/(concentrate_grade!$F$6/100) -> 0 | AQ38: =Q38*prices!$C$4 -> 0 | AR38: =R38*prices!$C$11 -> 0 | AS38: =S38*prices!$C$3 -> 0 | AT38: =T38*prices!$C$8 -> 0 | AU38: =U38*prices!$C$2 -> 0 | AV38: =V38*prices!$C$7 -> 0 | AW38: =W38*prices!$C$13 -> 0 | AX38: =X38*prices!$C$6 -> 0 | AY38: =Y38*prices!$C$5 -> 0 | AZ38: =Z38*prices!$C$9 -> 0 | BA38: =AB38*prices!$C$12 -> 0 | BB38: =AC38*prices!$C$14 -> 0 | BC38: =SUM(AQ38:AZ38) -> 0 | BD38: =AQ38/BC38 -> #DIV/0! | BE38: =AS38/BC38 -> #DIV/0! | BF38: PGMs+Cu+Ni
A39: NU-MAIN-8b0264c9 | C39: Meliadine | E39: Nunavut | F39: mining | G39: Open-pit, underground, concentrator | H39: Free-miling | I39: NPRI+GHG+Land | J39: Energy | L39: Gold | M39: Au (Ag) | N39: =prod_table_raw!N163 -> 1918143 | O39: =SUM(AD39:AP39) -> 0 | P39: =N39-O39 -> 1918143 | Q39: =prod_table_raw!N164 -> 11.32606 | R39: =prod_table_raw!N165 -> 0.8397945 | AF39: =S39/(concentrate_grade!$F$4/100) -> 0 | AG39: =T39/(concentrate_grade!$F$6/100) -> 0 | AQ39: =Q39*prices!$C$4 -> 586612.13 | AR39: =R39*prices!$C$11 -> 564.45108 | AS39: =S39*prices!$C$3 -> 0 | AT39: =T39*prices!$C$8 -> 0 | AU39: =U39*prices!$C$2 -> 0 | AV39: =V39*prices!$C$7 -> 0 | AW39: =W39*prices!$C$13 -> 0 | AX39: =X39*prices!$C$6 -> 0 | AY39: =Y39*prices!$C$5 -> 0 | AZ39: =Z39*prices!$C$9 -> 0 | BA39: =AB39*prices!$C$12 -> 0 | BB39: =AC39*prices!$C$14 -> 0 | BC39: =SUM(AQ39:AZ39) -> 587176.58 | BD39: =AQ39/BC39 -> 0.9990387 | BE39: =AS39/BC39 -> 0 | BF39: Au (Ag)
A40: BC-MAIN-ed23117f | C40: Mount Milligan | E40: British Columbia | F40: mining | G40: Open-pit, concentrator | H40: Cu-Au Porphyry sulfide, flotation-based | I40: NPRI+GHG+Water+Land | J40: Energy | L40: Copper, gold, silver | M40: Cu+Au | N40: =prod_table_raw!N175 -> 21680000 | O40: =SUM(AD40:AP40) -> 93533.694 | P40: =N40-O40 -> 21586466 | Q40: =prod_table_raw!N173 -> 4.8021005 | S40: =prod_table_raw!N171 -> 28060.108 | AF40: =S40/(concentrate_grade!$F$4/100) -> 93533.694 | AG40: =T40/(concentrate_grade!$F$6/100) -> 0 | AQ40: =Q40*prices!$C$4 -> 248715.84 | AR40: =R40*prices!$C$11 -> 0 | AS40: =S40*prices!$C$3 -> 193614.75 | AT40: =T40*prices!$C$8 -> 0 | AU40: =U40*prices!$C$2 -> 0 | AV40: =V40*prices!$C$7 -> 0 | AW40: =W40*prices!$C$13 -> 0 | AX40: =X40*prices!$C$6 -> 0 | AY40: =Y40*prices!$C$5 -> 0 | AZ40: =Z40*prices!$C$9 -> 0 | BA40: =AB40*prices!$C$12 -> 0 | BB40: =AC40*prices!$C$14 -> 0 | BC40: =SUM(AQ40:AZ40) -> 442330.59 | BD40: =AQ40/BC40 -> 0.56228497 | BE40: =AS40/BC40 -> 0.43771503 | BF40: Cu+Au
...

Sheet README
A1: Title of the article:
A2: Authors:
A3: Affiliations:
A4: Journal:
A7: TAB_NAME | B7: DESCRIPTION | C7: SOURCE
A8: site_selection | B8: Describe the selection of sites and their associated data | C8: MetalliCan
A9: prod_data | B9: Ore processed and metal content in product for each sites | C9: MetalliCan
A10: fu
A11: EI | B11: Ecoquery link to some Ecoinvent activities
A15: For dore we assume 88% of Au, 10% of Si and 2% impurities

Sheet site_selection
A1: skip | B1: main_id | C1: facility_group_id | D1: facility_name | E1: facility_group_name | G1: province | H1: facility_type | I1: mining_processing_type | J1: commodities | K1: technosphere_biosphere_data? | L1: material_data? | M1: ghg_data? | N1: water_data? | O1: land_data? | P1: fg_aggregation? | Q1: archetypes | R1: comment
A2: extracted | B2: AB-MAIN-9fed34a8 | D2: AltaSteel | G2: Alberta | H2: manufacturing | I2: Electric arc furnace | J2: Steel | K2: has some biosphere flows only
A3: extracted | B3: AB-MAIN-d3a4aba9 | D3: The Cobalt Refinery Company Inc. | G3: Alberta | H3: manufacturing | I3: Refinery | J3: Nickel, cobalt, copper sulfide, ammonium sulfate | K3: has some biosphere flows only | M3: has GHG data | Q3: Co hydrometallurgical refinery
A4: extracted | B4: BC-MAIN-23155c25 | D4: Myra Falls | G4: British Columbia | H4: mining | I4: Underground | J4: Zinc, copper, silver, gold, lead | K4: has some biosphere flows only | Q4: Porphyry sulfide, flotation-based
A5: extracted | B5: BC-MAIN-3bb6b7cd | D5: Trail | G5: British Columbia | H5: manufacturing | I5: Smelter, refinery, plant | J5: Zinc, lead, bismuth, cadmium, indium, germanium, precious metals, liquid sulfur dioxide, sulfuric acid | K5: has some biosphere flows only | M5: has GHG data | N5: Withdrawal , consumption, discharged
A6: extracted | B6: BC-MAIN-3f490561 | D6: Mount Polley | G6: British Columbia | H6: mining | I6: Open-pit, concentrator | J6: Gold, copper, silver | K6: has some biosphere flows only | M6: has GHG data | Q6: Concentrator with flotation & dewatering; copper-gold concentrate shipped to smelter.
A7: extracted | B7: BC-MAIN-4724f4ba | D7: Elk | G7: British Columbia | H7: mining | I7: Open-pit | J7: Gold | K7: has some technosphere flows | Q7: Free-miling
A8: extracted | B8: BC-MAIN-599152a0 | D8: Copper Mountain | G8: British Columbia | H8: mining | I8: Open-pit, concentrator | J8: Copper, gold, silver | K8: has some technosphere and biosphere flows | M8: has GHG data. Scope 1-2 collected | Q8: Porphyry sulfide, flotation-based
A9: extracted | B9: BC-MAIN-6b4800fe | D9: Gibraltar | G9: British Columbia | H9: mining | I9: Open-pit, concentrator | J9: Copper, molybdenum, silver | K9: has some technosphere and biosphere flows | M9: has GHG data | N9: Withdrawal, consumption (freshwater only) | Q9: Porphyry sulfide, flotation-based
A10: extracted | B10: BC-MAIN-857b7b89 | D10: Brucejack | G10: British Columbia | H10: mining | I10: Underground, concentrator | J10: Gold, silver | K10: has some technosphere and biosphere flows | M10: Scope 1-2-3 collected | N10: Withdrawal
A11: extracted | B11: BC-MAIN-8eb8be0d | D11: Red Chris | G11: British Columbia | H11: mining | I11: Open-pit, concentrator | J11: Gold, copper, silver | K11: has some technosphere and biosphere flows | M11: has GHG data | Q11: Porphyry sulfide, flotation-based
A12: extracted | B12: BC-MAIN-aa76f6f2 | D12: New Afton | G12: British Columbia | H12: mining | I12: Underground, concentrator | J12: Gold, copper, silver | K12: has some technosphere and biosphere flows | L12: has some material flows | M12: Scope 1-2 collected | N12: Withdrawal , consumption, discharged | Q12: Porphyry sulfide, flotation-based
A13: extracted | B13: BC-MAIN-bf503b6b | D13: Highland Valley | G13: British Columbia | H13: mining | I13: Open-pit, concentrator | J13: Copper, silver, molybdenum | K13: has some biosphere flows only | M13: has GHG data | N13: Withdrawal , consumption, discharged | Q13: Porphyry sulfide, flotation-based
A14: extracted | B14: BC-MAIN-ed23117f | D14: Mount Milligan | G14: British Columbia | H14: mining | I14: Open-pit, concentrator | J14: Copper, gold, silver | K14: has some technosphere and biosphere flows, but no NPRI. Energy data in GHG | M14: Scope 1-2 collected | Q14: Porphyry sulfide, flotation-based
A15: extracted | B15: MB-MAIN-0898e255 | C15: GRP-a13779f8 | D15: Stall Lake | E15: Snow Lake | G15: Manitoba | H15: mining | I15: Concentrator | J15: Gold, zinc | K15: has some technosphere and biosphere flows | P15: Production at F level (need to aggregate production); biosphere flows only for New Britannia and Snow Lake
A16: extracted | B16: MB-MAIN-b4ca1426 | D16: Manitoba Mill | G16: Manitoba | H16: manufacturing | I16: Electric arc furnace | J16: Steel | K16: has some biosphere flows only
A17: extracted | B17: MB-MAIN-be5b3dc8 | C17: GRP-a13779f8 | D17: Lalor Lake | E17: Snow Lake | G17: Manitoba | H17: mining | I17: Underground | J17: Gold, zinc, copper, silver | K17: has some technosphere and biosphere flows | P17: Production at F level (need to aggregate production); biosphere flows only for New Britannia and Snow Lake
A18: extracted | B18: MB-MAIN-da0b5c3d | C18: GRP-a13779f8 | D18: New Britannia | E18: Snow Lake | G18: Manitoba | H18: mining | I18: Concentrator | J18: Gold, copper | K18: has some technosphere and biosphere flows | P18: Production at F level (need to aggregate production); biosphere flows only for New Britannia and Snow Lake
A19: extracted | B19: MB-MAIN-e0a6250e | D19: Thompson (T-1 and T-3) | G19: Manitoba | H19: mining | I19: Open-pit, underground, concentrator | J19: Nickel, cobalt, copper, platinum group metals, gold, silver | K19: has some biosphere flows only | M19: has GHG data | Q19: Porphyry sulfide, flotation-based
A20: extracted | B20: NL-MAIN-2d8801d6 | D20: Voisey’s Bay | G20: Newfoundland and Labrador | H20: mining | I20: Open-pit, underground, concentrator | J20: Nickel, copper, cobalt | K20: has some biosphere flows only | M20: has GHG data | Q20: Porphyry sulfide, flotation-based
A21: extracted | B21: NL-MAIN-842ba1b4 | D21: Nugget Pond | G21: Newfoundland and Labrador | H21: mining | I21: Concentrator | J21: Copper | K21: has some biosphere flows only
A22: extracted | B22: NL-MAIN-b64bae7a | D22: Scully | G22: Newfoundland and Labrador | H22: mining | I22: Open-pit, concentrator | J22: Iron | K22: has some technosphere and biosphere flows | M22: has GHG data. Scope 1-2 collected | Q22: Fe concentrator
A23: extracted | B23: NL-MAIN-c139de6d | D23: Ming | G23: Newfoundland and Labrador | H23: mining | I23: Underground | J23: Copper, gold, silver | K23: has some biosphere flows only | Q23: Porphyry sulfide, flotation-based
A24: extracted | B24: NL-MAIN-d9036091 | D24: Long Harbour | G24: Newfoundland and Labrador | H24: manufacturing | I24: Refinery | J24: Nickel, copper, cobalt | K24: has some biosphere flows only | M24: has GHG data | Q24: Ni hydrometallurgical refinery
A25: extracted | B25: NL-MAIN-dd723db4 | D25: Carol Lake | G25: Newfoundland and Labrador | H25: mining | I25: Open-pit, concentrator | J25: Iron | K25: has some technosphere and biosphere flows. Only total energy | M25: has GHG data. Scope1+2 (aggregated) collected | Q25: Fe concentrator + pellet plant
A26: extracted | B26: NL-MAIN-e09881ff | C26: GRP-2a663492 | D26: DSO (3 and 4) | E26: DSO | G26: Newfoundland and Labrador | H26: mining | I26: Open-pit | J26: Iron | K26: has some biosphere flows only | M26: has GHG data | P26: Aggregated production data at FG | Q26: Direct Shipping Ore
A27: extracted | B27: NT-MAIN-0ec39ce0 | D27: Diavik | G27: Northwest Territories | H27: mining | I27: Underground, plant | J27: Diamonds | K27: has some biosphere flows only
A28: extracted | B28: NT-MAIN-6c1d6ee6 | D28: Ekati | G28: Northwest Territories | H28: mining | I28: Underground, plant | J28: Diamonds | K28: has some biosphere flows only | M28: has GHG data
A29: extracted | B29: NT-MAIN-94e652a5 | D29: Gahcho Kué | G29: Northwest Territories | H29: mining | I29: Open-pit, plant | J29: Diamonds | K29: has some biosphere flows only
A30: extracted | B30: NU-MAIN-4ea8ac9d | C30: GRP-0a2c0d69 | D30: Amaruq | E30: Meadowbank complex | G30: Nunavut | H30: mining | I30: Open-pit, underground | J30: Gold | K30: has some technosphere and biosphere flows | P30: Aggregated production data at FG; biosphere flows only for Meadowbank | Q30: Free-miling
A31: extracted | B31: NU-MAIN-5154702a | D31: Mary River | G31: Nunavut | H31: mining | I31: Open-pit | J31: Iron | K31: has some biosphere flows only | M31: Scope 1 collected | Q31: Direct Shipping Ore
A32: extracted | B32: NU-MAIN-730aefe3 | C32: GRP-0a2c0d69 | D32: Meadowbank | E32: Meadowbank complex | G32: Nunavut | H32: mining | I32: Concentrator | J32: Gold | K32: has some technosphere and biosphere flows | M32: has GHG data | P32: Aggregated production data at FG; biosphere flows only for Meadowbank | Q32: Free-miling
A33: extracted | B33: NU-MAIN-8b0264c9 | D33: Meliadine | G33: Nunavut | H33: mining | I33: Open-pit, underground, concentrator | J33: Gold | K33: has some technosphere and biosphere flows | M33: has GHG data | N33: Withdrawal, consumption. Freshwater withdrawal intensity per ore processed and oz gold | Q33: Free-miling
A34: extracted | B34: ON-MAIN-020a683c | D34: Hamilton Works | G34: Ontario | H34: manufacturing | I34: Basic oxygen furnace | J34: Steel | K34: has some biosphere flows only
A35: extracted | B35: ON-MAIN-0aadf28f | D35: Rainy River | G35: Ontario | H35: mining | I35: Open-pit, underground, concentrator | J35: Gold, silver | K35: has some technosphere and biosphere flows | L35: has some material flows | M35: has GHG data. Scope 1-2 collected | N35: Withdrawal , consumption, discharged | Q35: Free-miling
A36: extracted | B36: ON-MAIN-1c674cd0 | C36: GRP-0d911886 | D36: Borden | E36: Porcupine complex | G36: Ontario | H36: mining | I36: Open-pit, underground | J36: Gold | K36: has some technosphere and biosphere flows | L36: has some material flows | P36: Aggregated production data at FG; biosphere flows only for Borden and Hoyle Pond
A37: extracted | B37: ON-MAIN-1f126a43 | D37: Macassa | G37: Ontario | H37: mining | I37: Underground, concentrator | J37: Gold, silver | K37: has some technosphere and biosphere flows | M37: has GHG data | N37: Withdrawal (freshwater separated) , consumption, discharged. Freshwater withdrawal intensity per ore processed and oz gold | Q37: Refractory?
A38: extracted | B38: ON-MAIN-206041d1 | C38: GRP-de097f20 | D38: Fraser | E38: Integrated Nickel Operations | G38: Ontario | H38: mining | I38: Underground | J38: Nickel, copper, platinum group metals, gold, cobalt, silver | K38: has some biosphere flows only | P38: Production at F level | Q38: Porphyry sulfide, flotation-based
A39: extracted | B39: ON-MAIN-21b6ab35 | D39: Whitby Mill | G39: Ontario | H39: manufacturing | I39: Electric arc furnace | J39: Steel | K39: has some biosphere flows only
A40: extracted | B40: ON-MAIN-28f3f0fc | C40: GRP-dc07540b | D40: Totten | E40: Sudbury Operation | G40: Ontario | H40: mining | I40: Underground | J40: Nickel, copper, platinum group metals, gold, silver, cobalt | K40: has some biosphere flows only | P40: Aggregated at FG | Q40: Porphyry sulfide, flotation-based
...

Sheet prod_data
A1: main_id | B1: facility_group_id | C1: facility_name | D1: facility_group_name | E1: province | F1: facility_type | G1: mining_processing_type | H1: npv | I1: archetypes | J1: archetypes_detailed | K1: biosphere_data? | L1: technosphere_data? | M1: land_data? | N1: ta_data? | O1: infer_energy_data | P1: infer_land_data | Q1: infer_material_data | R1: infer_cement_data | S1: infer_explosives_data | T1: infer_water_data | U1: commodities | V1: Create_LCI? | W1: Main_product | X1: Stream | Y1: ore_processed_t | Z1: dore_t_mass | AA1: conc_t_mass | AB1: tailings_t_mass | AC1: dore_yield | AD1: concentrate_yield | AE1: % tailings | AF1: Au_t | AG1: Ag_t | AH1: Cu_t | AI1: Ni_t | AJ1: Co_t | AK1: Mo_t | AL1: Zn_t | AM1: Pb_t | AN1: Fe_t | AO1: Pt_t | AP1: Pd_t | AQ1: U_t | AR1: Nb_t | AS1: Cu_conc | AT1: Ni_conc | AU1: Mo_conc | AV1: Zn_conc | AW1: Pb_conc | AX1: Fe_conc | AY1: Pt_conc | AZ1: Pd_conc | BA1: U_conc | BB1: Nb_conc | BC1: Au_conc
A2: QC-MAIN-089f3c60 | C2: Bloom Lake | E2: Quebec | F2: mining | G2: Open-pit | I2: Magnetite concentrator | J2: Only mining | K2: NPRI+GHG+Land | L2: (NRJ could be back calculated with GHG) | M2: 15702688 | N2: Concentrate grade | O2: Yes | Q2: Yes | R2: Yes | S2: Yes | T2: Yes | U2: Iron | V2: No (iron) | W2: Fe | X2: Fe conc. | Y2: =prod_table_raw!N11 -> 11187000 | AB2: =Y2-Z2-AA2 -> 11187000 | AC2: =Z2/Y2 -> 0 | AD2: =AA2/Y2 -> 0 | AE2: =1-(Z2+AA2)/AB2 -> 1 | AS2: =AH2/(concentrate_grade!$F$4/100) -> 0 | AT2: =AI2/(concentrate_grade!$F$6/100) -> 0 | AU2: =AK2/(concentrate_grade!$F$5/100) -> 0 | AV2: =AL2/(concentrate_grade!$F$9/100) -> 0 | AW2: =AM2/(concentrate_grade!$F$8/100) -> 0 | BB2: =AR2/concentrate_grade!#REF! -> #REF! | BC2: =Z2 -> 0
A3: BC-MAIN-857b7b89 | C3: Brucejack | E3: British Columbia | F3: mining | G3: Underground, concentrator | H3: Low and High Shrub Tundra | I3: Au–Ag free-milling | J3: Might contain refractory ore? Big GHG outlier | K3: NPRI+GHG+Water | L3: Energy | N3: HG, RR | P3: Yes | Q3: Yes | R3: Yes | S3: Yes | T3: No | U3: Gold, silver | V3: Yes | W3: Au | X3: Au-Ag doré | Y3: =prod_table_raw!N13 -> 166000 | Z3: =(AF3+AG3)/0.98 -> 0.92040969 | AB3: =Y3-Z3-AA3 -> 165999.08 | AC3: =Z3/Y3 -> 5.5446367e-06 | AD3: =AA3/Y3 -> 0 | AE3: =1-(Z3+AA3)/AB3 -> 0.99999446 | AF3: =prod_table_raw!N14 -> 0.9020015 | AS3: =AH3/(concentrate_grade!$F$4/100) -> 0 | AT3: =AI3/(concentrate_grade!$F$6/100) -> 0 | AU3: =AK3/(concentrate_grade!$F$5/100) -> 0 | AV3: =AL3/(concentrate_grade!$F$9/100) -> 0 | AW3: =AM3/(concentrate_grade!$F$8/100) -> 0 | BB3: =AR3/concentrate_grade!#REF! -> #REF! | BC3: =Z3 -> 0.92040969
A4: QC-MAIN-de3d8b7b | C4: Canadian Electrolytic Zinc Limited (CEZinc) | E4: Quebec | F4: manufacturing | G4: Refinery | I4: Zn refinery | K4: Land | M4: 1248584.7 | Q4: Yes | R4: Yes | T4: Yes | U4: Lead, zinc | V4: No | W4: Zn (Pb) | AB4: =Y4-Z4-AA4 -> 0 | AL4: =prod_table_raw!N16 -> 752600 | AM4: =prod_table_raw!N15 -> 244600 | AS4: =AH4/(concentrate_grade!$F$4/100) -> 0 | AT4: =AI4/(concentrate_grade!$F$6/100) -> 0 | AU4: =AK4/(concentrate_grade!$F$5/100) -> 0 | AW4: =AM4/(concentrate_grade!$F$8/100) -> 407666.67 | BC4: =Z4 -> 0
A5: QC-MAIN-e7e6a960 | C5: Canadian Malartic | E5: Quebec | F5: mining | G5: Open-pit, concentrator | H5: Cool Mixed Forest | I5: Au–Ag free-milling | J5: Might contain refractory ore? | K5: NPRI+GHG+Land | L5: Energy | M5: 19028718 | N5: HG, RR, SR for Au | Q5: Yes | R5: Yes | S5: Yes | T5: m3/t | U5: Gold, silver | V5: Yes | W5: Au (Ag) | X5: Au-Ag doré | Y5: =prod_table_raw!N17 -> 17332900 | Z5: =(AF5+AG5)/0.98 -> 29.039085 | AB5: =Y5-Z5-AA5 -> 17332871 | AC5: =Z5/Y5 -> 1.6753737e-06 | AD5: =AA5/Y5 -> 0 | AE5: =1-(Z5+AA5)/AB5 -> 0.99999832 | AF5: =prod_table_raw!N18 -> 18.785114 | AG5: =prod_table_raw!N19 -> 9.6731885 | AS5: =AH5/(concentrate_grade!$F$4/100) -> 0 | AT5: =AI5/(concentrate_grade!$F$6/100) -> 0 | AU5: =AK5/(concentrate_grade!$F$5/100) -> 0 | AV5: =AL5/(concentrate_grade!$F$9/100) -> 0 | AW5: =AM5/(concentrate_grade!$F$8/100) -> 0 | BB5: =AR5/concentrate_grade!#REF! -> #REF! | BC5: =Z5 -> 29.039085
A6: NL-MAIN-dd723db4 | C6: Carol Lake | E6: Newfoundland and Labrador | F6: mining | G6: Open-pit, concentrator | H6: Cold Evergreen Needleleaf Forest | I6: Fe concentrator + pellet plant | K6: NPRI+GHG+Land | L6: Energy | M6: 26104649 | Q6: Yes | R6: Yes | S6: Yes | T6: Yes | U6: Iron | V6: No (iron) | W6: Fe | X6: Fe conc., Fe pellets | Y6: =prod_table_raw!N21 -> 16478000 | AB6: =Y6-Z6-AA6 -> 16478000 | AC6: =Z6/Y6 -> 0 | AD6: =AA6/Y6 -> 0 | AE6: =1-(Z6+AA6)/AB6 -> 1 | AS6: =AH6/(concentrate_grade!$F$4/100) -> 0 | AT6: =AI6/(concentrate_grade!$F$6/100) -> 0 | AU6: =AK6/(concentrate_grade!$F$5/100) -> 0 | AV6: =AL6/(concentrate_grade!$F$9/100) -> 0 | AW6: =AM6/(concentrate_grade!$F$8/100) -> 0 | BB6: =AR6/concentrate_grade!#REF! -> #REF! | BC6: =Z6 -> 0
A7: QC-MAIN-b86f7d07 | C7: Casa Berardi | E7: Quebec | F7: mining | G7: Open-pit, underground, concentrator | H7: Cool Mixed Forest | I7: Au–Ag free-milling | K7: NPRI+GHG+Land | L7: Energy and explosives | M7: 6202897 | N7: HG | R7: Yes | T7: Yes | U7: Gold, silver | V7: Yes | W7: Au | X7: Au-Ag doré | Y7: =prod_table_raw!N24 -> 1361450 | Z7: =(AF7+AG7)/0.98 -> 3.5165998 | AB7: =Y7-Z7-AA7 -> 1361446.5 | AC7: =Z7/Y7 -> 2.5829812e-06 | AD7: =AA7/Y7 -> 0 | AE7: =1-(Z7+AA7)/AB7 -> 0.99999742 | AF7: =prod_table_raw!N22 -> 2.6935631 | AG7: =prod_table_raw!N23 -> 0.7527047 | AS7: =AH7/(concentrate_grade!$F$4/100) -> 0 | AT7: =AI7/(concentrate_grade!$F$6/100) -> 0 | AU7: =AK7/(concentrate_grade!$F$5/100) -> 0 | AV7: =AL7/(concentrate_grade!$F$9/100) -> 0 | AW7: =AM7/(concentrate_grade!$F$8/100) -> 0 | BB7: =AR7/concentrate_grade!#REF! -> #REF! | BC7: =Z7 -> 3.5165998
A8: ON-MAIN-f080c409 | B8: GRP-dc07540b | C8: Copper Cliff Complex (mine) | D8: Sudbury Operation | E8: Ontario | F8: mining | G8: Underground | H8: Cool Mixed Forest | I8: Ni–Cu sulfide | J8: Only mining | K8: NPRI+Land | M8: 21591249 | Q8: Yes | R8: Yes | S8: Yes | T8: Yes | U8: Nickel, copper, platinum group metals, gold, silver, cobalt, selenium, tellurium | V8: Not sure (Vale Sudbury) | W8: Ni+Cu | X8: Ni-Cu bulk conc. | Y8: =prod_table_raw!N30 -> 748000 | AA8: =AI8/(concentrate_grade!$F$6/100) -> 54693.75 | AB8: =Y8-Z8-AA8 -> 693306.25 | AC8: =Z8/Y8 -> 0 | AD8: =AA8/Y8 -> 0.073119987 | AE8: =1-(Z8+AA8)/AB8 -> 0.9211117 | AH8: =prod_table_raw!N29 -> 10098 | AI8: =prod_table_raw!N28 -> 8751 | AT8: =AI8/(concentrate_grade!$F$6/100) -> 54693.75 | AU8: =AK8/(concentrate_grade!$F$5/100) -> 0 | AV8: =AL8/(concentrate_grade!$F$9/100) -> 0 | AW8: =AM8/(concentrate_grade!$F$8/100) -> 0 | BB8: =AR8/concentrate_grade!#REF! -> #REF! | BC8: =Z8 -> 0
A9: ON-MAIN-63b394c3 | B9: GRP-dc07540b | C9: Copper Cliff Complex (refinery) | D9: Sudbury Operation | E9: Ontario | F9: manufacturing | G9: Smelter, refinery, plant | H9: Cool Mixed Forest | I9: Cu-Ni smelter and refinery | K9: NPRI+GHG+Land | L9: (NRJ could be back calculated with GHG) | M9: 3963061.6 | O9: Yes | Q9: Yes | R9: Yes | T9: Yes | U9: Nickel (oxide sinter, pellets, powder, sulfide), copper cathodes, gold, silver, selenium cake, tellurium dioxide cake, platinum group metals (in residues), liquid sulfur dioxide, sulfuric acid | V9: Not sure (Vale Sudbury) | W9: Ni+Cu | X9: Refined Ni+Cu | AB9: =Y9-Z9-AA9 -> 0 | AH9: =prod_table_raw!N31 -> 57900 | AI9: =prod_table_raw!N32 -> 38200 | AU9: =AK9/(concentrate_grade!$F$5/100) -> 0 | AW9: =AM9/(concentrate_grade!$F$8/100) -> 0 | BC9: =Z9 -> 0
A10: BC-MAIN-599152a0 | C10: Copper Mountain | E10: British Columbia | F10: mining | G10: Open-pit, concentrator | H10: Cool Evergreen Needleleaf Forest | I10: Cu Porphyry | K10: NPRI+GHG+Land | L10: Energy (but sanity issue) | M10: 13233210 | N10: HG (Au, Ag, Cu), RR, SR | O10: Yes | Q10: Yes | R10: Yes | S10: Yes | T10: Yes | U10: Copper, gold, silver | V10: Yes | W10: Cu (Au, Ag) | X10: Cu conc. | Y10: =prod_table_raw!N36 -> 6862152 | AA10: =AH10/(concentrate_grade!$F$4/100) -> 63500 | AB10: =Y10-Z10-AA10 -> 6798652 | AC10: =Z10/Y10 -> 0 | AD10: =AA10/Y10 -> 0.0092536569 | AE10: =1-(Z10+AA10)/AB10 -> 0.99065991 | AF10: =prod_table_raw!N35 -> 0.27520377 | AG10: =prod_table_raw!N38 -> 6.7893342 | AH10: =prod_table_raw!N39 -> 19050 | AS10: =AH10/(concentrate_grade!$F$4/100) -> 63500 | AT10: =AI10/(concentrate_grade!$F$6/100) -> 0 | AU10: =AK10/(concentrate_grade!$F$5/100) -> 0 | AV10: =AL10/(concentrate_grade!$F$9/100) -> 0 | AW10: =AM10/(concentrate_grade!$F$8/100) -> 0 | BB10: =AR10/concentrate_grade!#REF! -> #REF! | BC10: =Z10 -> 0
A11: ON-MAIN-52224e1e | B11: GRP-dc07540b | C11: Creighton | D11: Sudbury Operation | E11: Ontario | F11: mining | G11: Underground | H11: Cool Mixed Forest | I11: Ni–Cu sulfide | J11: Only mining | K11: NPRI+land | M11: 1929968.2 | N11: HG | Q11: Yes | R11: Yes | S11: Yes | T11: Yes | U11: Nickel, copper, platinum group metals, gold, silver, cobalt, selenium, tellurium | V11: Not sure (Vale Sudbury) | W11: Ni+Cu | X11: Ni-Cu bulk conc. | Y11: =prod_table_raw!N44 -> 433000 | AA11: =AI11/(concentrate_grade!$F$6/100) -> 70900 | AB11: =Y11-Z11-AA11 -> 362100 | AC11: =Z11/Y11 -> 0 | AD11: =AA11/Y11 -> 0.16374134 | AE11: =1-(Z11+AA11)/AB11 -> 0.80419774 | AH11: =prod_table_raw!N43 -> 9396 | AI11: =prod_table_raw!N42 -> 11344 | AT11: =AI11/(concentrate_grade!$F$6/100) -> 70900 | AU11: =AK11/(concentrate_grade!$F$5/100) -> 0 | AV11: =AL11/(concentrate_grade!$F$9/100) -> 0 | AW11: =AM11/(concentrate_grade!$F$8/100) -> 0 | BB11: =AR11/concentrate_grade!#REF! -> #REF! | BC11: =Z11 -> 0
A12: ON-MAIN-aeafbb59 | C12: Detour Lake | E12: Ontario | F12: mining | G12: Open-pit, concentrator | H12: Cool Evergreen Needleleaf Forest | I12: Au–Ag free-milling | K12: NPRI+GHG+Land | L12: Energy | M12: 10276967 | N12: SR | Q12: Yes | R12: Yes | T12: m3/t | U12: Gold | V12: Yes | W12: Au (Ag) | X12: Au-Ag doré | Y12: =prod_table_raw!N48 -> 25434854 | Z12: =(AF12+AG12)/0.98 -> 24.008284 | AB12: =Y12-Z12-AA12 -> 25434829 | AC12: =Z12/Y12 -> 9.439128e-07 | AD12: =AA12/Y12 -> 0 | AE12: =1-(Z12+AA12)/AB12 -> 0.99999906 | AF12: =prod_table_raw!N49 -> 21.070942 | AG12: =prod_table_raw!N50 -> 2.4571765 | AS12: =AH12/(concentrate_grade!$F$4/100) -> 0 | AT12: =AI12/(concentrate_grade!$F$6/100) -> 0 | AU12: =AK12/(concentrate_grade!$F$5/100) -> 0 | AV12: =AL12/(concentrate_grade!$F$9/100) -> 0 | AW12: =AM12/(concentrate_grade!$F$8/100) -> 0 | BB12: =AR12/concentrate_grade!#REF! -> #REF! | BC12: =Z12 -> 24.008284
A13: ON-MAIN-cb85213a | C13: Eagle River | E13: Ontario | F13: mining | G13: Underground, concentrator | H13: Cool Mixed Forest | I13: Au–Ag free-milling | K13: NPRI+GHG | L13: Energy and explosives (but sanity issue) | M13: 352884.57 | N13: HG, RR, SR | O13: Yes | R13: Yes | T13: m3/t | U13: Gold | V13: Yes | W13: Au | X13: Au-Ag doré | Y13: =prod_table_raw!N55 -> 222627 | Z13: =(AF13+AG13)/0.98 -> 2.7760509 | AB13: =Y13-Z13-AA13 -> 222624.22 | AC13: =Z13/Y13 -> 1.2469516e-05 | AD13: =AA13/Y13 -> 0 | AE13: =1-(Z13+AA13)/AB13 -> 0.99998753 | AF13: =prod_table_raw!N54 -> 2.7205298 | AS13: =AH13/(concentrate_grade!$F$4/100) -> 0 | AT13: =AI13/(concentrate_grade!$F$6/100) -> 0 | AU13: =AK13/(concentrate_grade!$F$5/100) -> 0 | AV13: =AL13/(concentrate_grade!$F$9/100) -> 0 | AW13: =AM13/(concentrate_grade!$F$8/100) -> 0 | BB13: =AR13/concentrate_grade!#REF! -> #REF! | BC13: =Z13 -> 2.7760509
